Workbook

Sheet ASSUMPTIONS
A1: Assumption | B1: Value | C1: Note
A2: Days in Quarter | B2: 91 | C2: Used by DSO/DIO/DPO ratios. Approximation; varies 89-92 by quarter.

Sheet ANNL P&L
B1: FY2019 | C1: FY2020 | D1: FY2021 | E1: FY2022 | F1: FY2023 | G1: FY2024 | H1: FY2025 | I1: FY2026E | J1: FY2027E | K1: FY2028E | L1: FY2029E | M1: FY2030E | N1: FY2031E
A2: Net Sales / Revenue | B2: 4200819 | C2: 4598638 | D2: 5541352 | E2: 6311050 | F2: 7140027 | G2: 7492709 | H2: 8294343 | I2: ='QTR P&L'!Z2+'QTR P&L'!AA2+'QTR P&L'!AB2+'QTR P&L'!AC2 -> 9754572.1 | J2: ='QTR P&L'!AD2+'QTR P&L'!AE2+'QTR P&L'!AF2+'QTR P&L'!AG2 -> 11471876 | K2: ='QTR P&L'!AH2+'QTR P&L'!AI2+'QTR P&L'!AJ2+'QTR P&L'!AK2 -> 13491514 | L2: ='QTR P&L'!AL2+'QTR P&L'!AM2+'QTR P&L'!AN2+'QTR P&L'!AO2 -> 15866711 | M2: ='QTR P&L'!AP2+'QTR P&L'!AQ2+'QTR P&L'!AR2+'QTR P&L'!AS2 -> 18660065
A3: COGS | B3: -1682234 | C3: -1874758 | D3: -2432839 | E3: -3136483 | F3: -3345821 | G3: -3443831 | H3: -3662148 | I3: ='QTR P&L'!Z3+'QTR P&L'!AA3+'QTR P&L'!AB3+'QTR P&L'!AC3 -> -4338044.6 | J3: ='QTR P&L'!AD3+'QTR P&L'!AE3+'QTR P&L'!AF3+'QTR P&L'!AG3 -> -5101762.6 | K3: ='QTR P&L'!AH3+'QTR P&L'!AI3+'QTR P&L'!AJ3+'QTR P&L'!AK3 -> -5999934.1 | L3: ='QTR P&L'!AL3+'QTR P&L'!AM3+'QTR P&L'!AN3+'QTR P&L'!AO3 -> -7056229.7 | M3: ='QTR P&L'!AP3+'QTR P&L'!AQ3+'QTR P&L'!AR3+'QTR P&L'!AS3 -> -8298487.4
A4: Gross Profit (Loss) | B4: =B2+B3 -> 2518585 | C4: =C2+C3 -> 2723880 | D4: =D2+D3 -> 3108513 | E4: =E2+E3 -> 3174567 | F4: =F2+F3 -> 3794206 | G4: =G2+G3 -> 4048878 | H4: =H2+H3 -> 4632195 | I4: =I2+I3 -> 5416527.4 | ... N4: =N2+N3 -> 0
A5: Operating Expenses | B5: -1115646 | C5: -1090727 | D5: -1311046 | E5: -1589846 | F5: -1840851 | G5: -2118584 | H5: -2212841 | I5: ='QTR P&L'!Z5+'QTR P&L'!AA5+'QTR P&L'!AB5+'QTR P&L'!AC5 -> -2932702.6 | J5: ='QTR P&L'!AD5+'QTR P&L'!AE5+'QTR P&L'!AF5+'QTR P&L'!AG5 -> -3449008.4 | K5: ='QTR P&L'!AH5+'QTR P&L'!AI5+'QTR P&L'!AJ5+'QTR P&L'!AK5 -> -4056210.4 | L5: ='QTR P&L'!AL5+'QTR P&L'!AM5+'QTR P&L'!AN5+'QTR P&L'!AO5 -> -4770311.2 | M5: ='QTR P&L'!AP5+'QTR P&L'!AQ5+'QTR P&L'!AR5+'QTR P&L'!AS5 -> -5610130.2
A6: Income (Loss) from Operations | B6: =B4+B5 -> 1402939 | C6: =C4+C5 -> 1633153 | D6: =D4+D5 -> 1797467 | E6: =E4+E5 -> 1584721 | F6: =F4+F5 -> 1953355 | G6: =G4+G5 -> 1930294 | H6: =H4+H5 -> 2419354 | I6: =I4+I5 -> 2483824.9 | ... N6: =N4+N5 -> 0
A7: Interest Income (Expense) | B7: 0 | C7: 0 | D7: 0 | E7: 0 | F7: 115127 | G7: 59165 | H7: 0 | I7: ='QTR P&L'!Z8+'QTR P&L'!AA8+'QTR P&L'!AB8+'QTR P&L'!AC8 -> -150088 | J7: ='QTR P&L'!AD8+'QTR P&L'!AE8+'QTR P&L'!AF8+'QTR P&L'!AG8 -> -150088 | K7: ='QTR P&L'!AH8+'QTR P&L'!AI8+'QTR P&L'!AJ8+'QTR P&L'!AK8 -> -150088 | L7: ='QTR P&L'!AL8+'QTR P&L'!AM8+'QTR P&L'!AN8+'QTR P&L'!AO8 -> -150088 | M7: ='QTR P&L'!AP8+'QTR P&L'!AQ8+'QTR P&L'!AR8+'QTR P&L'!AS8 -> -150088
A8: Other Income (Expense) | B8: 13023 | C8: -6996 | D8: 3952 | E8: -12757 | F8: 0 | G8: 0 | H8: 63175 | I8: ='QTR P&L'!Z7+'QTR P&L'!AA7+'QTR P&L'!AB7+'QTR P&L'!AC7 -> 252700 | J8: ='QTR P&L'!AD7+'QTR P&L'!AE7+'QTR P&L'!AF7+'QTR P&L'!AG7 -> 252700 | K8: ='QTR P&L'!AH7+'QTR P&L'!AI7+'QTR P&L'!AJ7+'QTR P&L'!AK7 -> 252700 | L8: ='QTR P&L'!AL7+'QTR P&L'!AM7+'QTR P&L'!AN7+'QTR P&L'!AO7 -> 252700 | M8: ='QTR P&L'!AP7+'QTR P&L'!AQ7+'QTR P&L'!AR7+'QTR P&L'!AS7 -> 252700
A9: Pre-Tax Income (Loss) | B9: =B6+SUM(B7:B8) -> 1415962 | C9: =C6+SUM(C7:C8) -> 1626157 | D9: =D6+SUM(D7:D8) -> 1801419 | E9: =E6+SUM(E7:E8) -> 1571964 | F9: =F6+SUM(F7:F8) -> 2068482 | G9: =G6+SUM(G7:G8) -> 1989459 | H9: =H6+SUM(H7:H8) -> 2482529 | I9: =I6+SUM(I7:I8) -> 2586436.9 | ... N9: =N6+SUM(N7:N8) -> 0
A10: Income Tax (Expense) Benefit | B10: -308127 | C10: -216563 | D10: -423944 | E10: -380340 | F10: -437494 | G10: -480411 | H10: -577097 | I10: ='QTR P&L'!Z10+'QTR P&L'!AA10+'QTR P&L'!AB10+'QTR P&L'!AC10 -> -542044.55 | J10: ='QTR P&L'!AD10+'QTR P&L'!AE10+'QTR P&L'!AF10+'QTR P&L'!AG10 -> -633686.24 | K10: ='QTR P&L'!AH10+'QTR P&L'!AI10+'QTR P&L'!AJ10+'QTR P&L'!AK10 -> -741461.56 | L10: ='QTR P&L'!AL10+'QTR P&L'!AM10+'QTR P&L'!AN10+'QTR P&L'!AO10 -> -868210.85 | M10: ='QTR P&L'!AP10+'QTR P&L'!AQ10+'QTR P&L'!AR10+'QTR P&L'!AS10 -> -1017274.5
A11: Net Income (Loss) | B11: =B9+B10 -> 1107835 | C11: =C9+C10 -> 1409594 | D11: =D9+D10 -> 1377475 | E11: =E9+E10 -> 1191624 | F11: =F9+F10 -> 1630988 | G11: =G9+G10 -> 1509048 | H11: =H9+H10 -> 1905432 | I11: =I9+I10 -> 2044392.3 | ... N11: =N9+N10 -> 0
A12: Basic Earnings (Loss) per Share | B12: 2.04 | C12: 2.66 | D12: 2.61 | E12: 2.26 | F12: 1.56 | G12: 1.5 | H12: 1.95
A13: Diluted Earnings (Loss) per Share | B13: 2.03 | C13: 2.64 | D13: 2.57 | E13: 2.23 | F13: 1.54 | G13: 1.49 | H13: 1.94
A14: Weighted Average Shares Outstanding (Basic) | B14: 542191000 | C14: 529639000 | D14: 528763000 | E14: 526779000 | F14: 1044887000 | G14: 1004566000 | H14: 975887000
A15: Weighted Average Shares Outstanding (Diluted) | B15: 546608000 | C15: 534807000 | D15: 535639000 | E15: 533221000 | F15: 1057981000 | G15: 1013107000 | H15: 984451000
A16: Net Income (Loss) Attributable to Common Shareholders | B16: =B11 -> 1107835 | C16: =C11 -> 1409594 | D16: =D11 -> 1377475 | E16: =E11 -> 1191624 | F16: =F11 -> 1630988 | G16: =G11 -> 1509048 | H16: =H11 -> 1905432 | I16: =I11 -> 2044392.3 | ... N16: =N11 -> 0

Sheet BALANCE SHEET
B1: FY2020 | C1: FY2021 | D1: FY2022 | E1: FY2023 | F1: FY2024 | G1: FY2025 | H1: FY2026E | I1: FY2027E | J1: FY2028E | K1: FY2029E | L1: FY2030E | M1: FY2031E
A2: Cash & Cash Equivalents | B2: 1180413 | C2: 1326462 | D2: 1307141 | E2: 2297675 | F2: 1533287 | G2: 2088117 | H2: ='QTR BS'!Z2 -> 4144447.2 | I2: ='QTR BS'!AD2 -> 6528188 | J2: ='QTR BS'!AH2 -> 9296980.6 | K2: ='QTR BS'!AL2 -> 12518614 | L2: ='QTR BS'!AP2 -> 16272810
A3: Short-Term Investments | B3: 881354 | C3: 1749727 | D3: 1362314 | E3: 955605 | F3: 0 | G3: 677084 | H3: ='QTR BS'!Z3 -> 677084 | I3: ='QTR BS'!AD3 -> 677084 | J3: ='QTR BS'!AH3 -> 677084 | K3: ='QTR BS'!AL3 -> 677084 | L3: ='QTR BS'!AP3 -> 677084
A4: Accounts Receivable | B4: 666012 | C4: 896658 | D4: 1016203 | E4: 1193964 | F4: 1221646 | G4: 1618072 | H4: ='QTR BS'!Z4 -> 1902935.5 | I4: ='QTR BS'!AD4 -> 2237949.6 | J4: ='QTR BS'!AH4 -> 2631943.3 | K4: ='QTR BS'!AL4 -> 3095300.1 | L4: ='QTR BS'!AP4 -> 3640231.4
A5: Inventories | B5: 333085 | C5: 593357 | D5: 935631 | E5: 971406 | F5: 737107 | G5: 799623 | H5: ='QTR BS'!Z5 -> 940397.59 | I5: ='QTR BS'!AD5 -> 1105955.7 | J5: ='QTR BS'!AH5 -> 1300660.6 | K5: ='QTR BS'!AL5 -> 1529643.4 | L5: ='QTR BS'!AP5 -> 1798939
A6: Prepaid Expenses | B6: 55358 | C6: 82668 | D6: 109823 | E6: 116195 | F6: 107262 | G6: 103551 | H6: ='QTR BS'!Z6 -> 121781.28 | I6: ='QTR BS'!AD6 -> 143221.02 | J6: ='QTR BS'!AH6 -> 168435.25 | K6: ='QTR BS'!AL6 -> 198088.48 | L6: ='QTR BS'!AP6 -> 232962.2
A7: Prepaid Income Taxes | B7: 24733 | C7: 33238 | D7: 33785 | E7: 54151 | F7: 42202 | G7: 74637 | H7: ='QTR BS'!Z7 -> 87776.934 | I7: ='QTR BS'!AD7 -> 103230.17 | J7: ='QTR BS'!AH7 -> 121403.96 | K7: ='QTR BS'!AL7 -> 142777.28 | L7: ='QTR BS'!AP7 -> 167913.39
A8: Total Current Assets | B8: =SUM(B2:B7) -> 3140955 | C8: =SUM(C2:C7) -> 4682110 | D8: =SUM(D2:D7) -> 4764897 | E8: =SUM(E2:E7) -> 5588996 | F8: =SUM(F2:F7) -> 3641504 | G8: =SUM(G2:G7) -> 5361084 | H8: =SUM(H2:H7) -> 7874422.5 | I8: =SUM(I2:I7) -> 10795629 | ... M8: =SUM(M2:M7) -> 0
A9: Long-Term Investments | B9: 44291 | C9: 99419 | D9: 61443 | E9: 76431 | F9: 0 | G9: 487329 | H9: ='QTR BS'!Z9 -> 573123.86 | I9: ='QTR BS'!AD9 -> 674023 | J9: ='QTR BS'!AH9 -> 792685.56 | K9: ='QTR BS'!AL9 -> 932238.81 | L9: ='QTR BS'!AP9 -> 1096360.6
A10: Net PP&E | B10: 314656 | C10: 313753 | D10: 516897 | E10: 890796 | F10: 1047024 | G10: 1081544 | H10: ='QTR BS'!Z10 -> 1062117.7 | I10: ='QTR BS'!AD10 -> 1039271.4 | J10: ='QTR BS'!AH10 -> 1012403 | K10: ='QTR BS'!AL10 -> 980804.43 | L10: ='QTR BS'!AP10 -> 943642.85
A11: Deferred Tax Assets | B11: 241650 | C11: 225221 | D11: 177039 | E11: 175003 | F11: 184260 | G11: 188646 | H11: ='QTR BS'!Z11 -> 173626 | I11: ='QTR BS'!AD11 -> 158606 | J11: ='QTR BS'!AH11 -> 143586 | K11: ='QTR BS'!AL11 -> 128566 | L11: ='QTR BS'!AP11 -> 113546
A12: Goodwill | B12: 1331643 | C12: 1331643 | D12: 1417941 | E12: 1417941 | F12: 1331643 | G12: 1331643 | H12: ='QTR BS'!Z12 -> 1331643 | I12: ='QTR BS'!AD12 -> 1331643 | J12: ='QTR BS'!AH12 -> 1331643 | K12: ='QTR BS'!AL12 -> 1331643 | L12: ='QTR BS'!AP12 -> 1331643
A13: Intangible Assets | B13: 1059046 | C13: 1072386 | D13: 1220410 | E13: 1427139 | F13: 1414252 | G13: 1379268 | H13: ='QTR BS'!Z13 -> 1379268 | I13: ='QTR BS'!AD13 -> 1379268 | J13: ='QTR BS'!AH13 -> 1379268 | K13: ='QTR BS'!AL13 -> 1379268 | L13: ='QTR BS'!AP13 -> 1379268
A14: Other Non-Current Assets | B14: 70475 | C14: 80252 | D14: 134478 | E14: 110216 | F14: 100406 | G14: 159431 | H14: ='QTR BS'!Z14 -> 187499.02 | I14: ='QTR BS'!AD14 -> 220508.45 | J14: ='QTR BS'!AH14 -> 259329.23 | K14: ='QTR BS'!AL14 -> 304984.45 | L14: ='QTR BS'!AP14 -> 358677.33
A15: Total Assets | B15: =B8+SUM(B9:B14) -> 6202716 | C15: =C8+SUM(C9:C14) -> 7804784 | D15: =D8+SUM(D9:D14) -> 8293105 | E15: =E8+SUM(E9:E14) -> 9686522 | F15: =F8+SUM(F9:F14) -> 7719089 | G15: =G8+SUM(G9:G14) -> 9988945 | H15: =H8+SUM(H9:H14) -> 12581700 | I15: =I8+SUM(I9:I14) -> 15598948 | ... M15: =M8+SUM(M9:M14) -> 0
A16: Accounts Payable | B16: 296800 | C16: 404263 | D16: 444265 | E16: 564379 | F16: 466775 | G16: 565974 | H16: ='QTR BS'!Z16 -> 665614.4 | I16: ='QTR BS'!AD16 -> 782796.62 | J16: ='QTR BS'!AH16 -> 920608.91 | K16: ='QTR BS'!AL16 -> 1082683.2 | L16: ='QTR BS'!AP16 -> 1273290.9
A17: Accrued Expenses | B17: 142653 | C17: 210964 | D17: 172991 | E17: 183988 | F17: 220764 | G17: 306085 | H17: ='QTR BS'!Z17 -> 359971.63 | I17: ='QTR BS'!AD17 -> 423345.07 | J17: ='QTR BS'!AH17 -> 497875.48 | K17: ='QTR BS'!AL17 -> 585527.06 | L17: ='QTR BS'!AP17 -> 688609.8
A18: Accrued Promotional Allowance | B18: 186658 | C18: 211461 | D18: 255631 | E18: 269061 | F18: 267711 | G18: 384070 | H18: ='QTR BS'!Z18 -> 451685.99 | I18: ='QTR BS'!AD18 -> 531205.85 | J18: ='QTR BS'!AH18 -> 624725.28 | K18: ='QTR BS'!AL18 -> 734708.91 | L18: ='QTR BS'!AP18 -> 864055.3
A19: Deferred Revenue - Current | B19: 45429 | C19: 42530 | D19: 43311 | E19: 41914 | F19: 45809 | G19: 45323 | H19: ='QTR BS'!Z19 -> 53302.169 | I19: ='QTR BS'!AD19 -> 62686.08 | J19: ='QTR BS'!AH19 -> 73722.04 | K19: ='QTR BS'!AL19 -> 86700.893 | L19: ='QTR BS'!AP19 -> 101964.69
A20: Accrued Compensation | B20: 55015 | C20: 65459 | D20: 72463 | E20: 87392 | F20: 92454 | G20: 114023 | H20: ='QTR BS'!Z20 -> 134096.89 | I20: ='QTR BS'!AD20 -> 157704.8 | J20: ='QTR BS'!AH20 -> 185468.93 | K20: ='QTR BS'!AL20 -> 218120.95 | L20: ='QTR BS'!AP20 -> 256521.41
A21: Income Taxes Payable | B21: 23433 | C21: 30399 | D21: 13317 | E21: 14955 | F21: 4006 | G21: 32305 | H21: ='QTR BS'!Z21 -> 37992.334 | I21: ='QTR BS'!AD21 -> 44680.93 | J21: ='QTR BS'!AH21 -> 52547.062 | K21: ='QTR BS'!AL21 -> 61798.035 | L21: ='QTR BS'!AP21 -> 72677.654
A22: Total Current Liabilities | B22: =SUM(B16:B21) -> 749988 | C22: =SUM(C16:C21) -> 965076 | D22: =SUM(D16:D21) -> 1001978 | E22: =SUM(E16:E21) -> 1161689 | F22: =SUM(F16:F21) -> 1097519 | G22: =SUM(G16:G21) -> 1447780 | H22: =SUM(H16:H21) -> 1702663.4 | I22: =SUM(I16:I21) -> 2002419.4 | ... M22: =SUM(M16:M21) -> 0
A23: Deferred Revenue - Non-Current | B23: 264436 | C23: 243249 | D23: 223800 | E23: 204251 | F23: 179008 | G23: 159991 | H23: ='QTR BS'!Z23 -> 188157.61 | I23: ='QTR BS'!AD23 -> 221282.98 | J23: ='QTR BS'!AH23 -> 260240.12 | K23: ='QTR BS'!AL23 -> 306055.7 | L23: ='QTR BS'!AP23 -> 359937.18
A24: Other Non-Current Liabilities | B24: 27432 | C24: 29508 | D24: 42286 | E24: 91838 | F24: 110893 | G24: 127066 | H24: ='QTR BS'!Z25 -> 149436.12 | I24: ='QTR BS'!AD25 -> 175744.53 | J24: ='QTR BS'!AH25 -> 206684.57 | K24: ='QTR BS'!AL25 -> 243071.64 | L24: ='QTR BS'!AP25 -> 285864.69
A25: Long-Term Debt | B25: 0 | C25: 0 | D25: 0 | E25: 0 | F25: 373951 | G25: 0 | H25: ='QTR BS'!Z26 -> 0 | I25: ='QTR BS'!AD26 -> 0 | J25: ='QTR BS'!AH26 -> 0 | K25: ='QTR BS'!AL26 -> 0 | L25: ='QTR BS'!AP26 -> 0
A26: Total Liabilities | B26: =B22+SUM(B23:B25) -> 1041856 | C26: =C22+SUM(C23:C25) -> 1237833 | D26: =D22+SUM(D23:D25) -> 1268064 | E26: =E22+SUM(E23:E25) -> 1457778 | F26: =F22+SUM(F23:F25) -> 1761371 | G26: =G22+SUM(G23:G25) -> 1734837 | H26: =H22+SUM(H23:H25) -> 2040257.1 | I26: =I22+SUM(I23:I25) -> 2399446.9 | ... M26: =M22+SUM(M23:M25) -> 0
A27: Common Stock | B27: 3193 | C27: 3200 | D27: 3209 | E27: 5613 | F27: 5632 | G27: 5665 | H27: ='QTR BS'!Z28 -> 5665 | I27: ='QTR BS'!AD28 -> 5665 | J27: ='QTR BS'!AH28 -> 5665 | K27: ='QTR BS'!AL28 -> 5665 | L27: ='QTR BS'!AP28 -> 5665
A28: Additional Paid-in Capital | B28: 4537982 | C28: 4652620 | D28: 4780013 | E28: 4975115 | F28: 5144922 | G28: 5430847 | H28: ='QTR BS'!Z29 -> 5609468.9 | I28: ='QTR BS'!AD29 -> 5819537.3 | J28: ='QTR BS'!AH29 -> 6066588.6 | K28: ='QTR BS'!AL29 -> 6357133.5 | L28: ='QTR BS'!AP29 -> 6698829.3
A29: Retained Earnings (Accumulated Deficit) | B29: 6432074 | C29: 7809549 | D29: 9001173 | E29: 5939736 | F29: 7448784 | G29: 9354216 | H29: ='QTR BS'!Z30 -> 11398608 | I29: ='QTR BS'!AD30 -> 13788639 | J29: ='QTR BS'!AH30 -> 16585159 | K29: ='QTR BS'!AL30 -> 19859731 | L29: ='QTR BS'!AP30 -> 23696515
A30: Accumulated Other Comprehensive Income (Loss) | B30: 3034 | C30: -69165 | D30: -159073 | E30: -125337 | F30: -269487 | G30: -60841 | H30: ='QTR BS'!Z31 -> 39615 | I30: ='QTR BS'!AD31 -> 140071 | J30: ='QTR BS'!AH31 -> 240527 | K30: ='QTR BS'!AL31 -> 340983 | L30: ='QTR BS'!AP31 -> 441439
A31: Treasury Stock | B31: -5815423 | C31: -5829253 | D31: -6600281 | E31: -2566383 | F31: -6372133 | G31: -6475779 | H31: ='QTR BS'!Z32 -> -6475779 | I31: ='QTR BS'!AD32 -> -6475779 | J31: ='QTR BS'!AH32 -> -6475779 | K31: ='QTR BS'!AL32 -> -6475779 | L31: ='QTR BS'!AP32 -> -6475779
A32: Total Stockholders' Equity | B32: =SUM(B27:B31) -> 5160860 | C32: =SUM(C27:C31) -> 6566951 | D32: =SUM(D27:D31) -> 7025041 | E32: =SUM(E27:E31) -> 8228744 | F32: =SUM(F27:F31) -> 5957718 | G32: =SUM(G27:G31) -> 8254108 | H32: =SUM(H27:H31) -> 10577578 | I32: =SUM(I27:I31) -> 13278134 | ... M32: =SUM(M27:M31) -> 0
A33: Total Liabilities, Mezzanine & Stockholders' Equity | B33: =B26+B32 -> 6202716 | C33: =C26+C32 -> 7804784 | D33: =D26+D32 -> 8293105 | E33: =E26+E32 -> 9686522 | F33: =F26+F32 -> 7719089 | G33: =G26+G32 -> 9988945 | H33: =H26+H32 -> 12617835 | I33: =I26+I32 -> 15677581 | ... M33: =M26+M32 -> 0

Sheet CASH FLOW
B1: FY2019 | C1: FY2020 | D1: FY2021 | E1: FY2022 | F1: FY2023 | G1: FY2024 | H1: FY2025 | I1: FY2026E | J1: FY2027E | K1: FY2028E | L1: FY2029E | M1: FY2030E | N1: FY2031E
A2: Net Income (Loss) | B2: 1107835 | C2: 1409594 | D2: 1377475 | E2: 1191624 | F2: 1630988 | G2: 1509048 | H2: 1905432 | I2: ='QTR CF'!Z2+'QTR CF'!AA2+'QTR CF'!AB2+'QTR CF'!AC2 -> 2044392.3 | J2: ='QTR CF'!AD2+'QTR CF'!AE2+'QTR CF'!AF2+'QTR CF'!AG2 -> 2390031 | K2: ='QTR CF'!AH2+'QTR CF'!AI2+'QTR CF'!AJ2+'QTR CF'!AK2 -> 2796519.8 | L2: ='QTR CF'!AL2+'QTR CF'!AM2+'QTR CF'!AN2+'QTR CF'!AO2 -> 3274571.4 | M2: ='QTR CF'!AP2+'QTR CF'!AQ2+'QTR CF'!AR2+'QTR CF'!AS2 -> 3836784.6
A3: Depreciation & Amortization | B3: 60727 | C3: 57030 | D3: 50155 | E3: 61241 | F3: 68898 | G3: 80434 | H3: 114441 | I3: ='QTR CF'!Z3+'QTR CF'!AA3+'QTR CF'!AB3+'QTR CF'!AC3 -> 148388.48 | J3: ='QTR CF'!AD3+'QTR CF'!AE3+'QTR CF'!AF3+'QTR CF'!AG3 -> 174512.45 | K3: ='QTR CF'!AH3+'QTR CF'!AI3+'QTR CF'!AJ3+'QTR CF'!AK3 -> 205235.58 | L3: ='QTR CF'!AL3+'QTR CF'!AM3+'QTR CF'!AN3+'QTR CF'!AO3 -> 241367.55 | M3: ='QTR CF'!AP3+'QTR CF'!AQ3+'QTR CF'!AR3+'QTR CF'!AS3 -> 283860.6
A4: Non-Cash Lease Expense | B4: 4087 | C4: 3943 | D4: 4107 | E4: 7337 | F4: 9043 | G4: 13521 | H4: 15398 | I4: ='QTR CF'!Z4+'QTR CF'!AA4+'QTR CF'!AB4+'QTR CF'!AC4 -> 0 | J4: ='QTR CF'!AD4+'QTR CF'!AE4+'QTR CF'!AF4+'QTR CF'!AG4 -> 0 | K4: ='QTR CF'!AH4+'QTR CF'!AI4+'QTR CF'!AJ4+'QTR CF'!AK4 -> 0 | L4: ='QTR CF'!AL4+'QTR CF'!AM4+'QTR CF'!AN4+'QTR CF'!AO4 -> 0 | M4: ='QTR CF'!AP4+'QTR CF'!AQ4+'QTR CF'!AR4+'QTR CF'!AS4 -> 0
A5: Gain (Loss) on Disposal of PP&E | B5: -252 | C5: -350 | D5: -1013 | E5: -185 | F5: 166 | G5: 3328 | H5: 2781 | I5: ='QTR CF'!Z5+'QTR CF'!AA5+'QTR CF'!AB5+'QTR CF'!AC5 -> 0 | J5: ='QTR CF'!AD5+'QTR CF'!AE5+'QTR CF'!AF5+'QTR CF'!AG5 -> 0 | K5: ='QTR CF'!AH5+'QTR CF'!AI5+'QTR CF'!AJ5+'QTR CF'!AK5 -> 0 | L5: ='QTR CF'!AL5+'QTR CF'!AM5+'QTR CF'!AN5+'QTR CF'!AO5 -> 0 | M5: ='QTR CF'!AP5+'QTR CF'!AQ5+'QTR CF'!AR5+'QTR CF'!AS5 -> 0
A6: Gain on Bang Transaction | B6: 0 | C6: 0 | D6: 0 | E6: 0 | F6: -45382 | G6: 0 | H6: 0 | I6: ='QTR CF'!Z6+'QTR CF'!AA6+'QTR CF'!AB6+'QTR CF'!AC6 -> 0 | J6: ='QTR CF'!AD6+'QTR CF'!AE6+'QTR CF'!AF6+'QTR CF'!AG6 -> 0 | K6: ='QTR CF'!AH6+'QTR CF'!AI6+'QTR CF'!AJ6+'QTR CF'!AK6 -> 0 | L6: ='QTR CF'!AL6+'QTR CF'!AM6+'QTR CF'!AN6+'QTR CF'!AO6 -> 0 | M6: ='QTR CF'!AP6+'QTR CF'!AQ6+'QTR CF'!AR6+'QTR CF'!AS6 -> 0
A7: Impairment of Intangibles | B7: 0 | C7: 8700 | D7: 0 | E7: 2200 | F7: 38700 | G7: 127098 | H7: 38411 | I7: ='QTR CF'!Z7+'QTR CF'!AA7+'QTR CF'!AB7+'QTR CF'!AC7 -> 0 | J7: ='QTR CF'!AD7+'QTR CF'!AE7+'QTR CF'!AF7+'QTR CF'!AG7 -> 0 | K7: ='QTR CF'!AH7+'QTR CF'!AI7+'QTR CF'!AJ7+'QTR CF'!AK7 -> 0 | L7: ='QTR CF'!AL7+'QTR CF'!AM7+'QTR CF'!AN7+'QTR CF'!AO7 -> 0 | M7: ='QTR CF'!AP7+'QTR CF'!AQ7+'QTR CF'!AR7+'QTR CF'!AS7 -> 0
A8: Impairment of Long-Lived Assets (PP&E) | B8: 0 | C8: 0 | D8: 0 | E8: 0 | F8: 4336 | G8: 8184 | H8: 12029 | I8: ='QTR CF'!Z8+'QTR CF'!AA8+'QTR CF'!AB8+'QTR CF'!AC8 -> 0 | J8: ='QTR CF'!AD8+'QTR CF'!AE8+'QTR CF'!AF8+'QTR CF'!AG8 -> 0 | K8: ='QTR CF'!AH8+'QTR CF'!AI8+'QTR CF'!AJ8+'QTR CF'!AK8 -> 0 | L8: ='QTR CF'!AL8+'QTR CF'!AM8+'QTR CF'!AN8+'QTR CF'!AO8 -> 0 | M8: ='QTR CF'!AP8+'QTR CF'!AQ8+'QTR CF'!AR8+'QTR CF'!AS8 -> 0
A9: Stock-Based Compensation | B9: 63356 | C9: 70289 | D9: 70483 | E9: 64109 | F9: 68836 | G9: 90985 | H9: 125687 | I9: ='QTR CF'!Z9+'QTR CF'!AA9+'QTR CF'!AB9+'QTR CF'!AC9 -> 178621.87 | J9: ='QTR CF'!AD9+'QTR CF'!AE9+'QTR CF'!AF9+'QTR CF'!AG9 -> 210068.46 | K9: ='QTR CF'!AH9+'QTR CF'!AI9+'QTR CF'!AJ9+'QTR CF'!AK9 -> 247051.27 | L9: ='QTR CF'!AL9+'QTR CF'!AM9+'QTR CF'!AN9+'QTR CF'!AO9 -> 290544.94 | M9: ='QTR CF'!AP9+'QTR CF'!AQ9+'QTR CF'!AR9+'QTR CF'!AS9 -> 341695.73
A10: (Benefit) Provision for Deferred Income Taxes | B10: 1263 | C10: -156873 | D10: 16429 | E10: 48182 | F10: 2040 | G10: -11705 | H10: 4210 | I10: ='QTR CF'!Z10+'QTR CF'!AA10+'QTR CF'!AB10+'QTR CF'!AC10 -> 15020 | J10: ='QTR CF'!AD10+'QTR CF'!AE10+'QTR CF'!AF10+'QTR CF'!AG10 -> 15020 | K10: ='QTR CF'!AH10+'QTR CF'!AI10+'QTR CF'!AJ10+'QTR CF'!AK10 -> 15020 | L10: ='QTR CF'!AL10+'QTR CF'!AM10+'QTR CF'!AN10+'QTR CF'!AO10 -> 15020 | M10: ='QTR CF'!AP10+'QTR CF'!AQ10+'QTR CF'!AR10+'QTR CF'!AS10 -> 15020
A11: Accounts Receivable | B11: -59941 | C11: -119672 | D11: -254228 | E11: -128981 | F11: -163158 | G11: -93915 | H11: -300600 | I11: ='QTR CF'!Z11+'QTR CF'!AA11+'QTR CF'!AB11+'QTR CF'!AC11 -> -284863.52 | J11: ='QTR CF'!AD11+'QTR CF'!AE11+'QTR CF'!AF11+'QTR CF'!AG11 -> -335014.09 | K11: ='QTR CF'!AH11+'QTR CF'!AI11+'QTR CF'!AJ11+'QTR CF'!AK11 -> -393993.72 | L11: ='QTR CF'!AL11+'QTR CF'!AM11+'QTR CF'!AN11+'QTR CF'!AO11 -> -463356.79 | M11: ='QTR CF'!AP11+'QTR CF'!AQ11+'QTR CF'!AR11+'QTR CF'!AS11 -> -544931.32
A12: Inventories | B12: -85222 | C12: 30304 | D12: -277793 | E12: -347712 | F12: 7898 | G12: 211503 | H12: -34918 | I12: ='QTR CF'!Z13+'QTR CF'!AA13+'QTR CF'!AB13+'QTR CF'!AC13 -> -140774.59 | J12: ='QTR CF'!AD13+'QTR CF'!AE13+'QTR CF'!AF13+'QTR CF'!AG13 -> -165558.13 | K12: ='QTR CF'!AH13+'QTR CF'!AI13+'QTR CF'!AJ13+'QTR CF'!AK13 -> -194704.84 | L12: ='QTR CF'!AL13+'QTR CF'!AM13+'QTR CF'!AN13+'QTR CF'!AO13 -> -228982.86 | M12: ='QTR CF'!AP13+'QTR CF'!AQ13+'QTR CF'!AR13+'QTR CF'!AS13 -> -269295.56
A13: Prepaid Expenses | B13: -13774 | C13: 1024 | D13: -29341 | E13: -38268 | F13: -10215 | G13: 8959 | H13: -39307 | I13: ='QTR CF'!Z14+'QTR CF'!AA14+'QTR CF'!AB14+'QTR CF'!AC14 -> -18230.278 | J13: ='QTR CF'!AD14+'QTR CF'!AE14+'QTR CF'!AF14+'QTR CF'!AG14 -> -21439.741 | K13: ='QTR CF'!AH14+'QTR CF'!AI14+'QTR CF'!AJ14+'QTR CF'!AK14 -> -25214.233 | L13: ='QTR CF'!AL14+'QTR CF'!AM14+'QTR CF'!AN14+'QTR CF'!AO14 -> -29653.229 | M13: ='QTR CF'!AP14+'QTR CF'!AQ14+'QTR CF'!AR14+'QTR CF'!AS14 -> -34873.716
A14: Change in Prepaid Income Taxes | B14: 9481 | C14: 5516 | D14: -10919 | E14: -4439 | F14: -18833 | G14: 3062 | H14: -21094 | I14: ='QTR CF'!Z15+'QTR CF'!AA15+'QTR CF'!AB15+'QTR CF'!AC15 -> -13139.934 | J14: ='QTR CF'!AD15+'QTR CF'!AE15+'QTR CF'!AF15+'QTR CF'!AG15 -> -15453.235 | K14: ='QTR CF'!AH15+'QTR CF'!AI15+'QTR CF'!AJ15+'QTR CF'!AK15 -> -18173.795 | L14: ='QTR CF'!AL15+'QTR CF'!AM15+'QTR CF'!AN15+'QTR CF'!AO15 -> -21373.314 | M14: ='QTR CF'!AP15+'QTR CF'!AQ15+'QTR CF'!AR15+'QTR CF'!AS15 -> -25136.112
A15: Accounts Payable | B15: 28832 | C15: 18696 | D15: 114297 | E15: 49765 | F15: 112786 | G15: -61491 | H15: 78460 | I15: ='QTR CF'!Z16+'QTR CF'!AA16+'QTR CF'!AB16+'QTR CF'!AC16 -> 99640.404 | J15: ='QTR CF'!AD16+'QTR CF'!AE16+'QTR CF'!AF16+'QTR CF'!AG16 -> 117182.22 | K15: ='QTR CF'!AH16+'QTR CF'!AI16+'QTR CF'!AJ16+'QTR CF'!AK16 -> 137812.29 | L15: ='QTR CF'!AL16+'QTR CF'!AM16+'QTR CF'!AN16+'QTR CF'!AO16 -> 162074.31 | M15: ='QTR CF'!AP16+'QTR CF'!AQ16+'QTR CF'!AR16+'QTR CF'!AS16 -> 190607.68
A16: Accrued Expenses | B16: -14018 | C16: 26113 | D16: 71586 | E16: -30419 | F16: -10393 | G16: 18371 | H16: 81341 | I16: ='QTR CF'!Z17+'QTR CF'!AA17+'QTR CF'!AB17+'QTR CF'!AC17 -> 53886.633 | J16: ='QTR CF'!AD17+'QTR CF'!AE17+'QTR CF'!AF17+'QTR CF'!AG17 -> 63373.439 | K16: ='QTR CF'!AH17+'QTR CF'!AI17+'QTR CF'!AJ17+'QTR CF'!AK17 -> 74530.41 | L16: ='QTR CF'!AL17+'QTR CF'!AM17+'QTR CF'!AN17+'QTR CF'!AO17 -> 87651.578 | M16: ='QTR CF'!AP17+'QTR CF'!AQ17+'QTR CF'!AR17+'QTR CF'!AS17 -> 103082.74
A17: Accrued Promotional Allowance | B17: 21943 | C17: 13762 | D17: 31498 | E17: 50821 | F17: 8418 | G17: 9736 | H17: 98266 | I17: ='QTR CF'!Z18+'QTR CF'!AA18+'QTR CF'!AB18+'QTR CF'!AC18 -> 67615.986 | J17: ='QTR CF'!AD18+'QTR CF'!AE18+'QTR CF'!AF18+'QTR CF'!AG18 -> 79519.862 | K17: ='QTR CF'!AH18+'QTR CF'!AI18+'QTR CF'!AJ18+'QTR CF'!AK18 -> 93519.429 | L17: ='QTR CF'!AL18+'QTR CF'!AM18+'QTR CF'!AN18+'QTR CF'!AO18 -> 109983.64 | M17: ='QTR CF'!AP18+'QTR CF'!AQ18+'QTR CF'!AR18+'QTR CF'!AS18 -> 129346.39
A18: Change in Accrued Compensation | B18: 7228 | C18: 7501 | D18: 7950 | E18: 3729 | F18: 13398 | G18: 5947 | H18: 17801 | I18: ='QTR CF'!Z20+'QTR CF'!AA20+'QTR CF'!AB20+'QTR CF'!AC20 -> 20073.886 | J18: ='QTR CF'!AD20+'QTR CF'!AE20+'QTR CF'!AF20+'QTR CF'!AG20 -> 23607.918 | K18: ='QTR CF'!AH20+'QTR CF'!AI20+'QTR CF'!AJ20+'QTR CF'!AK20 -> 27764.121 | L18: ='QTR CF'!AL20+'QTR CF'!AM20+'QTR CF'!AN20+'QTR CF'!AO20 -> 32652.028 | M18: ='QTR CF'!AP20+'QTR CF'!AQ20+'QTR CF'!AR20+'QTR CF'!AS20 -> 38400.456
A19: Other Current Liabilities | B19: 8105 | C19: 10422 | D19: 7221 | E19: -16860 | F19: 1748 | G19: 9438 | H19: 27779 | I19: ='QTR CF'!Z21+'QTR CF'!AA21+'QTR CF'!AB21+'QTR CF'!AC21 -> 0 | J19: ='QTR CF'!AD21+'QTR CF'!AE21+'QTR CF'!AF21+'QTR CF'!AG21 -> 0 | K19: ='QTR CF'!AH21+'QTR CF'!AI21+'QTR CF'!AJ21+'QTR CF'!AK21 -> 0 | L19: ='QTR CF'!AL21+'QTR CF'!AM21+'QTR CF'!AN21+'QTR CF'!AO21 -> 0 | M19: ='QTR CF'!AP21+'QTR CF'!AQ21+'QTR CF'!AR21+'QTR CF'!AS21 -> 0
A20: Net Change in Other Working Capital | B20: -1030 | C20: -356 | D20: 492 | E20: -4540 | F20: 22951 | G20: 13390 | H20: -4935 | I20: ='QTR CF'!Z22+'QTR CF'!AA22+'QTR CF'!AB22+'QTR CF'!AC22 -> 0 | J20: ='QTR CF'!AD22+'QTR CF'!AE22+'QTR CF'!AF22+'QTR CF'!AG22 -> 0 | K20: ='QTR CF'!AH22+'QTR CF'!AI22+'QTR CF'!AJ22+'QTR CF'!AK22 -> 0 | L20: ='QTR CF'!AL22+'QTR CF'!AM22+'QTR CF'!AN22+'QTR CF'!AO22 -> 0 | M20: ='QTR CF'!AP22+'QTR CF'!AQ22+'QTR CF'!AR22+'QTR CF'!AS22 -> 0
A21: Deferred Revenue | B21: -24858 | C21: -21480 | D21: -22658 | E21: -19905 | F21: -24472 | G21: -17360 | H21: -23005 | I21: ='QTR CF'!Z23+'QTR CF'!AA23+'QTR CF'!AB23+'QTR CF'!AC23 -> 0 | J21: ='QTR CF'!AD23+'QTR CF'!AE23+'QTR CF'!AF23+'QTR CF'!AG23 -> 0 | K21: ='QTR CF'!AH23+'QTR CF'!AI23+'QTR CF'!AJ23+'QTR CF'!AK23 -> 0 | L21: ='QTR CF'!AL23+'QTR CF'!AM23+'QTR CF'!AN23+'QTR CF'!AO23 -> 0 | M21: ='QTR CF'!AP23+'QTR CF'!AQ23+'QTR CF'!AR23+'QTR CF'!AS23 -> 0
A22: Cash Flow from Operations | B22: =SUM(B2:B21) -> 1113762 | C22: =SUM(C2:C21) -> 1364163 | D22: =SUM(D2:D21) -> 1155741 | E22: =SUM(E2:E21) -> 887699 | F22: =SUM(F2:F21) -> 1717753 | G22: =SUM(G2:G21) -> 1928533 | H22: =SUM(H2:H21) -> 2098177 | I22: =SUM(I2:I21) -> 2170631.3 | ... N22: =SUM(N2:N21) -> 0
A23: Net Change in Long-Term Investments | B23: -216300 | C23: -379785 | D23: -924544 | E23: 405288 | F23: 409019 | G23: 1035794 | H23: -1163150 | I23: ='QTR CF'!Z25+'QTR CF'!AA25+'QTR CF'!AB25+'QTR CF'!AC25 -> -85794.857 | J23: ='QTR CF'!AD25+'QTR CF'!AE25+'QTR CF'!AF25+'QTR CF'!AG25 -> -100899.15 | K23: ='QTR CF'!AH25+'QTR CF'!AI25+'QTR CF'!AJ25+'QTR CF'!AK25 -> -118662.56 | L23: ='QTR CF'!AL25+'QTR CF'!AM25+'QTR CF'!AN25+'QTR CF'!AO25 -> -139553.25 | M23: ='QTR CF'!AP25+'QTR CF'!AQ25+'QTR CF'!AR25+'QTR CF'!AS25 -> -164121.77
A24: Acquisition of CANarchy | B24: 0 | C24: 0 | D24: 0 | E24: -329472 | F24: 0 | G24: 0 | H24: 0 | I24: ='QTR CF'!Z26+'QTR CF'!AA26+'QTR CF'!AB26+'QTR CF'!AC26 -> 0 | J24: ='QTR CF'!AD26+'QTR CF'!AE26+'QTR CF'!AF26+'QTR CF'!AG26 -> 0 | K24: ='QTR CF'!AH26+'QTR CF'!AI26+'QTR CF'!AJ26+'QTR CF'!AK26 -> 0 | L24: ='QTR CF'!AL26+'QTR CF'!AM26+'QTR CF'!AN26+'QTR CF'!AO26 -> 0 | M24: ='QTR CF'!AP26+'QTR CF'!AQ26+'QTR CF'!AR26+'QTR CF'!AS26 -> 0
A25: Acquisition of Monster Brewing | B25: 0 | C25: 0 | D25: 0 | E25: 0 | F25: 0 | G25: 0 | H25: 0 | I25: ='QTR CF'!Z27+'QTR CF'!AA27+'QTR CF'!AB27+'QTR CF'!AC27 -> 0 | J25: ='QTR CF'!AD27+'QTR CF'!AE27+'QTR CF'!AF27+'QTR CF'!AG27 -> 0 | K25: ='QTR CF'!AH27+'QTR CF'!AI27+'QTR CF'!AJ27+'QTR CF'!AK27 -> 0 | L25: ='QTR CF'!AL27+'QTR CF'!AM27+'QTR CF'!AN27+'QTR CF'!AO27 -> 0 | M25: ='QTR CF'!AP27+'QTR CF'!AQ27+'QTR CF'!AR27+'QTR CF'!AS27 -> 0
A26: Acquisition of Bang Energy | B26: 0 | C26: 0 | D26: 0 | E26: 0 | F26: -363385 | G26: 0 | H26: 0 | I26: ='QTR CF'!Z28+'QTR CF'!AA28+'QTR CF'!AB28+'QTR CF'!AC28 -> 0 | J26: ='QTR CF'!AD28+'QTR CF'!AE28+'QTR CF'!AF28+'QTR CF'!AG28 -> 0 | K26: ='QTR CF'!AH28+'QTR CF'!AI28+'QTR CF'!AJ28+'QTR CF'!AK28 -> 0 | L26: ='QTR CF'!AL28+'QTR CF'!AM28+'QTR CF'!AN28+'QTR CF'!AO28 -> 0 | M26: ='QTR CF'!AP28+'QTR CF'!AQ28+'QTR CF'!AR28+'QTR CF'!AS28 -> 0
A27: Purchase of PP&E | B27: -101661 | C27: -48722 | D27: -43868 | E27: -188726 | F27: -221428 | G27: -264074 | H27: -132275 | I27: ='QTR CF'!Z29+'QTR CF'!AA29+'QTR CF'!AB29+'QTR CF'!AC29 -> -128962.21 | J27: ='QTR CF'!AD29+'QTR CF'!AE29+'QTR CF'!AF29+'QTR CF'!AG29 -> -151666.17 | K27: ='QTR CF'!AH29+'QTR CF'!AI29+'QTR CF'!AJ29+'QTR CF'!AK29 -> -178367.18 | L27: ='QTR CF'!AL29+'QTR CF'!AM29+'QTR CF'!AN29+'QTR CF'!AO29 -> -209768.94 | M27: ='QTR CF'!AP29+'QTR CF'!AQ29+'QTR CF'!AR29+'QTR CF'!AS29 -> -246699.01
A28: Proceeds from Sale of Assets | B28: 1239 | C28: 993 | D28: 1328 | E28: 1313 | F28: 2520 | G28: 2732 | H28: 4299 | I28: ='QTR CF'!Z30+'QTR CF'!AA30+'QTR CF'!AB30+'QTR CF'!AC30 -> 0 | J28: ='QTR CF'!AD30+'QTR CF'!AE30+'QTR CF'!AF30+'QTR CF'!AG30 -> 0 | K28: ='QTR CF'!AH30+'QTR CF'!AI30+'QTR CF'!AJ30+'QTR CF'!AK30 -> 0 | L28: ='QTR CF'!AL30+'QTR CF'!AM30+'QTR CF'!AN30+'QTR CF'!AO30 -> 0 | M28: ='QTR CF'!AP30+'QTR CF'!AQ30+'QTR CF'!AR30+'QTR CF'!AS30 -> 0
A29: Additions to Intangibles | B29: -8737 | C29: -18550 | D29: -13585 | E29: -23427 | F29: -13296 | G29: -42360 | H29: -25254 | I29: ='QTR CF'!Z31+'QTR CF'!AA31+'QTR CF'!AB31+'QTR CF'!AC31 -> 0 | J29: ='QTR CF'!AD31+'QTR CF'!AE31+'QTR CF'!AF31+'QTR CF'!AG31 -> 0 | K29: ='QTR CF'!AH31+'QTR CF'!AI31+'QTR CF'!AJ31+'QTR CF'!AK31 -> 0 | L29: ='QTR CF'!AL31+'QTR CF'!AM31+'QTR CF'!AN31+'QTR CF'!AO31 -> 0 | M29: ='QTR CF'!AP31+'QTR CF'!AQ31+'QTR CF'!AR31+'QTR CF'!AS31 -> 0
A30: Other Investing Activities | B30: -1265 | C30: -26423 | D30: -11353 | E30: -26343 | F30: -6825 | G30: 1635 | H30: -398 | I30: ='QTR CF'!Z32+'QTR CF'!AA32+'QTR CF'!AB32+'QTR CF'!AC32 -> 0 | J30: ='QTR CF'!AD32+'QTR CF'!AE32+'QTR CF'!AF32+'QTR CF'!AG32 -> 0 | K30: ='QTR CF'!AH32+'QTR CF'!AI32+'QTR CF'!AJ32+'QTR CF'!AK32 -> 0 | L30: ='QTR CF'!AL32+'QTR CF'!AM32+'QTR CF'!AN32+'QTR CF'!AO32 -> 0 | M30: ='QTR CF'!AP32+'QTR CF'!AQ32+'QTR CF'!AR32+'QTR CF'!AS32 -> 0
A31: Cash Flow from Investing | B31: =SUM(B23:B30) -> -326724 | C31: =SUM(C23:C30) -> -472487 | D31: =SUM(D23:D30) -> -992022 | E31: =SUM(E23:E30) -> -161367 | F31: =SUM(F23:F30) -> -193395 | G31: =SUM(G23:G30) -> 733727 | H31: =SUM(H23:H30) -> -1316778 | I31: =SUM(I23:I30) -> -214757.07 | ... N31: =SUM(N23:N30) -> 0
A32: Net Change in Other Short-Term Debt | B32: -13569 | C32: -3086 | D32: 2928 | E32: 75 | F32: -13914 | G32: -8223 | H32: -10344 | I32: ='QTR CF'!Z35+'QTR CF'!AA35+'QTR CF'!AB35+'QTR CF'!AC35 -> 0 | J32: ='QTR CF'!AD35+'QTR CF'!AE35+'QTR CF'!AF35+'QTR CF'!AG35 -> 0 | K32: ='QTR CF'!AH35+'QTR CF'!AI35+'QTR CF'!AJ35+'QTR CF'!AK35 -> 0 | L32: ='QTR CF'!AL35+'QTR CF'!AM35+'QTR CF'!AN35+'QTR CF'!AO35 -> 0 | M32: ='QTR CF'!AP35+'QTR CF'!AQ35+'QTR CF'!AR35+'QTR CF'!AS35 -> 0
A33: Proceeds from Issuance of Long-Term Debt | B33: 0 | C33: 0 | D33: 0 | E33: 0 | F33: 0 | G33: 750000 | H33: 0 | I33: ='QTR CF'!Z36+'QTR CF'!AA36+'QTR CF'!AB36+'QTR CF'!AC36 -> 0 | J33: ='QTR CF'!AD36+'QTR CF'!AE36+'QTR CF'!AF36+'QTR CF'!AG36 -> 0 | K33: ='QTR CF'!AH36+'QTR CF'!AI36+'QTR CF'!AJ36+'QTR CF'!AK36 -> 0 | L33: ='QTR CF'!AL36+'QTR CF'!AM36+'QTR CF'!AN36+'QTR CF'!AO36 -> 0 | M33: ='QTR CF'!AP36+'QTR CF'!AQ36+'QTR CF'!AR36+'QTR CF'!AS36 -> 0
A34: Repayments of Long-Term Debt | B34: 0 | C34: 0 | D34: 0 | E34: 0 | F34: 0 | G34: -375000 | H34: -375000 | I34: ='QTR CF'!Z38+'QTR CF'!AA38+'QTR CF'!AB38+'QTR CF'!AC38 -> 0 | J34: ='QTR CF'!AD38+'QTR CF'!AE38+'QTR CF'!AF38+'QTR CF'!AG38 -> 0 | K34: ='QTR CF'!AH38+'QTR CF'!AI38+'QTR CF'!AJ38+'QTR CF'!AK38 -> 0 | L34: ='QTR CF'!AL38+'QTR CF'!AM38+'QTR CF'!AN38+'QTR CF'!AO38 -> 0 | M34: ='QTR CF'!AP38+'QTR CF'!AQ38+'QTR CF'!AR38+'QTR CF'!AS38 -> 0
A35: Debt Issuance Fees | B35: 0 | C35: 0 | D35: 0 | E35: 0 | F35: 0 | G35: -2904 | H35: 0 | I35: ='QTR CF'!Z37+'QTR CF'!AA37+'QTR CF'!AB37+'QTR CF'!AC37 -> 0 | J35: ='QTR CF'!AD37+'QTR CF'!AE37+'QTR CF'!AF37+'QTR CF'!AG37 -> 0 | K35: ='QTR CF'!AH37+'QTR CF'!AI37+'QTR CF'!AJ37+'QTR CF'!AK37 -> 0 | L35: ='QTR CF'!AL37+'QTR CF'!AM37+'QTR CF'!AN37+'QTR CF'!AO37 -> 0 | M35: ='QTR CF'!AP37+'QTR CF'!AQ37+'QTR CF'!AR37+'QTR CF'!AS37 -> 0
A36: Proceeds from Issuance of Common Stock | B36: 92363 | C36: 72936 | D36: 45723 | E36: 64015 | F36: 130267 | G36: 78973 | H36: 164568 | I36: ='QTR CF'!Z39+'QTR CF'!AA39+'QTR CF'!AB39+'QTR CF'!AC39 -> 0 | J36: ='QTR CF'!AD39+'QTR CF'!AE39+'QTR CF'!AF39+'QTR CF'!AG39 -> 0 | K36: ='QTR CF'!AH39+'QTR CF'!AI39+'QTR CF'!AJ39+'QTR CF'!AK39 -> 0 | L36: ='QTR CF'!AL39+'QTR CF'!AM39+'QTR CF'!AN39+'QTR CF'!AO39 -> 0 | M36: ='QTR CF'!AP39+'QTR CF'!AQ39+'QTR CF'!AR39+'QTR CF'!AS39 -> 0
A37: Share Repurchases | B37: -707300 | C37: -595918 | D37: -13830 | E37: -771028 | F37: -658952 | G37: -3771875 | H37: -103646 | I37: ='QTR CF'!Z40+'QTR CF'!AA40+'QTR CF'!AB40+'QTR CF'!AC40 -> 0 | J37: ='QTR CF'!AD40+'QTR CF'!AE40+'QTR CF'!AF40+'QTR CF'!AG40 -> 0 | K37: ='QTR CF'!AH40+'QTR CF'!AI40+'QTR CF'!AJ40+'QTR CF'!AK40 -> 0 | L37: ='QTR CF'!AL40+'QTR CF'!AM40+'QTR CF'!AN40+'QTR CF'!AO40 -> 0 | M37: ='QTR CF'!AP40+'QTR CF'!AQ40+'QTR CF'!AR40+'QTR CF'!AS40 -> 0
A38: Cash Flow from Financing | B38: =SUM(B32:B37) -> -628506 | C38: =SUM(C32:C37) -> -526068 | D38: =SUM(D32:D37) -> 34821 | E38: =SUM(E32:E37) -> -706938 | F38: =SUM(F32:F37) -> -542599 | G38: =SUM(G32:G37) -> -3329029 | H38: =SUM(H32:H37) -> -324422 | I38: =SUM(I32:I37) -> 0 | ... N38: =SUM(N32:N37) -> 0
A39: FX Effect on Cash | B39: 1912 | C39: 16848 | D39: -52491 | E39: -38715 | F39: 8775 | G39: -97619 | H39: 97853 | I39: ='QTR CF'!Z42+'QTR CF'!AA42+'QTR CF'!AB42+'QTR CF'!AC42 -> 100456 | J39: ='QTR CF'!AD42+'QTR CF'!AE42+'QTR CF'!AF42+'QTR CF'!AG42 -> 100456 | K39: ='QTR CF'!AH42+'QTR CF'!AI42+'QTR CF'!AJ42+'QTR CF'!AK42 -> 100456 | L39: ='QTR CF'!AL42+'QTR CF'!AM42+'QTR CF'!AN42+'QTR CF'!AO42 -> 100456 | M39: ='QTR CF'!AP42+'QTR CF'!AQ42+'QTR CF'!AR42+'QTR CF'!AS42 -> 100456
A40: Net Change in Cash | B40: =B22+B31+B38+B39 -> 160444 | C40: =C22+C31+C38+C39 -> 382456 | D40: =D22+D31+D38+D39 -> 146049 | E40: =E22+E31+E38+E39 -> -19321 | F40: =F22+F31+F38+F39 -> 990534 | G40: =G22+G31+G38+G39 -> -764388 | H40: =H22+H31+H38+H39 -> 554830 | I40: =I22+I31+I38+I39 -> 2056330.2 | ... N40: =N22+N31+N38+N39 -> 0

Sheet YTD P&L
B1: Q1 FY2020 | C1: Q2 FY2020 | D1: Q3 FY2020 | E1: Q1 FY2021 | F1: Q2 FY2021 | G1: Q3 FY2021 | H1: Q1 FY2022 | I1: Q2 FY2022 | J1: Q3 FY2022 | K1: Q1 FY2023 | L1: Q2 FY2023 | M1: Q3 FY2023 | N1: Q1 FY2024 | O1: Q2 FY2024 | P1: Q3 FY2024 | Q1: Q1 FY2025 | R1: Q2 FY2025 | S1: Q3 FY2025
A2: Net Sales / Revenue | B2: 1062097 | C2: 2155993 | D2: 3402355 | E2: 1243816 | F2: 2705751 | G2: 4116308 | H2: 1518574 | I2: 3173833 | J2: 4798119 | K2: 1698930 | L2: 3553891 | M2: 5409919 | N2: 1899098 | O2: 3799695 | P2: 5680668 | Q2: 1854558 | R2: 3966150 | S2: 6163290
A3: COGS | B3: -424901 | C3: -859329 | D3: -1369160 | E3: -528881 | F3: -1153976 | G3: -1775375 | H3: -741907 | I3: -1617306 | J3: -2407867 | K3: -801081 | L3: -1681820 | M3: -2554086 | N3: -871969 | O3: -1753061 | P3: -2634235 | Q3: -806596 | R3: -1741775 | S3: -2714428
A4: Gross Profit (Loss) | B4: =B2+B3 -> 637196 | C4: =C2+C3 -> 1296664 | D4: =D2+D3 -> 2033195 | E4: =E2+E3 -> 714935 | F4: =F2+F3 -> 1551775 | G4: =G2+G3 -> 2340933 | H4: =H2+H3 -> 776667 | I4: =I2+I3 -> 1556527 | ... S4: =S2+S3 -> 3448862
A5: Operating Expenses | B5: -272208 | C5: -524412 | D5: -802343 | E5: -300789 | F5: -611652 | G5: -956346 | H5: -377178 | I5: -784088 | J5: -1199883 | K5: -412785 | L5: -863201 | M5: -1336437 | N5: -485138 | O5: -977480 | P5: -1497363 | Q5: -478217 | R5: -1023008 | S5: -1572142
A6: Income (Loss) from Operations | B6: =B4+B5 -> 364988 | C6: =C4+C5 -> 772252 | D6: =D4+D5 -> 1230852 | E6: =E4+E5 -> 414146 | F6: =F4+F5 -> 940123 | G6: =G4+G5 -> 1384587 | H6: =H4+H5 -> 399489 | I6: =I4+I5 -> 772439 | ... S6: =S4+S5 -> 1876720
A7: Other Income (Expense) | B7: 0 | C7: 0 | D7: 0 | E7: 0 | F7: 0 | G7: 0 | H7: 0 | I7: 0 | J7: 0 | K7: 0 | L7: 0 | M7: 0 | N7: 35754 | O7: 60131 | P7: 0 | Q7: 8272 | R7: 23337 | S7: 0
A8: Interest Income (Expense) | B8: 872 | C8: -923 | D8: -5491 | E8: -759 | F8: 111 | G8: -2179 | H8: -7300 | I8: -14080 | J8: -11932 | K8: 12496 | L8: 27653 | M8: 99010 | N8: 0 | O8: 0 | P8: 54311 | Q8: 0 | R8: 0 | S8: 37522
A9: Pre-Tax Income (Loss) | B9: =B6+SUM(B7:B8) -> 365860 | C9: =C6+SUM(C7:C8) -> 771329 | D9: =D6+SUM(D7:D8) -> 1225361 | E9: =E6+SUM(E7:E8) -> 413387 | F9: =F6+SUM(F7:F8) -> 940234 | G9: =G6+SUM(G7:G8) -> 1382408 | H9: =H6+SUM(H7:H8) -> 392189 | I9: =I6+SUM(I7:I8) -> 758359 | ... S9: =S6+SUM(S7:S8) -> 1914242
A10: Income Tax (Expense) Benefit | B10: -87025 | C10: -181125 | D10: -287503 | E10: -98193 | F10: -221278 | G10: -326247 | H10: -97986 | I10: -190796 | J10: -288487 | K10: -100116 | L10: -225208 | M10: -354397 | N10: -135696 | O10: -261867 | P10: -365044 | Q10: -135024 | R10: -292917 | S10: -458000
A11: Net Income (Loss) | B11: =B9+B10 -> 278835 | C11: =C9+C10 -> 590204 | D11: =D9+D10 -> 937858 | E11: =E9+E10 -> 315194 | F11: =F9+F10 -> 718956 | G11: =G9+G10 -> 1056161 | H11: =H9+H10 -> 294203 | I11: =I9+I10 -> 567563 | ... S11: =S9+S10 -> 1456242
A12: Basic Earnings (Loss) per Share | B12: 0.52 | C12: 1.11 | D12: 1.77 | E12: 0.6 | F12: 1.36 | G12: 2 | H12: 0.56 | I12: 1.07 | J12: 1.68 | K12: 0.38 | L12: 0.78 | M12: 1.21 | N12: 0.42 | O12: 0.84 | P12: 1.22 | Q12: 0.45 | R12: 0.96 | S12: 1.49
A13: Diluted Earnings (Loss) per Share | B13: 0.52 | C13: 1.1 | D13: 1.75 | E13: 0.59 | F13: 1.34 | G13: 1.97 | H13: 0.55 | I13: 1.06 | J13: 1.66 | K13: 0.38 | L13: 0.77 | M13: 1.19 | N13: 0.42 | O13: 0.83 | P13: 1.21 | Q13: 0.45 | R13: 0.95 | S13: 1.48
A14: Weighted Average Shares Outstanding (Basic) | B14: 536061000 | C14: 531486000 | D14: 530194000 | E14: 528195000 | F14: 528425000 | G14: 528618000 | H14: 529405000 | I14: 529009000 | J14: 528263000 | K14: 1044909000 | L14: 1045993000 | M14: 1046337000 | N14: 1041081000 | O14: 1035175000 | P14: 1015252000 | Q14: 973622000 | R14: 974691000 | S14: 975337000
A15: Weighted Average Shares Outstanding (Diluted) | B15: 540518000 | C15: 535897000 | D15: 535011000 | E15: 534982000 | F15: 535324000 | G15: 535554000 | H15: 535554000 | I15: 535209000 | J15: 534599000 | K15: 1059069000 | L15: 1059667000 | M15: 1059809000 | N15: 1051282000 | O15: 1044363000 | P15: 1023912000 | Q15: 981282000 | R15: 982748000 | S15: 983532000
A16: Net Income (Loss) Attributable to Common Shareholders | B16: =B11 -> 278835 | C16: =C11 -> 590204 | D16: =D11 -> 937858 | E16: =E11 -> 315194 | F16: =F11 -> 718956 | G16: =G11 -> 1056161 | H16: =H11 -> 294203 | I16: =I11 -> 567563 | ... S16: =S11 -> 1456242

Sheet YTD BS
B1: Q4 FY2020 | C1: Q1 FY2021 | D1: Q2 FY2021 | E1: Q3 FY2021 | F1: Q4 FY2021 | G1: Q1 FY2022 | H1: Q2 FY2022 | I1: Q3 FY2022 | J1: Q4 FY2022 | K1: Q1 FY2023 | L1: Q2 FY2023 | M1: Q3 FY2023 | N1: Q4 FY2023 | O1: Q1 FY2024 | P1: Q2 FY2024 | Q1: Q3 FY2024 | R1: Q4 FY2024 | S1: Q1 FY2025 | T1: Q2 FY2025 | U1: Q3 FY2025
A2: Cash & Cash Equivalents | B2: 1180413 | C2: 1178879 | D2: 1584239 | E2: 1712671 | F2: 1326462 | G2: 1014786 | H2: 1132039 | I2: 1303048 | J2: 1307141 | K2: 1672660 | L2: 1869774 | M2: 1773849 | N2: 2297675 | O2: 2576524 | P2: 1564734 | Q2: 1625339 | R2: 1533287 | S2: 1903419 | T2: 1926927 | U2: 2292939
A3: Short-Term Investments | B3: 881354 | C3: 980108 | D3: 968952 | E3: 1224066 | F3: 1749727 | G3: 1717648 | H3: 1337792 | I3: 1346781 | J3: 1362314 | K3: 1383028 | L3: 1417239 | M3: 1236752 | N3: 955605 | O3: 984201 | P3: 0 | Q3: 0 | R3: 0 | S3: 0 | T3: 145253 | U3: 286391
A4: Accounts Receivable | B4: 666012 | C4: 802509 | D4: 909169 | E4: 849157 | F4: 896658 | G4: 1039780 | H4: 1175587 | I4: 1051642 | J4: 1016203 | K4: 1190351 | L4: 1333004 | M4: 1231188 | N4: 1193964 | O4: 1370239 | P4: 1362398 | Q4: 1285397 | R4: 1221646 | S4: 1360233 | T4: 1522702 | U4: 1601216
A5: Inventories | B5: 333085 | C5: 368402 | D5: 382890 | E5: 471553 | F5: 593357 | G5: 821132 | H5: 885948 | I5: 862977 | J5: 935631 | K5: 906723 | L5: 846812 | M5: 883582 | N5: 971406 | O5: 939630 | P5: 834404 | Q5: 770338 | R5: 737107 | S5: 725129 | T5: 658167 | U5: 704586
A6: Prepaid Expenses | B6: 55358 | C6: 72803 | D6: 83086 | E6: 95607 | F6: 82668 | G6: 110327 | H6: 132273 | I6: 112294 | J6: 109823 | K6: 110958 | L6: 148750 | M6: 162676 | N6: 116195 | O6: 124580 | P6: 129303 | Q6: 124656 | R6: 107262 | S6: 112525 | T6: 137257 | U6: 142713
A7: Prepaid Income Taxes | B7: 24733 | C7: 31171 | D7: 22339 | E7: 30619 | F7: 33238 | G7: 39993 | H7: 32981 | I7: 19949 | J7: 33785 | K7: 30889 | L7: 38534 | M7: 23468 | N7: 54151 | O7: 40340 | P7: 63458 | Q7: 92028 | R7: 42202 | S7: 34113 | T7: 39034 | U7: 38372
A8: Total Current Assets | B8: =SUM(B2:B7) -> 3140955 | C8: =SUM(C2:C7) -> 3433872 | D8: =SUM(D2:D7) -> 3950675 | E8: =SUM(E2:E7) -> 4383673 | F8: =SUM(F2:F7) -> 4682110 | G8: =SUM(G2:G7) -> 4743666 | H8: =SUM(H2:H7) -> 4696620 | I8: =SUM(I2:I7) -> 4696691 | ... U8: =SUM(U2:U7) -> 5066217
A9: Long-Term Investments | B9: 44291 | C9: 63751 | D9: 91033 | E9: 28255 | F9: 99419 | G9: 65652 | H9: 64119 | I9: 72373 | J9: 61443 | K9: 41152 | L9: 62248 | M9: 52636 | N9: 76431 | O9: 8162 | P9: 0 | Q9: 0 | R9: 0 | S9: 0 | T9: 138058 | U9: 359174
A10: Net PP&E | B10: 314656 | C10: 312155 | D10: 309178 | E10: 309574 | F10: 313753 | G10: 407391 | H10: 464541 | I10: 485550 | J10: 516897 | K10: 545922 | L10: 576645 | M10: 731208 | N10: 890796 | O10: 923290 | P10: 960962 | Q10: 1006788 | R10: 1047024 | S10: 1064008 | T10: 1090898 | U10: 1110705
A11: Deferred Tax Assets | B11: 241650 | C11: 241650 | D11: 241297 | E11: 241297 | F11: 225221 | G11: 225221 | H11: 203287 | I11: 195511 | J11: 177039 | K11: 177039 | L11: 177039 | M11: 176724 | N11: 175003 | O11: 175271 | P11: 187269 | Q11: 183430 | R11: 184260 | S11: 184358 | T11: 184791 | U11: 185321
A12: Goodwill | B12: 1331643 | C12: 1331643 | D12: 1331643 | E12: 1331643 | F12: 1331643 | G12: 1411928 | H12: 1412941 | I12: 1412941 | J12: 1417941 | K12: 1417941 | L12: 1417941 | M12: 1417941 | N12: 1417941 | O12: 1417941 | P12: 1417941 | Q12: 1417941 | R12: 1331643 | S12: 1331643 | T12: 1331643 | U12: 1331643
A13: Intangible Assets | B13: 1059046 | C13: 1063092 | D13: 1058323 | E13: 1066083 | F13: 1072386 | G13: 1232113 | H13: 1223114 | I13: 1225826 | J13: 1220410 | K13: 1222598 | L13: 1224100 | M13: 1459447 | N13: 1427139 | O13: 1430762 | P13: 1433326 | Q13: 1442426 | R13: 1414252 | S13: 1415958 | T13: 1418827 | U13: 1419306
A14: Other Non-Current Assets | B14: 70475 | C14: 88203 | D14: 89394 | E14: 88883 | F14: 80252 | G14: 101488 | H14: 110390 | I14: 115913 | J14: 134478 | K14: 145101 | L14: 151252 | M14: 164867 | N14: 110216 | O14: 107126 | P14: 107109 | Q14: 104958 | R14: 100406 | S14: 95642 | T14: 136331 | U14: 138907
A15: Total Assets | B15: =B8+SUM(B9:B14) -> 6202716 | C15: =C8+SUM(C9:C14) -> 6534366 | D15: =D8+SUM(D9:D14) -> 7071543 | E15: =E8+SUM(E9:E14) -> 7449408 | F15: =F8+SUM(F9:F14) -> 7804784 | G15: =G8+SUM(G9:G14) -> 8187459 | H15: =H8+SUM(H9:H14) -> 8175012 | I15: =I8+SUM(I9:I14) -> 8204805 | ... U15: =U8+SUM(U9:U14) -> 9611273
A16: Accounts Payable | B16: 296800 | C16: 334076 | D16: 362900 | E16: 396229 | F16: 404263 | G16: 438256 | H16: 492858 | I16: 520198 | J16: 444265 | K16: 491249 | L16: 568613 | M16: 539892 | N16: 564379 | O16: 533729 | P16: 511137 | Q16: 549028 | R16: 466775 | S16: 486951 | T16: 489037 | U16: 683030
A17: Accrued Expenses | B17: 142653 | C17: 170954 | D17: 172498 | E17: 180719 | F17: 210964 | G17: 234111 | H17: 209154 | I17: 198692 | J17: 172991 | K17: 245932 | L17: 198656 | M17: 207727 | N17: 183988 | O17: 204679 | P17: 213905 | Q17: 259088 | R17: 220764 | S17: 262545 | T17: 258937 | U17: 325450
A18: Accrued Promotional Allowance | B18: 186658 | C18: 197380 | D18: 227414 | E18: 232394 | F18: 211461 | G18: 270785 | H18: 277618 | I18: 281650 | J18: 255631 | K18: 308094 | L18: 283647 | M18: 296577 | N18: 269061 | O18: 318895 | P18: 319757 | Q18: 301973 | R18: 267711 | S18: 304670 | T18: 360406 | U18: 392628
A19: Deferred Revenue - Current | B19: 45429 | C19: 45961 | D19: 46656 | E19: 45278 | F19: 42530 | G19: 42540 | H19: 44344 | I19: 42608 | J19: 43311 | K19: 44440 | L19: 42765 | M19: 40127 | N19: 41914 | O19: 43776 | P19: 44377 | Q19: 45627 | R19: 45809 | S19: 47542 | T19: 49279 | U19: 47158
A20: Accrued Compensation | B20: 55015 | C20: 30499 | D20: 46770 | E20: 54507 | F20: 65459 | G20: 37551 | H20: 53717 | I20: 61426 | J20: 72463 | K20: 42673 | L20: 56195 | M20: 76835 | N20: 87392 | O20: 52638 | P20: 60357 | Q20: 81787 | R20: 92454 | S20: 55812 | T20: 72838 | U20: 102131
A21: Income Taxes Payable | B21: 23433 | C21: 9991 | D21: 31289 | E21: 23113 | F21: 30399 | G21: 21118 | H21: 15917 | I21: 17143 | J21: 13317 | K21: 55123 | L21: 12704 | M21: 17644 | N21: 14955 | O21: 75111 | P21: 10990 | Q21: 7641 | R21: 4006 | S21: 67837 | T21: 28121 | U21: 40023
A22: Total Current Liabilities | B22: =SUM(B16:B21) -> 749988 | C22: =SUM(C16:C21) -> 788861 | D22: =SUM(D16:D21) -> 887527 | E22: =SUM(E16:E21) -> 932240 | F22: =SUM(F16:F21) -> 965076 | G22: =SUM(G16:G21) -> 1044361 | H22: =SUM(H16:H21) -> 1093608 | I22: =SUM(I16:I21) -> 1121717 | ... U22: =SUM(U16:U21) -> 1590420
A23: Deferred Revenue - Non-Current | B23: 264436 | C23: 257730 | D23: 252056 | E23: 245621 | F23: 243249 | G23: 238241 | H23: 232170 | I23: 226294 | J23: 223800 | K23: 219764 | L23: 215039 | M23: 209136 | N23: 204251 | O23: 198759 | P23: 192354 | Q23: 186135 | R23: 179008 | S23: 173921 | T23: 169763 | U23: 164701
A24: Deferred Tax Liability | B24: 0 | C24: 0 | D24: 0 | E24: 0 | F24: 0 | G24: 0 | H24: 0 | I24: 0 | J24: 0 | K24: 0 | L24: 0 | M24: 0 | N24: 0 | O24: 0 | P24: 28896 | Q24: 28896 | R24: 0 | S24: 0 | T24: 0 | U24: 0
A25: Other Non-Current Liabilities | B25: 27432 | C25: 28338 | D25: 26462 | E25: 26550 | F25: 29508 | G25: 38185 | H25: 40056 | I25: 41034 | J25: 42286 | K25: 41727 | L25: 44255 | M25: 53251 | N25: 91838 | O25: 92690 | P25: 64068 | Q25: 64884 | R25: 110893 | S25: 109252 | T25: 110203 | U25: 110992
A26: Long-Term Debt | B26: 0 | C26: 0 | D26: 0 | E26: 0 | F26: 0 | G26: 0 | H26: 0 | I26: 0 | J26: 0 | K26: 0 | L26: 0 | M26: 0 | N26: 0 | O26: 0 | P26: 748740 | Q26: 748842 | R26: 373951 | S26: 199059 | T26: 0 | U26: 0
A27: Total Liabilities | B27: =B22+SUM(B23:B26) -> 1041856 | C27: =C22+SUM(C23:C26) -> 1074929 | D27: =D22+SUM(D23:D26) -> 1166045 | E27: =E22+SUM(E23:E26) -> 1204411 | F27: =F22+SUM(F23:F26) -> 1237833 | G27: =G22+SUM(G23:G26) -> 1320787 | H27: =H22+SUM(H23:H26) -> 1365834 | I27: =I22+SUM(I23:I26) -> 1389045 | ... U27: =U22+SUM(U23:U26) -> 1866113
A28: Common Stock | B28: 3193 | C28: 3196 | D28: 3198 | E28: 3199 | F28: 3200 | G28: 3203 | H28: 3205 | I28: 3206 | J28: 6418 | K28: 5587 | L28: 5591 | M28: 5592 | N28: 5613 | O28: 5624 | P28: 5627 | Q28: 5628 | R28: 5632 | S28: 5643 | T28: 5650 | U28: 5655
A29: Additional Paid-in Capital | B29: 4537982 | C29: 4562689 | D29: 4597333 | E29: 4626299 | F29: 4652620 | G29: 4673302 | H29: 4707569 | I29: 4736141 | J29: 4776804 | K29: 4829301 | L29: 4869791 | M29: 4893289 | N29: 4975115 | O29: 5034948 | P29: 5068291 | Q29: 5105957 | R29: 5144922 | S29: 5213731 | T29: 5285157 | U29: 5343915
A30: Retained Earnings (Accumulated Deficit) | B30: 6432074 | C30: 6747268 | D30: 7151030 | E30: 7488235 | F30: 7809549 | G30: 8103752 | H30: 8377112 | I30: 8699499 | J30: 9001173 | K30: 4706192 | L30: 5120063 | M30: 5572757 | N30: 5939736 | O30: 6381785 | P30: 6807154 | Q30: 7178073 | R30: 7448784 | S30: 7891777 | T30: 8380571 | U30: 8905026
A31: Accumulated Other Comprehensive Income (Loss) | B31: 3034 | C31: -24874 | D31: -16822 | E31: -43495 | F31: -69165 | G31: -72145 | H31: -152957 | I31: -224455 | J31: -159073 | K31: -147911 | L31: -155725 | M31: -198033 | N31: -125337 | O31: -157940 | P31: -182304 | Q31: -137842 | R31: -269487 | S31: -202946 | T31: -91308 | U31: -93382
A32: Treasury Stock | B32: -5815423 | C32: -5828842 | D32: -5829241 | E32: -5829241 | F32: -5829253 | G32: -5841440 | H32: -6125751 | I32: -6398631 | J32: -6600281 | K32: -1997809 | L32: -1998256 | M32: -2400456 | N32: -2566383 | O32: -2686628 | P32: -5832445 | Q32: -6372416 | R32: -6372133 | S32: -6388766 | T32: -6388766 | U32: -6416054
A33: Total Stockholders' Equity | B33: =SUM(B28:B32) -> 5160860 | C33: =SUM(C28:C32) -> 5459437 | D33: =SUM(D28:D32) -> 5905498 | E33: =SUM(E28:E32) -> 6244997 | F33: =SUM(F28:F32) -> 6566951 | G33: =SUM(G28:G32) -> 6866672 | H33: =SUM(H28:H32) -> 6809178 | I33: =SUM(I28:I32) -> 6815760 | ... U33: =SUM(U28:U32) -> 7745160
A34: Total Liabilities, Mezzanine & Stockholders' Equity | B34: =B27+B33 -> 6202716 | C34: =C27+C33 -> 6534366 | D34: =D27+D33 -> 7071543 | E34: =E27+E33 -> 7449408 | F34: =F27+F33 -> 7804784 | G34: =G27+G33 -> 8187459 | H34: =H27+H33 -> 8175012 | I34: =I27+I33 -> 8204805 | ... U34: =U27+U33 -> 9611273

Sheet YTD CF
B1: Q1 FY2020 | C1: Q2 FY2020 | D1: Q3 FY2020 | E1: Q1 FY2021 | F1: Q2 FY2021 | G1: Q3 FY2021 | H1: Q1 FY2022 | I1: Q2 FY2022 | J1: Q3 FY2022 | K1: Q1 FY2023 | L1: Q2 FY2023 | M1: Q3 FY2023 | N1: Q1 FY2024 | O1: Q2 FY2024 | P1: Q3 FY2024 | Q1: Q1 FY2025 | R1: Q2 FY2025 | S1: Q3 FY2025
A2: Net Income (Loss) | B2: 278835 | C2: 590204 | D2: 937858 | E2: 315194 | F2: 718956 | G2: 1056161 | H2: 294203 | I2: 567563 | J2: 889950 | K2: 397444 | L2: 811315 | M2: 1264009 | N2: 442049 | O2: 867418 | P2: 1238337 | Q2: 442993 | R2: 931787 | S2: 1456242
A3: Depreciation & Amortization | B3: 16546 | C3: 32057 | D3: 45879 | E3: 13777 | F3: 27489 | G3: 40716 | H3: 14599 | I3: 30432 | J3: 46040 | K3: 16808 | L3: 32384 | M3: 50364 | N3: 20475 | O3: 39913 | P3: 59822 | Q3: 24848 | R3: 52405 | S3: 82023
A4: Non-Cash Lease Expense | B4: 0 | C4: 0 | D4: 0 | E4: 0 | F4: 0 | G4: 0 | H4: 1481 | I4: 3222 | J4: 5180 | K4: 2160 | L4: 2828 | M4: 6471 | N4: 3185 | O4: 6599 | P4: 9801 | Q4: 4014 | R4: 6966 | S4: 10266
A5: Gain (Loss) on Disposal of PP&E | B5: -58 | C5: -179 | D5: -210 | E5: -88 | F5: -822 | G5: -984 | H5: -6 | I5: -69 | J5: -253 | K5: -385 | L5: -767 | M5: -686 | N5: -177 | O5: 1849 | P5: 2070 | Q5: 324 | R5: -641 | S5: -916
A6: Gain on Bang Transaction | B6: 0 | C6: 0 | D6: 0 | E6: 0 | F6: 0 | G6: 0 | H6: 0 | I6: 0 | J6: 0 | K6: 0 | L6: 0 | M6: -45382 | N6: 0 | O6: 0 | P6: 0 | Q6: 0 | R6: 0 | S6: 0
A7: Impairment of Intangibles | B7: 3000 | C7: 4000 | D7: 7000 | E7: 0 | F7: 0 | G7: 0 | H7: 0 | I7: 0 | J7: 0 | K7: 0 | L7: 2800 | M7: 2800 | N7: 0 | O7: 0 | P7: 0 | Q7: 0 | R7: 0 | S7: 0
A8: Impairment of Long-Lived Assets (PP&E) | B8: 0 | C8: 0 | D8: 0 | E8: 0 | F8: 0 | G8: 0 | H8: 0 | I8: 0 | J8: 0 | K8: 0 | L8: 0 | M8: 0 | N8: 0 | O8: 6067 | P8: 6067 | Q8: 2279 | R8: 2279 | S8: 2279
A9: Stock-Based Compensation | B9: 17098 | C9: 33034 | D9: 53042 | E9: 18362 | F9: 35691 | G9: 52391 | H9: 16332 | I9: 32609 | J9: 49167 | K9: 16051 | L9: 34603 | M9: 52465 | N9: 22472 | O9: 41262 | P9: 68793 | Q9: 20727 | R9: 53854 | S9: 86664
A10: (Benefit) Provision for Deferred Income Taxes | B10: 0 | C10: 0 | D10: 0 | E10: 0 | F10: 353 | G10: 353 | H10: 0 | I10: 21934 | J10: 29710 | K10: 0 | L10: 0 | M10: 0 | N10: 9 | O10: -13294 | P10: -10242 | Q10: 135 | R10: 646 | S10: 455
A11: Accounts Receivable | B11: -147660 | C11: -231782 | D11: -201677 | E11: -147544 | F11: -239700 | G11: -199709 | H11: -134433 | I11: -289236 | J11: -202447 | K11: -167512 | L11: -317808 | M11: -218804 | N11: -195081 | O11: -197227 | P11: -106404 | Q11: -109557 | R11: -222239 | S11: -299139
A12: Distributor Receivables | B12: 176 | C12: 188 | D12: 341 | E12: 92 | F12: 160 | G12: 228 | H12: 0 | I12: 0 | J12: 0 | K12: 0 | L12: 0 | M12: 0 | N12: 0 | O12: 0 | P12: 0 | Q12: 0 | R12: 0 | S12: 0
A13: Inventories | B13: 1037 | C13: 14181 | D13: 39490 | E13: -39546 | F13: -52541 | G13: -149414 | H13: -208673 | I13: -299076 | J13: -297140 | K13: 35495 | L13: 93077 | M13: 69796 | N13: 22708 | O13: 123484 | P13: 197107 | Q13: 19594 | R13: 104633 | S13: 58387
... A23: Deferred Revenue | B23: -4273 | C23: -10383 | D23: -15236 | E23: -5250 | F23: -10922 | G23: -17784 | H23: -5915 | I23: -9101 | J23: -16060 | K23: -5046 | L23: -12361 | M23: -19320 | N23: -3036 | O23: -7731 | P23: -12652 | Q23: -4339 | R23: -8598 | S23: -15907
A24: Cash Flow from Operations | B24: =SUM(B2:B23) -> 191132 | C24: =SUM(C2:C23) -> 440458 | D24: =SUM(D2:D23) -> 949236 | E24: =SUM(E2:E23) -> 175473 | F24: =SUM(F2:F23) -> 586586 | G24: =SUM(G2:G23) -> 927982 | H24: =SUM(H2:H23) -> -351 | I24: =SUM(I2:I23) -> 130663 | ... S24: =SUM(S2:S23) -> 1718762
A25: Net Change in Long-Term Investments | B25: 298837 | C25: 293643 | D25: -53418 | E25: -114819 | F25: -134502 | G25: -326795 | H25: 62883 | I25: 445440 | J25: 430033 | K25: 3750 | L25: -53323 | M25: 140805 | N25: 39897 | O25: 1035794 | P25: 1035794 | Q25: 0 | R25: -283097 | S25: -597703
A26: Acquisition of CANarchy | B26: 0 | C26: 0 | D26: 0 | E26: 0 | F26: 0 | G26: 0 | H26: -330356 | I26: -329472 | J26: -329472 | K26: 0 | L26: 0 | M26: 0 | N26: 0 | O26: 0 | P26: 0 | Q26: 0 | R26: 0 | S26: 0
A27: Acquisition of Monster Brewing | B27: 0 | C27: 0 | D27: 0 | E27: 0 | F27: 0 | G27: 0 | H27: 0 | I27: 0 | J27: 0 | K27: 0 | L27: 0 | M27: 0 | N27: 0 | O27: 0 | P27: 0 | Q27: 0 | R27: 0 | S27: 0
A28: Acquisition of Bang Energy | B28: 0 | C28: 0 | D28: 0 | E28: 0 | F28: 0 | G28: 0 | H28: 0 | I28: 0 | J28: 0 | K28: 0 | L28: 0 | M28: -363385 | N28: 0 | O28: 0 | P28: 0 | Q28: 0 | R28: 0 | S28: 0
A29: Purchase of PP&E | B29: -11119 | C29: -29116 | D29: -42062 | E29: -8400 | F29: -15522 | G29: -28131 | H29: -21511 | I29: -99446 | J29: -136158 | K29: -40100 | L29: -82425 | M29: -110224 | N29: -66044 | O29: -125812 | P29: -172795 | Q29: -29056 | R29: -60460 | S29: -104101
A30: Proceeds from Sale of Assets | B30: 217 | C30: 590 | D30: 880 | E30: 231 | F30: 1024 | G30: 1246 | H30: 14 | I30: 372 | J30: 603 | K30: 564 | L30: 1035 | M30: 1753 | N30: 422 | O30: 1052 | P30: 2095 | Q30: 1147 | R30: 2334 | S30: 2744
A31: Additions to Intangibles | B31: -6811 | C31: -13085 | D31: -19686 | E31: -7239 | F31: -9926 | G31: -5211 | H31: -8419 | I31: -9894 | J31: -3578 | K31: -3952 | L31: -5926 | M31: -9110 | N31: -8612 | O31: -6364 | P31: -21473 | Q31: -5343 | R31: -15399 | S31: -19681
A32: Other Investing Activities | B32: -1148 | C32: -1338 | D32: -26228 | E32: -18856 | F32: -21236 | G32: -22809 | H32: -6241 | I32: -12738 | J32: -19171 | K32: -13028 | L32: -17570 | M32: -19862 | N32: -985 | O32: -1366 | P32: -603 | Q32: 2397 | R32: -1107 | S32: -507
A33: Cash Flow from Investing | B33: =SUM(B25:B32) -> 279976 | C33: =SUM(C25:C32) -> 250694 | D33: =SUM(D25:D32) -> -140514 | E33: =SUM(E25:E32) -> -149083 | F33: =SUM(F25:F32) -> -180162 | G33: =SUM(G25:G32) -> -381700 | H33: =SUM(H25:H32) -> -303630 | I33: =SUM(I25:I32) -> -5738 | ... S33: =SUM(S25:S32) -> -719248
A34: Repayments of Short-Term Debt | B34: 0 | C34: 0 | D34: 0 | E34: 0 | F34: 0 | G34: 0 | H34: 0 | I34: 0 | J34: 0 | K34: 0 | L34: 0 | M34: 0 | N34: 0 | O34: -5269 | P34: -6717 | Q34: 0 | R34: 0 | S34: 0
A35: Net Change in Other Short-Term Debt | B35: -733 | C35: -1680 | D35: -2500 | E35: 957 | F35: 3624 | G35: -1814 | H35: 3454 | I35: 4924 | J35: -719 | K35: -7271 | L35: -6661 | M35: -11273 | N35: -2896 | O35: 0 | P35: 0 | Q35: -2045 | R35: -5023 | S35: -8043
A36: Proceeds from Issuance of Long-Term Debt | B36: 0 | C36: 0 | D36: 0 | E36: 0 | F36: 0 | G36: 0 | H36: 0 | I36: 0 | J36: 0 | K36: 0 | L36: 0 | M36: 0 | N36: 0 | O36: 750000 | P36: 750000 | Q36: 0 | R36: 0 | S36: 0
A37: Debt Issuance Fees | B37: 0 | C37: 0 | D37: 0 | E37: 0 | F37: 0 | G37: 0 | H37: 0 | I37: 0 | J37: 0 | K37: 0 | L37: 0 | M37: 0 | N37: 0 | O37: -2776 | P37: -2904 | Q37: 0 | R37: 0 | S37: 0
A38: Repayments of Long-Term Debt | B38: 0 | C38: 0 | D38: 0 | E38: 0 | F38: 0 | G38: 0 | H38: 0 | I38: 0 | J38: 0 | K38: 0 | L38: 0 | M38: 0 | N38: 0 | O38: 0 | P38: 0 | Q38: -175000 | R38: -375000 | S38: -375000
A39: Proceeds from Issuance of Common Stock | B39: 13975 | C39: 43842 | D39: 65540 | E39: 6761 | F39: 24486 | G39: 37160 | H39: 4510 | I39: 22622 | J39: 34759 | K39: 36348 | L39: 59666 | M39: 65560 | N39: 38392 | O39: 52093 | P39: 62101 | Q39: 48093 | R39: 87684 | S39: 114363
A40: Share Repurchases | B40: -559210 | C40: -595770 | D40: -595918 | E40: -13419 | F40: -13818 | G40: -13818 | H40: -12187 | I40: -296499 | J40: -493315 | K40: -35126 | L40: -90825 | M40: -488080 | N40: -120245 | O40: -3234523 | P40: -3770184 | Q40: -16633 | R40: -16633 | S40: -43921
A41: Cash Flow from Financing | B41: =SUM(B34:B40) -> -545968 | C41: =SUM(C34:C40) -> -553608 | D41: =SUM(D34:D40) -> -532878 | E41: =SUM(E34:E40) -> -5701 | F41: =SUM(F34:F40) -> 14292 | G41: =SUM(G34:G40) -> 21528 | H41: =SUM(H34:H40) -> -4223 | I41: =SUM(I34:I40) -> -268953 | ... S41: =SUM(S34:S40) -> -312601
A42: FX Effect on Cash | B42: -21261 | C42: -14175 | D42: 929 | E42: -22223 | F42: -16890 | G42: -35552 | H42: -3472 | I42: -50395 | J42: -95582 | K42: -141 | L42: -4500 | M42: -22902 | N42: -13222 | O42: -44203 | P42: -14482 | Q42: 38972 | R42: 86725 | S42: 72739
A43: Net Change in Cash | B43: =B24+B33+B41+B42 -> -96121 | C43: =C24+C33+C41+C42 -> 123369 | D43: =D24+D33+D41+D42 -> 276773 | E43: =E24+E33+E41+E42 -> -1534 | F43: =F24+F33+F41+F42 -> 403826 | G43: =G24+G33+G41+G42 -> 532258 | H43: =H24+H33+H41+H42 -> -311676 | I43: =I24+I33+I41+I42 -> -194423 | ... S43: =S24+S33+S41+S42 -> 759652

Sheet QTR P&L
B1: Q1 FY2020 | C1: Q2 FY2020 | D1: Q3 FY2020 | E1: Q4 FY2020 | F1: Q1 FY2021 | G1: Q2 FY2021 | H1: Q3 FY2021 | I1: Q4 FY2021 | J1: Q1 FY2022 | K1: Q2 FY2022 | L1: Q3 FY2022 | M1: Q4 FY2022 | N1: Q1 FY2023 | O1: Q2 FY2023 | P1: Q3 FY2023 | Q1: Q4 FY2023 | R1: Q1 FY2024 | S1: Q2 FY2024 | T1: Q3 FY2024 | U1: Q4 FY2024 | V1: Q1 FY2025 | W1: Q2 FY2025 | X1: Q3 FY2025 | Y1: Q4 FY2025 | Z1: Q1 FY2026E | AA1: Q2 FY2026E | AB1: Q3 FY2026E | AC1: Q4 FY2026E | AD1: Q1 FY2027E | AE1: Q2 FY2027E | AF1: Q3 FY2027E | AG1: Q4 FY2027E | AH1: Q1 FY2028E | AI1: Q2 FY2028E | AJ1: Q3 FY2028E | AK1: Q4 FY2028E | AL1: Q1 FY2029E | AM1: Q2 FY2029E | AN1: Q3 FY2029E | AO1: Q4 FY2029E | AP1: Q1 FY2030E | AQ1: Q2 FY2030E | AR1: Q3 FY2030E | AS1: Q4 FY2030E
A2: Net Sales / Revenue | B2: ='YTD P&L'!B2 -> 1062097 | C2: ='YTD P&L'!C2-'YTD P&L'!B2 -> 1093896 | D2: ='YTD P&L'!D2-'YTD P&L'!C2 -> 1246362 | E2: ='ANNL P&L'!C2-'YTD P&L'!D2 -> 1196283 | F2: ='YTD P&L'!E2 -> 1243816 | G2: ='YTD P&L'!F2-'YTD P&L'!E2 -> 1461935 | H2: ='YTD P&L'!G2-'YTD P&L'!F2 -> 1410557 | I2: ='ANNL P&L'!D2-'YTD P&L'!G2 -> 1425044 | J2: ='YTD P&L'!H2 -> 1518574 | K2: ='YTD P&L'!I2-'YTD P&L'!H2 -> 1655259 | L2: ='YTD P&L'!J2-'YTD P&L'!I2 -> 1624286 | M2: ='ANNL P&L'!E2-'YTD P&L'!J2 -> 1512931 | N2: ='YTD P&L'!K2 -> 1698930 | O2: ='YTD P&L'!L2-'YTD P&L'!K2 -> 1854961 | P2: ='YTD P&L'!M2-'YTD P&L'!L2 -> 1856028 | Q2: ='ANNL P&L'!F2-'YTD P&L'!M2 -> 1730108 | R2: ='YTD P&L'!N2 -> 1899098 | S2: ='YTD P&L'!O2-'YTD P&L'!N2 -> 1900597 | T2: ='YTD P&L'!P2-'YTD P&L'!O2 -> 1880973 | U2: ='ANNL P&L'!G2-'YTD P&L'!P2 -> 1812041 | V2: ='YTD P&L'!Q2 -> 1854558 | W2: ='YTD P&L'!R2-'YTD P&L'!Q2 -> 2111592 | X2: ='YTD P&L'!S2-'YTD P&L'!R2 -> 2197140 | Y2: ='ANNL P&L'!H2-'YTD P&L'!S2 -> 2131053 | Z2: =IF('IS DRIVERS'!$B2="QoQ",'QTR P&L'!Y2,'QTR P&L'!V2)*(1+'IS DRIVERS'!AA2) -> 2181055.2 | AA2: =IF('IS DRIVERS'!$B2="QoQ",'QTR P&L'!Z2,'QTR P&L'!W2)*(1+'IS DRIVERS'!AB2) -> 2483340.3 | AB2: =IF('IS DRIVERS'!$B2="QoQ",'QTR P&L'!AA2,'QTR P&L'!X2)*(1+'IS DRIVERS'!AC2) -> 2583949.1 | AC2: =IF('IS DRIVERS'!$B2="QoQ",'QTR P&L'!AB2,'QTR P&L'!Y2)*(1+'IS DRIVERS'!AD2) -> 2506227.4 | AD2: =IF('IS DRIVERS'!$B2="QoQ",'QTR P&L'!AC2,'QTR P&L'!Z2)*(1+'IS DRIVERS'!AE2) -> 2565032.6 | AE2: =IF('IS DRIVERS'!$B2="QoQ",'QTR P&L'!AD2,'QTR P&L'!AA2)*(1+'IS DRIVERS'!AF2) -> 2920535.4 | AF2: =IF('IS DRIVERS'!$B2="QoQ",'QTR P&L'!AE2,'QTR P&L'!AB2)*(1+'IS DRIVERS'!AG2) -> 3038856.5 | AG2: =IF('IS DRIVERS'!$B2="QoQ",'QTR P&L'!AF2,'QTR P&L'!AC2)*(1+'IS DRIVERS'!AH2) -> 2947451.8 | ... AS2: =IF('IS DRIVERS'!$B2="QoQ",'QTR P&L'!AR2,'QTR P&L'!AO2)*(1+'IS DRIVERS'!AT2) -> 4794302.2
A3: COGS | B3: ='YTD P&L'!B3 -> -424901 | C3: ='YTD P&L'!C3-'YTD P&L'!B3 -> -434428 | D3: ='YTD P&L'!D3-'YTD P&L'!C3 -> -509831 | E3: ='ANNL P&L'!C3-'YTD P&L'!D3 -> -505598 | F3: ='YTD P&L'!E3 -> -528881 | G3: ='YTD P&L'!F3-'YTD P&L'!E3 -> -625095 | H3: ='YTD P&L'!G3-'YTD P&L'!F3 -> -621399 | I3: ='ANNL P&L'!D3-'YTD P&L'!G3 -> -657464 | J3: ='YTD P&L'!H3 -> -741907 | K3: ='YTD P&L'!I3-'YTD P&L'!H3 -> -875399 | L3: ='YTD P&L'!J3-'YTD P&L'!I3 -> -790561 | M3: ='ANNL P&L'!E3-'YTD P&L'!J3 -> -728616 | N3: ='YTD P&L'!K3 -> -801081 | O3: ='YTD P&L'!L3-'YTD P&L'!K3 -> -880739 | P3: ='YTD P&L'!M3-'YTD P&L'!L3 -> -872266 | Q3: ='ANNL P&L'!F3-'YTD P&L'!M3 -> -791735 | R3: ='YTD P&L'!N3 -> -871969 | S3: ='YTD P&L'!O3-'YTD P&L'!N3 -> -881092 | T3: ='YTD P&L'!P3-'YTD P&L'!O3 -> -881174 | U3: ='ANNL P&L'!G3-'YTD P&L'!P3 -> -809596 | V3: ='YTD P&L'!Q3 -> -806596 | W3: ='YTD P&L'!R3-'YTD P&L'!Q3 -> -935179 | X3: ='YTD P&L'!S3-'YTD P&L'!R3 -> -972653 | Y3: ='ANNL P&L'!H3-'YTD P&L'!S3 -> -947720 | Z3: ='QTR P&L'!Z2*'IS DRIVERS'!AA3 -> -969956.92 | AA3: ='QTR P&L'!AA2*'IS DRIVERS'!AB3 -> -1104388.9 | AB3: ='QTR P&L'!AB2*'IS DRIVERS'!AC3 -> -1149131.6 | AC3: ='QTR P&L'!AC2*'IS DRIVERS'!AD3 -> -1114567.2 | AD3: ='QTR P&L'!AD2*'IS DRIVERS'!AE3 -> -1140719 | AE3: ='QTR P&L'!AE2*'IS DRIVERS'!AF3 -> -1298817.9 | AF3: ='QTR P&L'!AF2*'IS DRIVERS'!AG3 -> -1351437.6 | AG3: ='QTR P&L'!AG2*'IS DRIVERS'!AH3 -> -1310788.2 | ... AS3: ='QTR P&L'!AS2*'IS DRIVERS'!AT3 -> -2132117.8
