Workbook

Sheet ANNL P&L
B1: FY2019 | C1: FY2020 | D1: FY2021 | E1: FY2022 | F1: FY2023 | G1: FY2024 | H1: FY2025 | I1: FY2026E | J1: FY2027E | K1: FY2028E | L1: FY2029E | M1: FY2030E | N1: FY2031E
A2: Net Sales / Revenue | B2: 4200819 | C2: 4598638 | D2: 5541352 | E2: 6311050 | F2: 7140027 | G2: 7492709 | H2: 8294343
A3: COGS | B3: -1682234 | C3: -1874758 | D3: -2432839 | E3: -3136483 | F3: -3345821 | G3: -3443831 | H3: -3662148
A4: Gross Profit (Loss) | B4: =B2+B3 | C4: =C2+C3 | D4: =D2+D3 | E4: =E2+E3 | F4: =F2+F3 | G4: =G2+G3 | H4: =H2+H3 | I4: =I2+I3 | ... N4: =N2+N3
A5: Operating Expenses | B5: -1115646 | C5: -1090727 | D5: -1311046 | E5: -1589846 | F5: -1840851 | G5: -2118584 | H5: -2212841
A6: Income (Loss) from Operations | B6: =B4+B5 | C6: =C4+C5 | D6: =D4+D5 | E6: =E4+E5 | F6: =F4+F5 | G6: =G4+G5 | H6: =H4+H5 | I6: =I4+I5 | ... N6: =N4+N5
A7: Other Income (Expense) | B7: 13023 | C7: -6996 | D7: 3952 | E7: -12757 | F7: 115127 | G7: 59165 | H7: 63175
A8: Pre-Tax Income (Loss) | B8: =B6+B7 | C8: =C6+C7 | D8: =D6+D7 | E8: =E6+E7 | F8: =F6+F7 | G8: =G6+G7 | H8: =H6+H7 | I8: =I6+I7 | ... N8: =N6+N7
A9: Income Tax (Expense) Benefit | B9: -308127 | C9: -216563 | D9: -423944 | E9: -380340 | F9: -437494 | G9: -480411 | H9: -577097
A10: Net Income (Loss) | B10: =B8+B9 | C10: =C8+C9 | D10: =D8+D9 | E10: =E8+E9 | F10: =F8+F9 | G10: =G8+G9 | H10: =H8+H9 | I10: =I8+I9 | ... N10: =N8+N9
A11: Basic Earnings (Loss) per Share | B11: 2.04 | C11: 2.66 | D11: 2.61 | E11: 2.26 | F11: 1.56 | G11: 1.5 | H11: 1.95
A12: Diluted Earnings (Loss) per Share | B12: 2.03 | C12: 2.64 | D12: 2.57 | E12: 2.23 | F12: 1.54 | G12: 1.49 | H12: 1.94
A13: Weighted Average Shares Outstanding (Basic) | B13: 542191000 | C13: 529639000 | D13: 528763000 | E13: 526779000 | F13: 1044887000 | G13: 1004566000 | H13: 975887000
A14: Weighted Average Shares Outstanding (Diluted) | B14: 546608000 | C14: 534807000 | D14: 535639000 | E14: 533221000 | F14: 1057981000 | G14: 1013107000 | H14: 984451000
A15: Net Income (Loss) Attributable to Common Shareholders | B15: =B10 | C15: =C10 | D15: =D10 | E15: =E10 | F15: =F10 | G15: =G10 | H15: =H10 | I15: =I10 | ... N15: =N10

Sheet BALANCE SHEET
B1: FY2020 | C1: FY2021 | D1: FY2022 | E1: FY2023 | F1: FY2024 | G1: FY2025 | H1: FY2026E | I1: FY2027E | J1: FY2028E | K1: FY2029E | L1: FY2030E | M1: FY2031E
A2: Cash & Cash Equivalents | B2: 1180413 | C2: 1326462 | D2: 1307141 | E2: 2297675 | F2: 1533287 | G2: 2088117
A3: Short-Term Investments | B3: 881354 | C3: 1749727 | D3: 1362314 | E3: 955605 | F3: 0 | G3: 677084
A4: Accounts Receivable | B4: 666012 | C4: 896658 | D4: 1016203 | E4: 1193964 | F4: 1221646 | G4: 1618072
A5: Inventories | B5: 333085 | C5: 593357 | D5: 935631 | E5: 971406 | F5: 737107 | G5: 799623
A6: Prepaid Expenses | B6: 55358 | C6: 82668 | D6: 109823 | E6: 116195 | F6: 107262 | G6: 103551
A7: Prepaid Income Taxes | B7: 24733 | C7: 33238 | D7: 33785 | E7: 54151 | F7: 42202 | G7: 74637
A8: Total Current Assets | B8: =SUM(B2:B7) | C8: =SUM(C2:C7) | D8: =SUM(D2:D7) | E8: =SUM(E2:E7) | F8: =SUM(F2:F7) | G8: =SUM(G2:G7) | H8: =SUM(H2:H7) | I8: =SUM(I2:I7) | ... M8: =SUM(M2:M7)
A9: Long-Term Investments | B9: 44291 | C9: 99419 | D9: 61443 | E9: 76431 | F9: 0 | G9: 487329
A10: Net PP&E | B10: 314656 | C10: 313753 | D10: 516897 | E10: 890796 | F10: 1047024 | G10: 1081544
A11: Deferred Tax Assets | B11: 241650 | C11: 225221 | D11: 177039 | E11: 175003 | F11: 184260 | G11: 188646
A12: Goodwill | B12: 1331643 | C12: 1331643 | D12: 1417941 | E12: 1417941 | F12: 1331643 | G12: 1331643
A13: Intangible Assets | B13: 1059046 | C13: 1072386 | D13: 1220410 | E13: 1427139 | F13: 1414252 | G13: 1379268
A14: Other Non-Current Assets | B14: 70475 | C14: 80252 | D14: 134478 | E14: 110216 | F14: 100406 | G14: 159431
A15: Total Assets | B15: =B8+SUM(B9:B14) | C15: =C8+SUM(C9:C14) | D15: =D8+SUM(D9:D14) | E15: =E8+SUM(E9:E14) | F15: =F8+SUM(F9:F14) | G15: =G8+SUM(G9:G14) | H15: =H8+SUM(H9:H14) | I15: =I8+SUM(I9:I14) | ... M15: =M8+SUM(M9:M14)
A16: Accounts Payable | B16: 296800 | C16: 404263 | D16: 444265 | E16: 564379 | F16: 466775 | G16: 565974
A17: Accrued Expenses | B17: 142653 | C17: 210964 | D17: 172991 | E17: 183988 | F17: 220764 | G17: 306085
A18: Accrued Promotional Allowance | B18: 186658 | C18: 211461 | D18: 255631 | E18: 269061 | F18: 267711 | G18: 384070
A19: Deferred Revenue - Current | B19: 45429 | C19: 42530 | D19: 43311 | E19: 41914 | F19: 45809 | G19: 45323
A20: Accrued Compensation | B20: 55015 | C20: 65459 | D20: 72463 | E20: 87392 | F20: 92454 | G20: 114023
A21: Income Taxes Payable | B21: 23433 | C21: 30399 | D21: 13317 | E21: 14955 | F21: 4006 | G21: 32305
A22: Total Current Liabilities | B22: =SUM(B16:B21) | C22: =SUM(C16:C21) | D22: =SUM(D16:D21) | E22: =SUM(E16:E21) | F22: =SUM(F16:F21) | G22: =SUM(G16:G21) | H22: =SUM(H16:H21) | I22: =SUM(I16:I21) | ... M22: =SUM(M16:M21)
A23: Deferred Revenue - Non-Current | B23: 264436 | C23: 243249 | D23: 223800 | E23: 204251 | F23: 179008 | G23: 159991
A24: Other Non-Current Liabilities | B24: 27432 | C24: 29508 | D24: 42286 | E24: 91838 | F24: 110893 | G24: 127066
A25: Long-Term Debt | B25: 0 | C25: 0 | D25: 0 | E25: 0 | F25: 373951 | G25: 0
A26: Total Liabilities | B26: =B22+SUM(B23:B25) | C26: =C22+SUM(C23:C25) | D26: =D22+SUM(D23:D25) | E26: =E22+SUM(E23:E25) | F26: =F22+SUM(F23:F25) | G26: =G22+SUM(G23:G25) | H26: =H22+SUM(H23:H25) | I26: =I22+SUM(I23:I25) | ... M26: =M22+SUM(M23:M25)
A27: Common Stock | B27: 3193 | C27: 3200 | D27: 3209 | E27: 5613 | F27: 5632 | G27: 5665
A28: Additional Paid-in Capital | B28: 4537982 | C28: 4652620 | D28: 4780013 | E28: 4975115 | F28: 5144922 | G28: 5430847
A29: Retained Earnings (Accumulated Deficit) | B29: 6432074 | C29: 7809549 | D29: 9001173 | E29: 5939736 | F29: 7448784 | G29: 9354216
A30: Accumulated Other Comprehensive Income (Loss) | B30: 3034 | C30: -69165 | D30: -159073 | E30: -125337 | F30: -269487 | G30: -60841
A31: Treasury Stock | B31: -5815423 | C31: -5829253 | D31: -6600281 | E31: -2566383 | F31: -6372133 | G31: -6475779
A32: Total Stockholders' Equity | B32: =SUM(B27:B31) | C32: =SUM(C27:C31) | D32: =SUM(D27:D31) | E32: =SUM(E27:E31) | F32: =SUM(F27:F31) | G32: =SUM(G27:G31) | H32: =SUM(H27:H31) | I32: =SUM(I27:I31) | ... M32: =SUM(M27:M31)
A33: Total Liabilities, Mezzanine & Stockholders' Equity | B33: =B26+B32 | C33: =C26+C32 | D33: =D26+D32 | E33: =E26+E32 | F33: =F26+F32 | G33: =G26+G32 | H33: =H26+H32 | I33: =I26+I32 | ... M33: =M26+M32

Sheet CASH FLOW
B1: FY2019 | C1: FY2020 | D1: FY2021 | E1: FY2022 | F1: FY2023 | G1: FY2024 | H1: FY2025 | I1: FY2026E | J1: FY2027E | K1: FY2028E | L1: FY2029E | M1: FY2030E | N1: FY2031E
A2: Net Income (Loss) | B2: 1107835 | C2: 1409594 | D2: 1377475 | E2: 1191624 | F2: 1630988 | G2: 1509048 | H2: 1905432
A3: Depreciation & Amortization | B3: 60727 | C3: 57030 | D3: 50155 | E3: 61241 | F3: 68898 | G3: 80434 | H3: 114441
A4: Non-Cash Lease Expense | B4: 4087 | C4: 3943 | D4: 4107 | E4: 7337 | F4: 9043 | G4: 13521 | H4: 15398
A5: Gain (Loss) on Disposal of PP&E | B5: -252 | C5: -350 | D5: -1013 | E5: -185 | F5: 166 | G5: 3328 | H5: 2781
A6: Gain on Bang Transaction | B6: 0 | C6: 0 | D6: 0 | E6: 0 | F6: -45382 | G6: 0 | H6: 0
A7: Impairment of Intangibles | B7: 0 | C7: 8700 | D7: 0 | E7: 2200 | F7: 38700 | G7: 127098 | H7: 38411
A8: Impairment of Long-Lived Assets (PP&E) | B8: 0 | C8: 0 | D8: 0 | E8: 0 | F8: 4336 | G8: 8184 | H8: 12029
A9: Stock-Based Compensation | B9: 63356 | C9: 70289 | D9: 70483 | E9: 64109 | F9: 68836 | G9: 90985 | H9: 125687
A10: (Benefit) Provision for Deferred Income Taxes | B10: 1263 | C10: -156873 | D10: 16429 | E10: 48182 | F10: 2040 | G10: -11705 | H10: 4210
A11: Accounts Receivable | B11: -59941 | C11: -119672 | D11: -254228 | E11: -128981 | F11: -163158 | G11: -93915 | H11: -300600
A12: Inventories | B12: -85222 | C12: 30304 | D12: -277793 | E12: -347712 | F12: 7898 | G12: 211503 | H12: -34918
A13: Prepaid Expenses | B13: -13774 | C13: 1024 | D13: -29341 | E13: -38268 | F13: -10215 | G13: 8959 | H13: -39307
... A21: Deferred Revenue | B21: -24858 | C21: -21480 | D21: -22658 | E21: -19905 | F21: -24472 | G21: -17360 | H21: -23005
A22: Cash Flow from Operations | B22: =SUM(B2:B21) | C22: =SUM(C2:C21) | D22: =SUM(D2:D21) | E22: =SUM(E2:E21) | F22: =SUM(F2:F21) | G22: =SUM(G2:G21) | H22: =SUM(H2:H21) | I22: =SUM(I2:I21) | ... N22: =SUM(N2:N21)
A23: Net Change in Long-Term Investments | B23: -216300 | C23: -379785 | D23: -924544 | E23: 405288 | F23: 409019 | G23: 1035794 | H23: -1163150
A24: Acquisition of CANarchy | B24: 0 | C24: 0 | D24: 0 | E24: -329472 | F24: 0 | G24: 0 | H24: 0
A25: Acquisition of Monster Brewing | B25: 0 | C25: 0 | D25: 0 | E25: 0 | F25: 0 | G25: 0 | H25: 0
A26: Acquisition of Bang Energy | B26: 0 | C26: 0 | D26: 0 | E26: 0 | F26: -363385 | G26: 0 | H26: 0
A27: Purchase of PP&E | B27: -101661 | C27: -48722 | D27: -43868 | E27: -188726 | F27: -221428 | G27: -264074 | H27: -132275
A28: Proceeds from Sale of Assets | B28: 1239 | C28: 993 | D28: 1328 | E28: 1313 | F28: 2520 | G28: 2732 | H28: 4299
A29: Additions to Intangibles | B29: -8737 | C29: -18550 | D29: -13585 | E29: -23427 | F29: -13296 | G29: -42360 | H29: -25254
A30: Other Investing Activities | B30: -1265 | C30: -26423 | D30: -11353 | E30: -26343 | F30: -6825 | G30: 1635 | H30: -398
A31: Cash Flow from Investing | B31: =SUM(B23:B30) | C31: =SUM(C23:C30) | D31: =SUM(D23:D30) | E31: =SUM(E23:E30) | F31: =SUM(F23:F30) | G31: =SUM(G23:G30) | H31: =SUM(H23:H30) | I31: =SUM(I23:I30) | ... N31: =SUM(N23:N30)
A32: Net Change in Other Short-Term Debt | B32: -13569 | C32: -3086 | D32: 2928 | E32: 75 | F32: -13914 | G32: -8223 | H32: -10344
A33: Proceeds from Issuance of Long-Term Debt | B33: 0 | C33: 0 | D33: 0 | E33: 0 | F33: 0 | G33: 750000 | H33: 0
A34: Repayments of Long-Term Debt | B34: 0 | C34: 0 | D34: 0 | E34: 0 | F34: 0 | G34: -375000 | H34: -375000
A35: Debt Issuance Fees | B35: 0 | C35: 0 | D35: 0 | E35: 0 | F35: 0 | G35: -2904 | H35: 0
A36: Proceeds from Issuance of Common Stock | B36: 92363 | C36: 72936 | D36: 45723 | E36: 64015 | F36: 130267 | G36: 78973 | H36: 164568
A37: Share Repurchases | B37: -707300 | C37: -595918 | D37: -13830 | E37: -771028 | F37: -658952 | G37: -3771875 | H37: -103646
A38: Cash Flow from Financing | B38: =SUM(B32:B37) | C38: =SUM(C32:C37) | D38: =SUM(D32:D37) | E38: =SUM(E32:E37) | F38: =SUM(F32:F37) | G38: =SUM(G32:G37) | H38: =SUM(H32:H37) | I38: =SUM(I32:I37) | ... N38: =SUM(N32:N37)
A39: FX Effect on Cash | B39: 1912 | C39: 16848 | D39: -52491 | E39: -38715 | F39: 8775 | G39: -97619 | H39: 97853
A40: Net Change in Cash | B40: =B22+B31+B38+B39 | C40: =C22+C31+C38+C39 | D40: =D22+D31+D38+D39 | E40: =E22+E31+E38+E39 | F40: =F22+F31+F38+F39 | G40: =G22+G31+G38+G39 | H40: =H22+H31+H38+H39 | I40: =I22+I31+I38+I39 | ... N40: =N22+N31+N38+N39

Sheet YTD P&L
B1: Q1 FY2020 | C1: Q2 FY2020 | D1: Q3 FY2020 | E1: Q1 FY2021 | F1: Q2 FY2021 | G1: Q3 FY2021 | H1: Q1 FY2022 | I1: Q2 FY2022 | J1: Q3 FY2022 | K1: Q1 FY2023 | L1: Q2 FY2023 | M1: Q3 FY2023 | N1: Q1 FY2024 | O1: Q2 FY2024 | P1: Q3 FY2024 | Q1: Q1 FY2025 | R1: Q2 FY2025 | S1: Q3 FY2025
A2: Net Sales / Revenue | B2: 1062097 | C2: 2155993 | D2: 3402355 | E2: 1243816 | F2: 2705751 | G2: 4116308 | H2: 1518574 | I2: 3173833 | J2: 4798119 | K2: 1698930 | L2: 3553891 | M2: 5409919 | N2: 1899098 | O2: 3799695 | P2: 5680668 | Q2: 1854558 | R2: 3966150 | S2: 6163290
A3: COGS | B3: -424901 | C3: -859329 | D3: -1369160 | E3: -528881 | F3: -1153976 | G3: -1775375 | H3: -741907 | I3: -1617306 | J3: -2407867 | K3: -801081 | L3: -1681820 | M3: -2554086 | N3: -871969 | O3: -1753061 | P3: -2634235 | Q3: -806596 | R3: -1741775 | S3: -2714428
A4: Gross Profit (Loss) | B4: =B2+B3 | C4: =C2+C3 | D4: =D2+D3 | E4: =E2+E3 | F4: =F2+F3 | G4: =G2+G3 | H4: =H2+H3 | I4: =I2+I3 | ... S4: =S2+S3
A5: Operating Expenses | B5: -272208 | C5: -524412 | D5: -802343 | E5: -300789 | F5: -611652 | G5: -956346 | H5: -377178 | I5: -784088 | J5: -1199883 | K5: -412785 | L5: -863201 | M5: -1336437 | N5: -485138 | O5: -977480 | P5: -1497363 | Q5: -478217 | R5: -1023008 | S5: -1572142
A6: Income (Loss) from Operations | B6: =B4+B5 | C6: =C4+C5 | D6: =D4+D5 | E6: =E4+E5 | F6: =F4+F5 | G6: =G4+G5 | H6: =H4+H5 | I6: =I4+I5 | ... S6: =S4+S5
A7: Other Income (Expense) | B7: 872 | C7: -923 | D7: -5491 | E7: -759 | F7: 111 | G7: -2179 | H7: -7300 | I7: -14080 | J7: -11932 | K7: 12496 | L7: 27653 | M7: 99010 | N7: 35754 | O7: 60131 | P7: 54311 | Q7: 8272 | R7: 23337 | S7: 37522
A8: Pre-Tax Income (Loss) | B8: =B6+B7 | C8: =C6+C7 | D8: =D6+D7 | E8: =E6+E7 | F8: =F6+F7 | G8: =G6+G7 | H8: =H6+H7 | I8: =I6+I7 | ... S8: =S6+S7
A9: Income Tax (Expense) Benefit | B9: -87025 | C9: -181125 | D9: -287503 | E9: -98193 | F9: -221278 | G9: -326247 | H9: -97986 | I9: -190796 | J9: -288487 | K9: -100116 | L9: -225208 | M9: -354397 | N9: -135696 | O9: -261867 | P9: -365044 | Q9: -135024 | R9: -292917 | S9: -458000
A10: Net Income (Loss) | B10: =B8+B9 | C10: =C8+C9 | D10: =D8+D9 | E10: =E8+E9 | F10: =F8+F9 | G10: =G8+G9 | H10: =H8+H9 | I10: =I8+I9 | ... S10: =S8+S9
A11: Basic Earnings (Loss) per Share | B11: 0.52 | C11: 1.11 | D11: 1.77 | E11: 0.6 | F11: 1.36 | G11: 2 | H11: 0.56 | I11: 1.07 | J11: 1.68 | K11: 0.38 | L11: 0.78 | M11: 1.21 | N11: 0.42 | O11: 0.84 | P11: 1.22 | Q11: 0.45 | R11: 0.96 | S11: 1.49
A12: Diluted Earnings (Loss) per Share | B12: 0.52 | C12: 1.1 | D12: 1.75 | E12: 0.59 | F12: 1.34 | G12: 1.97 | H12: 0.55 | I12: 1.06 | J12: 1.66 | K12: 0.38 | L12: 0.77 | M12: 1.19 | N12: 0.42 | O12: 0.83 | P12: 1.21 | Q12: 0.45 | R12: 0.95 | S12: 1.48
A13: Weighted Average Shares Outstanding (Basic) | B13: 536061000 | C13: 531486000 | D13: 530194000 | E13: 528195000 | F13: 528425000 | G13: 528618000 | H13: 529405000 | I13: 529009000 | J13: 528263000 | K13: 1044909000 | L13: 1045993000 | M13: 1046337000 | N13: 1041081000 | O13: 1035175000 | P13: 1015252000 | Q13: 973622000 | R13: 974691000 | S13: 975337000
A14: Weighted Average Shares Outstanding (Diluted) | B14: 540518000 | C14: 535897000 | D14: 535011000 | E14: 534982000 | F14: 535324000 | G14: 535554000 | H14: 535554000 | I14: 535209000 | J14: 534599000 | K14: 1059069000 | L14: 1059667000 | M14: 1059809000 | N14: 1051282000 | O14: 1044363000 | P14: 1023912000 | Q14: 981282000 | R14: 982748000 | S14: 983532000
A15: Net Income (Loss) Attributable to Common Shareholders | B15: =B10 | C15: =C10 | D15: =D10 | E15: =E10 | F15: =F10 | G15: =G10 | H15: =H10 | I15: =I10 | ... S15: =S10

Sheet YTD BS
B1: Q4 FY2020 | C1: Q1 FY2021 | D1: Q2 FY2021 | E1: Q3 FY2021 | F1: Q4 FY2021 | G1: Q1 FY2022 | H1: Q2 FY2022 | I1: Q3 FY2022 | J1: Q4 FY2022 | K1: Q1 FY2023 | L1: Q2 FY2023 | M1: Q3 FY2023 | N1: Q4 FY2023 | O1: Q1 FY2024 | P1: Q2 FY2024 | Q1: Q3 FY2024 | R1: Q4 FY2024 | S1: Q1 FY2025 | T1: Q2 FY2025 | U1: Q3 FY2025
A2: Cash & Cash Equivalents | B2: 1180413 | C2: 1178879 | D2: 1584239 | E2: 1712671 | F2: 1326462 | G2: 1014786 | H2: 1132039 | I2: 1303048 | J2: 1307141 | K2: 1672660 | L2: 1869774 | M2: 1773849 | N2: 2297675 | O2: 2576524 | P2: 1564734 | Q2: 1625339 | R2: 1533287 | S2: 1903419 | T2: 1926927 | U2: 2292939
A3: Short-Term Investments | B3: 881354 | C3: 980108 | D3: 968952 | E3: 1224066 | F3: 1749727 | G3: 1717648 | H3: 1337792 | I3: 1346781 | J3: 1362314 | K3: 1383028 | L3: 1417239 | M3: 1236752 | N3: 955605 | O3: 984201 | P3: 0 | Q3: 0 | R3: 0 | S3: 0 | T3: 145253 | U3: 286391
A4: Accounts Receivable | B4: 666012 | C4: 802509 | D4: 909169 | E4: 849157 | F4: 896658 | G4: 1039780 | H4: 1175587 | I4: 1051642 | J4: 1016203 | K4: 1190351 | L4: 1333004 | M4: 1231188 | N4: 1193964 | O4: 1370239 | P4: 1362398 | Q4: 1285397 | R4: 1221646 | S4: 1360233 | T4: 1522702 | U4: 1601216
A5: Inventories | B5: 333085 | C5: 368402 | D5: 382890 | E5: 471553 | F5: 593357 | G5: 821132 | H5: 885948 | I5: 862977 | J5: 935631 | K5: 906723 | L5: 846812 | M5: 883582 | N5: 971406 | O5: 939630 | P5: 834404 | Q5: 770338 | R5: 737107 | S5: 725129 | T5: 658167 | U5: 704586
A6: Prepaid Expenses | B6: 55358 | C6: 72803 | D6: 83086 | E6: 95607 | F6: 82668 | G6: 110327 | H6: 132273 | I6: 112294 | J6: 109823 | K6: 110958 | L6: 148750 | M6: 162676 | N6: 116195 | O6: 124580 | P6: 129303 | Q6: 124656 | R6: 107262 | S6: 112525 | T6: 137257 | U6: 142713
A7: Prepaid Income Taxes | B7: 24733 | C7: 31171 | D7: 22339 | E7: 30619 | F7: 33238 | G7: 39993 | H7: 32981 | I7: 19949 | J7: 33785 | K7: 30889 | L7: 38534 | M7: 23468 | N7: 54151 | O7: 40340 | P7: 63458 | Q7: 92028 | R7: 42202 | S7: 34113 | T7: 39034 | U7: 38372
A8: Total Current Assets | B8: =SUM(B2:B7) | C8: =SUM(C2:C7) | D8: =SUM(D2:D7) | E8: =SUM(E2:E7) | F8: =SUM(F2:F7) | G8: =SUM(G2:G7) | H8: =SUM(H2:H7) | I8: =SUM(I2:I7) | ... U8: =SUM(U2:U7)
A9: Long-Term Investments | B9: 44291 | C9: 63751 | D9: 91033 | E9: 28255 | F9: 99419 | G9: 65652 | H9: 64119 | I9: 72373 | J9: 61443 | K9: 41152 | L9: 62248 | M9: 52636 | N9: 76431 | O9: 8162 | P9: 0 | Q9: 0 | R9: 0 | S9: 0 | T9: 138058 | U9: 359174
A10: Net PP&E | B10: 314656 | C10: 312155 | D10: 309178 | E10: 309574 | F10: 313753 | G10: 407391 | H10: 464541 | I10: 485550 | J10: 516897 | K10: 545922 | L10: 576645 | M10: 731208 | N10: 890796 | O10: 923290 | P10: 960962 | Q10: 1006788 | R10: 1047024 | S10: 1064008 | T10: 1090898 | U10: 1110705
A11: Deferred Tax Assets | B11: 241650 | C11: 241650 | D11: 241297 | E11: 241297 | F11: 225221 | G11: 225221 | H11: 203287 | I11: 195511 | J11: 177039 | K11: 177039 | L11: 177039 | M11: 176724 | N11: 175003 | O11: 175271 | P11: 187269 | Q11: 183430 | R11: 184260 | S11: 184358 | T11: 184791 | U11: 185321
A12: Goodwill | B12: 1331643 | C12: 1331643 | D12: 1331643 | E12: 1331643 | F12: 1331643 | G12: 1411928 | H12: 1412941 | I12: 1412941 | J12: 1417941 | K12: 1417941 | L12: 1417941 | M12: 1417941 | N12: 1417941 | O12: 1417941 | P12: 1417941 | Q12: 1417941 | R12: 1331643 | S12: 1331643 | T12: 1331643 | U12: 1331643
A13: Intangible Assets | B13: 1059046 | C13: 1063092 | D13: 1058323 | E13: 1066083 | F13: 1072386 | G13: 1232113 | H13: 1223114 | I13: 1225826 | J13: 1220410 | K13: 1222598 | L13: 1224100 | M13: 1459447 | N13: 1427139 | O13: 1430762 | P13: 1433326 | Q13: 1442426 | R13: 1414252 | S13: 1415958 | T13: 1418827 | U13: 1419306
A14: Other Non-Current Assets | B14: 70475 | C14: 88203 | D14: 89394 | E14: 88883 | F14: 80252 | G14: 101488 | H14: 110390 | I14: 115913 | J14: 134478 | K14: 145101 | L14: 151252 | M14: 164867 | N14: 110216 | O14: 107126 | P14: 107109 | Q14: 104958 | R14: 100406 | S14: 95642 | T14: 136331 | U14: 138907
A15: Total Assets | B15: =B8+SUM(B9:B14) | C15: =C8+SUM(C9:C14) | D15: =D8+SUM(D9:D14) | E15: =E8+SUM(E9:E14) | F15: =F8+SUM(F9:F14) | G15: =G8+SUM(G9:G14) | H15: =H8+SUM(H9:H14) | I15: =I8+SUM(I9:I14) | ... U15: =U8+SUM(U9:U14)
A16: Accounts Payable | B16: 296800 | C16: 334076 | D16: 362900 | E16: 396229 | F16: 404263 | G16: 438256 | H16: 492858 | I16: 520198 | J16: 444265 | K16: 491249 | L16: 568613 | M16: 539892 | N16: 564379 | O16: 533729 | P16: 511137 | Q16: 549028 | R16: 466775 | S16: 486951 | T16: 489037 | U16: 683030
A17: Accrued Expenses | B17: 142653 | C17: 170954 | D17: 172498 | E17: 180719 | F17: 210964 | G17: 234111 | H17: 209154 | I17: 198692 | J17: 172991 | K17: 245932 | L17: 198656 | M17: 207727 | N17: 183988 | O17: 204679 | P17: 213905 | Q17: 259088 | R17: 220764 | S17: 262545 | T17: 258937 | U17: 325450
A18: Accrued Promotional Allowance | B18: 186658 | C18: 197380 | D18: 227414 | E18: 232394 | F18: 211461 | G18: 270785 | H18: 277618 | I18: 281650 | J18: 255631 | K18: 308094 | L18: 283647 | M18: 296577 | N18: 269061 | O18: 318895 | P18: 319757 | Q18: 301973 | R18: 267711 | S18: 304670 | T18: 360406 | U18: 392628
A19: Deferred Revenue - Current | B19: 45429 | C19: 45961 | D19: 46656 | E19: 45278 | F19: 42530 | G19: 42540 | H19: 44344 | I19: 42608 | J19: 43311 | K19: 44440 | L19: 42765 | M19: 40127 | N19: 41914 | O19: 43776 | P19: 44377 | Q19: 45627 | R19: 45809 | S19: 47542 | T19: 49279 | U19: 47158
A20: Accrued Compensation | B20: 55015 | C20: 30499 | D20: 46770 | E20: 54507 | F20: 65459 | G20: 37551 | H20: 53717 | I20: 61426 | J20: 72463 | K20: 42673 | L20: 56195 | M20: 76835 | N20: 87392 | O20: 52638 | P20: 60357 | Q20: 81787 | R20: 92454 | S20: 55812 | T20: 72838 | U20: 102131
A21: Income Taxes Payable | B21: 23433 | C21: 9991 | D21: 31289 | E21: 23113 | F21: 30399 | G21: 21118 | H21: 15917 | I21: 17143 | J21: 13317 | K21: 55123 | L21: 12704 | M21: 17644 | N21: 14955 | O21: 75111 | P21: 10990 | Q21: 7641 | R21: 4006 | S21: 67837 | T21: 28121 | U21: 40023
A22: Total Current Liabilities | B22: =SUM(B16:B21) | C22: =SUM(C16:C21) | D22: =SUM(D16:D21) | E22: =SUM(E16:E21) | F22: =SUM(F16:F21) | G22: =SUM(G16:G21) | H22: =SUM(H16:H21) | I22: =SUM(I16:I21) | ... U22: =SUM(U16:U21)
A23: Deferred Revenue - Non-Current | B23: 264436 | C23: 257730 | D23: 252056 | E23: 245621 | F23: 243249 | G23: 238241 | H23: 232170 | I23: 226294 | J23: 223800 | K23: 219764 | L23: 215039 | M23: 209136 | N23: 204251 | O23: 198759 | P23: 192354 | Q23: 186135 | R23: 179008 | S23: 173921 | T23: 169763 | U23: 164701
A24: Deferred Tax Liability | B24: 0 | C24: 0 | D24: 0 | E24: 0 | F24: 0 | G24: 0 | H24: 0 | I24: 0 | J24: 0 | K24: 0 | L24: 0 | M24: 0 | N24: 0 | O24: 0 | P24: 28896 | Q24: 28896 | R24: 0 | S24: 0 | T24: 0 | U24: 0
A25: Other Non-Current Liabilities | B25: 27432 | C25: 28338 | D25: 26462 | E25: 26550 | F25: 29508 | G25: 38185 | H25: 40056 | I25: 41034 | J25: 42286 | K25: 41727 | L25: 44255 | M25: 53251 | N25: 91838 | O25: 92690 | P25: 64068 | Q25: 64884 | R25: 110893 | S25: 109252 | T25: 110203 | U25: 110992
A26: Long-Term Debt | B26: 0 | C26: 0 | D26: 0 | E26: 0 | F26: 0 | G26: 0 | H26: 0 | I26: 0 | J26: 0 | K26: 0 | L26: 0 | M26: 0 | N26: 0 | O26: 0 | P26: 748740 | Q26: 748842 | R26: 373951 | S26: 199059 | T26: 0 | U26: 0
A27: Total Liabilities | B27: =B22+SUM(B23:B26) | C27: =C22+SUM(C23:C26) | D27: =D22+SUM(D23:D26) | E27: =E22+SUM(E23:E26) | F27: =F22+SUM(F23:F26) | G27: =G22+SUM(G23:G26) | H27: =H22+SUM(H23:H26) | I27: =I22+SUM(I23:I26) | ... U27: =U22+SUM(U23:U26)
A28: Common Stock | B28: 3193 | C28: 3196 | D28: 3198 | E28: 3199 | F28: 3200 | G28: 3203 | H28: 3205 | I28: 3206 | J28: 6418 | K28: 5587 | L28: 5591 | M28: 5592 | N28: 5613 | O28: 5624 | P28: 5627 | Q28: 5628 | R28: 5632 | S28: 5643 | T28: 5650 | U28: 5655
A29: Additional Paid-in Capital | B29: 4537982 | C29: 4562689 | D29: 4597333 | E29: 4626299 | F29: 4652620 | G29: 4673302 | H29: 4707569 | I29: 4736141 | J29: 4776804 | K29: 4829301 | L29: 4869791 | M29: 4893289 | N29: 4975115 | O29: 5034948 | P29: 5068291 | Q29: 5105957 | R29: 5144922 | S29: 5213731 | T29: 5285157 | U29: 5343915
A30: Retained Earnings (Accumulated Deficit) | B30: 6432074 | C30: 6747268 | D30: 7151030 | E30: 7488235 | F30: 7809549 | G30: 8103752 | H30: 8377112 | I30: 8699499 | J30: 9001173 | K30: 4706192 | L30: 5120063 | M30: 5572757 | N30: 5939736 | O30: 6381785 | P30: 6807154 | Q30: 7178073 | R30: 7448784 | S30: 7891777 | T30: 8380571 | U30: 8905026
A31: Accumulated Other Comprehensive Income (Loss) | B31: 3034 | C31: -24874 | D31: -16822 | E31: -43495 | F31: -69165 | G31: -72145 | H31: -152957 | I31: -224455 | J31: -159073 | K31: -147911 | L31: -155725 | M31: -198033 | N31: -125337 | O31: -157940 | P31: -182304 | Q31: -137842 | R31: -269487 | S31: -202946 | T31: -91308 | U31: -93382
A32: Treasury Stock | B32: -5815423 | C32: -5828842 | D32: -5829241 | E32: -5829241 | F32: -5829253 | G32: -5841440 | H32: -6125751 | I32: -6398631 | J32: -6600281 | K32: -1997809 | L32: -1998256 | M32: -2400456 | N32: -2566383 | O32: -2686628 | P32: -5832445 | Q32: -6372416 | R32: -6372133 | S32: -6388766 | T32: -6388766 | U32: -6416054
A33: Total Stockholders' Equity | B33: =SUM(B28:B32) | C33: =SUM(C28:C32) | D33: =SUM(D28:D32) | E33: =SUM(E28:E32) | F33: =SUM(F28:F32) | G33: =SUM(G28:G32) | H33: =SUM(H28:H32) | I33: =SUM(I28:I32) | ... U33: =SUM(U28:U32)
A34: Total Liabilities, Mezzanine & Stockholders' Equity | B34: =B27+B33 | C34: =C27+C33 | D34: =D27+D33 | E34: =E27+E33 | F34: =F27+F33 | G34: =G27+G33 | H34: =H27+H33 | I34: =I27+I33 | ... U34: =U27+U33

Sheet YTD CF
B1: Q1 FY2020 | C1: Q2 FY2020 | D1: Q3 FY2020 | E1: Q1 FY2021 | F1: Q2 FY2021 | G1: Q3 FY2021 | H1: Q1 FY2022 | I1: Q2 FY2022 | J1: Q3 FY2022 | K1: Q1 FY2023 | L1: Q2 FY2023 | M1: Q3 FY2023 | N1: Q1 FY2024 | O1: Q2 FY2024 | P1: Q3 FY2024 | Q1: Q1 FY2025 | R1: Q2 FY2025 | S1: Q3 FY2025
A2: Net Income (Loss) | B2: 278835 | C2: 590204 | D2: 937858 | E2: 315194 | F2: 718956 | G2: 1056161 | H2: 294203 | I2: 567563 | J2: 889950 | K2: 397444 | L2: 811315 | M2: 1264009 | N2: 442049 | O2: 867418 | P2: 1238337 | Q2: 442993 | R2: 931787 | S2: 1456242
A3: Depreciation & Amortization | B3: 16546 | C3: 32057 | D3: 45879 | E3: 13777 | F3: 27489 | G3: 40716 | H3: 14599 | I3: 30432 | J3: 46040 | K3: 16808 | L3: 32384 | M3: 50364 | N3: 20475 | O3: 39913 | P3: 59822 | Q3: 24848 | R3: 52405 | S3: 82023
A4: Non-Cash Lease Expense | B4: 0 | C4: 0 | D4: 0 | E4: 0 | F4: 0 | G4: 0 | H4: 1481 | I4: 3222 | J4: 5180 | K4: 2160 | L4: 2828 | M4: 6471 | N4: 3185 | O4: 6599 | P4: 9801 | Q4: 4014 | R4: 6966 | S4: 10266
A5: Gain (Loss) on Disposal of PP&E | B5: -58 | C5: -179 | D5: -210 | E5: -88 | F5: -822 | G5: -984 | H5: -6 | I5: -69 | J5: -253 | K5: -385 | L5: -767 | M5: -686 | N5: -177 | O5: 1849 | P5: 2070 | Q5: 324 | R5: -641 | S5: -916
A6: Gain on Bang Transaction | B6: 0 | C6: 0 | D6: 0 | E6: 0 | F6: 0 | G6: 0 | H6: 0 | I6: 0 | J6: 0 | K6: 0 | L6: 0 | M6: -45382 | N6: 0 | O6: 0 | P6: 0 | Q6: 0 | R6: 0 | S6: 0
A7: Impairment of Intangibles | B7: 3000 | C7: 4000 | D7: 7000 | E7: 0 | F7: 0 | G7: 0 | H7: 0 | I7: 0 | J7: 0 | K7: 0 | L7: 2800 | M7: 2800 | N7: 0 | O7: 0 | P7: 0 | Q7: 0 | R7: 0 | S7: 0
A8: Impairment of Long-Lived Assets (PP&E) | B8: 0 | C8: 0 | D8: 0 | E8: 0 | F8: 0 | G8: 0 | H8: 0 | I8: 0 | J8: 0 | K8: 0 | L8: 0 | M8: 0 | N8: 0 | O8: 6067 | P8: 6067 | Q8: 2279 | R8: 2279 | S8: 2279
A9: Stock-Based Compensation | B9: 17098 | C9: 33034 | D9: 53042 | E9: 18362 | F9: 35691 | G9: 52391 | H9: 16332 | I9: 32609 | J9: 49167 | K9: 16051 | L9: 34603 | M9: 52465 | N9: 22472 | O9: 41262 | P9: 68793 | Q9: 20727 | R9: 53854 | S9: 86664
A10: (Benefit) Provision for Deferred Income Taxes | B10: 0 | C10: 0 | D10: 0 | E10: 0 | F10: 353 | G10: 353 | H10: 0 | I10: 21934 | J10: 29710 | K10: 0 | L10: 0 | M10: 0 | N10: 9 | O10: -13294 | P10: -10242 | Q10: 135 | R10: 646 | S10: 455
A11: Accounts Receivable | B11: -147660 | C11: -231782 | D11: -201677 | E11: -147544 | F11: -239700 | G11: -199709 | H11: -134433 | I11: -289236 | J11: -202447 | K11: -167512 | L11: -317808 | M11: -218804 | N11: -195081 | O11: -197227 | P11: -106404 | Q11: -109557 | R11: -222239 | S11: -299139
A12: Distributor Receivables | B12: 176 | C12: 188 | D12: 341 | E12: 92 | F12: 160 | G12: 228 | H12: 0 | I12: 0 | J12: 0 | K12: 0 | L12: 0 | M12: 0 | N12: 0 | O12: 0 | P12: 0 | Q12: 0 | R12: 0 | S12: 0
A13: Inventories | B13: 1037 | C13: 14181 | D13: 39490 | E13: -39546 | F13: -52541 | G13: -149414 | H13: -208673 | I13: -299076 | J13: -297140 | K13: 35495 | L13: 93077 | M13: 69796 | N13: 22708 | O13: 123484 | P13: 197107 | Q13: 19594 | R13: 104633 | S13: 58387
... A23: Deferred Revenue | B23: -4273 | C23: -10383 | D23: -15236 | E23: -5250 | F23: -10922 | G23: -17784 | H23: -5915 | I23: -9101 | J23: -16060 | K23: -5046 | L23: -12361 | M23: -19320 | N23: -3036 | O23: -7731 | P23: -12652 | Q23: -4339 | R23: -8598 | S23: -15907
A24: Cash Flow from Operations | B24: =SUM(B2:B23) | C24: =SUM(C2:C23) | D24: =SUM(D2:D23) | E24: =SUM(E2:E23) | F24: =SUM(F2:F23) | G24: =SUM(G2:G23) | H24: =SUM(H2:H23) | I24: =SUM(I2:I23) | ... S24: =SUM(S2:S23)
A25: Net Change in Long-Term Investments | B25: 298837 | C25: 293643 | D25: -53418 | E25: -114819 | F25: -134502 | G25: -326795 | H25: 62883 | I25: 445440 | J25: 430033 | K25: 3750 | L25: -53323 | M25: 140805 | N25: 39897 | O25: 1035794 | P25: 1035794 | Q25: 0 | R25: -283097 | S25: -597703
A26: Acquisition of CANarchy | B26: 0 | C26: 0 | D26: 0 | E26: 0 | F26: 0 | G26: 0 | H26: -330356 | I26: -329472 | J26: -329472 | K26: 0 | L26: 0 | M26: 0 | N26: 0 | O26: 0 | P26: 0 | Q26: 0 | R26: 0 | S26: 0
A27: Acquisition of Monster Brewing | B27: 0 | C27: 0 | D27: 0 | E27: 0 | F27: 0 | G27: 0 | H27: 0 | I27: 0 | J27: 0 | K27: 0 | L27: 0 | M27: 0 | N27: 0 | O27: 0 | P27: 0 | Q27: 0 | R27: 0 | S27: 0
A28: Acquisition of Bang Energy | B28: 0 | C28: 0 | D28: 0 | E28: 0 | F28: 0 | G28: 0 | H28: 0 | I28: 0 | J28: 0 | K28: 0 | L28: 0 | M28: -363385 | N28: 0 | O28: 0 | P28: 0 | Q28: 0 | R28: 0 | S28: 0
A29: Purchase of PP&E | B29: -11119 | C29: -29116 | D29: -42062 | E29: -8400 | F29: -15522 | G29: -28131 | H29: -21511 | I29: -99446 | J29: -136158 | K29: -40100 | L29: -82425 | M29: -110224 | N29: -66044 | O29: -125812 | P29: -172795 | Q29: -29056 | R29: -60460 | S29: -104101
A30: Proceeds from Sale of Assets | B30: 217 | C30: 590 | D30: 880 | E30: 231 | F30: 1024 | G30: 1246 | H30: 14 | I30: 372 | J30: 603 | K30: 564 | L30: 1035 | M30: 1753 | N30: 422 | O30: 1052 | P30: 2095 | Q30: 1147 | R30: 2334 | S30: 2744
A31: Additions to Intangibles | B31: -6811 | C31: -13085 | D31: -19686 | E31: -7239 | F31: -9926 | G31: -5211 | H31: -8419 | I31: -9894 | J31: -3578 | K31: -3952 | L31: -5926 | M31: -9110 | N31: -8612 | O31: -6364 | P31: -21473 | Q31: -5343 | R31: -15399 | S31: -19681
A32: Other Investing Activities | B32: -1148 | C32: -1338 | D32: -26228 | E32: -18856 | F32: -21236 | G32: -22809 | H32: -6241 | I32: -12738 | J32: -19171 | K32: -13028 | L32: -17570 | M32: -19862 | N32: -985 | O32: -1366 | P32: -603 | Q32: 2397 | R32: -1107 | S32: -507
A33: Cash Flow from Investing | B33: =SUM(B25:B32) | C33: =SUM(C25:C32) | D33: =SUM(D25:D32) | E33: =SUM(E25:E32) | F33: =SUM(F25:F32) | G33: =SUM(G25:G32) | H33: =SUM(H25:H32) | I33: =SUM(I25:I32) | ... S33: =SUM(S25:S32)
A34: Repayments of Short-Term Debt | B34: 0 | C34: 0 | D34: 0 | E34: 0 | F34: 0 | G34: 0 | H34: 0 | I34: 0 | J34: 0 | K34: 0 | L34: 0 | M34: 0 | N34: 0 | O34: -5269 | P34: -6717 | Q34: 0 | R34: 0 | S34: 0
A35: Net Change in Other Short-Term Debt | B35: -733 | C35: -1680 | D35: -2500 | E35: 957 | F35: 3624 | G35: -1814 | H35: 3454 | I35: 4924 | J35: -719 | K35: -7271 | L35: -6661 | M35: -11273 | N35: -2896 | O35: 0 | P35: 0 | Q35: -2045 | R35: -5023 | S35: -8043
A36: Proceeds from Issuance of Long-Term Debt | B36: 0 | C36: 0 | D36: 0 | E36: 0 | F36: 0 | G36: 0 | H36: 0 | I36: 0 | J36: 0 | K36: 0 | L36: 0 | M36: 0 | N36: 0 | O36: 750000 | P36: 750000 | Q36: 0 | R36: 0 | S36: 0
A37: Debt Issuance Fees | B37: 0 | C37: 0 | D37: 0 | E37: 0 | F37: 0 | G37: 0 | H37: 0 | I37: 0 | J37: 0 | K37: 0 | L37: 0 | M37: 0 | N37: 0 | O37: -2776 | P37: -2904 | Q37: 0 | R37: 0 | S37: 0
A38: Repayments of Long-Term Debt | B38: 0 | C38: 0 | D38: 0 | E38: 0 | F38: 0 | G38: 0 | H38: 0 | I38: 0 | J38: 0 | K38: 0 | L38: 0 | M38: 0 | N38: 0 | O38: 0 | P38: 0 | Q38: -175000 | R38: -375000 | S38: -375000
A39: Proceeds from Issuance of Common Stock | B39: 13975 | C39: 43842 | D39: 65540 | E39: 6761 | F39: 24486 | G39: 37160 | H39: 4510 | I39: 22622 | J39: 34759 | K39: 36348 | L39: 59666 | M39: 65560 | N39: 38392 | O39: 52093 | P39: 62101 | Q39: 48093 | R39: 87684 | S39: 114363
A40: Share Repurchases | B40: -559210 | C40: -595770 | D40: -595918 | E40: -13419 | F40: -13818 | G40: -13818 | H40: -12187 | I40: -296499 | J40: -493315 | K40: -35126 | L40: -90825 | M40: -488080 | N40: -120245 | O40: -3234523 | P40: -3770184 | Q40: -16633 | R40: -16633 | S40: -43921
A41: Cash Flow from Financing | B41: =SUM(B34:B40) | C41: =SUM(C34:C40) | D41: =SUM(D34:D40) | E41: =SUM(E34:E40) | F41: =SUM(F34:F40) | G41: =SUM(G34:G40) | H41: =SUM(H34:H40) | I41: =SUM(I34:I40) | ... S41: =SUM(S34:S40)
A42: FX Effect on Cash | B42: -21261 | C42: -14175 | D42: 929 | E42: -22223 | F42: -16890 | G42: -35552 | H42: -3472 | I42: -50395 | J42: -95582 | K42: -141 | L42: -4500 | M42: -22902 | N42: -13222 | O42: -44203 | P42: -14482 | Q42: 38972 | R42: 86725 | S42: 72739
A43: Net Change in Cash | B43: =B24+B33+B41+B42 | C43: =C24+C33+C41+C42 | D43: =D24+D33+D41+D42 | E43: =E24+E33+E41+E42 | F43: =F24+F33+F41+F42 | G43: =G24+G33+G41+G42 | H43: =H24+H33+H41+H42 | I43: =I24+I33+I41+I42 | ... S43: =S24+S33+S41+S42

Sheet QTR P&L
B1: Q1 FY2020 | C1: Q2 FY2020 | D1: Q3 FY2020 | E1: Q4 FY2020 | F1: Q1 FY2021 | G1: Q2 FY2021 | H1: Q3 FY2021 | I1: Q4 FY2021 | J1: Q1 FY2022 | K1: Q2 FY2022 | L1: Q3 FY2022 | M1: Q4 FY2022 | N1: Q1 FY2023 | O1: Q2 FY2023 | P1: Q3 FY2023 | Q1: Q4 FY2023 | R1: Q1 FY2024 | S1: Q2 FY2024 | T1: Q3 FY2024 | U1: Q4 FY2024 | V1: Q1 FY2025 | W1: Q2 FY2025 | X1: Q3 FY2025 | Y1: Q4 FY2025
A2: Net Sales / Revenue | B2: ='YTD P&L'!B2 | C2: ='YTD P&L'!C2-'YTD P&L'!B2 | D2: ='YTD P&L'!D2-'YTD P&L'!C2 | E2: ='ANNL P&L'!C2-'YTD P&L'!D2 | F2: ='YTD P&L'!E2 | G2: ='YTD P&L'!F2-'YTD P&L'!E2 | H2: ='YTD P&L'!G2-'YTD P&L'!F2 | I2: ='ANNL P&L'!D2-'YTD P&L'!G2 | J2: ='YTD P&L'!H2 | K2: ='YTD P&L'!I2-'YTD P&L'!H2 | L2: ='YTD P&L'!J2-'YTD P&L'!I2 | M2: ='ANNL P&L'!E2-'YTD P&L'!J2 | N2: ='YTD P&L'!K2 | O2: ='YTD P&L'!L2-'YTD P&L'!K2 | P2: ='YTD P&L'!M2-'YTD P&L'!L2 | Q2: ='ANNL P&L'!F2-'YTD P&L'!M2 | R2: ='YTD P&L'!N2 | S2: ='YTD P&L'!O2-'YTD P&L'!N2 | T2: ='YTD P&L'!P2-'YTD P&L'!O2 | U2: ='ANNL P&L'!G2-'YTD P&L'!P2 | V2: ='YTD P&L'!Q2 | W2: ='YTD P&L'!R2-'YTD P&L'!Q2 | X2: ='YTD P&L'!S2-'YTD P&L'!R2 | Y2: ='ANNL P&L'!H2-'YTD P&L'!S2
A3: COGS | B3: ='YTD P&L'!B3 | C3: ='YTD P&L'!C3-'YTD P&L'!B3 | D3: ='YTD P&L'!D3-'YTD P&L'!C3 | E3: ='ANNL P&L'!C3-'YTD P&L'!D3 | F3: ='YTD P&L'!E3 | G3: ='YTD P&L'!F3-'YTD P&L'!E3 | H3: ='YTD P&L'!G3-'YTD P&L'!F3 | I3: ='ANNL P&L'!D3-'YTD P&L'!G3 | J3: ='YTD P&L'!H3 | K3: ='YTD P&L'!I3-'YTD P&L'!H3 | L3: ='YTD P&L'!J3-'YTD P&L'!I3 | M3: ='ANNL P&L'!E3-'YTD P&L'!J3 | N3: ='YTD P&L'!K3 | O3: ='YTD P&L'!L3-'YTD P&L'!K3 | P3: ='YTD P&L'!M3-'YTD P&L'!L3 | Q3: ='ANNL P&L'!F3-'YTD P&L'!M3 | R3: ='YTD P&L'!N3 | S3: ='YTD P&L'!O3-'YTD P&L'!N3 | T3: ='YTD P&L'!P3-'YTD P&L'!O3 | U3: ='ANNL P&L'!G3-'YTD P&L'!P3 | V3: ='YTD P&L'!Q3 | W3: ='YTD P&L'!R3-'YTD P&L'!Q3 | X3: ='YTD P&L'!S3-'YTD P&L'!R3 | Y3: ='ANNL P&L'!H3-'YTD P&L'!S3
A4: Gross Profit (Loss) | B4: ='YTD P&L'!B4 | C4: ='YTD P&L'!C4-'YTD P&L'!B4 | D4: ='YTD P&L'!D4-'YTD P&L'!C4 | E4: ='ANNL P&L'!C4-'YTD P&L'!D4 | F4: ='YTD P&L'!E4 | G4: ='YTD P&L'!F4-'YTD P&L'!E4 | H4: ='YTD P&L'!G4-'YTD P&L'!F4 | I4: ='ANNL P&L'!D4-'YTD P&L'!G4 | J4: ='YTD P&L'!H4 | K4: ='YTD P&L'!I4-'YTD P&L'!H4 | L4: ='YTD P&L'!J4-'YTD P&L'!I4 | M4: ='ANNL P&L'!E4-'YTD P&L'!J4 | N4: ='YTD P&L'!K4 | O4: ='YTD P&L'!L4-'YTD P&L'!K4 | P4: ='YTD P&L'!M4-'YTD P&L'!L4 | Q4: ='ANNL P&L'!F4-'YTD P&L'!M4 | R4: ='YTD P&L'!N4 | S4: ='YTD P&L'!O4-'YTD P&L'!N4 | T4: ='YTD P&L'!P4-'YTD P&L'!O4 | U4: ='ANNL P&L'!G4-'YTD P&L'!P4 | V4: ='YTD P&L'!Q4 | W4: ='YTD P&L'!R4-'YTD P&L'!Q4 | X4: ='YTD P&L'!S4-'YTD P&L'!R4 | Y4: ='ANNL P&L'!H4-'YTD P&L'!S4
A5: Operating Expenses | B5: ='YTD P&L'!B5 | C5: ='YTD P&L'!C5-'YTD P&L'!B5 | D5: ='YTD P&L'!D5-'YTD P&L'!C5 | E5: ='ANNL P&L'!C5-'YTD P&L'!D5 | F5: ='YTD P&L'!E5 | G5: ='YTD P&L'!F5-'YTD P&L'!E5 | H5: ='YTD P&L'!G5-'YTD P&L'!F5 | I5: ='ANNL P&L'!D5-'YTD P&L'!G5 | J5: ='YTD P&L'!H5 | K5: ='YTD P&L'!I5-'YTD P&L'!H5 | L5: ='YTD P&L'!J5-'YTD P&L'!I5 | M5: ='ANNL P&L'!E5-'YTD P&L'!J5 | N5: ='YTD P&L'!K5 | O5: ='YTD P&L'!L5-'YTD P&L'!K5 | P5: ='YTD P&L'!M5-'YTD P&L'!L5 | Q5: ='ANNL P&L'!F5-'YTD P&L'!M5 | R5: ='YTD P&L'!N5 | S5: ='YTD P&L'!O5-'YTD P&L'!N5 | T5: ='YTD P&L'!P5-'YTD P&L'!O5 | U5: ='ANNL P&L'!G5-'YTD P&L'!P5 | V5: ='YTD P&L'!Q5 | W5: ='YTD P&L'!R5-'YTD P&L'!Q5 | X5: ='YTD P&L'!S5-'YTD P&L'!R5 | Y5: ='ANNL P&L'!H5-'YTD P&L'!S5
A6: Income (Loss) from Operations | B6: ='YTD P&L'!B6 | C6: ='YTD P&L'!C6-'YTD P&L'!B6 | D6: ='YTD P&L'!D6-'YTD P&L'!C6 | E6: ='ANNL P&L'!C6-'YTD P&L'!D6 | F6: ='YTD P&L'!E6 | G6: ='YTD P&L'!F6-'YTD P&L'!E6 | H6: ='YTD P&L'!G6-'YTD P&L'!F6 | I6: ='ANNL P&L'!D6-'YTD P&L'!G6 | J6: ='YTD P&L'!H6 | K6: ='YTD P&L'!I6-'YTD P&L'!H6 | L6: ='YTD P&L'!J6-'YTD P&L'!I6 | M6: ='ANNL P&L'!E6-'YTD P&L'!J6 | N6: ='YTD P&L'!K6 | O6: ='YTD P&L'!L6-'YTD P&L'!K6 | P6: ='YTD P&L'!M6-'YTD P&L'!L6 | Q6: ='ANNL P&L'!F6-'YTD P&L'!M6 | R6: ='YTD P&L'!N6 | S6: ='YTD P&L'!O6-'YTD P&L'!N6 | T6: ='YTD P&L'!P6-'YTD P&L'!O6 | U6: ='ANNL P&L'!G6-'YTD P&L'!P6 | V6: ='YTD P&L'!Q6 | W6: ='YTD P&L'!R6-'YTD P&L'!Q6 | X6: ='YTD P&L'!S6-'YTD P&L'!R6 | Y6: ='ANNL P&L'!H6-'YTD P&L'!S6
A7: Other Income (Expense) | B7: ='YTD P&L'!B7 | C7: ='YTD P&L'!C7-'YTD P&L'!B7 | D7: ='YTD P&L'!D7-'YTD P&L'!C7 | E7: ='ANNL P&L'!C7-'YTD P&L'!D7 | F7: ='YTD P&L'!E7 | G7: ='YTD P&L'!F7-'YTD P&L'!E7 | H7: ='YTD P&L'!G7-'YTD P&L'!F7 | I7: ='ANNL P&L'!D7-'YTD P&L'!G7 | J7: ='YTD P&L'!H7 | K7: ='YTD P&L'!I7-'YTD P&L'!H7 | L7: ='YTD P&L'!J7-'YTD P&L'!I7 | M7: ='ANNL P&L'!E7-'YTD P&L'!J7 | N7: ='YTD P&L'!K7 | O7: ='YTD P&L'!L7-'YTD P&L'!K7 | P7: ='YTD P&L'!M7-'YTD P&L'!L7 | Q7: ='ANNL P&L'!F7-'YTD P&L'!M7 | R7: ='YTD P&L'!N7 | S7: ='YTD P&L'!O7-'YTD P&L'!N7 | T7: ='YTD P&L'!P7-'YTD P&L'!O7 | U7: ='ANNL P&L'!G7-'YTD P&L'!P7 | V7: ='YTD P&L'!Q7 | W7: ='YTD P&L'!R7-'YTD P&L'!Q7 | X7: ='YTD P&L'!S7-'YTD P&L'!R7 | Y7: ='ANNL P&L'!H7-'YTD P&L'!S7
A8: Pre-Tax Income (Loss) | B8: ='YTD P&L'!B8 | C8: ='YTD P&L'!C8-'YTD P&L'!B8 | D8: ='YTD P&L'!D8-'YTD P&L'!C8 | E8: ='ANNL P&L'!C8-'YTD P&L'!D8 | F8: ='YTD P&L'!E8 | G8: ='YTD P&L'!F8-'YTD P&L'!E8 | H8: ='YTD P&L'!G8-'YTD P&L'!F8 | I8: ='ANNL P&L'!D8-'YTD P&L'!G8 | J8: ='YTD P&L'!H8 | K8: ='YTD P&L'!I8-'YTD P&L'!H8 | L8: ='YTD P&L'!J8-'YTD P&L'!I8 | M8: ='ANNL P&L'!E8-'YTD P&L'!J8 | N8: ='YTD P&L'!K8 | O8: ='YTD P&L'!L8-'YTD P&L'!K8 | P8: ='YTD P&L'!M8-'YTD P&L'!L8 | Q8: ='ANNL P&L'!F8-'YTD P&L'!M8 | R8: ='YTD P&L'!N8 | S8: ='YTD P&L'!O8-'YTD P&L'!N8 | T8: ='YTD P&L'!P8-'YTD P&L'!O8 | U8: ='ANNL P&L'!G8-'YTD P&L'!P8 | V8: ='YTD P&L'!Q8 | W8: ='YTD P&L'!R8-'YTD P&L'!Q8 | X8: ='YTD P&L'!S8-'YTD P&L'!R8 | Y8: ='ANNL P&L'!H8-'YTD P&L'!S8
A9: Income Tax (Expense) Benefit | B9: ='YTD P&L'!B9 | C9: ='YTD P&L'!C9-'YTD P&L'!B9 | D9: ='YTD P&L'!D9-'YTD P&L'!C9 | E9: ='ANNL P&L'!C9-'YTD P&L'!D9 | F9: ='YTD P&L'!E9 | G9: ='YTD P&L'!F9-'YTD P&L'!E9 | H9: ='YTD P&L'!G9-'YTD P&L'!F9 | I9: ='ANNL P&L'!D9-'YTD P&L'!G9 | J9: ='YTD P&L'!H9 | K9: ='YTD P&L'!I9-'YTD P&L'!H9 | L9: ='YTD P&L'!J9-'YTD P&L'!I9 | M9: ='ANNL P&L'!E9-'YTD P&L'!J9 | N9: ='YTD P&L'!K9 | O9: ='YTD P&L'!L9-'YTD P&L'!K9 | P9: ='YTD P&L'!M9-'YTD P&L'!L9 | Q9: ='ANNL P&L'!F9-'YTD P&L'!M9 | R9: ='YTD P&L'!N9 | S9: ='YTD P&L'!O9-'YTD P&L'!N9 | T9: ='YTD P&L'!P9-'YTD P&L'!O9 | U9: ='ANNL P&L'!G9-'YTD P&L'!P9 | V9: ='YTD P&L'!Q9 | W9: ='YTD P&L'!R9-'YTD P&L'!Q9 | X9: ='YTD P&L'!S9-'YTD P&L'!R9 | Y9: ='ANNL P&L'!H9-'YTD P&L'!S9
A10: Net Income (Loss) | B10: ='YTD P&L'!B10 | C10: ='YTD P&L'!C10-'YTD P&L'!B10 | D10: ='YTD P&L'!D10-'YTD P&L'!C10 | E10: ='ANNL P&L'!C10-'YTD P&L'!D10 | F10: ='YTD P&L'!E10 | G10: ='YTD P&L'!F10-'YTD P&L'!E10 | H10: ='YTD P&L'!G10-'YTD P&L'!F10 | I10: ='ANNL P&L'!D10-'YTD P&L'!G10 | J10: ='YTD P&L'!H10 | K10: ='YTD P&L'!I10-'YTD P&L'!H10 | L10: ='YTD P&L'!J10-'YTD P&L'!I10 | M10: ='ANNL P&L'!E10-'YTD P&L'!J10 | N10: ='YTD P&L'!K10 | O10: ='YTD P&L'!L10-'YTD P&L'!K10 | P10: ='YTD P&L'!M10-'YTD P&L'!L10 | Q10: ='ANNL P&L'!F10-'YTD P&L'!M10 | R10: ='YTD P&L'!N10 | S10: ='YTD P&L'!O10-'YTD P&L'!N10 | T10: ='YTD P&L'!P10-'YTD P&L'!O10 | U10: ='ANNL P&L'!G10-'YTD P&L'!P10 | V10: ='YTD P&L'!Q10 | W10: ='YTD P&L'!R10-'YTD P&L'!Q10 | X10: ='YTD P&L'!S10-'YTD P&L'!R10 | Y10: ='ANNL P&L'!H10-'YTD P&L'!S10
A11: Basic Earnings (Loss) per Share
A12: Diluted Earnings (Loss) per Share
A13: Weighted Average Shares Outstanding (Basic)
A14: Weighted Average Shares Outstanding (Diluted)
A15: Net Income (Loss) Attributable to Common Shareholders | B15: ='YTD P&L'!B15 | C15: ='YTD P&L'!C15-'YTD P&L'!B15 | D15: ='YTD P&L'!D15-'YTD P&L'!C15 | E15: ='ANNL P&L'!C15-'YTD P&L'!D15 | F15: ='YTD P&L'!E15 | G15: ='YTD P&L'!F15-'YTD P&L'!E15 | H15: ='YTD P&L'!G15-'YTD P&L'!F15 | I15: ='ANNL P&L'!D15-'YTD P&L'!G15 | J15: ='YTD P&L'!H15 | K15: ='YTD P&L'!I15-'YTD P&L'!H15 | L15: ='YTD P&L'!J15-'YTD P&L'!I15 | M15: ='ANNL P&L'!E15-'YTD P&L'!J15 | N15: ='YTD P&L'!K15 | O15: ='YTD P&L'!L15-'YTD P&L'!K15 | P15: ='YTD P&L'!M15-'YTD P&L'!L15 | Q15: ='ANNL P&L'!F15-'YTD P&L'!M15 | R15: ='YTD P&L'!N15 | S15: ='YTD P&L'!O15-'YTD P&L'!N15 | T15: ='YTD P&L'!P15-'YTD P&L'!O15 | U15: ='ANNL P&L'!G15-'YTD P&L'!P15 | V15: ='YTD P&L'!Q15 | W15: ='YTD P&L'!R15-'YTD P&L'!Q15 | X15: ='YTD P&L'!S15-'YTD P&L'!R15 | Y15: ='ANNL P&L'!H15-'YTD P&L'!S15

Sheet QTR BS
B1: Q4 FY2020 | C1: Q1 FY2021 | D1: Q2 FY2021 | E1: Q3 FY2021 | F1: Q4 FY2021 | G1: Q1 FY2022 | H1: Q2 FY2022 | I1: Q3 FY2022 | J1: Q4 FY2022 | K1: Q1 FY2023 | L1: Q2 FY2023 | M1: Q3 FY2023 | N1: Q4 FY2023 | O1: Q1 FY2024 | P1: Q2 FY2024 | Q1: Q3 FY2024 | R1: Q4 FY2024 | S1: Q1 FY2025 | T1: Q2 FY2025 | U1: Q3 FY2025 | V1: Q4 FY2025
A2: Cash & Cash Equivalents | B2: ='BALANCE SHEET'!B2 | C2: ='YTD BS'!C2 | D2: ='YTD BS'!D2 | E2: ='YTD BS'!E2 | F2: ='BALANCE SHEET'!C2 | G2: ='YTD BS'!G2 | H2: ='YTD BS'!H2 | I2: ='YTD BS'!I2 | J2: ='BALANCE SHEET'!D2 | K2: ='YTD BS'!K2 | L2: ='YTD BS'!L2 | M2: ='YTD BS'!M2 | N2: ='BALANCE SHEET'!E2 | O2: ='YTD BS'!O2 | P2: ='YTD BS'!P2 | Q2: ='YTD BS'!Q2 | R2: ='BALANCE SHEET'!F2 | S2: ='YTD BS'!S2 | T2: ='YTD BS'!T2 | U2: ='YTD BS'!U2 | V2: ='BALANCE SHEET'!G2
A3: Short-Term Investments | B3: ='BALANCE SHEET'!B3 | C3: ='YTD BS'!C3 | D3: ='YTD BS'!D3 | E3: ='YTD BS'!E3 | F3: ='BALANCE SHEET'!C3 | G3: ='YTD BS'!G3 | H3: ='YTD BS'!H3 | I3: ='YTD BS'!I3 | J3: ='BALANCE SHEET'!D3 | K3: ='YTD BS'!K3 | L3: ='YTD BS'!L3 | M3: ='YTD BS'!M3 | N3: ='BALANCE SHEET'!E3 | O3: ='YTD BS'!O3 | P3: ='YTD BS'!P3 | Q3: ='YTD BS'!Q3 | R3: ='BALANCE SHEET'!F3 | S3: ='YTD BS'!S3 | T3: ='YTD BS'!T3 | U3: ='YTD BS'!U3 | V3: ='BALANCE SHEET'!G3
A4: Accounts Receivable | B4: ='BALANCE SHEET'!B4 | C4: ='YTD BS'!C4 | D4: ='YTD BS'!D4 | E4: ='YTD BS'!E4 | F4: ='BALANCE SHEET'!C4 | G4: ='YTD BS'!G4 | H4: ='YTD BS'!H4 | I4: ='YTD BS'!I4 | J4: ='BALANCE SHEET'!D4 | K4: ='YTD BS'!K4 | L4: ='YTD BS'!L4 | M4: ='YTD BS'!M4 | N4: ='BALANCE SHEET'!E4 | O4: ='YTD BS'!O4 | P4: ='YTD BS'!P4 | Q4: ='YTD BS'!Q4 | R4: ='BALANCE SHEET'!F4 | S4: ='YTD BS'!S4 | T4: ='YTD BS'!T4 | U4: ='YTD BS'!U4 | V4: ='BALANCE SHEET'!G4
A5: Inventories | B5: ='BALANCE SHEET'!B5 | C5: ='YTD BS'!C5 | D5: ='YTD BS'!D5 | E5: ='YTD BS'!E5 | F5: ='BALANCE SHEET'!C5 | G5: ='YTD BS'!G5 | H5: ='YTD BS'!H5 | I5: ='YTD BS'!I5 | J5: ='BALANCE SHEET'!D5 | K5: ='YTD BS'!K5 | L5: ='YTD BS'!L5 | M5: ='YTD BS'!M5 | N5: ='BALANCE SHEET'!E5 | O5: ='YTD BS'!O5 | P5: ='YTD BS'!P5 | Q5: ='YTD BS'!Q5 | R5: ='BALANCE SHEET'!F5 | S5: ='YTD BS'!S5 | T5: ='YTD BS'!T5 | U5: ='YTD BS'!U5 | V5: ='BALANCE SHEET'!G5
A6: Prepaid Expenses | B6: ='BALANCE SHEET'!B6 | C6: ='YTD BS'!C6 | D6: ='YTD BS'!D6 | E6: ='YTD BS'!E6 | F6: ='BALANCE SHEET'!C6 | G6: ='YTD BS'!G6 | H6: ='YTD BS'!H6 | I6: ='YTD BS'!I6 | J6: ='BALANCE SHEET'!D6 | K6: ='YTD BS'!K6 | L6: ='YTD BS'!L6 | M6: ='YTD BS'!M6 | N6: ='BALANCE SHEET'!E6 | O6: ='YTD BS'!O6 | P6: ='YTD BS'!P6 | Q6: ='YTD BS'!Q6 | R6: ='BALANCE SHEET'!F6 | S6: ='YTD BS'!S6 | T6: ='YTD BS'!T6 | U6: ='YTD BS'!U6 | V6: ='BALANCE SHEET'!G6
A7: Prepaid Income Taxes | B7: ='BALANCE SHEET'!B7 | C7: ='YTD BS'!C7 | D7: ='YTD BS'!D7 | E7: ='YTD BS'!E7 | F7: ='BALANCE SHEET'!C7 | G7: ='YTD BS'!G7 | H7: ='YTD BS'!H7 | I7: ='YTD BS'!I7 | J7: ='BALANCE SHEET'!D7 | K7: ='YTD BS'!K7 | L7: ='YTD BS'!L7 | M7: ='YTD BS'!M7 | N7: ='BALANCE SHEET'!E7 | O7: ='YTD BS'!O7 | P7: ='YTD BS'!P7 | Q7: ='YTD BS'!Q7 | R7: ='BALANCE SHEET'!F7 | S7: ='YTD BS'!S7 | T7: ='YTD BS'!T7 | U7: ='YTD BS'!U7 | V7: ='BALANCE SHEET'!G7
A8: Total Current Assets | B8: ='BALANCE SHEET'!B8 | C8: ='YTD BS'!C8 | D8: ='YTD BS'!D8 | E8: ='YTD BS'!E8 | F8: ='BALANCE SHEET'!C8 | G8: ='YTD BS'!G8 | H8: ='YTD BS'!H8 | I8: ='YTD BS'!I8 | J8: ='BALANCE SHEET'!D8 | K8: ='YTD BS'!K8 | L8: ='YTD BS'!L8 | M8: ='YTD BS'!M8 | N8: ='BALANCE SHEET'!E8 | O8: ='YTD BS'!O8 | P8: ='YTD BS'!P8 | Q8: ='YTD BS'!Q8 | R8: ='BALANCE SHEET'!F8 | S8: ='YTD BS'!S8 | T8: ='YTD BS'!T8 | U8: ='YTD BS'!U8 | V8: ='BALANCE SHEET'!G8
A9: Long-Term Investments | B9: ='BALANCE SHEET'!B9 | C9: ='YTD BS'!C9 | D9: ='YTD BS'!D9 | E9: ='YTD BS'!E9 | F9: ='BALANCE SHEET'!C9 | G9: ='YTD BS'!G9 | H9: ='YTD BS'!H9 | I9: ='YTD BS'!I9 | J9: ='BALANCE SHEET'!D9 | K9: ='YTD BS'!K9 | L9: ='YTD BS'!L9 | M9: ='YTD BS'!M9 | N9: ='BALANCE SHEET'!E9 | O9: ='YTD BS'!O9 | P9: ='YTD BS'!P9 | Q9: ='YTD BS'!Q9 | R9: ='BALANCE SHEET'!F9 | S9: ='YTD BS'!S9 | T9: ='YTD BS'!T9 | U9: ='YTD BS'!U9 | V9: ='BALANCE SHEET'!G9
A10: Net PP&E | B10: ='BALANCE SHEET'!B10 | C10: ='YTD BS'!C10 | D10: ='YTD BS'!D10 | E10: ='YTD BS'!E10 | F10: ='BALANCE SHEET'!C10 | G10: ='YTD BS'!G10 | H10: ='YTD BS'!H10 | I10: ='YTD BS'!I10 | J10: ='BALANCE SHEET'!D10 | K10: ='YTD BS'!K10 | L10: ='YTD BS'!L10 | M10: ='YTD BS'!M10 | N10: ='BALANCE SHEET'!E10 | O10: ='YTD BS'!O10 | P10: ='YTD BS'!P10 | Q10: ='YTD BS'!Q10 | R10: ='BALANCE SHEET'!F10 | S10: ='YTD BS'!S10 | T10: ='YTD BS'!T10 | U10: ='YTD BS'!U10 | V10: ='BALANCE SHEET'!G10
A11: Deferred Tax Assets | B11: ='BALANCE SHEET'!B11 | C11: ='YTD BS'!C11 | D11: ='YTD BS'!D11 | E11: ='YTD BS'!E11 | F11: ='BALANCE SHEET'!C11 | G11: ='YTD BS'!G11 | H11: ='YTD BS'!H11 | I11: ='YTD BS'!I11 | J11: ='BALANCE SHEET'!D11 | K11: ='YTD BS'!K11 | L11: ='YTD BS'!L11 | M11: ='YTD BS'!M11 | N11: ='BALANCE SHEET'!E11 | O11: ='YTD BS'!O11 | P11: ='YTD BS'!P11 | Q11: ='YTD BS'!Q11 | R11: ='BALANCE SHEET'!F11 | S11: ='YTD BS'!S11 | T11: ='YTD BS'!T11 | U11: ='YTD BS'!U11 | V11: ='BALANCE SHEET'!G11
A12: Goodwill | B12: ='BALANCE SHEET'!B12 | C12: ='YTD BS'!C12 | D12: ='YTD BS'!D12 | E12: ='YTD BS'!E12 | F12: ='BALANCE SHEET'!C12 | G12: ='YTD BS'!G12 | H12: ='YTD BS'!H12 | I12: ='YTD BS'!I12 | J12: ='BALANCE SHEET'!D12 | K12: ='YTD BS'!K12 | L12: ='YTD BS'!L12 | M12: ='YTD BS'!M12 | N12: ='BALANCE SHEET'!E12 | O12: ='YTD BS'!O12 | P12: ='YTD BS'!P12 | Q12: ='YTD BS'!Q12 | R12: ='BALANCE SHEET'!F12 | S12: ='YTD BS'!S12 | T12: ='YTD BS'!T12 | U12: ='YTD BS'!U12 | V12: ='BALANCE SHEET'!G12
A13: Intangible Assets | B13: ='BALANCE SHEET'!B13 | C13: ='YTD BS'!C13 | D13: ='YTD BS'!D13 | E13: ='YTD BS'!E13 | F13: ='BALANCE SHEET'!C13 | G13: ='YTD BS'!G13 | H13: ='YTD BS'!H13 | I13: ='YTD BS'!I13 | J13: ='BALANCE SHEET'!D13 | K13: ='YTD BS'!K13 | L13: ='YTD BS'!L13 | M13: ='YTD BS'!M13 | N13: ='BALANCE SHEET'!E13 | O13: ='YTD BS'!O13 | P13: ='YTD BS'!P13 | Q13: ='YTD BS'!Q13 | R13: ='BALANCE SHEET'!F13 | S13: ='YTD BS'!S13 | T13: ='YTD BS'!T13 | U13: ='YTD BS'!U13 | V13: ='BALANCE SHEET'!G13
... A23: Deferred Revenue - Non-Current | B23: ='BALANCE SHEET'!B23 | C23: ='YTD BS'!C23 | D23: ='YTD BS'!D23 | E23: ='YTD BS'!E23 | F23: ='BALANCE SHEET'!C23 | G23: ='YTD BS'!G23 | H23: ='YTD BS'!H23 | I23: ='YTD BS'!I23 | J23: ='BALANCE SHEET'!D23 | K23: ='YTD BS'!K23 | L23: ='YTD BS'!L23 | M23: ='YTD BS'!M23 | N23: ='BALANCE SHEET'!E23 | O23: ='YTD BS'!O23 | P23: ='YTD BS'!P23 | Q23: ='YTD BS'!Q23 | R23: ='BALANCE SHEET'!F23 | S23: ='YTD BS'!S23 | T23: ='YTD BS'!T23 | U23: ='YTD BS'!U23 | V23: ='BALANCE SHEET'!G23
A24: Deferred Tax Liability | C24: ='YTD BS'!C24 | D24: ='YTD BS'!D24 | E24: ='YTD BS'!E24 | G24: ='YTD BS'!G24 | H24: ='YTD BS'!H24 | I24: ='YTD BS'!I24 | K24: ='YTD BS'!K24 | L24: ='YTD BS'!L24 | M24: ='YTD BS'!M24 | O24: ='YTD BS'!O24 | P24: ='YTD BS'!P24 | Q24: ='YTD BS'!Q24 | S24: ='YTD BS'!S24 | T24: ='YTD BS'!T24 | U24: ='YTD BS'!U24
A25: Other Non-Current Liabilities | B25: ='BALANCE SHEET'!B24 | C25: ='YTD BS'!C25 | D25: ='YTD BS'!D25 | E25: ='YTD BS'!E25 | F25: ='BALANCE SHEET'!C24 | G25: ='YTD BS'!G25 | H25: ='YTD BS'!H25 | I25: ='YTD BS'!I25 | J25: ='BALANCE SHEET'!D24 | K25: ='YTD BS'!K25 | L25: ='YTD BS'!L25 | M25: ='YTD BS'!M25 | N25: ='BALANCE SHEET'!E24 | O25: ='YTD BS'!O25 | P25: ='YTD BS'!P25 | Q25: ='YTD BS'!Q25 | R25: ='BALANCE SHEET'!F24 | S25: ='YTD BS'!S25 | T25: ='YTD BS'!T25 | U25: ='YTD BS'!U25 | V25: ='BALANCE SHEET'!G24
A26: Long-Term Debt | B26: ='BALANCE SHEET'!B25 | C26: ='YTD BS'!C26 | D26: ='YTD BS'!D26 | E26: ='YTD BS'!E26 | F26: ='BALANCE SHEET'!C25 | G26: ='YTD BS'!G26 | H26: ='YTD BS'!H26 | I26: ='YTD BS'!I26 | J26: ='BALANCE SHEET'!D25 | K26: ='YTD BS'!K26 | L26: ='YTD BS'!L26 | M26: ='YTD BS'!M26 | N26: ='BALANCE SHEET'!E25 | O26: ='YTD BS'!O26 | P26: ='YTD BS'!P26 | Q26: ='YTD BS'!Q26 | R26: ='BALANCE SHEET'!F25 | S26: ='YTD BS'!S26 | T26: ='YTD BS'!T26 | U26: ='YTD BS'!U26 | V26: ='BALANCE SHEET'!G25
A27: Total Liabilities | B27: ='BALANCE SHEET'!B26 | C27: ='YTD BS'!C27 | D27: ='YTD BS'!D27 | E27: ='YTD BS'!E27 | F27: ='BALANCE SHEET'!C26 | G27: ='YTD BS'!G27 | H27: ='YTD BS'!H27 | I27: ='YTD BS'!I27 | J27: ='BALANCE SHEET'!D26 | K27: ='YTD BS'!K27 | L27: ='YTD BS'!L27 | M27: ='YTD BS'!M27 | N27: ='BALANCE SHEET'!E26 | O27: ='YTD BS'!O27 | P27: ='YTD BS'!P27 | Q27: ='YTD BS'!Q27 | R27: ='BALANCE SHEET'!F26 | S27: ='YTD BS'!S27 | T27: ='YTD BS'!T27 | U27: ='YTD BS'!U27 | V27: ='BALANCE SHEET'!G26
A28: Common Stock | B28: ='BALANCE SHEET'!B27 | C28: ='YTD BS'!C28 | D28: ='YTD BS'!D28 | E28: ='YTD BS'!E28 | F28: ='BALANCE SHEET'!C27 | G28: ='YTD BS'!G28 | H28: ='YTD BS'!H28 | I28: ='YTD BS'!I28 | J28: ='BALANCE SHEET'!D27 | K28: ='YTD BS'!K28 | L28: ='YTD BS'!L28 | M28: ='YTD BS'!M28 | N28: ='BALANCE SHEET'!E27 | O28: ='YTD BS'!O28 | P28: ='YTD BS'!P28 | Q28: ='YTD BS'!Q28 | R28: ='BALANCE SHEET'!F27 | S28: ='YTD BS'!S28 | T28: ='YTD BS'!T28 | U28: ='YTD BS'!U28 | V28: ='BALANCE SHEET'!G27
A29: Additional Paid-in Capital | B29: ='BALANCE SHEET'!B28 | C29: ='YTD BS'!C29 | D29: ='YTD BS'!D29 | E29: ='YTD BS'!E29 | F29: ='BALANCE SHEET'!C28 | G29: ='YTD BS'!G29 | H29: ='YTD BS'!H29 | I29: ='YTD BS'!I29 | J29: ='BALANCE SHEET'!D28 | K29: ='YTD BS'!K29 | L29: ='YTD BS'!L29 | M29: ='YTD BS'!M29 | N29: ='BALANCE SHEET'!E28 | O29: ='YTD BS'!O29 | P29: ='YTD BS'!P29 | Q29: ='YTD BS'!Q29 | R29: ='BALANCE SHEET'!F28 | S29: ='YTD BS'!S29 | T29: ='YTD BS'!T29 | U29: ='YTD BS'!U29 | V29: ='BALANCE SHEET'!G28
A30: Retained Earnings (Accumulated Deficit) | B30: ='BALANCE SHEET'!B29 | C30: ='YTD BS'!C30 | D30: ='YTD BS'!D30 | E30: ='YTD BS'!E30 | F30: ='BALANCE SHEET'!C29 | G30: ='YTD BS'!G30 | H30: ='YTD BS'!H30 | I30: ='YTD BS'!I30 | J30: ='BALANCE SHEET'!D29 | K30: ='YTD BS'!K30 | L30: ='YTD BS'!L30 | M30: ='YTD BS'!M30 | N30: ='BALANCE SHEET'!E29 | O30: ='YTD BS'!O30 | P30: ='YTD BS'!P30 | Q30: ='YTD BS'!Q30 | R30: ='BALANCE SHEET'!F29 | S30: ='YTD BS'!S30 | T30: ='YTD BS'!T30 | U30: ='YTD BS'!U30 | V30: ='BALANCE SHEET'!G29
A31: Accumulated Other Comprehensive Income (Loss) | B31: ='BALANCE SHEET'!B30 | C31: ='YTD BS'!C31 | D31: ='YTD BS'!D31 | E31: ='YTD BS'!E31 | F31: ='BALANCE SHEET'!C30 | G31: ='YTD BS'!G31 | H31: ='YTD BS'!H31 | I31: ='YTD BS'!I31 | J31: ='BALANCE SHEET'!D30 | K31: ='YTD BS'!K31 | L31: ='YTD BS'!L31 | M31: ='YTD BS'!M31 | N31: ='BALANCE SHEET'!E30 | O31: ='YTD BS'!O31 | P31: ='YTD BS'!P31 | Q31: ='YTD BS'!Q31 | R31: ='BALANCE SHEET'!F30 | S31: ='YTD BS'!S31 | T31: ='YTD BS'!T31 | U31: ='YTD BS'!U31 | V31: ='BALANCE SHEET'!G30
A32: Treasury Stock | B32: ='BALANCE SHEET'!B31 | C32: ='YTD BS'!C32 | D32: ='YTD BS'!D32 | E32: ='YTD BS'!E32 | F32: ='BALANCE SHEET'!C31 | G32: ='YTD BS'!G32 | H32: ='YTD BS'!H32 | I32: ='YTD BS'!I32 | J32: ='BALANCE SHEET'!D31 | K32: ='YTD BS'!K32 | L32: ='YTD BS'!L32 | M32: ='YTD BS'!M32 | N32: ='BALANCE SHEET'!E31 | O32: ='YTD BS'!O32 | P32: ='YTD BS'!P32 | Q32: ='YTD BS'!Q32 | R32: ='BALANCE SHEET'!F31 | S32: ='YTD BS'!S32 | T32: ='YTD BS'!T32 | U32: ='YTD BS'!U32 | V32: ='BALANCE SHEET'!G31
A33: Total Stockholders' Equity | B33: ='BALANCE SHEET'!B32 | C33: ='YTD BS'!C33 | D33: ='YTD BS'!D33 | E33: ='YTD BS'!E33 | F33: ='BALANCE SHEET'!C32 | G33: ='YTD BS'!G33 | H33: ='YTD BS'!H33 | I33: ='YTD BS'!I33 | J33: ='BALANCE SHEET'!D32 | K33: ='YTD BS'!K33 | L33: ='YTD BS'!L33 | M33: ='YTD BS'!M33 | N33: ='BALANCE SHEET'!E32 | O33: ='YTD BS'!O33 | P33: ='YTD BS'!P33 | Q33: ='YTD BS'!Q33 | R33: ='BALANCE SHEET'!F32 | S33: ='YTD BS'!S33 | T33: ='YTD BS'!T33 | U33: ='YTD BS'!U33 | V33: ='BALANCE SHEET'!G32
A34: Total Liabilities, Mezzanine & Stockholders' Equity | B34: ='BALANCE SHEET'!B33 | C34: ='YTD BS'!C34 | D34: ='YTD BS'!D34 | E34: ='YTD BS'!E34 | F34: ='BALANCE SHEET'!C33 | G34: ='YTD BS'!G34 | H34: ='YTD BS'!H34 | I34: ='YTD BS'!I34 | J34: ='BALANCE SHEET'!D33 | K34: ='YTD BS'!K34 | L34: ='YTD BS'!L34 | M34: ='YTD BS'!M34 | N34: ='BALANCE SHEET'!E33 | O34: ='YTD BS'!O34 | P34: ='YTD BS'!P34 | Q34: ='YTD BS'!Q34 | R34: ='BALANCE SHEET'!F33 | S34: ='YTD BS'!S34 | T34: ='YTD BS'!T34 | U34: ='YTD BS'!U34 | V34: ='BALANCE SHEET'!G33

Sheet QTR CF
B1: Q1 FY2020 | C1: Q2 FY2020 | D1: Q3 FY2020 | E1: Q4 FY2020 | F1: Q1 FY2021 | G1: Q2 FY2021 | H1: Q3 FY2021 | I1: Q4 FY2021 | J1: Q1 FY2022 | K1: Q2 FY2022 | L1: Q3 FY2022 | M1: Q4 FY2022 | N1: Q1 FY2023 | O1: Q2 FY2023 | P1: Q3 FY2023 | Q1: Q4 FY2023 | R1: Q1 FY2024 | S1: Q2 FY2024 | T1: Q3 FY2024 | U1: Q4 FY2024 | V1: Q1 FY2025 | W1: Q2 FY2025 | X1: Q3 FY2025 | Y1: Q4 FY2025
A2: Net Income (Loss) | B2: ='YTD CF'!B2 | C2: ='YTD CF'!C2-'YTD CF'!B2 | D2: ='YTD CF'!D2-'YTD CF'!C2 | E2: ='CASH FLOW'!C2-'YTD CF'!D2 | F2: ='YTD CF'!E2 | G2: ='YTD CF'!F2-'YTD CF'!E2 | H2: ='YTD CF'!G2-'YTD CF'!F2 | I2: ='CASH FLOW'!D2-'YTD CF'!G2 | J2: ='YTD CF'!H2 | K2: ='YTD CF'!I2-'YTD CF'!H2 | L2: ='YTD CF'!J2-'YTD CF'!I2 | M2: ='CASH FLOW'!E2-'YTD CF'!J2 | N2: ='YTD CF'!K2 | O2: ='YTD CF'!L2-'YTD CF'!K2 | P2: ='YTD CF'!M2-'YTD CF'!L2 | Q2: ='CASH FLOW'!F2-'YTD CF'!M2 | R2: ='YTD CF'!N2 | S2: ='YTD CF'!O2-'YTD CF'!N2 | T2: ='YTD CF'!P2-'YTD CF'!O2 | U2: ='CASH FLOW'!G2-'YTD CF'!P2 | V2: ='YTD CF'!Q2 | W2: ='YTD CF'!R2-'YTD CF'!Q2 | X2: ='YTD CF'!S2-'YTD CF'!R2 | Y2: ='CASH FLOW'!H2-'YTD CF'!S2
A3: Depreciation & Amortization | B3: ='YTD CF'!B3 | C3: ='YTD CF'!C3-'YTD CF'!B3 | D3: ='YTD CF'!D3-'YTD CF'!C3 | E3: ='CASH FLOW'!C3-'YTD CF'!D3 | F3: ='YTD CF'!E3 | G3: ='YTD CF'!F3-'YTD CF'!E3 | H3: ='YTD CF'!G3-'YTD CF'!F3 | I3: ='CASH FLOW'!D3-'YTD CF'!G3 | J3: ='YTD CF'!H3 | K3: ='YTD CF'!I3-'YTD CF'!H3 | L3: ='YTD CF'!J3-'YTD CF'!I3 | M3: ='CASH FLOW'!E3-'YTD CF'!J3 | N3: ='YTD CF'!K3 | O3: ='YTD CF'!L3-'YTD CF'!K3 | P3: ='YTD CF'!M3-'YTD CF'!L3 | Q3: ='CASH FLOW'!F3-'YTD CF'!M3 | R3: ='YTD CF'!N3 | S3: ='YTD CF'!O3-'YTD CF'!N3 | T3: ='YTD CF'!P3-'YTD CF'!O3 | U3: ='CASH FLOW'!G3-'YTD CF'!P3 | V3: ='YTD CF'!Q3 | W3: ='YTD CF'!R3-'YTD CF'!Q3 | X3: ='YTD CF'!S3-'YTD CF'!R3 | Y3: ='CASH FLOW'!H3-'YTD CF'!S3
A4: Non-Cash Lease Expense | B4: ='YTD CF'!B4 | C4: ='YTD CF'!C4-'YTD CF'!B4 | D4: ='YTD CF'!D4-'YTD CF'!C4 | E4: ='CASH FLOW'!C4-'YTD CF'!D4 | F4: ='YTD CF'!E4 | G4: ='YTD CF'!F4-'YTD CF'!E4 | H4: ='YTD CF'!G4-'YTD CF'!F4 | I4: ='CASH FLOW'!D4-'YTD CF'!G4 | J4: ='YTD CF'!H4 | K4: ='YTD CF'!I4-'YTD CF'!H4 | L4: ='YTD CF'!J4-'YTD CF'!I4 | M4: ='CASH FLOW'!E4-'YTD CF'!J4 | N4: ='YTD CF'!K4 | O4: ='YTD CF'!L4-'YTD CF'!K4 | P4: ='YTD CF'!M4-'YTD CF'!L4 | Q4: ='CASH FLOW'!F4-'YTD CF'!M4 | R4: ='YTD CF'!N4 | S4: ='YTD CF'!O4-'YTD CF'!N4 | T4: ='YTD CF'!P4-'YTD CF'!O4 | U4: ='CASH FLOW'!G4-'YTD CF'!P4 | V4: ='YTD CF'!Q4 | W4: ='YTD CF'!R4-'YTD CF'!Q4 | X4: ='YTD CF'!S4-'YTD CF'!R4 | Y4: ='CASH FLOW'!H4-'YTD CF'!S4
A5: Gain (Loss) on Disposal of PP&E | B5: ='YTD CF'!B5 | C5: ='YTD CF'!C5-'YTD CF'!B5 | D5: ='YTD CF'!D5-'YTD CF'!C5 | E5: ='CASH FLOW'!C5-'YTD CF'!D5 | F5: ='YTD CF'!E5 | G5: ='YTD CF'!F5-'YTD CF'!E5 | H5: ='YTD CF'!G5-'YTD CF'!F5 | I5: ='CASH FLOW'!D5-'YTD CF'!G5 | J5: ='YTD CF'!H5 | K5: ='YTD CF'!I5-'YTD CF'!H5 | L5: ='YTD CF'!J5-'YTD CF'!I5 | M5: ='CASH FLOW'!E5-'YTD CF'!J5 | N5: ='YTD CF'!K5 | O5: ='YTD CF'!L5-'YTD CF'!K5 | P5: ='YTD CF'!M5-'YTD CF'!L5 | Q5: ='CASH FLOW'!F5-'YTD CF'!M5 | R5: ='YTD CF'!N5 | S5: ='YTD CF'!O5-'YTD CF'!N5 | T5: ='YTD CF'!P5-'YTD CF'!O5 | U5: ='CASH FLOW'!G5-'YTD CF'!P5 | V5: ='YTD CF'!Q5 | W5: ='YTD CF'!R5-'YTD CF'!Q5 | X5: ='YTD CF'!S5-'YTD CF'!R5 | Y5: ='CASH FLOW'!H5-'YTD CF'!S5
A6: Gain on Bang Transaction | B6: ='YTD CF'!B6 | C6: ='YTD CF'!C6-'YTD CF'!B6 | D6: ='YTD CF'!D6-'YTD CF'!C6 | E6: ='CASH FLOW'!C6-'YTD CF'!D6 | F6: ='YTD CF'!E6 | G6: ='YTD CF'!F6-'YTD CF'!E6 | H6: ='YTD CF'!G6-'YTD CF'!F6 | I6: ='CASH FLOW'!D6-'YTD CF'!G6 | J6: ='YTD CF'!H6 | K6: ='YTD CF'!I6-'YTD CF'!H6 | L6: ='YTD CF'!J6-'YTD CF'!I6 | M6: ='CASH FLOW'!E6-'YTD CF'!J6 | N6: ='YTD CF'!K6 | O6: ='YTD CF'!L6-'YTD CF'!K6 | P6: ='YTD CF'!M6-'YTD CF'!L6 | Q6: ='CASH FLOW'!F6-'YTD CF'!M6 | R6: ='YTD CF'!N6 | S6: ='YTD CF'!O6-'YTD CF'!N6 | T6: ='YTD CF'!P6-'YTD CF'!O6 | U6: ='CASH FLOW'!G6-'YTD CF'!P6 | V6: ='YTD CF'!Q6 | W6: ='YTD CF'!R6-'YTD CF'!Q6 | X6: ='YTD CF'!S6-'YTD CF'!R6 | Y6: ='CASH FLOW'!H6-'YTD CF'!S6
A7: Impairment of Intangibles | B7: ='YTD CF'!B7 | C7: ='YTD CF'!C7-'YTD CF'!B7 | D7: ='YTD CF'!D7-'YTD CF'!C7 | E7: ='CASH FLOW'!C7-'YTD CF'!D7 | F7: ='YTD CF'!E7 | G7: ='YTD CF'!F7-'YTD CF'!E7 | H7: ='YTD CF'!G7-'YTD CF'!F7 | I7: ='CASH FLOW'!D7-'YTD CF'!G7 | J7: ='YTD CF'!H7 | K7: ='YTD CF'!I7-'YTD CF'!H7 | L7: ='YTD CF'!J7-'YTD CF'!I7 | M7: ='CASH FLOW'!E7-'YTD CF'!J7 | N7: ='YTD CF'!K7 | O7: ='YTD CF'!L7-'YTD CF'!K7 | P7: ='YTD CF'!M7-'YTD CF'!L7 | Q7: ='CASH FLOW'!F7-'YTD CF'!M7 | R7: ='YTD CF'!N7 | S7: ='YTD CF'!O7-'YTD CF'!N7 | T7: ='YTD CF'!P7-'YTD CF'!O7 | U7: ='CASH FLOW'!G7-'YTD CF'!P7 | V7: ='YTD CF'!Q7 | W7: ='YTD CF'!R7-'YTD CF'!Q7 | X7: ='YTD CF'!S7-'YTD CF'!R7 | Y7: ='CASH FLOW'!H7-'YTD CF'!S7
A8: Impairment of Long-Lived Assets (PP&E) | B8: ='YTD CF'!B8 | C8: ='YTD CF'!C8-'YTD CF'!B8 | D8: ='YTD CF'!D8-'YTD CF'!C8 | E8: ='CASH FLOW'!C8-'YTD CF'!D8 | F8: ='YTD CF'!E8 | G8: ='YTD CF'!F8-'YTD CF'!E8 | H8: ='YTD CF'!G8-'YTD CF'!F8 | I8: ='CASH FLOW'!D8-'YTD CF'!G8 | J8: ='YTD CF'!H8 | K8: ='YTD CF'!I8-'YTD CF'!H8 | L8: ='YTD CF'!J8-'YTD CF'!I8 | M8: ='CASH FLOW'!E8-'YTD CF'!J8 | N8: ='YTD CF'!K8 | O8: ='YTD CF'!L8-'YTD CF'!K8 | P8: ='YTD CF'!M8-'YTD CF'!L8 | Q8: ='CASH FLOW'!F8-'YTD CF'!M8 | R8: ='YTD CF'!N8 | S8: ='YTD CF'!O8-'YTD CF'!N8 | T8: ='YTD CF'!P8-'YTD CF'!O8 | U8: ='CASH FLOW'!G8-'YTD CF'!P8 | V8: ='YTD CF'!Q8 | W8: ='YTD CF'!R8-'YTD CF'!Q8 | X8: ='YTD CF'!S8-'YTD CF'!R8 | Y8: ='CASH FLOW'!H8-'YTD CF'!S8
A9: Stock-Based Compensation | B9: ='YTD CF'!B9 | C9: ='YTD CF'!C9-'YTD CF'!B9 | D9: ='YTD CF'!D9-'YTD CF'!C9 | E9: ='CASH FLOW'!C9-'YTD CF'!D9 | F9: ='YTD CF'!E9 | G9: ='YTD CF'!F9-'YTD CF'!E9 | H9: ='YTD CF'!G9-'YTD CF'!F9 | I9: ='CASH FLOW'!D9-'YTD CF'!G9 | J9: ='YTD CF'!H9 | K9: ='YTD CF'!I9-'YTD CF'!H9 | L9: ='YTD CF'!J9-'YTD CF'!I9 | M9: ='CASH FLOW'!E9-'YTD CF'!J9 | N9: ='YTD CF'!K9 | O9: ='YTD CF'!L9-'YTD CF'!K9 | P9: ='YTD CF'!M9-'YTD CF'!L9 | Q9: ='CASH FLOW'!F9-'YTD CF'!M9 | R9: ='YTD CF'!N9 | S9: ='YTD CF'!O9-'YTD CF'!N9 | T9: ='YTD CF'!P9-'YTD CF'!O9 | U9: ='CASH FLOW'!G9-'YTD CF'!P9 | V9: ='YTD CF'!Q9 | W9: ='YTD CF'!R9-'YTD CF'!Q9 | X9: ='YTD CF'!S9-'YTD CF'!R9 | Y9: ='CASH FLOW'!H9-'YTD CF'!S9
A10: (Benefit) Provision for Deferred Income Taxes | B10: ='YTD CF'!B10 | C10: ='YTD CF'!C10-'YTD CF'!B10 | D10: ='YTD CF'!D10-'YTD CF'!C10 | E10: ='CASH FLOW'!C10-'YTD CF'!D10 | F10: ='YTD CF'!E10 | G10: ='YTD CF'!F10-'YTD CF'!E10 | H10: ='YTD CF'!G10-'YTD CF'!F10 | I10: ='CASH FLOW'!D10-'YTD CF'!G10 | J10: ='YTD CF'!H10 | K10: ='YTD CF'!I10-'YTD CF'!H10 | L10: ='YTD CF'!J10-'YTD CF'!I10 | M10: ='CASH FLOW'!E10-'YTD CF'!J10 | N10: ='YTD CF'!K10 | O10: ='YTD CF'!L10-'YTD CF'!K10 | P10: ='YTD CF'!M10-'YTD CF'!L10 | Q10: ='CASH FLOW'!F10-'YTD CF'!M10 | R10: ='YTD CF'!N10 | S10: ='YTD CF'!O10-'YTD CF'!N10 | T10: ='YTD CF'!P10-'YTD CF'!O10 | U10: ='CASH FLOW'!G10-'YTD CF'!P10 | V10: ='YTD CF'!Q10 | W10: ='YTD CF'!R10-'YTD CF'!Q10 | X10: ='YTD CF'!S10-'YTD CF'!R10 | Y10: ='CASH FLOW'!H10-'YTD CF'!S10
