Workbook

Sheet ASSUMPTIONS
A1: Assumption | B1: Value | C1: Note
A2: Days in Quarter | B2: 91 | C2: Used by DSO/DIO/DPO ratios. Approximation; varies 89-92 by quarter.

Sheet ANNL P&L
B1: FY2021 | C1: FY2022 | D1: FY2023 | E1: FY2024 | F1: FY2025 | G1: FY2026E | H1: FY2027E | I1: FY2028E | J1: FY2029E | K1: FY2030E | L1: FY2031E
A2: Net Sales / Revenue | B2: 79474 | C2: 86392 | D2: 91471 | E2: 91854 | F2: 93925 | G2: ='QTR P&L'!R2+'QTR P&L'!S2+'QTR P&L'!T2+'QTR P&L'!U2 | H2: ='QTR P&L'!V2+'QTR P&L'!W2+'QTR P&L'!X2+'QTR P&L'!Y2 | I2: ='QTR P&L'!Z2+'QTR P&L'!AA2+'QTR P&L'!AB2+'QTR P&L'!AC2 | J2: ='QTR P&L'!AD2+'QTR P&L'!AE2+'QTR P&L'!AF2+'QTR P&L'!AG2 | K2: ='QTR P&L'!AH2+'QTR P&L'!AI2+'QTR P&L'!AJ2+'QTR P&L'!AK2 | L2: ='QTR P&L'!AL2+'QTR P&L'!AM2+'QTR P&L'!AN2+'QTR P&L'!AO2
A3: COGS | B3: -37075 | C3: -40576 | D3: -41881 | E3: -41744 | F3: -43066 | G3: ='QTR P&L'!R3+'QTR P&L'!S3+'QTR P&L'!T3+'QTR P&L'!U3 | H3: ='QTR P&L'!V3+'QTR P&L'!W3+'QTR P&L'!X3+'QTR P&L'!Y3 | I3: ='QTR P&L'!Z3+'QTR P&L'!AA3+'QTR P&L'!AB3+'QTR P&L'!AC3 | J3: ='QTR P&L'!AD3+'QTR P&L'!AE3+'QTR P&L'!AF3+'QTR P&L'!AG3 | K3: ='QTR P&L'!AH3+'QTR P&L'!AI3+'QTR P&L'!AJ3+'QTR P&L'!AK3 | L3: ='QTR P&L'!AL3+'QTR P&L'!AM3+'QTR P&L'!AN3+'QTR P&L'!AO3
A4: Gross Profit (Loss) | B4: =B2+B3 | C4: =C2+C3 | D4: =D2+D3 | E4: =E2+E3 | F4: =F2+F3 | G4: =G2+G3 | H4: =H2+H3 | I4: =I2+I3 | ... L4: =L2+L3
A5: SG&A | B5: -31237 | C5: -34459 | D5: -36677 | E5: -37190 | F5: -37368 | G5: ='QTR P&L'!R5+'QTR P&L'!S5+'QTR P&L'!T5+'QTR P&L'!U5 | H5: ='QTR P&L'!V5+'QTR P&L'!W5+'QTR P&L'!X5+'QTR P&L'!Y5 | I5: ='QTR P&L'!Z5+'QTR P&L'!AA5+'QTR P&L'!AB5+'QTR P&L'!AC5 | J5: ='QTR P&L'!AD5+'QTR P&L'!AE5+'QTR P&L'!AF5+'QTR P&L'!AG5 | K5: ='QTR P&L'!AH5+'QTR P&L'!AI5+'QTR P&L'!AJ5+'QTR P&L'!AK5 | L5: ='QTR P&L'!AL5+'QTR P&L'!AM5+'QTR P&L'!AN5+'QTR P&L'!AO5
A6: Gain on Juice Transaction | B6: 0 | C6: -3321 | D6: 0 | E6: 0 | F6: 0 | G6: ='QTR P&L'!R6+'QTR P&L'!S6+'QTR P&L'!T6+'QTR P&L'!U6 | H6: ='QTR P&L'!V6+'QTR P&L'!W6+'QTR P&L'!X6+'QTR P&L'!Y6 | I6: ='QTR P&L'!Z6+'QTR P&L'!AA6+'QTR P&L'!AB6+'QTR P&L'!AC6 | J6: ='QTR P&L'!AD6+'QTR P&L'!AE6+'QTR P&L'!AF6+'QTR P&L'!AG6 | K6: ='QTR P&L'!AH6+'QTR P&L'!AI6+'QTR P&L'!AJ6+'QTR P&L'!AK6 | L6: ='QTR P&L'!AL6+'QTR P&L'!AM6+'QTR P&L'!AN6+'QTR P&L'!AO6
A7: Impairment of Intangibles | B7: 0 | C7: -3166 | D7: -927 | E7: -33 | F7: -1993 | G7: ='QTR P&L'!R7+'QTR P&L'!S7+'QTR P&L'!T7+'QTR P&L'!U7 | H7: ='QTR P&L'!V7+'QTR P&L'!W7+'QTR P&L'!X7+'QTR P&L'!Y7 | I7: ='QTR P&L'!Z7+'QTR P&L'!AA7+'QTR P&L'!AB7+'QTR P&L'!AC7 | J7: ='QTR P&L'!AD7+'QTR P&L'!AE7+'QTR P&L'!AF7+'QTR P&L'!AG7 | K7: ='QTR P&L'!AH7+'QTR P&L'!AI7+'QTR P&L'!AJ7+'QTR P&L'!AK7 | L7: ='QTR P&L'!AL7+'QTR P&L'!AM7+'QTR P&L'!AN7+'QTR P&L'!AO7
A8: Income (Loss) from Operations | B8: =B4+SUM(B5:B7) | C8: =C4+SUM(C5:C7) | D8: =D4+SUM(D5:D7) | E8: =E4+SUM(E5:E7) | F8: =F4+SUM(F5:F7) | G8: =G4+SUM(G5:G7) | H8: =H4+SUM(H5:H7) | I8: =I4+SUM(I5:I7) | ... L8: =L4+SUM(L5:L7)
A9: Other Pension and OPEB Benefits Income (Expense) | B9: 522 | C9: 132 | D9: 250 | E9: -22 | F9: -133 | G9: ='QTR P&L'!R9+'QTR P&L'!S9+'QTR P&L'!T9+'QTR P&L'!U9 | H9: ='QTR P&L'!V9+'QTR P&L'!W9+'QTR P&L'!X9+'QTR P&L'!Y9 | I9: ='QTR P&L'!Z9+'QTR P&L'!AA9+'QTR P&L'!AB9+'QTR P&L'!AC9 | J9: ='QTR P&L'!AD9+'QTR P&L'!AE9+'QTR P&L'!AF9+'QTR P&L'!AG9 | K9: ='QTR P&L'!AH9+'QTR P&L'!AI9+'QTR P&L'!AJ9+'QTR P&L'!AK9 | L9: ='QTR P&L'!AL9+'QTR P&L'!AM9+'QTR P&L'!AN9+'QTR P&L'!AO9
A10: Interest Income (Expense) | B10: -1863 | C10: -939 | D10: -819 | E10: -919 | F10: -1121 | G10: ='QTR P&L'!R10+'QTR P&L'!S10+'QTR P&L'!T10+'QTR P&L'!U10 | H10: ='QTR P&L'!V10+'QTR P&L'!W10+'QTR P&L'!X10+'QTR P&L'!Y10 | I10: ='QTR P&L'!Z10+'QTR P&L'!AA10+'QTR P&L'!AB10+'QTR P&L'!AC10 | J10: ='QTR P&L'!AD10+'QTR P&L'!AE10+'QTR P&L'!AF10+'QTR P&L'!AG10 | K10: ='QTR P&L'!AH10+'QTR P&L'!AI10+'QTR P&L'!AJ10+'QTR P&L'!AK10 | L10: ='QTR P&L'!AL10+'QTR P&L'!AM10+'QTR P&L'!AN10+'QTR P&L'!AO10
A11: Pre-Tax Income (Loss) | B11: =B8+SUM(B9:B10) | C11: =C8+SUM(C9:C10) | D11: =D8+SUM(D9:D10) | E11: =E8+SUM(E9:E10) | F11: =F8+SUM(F9:F10) | G11: =G8+SUM(G9:G10) | H11: =H8+SUM(H9:H10) | I11: =I8+SUM(I9:I10) | ... L11: =L8+SUM(L9:L10)
A12: Income Tax (Expense) Benefit | B12: -2142 | C12: -1727 | D12: -2262 | E12: -2320 | F12: -1949 | G12: ='QTR P&L'!R12+'QTR P&L'!S12+'QTR P&L'!T12+'QTR P&L'!U12 | H12: ='QTR P&L'!V12+'QTR P&L'!W12+'QTR P&L'!X12+'QTR P&L'!Y12 | I12: ='QTR P&L'!Z12+'QTR P&L'!AA12+'QTR P&L'!AB12+'QTR P&L'!AC12 | J12: ='QTR P&L'!AD12+'QTR P&L'!AE12+'QTR P&L'!AF12+'QTR P&L'!AG12 | K12: ='QTR P&L'!AH12+'QTR P&L'!AI12+'QTR P&L'!AJ12+'QTR P&L'!AK12 | L12: ='QTR P&L'!AL12+'QTR P&L'!AM12+'QTR P&L'!AN12+'QTR P&L'!AO12
A13: Net Income (Loss) | B13: =B11+B12 | C13: =C11+C12 | D13: =D11+D12 | E13: =E11+E12 | F13: =F11+F12 | G13: =G11+G12 | H13: =H11+H12 | I13: =I11+I12 | ... L13: =L11+L12
A14: Net Income (Loss) Attributable to Noncontrolling Interest | B14: 61 | C14: 68 | D14: 81 | E14: 48 | F14: 55 | G14: ='QTR P&L'!R14+'QTR P&L'!S14+'QTR P&L'!T14+'QTR P&L'!U14 | H14: ='QTR P&L'!V14+'QTR P&L'!W14+'QTR P&L'!X14+'QTR P&L'!Y14 | I14: ='QTR P&L'!Z14+'QTR P&L'!AA14+'QTR P&L'!AB14+'QTR P&L'!AC14 | J14: ='QTR P&L'!AD14+'QTR P&L'!AE14+'QTR P&L'!AF14+'QTR P&L'!AG14 | K14: ='QTR P&L'!AH14+'QTR P&L'!AI14+'QTR P&L'!AJ14+'QTR P&L'!AK14 | L14: ='QTR P&L'!AL14+'QTR P&L'!AM14+'QTR P&L'!AN14+'QTR P&L'!AO14
A15: Net Income (Loss) Less NCI | B15: =B13-B14 | C15: =C13-C14 | D15: =D13-D14 | E15: =E13-E14 | F15: =F13-F14 | G15: =G13-G14 | H15: =H13-H14 | I15: =I13-I14 | ... L15: =L13-L14
A16: Basic Earnings (Loss) per Share | B16: 5.51 | C16: 6.45 | D16: 6.59 | E16: 6.97 | F16: 6.02
A17: Diluted Earnings (Loss) per Share | B17: 5.49 | C17: 6.42 | D17: 6.56 | E17: 6.95 | F17: 6
A18: Weighted Average Shares Outstanding (Basic) | B18: 1382000000 | C18: 1380000000 | D18: 1376000000 | E18: 1373000000 | F18: 1369000000
A19: Weighted Average Shares Outstanding (Diluted) | B19: 1389000000 | C19: 1387000000 | D19: 1383000000 | E19: 1378000000 | F19: 1373000000

Sheet BALANCE SHEET
B1: FY2022 | C1: FY2023 | D1: FY2024 | E1: FY2025 | F1: FY2026E | G1: FY2027E | H1: FY2028E | I1: FY2029E | J1: FY2030E | K1: FY2031E
A2: Cash & Cash Equivalents | B2: 4954 | C2: 9711 | D2: 8505 | E2: 9159 | F2: ='QTR BS'!R2 | G2: ='QTR BS'!V2 | H2: ='QTR BS'!Z2 | I2: ='QTR BS'!AD2 | J2: ='QTR BS'!AH2 | K2: ='QTR BS'!AL2
A3: Short-Term Investments | B3: 394 | C3: 292 | D3: 761 | E3: 371 | F3: ='QTR BS'!R3 | G3: ='QTR BS'!V3 | H3: ='QTR BS'!Z3 | I3: ='QTR BS'!AD3 | J3: ='QTR BS'!AH3 | K3: ='QTR BS'!AL3
A4: Accounts Receivable | B4: 10163 | C4: 10815 | D4: 10333 | E4: 11506 | F4: ='QTR BS'!R4 | G4: ='QTR BS'!V4 | H4: ='QTR BS'!Z4 | I4: ='QTR BS'!AD4 | J4: ='QTR BS'!AH4 | K4: ='QTR BS'!AL4
A5: Inventories | B5: 5222 | C5: 5334 | D5: 5306 | E5: 5845 | F5: ='QTR BS'!R5 | G5: ='QTR BS'!V5 | H5: ='QTR BS'!Z5 | I5: ='QTR BS'!AD5 | J5: ='QTR BS'!AH5 | K5: ='QTR BS'!AL5
A6: Prepaid Expenses | B6: 806 | C6: 798 | D6: 921 | E6: 1068 | F6: ='QTR BS'!R6 | G6: ='QTR BS'!V6 | H6: ='QTR BS'!Z6 | I6: ='QTR BS'!AD6 | J6: ='QTR BS'!AH6 | K6: ='QTR BS'!AL6
A7: Total Current Assets | B7: =SUM(B2:B6) | C7: =SUM(C2:C6) | D7: =SUM(D2:D6) | E7: =SUM(E2:E6) | F7: =SUM(F2:F6) | G7: =SUM(G2:G6) | H7: =SUM(H2:H6) | I7: =SUM(I2:I6) | ... K7: =SUM(K2:K6)
A8: Net PP&E | B8: 24291 | C8: 27039 | D8: 28008 | E8: 29905 | F8: ='QTR BS'!R8 | G8: ='QTR BS'!V8 | H8: ='QTR BS'!Z8 | I8: ='QTR BS'!AD8 | J8: ='QTR BS'!AH8 | K8: ='QTR BS'!AL8
A9: Intangible Assets | B9: 15586 | C9: 14929 | D9: 14801 | E9: 15066 | F9: ='QTR BS'!R9 | G9: ='QTR BS'!V9 | H9: ='QTR BS'!Z9 | I9: ='QTR BS'!AD9 | J9: ='QTR BS'!AH9 | K9: ='QTR BS'!AL9
A10: Goodwill | B10: 18202 | C10: 17728 | D10: 17534 | E10: 18916 | F10: ='QTR BS'!R10 | G10: ='QTR BS'!V10 | H10: ='QTR BS'!Z10 | I10: ='QTR BS'!AD10 | J10: ='QTR BS'!AH10 | K10: ='QTR BS'!AL10
A11: Equity Method Investments | B11: 3073 | C11: 2714 | D11: 1985 | E11: 2038 | F11: ='QTR BS'!R11 | G11: ='QTR BS'!V11 | H11: ='QTR BS'!Z11 | I11: ='QTR BS'!AD11 | J11: ='QTR BS'!AH11 | K11: ='QTR BS'!AL11
A12: Deferred Tax Assets | B12: 4204 | C12: 4474 | D12: 4362 | E12: 4541 | F12: ='QTR BS'!R12 | G12: ='QTR BS'!V12 | H12: ='QTR BS'!Z12 | I12: ='QTR BS'!AD12 | J12: ='QTR BS'!AH12 | K12: ='QTR BS'!AL12
A13: Other Non-Current Assets | B13: 5292 | C13: 6661 | D13: 6951 | E13: 8984 | F13: ='QTR BS'!R13 | G13: ='QTR BS'!V13 | H13: ='QTR BS'!Z13 | I13: ='QTR BS'!AD13 | J13: ='QTR BS'!AH13 | K13: ='QTR BS'!AL13
A14: Total Assets | B14: =B7+SUM(B8:B13) | C14: =C7+SUM(C8:C13) | D14: =D7+SUM(D8:D13) | E14: =E7+SUM(E8:E13) | F14: =F7+SUM(F8:F13) | G14: =G7+SUM(G8:G13) | H14: =H7+SUM(H8:H13) | I14: =I7+SUM(I8:I13) | ... K14: =K7+SUM(K8:K13)
A15: Short-Term Debt Obligations | B15: 3414 | C15: 6510 | D15: 7082 | E15: 6861 | F15: ='QTR BS'!R15 | G15: ='QTR BS'!V15 | H15: ='QTR BS'!Z15 | I15: ='QTR BS'!AD15 | J15: ='QTR BS'!AH15 | K15: ='QTR BS'!AL15
A16: Accrued Expenses | B16: 23371 | C16: 25137 | D16: 24454 | E16: 25903 | F16: ='QTR BS'!R16 | G16: ='QTR BS'!V16 | H16: ='QTR BS'!Z16 | I16: ='QTR BS'!AD16 | J16: ='QTR BS'!AH16 | K16: ='QTR BS'!AL16
A17: Total Current Liabilities | B17: =SUM(B15:B16) | C17: =SUM(C15:C16) | D17: =SUM(D15:D16) | E17: =SUM(E15:E16) | F17: =SUM(F15:F16) | G17: =SUM(G15:G16) | H17: =SUM(H15:H16) | I17: =SUM(I15:I16) | ... K17: =SUM(K15:K16)
A18: Long-Term Debt | B18: 35657 | C18: 37595 | D18: 37224 | E18: 42321 | F18: ='QTR BS'!R18 | G18: ='QTR BS'!V18 | H18: ='QTR BS'!Z18 | I18: ='QTR BS'!AD18 | J18: ='QTR BS'!AH18 | K18: ='QTR BS'!AL18
A19: Deferred Tax Liability | B19: 4133 | C19: 3895 | D19: 3484 | E19: 3802 | F19: ='QTR BS'!R19 | G19: ='QTR BS'!V19 | H19: ='QTR BS'!Z19 | I19: ='QTR BS'!AD19 | J19: ='QTR BS'!AH19 | K19: ='QTR BS'!AL19
A20: Other Non-Current Liabilities | B20: 8339 | C20: 8721 | D20: 9052 | E20: 7965 | F20: ='QTR BS'!R20 | G20: ='QTR BS'!V20 | H20: ='QTR BS'!Z20 | I20: ='QTR BS'!AD20 | J20: ='QTR BS'!AH20 | K20: ='QTR BS'!AL20
A21: Total Liabilities | B21: =B17+SUM(B18:B20) | C21: =C17+SUM(C18:C20) | D21: =D17+SUM(D18:D20) | E21: =E17+SUM(E18:E20) | F21: =F17+SUM(F18:F20) | G21: =G17+SUM(G18:G20) | H21: =H17+SUM(H18:H20) | I21: =I17+SUM(I18:I20) | ... K21: =K17+SUM(K18:K20)
A22: Common Stock | B22: 23 | C22: 23 | D22: 23 | E22: 23 | F22: ='QTR BS'!R22 | G22: ='QTR BS'!V22 | H22: ='QTR BS'!Z22 | I22: ='QTR BS'!AD22 | J22: ='QTR BS'!AH22 | K22: ='QTR BS'!AL22
A23: Additional Paid-in Capital | B23: 4134 | C23: 4261 | D23: 4385 | E23: 4451 | F23: ='QTR BS'!R23 | G23: ='QTR BS'!V23 | H23: ='QTR BS'!Z23 | I23: ='QTR BS'!AD23 | J23: ='QTR BS'!AH23 | K23: ='QTR BS'!AL23
A24: Retained Earnings (Accumulated Deficit) | B24: 67800 | C24: 70035 | D24: 72266 | E24: 72788 | F24: ='QTR BS'!R24 | G24: ='QTR BS'!V24 | H24: ='QTR BS'!Z24 | I24: ='QTR BS'!AD24 | J24: ='QTR BS'!AH24 | K24: ='QTR BS'!AL24
A25: Accumulated Other Comprehensive Income (Loss) | B25: -15302 | C25: -15534 | D25: -17612 | E25: -15024 | F25: ='QTR BS'!R25 | G25: ='QTR BS'!V25 | H25: ='QTR BS'!Z25 | I25: ='QTR BS'!AD25 | J25: ='QTR BS'!AH25 | K25: ='QTR BS'!AL25
A26: Treasury Stock | B26: -39506 | C26: -40282 | D26: -41021 | E26: -41832 | F26: ='QTR BS'!R26 | G26: ='QTR BS'!V26 | H26: ='QTR BS'!Z26 | I26: ='QTR BS'!AD26 | J26: ='QTR BS'!AH26 | K26: ='QTR BS'!AL26
A27: Noncontrolling Interest | B27: 124 | C27: 134 | D27: 130 | E27: 141 | F27: ='QTR BS'!R27 | G27: ='QTR BS'!V27 | H27: ='QTR BS'!Z27 | I27: ='QTR BS'!AD27 | J27: ='QTR BS'!AH27 | K27: ='QTR BS'!AL27
A28: Total Stockholders' Equity | B28: =SUM(B22:B27) | C28: =SUM(C22:C27) | D28: =SUM(D22:D27) | E28: =SUM(E22:E27) | F28: =SUM(F22:F27) | G28: =SUM(G22:G27) | H28: =SUM(H22:H27) | I28: =SUM(I22:I27) | ... K28: =SUM(K22:K27)
A29: Total Liabilities, Mezzanine & Stockholders' Equity | B29: =B21+B28 | C29: =C21+C28 | D29: =D21+D28 | E29: =E21+E28 | F29: =F21+F28 | G29: =G21+G28 | H29: =H21+H28 | I29: =I21+I28 | ... K29: =K21+K28

Sheet CASH FLOW
B1: FY2021 | C1: FY2022 | D1: FY2023 | E1: FY2024 | F1: FY2025 | G1: FY2026E | H1: FY2027E | I1: FY2028E | J1: FY2029E | K1: FY2030E | L1: FY2031E
A2: Net Income (Loss) | B2: 7679 | C2: 8978 | D2: 9155 | E2: 9626 | F2: 8295 | G2: ='QTR CF'!R2+'QTR CF'!S2+'QTR CF'!T2+'QTR CF'!U2 | H2: ='QTR CF'!V2+'QTR CF'!W2+'QTR CF'!X2+'QTR CF'!Y2 | I2: ='QTR CF'!Z2+'QTR CF'!AA2+'QTR CF'!AB2+'QTR CF'!AC2 | J2: ='QTR CF'!AD2+'QTR CF'!AE2+'QTR CF'!AF2+'QTR CF'!AG2 | K2: ='QTR CF'!AH2+'QTR CF'!AI2+'QTR CF'!AJ2+'QTR CF'!AK2 | L2: ='QTR CF'!AL2+'QTR CF'!AM2+'QTR CF'!AN2+'QTR CF'!AO2
A3: Depreciation & Amortization | B3: 2710 | C3: 2763 | D3: 2948 | E3: 3160 | F3: 3451 | G3: ='QTR CF'!R3+'QTR CF'!S3+'QTR CF'!T3+'QTR CF'!U3 | H3: ='QTR CF'!V3+'QTR CF'!W3+'QTR CF'!X3+'QTR CF'!Y3 | I3: ='QTR CF'!Z3+'QTR CF'!AA3+'QTR CF'!AB3+'QTR CF'!AC3 | J3: ='QTR CF'!AD3+'QTR CF'!AE3+'QTR CF'!AF3+'QTR CF'!AG3 | K3: ='QTR CF'!AH3+'QTR CF'!AI3+'QTR CF'!AJ3+'QTR CF'!AK3 | L3: ='QTR CF'!AL3+'QTR CF'!AM3+'QTR CF'!AN3+'QTR CF'!AO3
A4: Gain on Juice Transaction | B4: 0 | C4: -3321 | D4: 0 | E4: 0 | F4: 0 | G4: ='QTR CF'!R4+'QTR CF'!S4+'QTR CF'!T4+'QTR CF'!U4 | H4: ='QTR CF'!V4+'QTR CF'!W4+'QTR CF'!X4+'QTR CF'!Y4 | I4: ='QTR CF'!Z4+'QTR CF'!AA4+'QTR CF'!AB4+'QTR CF'!AC4 | J4: ='QTR CF'!AD4+'QTR CF'!AE4+'QTR CF'!AF4+'QTR CF'!AG4 | K4: ='QTR CF'!AH4+'QTR CF'!AI4+'QTR CF'!AJ4+'QTR CF'!AK4 | L4: ='QTR CF'!AL4+'QTR CF'!AM4+'QTR CF'!AN4+'QTR CF'!AO4
A5: Impairment and Other Charges | B5: 0 | C5: 3618 | D5: 1230 | E5: 714 | F5: 1946 | G5: ='QTR CF'!R5+'QTR CF'!S5+'QTR CF'!T5+'QTR CF'!U5 | H5: ='QTR CF'!V5+'QTR CF'!W5+'QTR CF'!X5+'QTR CF'!Y5 | I5: ='QTR CF'!Z5+'QTR CF'!AA5+'QTR CF'!AB5+'QTR CF'!AC5 | J5: ='QTR CF'!AD5+'QTR CF'!AE5+'QTR CF'!AF5+'QTR CF'!AG5 | K5: ='QTR CF'!AH5+'QTR CF'!AI5+'QTR CF'!AJ5+'QTR CF'!AK5 | L5: ='QTR CF'!AL5+'QTR CF'!AM5+'QTR CF'!AN5+'QTR CF'!AO5
A6: Indirect Tax Impact | B6: 0 | C6: 0 | D6: 0 | E6: 218 | F6: 0 | G6: ='QTR CF'!R6+'QTR CF'!S6+'QTR CF'!T6+'QTR CF'!U6 | H6: ='QTR CF'!V6+'QTR CF'!W6+'QTR CF'!X6+'QTR CF'!Y6 | I6: ='QTR CF'!Z6+'QTR CF'!AA6+'QTR CF'!AB6+'QTR CF'!AC6 | J6: ='QTR CF'!AD6+'QTR CF'!AE6+'QTR CF'!AF6+'QTR CF'!AG6 | K6: ='QTR CF'!AH6+'QTR CF'!AI6+'QTR CF'!AJ6+'QTR CF'!AK6 | L6: ='QTR CF'!AL6+'QTR CF'!AM6+'QTR CF'!AN6+'QTR CF'!AO6
A7: Product Recall Impact | B7: 0 | C7: 0 | D7: 136 | E7: 187 | F7: 0 | G7: ='QTR CF'!R7+'QTR CF'!S7+'QTR CF'!T7+'QTR CF'!U7 | H7: ='QTR CF'!V7+'QTR CF'!W7+'QTR CF'!X7+'QTR CF'!Y7 | I7: ='QTR CF'!Z7+'QTR CF'!AA7+'QTR CF'!AB7+'QTR CF'!AC7 | J7: ='QTR CF'!AD7+'QTR CF'!AE7+'QTR CF'!AF7+'QTR CF'!AG7 | K7: ='QTR CF'!AH7+'QTR CF'!AI7+'QTR CF'!AJ7+'QTR CF'!AK7 | L7: ='QTR CF'!AL7+'QTR CF'!AM7+'QTR CF'!AN7+'QTR CF'!AO7
A8: Cash Payments for Product Recall | B8: 0 | C8: 0 | D8: 0 | E8: -148 | F8: -6 | G8: ='QTR CF'!R8+'QTR CF'!S8+'QTR CF'!T8+'QTR CF'!U8 | H8: ='QTR CF'!V8+'QTR CF'!W8+'QTR CF'!X8+'QTR CF'!Y8 | I8: ='QTR CF'!Z8+'QTR CF'!AA8+'QTR CF'!AB8+'QTR CF'!AC8 | J8: ='QTR CF'!AD8+'QTR CF'!AE8+'QTR CF'!AF8+'QTR CF'!AG8 | K8: ='QTR CF'!AH8+'QTR CF'!AI8+'QTR CF'!AJ8+'QTR CF'!AK8 | L8: ='QTR CF'!AL8+'QTR CF'!AM8+'QTR CF'!AN8+'QTR CF'!AO8
A9: Operating Lease ROU Asset Amortization | B9: 505 | C9: 517 | D9: 570 | E9: 655 | F9: 727 | G9: ='QTR CF'!R9+'QTR CF'!S9+'QTR CF'!T9+'QTR CF'!U9 | H9: ='QTR CF'!V9+'QTR CF'!W9+'QTR CF'!X9+'QTR CF'!Y9 | I9: ='QTR CF'!Z9+'QTR CF'!AA9+'QTR CF'!AB9+'QTR CF'!AC9 | J9: ='QTR CF'!AD9+'QTR CF'!AE9+'QTR CF'!AF9+'QTR CF'!AG9 | K9: ='QTR CF'!AH9+'QTR CF'!AI9+'QTR CF'!AJ9+'QTR CF'!AK9 | L9: ='QTR CF'!AL9+'QTR CF'!AM9+'QTR CF'!AN9+'QTR CF'!AO9
A10: Stock-Based Compensation | B10: 301 | C10: 343 | D10: 380 | E10: 362 | F10: 288 | G10: ='QTR CF'!R10+'QTR CF'!S10+'QTR CF'!T10+'QTR CF'!U10 | H10: ='QTR CF'!V10+'QTR CF'!W10+'QTR CF'!X10+'QTR CF'!Y10 | I10: ='QTR CF'!Z10+'QTR CF'!AA10+'QTR CF'!AB10+'QTR CF'!AC10 | J10: ='QTR CF'!AD10+'QTR CF'!AE10+'QTR CF'!AF10+'QTR CF'!AG10 | K10: ='QTR CF'!AH10+'QTR CF'!AI10+'QTR CF'!AJ10+'QTR CF'!AK10 | L10: ='QTR CF'!AL10+'QTR CF'!AM10+'QTR CF'!AN10+'QTR CF'!AO10
A11: Restructuring and Asset Impairment Charges | B11: 247 | C11: 411 | D11: 445 | E11: 727 | F11: 983 | G11: ='QTR CF'!R11+'QTR CF'!S11+'QTR CF'!T11+'QTR CF'!U11 | H11: ='QTR CF'!V11+'QTR CF'!W11+'QTR CF'!X11+'QTR CF'!Y11 | I11: ='QTR CF'!Z11+'QTR CF'!AA11+'QTR CF'!AB11+'QTR CF'!AC11 | J11: ='QTR CF'!AD11+'QTR CF'!AE11+'QTR CF'!AF11+'QTR CF'!AG11 | K11: ='QTR CF'!AH11+'QTR CF'!AI11+'QTR CF'!AJ11+'QTR CF'!AK11 | L11: ='QTR CF'!AL11+'QTR CF'!AM11+'QTR CF'!AN11+'QTR CF'!AO11
A12: Cash Payments for Restructuring | B12: -256 | C12: -224 | D12: -434 | E12: -436 | F12: -796 | G12: ='QTR CF'!R12+'QTR CF'!S12+'QTR CF'!T12+'QTR CF'!U12 | H12: ='QTR CF'!V12+'QTR CF'!W12+'QTR CF'!X12+'QTR CF'!Y12 | I12: ='QTR CF'!Z12+'QTR CF'!AA12+'QTR CF'!AB12+'QTR CF'!AC12 | J12: ='QTR CF'!AD12+'QTR CF'!AE12+'QTR CF'!AF12+'QTR CF'!AG12 | K12: ='QTR CF'!AH12+'QTR CF'!AI12+'QTR CF'!AJ12+'QTR CF'!AK12 | L12: ='QTR CF'!AL12+'QTR CF'!AM12+'QTR CF'!AN12+'QTR CF'!AO12
A13: Acquisition and Divestiture-Related Charges | B13: -4 | C13: 80 | D13: 41 | E13: 0 | F13: 453 | G13: ='QTR CF'!R13+'QTR CF'!S13+'QTR CF'!T13+'QTR CF'!U13 | H13: ='QTR CF'!V13+'QTR CF'!W13+'QTR CF'!X13+'QTR CF'!Y13 | I13: ='QTR CF'!Z13+'QTR CF'!AA13+'QTR CF'!AB13+'QTR CF'!AC13 | J13: ='QTR CF'!AD13+'QTR CF'!AE13+'QTR CF'!AF13+'QTR CF'!AG13 | K13: ='QTR CF'!AH13+'QTR CF'!AI13+'QTR CF'!AJ13+'QTR CF'!AK13 | L13: ='QTR CF'!AL13+'QTR CF'!AM13+'QTR CF'!AN13+'QTR CF'!AO13
... A25: Other Operating Items | B25: 375 | C25: -359 | D25: 189 | E25: -307 | F25: -712 | G25: ='QTR CF'!R25+'QTR CF'!S25+'QTR CF'!T25+'QTR CF'!U25 | H25: ='QTR CF'!V25+'QTR CF'!W25+'QTR CF'!X25+'QTR CF'!Y25 | I25: ='QTR CF'!Z25+'QTR CF'!AA25+'QTR CF'!AB25+'QTR CF'!AC25 | J25: ='QTR CF'!AD25+'QTR CF'!AE25+'QTR CF'!AF25+'QTR CF'!AG25 | K25: ='QTR CF'!AH25+'QTR CF'!AI25+'QTR CF'!AJ25+'QTR CF'!AK25 | L25: ='QTR CF'!AL25+'QTR CF'!AM25+'QTR CF'!AN25+'QTR CF'!AO25
A26: Cash Flow from Operations | B26: =SUM(B2:B25) | C26: =SUM(C2:C25) | D26: =SUM(D2:D25) | E26: =SUM(E2:E25) | F26: =SUM(F2:F25) | G26: =SUM(G2:G25) | H26: =SUM(H2:H25) | I26: =SUM(I2:I25) | ... L26: =SUM(L2:L25)
A27: Purchase of PP&E | B27: -4625 | C27: -5207 | D27: -5518 | E27: -5318 | F27: -4415 | G27: ='QTR CF'!R27+'QTR CF'!S27+'QTR CF'!T27+'QTR CF'!U27 | H27: ='QTR CF'!V27+'QTR CF'!W27+'QTR CF'!X27+'QTR CF'!Y27 | I27: ='QTR CF'!Z27+'QTR CF'!AA27+'QTR CF'!AB27+'QTR CF'!AC27 | J27: ='QTR CF'!AD27+'QTR CF'!AE27+'QTR CF'!AF27+'QTR CF'!AG27 | K27: ='QTR CF'!AH27+'QTR CF'!AI27+'QTR CF'!AJ27+'QTR CF'!AK27 | L27: ='QTR CF'!AL27+'QTR CF'!AM27+'QTR CF'!AN27+'QTR CF'!AO27
A28: Proceeds from Sale of Assets | B28: 166 | C28: 251 | D28: 198 | E28: 342 | F28: 528 | G28: ='QTR CF'!R28+'QTR CF'!S28+'QTR CF'!T28+'QTR CF'!U28 | H28: ='QTR CF'!V28+'QTR CF'!W28+'QTR CF'!X28+'QTR CF'!Y28 | I28: ='QTR CF'!Z28+'QTR CF'!AA28+'QTR CF'!AB28+'QTR CF'!AC28 | J28: ='QTR CF'!AD28+'QTR CF'!AE28+'QTR CF'!AF28+'QTR CF'!AG28 | K28: ='QTR CF'!AH28+'QTR CF'!AI28+'QTR CF'!AJ28+'QTR CF'!AK28 | L28: ='QTR CF'!AL28+'QTR CF'!AM28+'QTR CF'!AN28+'QTR CF'!AO28
A29: Acquisitions, Net of Cash Acquired | B29: -61 | C29: -873 | D29: -314 | E29: -256 | F29: -3391 | G29: ='QTR CF'!R29+'QTR CF'!S29+'QTR CF'!T29+'QTR CF'!U29 | H29: ='QTR CF'!V29+'QTR CF'!W29+'QTR CF'!X29+'QTR CF'!Y29 | I29: ='QTR CF'!Z29+'QTR CF'!AA29+'QTR CF'!AB29+'QTR CF'!AC29 | J29: ='QTR CF'!AD29+'QTR CF'!AE29+'QTR CF'!AF29+'QTR CF'!AG29 | K29: ='QTR CF'!AH29+'QTR CF'!AI29+'QTR CF'!AJ29+'QTR CF'!AK29 | L29: ='QTR CF'!AL29+'QTR CF'!AM29+'QTR CF'!AN29+'QTR CF'!AO29
A30: Proceeds from Juice Transaction | B30: 0 | C30: 3456 | D30: 0 | E30: 0 | F30: 0 | G30: ='QTR CF'!R30+'QTR CF'!S30+'QTR CF'!T30+'QTR CF'!U30 | H30: ='QTR CF'!V30+'QTR CF'!W30+'QTR CF'!X30+'QTR CF'!Y30 | I30: ='QTR CF'!Z30+'QTR CF'!AA30+'QTR CF'!AB30+'QTR CF'!AC30 | J30: ='QTR CF'!AD30+'QTR CF'!AE30+'QTR CF'!AF30+'QTR CF'!AG30 | K30: ='QTR CF'!AH30+'QTR CF'!AI30+'QTR CF'!AJ30+'QTR CF'!AK30 | L30: ='QTR CF'!AL30+'QTR CF'!AM30+'QTR CF'!AN30+'QTR CF'!AO30
A31: Proceeds from Divestitures of Businesses | B31: 169 | C31: 49 | D31: 75 | E31: 166 | F31: 39 | G31: ='QTR CF'!R31+'QTR CF'!S31+'QTR CF'!T31+'QTR CF'!U31 | H31: ='QTR CF'!V31+'QTR CF'!W31+'QTR CF'!X31+'QTR CF'!Y31 | I31: ='QTR CF'!Z31+'QTR CF'!AA31+'QTR CF'!AB31+'QTR CF'!AC31 | J31: ='QTR CF'!AD31+'QTR CF'!AE31+'QTR CF'!AF31+'QTR CF'!AG31 | K31: ='QTR CF'!AH31+'QTR CF'!AI31+'QTR CF'!AJ31+'QTR CF'!AK31 | L31: ='QTR CF'!AL31+'QTR CF'!AM31+'QTR CF'!AN31+'QTR CF'!AO31
A32: Net Change in Short-Term Investments | B32: 1077 | C32: -117 | D32: 16 | E32: -420 | F32: 460 | G32: ='QTR CF'!R32+'QTR CF'!S32+'QTR CF'!T32+'QTR CF'!U32 | H32: ='QTR CF'!V32+'QTR CF'!W32+'QTR CF'!X32+'QTR CF'!Y32 | I32: ='QTR CF'!Z32+'QTR CF'!AA32+'QTR CF'!AB32+'QTR CF'!AC32 | J32: ='QTR CF'!AD32+'QTR CF'!AE32+'QTR CF'!AF32+'QTR CF'!AG32 | K32: ='QTR CF'!AH32+'QTR CF'!AI32+'QTR CF'!AJ32+'QTR CF'!AK32 | L32: ='QTR CF'!AL32+'QTR CF'!AM32+'QTR CF'!AN32+'QTR CF'!AO32
A33: Other Investing Activities | B33: 5 | C33: 11 | D33: 48 | E33: 14 | F33: -100 | G33: ='QTR CF'!R33+'QTR CF'!S33+'QTR CF'!T33+'QTR CF'!U33 | H33: ='QTR CF'!V33+'QTR CF'!W33+'QTR CF'!X33+'QTR CF'!Y33 | I33: ='QTR CF'!Z33+'QTR CF'!AA33+'QTR CF'!AB33+'QTR CF'!AC33 | J33: ='QTR CF'!AD33+'QTR CF'!AE33+'QTR CF'!AF33+'QTR CF'!AG33 | K33: ='QTR CF'!AH33+'QTR CF'!AI33+'QTR CF'!AJ33+'QTR CF'!AK33 | L33: ='QTR CF'!AL33+'QTR CF'!AM33+'QTR CF'!AN33+'QTR CF'!AO33
A34: Cash Flow from Investing | B34: =SUM(B27:B33) | C34: =SUM(C27:C33) | D34: =SUM(D27:D33) | E34: =SUM(E27:E33) | F34: =SUM(F27:F33) | G34: =SUM(G27:G33) | H34: =SUM(H27:H33) | I34: =SUM(I27:I33) | ... L34: =SUM(L27:L33)
A35: Proceeds from Issuance of Long-Term Debt | B35: 4122 | C35: 3377 | D35: 5482 | E35: 4042 | F35: 8189 | G35: ='QTR CF'!R35+'QTR CF'!S35+'QTR CF'!T35+'QTR CF'!U35 | H35: ='QTR CF'!V35+'QTR CF'!W35+'QTR CF'!X35+'QTR CF'!Y35 | I35: ='QTR CF'!Z35+'QTR CF'!AA35+'QTR CF'!AB35+'QTR CF'!AC35 | J35: ='QTR CF'!AD35+'QTR CF'!AE35+'QTR CF'!AF35+'QTR CF'!AG35 | K35: ='QTR CF'!AH35+'QTR CF'!AI35+'QTR CF'!AJ35+'QTR CF'!AK35 | L35: ='QTR CF'!AL35+'QTR CF'!AM35+'QTR CF'!AN35+'QTR CF'!AO35
A36: Repayments of Long-Term Debt | B36: -8299 | C36: -4174 | D36: -3005 | E36: -3886 | F36: -4082 | G36: ='QTR CF'!R36+'QTR CF'!S36+'QTR CF'!T36+'QTR CF'!U36 | H36: ='QTR CF'!V36+'QTR CF'!W36+'QTR CF'!X36+'QTR CF'!Y36 | I36: ='QTR CF'!Z36+'QTR CF'!AA36+'QTR CF'!AB36+'QTR CF'!AC36 | J36: ='QTR CF'!AD36+'QTR CF'!AE36+'QTR CF'!AF36+'QTR CF'!AG36 | K36: ='QTR CF'!AH36+'QTR CF'!AI36+'QTR CF'!AJ36+'QTR CF'!AK36 | L36: ='QTR CF'!AL36+'QTR CF'!AM36+'QTR CF'!AN36+'QTR CF'!AO36
A37: Proceeds from Short-Term Debt | B37: 8 | C37: 1969 | D37: 5428 | E37: 5786 | F37: 6391 | G37: ='QTR CF'!R37+'QTR CF'!S37+'QTR CF'!T37+'QTR CF'!U37 | H37: ='QTR CF'!V37+'QTR CF'!W37+'QTR CF'!X37+'QTR CF'!Y37 | I37: ='QTR CF'!Z37+'QTR CF'!AA37+'QTR CF'!AB37+'QTR CF'!AC37 | J37: ='QTR CF'!AD37+'QTR CF'!AE37+'QTR CF'!AF37+'QTR CF'!AG37 | K37: ='QTR CF'!AH37+'QTR CF'!AI37+'QTR CF'!AJ37+'QTR CF'!AK37 | L37: ='QTR CF'!AL37+'QTR CF'!AM37+'QTR CF'!AN37+'QTR CF'!AO37
A38: Repayments of Short-Term Debt | B38: -397 | C38: -1951 | D38: -3106 | E38: -5639 | F38: -7920 | G38: ='QTR CF'!R38+'QTR CF'!S38+'QTR CF'!T38+'QTR CF'!U38 | H38: ='QTR CF'!V38+'QTR CF'!W38+'QTR CF'!X38+'QTR CF'!Y38 | I38: ='QTR CF'!Z38+'QTR CF'!AA38+'QTR CF'!AB38+'QTR CF'!AC38 | J38: ='QTR CF'!AD38+'QTR CF'!AE38+'QTR CF'!AF38+'QTR CF'!AG38 | K38: ='QTR CF'!AH38+'QTR CF'!AI38+'QTR CF'!AJ38+'QTR CF'!AK38 | L38: ='QTR CF'!AL38+'QTR CF'!AM38+'QTR CF'!AN38+'QTR CF'!AO38
A39: Net Change in Other Short-Term Debt | B39: 434 | C39: -31 | D39: -29 | E39: 392 | F39: 1170 | G39: ='QTR CF'!R39+'QTR CF'!S39+'QTR CF'!T39+'QTR CF'!U39 | H39: ='QTR CF'!V39+'QTR CF'!W39+'QTR CF'!X39+'QTR CF'!Y39 | I39: ='QTR CF'!Z39+'QTR CF'!AA39+'QTR CF'!AB39+'QTR CF'!AC39 | J39: ='QTR CF'!AD39+'QTR CF'!AE39+'QTR CF'!AF39+'QTR CF'!AG39 | K39: ='QTR CF'!AH39+'QTR CF'!AI39+'QTR CF'!AJ39+'QTR CF'!AK39 | L39: ='QTR CF'!AL39+'QTR CF'!AM39+'QTR CF'!AN39+'QTR CF'!AO39
A40: Payments of Contingent Consideration | B40: -773 | C40: 0 | D40: 0 | E40: 0 | F40: 0 | G40: ='QTR CF'!R40+'QTR CF'!S40+'QTR CF'!T40+'QTR CF'!U40 | H40: ='QTR CF'!V40+'QTR CF'!W40+'QTR CF'!X40+'QTR CF'!Y40 | I40: ='QTR CF'!Z40+'QTR CF'!AA40+'QTR CF'!AB40+'QTR CF'!AC40 | J40: ='QTR CF'!AD40+'QTR CF'!AE40+'QTR CF'!AF40+'QTR CF'!AG40 | K40: ='QTR CF'!AH40+'QTR CF'!AI40+'QTR CF'!AJ40+'QTR CF'!AK40 | L40: ='QTR CF'!AL40+'QTR CF'!AM40+'QTR CF'!AN40+'QTR CF'!AO40
A41: Common Dividends | B41: -5815 | C41: -6172 | D41: -6682 | E41: -7229 | F41: -7638 | G41: ='QTR CF'!R41+'QTR CF'!S41+'QTR CF'!T41+'QTR CF'!U41 | H41: ='QTR CF'!V41+'QTR CF'!W41+'QTR CF'!X41+'QTR CF'!Y41 | I41: ='QTR CF'!Z41+'QTR CF'!AA41+'QTR CF'!AB41+'QTR CF'!AC41 | J41: ='QTR CF'!AD41+'QTR CF'!AE41+'QTR CF'!AF41+'QTR CF'!AG41 | K41: ='QTR CF'!AH41+'QTR CF'!AI41+'QTR CF'!AJ41+'QTR CF'!AK41 | L41: ='QTR CF'!AL41+'QTR CF'!AM41+'QTR CF'!AN41+'QTR CF'!AO41
A42: Share Repurchases | B42: -106 | C42: -1500 | D42: -1000 | E42: -1000 | F42: -1000 | G42: ='QTR CF'!R42+'QTR CF'!S42+'QTR CF'!T42+'QTR CF'!U42 | H42: ='QTR CF'!V42+'QTR CF'!W42+'QTR CF'!X42+'QTR CF'!Y42 | I42: ='QTR CF'!Z42+'QTR CF'!AA42+'QTR CF'!AB42+'QTR CF'!AC42 | J42: ='QTR CF'!AD42+'QTR CF'!AE42+'QTR CF'!AF42+'QTR CF'!AG42 | K42: ='QTR CF'!AH42+'QTR CF'!AI42+'QTR CF'!AJ42+'QTR CF'!AK42 | L42: ='QTR CF'!AL42+'QTR CF'!AM42+'QTR CF'!AN42+'QTR CF'!AO42
A43: Proceeds from Exercise of Stock Options | B43: 185 | C43: 138 | D43: 116 | E43: 166 | F43: 97 | G43: ='QTR CF'!R43+'QTR CF'!S43+'QTR CF'!T43+'QTR CF'!U43 | H43: ='QTR CF'!V43+'QTR CF'!W43+'QTR CF'!X43+'QTR CF'!Y43 | I43: ='QTR CF'!Z43+'QTR CF'!AA43+'QTR CF'!AB43+'QTR CF'!AC43 | J43: ='QTR CF'!AD43+'QTR CF'!AE43+'QTR CF'!AF43+'QTR CF'!AG43 | K43: ='QTR CF'!AH43+'QTR CF'!AI43+'QTR CF'!AJ43+'QTR CF'!AK43 | L43: ='QTR CF'!AL43+'QTR CF'!AM43+'QTR CF'!AN43+'QTR CF'!AO43
A44: Tax Withholdings on RSU/PSU Settlement | B44: -92 | C44: -107 | D44: -140 | E44: -135 | F44: -113 | G44: ='QTR CF'!R44+'QTR CF'!S44+'QTR CF'!T44+'QTR CF'!U44 | H44: ='QTR CF'!V44+'QTR CF'!W44+'QTR CF'!X44+'QTR CF'!Y44 | I44: ='QTR CF'!Z44+'QTR CF'!AA44+'QTR CF'!AB44+'QTR CF'!AC44 | J44: ='QTR CF'!AD44+'QTR CF'!AE44+'QTR CF'!AF44+'QTR CF'!AG44 | K44: ='QTR CF'!AH44+'QTR CF'!AI44+'QTR CF'!AJ44+'QTR CF'!AK44 | L44: ='QTR CF'!AL44+'QTR CF'!AM44+'QTR CF'!AN44+'QTR CF'!AO44
A45: Other Financing Activities | B45: -47 | C45: -72 | D45: -73 | E45: -53 | F45: -73 | G45: ='QTR CF'!R45+'QTR CF'!S45+'QTR CF'!T45+'QTR CF'!U45 | H45: ='QTR CF'!V45+'QTR CF'!W45+'QTR CF'!X45+'QTR CF'!Y45 | I45: ='QTR CF'!Z45+'QTR CF'!AA45+'QTR CF'!AB45+'QTR CF'!AC45 | J45: ='QTR CF'!AD45+'QTR CF'!AE45+'QTR CF'!AF45+'QTR CF'!AG45 | K45: ='QTR CF'!AH45+'QTR CF'!AI45+'QTR CF'!AJ45+'QTR CF'!AK45 | L45: ='QTR CF'!AL45+'QTR CF'!AM45+'QTR CF'!AN45+'QTR CF'!AO45
A46: Cash Flow from Financing | B46: =SUM(B35:B45) | C46: =SUM(C35:C45) | D46: =SUM(D35:D45) | E46: =SUM(E35:E45) | F46: =SUM(F35:F45) | G46: =SUM(G35:G45) | H46: =SUM(H35:H45) | I46: =SUM(I35:I45) | ... L46: =SUM(L35:L45)
A47: FX Effect on Cash | B47: -114 | C47: -465 | D47: -277 | E47: -687 | F47: 422 | G47: ='QTR CF'!R47+'QTR CF'!S47+'QTR CF'!T47+'QTR CF'!U47 | H47: ='QTR CF'!V47+'QTR CF'!W47+'QTR CF'!X47+'QTR CF'!Y47 | I47: ='QTR CF'!Z47+'QTR CF'!AA47+'QTR CF'!AB47+'QTR CF'!AC47 | J47: ='QTR CF'!AD47+'QTR CF'!AE47+'QTR CF'!AF47+'QTR CF'!AG47 | K47: ='QTR CF'!AH47+'QTR CF'!AI47+'QTR CF'!AJ47+'QTR CF'!AK47 | L47: ='QTR CF'!AL47+'QTR CF'!AM47+'QTR CF'!AN47+'QTR CF'!AO47
A48: Net Change in Cash | B48: =B26+B34+B46+B47 | C48: =C26+C34+C46+C47 | D48: =D26+D34+D46+D47 | E48: =E26+E34+E46+E47 | F48: =F26+F34+F46+F47 | G48: =G26+G34+G46+G47 | H48: =H26+H34+H46+H47 | I48: =I26+I34+I46+I47 | ... L48: =L26+L34+L46+L47

Sheet YTD P&L
B1: Q1 FY2022 | C1: Q2 FY2022 | D1: Q3 FY2022 | E1: Q1 FY2023 | F1: Q2 FY2023 | G1: Q3 FY2023 | H1: Q1 FY2024 | I1: Q2 FY2024 | J1: Q3 FY2024 | K1: Q1 FY2025 | L1: Q2 FY2025 | M1: Q3 FY2025 | N1: Q1 FY2026
A2: Net Sales / Revenue | B2: 16200 | C2: 36425 | D2: 58396 | E2: 17846 | F2: 40168 | G2: 63621 | H2: 18250 | I2: 40751 | J2: 64070 | K2: 17919 | L2: 40645 | M2: 64582 | N2: 19443
A3: COGS | B3: -7433 | C3: -16848 | D3: -27156 | E3: -7988 | F3: -18109 | G3: -28784 | H3: -8248 | I3: -18167 | J3: -28563 | K3: -7926 | L3: -18230 | M3: -29343 | N3: -8712
A4: Gross Profit (Loss) | B4: =B2+B3 | C4: =C2+C3 | D4: =D2+D3 | E4: =E2+E3 | F4: =F2+F3 | G4: =G2+G3 | H4: =H2+H3 | I4: =I2+I3 | ... N4: =N2+N3
A5: SG&A | B5: -6580 | C5: -13967 | D5: -22262 | E5: -7229 | F5: -15771 | G5: -24528 | H5: -7285 | I5: -15819 | J5: -24870 | K5: -7410 | L5: -16183 | M5: -25305 | N5: -7518
A6: Gain on Juice Transaction | B6: -3322 | C6: -3335 | D6: -3321 | E6: 0 | F6: 0 | G6: 0 | H6: 0 | I6: 0 | J6: 0 | K6: 0 | L6: 0 | M6: 0 | N6: 0
A7: Impairment of Intangibles | B7: -242 | C7: -1601 | D7: -1602 | E7: 0 | F7: 0 | G7: -6 | H7: 0 | I7: 0 | J7: 0 | K7: 0 | L7: -1860 | M7: -1993 | N7: 0
A8: Income (Loss) from Operations | B8: =B4+SUM(B5:B7) | C8: =C4+SUM(C5:C7) | D8: =D4+SUM(D5:D7) | E8: =E4+SUM(E5:E7) | F8: =F4+SUM(F5:F7) | G8: =G4+SUM(G5:G7) | H8: =H4+SUM(H5:H7) | I8: =I4+SUM(I5:I7) | ... N8: =N4+SUM(N5:N7)
A9: Other Pension and OPEB Benefits Income (Expense) | B9: 134 | C9: 132 | D9: 168 | E9: 61 | F9: 121 | G9: 183 | H9: 58 | I9: 114 | J9: 155 | K9: 23 | L9: 65 | M9: 91 | N9: 58
A10: Interest Income (Expense) | B10: -240 | C10: -476 | D10: -666 | E10: -200 | F10: -401 | G10: -602 | H10: -202 | I10: -436 | J10: -655 | K10: -264 | L10: -524 | M10: -788 | N10: -301
A11: Pre-Tax Income (Loss) | B11: =B8+SUM(B9:B10) | C11: =C8+SUM(C9:C10) | D11: =D8+SUM(D9:D10) | E11: =E8+SUM(E9:E10) | F11: =F8+SUM(F9:F10) | G11: =G8+SUM(G9:G10) | H11: =H8+SUM(H9:H10) | I11: =I8+SUM(I9:I10) | ... N11: =N8+SUM(N9:N10)
A12: Income Tax (Expense) Benefit | B12: -888 | C12: -1281 | D12: -1756 | E12: -546 | F12: -1293 | G12: -2053 | H12: -520 | I12: -1296 | J12: -2045 | K12: -499 | L12: -791 | M12: -1504 | N12: -632
A13: Net Income (Loss) | B13: =B11+B12 | C13: =C11+C12 | D13: =D11+D12 | E13: =E11+E12 | F13: =F11+F12 | G13: =G11+G12 | H13: =H11+H12 | I13: =I11+I12 | ... N13: =N11+N12
A14: Net Income (Loss) Attributable to Noncontrolling Interest | B14: 12 | C14: 29 | D14: 51 | E14: 12 | F14: 35 | G14: 59 | H14: 11 | I14: 22 | J14: 37 | K14: 9 | L14: 25 | M14: 40 | N14: 11
A15: Net Income (Loss) Less NCI | B15: =B13-B14 | C15: =C13-C14 | D15: =D13-D14 | E15: =E13-E14 | F15: =F13-F14 | G15: =G13-G14 | H15: =H13-H14 | I15: =I13-I14 | ... N15: =N13-N14
A16: Basic Earnings (Loss) per Share | B16: 3.08 | C16: 4.11 | D16: 6.07 | E16: 1.4 | F16: 3.4 | G16: 5.64 | H16: 1.49 | I16: 3.73 | J16: 5.86 | K16: 1.34 | L16: 2.26 | M16: 4.16 | N16: 1.7
A17: Diluted Earnings (Loss) per Share | B17: 3.06 | C17: 4.09 | D17: 6.04 | E17: 1.4 | F17: 3.38 | G17: 5.62 | H17: 1.48 | I17: 3.71 | J17: 5.84 | K17: 1.33 | L17: 2.25 | M17: 4.15 | N17: 1.7
A18: Weighted Average Shares Outstanding (Basic) | B18: 1383000000 | C18: 1383000000 | D18: 1382000000 | E18: 1378000000 | F18: 1378000000 | G18: 1377000000 | H18: 1375000000 | I18: 1375000000 | J18: 1374000000 | K18: 1372000000 | L18: 1371000000 | M18: 1370000000 | N18: 1367000000
A19: Weighted Average Shares Outstanding (Diluted) | B19: 1391000000 | C19: 1390000000 | D19: 1389000000 | E19: 1384000000 | F19: 1384000000 | G19: 1384000000 | H19: 1380000000 | I19: 1380000000 | J19: 1379000000 | K19: 1376000000 | L19: 1374000000 | M19: 1373000000 | N19: 1371000000

Sheet YTD BS
B1: Q4 FY2022 | C1: Q1 FY2023 | D1: Q2 FY2023 | E1: Q3 FY2023 | F1: Q4 FY2023 | G1: Q1 FY2024 | H1: Q2 FY2024 | I1: Q3 FY2024 | J1: Q4 FY2024 | K1: Q1 FY2025 | L1: Q2 FY2025 | M1: Q3 FY2025 | N1: Q4 FY2025 | O1: Q1 FY2026
A2: Cash & Cash Equivalents | B2: 4954 | C2: 4770 | D2: 6116 | E2: 10017 | F2: 9711 | G2: 8047 | H2: 6353 | I2: 7308 | J2: 8505 | K2: 8268 | L2: 7631 | M2: 8126 | N2: 9159 | O2: 10475
A3: Short-Term Investments | B3: 394 | C3: 434 | D3: 338 | E3: 266 | F3: 292 | G3: 303 | H3: 315 | I3: 743 | J3: 761 | K3: 314 | L3: 342 | M3: 535 | N3: 371 | O3: 353
A4: Accounts Receivable | B4: 10163 | C4: 10469 | D4: 11456 | E4: 11782 | F4: 10815 | G4: 10938 | H4: 11942 | I4: 12088 | J4: 10333 | K4: 10800 | L4: 12390 | M4: 12634 | N4: 11506 | O4: 12171
A5: Inventories | B5: 5222 | C5: 5697 | D5: 5969 | E5: 5558 | F5: 5334 | G5: 5569 | H5: 5887 | I5: 5644 | J5: 5306 | K5: 5660 | L5: 6487 | M5: 6093 | N5: 5845 | O5: 6211
A6: Prepaid Expenses | B6: 806 | C6: 1057 | D6: 1075 | E6: 1026 | F6: 798 | G6: 1148 | H6: 1206 | I6: 1069 | J6: 921 | K6: 1246 | L6: 1360 | M6: 1334 | N6: 1068 | O6: 1706
A7: Total Current Assets | B7: =SUM(B2:B6) | C7: =SUM(C2:C6) | D7: =SUM(D2:D6) | E7: =SUM(E2:E6) | F7: =SUM(F2:F6) | G7: =SUM(G2:G6) | H7: =SUM(H2:H6) | I7: =SUM(I2:I6) | ... O7: =SUM(O2:O6)
A8: Net PP&E | B8: 24291 | C8: 24228 | D8: 24500 | E8: 24853 | F8: 27039 | G8: 26792 | H8: 27042 | I8: 27188 | J8: 28008 | K8: 28213 | L8: 28797 | M8: 29053 | N8: 29905 | O8: 29807
A9: Intangible Assets | B9: 15586 | C9: 15523 | D9: 15562 | E9: 15501 | F9: 14929 | G9: 14853 | H9: 14826 | I9: 14857 | J9: 14801 | K9: 15363 | L9: 15523 | M9: 14852 | N9: 15066 | O9: 15143
A10: Goodwill | B10: 18202 | C10: 18089 | D10: 17997 | E10: 17892 | F10: 17728 | G10: 17646 | H10: 17648 | I10: 17709 | J10: 17534 | K10: 18364 | L10: 18952 | M10: 18845 | N10: 18916 | O10: 19021
A11: Equity Method Investments | B11: 3073 | C11: 3123 | D11: 3038 | E11: 2955 | F11: 2714 | G11: 2734 | H11: 2674 | I11: 2645 | J11: 1985 | K11: 1996 | L11: 2061 | M11: 2084 | N11: 2038 | O11: 2135
A12: Deferred Tax Assets | B12: 4204 | C12: 4211 | D12: 4186 | E12: 4165 | F12: 4474 | G12: 4444 | H12: 4465 | I12: 4321 | J12: 4362 | K12: 4350 | L12: 4293 | M12: 4341 | N12: 4541 | O12: 4560
A13: Other Non-Current Assets | B13: 5292 | C13: 5441 | D13: 5669 | E13: 5938 | F13: 6661 | G13: 7566 | H13: 7175 | I13: 6941 | J13: 6951 | K13: 7163 | L13: 7509 | M13: 8661 | N13: 8984 | O13: 9064
A14: Total Assets | B14: =B7+SUM(B8:B13) | C14: =C7+SUM(C8:C13) | D14: =D7+SUM(D8:D13) | E14: =E7+SUM(E8:E13) | F14: =F7+SUM(F8:F13) | G14: =G7+SUM(G8:G13) | H14: =H7+SUM(H8:H13) | I14: =I7+SUM(I8:I13) | ... O14: =O7+SUM(O8:O13)
A15: Short-Term Debt Obligations | B15: 3414 | C15: 4281 | D15: 7613 | E15: 8937 | F15: 6510 | G15: 8161 | H15: 8289 | I15: 6524 | J15: 7082 | K15: 9099 | L15: 12056 | M15: 6736 | N15: 6861 | O15: 10151
A16: Accrued Expenses | B16: 23371 | C16: 21556 | D16: 22005 | E16: 23723 | F16: 25137 | G16: 22073 | H16: 22859 | I16: 23791 | J16: 24454 | K16: 22412 | L16: 24340 | M16: 24763 | N16: 25903 | O16: 24326
A17: Total Current Liabilities | B17: =SUM(B15:B16) | C17: =SUM(C15:C16) | D17: =SUM(D15:D16) | E17: =SUM(E15:E16) | F17: =SUM(F15:F16) | G17: =SUM(G15:G16) | H17: =SUM(H15:H16) | I17: =SUM(I15:I16) | ... O17: =SUM(O15:O16)
A18: Long-Term Debt | B18: 35657 | C18: 37486 | D18: 36008 | E18: 35837 | F18: 37595 | G18: 37707 | H18: 36638 | I18: 38490 | J18: 37224 | K18: 39419 | L18: 39328 | M18: 44113 | N18: 42321 | O18: 42577
A19: Deferred Tax Liability | B19: 4133 | C19: 4039 | D19: 4113 | E19: 4047 | F19: 3895 | G19: 4087 | H19: 3908 | I19: 3684 | J19: 3484 | K19: 3541 | L19: 3102 | M19: 3474 | N19: 3802 | O19: 4048
A20: Other Non-Current Liabilities | B20: 8339 | C20: 8505 | D20: 8342 | E20: 8439 | F20: 8721 | G20: 8822 | H20: 8259 | I20: 8419 | J20: 9052 | K20: 8737 | L20: 7960 | M20: 7929 | N20: 7965 | O20: 8008
A21: Total Liabilities | B21: =B17+SUM(B18:B20) | C21: =C17+SUM(C18:C20) | D21: =D17+SUM(D18:D20) | E21: =E17+SUM(E18:E20) | F21: =F17+SUM(F18:F20) | G21: =G17+SUM(G18:G20) | H21: =H17+SUM(H18:H20) | I21: =I17+SUM(I18:I20) | ... O21: =O17+SUM(O18:O20)
A22: Common Stock | B22: 23 | C22: 23 | D22: 23 | E22: 23 | F22: 23 | G22: 23 | H22: 23 | I22: 23 | J22: 23 | K22: 23 | L22: 23 | M22: 23 | N22: 23 | O22: 23
A23: Additional Paid-in Capital | B23: 4134 | C23: 3996 | D23: 4082 | E23: 4154 | F23: 4261 | G23: 4132 | H23: 4203 | I23: 4281 | J23: 4385 | K23: 4274 | L23: 4299 | M23: 4374 | N23: 4451 | O23: 4401
A24: Retained Earnings (Accumulated Deficit) | B24: 67800 | C24: 68142 | D24: 69135 | E24: 70479 | F24: 70035 | G24: 70331 | H24: 71545 | I24: 72607 | J24: 72266 | K24: 72238 | L24: 71547 | M24: 72197 | N24: 72788 | O24: 73165
A25: Accumulated Other Comprehensive Income (Loss) | B25: -15302 | C25: -15601 | D25: -15780 | E25: -15794 | F25: -15534 | G25: -15179 | H25: -15786 | I25: -16652 | J25: -17612 | K25: -17078 | L25: -16090 | M25: -15597 | N25: -15024 | O25: -14342
A26: Treasury Stock | B26: -39506 | C26: -39518 | D26: -39775 | E26: -40056 | F26: -40282 | G26: -40260 | H26: -40539 | I26: -40806 | J26: -41021 | K26: -41068 | L26: -41361 | M26: -41609 | N26: -41832 | O26: -41864
A27: Noncontrolling Interest | B27: 124 | C27: 133 | D27: 140 | E27: 164 | F27: 134 | G27: 143 | H27: 134 | I27: 152 | J27: 130 | K27: 140 | L27: 141 | M27: 155 | N27: 141 | O27: 153
A28: Total Stockholders' Equity | B28: =SUM(B22:B27) | C28: =SUM(C22:C27) | D28: =SUM(D22:D27) | E28: =SUM(E22:E27) | F28: =SUM(F22:F27) | G28: =SUM(G22:G27) | H28: =SUM(H22:H27) | I28: =SUM(I22:I27) | ... O28: =SUM(O22:O27)
A29: Total Liabilities, Mezzanine & Stockholders' Equity | B29: =B21+B28 | C29: =C21+C28 | D29: =D21+D28 | E29: =E21+E28 | F29: =F21+F28 | G29: =G21+G28 | H29: =H21+H28 | I29: =I21+I28 | ... O29: =O21+O28

Sheet YTD CF
B1: Q1 FY2022 | C1: Q2 FY2022 | D1: Q3 FY2022 | E1: Q1 FY2023 | F1: Q2 FY2023 | G1: Q3 FY2023 | H1: Q1 FY2024 | I1: Q2 FY2024 | J1: Q3 FY2024 | K1: Q1 FY2025 | L1: Q2 FY2025 | M1: Q3 FY2025 | N1: Q1 FY2026
A2: Net Income (Loss) | B2: 4273 | C2: 5719 | D2: 8443 | E2: 1944 | F2: 4715 | G2: 7831 | H2: 2053 | I2: 5147 | J2: 8092 | K2: 1843 | L2: 3122 | M2: 5740 | N2: 2338
A3: Depreciation & Amortization | B3: 555 | C3: 1195 | D3: 1854 | E3: 590 | F3: 1268 | G3: 1973 | H3: 641 | I3: 1379 | J3: 2118 | K3: 684 | L3: 1491 | M3: 2315 | N3: 742
A4: Gain on Juice Transaction | B4: -3322 | C4: -3335 | D4: -3321 | E4: 0 | F4: 0 | G4: 0 | H4: 0 | I4: 0 | J4: 0 | K4: 0 | L4: 0 | M4: 0 | N4: 0
A5: Impairment and Other Charges | B5: 482 | C5: 1871 | D5: 1877 | E5: -13 | F5: 97 | G5: 102 | H5: 0 | I5: 0 | J5: 10 | K5: 0 | L5: 1860 | M5: 1960 | N5: 0
A6: Indirect Tax Impact | B6: 0 | C6: 0 | D6: 0 | E6: 0 | F6: 0 | G6: 0 | H6: 0 | I6: 0 | J6: 0 | K6: 0 | L6: 0 | M6: 0 | N6: 0
A7: Product Recall Impact | B7: 0 | C7: 0 | D7: 0 | E7: 0 | F7: 0 | G7: 0 | H7: 167 | I7: 182 | J7: 184 | K7: 0 | L7: 0 | M7: 0 | N7: 0
A8: Cash Payments for Product Recall | B8: 0 | C8: 0 | D8: 0 | E8: 0 | F8: 0 | G8: 0 | H8: -108 | I8: -135 | J8: -138 | K8: -2 | L8: -2 | M8: -5 | N8: 0
A9: Operating Lease ROU Asset Amortization | B9: 103 | C9: 223 | D9: 346 | E9: 116 | F9: 248 | G9: 384 | H9: 127 | I9: 278 | J9: 438 | K9: 145 | L9: 315 | M9: 489 | N9: 162
A10: Stock-Based Compensation | B10: 81 | C10: 156 | D10: 233 | E10: 93 | F10: 179 | G10: 267 | H10: 97 | I10: 183 | J10: 260 | K10: 77 | L10: 131 | M10: 207 | N10: 93
A11: Restructuring and Asset Impairment Charges | B11: 27 | C11: 75 | D11: 126 | E11: 112 | F11: 204 | G11: 287 | H11: 96 | I11: 170 | J11: 415 | K11: 213 | L11: 426 | M11: 567 | N11: 133
A12: Cash Payments for Restructuring | B12: -32 | C12: -82 | D12: -134 | E12: -64 | F12: -187 | G12: -283 | H12: -60 | I12: -173 | J12: -284 | K12: -232 | L12: -387 | M12: -554 | N12: -145
A13: Acquisition and Divestiture-Related Charges | B13: 56 | C13: 64 | D13: 69 | E13: 2 | F13: 9 | G13: 20 | H13: 0 | I13: 0 | J13: 0 | K13: 0 | L13: 0 | M13: 308 | N13: -113
... A25: Other Operating Items | B25: -133 | C25: -325 | D25: -426 | E25: 46 | F25: -6 | G25: 72 | H25: -68 | I25: -203 | J25: -135 | K25: -232 | L25: -269 | M25: -441 | N25: -157
A26: Cash Flow from Operations | B26: =SUM(B2:B25) | C26: =SUM(C2:C25) | D26: =SUM(D2:D25) | E26: =SUM(E2:E25) | F26: =SUM(F2:F25) | G26: =SUM(G2:G25) | H26: =SUM(H2:H25) | I26: =SUM(I2:I25) | ... N26: =SUM(N2:N25)
A27: Purchase of PP&E | B27: -522 | C27: -1499 | D27: -2556 | E27: -581 | F27: -1513 | G27: -2537 | H27: -614 | I27: -1701 | J27: -2850 | K27: -603 | L27: -1507 | M27: -2499 | N27: -447
A28: Proceeds from Sale of Assets | B28: 3 | C28: 222 | D28: 228 | E28: 19 | F28: 122 | G28: 131 | H28: 7 | I28: 127 | J28: 177 | K28: 132 | L28: 169 | M28: 272 | N28: 13
A29: Acquisitions, Net of Cash Acquired | B29: -13 | C29: -29 | D29: -804 | E29: -16 | F29: -83 | G29: -132 | H29: -6 | I29: -30 | J29: -31 | K29: -1200 | L29: -3130 | M29: -3176 | N29: -67
A30: Proceeds from Juice Transaction | B30: 3456 | C30: 3456 | D30: 3456 | E30: 0 | F30: 0 | G30: 0 | H30: 0 | I30: 0 | J30: 0 | K30: 0 | L30: 0 | M30: 0 | N30: 0
A31: Proceeds from Divestitures of Businesses | B31: 5 | C31: 15 | D31: 15 | E31: 85 | F31: 75 | G31: 75 | H31: 53 | I31: 135 | J31: 145 | K31: 2 | L31: 5 | M31: 5 | N31: 0
A32: Net Change in Short-Term Investments | B32: 22 | C32: 8 | D32: -37 | E32: -39 | F32: -56 | G32: 35 | H32: 8 | I32: 1 | J32: -421 | K32: 441 | L32: 447 | M32: 278 | N32: 5
A33: Other Investing Activities | B33: 4 | C33: -1 | D33: 7 | E33: 0 | F33: 32 | G33: 49 | H33: -10 | I33: 14 | J33: 15 | K33: -4 | L33: -111 | M33: -117 | N33: 19
A34: Cash Flow from Investing | B34: =SUM(B27:B33) | C34: =SUM(C27:C33) | D34: =SUM(D27:D33) | E34: =SUM(E27:E33) | F34: =SUM(F27:F33) | G34: =SUM(G27:G33) | H34: =SUM(H27:H33) | I34: =SUM(I27:I33) | ... N34: =SUM(N27:N33)
A35: Proceeds from Issuance of Long-Term Debt | B35: 0 | C35: 0 | D35: 3377 | E35: 2986 | F35: 2986 | G35: 2986 | H35: 1761 | I35: 1765 | J35: 4014 | K35: 3505 | L35: 3521 | M35: 8179 | N35: 2964
A36: Repayments of Long-Term Debt | B36: -1251 | C36: -3202 | D36: -3203 | E36: -1251 | F36: -2252 | G36: -2253 | H36: -1252 | I36: -2882 | J36: -2883 | K36: -1541 | L36: -2543 | M36: -3245 | N36: -1629
A37: Proceeds from Short-Term Debt | B37: 559 | C37: 1935 | D37: 1947 | E37: 393 | F37: 1660 | G37: 4688 | H37: 2313 | I37: 3080 | J37: 3808 | K37: 3656 | L37: 5251 | M37: 5528 | N37: 1937
A38: Repayments of Short-Term Debt | B38: 0 | C38: 0 | D38: -1932 | E38: -1 | F38: -26 | G38: -1037 | H38: -1631 | I38: -2138 | J38: -4177 | K38: -2119 | L38: -2492 | M38: -5417 | N38: -676
A39: Net Change in Other Short-Term Debt | B39: 647 | C39: 844 | D39: -45 | E39: 491 | F39: 2023 | G39: 1395 | H39: 774 | I39: 1286 | J39: 101 | K39: 373 | L39: 2438 | M39: 445 | N39: 1198
A40: Payments of Contingent Consideration | B40: 0 | C40: 0 | D40: 0 | E40: 0 | F40: 0 | G40: 0 | H40: 0 | I40: 0 | J40: 0 | K40: 0 | L40: 0 | M40: 0 | N40: 0
A41: Common Dividends | B41: -1505 | C41: -2997 | D41: -4586 | E41: -1608 | F41: -3199 | G41: -4941 | H41: -1767 | I41: -3506 | J41: -5369 | K41: -1882 | L41: -3743 | M41: -5692 | N41: -1966
A42: Share Repurchases | B42: -193 | C42: -699 | D42: -1156 | E42: -160 | F42: -453 | G42: -751 | H42: -146 | I42: -461 | J42: -760 | K42: -183 | L42: -494 | M42: -752 | N42: -182
A43: Proceeds from Exercise of Stock Options | B43: 49 | C43: 89 | D43: 113 | E43: 46 | F43: 86 | G43: 100 | H43: 66 | I43: 107 | J43: 138 | K43: 50 | L43: 58 | M43: 76 | N43: 93
A44: Tax Withholdings on RSU/PSU Settlement | B44: -85 | C44: -87 | D44: -97 | E44: -116 | F44: -119 | G44: -135 | H44: -108 | I44: -131 | J44: -132 | K44: -89 | L44: -111 | M44: -112 | N44: -76
A45: Other Financing Activities | B45: -1 | C45: -15 | D45: -25 | E45: -3 | F45: -16 | G45: -18 | H45: 0 | I45: -20 | J45: -22 | K45: -2 | L45: -17 | M45: -18 | N45: -1
A46: Cash Flow from Financing | B46: =SUM(B35:B45) | C46: =SUM(C35:C45) | D46: =SUM(D35:D45) | E46: =SUM(E35:E45) | F46: =SUM(F35:F45) | G46: =SUM(G35:G45) | H46: =SUM(H35:H45) | I46: =SUM(I35:I45) | ... N46: =SUM(N35:N45)
A47: FX Effect on Cash | B47: -17 | C47: -83 | D47: -197 | E47: -116 | F47: -144 | G47: -254 | H47: -38 | I47: -304 | J47: -391 | K47: 203 | L47: 422 | M47: 395 | N47: 121
A48: Net Change in Cash | B48: =B26+B34+B46+B47 | C48: =C26+C34+C46+C47 | D48: =D26+D34+D46+D47 | E48: =E26+E34+E46+E47 | F48: =F26+F34+F46+F47 | G48: =G26+G34+G46+G47 | H48: =H26+H34+H46+H47 | I48: =I26+I34+I46+I47 | ... N48: =N26+N34+N46+N47

Sheet QTR P&L
B1: Q1 FY2022 | C1: Q2 FY2022 | D1: Q3 FY2022 | E1: Q4 FY2022 | F1: Q1 FY2023 | G1: Q2 FY2023 | H1: Q3 FY2023 | I1: Q4 FY2023 | J1: Q1 FY2024 | K1: Q2 FY2024 | L1: Q3 FY2024 | M1: Q4 FY2024 | N1: Q1 FY2025 | O1: Q2 FY2025 | P1: Q3 FY2025 | Q1: Q4 FY2025 | R1: Q1 FY2026 | S1: Q2 FY2026E | T1: Q3 FY2026E | U1: Q4 FY2026E | V1: Q1 FY2027E | W1: Q2 FY2027E | X1: Q3 FY2027E | Y1: Q4 FY2027E | Z1: Q1 FY2028E | AA1: Q2 FY2028E | AB1: Q3 FY2028E | AC1: Q4 FY2028E | AD1: Q1 FY2029E | AE1: Q2 FY2029E | AF1: Q3 FY2029E | AG1: Q4 FY2029E | AH1: Q1 FY2030E | AI1: Q2 FY2030E | AJ1: Q3 FY2030E | AK1: Q4 FY2030E | AL1: Q1 FY2031E | AM1: Q2 FY2031E | AN1: Q3 FY2031E | AO1: Q4 FY2031E
A2: Net Sales / Revenue | B2: ='YTD P&L'!B2 | C2: ='YTD P&L'!C2-'YTD P&L'!B2 | D2: ='YTD P&L'!D2-'YTD P&L'!C2 | E2: ='ANNL P&L'!C2-'YTD P&L'!D2 | F2: ='YTD P&L'!E2 | G2: ='YTD P&L'!F2-'YTD P&L'!E2 | H2: ='YTD P&L'!G2-'YTD P&L'!F2 | I2: ='ANNL P&L'!D2-'YTD P&L'!G2 | J2: ='YTD P&L'!H2 | K2: ='YTD P&L'!I2-'YTD P&L'!H2 | L2: ='YTD P&L'!J2-'YTD P&L'!I2 | M2: ='ANNL P&L'!E2-'YTD P&L'!J2 | N2: ='YTD P&L'!K2 | O2: ='YTD P&L'!L2-'YTD P&L'!K2 | P2: ='YTD P&L'!M2-'YTD P&L'!L2 | Q2: ='ANNL P&L'!F2-'YTD P&L'!M2 | R2: ='YTD P&L'!N2 | S2: =IF('IS DRIVERS'!$B2="QoQ",'QTR P&L'!R2,'QTR P&L'!O2)*(1+'IS DRIVERS'!T2) | T2: =IF('IS DRIVERS'!$B2="QoQ",'QTR P&L'!S2,'QTR P&L'!P2)*(1+'IS DRIVERS'!U2) | U2: =IF('IS DRIVERS'!$B2="QoQ",'QTR P&L'!T2,'QTR P&L'!Q2)*(1+'IS DRIVERS'!V2) | V2: =IF('IS DRIVERS'!$B2="QoQ",'QTR P&L'!U2,'QTR P&L'!R2)*(1+'IS DRIVERS'!W2) | W2: =IF('IS DRIVERS'!$B2="QoQ",'QTR P&L'!V2,'QTR P&L'!S2)*(1+'IS DRIVERS'!X2) | X2: =IF('IS DRIVERS'!$B2="QoQ",'QTR P&L'!W2,'QTR P&L'!T2)*(1+'IS DRIVERS'!Y2) | Y2: =IF('IS DRIVERS'!$B2="QoQ",'QTR P&L'!X2,'QTR P&L'!U2)*(1+'IS DRIVERS'!Z2) | Z2: =IF('IS DRIVERS'!$B2="QoQ",'QTR P&L'!Y2,'QTR P&L'!V2)*(1+'IS DRIVERS'!AA2) | ... AO2: =IF('IS DRIVERS'!$B2="QoQ",'QTR P&L'!AN2,'QTR P&L'!AK2)*(1+'IS DRIVERS'!AP2)
A3: COGS | B3: ='YTD P&L'!B3 | C3: ='YTD P&L'!C3-'YTD P&L'!B3 | D3: ='YTD P&L'!D3-'YTD P&L'!C3 | E3: ='ANNL P&L'!C3-'YTD P&L'!D3 | F3: ='YTD P&L'!E3 | G3: ='YTD P&L'!F3-'YTD P&L'!E3 | H3: ='YTD P&L'!G3-'YTD P&L'!F3 | I3: ='ANNL P&L'!D3-'YTD P&L'!G3 | J3: ='YTD P&L'!H3 | K3: ='YTD P&L'!I3-'YTD P&L'!H3 | L3: ='YTD P&L'!J3-'YTD P&L'!I3 | M3: ='ANNL P&L'!E3-'YTD P&L'!J3 | N3: ='YTD P&L'!K3 | O3: ='YTD P&L'!L3-'YTD P&L'!K3 | P3: ='YTD P&L'!M3-'YTD P&L'!L3 | Q3: ='ANNL P&L'!F3-'YTD P&L'!M3 | R3: ='YTD P&L'!N3 | S3: ='QTR P&L'!S2*'IS DRIVERS'!T3 | T3: ='QTR P&L'!T2*'IS DRIVERS'!U3 | U3: ='QTR P&L'!U2*'IS DRIVERS'!V3 | V3: ='QTR P&L'!V2*'IS DRIVERS'!W3 | W3: ='QTR P&L'!W2*'IS DRIVERS'!X3 | X3: ='QTR P&L'!X2*'IS DRIVERS'!Y3 | Y3: ='QTR P&L'!Y2*'IS DRIVERS'!Z3 | Z3: ='QTR P&L'!Z2*'IS DRIVERS'!AA3 | ... AO3: ='QTR P&L'!AO2*'IS DRIVERS'!AP3
A4: Gross Profit (Loss) | B4: ='YTD P&L'!B4 | C4: ='YTD P&L'!C4-'YTD P&L'!B4 | D4: ='YTD P&L'!D4-'YTD P&L'!C4 | E4: ='ANNL P&L'!C4-'YTD P&L'!D4 | F4: ='YTD P&L'!E4 | G4: ='YTD P&L'!F4-'YTD P&L'!E4 | H4: ='YTD P&L'!G4-'YTD P&L'!F4 | I4: ='ANNL P&L'!D4-'YTD P&L'!G4 | J4: ='YTD P&L'!H4 | K4: ='YTD P&L'!I4-'YTD P&L'!H4 | L4: ='YTD P&L'!J4-'YTD P&L'!I4 | M4: ='ANNL P&L'!E4-'YTD P&L'!J4 | N4: ='YTD P&L'!K4 | O4: ='YTD P&L'!L4-'YTD P&L'!K4 | P4: ='YTD P&L'!M4-'YTD P&L'!L4 | Q4: ='ANNL P&L'!F4-'YTD P&L'!M4 | R4: ='YTD P&L'!N4 | S4: =S2+S3 | T4: =T2+T3 | U4: =U2+U3 | V4: =V2+V3 | W4: =W2+W3 | X4: =X2+X3 | Y4: =Y2+Y3 | Z4: =Z2+Z3 | ... AO4: =AO2+AO3
A5: SG&A | B5: ='YTD P&L'!B5 | C5: ='YTD P&L'!C5-'YTD P&L'!B5 | D5: ='YTD P&L'!D5-'YTD P&L'!C5 | E5: ='ANNL P&L'!C5-'YTD P&L'!D5 | F5: ='YTD P&L'!E5 | G5: ='YTD P&L'!F5-'YTD P&L'!E5 | H5: ='YTD P&L'!G5-'YTD P&L'!F5 | I5: ='ANNL P&L'!D5-'YTD P&L'!G5 | J5: ='YTD P&L'!H5 | K5: ='YTD P&L'!I5-'YTD P&L'!H5 | L5: ='YTD P&L'!J5-'YTD P&L'!I5 | M5: ='ANNL P&L'!E5-'YTD P&L'!J5 | N5: ='YTD P&L'!K5 | O5: ='YTD P&L'!L5-'YTD P&L'!K5 | P5: ='YTD P&L'!M5-'YTD P&L'!L5 | Q5: ='ANNL P&L'!F5-'YTD P&L'!M5 | R5: ='YTD P&L'!N5 | S5: ='QTR P&L'!S2*'IS DRIVERS'!T4 | T5: ='QTR P&L'!T2*'IS DRIVERS'!U4 | U5: ='QTR P&L'!U2*'IS DRIVERS'!V4 | V5: ='QTR P&L'!V2*'IS DRIVERS'!W4 | W5: ='QTR P&L'!W2*'IS DRIVERS'!X4 | X5: ='QTR P&L'!X2*'IS DRIVERS'!Y4 | Y5: ='QTR P&L'!Y2*'IS DRIVERS'!Z4 | Z5: ='QTR P&L'!Z2*'IS DRIVERS'!AA4 | ... AO5: ='QTR P&L'!AO2*'IS DRIVERS'!AP4
A6: Gain on Juice Transaction | B6: ='YTD P&L'!B6 | C6: ='YTD P&L'!C6-'YTD P&L'!B6 | D6: ='YTD P&L'!D6-'YTD P&L'!C6 | E6: ='ANNL P&L'!C6-'YTD P&L'!D6 | F6: ='YTD P&L'!E6 | G6: ='YTD P&L'!F6-'YTD P&L'!E6 | H6: ='YTD P&L'!G6-'YTD P&L'!F6 | I6: ='ANNL P&L'!D6-'YTD P&L'!G6 | J6: ='YTD P&L'!H6 | K6: ='YTD P&L'!I6-'YTD P&L'!H6 | L6: ='YTD P&L'!J6-'YTD P&L'!I6 | M6: ='ANNL P&L'!E6-'YTD P&L'!J6 | N6: ='YTD P&L'!K6 | O6: ='YTD P&L'!L6-'YTD P&L'!K6 | P6: ='YTD P&L'!M6-'YTD P&L'!L6 | Q6: ='ANNL P&L'!F6-'YTD P&L'!M6 | R6: ='YTD P&L'!N6 | S6: ='IS DRIVERS'!T5 | T6: ='IS DRIVERS'!U5 | U6: ='IS DRIVERS'!V5 | V6: ='IS DRIVERS'!W5 | W6: ='IS DRIVERS'!X5 | X6: ='IS DRIVERS'!Y5 | Y6: ='IS DRIVERS'!Z5 | Z6: ='IS DRIVERS'!AA5 | ... AO6: ='IS DRIVERS'!AP5
A7: Impairment of Intangibles | B7: ='YTD P&L'!B7 | C7: ='YTD P&L'!C7-'YTD P&L'!B7 | D7: ='YTD P&L'!D7-'YTD P&L'!C7 | E7: ='ANNL P&L'!C7-'YTD P&L'!D7 | F7: ='YTD P&L'!E7 | G7: ='YTD P&L'!F7-'YTD P&L'!E7 | H7: ='YTD P&L'!G7-'YTD P&L'!F7 | I7: ='ANNL P&L'!D7-'YTD P&L'!G7 | J7: ='YTD P&L'!H7 | K7: ='YTD P&L'!I7-'YTD P&L'!H7 | L7: ='YTD P&L'!J7-'YTD P&L'!I7 | M7: ='ANNL P&L'!E7-'YTD P&L'!J7 | N7: ='YTD P&L'!K7 | O7: ='YTD P&L'!L7-'YTD P&L'!K7 | P7: ='YTD P&L'!M7-'YTD P&L'!L7 | Q7: ='ANNL P&L'!F7-'YTD P&L'!M7 | R7: ='YTD P&L'!N7 | S7: ='QTR P&L'!S2*'IS DRIVERS'!T6 | T7: ='QTR P&L'!T2*'IS DRIVERS'!U6 | U7: ='QTR P&L'!U2*'IS DRIVERS'!V6 | V7: ='QTR P&L'!V2*'IS DRIVERS'!W6 | W7: ='QTR P&L'!W2*'IS DRIVERS'!X6 | X7: ='QTR P&L'!X2*'IS DRIVERS'!Y6 | Y7: ='QTR P&L'!Y2*'IS DRIVERS'!Z6 | Z7: ='QTR P&L'!Z2*'IS DRIVERS'!AA6 | ... AO7: ='QTR P&L'!AO2*'IS DRIVERS'!AP6
A8: Income (Loss) from Operations | B8: ='YTD P&L'!B8 | C8: ='YTD P&L'!C8-'YTD P&L'!B8 | D8: ='YTD P&L'!D8-'YTD P&L'!C8 | E8: ='ANNL P&L'!C8-'YTD P&L'!D8 | F8: ='YTD P&L'!E8 | G8: ='YTD P&L'!F8-'YTD P&L'!E8 | H8: ='YTD P&L'!G8-'YTD P&L'!F8 | I8: ='ANNL P&L'!D8-'YTD P&L'!G8 | J8: ='YTD P&L'!H8 | K8: ='YTD P&L'!I8-'YTD P&L'!H8 | L8: ='YTD P&L'!J8-'YTD P&L'!I8 | M8: ='ANNL P&L'!E8-'YTD P&L'!J8 | N8: ='YTD P&L'!K8 | O8: ='YTD P&L'!L8-'YTD P&L'!K8 | P8: ='YTD P&L'!M8-'YTD P&L'!L8 | Q8: ='ANNL P&L'!F8-'YTD P&L'!M8 | R8: ='YTD P&L'!N8 | S8: =S4+SUM(S5:S7) | T8: =T4+SUM(T5:T7) | U8: =U4+SUM(U5:U7) | V8: =V4+SUM(V5:V7) | W8: =W4+SUM(W5:W7) | X8: =X4+SUM(X5:X7) | Y8: =Y4+SUM(Y5:Y7) | Z8: =Z4+SUM(Z5:Z7) | ... AO8: =AO4+SUM(AO5:AO7)
A9: Other Pension and OPEB Benefits Income (Expense) | B9: ='YTD P&L'!B9 | C9: ='YTD P&L'!C9-'YTD P&L'!B9 | D9: ='YTD P&L'!D9-'YTD P&L'!C9 | E9: ='ANNL P&L'!C9-'YTD P&L'!D9 | F9: ='YTD P&L'!E9 | G9: ='YTD P&L'!F9-'YTD P&L'!E9 | H9: ='YTD P&L'!G9-'YTD P&L'!F9 | I9: ='ANNL P&L'!D9-'YTD P&L'!G9 | J9: ='YTD P&L'!H9 | K9: ='YTD P&L'!I9-'YTD P&L'!H9 | L9: ='YTD P&L'!J9-'YTD P&L'!I9 | M9: ='ANNL P&L'!E9-'YTD P&L'!J9 | N9: ='YTD P&L'!K9 | O9: ='YTD P&L'!L9-'YTD P&L'!K9 | P9: ='YTD P&L'!M9-'YTD P&L'!L9 | Q9: ='ANNL P&L'!F9-'YTD P&L'!M9 | R9: ='YTD P&L'!N9 | S9: ='IS DRIVERS'!T7 | T9: ='IS DRIVERS'!U7 | U9: ='IS DRIVERS'!V7 | V9: ='IS DRIVERS'!W7 | W9: ='IS DRIVERS'!X7 | X9: ='IS DRIVERS'!Y7 | Y9: ='IS DRIVERS'!Z7 | Z9: ='IS DRIVERS'!AA7 | ... AO9: ='IS DRIVERS'!AP7
A10: Interest Income (Expense) | B10: ='YTD P&L'!B10 | C10: ='YTD P&L'!C10-'YTD P&L'!B10 | D10: ='YTD P&L'!D10-'YTD P&L'!C10 | E10: ='ANNL P&L'!C10-'YTD P&L'!D10 | F10: ='YTD P&L'!E10 | G10: ='YTD P&L'!F10-'YTD P&L'!E10 | H10: ='YTD P&L'!G10-'YTD P&L'!F10 | I10: ='ANNL P&L'!D10-'YTD P&L'!G10 | J10: ='YTD P&L'!H10 | K10: ='YTD P&L'!I10-'YTD P&L'!H10 | L10: ='YTD P&L'!J10-'YTD P&L'!I10 | M10: ='ANNL P&L'!E10-'YTD P&L'!J10 | N10: ='YTD P&L'!K10 | O10: ='YTD P&L'!L10-'YTD P&L'!K10 | P10: ='YTD P&L'!M10-'YTD P&L'!L10 | Q10: ='ANNL P&L'!F10-'YTD P&L'!M10 | R10: ='YTD P&L'!N10 | S10: ='IS DRIVERS'!T8 | T10: ='IS DRIVERS'!U8 | U10: ='IS DRIVERS'!V8 | V10: ='IS DRIVERS'!W8 | W10: ='IS DRIVERS'!X8 | X10: ='IS DRIVERS'!Y8 | Y10: ='IS DRIVERS'!Z8 | Z10: ='IS DRIVERS'!AA8 | ... AO10: ='IS DRIVERS'!AP8
A11: Pre-Tax Income (Loss) | B11: ='YTD P&L'!B11 | C11: ='YTD P&L'!C11-'YTD P&L'!B11 | D11: ='YTD P&L'!D11-'YTD P&L'!C11 | E11: ='ANNL P&L'!C11-'YTD P&L'!D11 | F11: ='YTD P&L'!E11 | G11: ='YTD P&L'!F11-'YTD P&L'!E11 | H11: ='YTD P&L'!G11-'YTD P&L'!F11 | I11: ='ANNL P&L'!D11-'YTD P&L'!G11 | J11: ='YTD P&L'!H11 | K11: ='YTD P&L'!I11-'YTD P&L'!H11 | L11: ='YTD P&L'!J11-'YTD P&L'!I11 | M11: ='ANNL P&L'!E11-'YTD P&L'!J11 | N11: ='YTD P&L'!K11 | O11: ='YTD P&L'!L11-'YTD P&L'!K11 | P11: ='YTD P&L'!M11-'YTD P&L'!L11 | Q11: ='ANNL P&L'!F11-'YTD P&L'!M11 | R11: ='YTD P&L'!N11 | S11: =S8+SUM(S9:S10) | T11: =T8+SUM(T9:T10) | U11: =U8+SUM(U9:U10) | V11: =V8+SUM(V9:V10) | W11: =W8+SUM(W9:W10) | X11: =X8+SUM(X9:X10) | Y11: =Y8+SUM(Y9:Y10) | Z11: =Z8+SUM(Z9:Z10) | ... AO11: =AO8+SUM(AO9:AO10)
A12: Income Tax (Expense) Benefit | B12: ='YTD P&L'!B12 | C12: ='YTD P&L'!C12-'YTD P&L'!B12 | D12: ='YTD P&L'!D12-'YTD P&L'!C12 | E12: ='ANNL P&L'!C12-'YTD P&L'!D12 | F12: ='YTD P&L'!E12 | G12: ='YTD P&L'!F12-'YTD P&L'!E12 | H12: ='YTD P&L'!G12-'YTD P&L'!F12 | I12: ='ANNL P&L'!D12-'YTD P&L'!G12 | J12: ='YTD P&L'!H12 | K12: ='YTD P&L'!I12-'YTD P&L'!H12 | L12: ='YTD P&L'!J12-'YTD P&L'!I12 | M12: ='ANNL P&L'!E12-'YTD P&L'!J12 | N12: ='YTD P&L'!K12 | O12: ='YTD P&L'!L12-'YTD P&L'!K12 | P12: ='YTD P&L'!M12-'YTD P&L'!L12 | Q12: ='ANNL P&L'!F12-'YTD P&L'!M12 | R12: ='YTD P&L'!N12 | S12: ='QTR P&L'!S11*'IS DRIVERS'!T9 | T12: ='QTR P&L'!T11*'IS DRIVERS'!U9 | U12: ='QTR P&L'!U11*'IS DRIVERS'!V9 | V12: ='QTR P&L'!V11*'IS DRIVERS'!W9 | W12: ='QTR P&L'!W11*'IS DRIVERS'!X9 | X12: ='QTR P&L'!X11*'IS DRIVERS'!Y9 | Y12: ='QTR P&L'!Y11*'IS DRIVERS'!Z9 | Z12: ='QTR P&L'!Z11*'IS DRIVERS'!AA9 | ... AO12: ='QTR P&L'!AO11*'IS DRIVERS'!AP9
A13: Net Income (Loss) | B13: ='YTD P&L'!B13 | C13: ='YTD P&L'!C13-'YTD P&L'!B13 | D13: ='YTD P&L'!D13-'YTD P&L'!C13 | E13: ='ANNL P&L'!C13-'YTD P&L'!D13 | F13: ='YTD P&L'!E13 | G13: ='YTD P&L'!F13-'YTD P&L'!E13 | H13: ='YTD P&L'!G13-'YTD P&L'!F13 | I13: ='ANNL P&L'!D13-'YTD P&L'!G13 | J13: ='YTD P&L'!H13 | K13: ='YTD P&L'!I13-'YTD P&L'!H13 | L13: ='YTD P&L'!J13-'YTD P&L'!I13 | M13: ='ANNL P&L'!E13-'YTD P&L'!J13 | N13: ='YTD P&L'!K13 | O13: ='YTD P&L'!L13-'YTD P&L'!K13 | P13: ='YTD P&L'!M13-'YTD P&L'!L13 | Q13: ='ANNL P&L'!F13-'YTD P&L'!M13 | R13: ='YTD P&L'!N13 | S13: =S11+S12 | T13: =T11+T12 | U13: =U11+U12 | V13: =V11+V12 | W13: =W11+W12 | X13: =X11+X12 | Y13: =Y11+Y12 | Z13: =Z11+Z12 | ... AO13: =AO11+AO12
A14: Net Income (Loss) Attributable to Noncontrolling Interest | B14: ='YTD P&L'!B14 | C14: ='YTD P&L'!C14-'YTD P&L'!B14 | D14: ='YTD P&L'!D14-'YTD P&L'!C14 | E14: ='ANNL P&L'!C14-'YTD P&L'!D14 | F14: ='YTD P&L'!E14 | G14: ='YTD P&L'!F14-'YTD P&L'!E14 | H14: ='YTD P&L'!G14-'YTD P&L'!F14 | I14: ='ANNL P&L'!D14-'YTD P&L'!G14 | J14: ='YTD P&L'!H14 | K14: ='YTD P&L'!I14-'YTD P&L'!H14 | L14: ='YTD P&L'!J14-'YTD P&L'!I14 | M14: ='ANNL P&L'!E14-'YTD P&L'!J14 | N14: ='YTD P&L'!K14 | O14: ='YTD P&L'!L14-'YTD P&L'!K14 | P14: ='YTD P&L'!M14-'YTD P&L'!L14 | Q14: ='ANNL P&L'!F14-'YTD P&L'!M14 | R14: ='YTD P&L'!N14 | S14: ='IS DRIVERS'!T10 | T14: ='IS DRIVERS'!U10 | U14: ='IS DRIVERS'!V10 | V14: ='IS DRIVERS'!W10 | W14: ='IS DRIVERS'!X10 | X14: ='IS DRIVERS'!Y10 | Y14: ='IS DRIVERS'!Z10 | Z14: ='IS DRIVERS'!AA10 | ... AO14: ='IS DRIVERS'!AP10
A15: Net Income (Loss) Less NCI | B15: ='YTD P&L'!B15 | C15: ='YTD P&L'!C15-'YTD P&L'!B15 | D15: ='YTD P&L'!D15-'YTD P&L'!C15 | E15: ='ANNL P&L'!C15-'YTD P&L'!D15 | F15: ='YTD P&L'!E15 | G15: ='YTD P&L'!F15-'YTD P&L'!E15 | H15: ='YTD P&L'!G15-'YTD P&L'!F15 | I15: ='ANNL P&L'!D15-'YTD P&L'!G15 | J15: ='YTD P&L'!H15 | K15: ='YTD P&L'!I15-'YTD P&L'!H15 | L15: ='YTD P&L'!J15-'YTD P&L'!I15 | M15: ='ANNL P&L'!E15-'YTD P&L'!J15 | N15: ='YTD P&L'!K15 | O15: ='YTD P&L'!L15-'YTD P&L'!K15 | P15: ='YTD P&L'!M15-'YTD P&L'!L15 | Q15: ='ANNL P&L'!F15-'YTD P&L'!M15 | R15: ='YTD P&L'!N15
A16: Basic Earnings (Loss) per Share
A17: Diluted Earnings (Loss) per Share
A18: Weighted Average Shares Outstanding (Basic)
A19: Weighted Average Shares Outstanding (Diluted)

Sheet QTR BS
B1: Q4 FY2022 | C1: Q1 FY2023 | D1: Q2 FY2023 | E1: Q3 FY2023 | F1: Q4 FY2023 | G1: Q1 FY2024 | H1: Q2 FY2024 | I1: Q3 FY2024 | J1: Q4 FY2024 | K1: Q1 FY2025 | L1: Q2 FY2025 | M1: Q3 FY2025 | N1: Q4 FY2025 | O1: Q1 FY2026 | P1: Q2 FY2026E | Q1: Q3 FY2026E | R1: Q4 FY2026E | S1: Q1 FY2027E | T1: Q2 FY2027E | U1: Q3 FY2027E | V1: Q4 FY2027E | W1: Q1 FY2028E | X1: Q2 FY2028E | Y1: Q3 FY2028E | Z1: Q4 FY2028E | AA1: Q1 FY2029E | AB1: Q2 FY2029E | AC1: Q3 FY2029E | AD1: Q4 FY2029E | AE1: Q1 FY2030E | AF1: Q2 FY2030E | AG1: Q3 FY2030E | AH1: Q4 FY2030E | AI1: Q1 FY2031E | AJ1: Q2 FY2031E | AK1: Q3 FY2031E | AL1: Q4 FY2031E
A2: Cash & Cash Equivalents | B2: ='BALANCE SHEET'!B2 | C2: ='YTD BS'!C2 | D2: ='YTD BS'!D2 | E2: ='YTD BS'!E2 | F2: ='BALANCE SHEET'!C2 | G2: ='YTD BS'!G2 | H2: ='YTD BS'!H2 | I2: ='YTD BS'!I2 | J2: ='BALANCE SHEET'!D2 | K2: ='YTD BS'!K2 | L2: ='YTD BS'!L2 | M2: ='YTD BS'!M2 | N2: ='BALANCE SHEET'!E2 | O2: ='YTD BS'!O2 | P2: ='BS DRIVERS'!P2 | Q2: ='BS DRIVERS'!Q2 | R2: ='BS DRIVERS'!R2 | S2: ='BS DRIVERS'!S2 | T2: ='BS DRIVERS'!T2 | U2: ='BS DRIVERS'!U2 | V2: ='BS DRIVERS'!V2 | W2: ='BS DRIVERS'!W2 | ... AL2: ='BS DRIVERS'!AL2
A3: Short-Term Investments | B3: ='BALANCE SHEET'!B3 | C3: ='YTD BS'!C3 | D3: ='YTD BS'!D3 | E3: ='YTD BS'!E3 | F3: ='BALANCE SHEET'!C3 | G3: ='YTD BS'!G3 | H3: ='YTD BS'!H3 | I3: ='YTD BS'!I3 | J3: ='BALANCE SHEET'!D3 | K3: ='YTD BS'!K3 | L3: ='YTD BS'!L3 | M3: ='YTD BS'!M3 | N3: ='BALANCE SHEET'!E3 | O3: ='YTD BS'!O3 | P3: ='BS DRIVERS'!P3 | Q3: ='BS DRIVERS'!Q3 | R3: ='BS DRIVERS'!R3 | S3: ='BS DRIVERS'!S3 | T3: ='BS DRIVERS'!T3 | U3: ='BS DRIVERS'!U3 | V3: ='BS DRIVERS'!V3 | W3: ='BS DRIVERS'!W3 | ... AL3: ='BS DRIVERS'!AL3
A4: Accounts Receivable | B4: ='BALANCE SHEET'!B4 | C4: ='YTD BS'!C4 | D4: ='YTD BS'!D4 | E4: ='YTD BS'!E4 | F4: ='BALANCE SHEET'!C4 | G4: ='YTD BS'!G4 | H4: ='YTD BS'!H4 | I4: ='YTD BS'!I4 | J4: ='BALANCE SHEET'!D4 | K4: ='YTD BS'!K4 | L4: ='YTD BS'!L4 | M4: ='YTD BS'!M4 | N4: ='BALANCE SHEET'!E4 | O4: ='YTD BS'!O4 | P4: ='QTR P&L'!S2*'BS DRIVERS'!P4/ASSUMPTIONS!$B$2 | Q4: ='QTR P&L'!T2*'BS DRIVERS'!Q4/ASSUMPTIONS!$B$2 | R4: ='QTR P&L'!U2*'BS DRIVERS'!R4/ASSUMPTIONS!$B$2 | S4: ='QTR P&L'!V2*'BS DRIVERS'!S4/ASSUMPTIONS!$B$2 | T4: ='QTR P&L'!W2*'BS DRIVERS'!T4/ASSUMPTIONS!$B$2 | U4: ='QTR P&L'!X2*'BS DRIVERS'!U4/ASSUMPTIONS!$B$2 | V4: ='QTR P&L'!Y2*'BS DRIVERS'!V4/ASSUMPTIONS!$B$2 | W4: ='QTR P&L'!Z2*'BS DRIVERS'!W4/ASSUMPTIONS!$B$2 | ... AL4: ='QTR P&L'!AO2*'BS DRIVERS'!AL4/ASSUMPTIONS!$B$2
A5: Inventories | B5: ='BALANCE SHEET'!B5 | C5: ='YTD BS'!C5 | D5: ='YTD BS'!D5 | E5: ='YTD BS'!E5 | F5: ='BALANCE SHEET'!C5 | G5: ='YTD BS'!G5 | H5: ='YTD BS'!H5 | I5: ='YTD BS'!I5 | J5: ='BALANCE SHEET'!D5 | K5: ='YTD BS'!K5 | L5: ='YTD BS'!L5 | M5: ='YTD BS'!M5 | N5: ='BALANCE SHEET'!E5 | O5: ='YTD BS'!O5 | P5: ='QTR P&L'!S3*'BS DRIVERS'!P5/ASSUMPTIONS!$B$2 | Q5: ='QTR P&L'!T3*'BS DRIVERS'!Q5/ASSUMPTIONS!$B$2 | R5: ='QTR P&L'!U3*'BS DRIVERS'!R5/ASSUMPTIONS!$B$2 | S5: ='QTR P&L'!V3*'BS DRIVERS'!S5/ASSUMPTIONS!$B$2 | T5: ='QTR P&L'!W3*'BS DRIVERS'!T5/ASSUMPTIONS!$B$2 | U5: ='QTR P&L'!X3*'BS DRIVERS'!U5/ASSUMPTIONS!$B$2 | V5: ='QTR P&L'!Y3*'BS DRIVERS'!V5/ASSUMPTIONS!$B$2 | W5: ='QTR P&L'!Z3*'BS DRIVERS'!W5/ASSUMPTIONS!$B$2 | ... AL5: ='QTR P&L'!AO3*'BS DRIVERS'!AL5/ASSUMPTIONS!$B$2
A6: Prepaid Expenses | B6: ='BALANCE SHEET'!B6 | C6: ='YTD BS'!C6 | D6: ='YTD BS'!D6 | E6: ='YTD BS'!E6 | F6: ='BALANCE SHEET'!C6 | G6: ='YTD BS'!G6 | H6: ='YTD BS'!H6 | I6: ='YTD BS'!I6 | J6: ='BALANCE SHEET'!D6 | K6: ='YTD BS'!K6 | L6: ='YTD BS'!L6 | M6: ='YTD BS'!M6 | N6: ='BALANCE SHEET'!E6 | O6: ='YTD BS'!O6 | P6: ='QTR P&L'!S2*'BS DRIVERS'!P6 | Q6: ='QTR P&L'!T2*'BS DRIVERS'!Q6 | R6: ='QTR P&L'!U2*'BS DRIVERS'!R6 | S6: ='QTR P&L'!V2*'BS DRIVERS'!S6 | T6: ='QTR P&L'!W2*'BS DRIVERS'!T6 | U6: ='QTR P&L'!X2*'BS DRIVERS'!U6 | V6: ='QTR P&L'!Y2*'BS DRIVERS'!V6 | W6: ='QTR P&L'!Z2*'BS DRIVERS'!W6 | ... AL6: ='QTR P&L'!AO2*'BS DRIVERS'!AL6
