Workbook

Sheet ASSUMPTIONS
A1: Assumption | B1: Value | C1: Note
A2: Days in Quarter | B2: 91 | C2: Used by DSO/DIO/DPO ratios. Approximation; varies 89-92 by quarter.

Sheet ANNL P&L
B1: FY2017 | C1: FY2018 | D1: FY2019 | E1: FY2020 | F1: FY2021 | G1: FY2022 | H1: FY2023 | I1: FY2024 | J1: FY2025 | K1: FY2026E | L1: FY2027E | M1: FY2028E | N1: FY2029E | O1: FY2030E | P1: FY2031E
A2: Net Sales / Revenue | B2: 110855 | C2: 136819 | D2: 161857 | E2: 182527 | F2: 257637 | G2: 282836 | H2: 307394 | I2: 350018 | J2: 402836 | K2: ='QTR P&L'!AH2+'QTR P&L'!AI2+'QTR P&L'!AJ2+'QTR P&L'!AK2 | L2: ='QTR P&L'!AL2+'QTR P&L'!AM2+'QTR P&L'!AN2+'QTR P&L'!AO2 | M2: ='QTR P&L'!AP2+'QTR P&L'!AQ2+'QTR P&L'!AR2+'QTR P&L'!AS2 | N2: ='QTR P&L'!AT2+'QTR P&L'!AU2+'QTR P&L'!AV2+'QTR P&L'!AW2 | O2: ='QTR P&L'!AX2+'QTR P&L'!AY2+'QTR P&L'!AZ2+'QTR P&L'!BA2
A3: COGS | B3: -45583 | C3: -59549 | D3: -71896 | E3: -84732 | F3: -110939 | G3: -126203 | H3: -133332 | I3: -146306 | J3: -162535 | K3: ='QTR P&L'!AH3+'QTR P&L'!AI3+'QTR P&L'!AJ3+'QTR P&L'!AK3 | L3: ='QTR P&L'!AL3+'QTR P&L'!AM3+'QTR P&L'!AN3+'QTR P&L'!AO3 | M3: ='QTR P&L'!AP3+'QTR P&L'!AQ3+'QTR P&L'!AR3+'QTR P&L'!AS3 | N3: ='QTR P&L'!AT3+'QTR P&L'!AU3+'QTR P&L'!AV3+'QTR P&L'!AW3 | O3: ='QTR P&L'!AX3+'QTR P&L'!AY3+'QTR P&L'!AZ3+'QTR P&L'!BA3
A4: Gross Profit (Loss) | B4: =B2+B3 | C4: =C2+C3 | D4: =D2+D3 | E4: =E2+E3 | F4: =F2+F3 | G4: =G2+G3 | H4: =H2+H3 | I4: =I2+I3 | ... P4: =P2+P3
A5: Research and Development | B5: -16625 | C5: -21419 | D5: -26018 | E5: -27573 | F5: -31562 | G5: -39500 | H5: -45427 | I5: -49326 | J5: -61087 | K5: ='QTR P&L'!AH5+'QTR P&L'!AI5+'QTR P&L'!AJ5+'QTR P&L'!AK5 | L5: ='QTR P&L'!AL5+'QTR P&L'!AM5+'QTR P&L'!AN5+'QTR P&L'!AO5 | M5: ='QTR P&L'!AP5+'QTR P&L'!AQ5+'QTR P&L'!AR5+'QTR P&L'!AS5 | N5: ='QTR P&L'!AT5+'QTR P&L'!AU5+'QTR P&L'!AV5+'QTR P&L'!AW5 | O5: ='QTR P&L'!AX5+'QTR P&L'!AY5+'QTR P&L'!AZ5+'QTR P&L'!BA5
A6: Sales and Marketing | B6: -12893 | C6: -16333 | D6: -18464 | E6: -17946 | F6: -22912 | G6: -26567 | H6: -27917 | I6: -27808 | J6: -28693 | K6: ='QTR P&L'!AH6+'QTR P&L'!AI6+'QTR P&L'!AJ6+'QTR P&L'!AK6 | L6: ='QTR P&L'!AL6+'QTR P&L'!AM6+'QTR P&L'!AN6+'QTR P&L'!AO6 | M6: ='QTR P&L'!AP6+'QTR P&L'!AQ6+'QTR P&L'!AR6+'QTR P&L'!AS6 | N6: ='QTR P&L'!AT6+'QTR P&L'!AU6+'QTR P&L'!AV6+'QTR P&L'!AW6 | O6: ='QTR P&L'!AX6+'QTR P&L'!AY6+'QTR P&L'!AZ6+'QTR P&L'!BA6
A7: General and Administrative | B7: -6840 | C7: -6923 | D7: -9551 | E7: -11052 | F7: -13510 | G7: -15724 | H7: -16425 | I7: -14188 | J7: -21482 | K7: ='QTR P&L'!AH7+'QTR P&L'!AI7+'QTR P&L'!AJ7+'QTR P&L'!AK7 | L7: ='QTR P&L'!AL7+'QTR P&L'!AM7+'QTR P&L'!AN7+'QTR P&L'!AO7 | M7: ='QTR P&L'!AP7+'QTR P&L'!AQ7+'QTR P&L'!AR7+'QTR P&L'!AS7 | N7: ='QTR P&L'!AT7+'QTR P&L'!AU7+'QTR P&L'!AV7+'QTR P&L'!AW7 | O7: ='QTR P&L'!AX7+'QTR P&L'!AY7+'QTR P&L'!AZ7+'QTR P&L'!BA7
A8: Litigation and Regulatory Charges | B8: -2736 | C8: -5071 | D8: -1697 | E8: 0 | F8: 0 | G8: 0 | H8: 0 | I8: 0 | J8: 0 | K8: ='QTR P&L'!AH8+'QTR P&L'!AI8+'QTR P&L'!AJ8+'QTR P&L'!AK8 | L8: ='QTR P&L'!AL8+'QTR P&L'!AM8+'QTR P&L'!AN8+'QTR P&L'!AO8 | M8: ='QTR P&L'!AP8+'QTR P&L'!AQ8+'QTR P&L'!AR8+'QTR P&L'!AS8 | N8: ='QTR P&L'!AT8+'QTR P&L'!AU8+'QTR P&L'!AV8+'QTR P&L'!AW8 | O8: ='QTR P&L'!AX8+'QTR P&L'!AY8+'QTR P&L'!AZ8+'QTR P&L'!BA8
A9: Income (Loss) from Operations | B9: =B4+SUM(B5:B8) | C9: =C4+SUM(C5:C8) | D9: =D4+SUM(D5:D8) | E9: =E4+SUM(E5:E8) | F9: =F4+SUM(F5:F8) | G9: =G4+SUM(G5:G8) | H9: =H4+SUM(H5:H8) | I9: =I4+SUM(I5:I8) | ... P9: =P4+SUM(P5:P8)
A10: Other Income (Expense) | B10: 1015 | C10: 7389 | D10: 5394 | E10: 6858 | F10: 12020 | G10: -3514 | H10: 1424 | I10: 7425 | J10: 29787 | K10: ='QTR P&L'!AH10+'QTR P&L'!AI10+'QTR P&L'!AJ10+'QTR P&L'!AK10 | L10: ='QTR P&L'!AL10+'QTR P&L'!AM10+'QTR P&L'!AN10+'QTR P&L'!AO10 | M10: ='QTR P&L'!AP10+'QTR P&L'!AQ10+'QTR P&L'!AR10+'QTR P&L'!AS10 | N10: ='QTR P&L'!AT10+'QTR P&L'!AU10+'QTR P&L'!AV10+'QTR P&L'!AW10 | O10: ='QTR P&L'!AX10+'QTR P&L'!AY10+'QTR P&L'!AZ10+'QTR P&L'!BA10
A11: Pre-Tax Income (Loss) | B11: =B9+B10 | C11: =C9+C10 | D11: =D9+D10 | E11: =E9+E10 | F11: =F9+F10 | G11: =G9+G10 | H11: =H9+H10 | I11: =I9+I10 | ... P11: =P9+P10
A12: Income Tax (Expense) Benefit | B12: -14531 | C12: -4177 | D12: -5282 | E12: -7813 | F12: -14701 | G12: -11356 | H12: -11922 | I12: -19697 | J12: -26656 | K12: ='QTR P&L'!AH12+'QTR P&L'!AI12+'QTR P&L'!AJ12+'QTR P&L'!AK12 | L12: ='QTR P&L'!AL12+'QTR P&L'!AM12+'QTR P&L'!AN12+'QTR P&L'!AO12 | M12: ='QTR P&L'!AP12+'QTR P&L'!AQ12+'QTR P&L'!AR12+'QTR P&L'!AS12 | N12: ='QTR P&L'!AT12+'QTR P&L'!AU12+'QTR P&L'!AV12+'QTR P&L'!AW12 | O12: ='QTR P&L'!AX12+'QTR P&L'!AY12+'QTR P&L'!AZ12+'QTR P&L'!BA12
A13: Net Income (Loss) | B13: =B11+B12 | C13: =C11+C12 | D13: =D11+D12 | E13: =E11+E12 | F13: =F11+F12 | G13: =G11+G12 | H13: =H11+H12 | I13: =I11+I12 | ... P13: =P11+P12
A14: Basic Earnings (Loss) per Share | B14: 18.27 | C14: 44.22 | D14: 49.59 | E14: 59.15 | F14: 113.88 | G14: 4.59 | H14: 5.84 | I14: 8.13 | J14: 10.91
A15: Diluted Earnings (Loss) per Share | B15: 18 | C15: 43.7 | D15: 49.16 | E15: 58.61 | F15: 112.2 | G15: 4.56 | H15: 5.8 | I15: 8.04 | J15: 10.81

Sheet BALANCE SHEET
B1: FY2018 | C1: FY2019 | D1: FY2020 | E1: FY2021 | F1: FY2022 | G1: FY2023 | H1: FY2024 | I1: FY2025 | J1: FY2026E | K1: FY2027E | L1: FY2028E | M1: FY2029E | N1: FY2030E | O1: FY2031E
A2: Cash & Cash Equivalents | B2: 16701 | C2: 18498 | D2: 26465 | E2: 20945 | F2: 21879 | G2: 24048 | H2: 23466 | I2: 30708 | J2: ='QTR BS'!AH2 | K2: ='QTR BS'!AL2 | L2: ='QTR BS'!AP2 | M2: ='QTR BS'!AT2 | N2: ='QTR BS'!AX2
A3: Short-Term Investments | B3: 92439 | C3: 101177 | D3: 110229 | E3: 118704 | F3: 91883 | G3: 86868 | H3: 72191 | I3: 96135 | J3: ='QTR BS'!AH3 | K3: ='QTR BS'!AL3 | L3: ='QTR BS'!AP3 | M3: ='QTR BS'!AT3 | N3: ='QTR BS'!AX3
A4: Accounts Receivable | B4: 20838 | C4: 25326 | D4: 30930 | E4: 39304 | F4: 40258 | G4: 47964 | H4: 52340 | I4: 62886 | J4: ='QTR BS'!AH4 | K4: ='QTR BS'!AL4 | L4: ='QTR BS'!AP4 | M4: ='QTR BS'!AT4 | N4: ='QTR BS'!AX4
A5: Note Receivable - Current | B5: 355 | C5: 2166 | D5: 454 | E5: 966 | F5: 0 | G5: 0 | H5: 0 | I5: 0 | J5: ='QTR BS'!AH5 | K5: ='QTR BS'!AL5 | L5: ='QTR BS'!AP5 | M5: ='QTR BS'!AT5 | N5: ='QTR BS'!AX5
A6: Inventories | B6: 1107 | C6: 999 | D6: 728 | E6: 1170 | F6: 2670 | G6: 0 | H6: 0 | I6: 0 | J6: ='QTR BS'!AH6 | K6: ='QTR BS'!AL6 | L6: ='QTR BS'!AP6 | M6: ='QTR BS'!AT6 | N6: ='QTR BS'!AX6
A7: Other Current Assets | B7: 4236 | C7: 4412 | D7: 5490 | E7: 7054 | F7: 8105 | G7: 12650 | H7: 15714 | I7: 16309 | J7: ='QTR BS'!AH7 | K7: ='QTR BS'!AL7 | L7: ='QTR BS'!AP7 | M7: ='QTR BS'!AT7 | N7: ='QTR BS'!AX7
A8: Total Current Assets | B8: =SUM(B2:B7) | C8: =SUM(C2:C7) | D8: =SUM(D2:D7) | E8: =SUM(E2:E7) | F8: =SUM(F2:F7) | G8: =SUM(G2:G7) | H8: =SUM(H2:H7) | I8: =SUM(I2:I7) | ... O8: =SUM(O2:O7)
A9: Long-Term Investments | B9: 13859 | C9: 13078 | D9: 20703 | E9: 29549 | F9: 30492 | G9: 31008 | H9: 37982 | I9: 68687 | J9: ='QTR BS'!AH9 | K9: ='QTR BS'!AL9 | L9: ='QTR BS'!AP9 | M9: ='QTR BS'!AT9 | N9: ='QTR BS'!AX9
A10: Deferred Tax Assets | B10: 737 | C10: 721 | D10: 1084 | E10: 1284 | F10: 5261 | G10: 12169 | H10: 17180 | I10: 9113 | J10: ='QTR BS'!AH10 | K10: ='QTR BS'!AL10 | L10: ='QTR BS'!AP10 | M10: ='QTR BS'!AT10 | N10: ='QTR BS'!AX10
A11: Net PP&E | B11: 59719 | C11: 73646 | D11: 84749 | E11: 97599 | F11: 112668 | G11: 134345 | H11: 171036 | I11: 246597 | J11: ='QTR BS'!AH11 | K11: ='QTR BS'!AL11 | L11: ='QTR BS'!AP11 | M11: ='QTR BS'!AT11 | N11: ='QTR BS'!AX11
A12: ROU Assets - Operating - Non-Current | B12: 0 | C12: 10941 | D12: 12211 | E12: 12959 | F12: 14381 | G12: 14091 | H12: 13588 | I12: 15221 | J12: ='QTR BS'!AH12 | K12: ='QTR BS'!AL12 | L12: ='QTR BS'!AP12 | M12: ='QTR BS'!AT12 | N12: ='QTR BS'!AX12
A13: Intangible Assets | B13: 2220 | C13: 1979 | D13: 1445 | E13: 1417 | F13: 2084 | G13: 0 | H13: 0 | I13: 0 | J13: ='QTR BS'!AH13 | K13: ='QTR BS'!AL13 | L13: ='QTR BS'!AP13 | M13: ='QTR BS'!AT13 | N13: ='QTR BS'!AX13
A14: Goodwill | B14: 17888 | C14: 20624 | D14: 21175 | E14: 22956 | F14: 28960 | G14: 29198 | H14: 31885 | I14: 33380 | J14: ='QTR BS'!AH14 | K14: ='QTR BS'!AL14 | L14: ='QTR BS'!AP14 | M14: ='QTR BS'!AT14 | N14: ='QTR BS'!AX14
A15: Other Non-Current Assets | B15: 2693 | C15: 2342 | D15: 3953 | E15: 5361 | F15: 6623 | G15: 10051 | H15: 14874 | I15: 16245 | J15: ='QTR BS'!AH15 | K15: ='QTR BS'!AL15 | L15: ='QTR BS'!AP15 | M15: ='QTR BS'!AT15 | N15: ='QTR BS'!AX15
A16: Total Assets | B16: =B8+SUM(B9:B15) | C16: =C8+SUM(C9:C15) | D16: =D8+SUM(D9:D15) | E16: =E8+SUM(E9:E15) | F16: =F8+SUM(F9:F15) | G16: =G8+SUM(G9:G15) | H16: =H8+SUM(H9:H15) | I16: =I8+SUM(I9:I15) | ... O16: =O8+SUM(O9:O15)
A17: Accounts Payable | B17: 4378 | C17: 5561 | D17: 5589 | E17: 6037 | F17: 5128 | G17: 7493 | H17: 7987 | I17: 12200 | J17: ='QTR BS'!AH17 | K17: ='QTR BS'!AL17 | L17: ='QTR BS'!AP17 | M17: ='QTR BS'!AT17 | N17: ='QTR BS'!AX17
A18: Accrued Compensation | B18: 6839 | C18: 8495 | D18: 11086 | E18: 13889 | F18: 14028 | G18: 15140 | H18: 15069 | I18: 17546 | J18: ='QTR BS'!AH18 | K18: ='QTR BS'!AL18 | L18: ='QTR BS'!AP18 | M18: ='QTR BS'!AT18 | N18: ='QTR BS'!AX18
A19: Accrued Expenses | B19: 16958 | C19: 23067 | D19: 28631 | E19: 31236 | F19: 37866 | G19: 46168 | H19: 51228 | I19: 55557 | J19: ='QTR BS'!AH19 | K19: ='QTR BS'!AL19 | L19: ='QTR BS'!AP19 | M19: ='QTR BS'!AT19 | N19: ='QTR BS'!AX19
A20: Accrued Revenue Share | B20: 4592 | C20: 5916 | D20: 7500 | E20: 8996 | F20: 8370 | G20: 8876 | H20: 9802 | I20: 10864 | J20: ='QTR BS'!AH20 | K20: ='QTR BS'!AL20 | L20: ='QTR BS'!AP20 | M20: ='QTR BS'!AT20 | N20: ='QTR BS'!AX20
A21: Deferred Revenue - Current | B21: 1784 | C21: 1908 | D21: 2543 | E21: 3288 | F21: 3908 | G21: 4137 | H21: 5036 | I21: 6578 | J21: ='QTR BS'!AH21 | K21: ='QTR BS'!AL21 | L21: ='QTR BS'!AP21 | M21: ='QTR BS'!AT21 | N21: ='QTR BS'!AX21
A22: Income Taxes Payable | B22: 69 | C22: 274 | D22: 1485 | E22: 808 | F22: 0 | G22: 0 | H22: 0 | I22: 0 | J22: ='QTR BS'!AH22 | K22: ='QTR BS'!AL22 | L22: ='QTR BS'!AP22 | M22: ='QTR BS'!AT22 | N22: ='QTR BS'!AX22
A23: Total Current Liabilities | B23: =SUM(B17:B22) | C23: =SUM(C17:C22) | D23: =SUM(D17:D22) | E23: =SUM(E17:E22) | F23: =SUM(F17:F22) | G23: =SUM(G17:G22) | H23: =SUM(H17:H22) | I23: =SUM(I17:I22) | ... O23: =SUM(O17:O22)
A24: Long-Term Debt | B24: 15339 | C24: 14439 | D24: 22781 | E24: 23993 | F24: 23959 | G24: 21727 | H24: 19665 | I24: 56078 | J24: ='QTR BS'!AH24 | K24: ='QTR BS'!AL24 | L24: ='QTR BS'!AP24 | M24: ='QTR BS'!AT24 | N24: ='QTR BS'!AX24
A25: Deferred Revenue - Non-Current | B25: 396 | C25: 358 | D25: 481 | E25: 535 | F25: 599 | G25: 911 | H25: 0 | I25: 0 | J25: ='QTR BS'!AH25 | K25: ='QTR BS'!AL25 | L25: ='QTR BS'!AP25 | M25: ='QTR BS'!AT25 | N25: ='QTR BS'!AX25
A26: Deferred Tax Liability | B26: 1264 | C26: 1701 | D26: 3561 | E26: 5257 | F26: 514 | G26: 485 | H26: 0 | I26: 0 | J26: ='QTR BS'!AH26 | K26: ='QTR BS'!AL26 | L26: ='QTR BS'!AP26 | M26: ='QTR BS'!AT26 | N26: ='QTR BS'!AX26
A27: Lease Liability - Operating - Non-Current | B27: 0 | C27: 10214 | D27: 11146 | E27: 11389 | F27: 12501 | G27: 12460 | H27: 11691 | I27: 12744 | J27: ='QTR BS'!AH27 | K27: ='QTR BS'!AL27 | L27: ='QTR BS'!AP27 | M27: ='QTR BS'!AT27 | N27: ='QTR BS'!AX27
A28: Other Non-Current Liabilities | B28: 3545 | C28: 2534 | D28: 2269 | E28: 2205 | F28: 2247 | G28: 1616 | H28: 4694 | I28: 8449 | J28: ='QTR BS'!AH28 | K28: ='QTR BS'!AL28 | L28: ='QTR BS'!AP28 | M28: ='QTR BS'!AT28 | N28: ='QTR BS'!AX28
A29: Total Liabilities | B29: =B23+SUM(B24:B28) | C29: =C23+SUM(C24:C28) | D29: =D23+SUM(D24:D28) | E29: =E23+SUM(E24:E28) | F29: =F23+SUM(F24:F28) | G29: =G23+SUM(G24:G28) | H29: =H23+SUM(H24:H28) | I29: =I23+SUM(I24:I28) | ... O29: =O23+SUM(O24:O28)
A30: Convertible Preferred Stock | B30: 0 | C30: 0 | D30: 0 | E30: 0 | F30: 0 | G30: 0 | H30: 0 | I30: 0 | J30: ='QTR BS'!AH30 | K30: ='QTR BS'!AL30 | L30: ='QTR BS'!AP30 | M30: ='QTR BS'!AT30 | N30: ='QTR BS'!AX30
A31: Common Stock and Additional Paid-in Capital | B31: 45049 | C31: 50552 | D31: 58510 | E31: 61774 | F31: 68184 | G31: 76534 | H31: 84800 | I31: 93126 | J31: ='QTR BS'!AH31 | K31: ='QTR BS'!AL31 | L31: ='QTR BS'!AP31 | M31: ='QTR BS'!AT31 | N31: ='QTR BS'!AX31
A32: Accumulated Other Comprehensive Income (Loss) | B32: -2306 | C32: -1232 | D32: 633 | E32: -1623 | F32: -7603 | G32: -4402 | H32: -4800 | I32: -1916 | J32: ='QTR BS'!AH32 | K32: ='QTR BS'!AL32 | L32: ='QTR BS'!AP32 | M32: ='QTR BS'!AT32 | N32: ='QTR BS'!AX32
A33: Retained Earnings (Accumulated Deficit) | B33: 134885 | C33: 152122 | D33: 163401 | E33: 191484 | F33: 195563 | G33: 211247 | H33: 245084 | I33: 324055 | J33: ='QTR BS'!AH33 | K33: ='QTR BS'!AL33 | L33: ='QTR BS'!AP33 | M33: ='QTR BS'!AT33 | N33: ='QTR BS'!AX33
A34: Total Stockholders' Equity | B34: =SUM(B30:B33) | C34: =SUM(C30:C33) | D34: =SUM(D30:D33) | E34: =SUM(E30:E33) | F34: =SUM(F30:F33) | G34: =SUM(G30:G33) | H34: =SUM(H30:H33) | I34: =SUM(I30:I33) | ... O34: =SUM(O30:O33)
A35: Total Liabilities, Mezzanine & Stockholders' Equity | B35: =B29+B34 | C35: =C29+C34 | D35: =D29+D34 | E35: =E29+E34 | F35: =F29+F34 | G35: =G29+G34 | H35: =H29+H34 | I35: =I29+I34 | ... O35: =O29+O34

Sheet CASH FLOW
B1: FY2017 | C1: FY2018 | D1: FY2019 | E1: FY2020 | F1: FY2021 | G1: FY2022 | H1: FY2023 | I1: FY2024 | J1: FY2025 | K1: FY2026E | L1: FY2027E | M1: FY2028E | N1: FY2029E | O1: FY2030E | P1: FY2031E
A2: Net Income (Loss) | B2: 12662 | C2: 30736 | D2: 34343 | E2: 40269 | F2: 76033 | G2: 59972 | H2: 73795 | I2: 100118 | J2: 132170 | K2: ='QTR CF'!AH2+'QTR CF'!AI2+'QTR CF'!AJ2+'QTR CF'!AK2 | L2: ='QTR CF'!AL2+'QTR CF'!AM2+'QTR CF'!AN2+'QTR CF'!AO2 | M2: ='QTR CF'!AP2+'QTR CF'!AQ2+'QTR CF'!AR2+'QTR CF'!AS2 | N2: ='QTR CF'!AT2+'QTR CF'!AU2+'QTR CF'!AV2+'QTR CF'!AW2 | O2: ='QTR CF'!AX2+'QTR CF'!AY2+'QTR CF'!AZ2+'QTR CF'!BA2
A3: Depreciation and Impairment of PP&E | B3: 6103 | C3: 8164 | D3: 10856 | E3: 12905 | F3: 11555 | G3: 15287 | H3: 0 | I3: 0 | J3: 0 | K3: ='QTR CF'!AH3+'QTR CF'!AI3+'QTR CF'!AJ3+'QTR CF'!AK3 | L3: ='QTR CF'!AL3+'QTR CF'!AM3+'QTR CF'!AN3+'QTR CF'!AO3 | M3: ='QTR CF'!AP3+'QTR CF'!AQ3+'QTR CF'!AR3+'QTR CF'!AS3 | N3: ='QTR CF'!AT3+'QTR CF'!AU3+'QTR CF'!AV3+'QTR CF'!AW3 | O3: ='QTR CF'!AX3+'QTR CF'!AY3+'QTR CF'!AZ3+'QTR CF'!BA3
A4: Amortization and Impairment of Intangibles | B4: 812 | C4: 871 | D4: 925 | E4: 792 | F4: 886 | G4: 641 | H4: 0 | I4: 0 | J4: 0 | K4: ='QTR CF'!AH4+'QTR CF'!AI4+'QTR CF'!AJ4+'QTR CF'!AK4 | L4: ='QTR CF'!AL4+'QTR CF'!AM4+'QTR CF'!AN4+'QTR CF'!AO4 | M4: ='QTR CF'!AP4+'QTR CF'!AQ4+'QTR CF'!AR4+'QTR CF'!AS4 | N4: ='QTR CF'!AT4+'QTR CF'!AU4+'QTR CF'!AV4+'QTR CF'!AW4 | O4: ='QTR CF'!AX4+'QTR CF'!AY4+'QTR CF'!AZ4+'QTR CF'!BA4
A5: Depreciation | B5: 0 | C5: 0 | D5: 0 | E5: 0 | F5: 0 | G5: 0 | H5: 11946 | I5: 15311 | J5: 21136 | K5: ='QTR CF'!AH5+'QTR CF'!AI5+'QTR CF'!AJ5+'QTR CF'!AK5 | L5: ='QTR CF'!AL5+'QTR CF'!AM5+'QTR CF'!AN5+'QTR CF'!AO5 | M5: ='QTR CF'!AP5+'QTR CF'!AQ5+'QTR CF'!AR5+'QTR CF'!AS5 | N5: ='QTR CF'!AT5+'QTR CF'!AU5+'QTR CF'!AV5+'QTR CF'!AW5 | O5: ='QTR CF'!AX5+'QTR CF'!AY5+'QTR CF'!AZ5+'QTR CF'!BA5
A6: Stock-Based Compensation | B6: 7679 | C6: 9353 | D6: 10794 | E6: 12991 | F6: 15376 | G6: 19362 | H6: 22460 | I6: 22785 | J6: 24953 | K6: ='QTR CF'!AH6+'QTR CF'!AI6+'QTR CF'!AJ6+'QTR CF'!AK6 | L6: ='QTR CF'!AL6+'QTR CF'!AM6+'QTR CF'!AN6+'QTR CF'!AO6 | M6: ='QTR CF'!AP6+'QTR CF'!AQ6+'QTR CF'!AR6+'QTR CF'!AS6 | N6: ='QTR CF'!AT6+'QTR CF'!AU6+'QTR CF'!AV6+'QTR CF'!AW6 | O6: ='QTR CF'!AX6+'QTR CF'!AY6+'QTR CF'!AZ6+'QTR CF'!BA6
A7: (Benefit) Provision for Deferred Income Taxes | B7: 258 | C7: 778 | D7: 173 | E7: 1390 | F7: 1808 | G7: -8081 | H7: -7763 | I7: -5257 | J7: 8348 | K7: ='QTR CF'!AH7+'QTR CF'!AI7+'QTR CF'!AJ7+'QTR CF'!AK7 | L7: ='QTR CF'!AL7+'QTR CF'!AM7+'QTR CF'!AN7+'QTR CF'!AO7 | M7: ='QTR CF'!AP7+'QTR CF'!AQ7+'QTR CF'!AR7+'QTR CF'!AS7 | N7: ='QTR CF'!AT7+'QTR CF'!AU7+'QTR CF'!AV7+'QTR CF'!AW7 | O7: ='QTR CF'!AX7+'QTR CF'!AY7+'QTR CF'!AZ7+'QTR CF'!BA7
A8: Loss (Gain) on Equity and Debt Securities, Net | B8: 37 | C8: -6650 | D8: -2798 | E8: -6317 | F8: -12270 | G8: 5519 | H8: 823 | I8: -2671 | J8: -24620 | K8: ='QTR CF'!AH8+'QTR CF'!AI8+'QTR CF'!AJ8+'QTR CF'!AK8 | L8: ='QTR CF'!AL8+'QTR CF'!AM8+'QTR CF'!AN8+'QTR CF'!AO8 | M8: ='QTR CF'!AP8+'QTR CF'!AQ8+'QTR CF'!AR8+'QTR CF'!AS8 | N8: ='QTR CF'!AT8+'QTR CF'!AU8+'QTR CF'!AV8+'QTR CF'!AW8 | O8: ='QTR CF'!AX8+'QTR CF'!AY8+'QTR CF'!AZ8+'QTR CF'!BA8
A9: Other Operating Items | B9: -1870 | C9: -1396 | D9: -1213 | E9: -63 | F9: -2059 | G9: -4016 | H9: 2187 | I9: 2022 | J9: -2434 | K9: ='QTR CF'!AH9+'QTR CF'!AI9+'QTR CF'!AJ9+'QTR CF'!AK9 | L9: ='QTR CF'!AL9+'QTR CF'!AM9+'QTR CF'!AN9+'QTR CF'!AO9 | M9: ='QTR CF'!AP9+'QTR CF'!AQ9+'QTR CF'!AR9+'QTR CF'!AS9 | N9: ='QTR CF'!AT9+'QTR CF'!AU9+'QTR CF'!AV9+'QTR CF'!AW9 | O9: ='QTR CF'!AX9+'QTR CF'!AY9+'QTR CF'!AZ9+'QTR CF'!BA9
A10: Accounts Receivable | B10: -3768 | C10: -2169 | D10: -4340 | E10: -6524 | F10: -9095 | G10: -2317 | H10: -7833 | I10: -5891 | J10: -8779 | K10: ='QTR CF'!AH10+'QTR CF'!AI10+'QTR CF'!AJ10+'QTR CF'!AK10 | L10: ='QTR CF'!AL10+'QTR CF'!AM10+'QTR CF'!AN10+'QTR CF'!AO10 | M10: ='QTR CF'!AP10+'QTR CF'!AQ10+'QTR CF'!AR10+'QTR CF'!AS10 | N10: ='QTR CF'!AT10+'QTR CF'!AU10+'QTR CF'!AV10+'QTR CF'!AW10 | O10: ='QTR CF'!AX10+'QTR CF'!AY10+'QTR CF'!AZ10+'QTR CF'!BA10
A11: Change in Income Taxes | B11: 8211 | C11: -2251 | D11: -3128 | E11: 1209 | F11: -625 | G11: 584 | H11: 523 | I11: -2418 | J11: -3226 | K11: ='QTR CF'!AH11+'QTR CF'!AI11+'QTR CF'!AJ11+'QTR CF'!AK11 | L11: ='QTR CF'!AL11+'QTR CF'!AM11+'QTR CF'!AN11+'QTR CF'!AO11 | M11: ='QTR CF'!AP11+'QTR CF'!AQ11+'QTR CF'!AR11+'QTR CF'!AS11 | N11: ='QTR CF'!AT11+'QTR CF'!AU11+'QTR CF'!AV11+'QTR CF'!AW11 | O11: ='QTR CF'!AX11+'QTR CF'!AY11+'QTR CF'!AZ11+'QTR CF'!BA11
A12: Accounts Payable | B12: 731 | C12: 1067 | D12: 428 | E12: 694 | F12: 283 | G12: 707 | H12: 664 | I12: 359 | J12: 907 | K12: ='QTR CF'!AH12+'QTR CF'!AI12+'QTR CF'!AJ12+'QTR CF'!AK12 | L12: ='QTR CF'!AL12+'QTR CF'!AM12+'QTR CF'!AN12+'QTR CF'!AO12 | M12: ='QTR CF'!AP12+'QTR CF'!AQ12+'QTR CF'!AR12+'QTR CF'!AS12 | N12: ='QTR CF'!AT12+'QTR CF'!AU12+'QTR CF'!AV12+'QTR CF'!AW12 | O12: ='QTR CF'!AX12+'QTR CF'!AY12+'QTR CF'!AZ12+'QTR CF'!BA12
A13: Accrued Expenses | B13: 4891 | C13: 8614 | D13: 7170 | E13: 5504 | F13: 7304 | G13: 3915 | H13: 3937 | I13: -1161 | J13: 12939 | K13: ='QTR CF'!AH13+'QTR CF'!AI13+'QTR CF'!AJ13+'QTR CF'!AK13 | L13: ='QTR CF'!AL13+'QTR CF'!AM13+'QTR CF'!AN13+'QTR CF'!AO13 | M13: ='QTR CF'!AP13+'QTR CF'!AQ13+'QTR CF'!AR13+'QTR CF'!AS13 | N13: ='QTR CF'!AT13+'QTR CF'!AU13+'QTR CF'!AV13+'QTR CF'!AW13 | O13: ='QTR CF'!AX13+'QTR CF'!AY13+'QTR CF'!AZ13+'QTR CF'!BA13
... A15: Deferred Revenue | B15: 390 | C15: 371 | D15: 37 | E15: 635 | F15: 774 | G15: 367 | H15: 525 | I15: 1043 | J15: 2420 | K15: ='QTR CF'!AH15+'QTR CF'!AI15+'QTR CF'!AJ15+'QTR CF'!AK15 | L15: ='QTR CF'!AL15+'QTR CF'!AM15+'QTR CF'!AN15+'QTR CF'!AO15 | M15: ='QTR CF'!AP15+'QTR CF'!AQ15+'QTR CF'!AR15+'QTR CF'!AS15 | N15: ='QTR CF'!AT15+'QTR CF'!AU15+'QTR CF'!AV15+'QTR CF'!AW15 | O15: ='QTR CF'!AX15+'QTR CF'!AY15+'QTR CF'!AZ15+'QTR CF'!BA15
A16: Cash Flow from Operations | B16: =SUM(B2:B15) | C16: =SUM(C2:C15) | D16: =SUM(D2:D15) | E16: =SUM(E2:E15) | F16: =SUM(F2:F15) | G16: =SUM(G2:G15) | H16: =SUM(H2:H15) | I16: =SUM(I2:I15) | ... P16: =SUM(P2:P15)
A17: Purchase of PP&E | B17: -13184 | C17: -25139 | D17: -23548 | E17: -22281 | F17: -24640 | G17: -31485 | H17: -32251 | I17: -52535 | J17: -91447 | K17: ='QTR CF'!AH17+'QTR CF'!AI17+'QTR CF'!AJ17+'QTR CF'!AK17 | L17: ='QTR CF'!AL17+'QTR CF'!AM17+'QTR CF'!AN17+'QTR CF'!AO17 | M17: ='QTR CF'!AP17+'QTR CF'!AQ17+'QTR CF'!AR17+'QTR CF'!AS17 | N17: ='QTR CF'!AT17+'QTR CF'!AU17+'QTR CF'!AV17+'QTR CF'!AW17 | O17: ='QTR CF'!AX17+'QTR CF'!AY17+'QTR CF'!AZ17+'QTR CF'!BA17
A18: Net Change in Short-Term Investments | B18: -18236 | C18: -1651 | D18: -2490 | E18: -3670 | F18: -6902 | G18: 18948 | H18: 8814 | I18: 16749 | J18: -20533 | K18: ='QTR CF'!AH19+'QTR CF'!AI19+'QTR CF'!AJ19+'QTR CF'!AK19 | L18: ='QTR CF'!AL19+'QTR CF'!AM19+'QTR CF'!AN19+'QTR CF'!AO19 | M18: ='QTR CF'!AP19+'QTR CF'!AQ19+'QTR CF'!AR19+'QTR CF'!AS19 | N18: ='QTR CF'!AT19+'QTR CF'!AU19+'QTR CF'!AV19+'QTR CF'!AW19 | O18: ='QTR CF'!AX19+'QTR CF'!AY19+'QTR CF'!AZ19+'QTR CF'!BA19
A19: Net Change in Long-Term Investments | B19: -1212 | C19: -321 | D19: -1527 | E19: -6152 | F19: -1904 | G19: -2381 | H19: -2080 | I19: -4152 | J19: -4349 | K19: ='QTR CF'!AH20+'QTR CF'!AI20+'QTR CF'!AJ20+'QTR CF'!AK20 | L19: ='QTR CF'!AL20+'QTR CF'!AM20+'QTR CF'!AN20+'QTR CF'!AO20 | M19: ='QTR CF'!AP20+'QTR CF'!AQ20+'QTR CF'!AR20+'QTR CF'!AS20 | N19: ='QTR CF'!AT20+'QTR CF'!AU20+'QTR CF'!AV20+'QTR CF'!AW20 | O19: ='QTR CF'!AX20+'QTR CF'!AY20+'QTR CF'!AZ20+'QTR CF'!BA20
A20: Acquisitions, Net of Cash Acquired | B20: -287 | C20: -1491 | D20: -2515 | E20: -738 | F20: -2618 | G20: -6969 | H20: -495 | I20: -2931 | J20: -1592 | K20: ='QTR CF'!AH21+'QTR CF'!AI21+'QTR CF'!AJ21+'QTR CF'!AK21 | L20: ='QTR CF'!AL21+'QTR CF'!AM21+'QTR CF'!AN21+'QTR CF'!AO21 | M20: ='QTR CF'!AP21+'QTR CF'!AQ21+'QTR CF'!AR21+'QTR CF'!AS21 | N20: ='QTR CF'!AT21+'QTR CF'!AU21+'QTR CF'!AV21+'QTR CF'!AW21 | O20: ='QTR CF'!AX21+'QTR CF'!AY21+'QTR CF'!AZ21+'QTR CF'!BA21
A21: Collections from Note Receivable | B21: 1419 | C21: 0 | D21: 0 | E21: 0 | F21: 0 | G21: 0 | H21: 0 | I21: 0 | J21: 0 | K21: ='QTR CF'!AH22+'QTR CF'!AI22+'QTR CF'!AJ22+'QTR CF'!AK22 | L21: ='QTR CF'!AL22+'QTR CF'!AM22+'QTR CF'!AN22+'QTR CF'!AO22 | M21: ='QTR CF'!AP22+'QTR CF'!AQ22+'QTR CF'!AR22+'QTR CF'!AS22 | N21: ='QTR CF'!AT22+'QTR CF'!AU22+'QTR CF'!AV22+'QTR CF'!AW22 | O21: ='QTR CF'!AX22+'QTR CF'!AY22+'QTR CF'!AZ22+'QTR CF'!BA22
A22: Other Investing Activities | B22: 99 | C22: 98 | D22: 589 | E22: 68 | F22: 541 | G22: 1589 | H22: -1051 | I22: -2667 | J22: -2370 | K22: ='QTR CF'!AH23+'QTR CF'!AI23+'QTR CF'!AJ23+'QTR CF'!AK23 | L22: ='QTR CF'!AL23+'QTR CF'!AM23+'QTR CF'!AN23+'QTR CF'!AO23 | M22: ='QTR CF'!AP23+'QTR CF'!AQ23+'QTR CF'!AR23+'QTR CF'!AS23 | N22: ='QTR CF'!AT23+'QTR CF'!AU23+'QTR CF'!AV23+'QTR CF'!AW23 | O22: ='QTR CF'!AX23+'QTR CF'!AY23+'QTR CF'!AZ23+'QTR CF'!BA23
A23: Cash Flow from Investing | B23: =SUM(B17:B22) | C23: =SUM(C17:C22) | D23: =SUM(D17:D22) | E23: =SUM(E17:E22) | F23: =SUM(F17:F22) | G23: =SUM(G17:G22) | H23: =SUM(H17:H22) | I23: =SUM(I17:I22) | ... P23: =SUM(P17:P22)
A24: Stock-Based Award Activities, Net | B24: -4166 | C24: -4993 | D24: -4765 | E24: -5720 | F24: -10162 | G24: -9300 | H24: -9837 | I24: -12190 | J24: -14167 | K24: ='QTR CF'!AH25+'QTR CF'!AI25+'QTR CF'!AJ25+'QTR CF'!AK25 | L24: ='QTR CF'!AL25+'QTR CF'!AM25+'QTR CF'!AN25+'QTR CF'!AO25 | M24: ='QTR CF'!AP25+'QTR CF'!AQ25+'QTR CF'!AR25+'QTR CF'!AS25 | N24: ='QTR CF'!AT25+'QTR CF'!AU25+'QTR CF'!AV25+'QTR CF'!AW25 | O24: ='QTR CF'!AX25+'QTR CF'!AY25+'QTR CF'!AZ25+'QTR CF'!BA25
A25: Share Repurchases | B25: -4846 | C25: -9075 | D25: -18396 | E25: -31149 | F25: -50274 | G25: -59296 | H25: -61504 | I25: -62222 | J25: -45709 | K25: ='QTR CF'!AH26+'QTR CF'!AI26+'QTR CF'!AJ26+'QTR CF'!AK26 | L25: ='QTR CF'!AL26+'QTR CF'!AM26+'QTR CF'!AN26+'QTR CF'!AO26 | M25: ='QTR CF'!AP26+'QTR CF'!AQ26+'QTR CF'!AR26+'QTR CF'!AS26 | N25: ='QTR CF'!AT26+'QTR CF'!AU26+'QTR CF'!AV26+'QTR CF'!AW26 | O25: ='QTR CF'!AX26+'QTR CF'!AY26+'QTR CF'!AZ26+'QTR CF'!BA26
A26: Common Dividends | B26: 0 | C26: 0 | D26: 0 | E26: 0 | F26: 0 | G26: 0 | H26: 0 | I26: -7363 | J26: -10049 | K26: ='QTR CF'!AH27+'QTR CF'!AI27+'QTR CF'!AJ27+'QTR CF'!AK27 | L26: ='QTR CF'!AL27+'QTR CF'!AM27+'QTR CF'!AN27+'QTR CF'!AO27 | M26: ='QTR CF'!AP27+'QTR CF'!AQ27+'QTR CF'!AR27+'QTR CF'!AS27 | N26: ='QTR CF'!AT27+'QTR CF'!AU27+'QTR CF'!AV27+'QTR CF'!AW27 | O26: ='QTR CF'!AX27+'QTR CF'!AY27+'QTR CF'!AZ27+'QTR CF'!BA27
A27: Proceeds from Issuance of Long-Term Debt | B27: 4291 | C27: 6766 | D27: 317 | E27: 11761 | F27: 20199 | G27: 52872 | H27: 10790 | I27: 13589 | J27: 64564 | K27: ='QTR CF'!AH28+'QTR CF'!AI28+'QTR CF'!AJ28+'QTR CF'!AK28 | L27: ='QTR CF'!AL28+'QTR CF'!AM28+'QTR CF'!AN28+'QTR CF'!AO28 | M27: ='QTR CF'!AP28+'QTR CF'!AQ28+'QTR CF'!AR28+'QTR CF'!AS28 | N27: ='QTR CF'!AT28+'QTR CF'!AU28+'QTR CF'!AV28+'QTR CF'!AW28 | O27: ='QTR CF'!AX28+'QTR CF'!AY28+'QTR CF'!AZ28+'QTR CF'!BA28
A28: Net Change in Other Short-Term Debt | B28: -4377 | C28: -6827 | D28: -585 | E28: -2100 | F28: -21435 | G28: -54068 | H28: -11550 | I28: -12701 | J28: -32427 | K28: ='QTR CF'!AH29+'QTR CF'!AI29+'QTR CF'!AJ29+'QTR CF'!AK29 | L28: ='QTR CF'!AL29+'QTR CF'!AM29+'QTR CF'!AN29+'QTR CF'!AO29 | M28: ='QTR CF'!AP29+'QTR CF'!AQ29+'QTR CF'!AR29+'QTR CF'!AS29 | N28: ='QTR CF'!AT29+'QTR CF'!AU29+'QTR CF'!AV29+'QTR CF'!AW29 | O28: ='QTR CF'!AX29+'QTR CF'!AY29+'QTR CF'!AZ29+'QTR CF'!BA29
A29: Proceeds from Sale of Interest in Consolidated Entities | B29: 800 | C29: 950 | D29: 220 | E29: 2800 | F29: 310 | G29: 35 | H29: 8 | I29: 1154 | J29: 400 | K29: ='QTR CF'!AH30+'QTR CF'!AI30+'QTR CF'!AJ30+'QTR CF'!AK30 | L29: ='QTR CF'!AL30+'QTR CF'!AM30+'QTR CF'!AN30+'QTR CF'!AO30 | M29: ='QTR CF'!AP30+'QTR CF'!AQ30+'QTR CF'!AR30+'QTR CF'!AS30 | N29: ='QTR CF'!AT30+'QTR CF'!AU30+'QTR CF'!AV30+'QTR CF'!AW30 | O29: ='QTR CF'!AX30+'QTR CF'!AY30+'QTR CF'!AZ30+'QTR CF'!BA30
A30: Cash Flow from Financing | B30: =SUM(B24:B29) | C30: =SUM(C24:C29) | D30: =SUM(D24:D29) | E30: =SUM(E24:E29) | F30: =SUM(F24:F29) | G30: =SUM(G24:G29) | H30: =SUM(H24:H29) | I30: =SUM(I24:I29) | ... P30: =SUM(P24:P29)
A31: FX Effect on Cash | B31: 405 | C31: -302 | D31: -23 | E31: 24 | F31: -287 | G31: -506 | H31: -421 | I31: -612 | J31: 208 | K31: ='QTR CF'!AH32+'QTR CF'!AI32+'QTR CF'!AJ32+'QTR CF'!AK32 | L31: ='QTR CF'!AL32+'QTR CF'!AM32+'QTR CF'!AN32+'QTR CF'!AO32 | M31: ='QTR CF'!AP32+'QTR CF'!AQ32+'QTR CF'!AR32+'QTR CF'!AS32 | N31: ='QTR CF'!AT32+'QTR CF'!AU32+'QTR CF'!AV32+'QTR CF'!AW32 | O31: ='QTR CF'!AX32+'QTR CF'!AY32+'QTR CF'!AZ32+'QTR CF'!BA32
A32: Net Change in Cash | B32: =B16+B23+B30+B31 | C32: =C16+C23+C30+C31 | D32: =D16+D23+D30+D31 | E32: =E16+E23+E30+E31 | F32: =F16+F23+F30+F31 | G32: =G16+G23+G30+G31 | H32: =H16+H23+H30+H31 | I32: =I16+I23+I30+I31 | ... P32: =P16+P23+P30+P31

Sheet YTD P&L
B1: Q1 FY2018 | C1: Q2 FY2018 | D1: Q3 FY2018 | E1: Q1 FY2019 | F1: Q2 FY2019 | G1: Q3 FY2019 | H1: Q1 FY2020 | I1: Q2 FY2020 | J1: Q3 FY2020 | K1: Q1 FY2021 | L1: Q2 FY2021 | M1: Q3 FY2021 | N1: Q1 FY2022 | O1: Q2 FY2022 | P1: Q3 FY2022 | Q1: Q1 FY2023 | R1: Q2 FY2023 | S1: Q3 FY2023 | T1: Q1 FY2024 | U1: Q2 FY2024 | V1: Q3 FY2024 | W1: Q1 FY2025 | X1: Q2 FY2025 | Y1: Q3 FY2025
A2: Net Sales / Revenue | B2: 31146 | C2: 63803 | D2: 97543 | E2: 36339 | F2: 75283 | G2: 115782 | H2: 41159 | I2: 79456 | J2: 125629 | K2: 55314 | L2: 117194 | M2: 182312 | N2: 68011 | O2: 137696 | P2: 206788 | Q2: 69787 | R2: 144391 | S2: 221084 | T2: 80539 | U2: 165281 | V2: 253549 | W2: 90234 | X2: 186662 | Y2: 289007
A3: COGS | B3: -13467 | C3: -27350 | D3: -41631 | E3: -16012 | F3: -33308 | G3: -50876 | H3: -18982 | I3: -37535 | J3: -58652 | K3: -24103 | L3: -50330 | M3: -77951 | N3: -29599 | O3: -59703 | P3: -90861 | Q3: -30612 | R3: -62528 | S3: -95757 | T3: -33712 | U3: -69219 | V3: -105693 | W3: -36361 | X3: -75400 | Y3: -116768
A4: Gross Profit (Loss) | B4: =B2+B3 | C4: =C2+C3 | D4: =D2+D3 | E4: =E2+E3 | F4: =F2+F3 | G4: =G2+G3 | H4: =H2+H3 | I4: =I2+I3 | ... Y4: =Y2+Y3
A5: Research and Development | B5: -5039 | C5: -10153 | D5: -15385 | E5: -6029 | F5: -12242 | G5: -18796 | H5: -6820 | I5: -13695 | J5: -20551 | K5: -7485 | L5: -15160 | M5: -22854 | N5: -9119 | O5: -18960 | P5: -29233 | Q5: -11468 | R5: -22056 | S5: -33314 | T5: -11903 | U5: -23763 | V5: -36210 | W5: -13556 | X5: -27364 | Y5: -42515
A6: Sales and Marketing | B6: -3604 | C6: -7384 | D6: -11233 | E6: -3905 | F6: -8117 | G6: -12726 | H6: -4500 | I6: -8401 | J6: -12632 | K6: -4516 | L6: -9792 | M6: -15308 | N6: -5825 | O6: -12455 | P6: -19384 | Q6: -6533 | R6: -13314 | S6: -20198 | T6: -6426 | U6: -13218 | V6: -20445 | W6: -6172 | X6: -13273 | Y6: -20478
A7: General and Administrative | B7: -1403 | C7: -3167 | D7: -4920 | E7: -2088 | F7: -4131 | G7: -6722 | H7: -2880 | I7: -5465 | J7: -8221 | K7: -2773 | L7: -6114 | M7: -9370 | N7: -3374 | O7: -7031 | P7: -10628 | Q7: -3759 | R7: -7240 | S7: -11219 | T7: -3026 | U7: -6184 | V7: -9783 | W7: -3539 | X7: -8748 | Y7: -16141
A8: Litigation and Regulatory Charges | B8: 0 | C8: -5071 | D8: -5071 | E8: -1697 | F8: -1697 | G8: -1697 | H8: 0 | I8: 0 | J8: 0 | K8: 0 | L8: 0 | M8: 0 | N8: 0 | O8: 0 | P8: 0 | Q8: 0 | R8: 0 | S8: 0 | T8: 0 | U8: 0 | V8: 0 | W8: 0 | X8: 0 | Y8: 0
A9: Income (Loss) from Operations | B9: =B4+SUM(B5:B8) | C9: =C4+SUM(C5:C8) | D9: =D4+SUM(D5:D8) | E9: =E4+SUM(E5:E8) | F9: =F4+SUM(F5:F8) | G9: =G4+SUM(G5:G8) | H9: =H4+SUM(H5:H8) | I9: =I4+SUM(I5:I8) | ... Y9: =Y4+SUM(Y5:Y8)
A10: Other Income (Expense) | B10: 2910 | C10: 4080 | D10: 5538 | E10: 1538 | F10: 4505 | G10: 3956 | H10: -220 | I10: 1674 | J10: 3820 | K10: 4846 | L10: 7470 | M10: 9503 | N10: -1160 | O10: -1599 | P10: -2501 | Q10: 790 | R10: 855 | S10: 709 | T10: 2843 | U10: 2969 | V10: 6154 | W10: 11183 | X10: 13845 | Y10: 26604
A11: Pre-Tax Income (Loss) | B11: =B9+B10 | C11: =C9+C10 | D11: =D9+D10 | E11: =E9+E10 | F11: =F9+F10 | G11: =G9+G10 | H11: =H9+H10 | I11: =I9+I10 | ... Y11: =Y9+Y10
A12: Income Tax (Expense) Benefit | B12: -1142 | C12: -2162 | D12: -3053 | E12: -1489 | F12: -3689 | G12: -5249 | H12: -921 | I12: -2239 | J12: -4351 | K12: -3353 | L12: -6813 | M12: -10941 | N12: -2498 | O12: -5510 | P12: -7833 | Q12: -3154 | R12: -6689 | S12: -8197 | T12: -4653 | U12: -8585 | V12: -13990 | W12: -7249 | X12: -12986 | Y12: -21994
A13: Net Income (Loss) | B13: =B11+B12 | C13: =C11+C12 | D13: =D11+D12 | E13: =E11+E12 | F13: =F11+F12 | G13: =G11+G12 | H13: =H11+H12 | I13: =I11+I12 | ... Y13: =Y11+Y12
A14: Basic Earnings (Loss) per Share | B14: 13.53 | C14: 18.13 | D14: 31.34 | E14: 9.58 | F14: 23.91 | G14: 34.12 | H14: 9.96 | I14: 20.16 | J14: 36.69 | K14: 26.63 | L14: 54.32 | M14: 82.76 | N14: 24.9 | O14: 2.46 | P14: 3.53 | Q14: 1.18 | R14: 2.63 | S14: 4.19 | T14: 1.91 | U14: 3.82 | V14: 5.96 | W14: 2.84 | X14: 5.16 | Y14: 8.06
A15: Diluted Earnings (Loss) per Share | B15: 13.33 | C15: 17.89 | D15: 30.95 | E15: 9.5 | F15: 23.71 | G15: 33.83 | H15: 9.87 | I15: 20 | J15: 36.38 | K15: 26.29 | L15: 53.54 | M15: 81.53 | N15: 24.62 | O15: 2.44 | P15: 3.5 | Q15: 1.17 | R15: 2.61 | S15: 4.16 | T15: 1.89 | U15: 3.78 | V15: 5.9 | W15: 2.81 | X15: 5.12 | Y15: 7.99

Sheet YTD BS
B1: Q4 FY2018 | C1: Q1 FY2019 | D1: Q2 FY2019 | E1: Q3 FY2019 | F1: Q4 FY2019 | G1: Q1 FY2020 | H1: Q2 FY2020 | I1: Q3 FY2020 | J1: Q4 FY2020 | K1: Q1 FY2021 | L1: Q2 FY2021 | M1: Q3 FY2021 | N1: Q4 FY2021 | O1: Q1 FY2022 | P1: Q2 FY2022 | Q1: Q3 FY2022 | R1: Q4 FY2022 | S1: Q1 FY2023 | T1: Q2 FY2023 | U1: Q3 FY2023 | V1: Q4 FY2023 | W1: Q1 FY2024 | X1: Q2 FY2024 | Y1: Q3 FY2024 | Z1: Q4 FY2024 | AA1: Q1 FY2025 | AB1: Q2 FY2025 | AC1: Q3 FY2025
A2: Cash & Cash Equivalents | B2: 16701 | C2: 19148 | D2: 16587 | E2: 16032 | F2: 18498 | G2: 19644 | H2: 17742 | I2: 20129 | J2: 26465 | K2: 26622 | L2: 23630 | M2: 23719 | N2: 20945 | O2: 20886 | P2: 17936 | Q2: 21984 | R2: 21879 | S2: 25924 | T2: 25929 | U2: 30702 | V2: 24048 | W2: 24493 | X2: 27225 | Y2: 19959 | Z2: 23466 | AA2: 23264 | AB2: 21036 | AC2: 23090
A3: Short-Term Investments | B3: 92439 | C3: 94340 | D3: 104469 | E3: 105145 | F3: 101177 | G3: 97585 | H3: 103338 | I3: 112467 | J3: 110229 | K3: 108482 | L3: 112233 | M3: 118284 | N3: 118704 | O3: 113084 | P3: 107061 | Q3: 94275 | R3: 91883 | S3: 89178 | T3: 92403 | U3: 89233 | V3: 86868 | W3: 83597 | X3: 73500 | Y3: 73271 | Z3: 72191 | AA3: 72064 | AB3: 74112 | AC3: 75406
A4: Accounts Receivable | B4: 20838 | C4: 19149 | D4: 20965 | E4: 20889 | F4: 25326 | G4: 21825 | H4: 21201 | I4: 24925 | J4: 30930 | K4: 28006 | L4: 31967 | M4: 34047 | N4: 39304 | O4: 34703 | P4: 35707 | Q4: 34697 | R4: 40258 | S4: 36036 | T4: 38804 | U4: 41020 | V4: 47964 | W4: 44552 | X4: 47087 | Y4: 49104 | Z4: 52340 | AA4: 51000 | AB4: 55048 | AC4: 57148
A5: Note Receivable - Current | B5: 355 | C5: 111 | D5: 352 | E5: 192 | F5: 2166 | G5: 1910 | H5: 394 | I5: 588 | J5: 454 | K5: 493 | L5: 884 | M5: 753 | N5: 966 | O5: 919 | P5: 1366 | Q5: 1479 | R5: 0 | S5: 0 | T5: 0 | U5: 0 | V5: 0 | W5: 0 | X5: 0 | Y5: 0 | Z5: 0 | AA5: 0 | AB5: 0 | AC5: 0
A6: Inventories | B6: 1107 | C6: 1053 | D6: 964 | E6: 1401 | F6: 999 | G6: 889 | H6: 815 | I6: 835 | J6: 728 | K6: 888 | L6: 907 | M6: 1278 | N6: 1170 | O6: 1369 | P6: 1980 | Q6: 3156 | R6: 2670 | S6: 2315 | T6: 2231 | U6: 2957 | V6: 0 | W6: 0 | X6: 0 | Y6: 0 | Z6: 0 | AA6: 0 | AB6: 0 | AC6: 0
A7: Other Current Assets | B7: 4236 | C7: 4406 | D7: 4100 | E7: 4699 | F7: 4412 | G7: 5165 | H7: 5579 | I7: 5425 | J7: 5490 | K7: 7646 | L7: 6076 | M7: 6029 | N7: 7054 | O7: 6892 | P7: 8321 | Q7: 10518 | R7: 8105 | S7: 8532 | T7: 9421 | U7: 12398 | V7: 12650 | W7: 12829 | X7: 14183 | Y7: 15207 | Z7: 15714 | AA7: 15724 | AB7: 16020 | AC7: 18303
A8: Total Current Assets | B8: =SUM(B2:B7) | C8: =SUM(C2:C7) | D8: =SUM(D2:D7) | E8: =SUM(E2:E7) | F8: =SUM(F2:F7) | G8: =SUM(G2:G7) | H8: =SUM(H2:H7) | I8: =SUM(I2:I7) | ... AC8: =SUM(AC2:AC7)
A9: Long-Term Investments | B9: 13859 | C9: 14474 | D9: 12112 | E9: 12488 | F9: 13078 | G9: 12367 | H9: 12961 | I9: 14656 | J9: 20703 | K9: 25294 | L9: 25532 | M9: 26101 | N9: 29549 | O9: 30544 | P9: 30665 | Q9: 30419 | R9: 30492 | S9: 31213 | T9: 31224 | U9: 30907 | V9: 31008 | W9: 33994 | X9: 34172 | Y9: 36177 | Z9: 37982 | AA9: 51029 | AB9: 52574 | AC9: 63800
A10: Deferred Tax Assets | B10: 737 | C10: 750 | D10: 585 | E10: 564 | F10: 721 | G10: 730 | H10: 895 | I10: 972 | J10: 1084 | K10: 1129 | L10: 1153 | M10: 1195 | N10: 1284 | O10: 1388 | P10: 1490 | Q10: 2991 | R10: 5261 | S10: 6885 | T10: 9357 | U10: 10983 | V10: 12169 | W10: 11687 | X10: 14958 | Y10: 15915 | Z10: 17180 | AA10: 18386 | AB10: 19289 | AC10: 10331
A11: Net PP&E | B11: 59719 | C11: 60528 | D11: 64891 | E11: 69252 | F11: 73646 | G11: 76747 | H11: 78748 | I11: 81636 | J11: 84749 | K11: 87606 | L11: 91697 | M11: 94631 | N11: 97599 | O11: 104218 | P11: 106223 | Q11: 108363 | R11: 112668 | S11: 117560 | T11: 121208 | U11: 125705 | V11: 134345 | W11: 143182 | X11: 151155 | Y11: 161270 | Z11: 171036 | AA11: 185062 | AB11: 203231 | AC11: 223787
A12: ROU Assets - Operating - Non-Current | B12: 0 | C12: 8837 | D12: 9713 | E12: 10341 | F12: 10941 | G12: 11219 | H12: 11567 | I12: 11946 | J12: 12211 | K12: 12598 | L12: 12978 | M12: 12918 | N12: 12959 | O12: 12992 | P12: 13398 | Q12: 13677 | R12: 14381 | S12: 14447 | T12: 14469 | U12: 14199 | V12: 14091 | W12: 13768 | X12: 13606 | Y12: 13561 | Z12: 13588 | AA12: 13722 | AB12: 14255 | AC12: 14524
A13: Intangible Assets | B13: 2220 | C13: 2063 | D13: 1902 | E13: 1747 | F13: 1979 | G13: 1840 | H13: 1697 | I13: 1520 | J13: 1445 | K13: 1823 | L13: 1626 | M13: 1549 | N13: 1417 | O13: 1313 | P13: 1377 | Q13: 2192 | R13: 2084 | S13: 1968 | T13: 1966 | U13: 1833 | V13: 0 | W13: 0 | X13: 0 | Y13: 0 | Z13: 0 | AA13: 0 | AB13: 0 | AC13: 0
A14: Goodwill | B14: 17888 | C14: 17943 | D14: 18000 | E14: 18069 | F14: 20624 | G14: 20734 | H14: 20824 | I14: 20870 | J14: 21175 | K14: 22341 | L14: 22406 | M14: 22623 | N14: 22956 | O14: 23010 | P14: 23949 | Q14: 28834 | R14: 28960 | S14: 28994 | T14: 29210 | U14: 29146 | V14: 29198 | W14: 29183 | X14: 29185 | Y14: 31935 | Z14: 31885 | AA14: 32173 | AB14: 32335 | AC14: 33269
A15: Other Non-Current Assets | B15: 2693 | C15: 2547 | D15: 2461 | E15: 2225 | F15: 2342 | G15: 2748 | H15: 2731 | I15: 3274 | J15: 3953 | K15: 4167 | L15: 4298 | M15: 4276 | N15: 5361 | O15: 5778 | P15: 5712 | Q15: 5670 | R15: 6623 | S15: 6439 | T15: 6822 | U15: 7628 | V15: 10051 | W15: 10065 | X15: 9699 | Y15: 13867 | Z15: 14874 | AA15: 12950 | AB15: 14153 | AC15: 16811
A16: Total Assets | B16: =B8+SUM(B9:B15) | C16: =C8+SUM(C9:C15) | D16: =D8+SUM(D9:D15) | E16: =E8+SUM(E9:E15) | F16: =F8+SUM(F9:F15) | G16: =G8+SUM(G9:G15) | H16: =H8+SUM(H9:H15) | I16: =I8+SUM(I9:I15) | ... AC16: =AC8+SUM(AC9:AC15)
A17: Accounts Payable | B17: 4378 | C17: 3710 | D17: 3925 | E17: 4142 | F17: 5561 | G17: 4099 | H17: 4064 | I17: 4391 | J17: 5589 | K17: 4801 | L17: 4708 | M17: 4616 | N17: 6037 | O17: 3436 | P17: 4409 | Q17: 6303 | R17: 5128 | S17: 4184 | T17: 5313 | U17: 5803 | V17: 7493 | W17: 6198 | X17: 6092 | Y17: 7049 | Z17: 7987 | AA17: 8497 | AB17: 8347 | AC17: 10546
A18: Accrued Compensation | B18: 6839 | C18: 5072 | D18: 6432 | E18: 7399 | F18: 8495 | G18: 5656 | H18: 7127 | I18: 8747 | J18: 11086 | K18: 8375 | L18: 10088 | M18: 12170 | N18: 13889 | O18: 9803 | P18: 10852 | Q18: 12366 | R18: 14028 | S18: 9954 | T18: 11260 | U18: 12562 | V18: 15140 | W18: 9703 | X18: 11373 | Y18: 12908 | Z18: 15069 | AA18: 9984 | AB18: 12168 | AC18: 13944
A19: Accrued Expenses | B19: 16958 | C19: 19382 | D19: 19823 | E19: 21038 | F19: 23067 | G19: 22601 | H19: 24426 | I19: 25631 | J19: 28631 | K19: 30732 | L19: 28981 | M19: 30113 | N19: 31236 | O19: 33051 | P19: 32976 | Q19: 35038 | R19: 37866 | S19: 43185 | T19: 49300 | U19: 55602 | V19: 46168 | W19: 48603 | X19: 47298 | Y19: 46585 | Z19: 51228 | AA19: 58300 | AB19: 52039 | AC19: 59437
A20: Accrued Revenue Share | B20: 4592 | C20: 4318 | D20: 4567 | E20: 4835 | F20: 5916 | G20: 4982 | H20: 5005 | I20: 6030 | J20: 7500 | K20: 6962 | L20: 7438 | M20: 7745 | N20: 8996 | O20: 8116 | P20: 7889 | Q20: 7662 | R20: 8370 | S20: 7816 | T20: 7990 | U20: 8025 | V20: 8876 | W20: 8520 | X20: 8899 | Y20: 9365 | Z20: 9802 | AA20: 9965 | AB20: 9787 | AC20: 10081
A21: Deferred Revenue - Current | B21: 1784 | C21: 1667 | D21: 1717 | E21: 1679 | F21: 1908 | G21: 1938 | H21: 2061 | I21: 2302 | J21: 2543 | K21: 2690 | L21: 2715 | M21: 2968 | N21: 3288 | O21: 3198 | P21: 3272 | Q21: 3585 | R21: 3908 | S21: 3715 | T21: 3846 | U21: 4303 | V21: 4137 | W21: 3973 | X21: 4251 | Y21: 4896 | Z21: 5036 | AA21: 4908 | AB21: 4969 | AC21: 5542
A22: Income Taxes Payable | B22: 69 | C22: 761 | D22: 536 | E22: 131 | F22: 274 | G22: 913 | H22: 975 | I22: 1099 | J22: 1485 | K22: 1893 | L22: 1811 | M22: 4170 | N22: 808 | O22: 4344 | P22: 1956 | Q22: 1025 | R22: 0 | S22: 0 | T22: 0 | U22: 0 | V22: 0 | W22: 0 | X22: 0 | Y22: 0 | Z22: 0 | AA22: 0 | AB22: 0 | AC22: 0
A23: Total Current Liabilities | B23: =SUM(B17:B22) | C23: =SUM(C17:C22) | D23: =SUM(D17:D22) | E23: =SUM(E17:E22) | F23: =SUM(F17:F22) | G23: =SUM(G17:G22) | H23: =SUM(H17:H22) | I23: =SUM(I17:I22) | ... AC23: =SUM(AC17:AC22)
A24: Long-Term Debt | B24: 15339 | C24: 15671 | D24: 15043 | E24: 15437 | F24: 14439 | G24: 14223 | H24: 12617 | I24: 22518 | J24: 22781 | K24: 23165 | L24: 22979 | M24: 23272 | N24: 23993 | O24: 24197 | P24: 22897 | Q24: 23225 | R24: 23959 | S24: 23419 | T24: 22458 | U24: 21819 | V24: 21727 | W24: 22462 | X24: 20941 | Y24: 20516 | Z24: 19665 | AA24: 20659 | AB24: 33634 | AC24: 31679
A25: Deferred Revenue - Non-Current | B25: 396 | C25: 391 | D25: 387 | E25: 364 | F25: 358 | G25: 350 | H25: 397 | I25: 454 | J25: 481 | K25: 530 | L25: 510 | M25: 510 | N25: 535 | O25: 499 | P25: 472 | Q25: 594 | R25: 599 | S25: 610 | T25: 667 | U25: 884 | V25: 911 | W25: 921 | X25: 985 | Y25: 1015 | Z25: 0 | AA25: 0 | AB25: 0 | AC25: 0
A26: Deferred Tax Liability | B26: 1264 | C26: 1282 | D26: 1892 | E26: 1747 | F26: 1701 | G26: 2079 | H26: 1797 | I26: 1973 | J26: 3561 | K26: 4406 | L26: 4703 | M26: 3551 | N26: 5257 | O26: 2843 | P26: 924 | Q26: 476 | R26: 514 | S26: 542 | T26: 558 | U26: 528 | V26: 485 | W26: 486 | X26: 717 | Y26: 706 | Z26: 0 | AA26: 0 | AB26: 0 | AC26: 0
A27: Lease Liability - Operating - Non-Current | B27: 0 | C27: 8206 | D27: 9088 | E27: 9666 | F27: 10214 | G27: 10476 | H27: 10709 | I27: 10984 | J27: 11146 | K27: 11382 | L27: 11619 | M27: 11471 | N27: 11389 | O27: 11363 | P27: 11697 | Q27: 11984 | R27: 12501 | S27: 12799 | T27: 12746 | U27: 12550 | V27: 12460 | W27: 11957 | X27: 11708 | Y27: 11654 | Z27: 11691 | AA27: 11678 | AB27: 11952 | AC27: 12106
A28: Other Non-Current Liabilities | B28: 3545 | C28: 1417 | D28: 1499 | E28: 1637 | F28: 2534 | G28: 2427 | H28: 1992 | I28: 2194 | J28: 2269 | K28: 2146 | L28: 2270 | M28: 2250 | N28: 2205 | O28: 2242 | P28: 2422 | Q28: 2371 | R28: 2247 | S28: 2373 | T28: 1765 | U28: 1433 | V28: 1616 | W28: 1683 | X28: 1753 | Y28: 1453 | Z28: 4694 | AA28: 6116 | AB28: 6241 | AC28: 6267
A29: Total Liabilities | B29: =B23+SUM(B24:B28) | C29: =C23+SUM(C24:C28) | D29: =D23+SUM(D24:D28) | E29: =E23+SUM(E24:E28) | F29: =F23+SUM(F24:F28) | G29: =G23+SUM(G24:G28) | H29: =H23+SUM(H24:H28) | I29: =I23+SUM(I24:I28) | ... AC29: =AC23+SUM(AC24:AC28)
A30: Convertible Preferred Stock | B30: 0 | C30: 0 | D30: 0 | E30: 0 | F30: 0 | G30: 0 | H30: 0 | I30: 0 | J30: 0 | K30: 0 | L30: 0 | M30: 0 | N30: 0 | O30: 0 | P30: 0 | Q30: 0 | R30: 0 | S30: 0 | T30: 0 | U30: 0 | V30: 0 | W30: 0 | X30: 0 | Y30: 0 | Z30: 0 | AA30: 0 | AB30: 0 | AC30: 0
A31: Common Stock and Additional Paid-in Capital | B31: 45049 | C31: 46532 | D31: 47937 | E31: 49040 | F31: 50552 | G31: 53688 | H31: 55937 | I31: 57307 | J31: 58510 | K31: 59436 | L31: 60436 | M31: 61193 | N31: 61774 | O31: 62832 | P31: 64402 | Q31: 66258 | R31: 68184 | S31: 70269 | T31: 72248 | U31: 74591 | V31: 76534 | W31: 77913 | X31: 79732 | Y31: 82030 | Z31: 84800 | AA31: 86725 | AB31: 89283 | AC31: 91695
A32: Accumulated Other Comprehensive Income (Loss) | B32: -2306 | C32: -1780 | D32: -1091 | E32: -1196 | F32: -1232 | G32: -1097 | H32: -296 | I32: 46 | J32: 633 | K32: -3 | L32: 190 | M32: -408 | N32: -1623 | O32: -4049 | P32: -5828 | Q32: -8852 | R32: -7603 | S32: -6000 | T32: -5991 | U32: -7036 | V32: -4402 | W32: -4839 | X32: -5012 | Y32: -3228 | Z32: -4800 | AA32: -4086 | AB32: -2127 | AC32: -2054
A33: Retained Earnings (Accumulated Deficit) | B33: 134885 | C33: 138720 | D33: 145346 | E33: 147125 | F33: 152122 | G33: 151068 | H33: 151681 | I33: 155567 | J33: 163401 | K33: 170580 | L33: 176939 | M33: 183782 | N33: 191484 | O33: 195221 | P33: 196845 | Q33: 196220 | R33: 195563 | S33: 196625 | T33: 200884 | U33: 205647 | V33: 211247 | W33: 219770 | X33: 226033 | Y33: 235317 | Z33: 245084 | AA33: 262628 | AB33: 275760 | AC33: 297226
A34: Total Stockholders' Equity | B34: =SUM(B30:B33) | C34: =SUM(C30:C33) | D34: =SUM(D30:D33) | E34: =SUM(E30:E33) | F34: =SUM(F30:F33) | G34: =SUM(G30:G33) | H34: =SUM(H30:H33) | I34: =SUM(I30:I33) | ... AC34: =SUM(AC30:AC33)
A35: Total Liabilities, Mezzanine & Stockholders' Equity | B35: =B29+B34 | C35: =C29+C34 | D35: =D29+D34 | E35: =E29+E34 | F35: =F29+F34 | G35: =G29+G34 | H35: =H29+H34 | I35: =I29+I34 | ... AC35: =AC29+AC34

Sheet YTD CF
B1: Q1 FY2018 | C1: Q2 FY2018 | D1: Q3 FY2018 | E1: Q1 FY2019 | F1: Q2 FY2019 | G1: Q3 FY2019 | H1: Q1 FY2020 | I1: Q2 FY2020 | J1: Q3 FY2020 | K1: Q1 FY2021 | L1: Q2 FY2021 | M1: Q3 FY2021 | N1: Q1 FY2022 | O1: Q2 FY2022 | P1: Q3 FY2022 | Q1: Q1 FY2023 | R1: Q2 FY2023 | S1: Q3 FY2023 | T1: Q1 FY2024 | U1: Q2 FY2024 | V1: Q3 FY2024 | W1: Q1 FY2025 | X1: Q2 FY2025 | Y1: Q3 FY2025
A2: Net Income (Loss) | B2: 9401 | C2: 12596 | D2: 21788 | E2: 6657 | F2: 16604 | G2: 23672 | H2: 6836 | I2: 13795 | J2: 25042 | K2: 17930 | L2: 36455 | M2: 55391 | N2: 16436 | O2: 32438 | P2: 46348 | Q2: 15051 | R2: 33419 | S2: 53108 | T2: 23662 | U2: 47281 | V2: 73582 | W2: 34540 | X2: 62736 | Y2: 97715
A3: Depreciation and Impairment of PP&E | B3: 1791 | C3: 3653 | D3: 5791 | E3: 2416 | F3: 5042 | G3: 7774 | H3: 2899 | I3: 6077 | J3: 9366 | K3: 2525 | L3: 5255 | M3: 8340 | N3: 3591 | O3: 7289 | P3: 11222 | Q3: 3060 | R3: 6339 | S3: 10010 | T3: 0 | U3: 0 | V3: 0 | W3: 0 | X3: 0 | Y3: 0
A4: Amortization and Impairment of Intangibles | B4: 195 | C4: 447 | D4: 664 | E4: 197 | F4: 406 | G4: 594 | H4: 209 | I4: 417 | J4: 606 | K4: 228 | L4: 443 | M4: 662 | N4: 191 | O4: 392 | P4: 505 | Q4: 126 | R4: 244 | S4: 373 | T4: 0 | U4: 0 | V4: 0 | W4: 0 | X4: 0 | Y4: 0
A5: Depreciation | B5: 0 | C5: 0 | D5: 0 | E5: 0 | F5: 0 | G5: 0 | H5: 0 | I5: 0 | J5: 0 | K5: 0 | L5: 0 | M5: 0 | N5: 0 | O5: 0 | P5: 0 | Q5: 0 | R5: 0 | S5: 0 | T5: 3413 | U5: 7121 | V5: 11106 | W5: 4487 | X5: 9485 | Y5: 15096
A6: Stock-Based Compensation | B6: 2457 | C6: 4870 | D6: 7100 | E6: 2769 | F6: 5525 | G6: 8149 | H6: 3191 | I6: 6573 | J6: 9768 | K6: 3745 | L6: 7548 | M6: 11422 | N6: 4504 | O6: 9286 | P6: 14262 | Q6: 5284 | R6: 11058 | S6: 16801 | T6: 5264 | U6: 11129 | V6: 16975 | W6: 5516 | X6: 11514 | Y6: 17882
A7: (Benefit) Provision for Deferred Income Taxes | B7: -18 | C7: -157 | D7: 723 | E7: -73 | F7: 620 | G7: 381 | H7: 175 | I7: -416 | J7: -280 | K7: 1100 | L7: 1479 | M7: 192 | N7: -2090 | O7: -4237 | P7: -6157 | Q7: -1854 | R7: -4269 | S7: -6093 | T7: 419 | U7: -2738 | V7: -3809 | W7: -1152 | X7: -1596 | Y7: 7130
A8: Loss (Gain) on Equity and Debt Securities, Net | B8: -2992 | C8: -4060 | D8: -5413 | E8: -1081 | F8: -3878 | G8: -2399 | H8: 802 | I8: -1040 | J8: -3055 | K8: -4751 | L8: -7634 | M8: -9792 | N8: 1437 | O8: 2478 | P8: 3856 | Q8: -84 | R8: 425 | S8: 1294 | T8: -1781 | U8: -757 | V8: -2738 | W8: -9960 | X8: -11411 | Y8: -22266
A9: Other Operating Items | B9: -498 | C9: -876 | D9: -1322 | E9: -243 | F9: -224 | G9: -906 | H9: 182 | I9: 310 | J9: 283 | K9: -248 | L9: -455 | M9: -1646 | N9: -636 | O9: -1419 | P9: -3899 | Q9: -193 | R9: -609 | S9: -1971 | T9: -666 | U9: -347 | V9: 258 | W9: -807 | X9: -1726 | Y9: -3217
A10: Accounts Receivable | B10: 1700 | C10: 1388 | D10: 718 | E10: 1172 | F10: 26 | G10: 25 | H10: 2602 | I10: 2522 | J10: -1079 | K10: 2794 | L10: -867 | M10: -3276 | N10: 4364 | O10: 2395 | P10: 2298 | Q10: 4454 | R10: 1506 | S10: -1315 | T10: 3167 | U10: 110 | V10: -1321 | W10: 1638 | X10: -1201 | Y10: -3582
A11: Change in Income Taxes | B11: 782 | C11: -656 | D11: -1891 | E11: 1068 | F11: 25 | G11: 210 | H11: -245 | I11: 538 | J11: 469 | K11: 785 | L11: -297 | M11: 2744 | N11: 3820 | O11: -253 | P11: -862 | Q11: 4069 | R11: 8520 | S11: 10392 | T11: 3011 | U11: -889 | V11: -2797 | W11: 7197 | X11: -2434 | Y11: -3292
A12: Accounts Payable | B12: 122 | C12: -23 | D12: 293 | E12: -425 | F12: -443 | G12: -386 | H12: -835 | I12: -689 | J12: -269 | K12: -982 | L12: -1112 | M12: -874 | N12: -2373 | O12: -1172 | P12: 735 | Q12: -1105 | R12: 14 | S12: 237 | T12: -2124 | U12: -563 | V12: -42 | W12: -880 | X12: -327 | Y12: -771
A13: Accrued Expenses | B13: -1142 | C13: 4600 | D13: 6457 | E13: -229 | F13: 1074 | G13: 2927 | H13: -3531 | I13: -2099 | J13: 891 | K13: -3530 | L13: 201 | M13: 2763 | N13: -3216 | O13: -1719 | P13: 491 | Q13: -4496 | R13: -4037 | S13: -380 | T13: -5054 | U13: -5176 | V13: -6366 | W13: -5045 | X13: -1560 | Y13: 6199
... A15: Deferred Revenue | B15: 130 | C15: 295 | D15: 272 | E15: -81 | F15: -90 | G15: -149 | H15: 37 | I15: 148 | J15: 428 | K15: 137 | L15: 134 | M15: 406 | N15: -94 | O15: -8 | P15: 104 | Q15: -201 | R15: -17 | S15: 690 | T15: -141 | U15: 220 | V15: 860 | W15: 500 | X15: 636 | Y15: 1317
A16: Cash Flow from Operations | B16: =SUM(B2:B15) | C16: =SUM(C2:C15) | D16: =SUM(D2:D15) | E16: =SUM(E2:E15) | F16: =SUM(F2:F15) | G16: =SUM(G2:G15) | H16: =SUM(H2:H15) | I16: =SUM(I2:I15) | ... Y16: =SUM(Y2:Y15)
A17: Purchase of PP&E | B17: -7299 | C17: -12776 | D17: -18058 | E17: -4638 | F17: -10764 | G17: -17496 | H17: -6005 | I17: -11396 | J17: -16802 | K17: -5942 | L17: -11438 | M17: -18257 | N17: -9786 | O17: -16614 | P17: -23890 | Q17: -6289 | R17: -13177 | S17: -21232 | T17: -12012 | U17: -25198 | V17: -38259 | W17: -17197 | X17: -39643 | Y17: -63596
A18: Proceeds from Sale of Assets | B18: 30 | C18: 0 | D18: 0 | E18: 34 | F18: 0 | G18: 0 | H18: 0 | I18: 0 | J18: 0 | K18: 0 | L18: 0 | M18: 0 | N18: 0 | O18: 0 | P18: 0 | Q18: 0 | R18: 0 | S18: 0 | T18: 0 | U18: 0 | V18: 0 | W18: 0 | X18: 0 | Y18: 0
A19: Net Change in Short-Term Investments | B19: 502 | C19: 2482 | D19: -2414 | E19: 123 | F19: -4032 | G19: -6185 | H19: 4248 | I19: 1763 | J19: -7181 | K19: 2822 | L19: 58 | M19: -2980 | N19: 1317 | O19: 5175 | P19: 16834 | Q19: 4100 | R19: 1460 | S19: 3220 | T19: 4301 | U19: 15566 | V19: 16745 | W19: 1892 | X19: 1060 | Y19: 467
A20: Net Change in Long-Term Investments | B20: 171 | C20: 459 | D20: 227 | E20: -808 | F20: -889 | G20: -1202 | H20: -312 | I20: -838 | J20: -1266 | K20: -627 | L20: -1156 | M20: -1478 | N20: -764 | O20: -1139 | P20: -1497 | Q20: -590 | R20: -1332 | S20: -1433 | T20: -893 | U20: -1594 | V20: -2502 | W20: -699 | X20: -1439 | Y20: -2116
A21: Acquisitions, Net of Cash Acquired | B21: -1250 | C21: -1434 | D21: -1452 | E21: -99 | F21: -247 | G21: -373 | H21: -190 | I21: -355 | J21: -368 | K21: -1666 | L21: -1974 | M21: -2233 | N21: -173 | O21: -1236 | P21: -6885 | Q21: -42 | R21: -340 | S21: -466 | T21: -61 | U21: -87 | V21: -2840 | W21: -340 | X21: -353 | Y21: -1425
A22: Collections from Note Receivable | B22: 0 | C22: 0 | D22: 0 | E22: 0 | F22: 0 | G22: 0 | H22: 0 | I22: 0 | J22: 0 | K22: 0 | L22: 0 | M22: 0 | N22: 0 | O22: 0 | P22: 0 | Q22: 0 | R22: 0 | S22: 0 | T22: 0 | U22: 0 | V22: 0 | W22: 0 | X22: 0 | Y22: 0
A23: Other Investing Activities | B23: 0 | C23: 49 | D23: 69 | E23: 0 | F23: 89 | G23: 468 | H23: 412 | I23: 531 | J23: 125 | K23: 30 | L23: 53 | M23: 441 | N23: 355 | O23: 576 | P23: 1367 | Q23: -125 | R23: -357 | S23: -985 | T23: 101 | U23: -32 | V23: -2500 | W23: 150 | X23: -363 | Y23: -1845
A24: Cash Flow from Investing | B24: =SUM(B17:B23) | C24: =SUM(C17:C23) | D24: =SUM(D17:D23) | E24: =SUM(E17:E23) | F24: =SUM(F17:F23) | G24: =SUM(G17:G23) | H24: =SUM(H17:H23) | I24: =SUM(I17:I23) | ... Y24: =SUM(Y17:Y23)
A25: Stock-Based Award Activities, Net | B25: -1158 | C25: -2699 | D25: -3952 | E25: -1175 | F25: -2435 | G25: -3566 | H25: -1241 | I25: -2716 | J25: -4073 | K25: -2184 | L25: -4637 | M25: -7239 | N25: -2916 | O25: -5180 | P25: -7221 | Q25: -1989 | R25: -4725 | S25: -7157 | T25: -2929 | U25: -6138 | V25: -9141 | W25: -3110 | X25: -5731 | Y25: -9001
A26: Share Repurchases | B26: -2173 | C26: -4225 | D26: -6425 | E26: -3025 | F26: -6602 | G26: -12298 | H26: -8496 | I26: -15348 | J26: -23245 | K26: -11395 | L26: -24191 | M26: -36801 | N26: -13300 | O26: -28497 | P26: -43889 | Q26: -14557 | R26: -29526 | S26: -45313 | T26: -15696 | U26: -31380 | V26: -46671 | W26: -15068 | X26: -28706 | Y26: -40210
A27: Common Dividends | B27: 0 | C27: 0 | D27: 0 | E27: 0 | F27: 0 | G27: 0 | H27: 0 | I27: 0 | J27: 0 | K27: 0 | L27: 0 | M27: 0 | N27: 0 | O27: 0 | P27: 0 | Q27: 0 | R27: 0 | S27: 0 | T27: 0 | U27: -2466 | V27: -4921 | W27: -2434 | X27: -4977 | Y27: -7513
A28: Proceeds from Issuance of Long-Term Debt | B28: 4691 | C28: 6236 | D28: 6766 | E28: 315 | F28: 317 | G28: 317 | H28: 1898 | I28: 1898 | J28: 11761 | K28: 900 | L28: 7599 | M28: 13949 | N28: 16422 | O28: 29228 | P28: 44322 | Q28: 6927 | R28: 8050 | S28: 9298 | T28: 1982 | U28: 4875 | V28: 8694 | W28: 4532 | X28: 31378 | Y28: 38002
A29: Net Change in Other Short-Term Debt | B29: -3378 | C29: -6267 | D29: -6822 | E29: -345 | F29: -393 | G29: -538 | H29: -1947 | I29: -1982 | J29: -2043 | K29: -937 | L29: -8678 | M29: -15070 | N29: -16420 | O29: -29582 | P29: -45350 | Q29: -6952 | R29: -8207 | S29: -9621 | T29: -3079 | U29: -5502 | V29: -8951 | W29: -4521 | X29: -18397 | Y29: -26094
A30: Proceeds from Sale of Interest in Consolidated Entities | B30: 0 | C30: 0 | D30: 0 | E30: 47 | F30: 184 | G30: 202 | H30: 1600 | I30: 2464 | J30: 2462 | K30: 10 | L30: 310 | M30: 310 | N30: 0 | O30: 0 | P30: 10 | Q30: 3 | R30: 5 | S30: 8 | T30: 8 | U30: 8 | V30: 293 | W30: 400 | X30: 400 | Y30: 400
A31: Cash Flow from Financing | B31: =SUM(B25:B30) | C31: =SUM(C25:C30) | D31: =SUM(D25:D30) | E31: =SUM(E25:E30) | F31: =SUM(F25:F30) | G31: =SUM(G25:G30) | H31: =SUM(H25:H30) | I31: =SUM(I25:I30) | ... Y31: =SUM(Y25:Y30)
A32: FX Effect on Cash | B32: 165 | C32: -166 | D32: -195 | E32: 18 | F32: 31 | G32: -91 | H32: -272 | I32: -221 | J32: -186 | K32: -143 | L32: 40 | M32: -106 | N32: 100 | O32: -268 | P32: -643 | Q32: 50 | R32: 24 | S32: -327 | T32: -125 | U32: -363 | V32: -222 | W32: 43 | X32: 444 | Y32: 244
A33: Net Change in Cash | B33: =B16+B24+B31+B32 | C33: =C16+C24+C31+C32 | D33: =D16+D24+D31+D32 | E33: =E16+E24+E31+E32 | F33: =F16+F24+F31+F32 | G33: =G16+G24+G31+G32 | H33: =H16+H24+H31+H32 | I33: =I16+I24+I31+I32 | ... Y33: =Y16+Y24+Y31+Y32

Sheet QTR P&L
B1: Q1 FY2018 | C1: Q2 FY2018 | D1: Q3 FY2018 | E1: Q4 FY2018 | F1: Q1 FY2019 | G1: Q2 FY2019 | H1: Q3 FY2019 | I1: Q4 FY2019 | J1: Q1 FY2020 | K1: Q2 FY2020 | L1: Q3 FY2020 | M1: Q4 FY2020 | N1: Q1 FY2021 | O1: Q2 FY2021 | P1: Q3 FY2021 | Q1: Q4 FY2021 | R1: Q1 FY2022 | S1: Q2 FY2022 | T1: Q3 FY2022 | U1: Q4 FY2022 | V1: Q1 FY2023 | W1: Q2 FY2023 | X1: Q3 FY2023 | Y1: Q4 FY2023 | Z1: Q1 FY2024 | AA1: Q2 FY2024 | AB1: Q3 FY2024 | AC1: Q4 FY2024 | AD1: Q1 FY2025 | AE1: Q2 FY2025 | AF1: Q3 FY2025 | AG1: Q4 FY2025 | AH1: Q1 FY2026E | AI1: Q2 FY2026E | AJ1: Q3 FY2026E | AK1: Q4 FY2026E | AL1: Q1 FY2027E | AM1: Q2 FY2027E | AN1: Q3 FY2027E | AO1: Q4 FY2027E | AP1: Q1 FY2028E | AQ1: Q2 FY2028E | AR1: Q3 FY2028E | AS1: Q4 FY2028E | AT1: Q1 FY2029E | AU1: Q2 FY2029E | AV1: Q3 FY2029E | AW1: Q4 FY2029E | AX1: Q1 FY2030E | AY1: Q2 FY2030E | AZ1: Q3 FY2030E | BA1: Q4 FY2030E
A2: Net Sales / Revenue | B2: ='YTD P&L'!B2 | C2: ='YTD P&L'!C2-'YTD P&L'!B2 | D2: ='YTD P&L'!D2-'YTD P&L'!C2 | E2: ='ANNL P&L'!C2-'YTD P&L'!D2 | F2: ='YTD P&L'!E2 | G2: ='YTD P&L'!F2-'YTD P&L'!E2 | H2: ='YTD P&L'!G2-'YTD P&L'!F2 | I2: ='ANNL P&L'!D2-'YTD P&L'!G2 | J2: ='YTD P&L'!H2 | K2: ='YTD P&L'!I2-'YTD P&L'!H2 | L2: ='YTD P&L'!J2-'YTD P&L'!I2 | M2: ='ANNL P&L'!E2-'YTD P&L'!J2 | N2: ='YTD P&L'!K2 | O2: ='YTD P&L'!L2-'YTD P&L'!K2 | P2: ='YTD P&L'!M2-'YTD P&L'!L2 | Q2: ='ANNL P&L'!F2-'YTD P&L'!M2 | R2: ='YTD P&L'!N2 | S2: ='YTD P&L'!O2-'YTD P&L'!N2 | T2: ='YTD P&L'!P2-'YTD P&L'!O2 | U2: ='ANNL P&L'!G2-'YTD P&L'!P2 | V2: ='YTD P&L'!Q2 | W2: ='YTD P&L'!R2-'YTD P&L'!Q2 | X2: ='YTD P&L'!S2-'YTD P&L'!R2 | Y2: ='ANNL P&L'!H2-'YTD P&L'!S2 | Z2: ='YTD P&L'!T2 | AA2: ='YTD P&L'!U2-'YTD P&L'!T2 | AB2: ='YTD P&L'!V2-'YTD P&L'!U2 | AC2: ='ANNL P&L'!I2-'YTD P&L'!V2 | AD2: ='YTD P&L'!W2 | AE2: ='YTD P&L'!X2-'YTD P&L'!W2 | AF2: ='YTD P&L'!Y2-'YTD P&L'!X2 | AG2: ='ANNL P&L'!J2-'YTD P&L'!Y2 | AH2: =IF('IS DRIVERS'!$B2="QoQ",'QTR P&L'!AG2,'QTR P&L'!AD2)*(1+'IS DRIVERS'!AI2) | AI2: =IF('IS DRIVERS'!$B2="QoQ",'QTR P&L'!AH2,'QTR P&L'!AE2)*(1+'IS DRIVERS'!AJ2) | AJ2: =IF('IS DRIVERS'!$B2="QoQ",'QTR P&L'!AI2,'QTR P&L'!AF2)*(1+'IS DRIVERS'!AK2) | AK2: =IF('IS DRIVERS'!$B2="QoQ",'QTR P&L'!AJ2,'QTR P&L'!AG2)*(1+'IS DRIVERS'!AL2) | AL2: =IF('IS DRIVERS'!$B2="QoQ",'QTR P&L'!AK2,'QTR P&L'!AH2)*(1+'IS DRIVERS'!AM2) | AM2: =IF('IS DRIVERS'!$B2="QoQ",'QTR P&L'!AL2,'QTR P&L'!AI2)*(1+'IS DRIVERS'!AN2) | AN2: =IF('IS DRIVERS'!$B2="QoQ",'QTR P&L'!AM2,'QTR P&L'!AJ2)*(1+'IS DRIVERS'!AO2) | AO2: =IF('IS DRIVERS'!$B2="QoQ",'QTR P&L'!AN2,'QTR P&L'!AK2)*(1+'IS DRIVERS'!AP2) | ... BA2: =IF('IS DRIVERS'!$B2="QoQ",'QTR P&L'!AZ2,'QTR P&L'!AW2)*(1+'IS DRIVERS'!BB2)
A3: COGS | B3: ='YTD P&L'!B3 | C3: ='YTD P&L'!C3-'YTD P&L'!B3 | D3: ='YTD P&L'!D3-'YTD P&L'!C3 | E3: ='ANNL P&L'!C3-'YTD P&L'!D3 | F3: ='YTD P&L'!E3 | G3: ='YTD P&L'!F3-'YTD P&L'!E3 | H3: ='YTD P&L'!G3-'YTD P&L'!F3 | I3: ='ANNL P&L'!D3-'YTD P&L'!G3 | J3: ='YTD P&L'!H3 | K3: ='YTD P&L'!I3-'YTD P&L'!H3 | L3: ='YTD P&L'!J3-'YTD P&L'!I3 | M3: ='ANNL P&L'!E3-'YTD P&L'!J3 | N3: ='YTD P&L'!K3 | O3: ='YTD P&L'!L3-'YTD P&L'!K3 | P3: ='YTD P&L'!M3-'YTD P&L'!L3 | Q3: ='ANNL P&L'!F3-'YTD P&L'!M3 | R3: ='YTD P&L'!N3 | S3: ='YTD P&L'!O3-'YTD P&L'!N3 | T3: ='YTD P&L'!P3-'YTD P&L'!O3 | U3: ='ANNL P&L'!G3-'YTD P&L'!P3 | V3: ='YTD P&L'!Q3 | W3: ='YTD P&L'!R3-'YTD P&L'!Q3 | X3: ='YTD P&L'!S3-'YTD P&L'!R3 | Y3: ='ANNL P&L'!H3-'YTD P&L'!S3 | Z3: ='YTD P&L'!T3 | AA3: ='YTD P&L'!U3-'YTD P&L'!T3 | AB3: ='YTD P&L'!V3-'YTD P&L'!U3 | AC3: ='ANNL P&L'!I3-'YTD P&L'!V3 | AD3: ='YTD P&L'!W3 | AE3: ='YTD P&L'!X3-'YTD P&L'!W3 | AF3: ='YTD P&L'!Y3-'YTD P&L'!X3 | AG3: ='ANNL P&L'!J3-'YTD P&L'!Y3 | AH3: ='QTR P&L'!AH2*'IS DRIVERS'!AI3 | AI3: ='QTR P&L'!AI2*'IS DRIVERS'!AJ3 | AJ3: ='QTR P&L'!AJ2*'IS DRIVERS'!AK3 | AK3: ='QTR P&L'!AK2*'IS DRIVERS'!AL3 | AL3: ='QTR P&L'!AL2*'IS DRIVERS'!AM3 | AM3: ='QTR P&L'!AM2*'IS DRIVERS'!AN3 | AN3: ='QTR P&L'!AN2*'IS DRIVERS'!AO3 | AO3: ='QTR P&L'!AO2*'IS DRIVERS'!AP3 | ... BA3: ='QTR P&L'!BA2*'IS DRIVERS'!BB3
A4: Gross Profit (Loss) | B4: ='YTD P&L'!B4 | C4: ='YTD P&L'!C4-'YTD P&L'!B4 | D4: ='YTD P&L'!D4-'YTD P&L'!C4 | E4: ='ANNL P&L'!C4-'YTD P&L'!D4 | F4: ='YTD P&L'!E4 | G4: ='YTD P&L'!F4-'YTD P&L'!E4 | H4: ='YTD P&L'!G4-'YTD P&L'!F4 | I4: ='ANNL P&L'!D4-'YTD P&L'!G4 | J4: ='YTD P&L'!H4 | K4: ='YTD P&L'!I4-'YTD P&L'!H4 | L4: ='YTD P&L'!J4-'YTD P&L'!I4 | M4: ='ANNL P&L'!E4-'YTD P&L'!J4 | N4: ='YTD P&L'!K4 | O4: ='YTD P&L'!L4-'YTD P&L'!K4 | P4: ='YTD P&L'!M4-'YTD P&L'!L4 | Q4: ='ANNL P&L'!F4-'YTD P&L'!M4 | R4: ='YTD P&L'!N4 | S4: ='YTD P&L'!O4-'YTD P&L'!N4 | T4: ='YTD P&L'!P4-'YTD P&L'!O4 | U4: ='ANNL P&L'!G4-'YTD P&L'!P4 | V4: ='YTD P&L'!Q4 | W4: ='YTD P&L'!R4-'YTD P&L'!Q4 | X4: ='YTD P&L'!S4-'YTD P&L'!R4 | Y4: ='ANNL P&L'!H4-'YTD P&L'!S4 | Z4: ='YTD P&L'!T4 | AA4: ='YTD P&L'!U4-'YTD P&L'!T4 | AB4: ='YTD P&L'!V4-'YTD P&L'!U4 | AC4: ='ANNL P&L'!I4-'YTD P&L'!V4 | AD4: ='YTD P&L'!W4 | AE4: ='YTD P&L'!X4-'YTD P&L'!W4 | AF4: ='YTD P&L'!Y4-'YTD P&L'!X4 | AG4: ='ANNL P&L'!J4-'YTD P&L'!Y4 | AH4: =AH2+AH3 | AI4: =AI2+AI3 | AJ4: =AJ2+AJ3 | AK4: =AK2+AK3 | AL4: =AL2+AL3 | AM4: =AM2+AM3 | AN4: =AN2+AN3 | AO4: =AO2+AO3 | ... BA4: =BA2+BA3
A5: Research and Development | B5: ='YTD P&L'!B5 | C5: ='YTD P&L'!C5-'YTD P&L'!B5 | D5: ='YTD P&L'!D5-'YTD P&L'!C5 | E5: ='ANNL P&L'!C5-'YTD P&L'!D5 | F5: ='YTD P&L'!E5 | G5: ='YTD P&L'!F5-'YTD P&L'!E5 | H5: ='YTD P&L'!G5-'YTD P&L'!F5 | I5: ='ANNL P&L'!D5-'YTD P&L'!G5 | J5: ='YTD P&L'!H5 | K5: ='YTD P&L'!I5-'YTD P&L'!H5 | L5: ='YTD P&L'!J5-'YTD P&L'!I5 | M5: ='ANNL P&L'!E5-'YTD P&L'!J5 | N5: ='YTD P&L'!K5 | O5: ='YTD P&L'!L5-'YTD P&L'!K5 | P5: ='YTD P&L'!M5-'YTD P&L'!L5 | Q5: ='ANNL P&L'!F5-'YTD P&L'!M5 | R5: ='YTD P&L'!N5 | S5: ='YTD P&L'!O5-'YTD P&L'!N5 | T5: ='YTD P&L'!P5-'YTD P&L'!O5 | U5: ='ANNL P&L'!G5-'YTD P&L'!P5 | V5: ='YTD P&L'!Q5 | W5: ='YTD P&L'!R5-'YTD P&L'!Q5 | X5: ='YTD P&L'!S5-'YTD P&L'!R5 | Y5: ='ANNL P&L'!H5-'YTD P&L'!S5 | Z5: ='YTD P&L'!T5 | AA5: ='YTD P&L'!U5-'YTD P&L'!T5 | AB5: ='YTD P&L'!V5-'YTD P&L'!U5 | AC5: ='ANNL P&L'!I5-'YTD P&L'!V5 | AD5: ='YTD P&L'!W5 | AE5: ='YTD P&L'!X5-'YTD P&L'!W5 | AF5: ='YTD P&L'!Y5-'YTD P&L'!X5 | AG5: ='ANNL P&L'!J5-'YTD P&L'!Y5 | AH5: ='QTR P&L'!AH2*'IS DRIVERS'!AI4 | AI5: ='QTR P&L'!AI2*'IS DRIVERS'!AJ4 | AJ5: ='QTR P&L'!AJ2*'IS DRIVERS'!AK4 | AK5: ='QTR P&L'!AK2*'IS DRIVERS'!AL4 | AL5: ='QTR P&L'!AL2*'IS DRIVERS'!AM4 | AM5: ='QTR P&L'!AM2*'IS DRIVERS'!AN4 | AN5: ='QTR P&L'!AN2*'IS DRIVERS'!AO4 | AO5: ='QTR P&L'!AO2*'IS DRIVERS'!AP4 | ... BA5: ='QTR P&L'!BA2*'IS DRIVERS'!BB4
A6: Sales and Marketing | B6: ='YTD P&L'!B6 | C6: ='YTD P&L'!C6-'YTD P&L'!B6 | D6: ='YTD P&L'!D6-'YTD P&L'!C6 | E6: ='ANNL P&L'!C6-'YTD P&L'!D6 | F6: ='YTD P&L'!E6 | G6: ='YTD P&L'!F6-'YTD P&L'!E6 | H6: ='YTD P&L'!G6-'YTD P&L'!F6 | I6: ='ANNL P&L'!D6-'YTD P&L'!G6 | J6: ='YTD P&L'!H6 | K6: ='YTD P&L'!I6-'YTD P&L'!H6 | L6: ='YTD P&L'!J6-'YTD P&L'!I6 | M6: ='ANNL P&L'!E6-'YTD P&L'!J6 | N6: ='YTD P&L'!K6 | O6: ='YTD P&L'!L6-'YTD P&L'!K6 | P6: ='YTD P&L'!M6-'YTD P&L'!L6 | Q6: ='ANNL P&L'!F6-'YTD P&L'!M6 | R6: ='YTD P&L'!N6 | S6: ='YTD P&L'!O6-'YTD P&L'!N6 | T6: ='YTD P&L'!P6-'YTD P&L'!O6 | U6: ='ANNL P&L'!G6-'YTD P&L'!P6 | V6: ='YTD P&L'!Q6 | W6: ='YTD P&L'!R6-'YTD P&L'!Q6 | X6: ='YTD P&L'!S6-'YTD P&L'!R6 | Y6: ='ANNL P&L'!H6-'YTD P&L'!S6 | Z6: ='YTD P&L'!T6 | AA6: ='YTD P&L'!U6-'YTD P&L'!T6 | AB6: ='YTD P&L'!V6-'YTD P&L'!U6 | AC6: ='ANNL P&L'!I6-'YTD P&L'!V6 | AD6: ='YTD P&L'!W6 | AE6: ='YTD P&L'!X6-'YTD P&L'!W6 | AF6: ='YTD P&L'!Y6-'YTD P&L'!X6 | AG6: ='ANNL P&L'!J6-'YTD P&L'!Y6 | AH6: ='QTR P&L'!AH2*'IS DRIVERS'!AI5 | AI6: ='QTR P&L'!AI2*'IS DRIVERS'!AJ5 | AJ6: ='QTR P&L'!AJ2*'IS DRIVERS'!AK5 | AK6: ='QTR P&L'!AK2*'IS DRIVERS'!AL5 | AL6: ='QTR P&L'!AL2*'IS DRIVERS'!AM5 | AM6: ='QTR P&L'!AM2*'IS DRIVERS'!AN5 | AN6: ='QTR P&L'!AN2*'IS DRIVERS'!AO5 | AO6: ='QTR P&L'!AO2*'IS DRIVERS'!AP5 | ... BA6: ='QTR P&L'!BA2*'IS DRIVERS'!BB5
