Workbook

Sheet ANNL P&L
B1: FY2021 | C1: FY2022 | D1: FY2023 | E1: FY2024 | F1: FY2025 | G1: FY2026E | H1: FY2027E | I1: FY2028E | J1: FY2029E | K1: FY2030E | L1: FY2031E
A2: Net Sales / Revenue | B2: 314272 | C2: 653604 | D2: 1318014 | E2: 1355630 | F2: 2515269
A3: COGS | B3: -186103 | C3: -382735 | D3: -684875 | E3: -675423 | F3: -1247936
A4: Gross Profit (Loss) | B4: =B2+B3 | C4: =C2+C3 | D4: =D2+D3 | E4: =E2+E3 | F4: =F2+F3 | G4: =G2+G3 | H4: =H2+H3 | I4: =I2+I3 | ... L4: =L2+L3
A5: SG&A | B5: -132259 | C5: -428670 | D5: -366773 | E5: -524479 | F5: -798810
A6: Distributor Termination Fees | B6: 0 | C6: 0 | D6: 0 | E6: 0 | F6: -327461
A7: Income (Loss) from Operations | B7: =B4+SUM(B5:B6) | C7: =C4+SUM(C5:C6) | D7: =D4+SUM(D5:D6) | E7: =E4+SUM(E5:E6) | F7: =F4+SUM(F5:F6) | G7: =G4+SUM(G5:G6) | H7: =H4+SUM(H5:H6) | I7: =I4+SUM(I5:I6) | ... L7: =L4+SUM(L5:L6)
A8: Interest Income (Expense) | B8: 307 | C8: 5529 | D8: 26629 | E8: 39263 | F8: -27892
A9: Foreign Currency Gain (Loss) | B9: -276 | C9: -392 | D9: -1246 | E9: -1734 | F9: 0
A10: Other Income (Expense) | B10: 0 | C10: 0 | D10: 0 | E10: 1793 | F10: 11863
A11: Pre-Tax Income (Loss) | B11: =B7+SUM(B8:B10) | C11: =C7+SUM(C8:C10) | D11: =D7+SUM(D8:D10) | E11: =E7+SUM(E8:E10) | F11: =F7+SUM(F8:F10) | G11: =G7+SUM(G8:G10) | H11: =H7+SUM(H8:H10) | I11: =I7+SUM(I8:I10) | ... L11: =L7+SUM(L8:L10)
A12: Income Tax (Expense) Benefit | B12: 7996 | C12: -34618 | D12: -64948 | E12: -49976 | F12: -17034
A13: Net Income (Loss) | B13: =B11+B12 | C13: =C11+C12 | D13: =D11+D12 | E13: =E11+E12 | F13: =F11+F12 | G13: =G11+G12 | H13: =H11+H12 | I13: =I11+I12 | ... L13: =L11+L12
A14: Preferred Dividends | B14: 0 | C14: -11526 | D14: -27462 | E14: -27500 | F14: -37608
A15: Income Allocated to Participating Preferred | B15: 0 | C15: 0 | D15: -17348 | E15: -10117 | F15: -6554
A16: Net Income (Loss) Attributable to Common Shareholders | B16: =B13+B14+B15 | C16: =C13+C14+C15 | D16: =D13+D14+D15 | E16: =E13+E14+E15 | F16: =F13+F14+F15 | G16: =G13+G14+G15 | H16: =H13+H14+H15 | I16: =I13+I14+I15 | ... L16: =L13+L14+L15

Sheet BALANCE SHEET
B1: FY2022 | C1: FY2023 | D1: FY2024 | E1: FY2025 | F1: FY2026E | G1: FY2027E | H1: FY2028E | I1: FY2029E | J1: FY2030E | K1: FY2031E
A2: Cash & Cash Equivalents | B2: 614159 | C2: 755981 | D2: 890190 | E2: 398866
A3: Restricted Cash | B3: 38768 | C3: 0 | D3: 0 | E3: 141121
A4: Accounts Receivable | B4: 63311 | C4: 183703 | D4: 270342 | E4: 755499
A5: Note Receivable - Current | B5: 2979 | C5: 2318 | D5: 0 | E5: 0
A6: Inventories | B6: 173289 | C6: 229275 | D6: 131165 | E6: 337698
A7: Prepaid Expenses | B7: 11341 | C7: 19503 | D7: 18759 | E7: 128806
A8: Deferred Other Costs - Current | B8: 14124 | C8: 14124 | D8: 14124 | E8: 49164
A9: Total Current Assets | B9: =SUM(B2:B8) | C9: =SUM(C2:C8) | D9: =SUM(D2:D8) | E9: =SUM(E2:E8) | F9: =SUM(F2:F8) | G9: =SUM(G2:G8) | H9: =SUM(H2:H8) | I9: =SUM(I2:I8) | ... K9: =SUM(K2:K8)
A10: Note Receivable - Non-Current | B10: 3574 | C10: 0 | D10: 0 | E10: 0
A11: Net PP&E | B11: 10185 | C11: 24868 | D11: 55602 | E11: 87910
A12: ROU Assets - Operating - Non-Current | B12: 972 | C12: 1957 | D12: 21606 | E12: 0
A13: ROU Assets - Finance - Non-Current | B13: 208 | C13: 208 | D13: 230 | E13: 0
A14: Intangible Assets | B14: 12254 | C14: 12139 | D14: 12213 | E14: 1391915
A15: Goodwill | B15: 13679 | C15: 14173 | D15: 71582 | E15: 917560
A16: Deferred Other Costs - Non-Current | B16: 262462 | C16: 248338 | D16: 234215 | E16: 771635
A17: Deferred Tax Assets | B17: 501 | C17: 29518 | D17: 38699 | E17: 96013
A18: Other Non-Current Assets | B18: 263 | C18: 291 | D18: 8154 | E18: 43434
A19: Total Assets | B19: =B9+SUM(B10:B18) | C19: =C9+SUM(C10:C18) | D19: =D9+SUM(D10:D18) | E19: =E9+SUM(E10:E18) | F19: =F9+SUM(F10:F18) | G19: =G9+SUM(G10:G18) | H19: =H9+SUM(H10:H18) | I19: =I9+SUM(I10:I18) | ... K19: =K9+SUM(K10:K18)
A20: Accounts Payable | B20: 36248 | C20: 42840 | D20: 41287 | E20: 137930
A21: Accrued Expenses | B21: 69899 | C21: 62120 | D21: 148780 | E21: 230721
A22: Income Taxes Payable | B22: 1193 | C22: 50424 | D22: 10834 | E22: 49612
A23: Accrued Distributor Termination Fees | B23: 3986 | C23: 0 | D23: 0 | E23: 264088
A24: Accrued Promotional Allowance | B24: 35977 | C24: 99787 | D24: 135948 | E24: 307922
A25: Lease Liability - Operating - Current | B25: 661 | C25: 980 | D25: 3265 | E25: 0
A26: Lease Liability - Finance - Current | B26: 70 | C26: 59 | D26: 100 | E26: 0
A27: Contingent Consideration - Current | B27: 0 | C27: 0 | D27: 0 | E27: 25000
A28: Deferred Revenue - Current | B28: 9675 | C28: 9513 | D28: 9513 | E28: 26988
A29: Other Current Liabilities | B29: 3586 | C29: 10890 | D29: 15808 | E29: 36465
A30: Total Current Liabilities | B30: =SUM(B20:B29) | C30: =SUM(C20:C29) | D30: =SUM(D20:D29) | E30: =SUM(E20:E29) | F30: =SUM(F20:F29) | G30: =SUM(G20:G29) | H30: =SUM(H20:H29) | I30: =SUM(I20:I29) | ... K30: =SUM(K20:K29)
A31: Lease Liability - Operating - Non-Current | B31: 326 | C31: 955 | D31: 16674 | E31: 0
A32: Lease Liability - Finance - Non-Current | B32: 162 | C32: 193 | D32: 211 | E32: 0
A33: Deferred Tax Liability | B33: 15919 | C33: 2880 | D33: 2330 | E33: 0
A34: Long-Term Debt | B34: 0 | C34: 0 | D34: 0 | E34: 669926
A35: Deferred Revenue - Non-Current | B35: 179788 | C35: 167227 | D35: 157714 | E35: 401155
A36: Other Non-Current Liabilities | B36: 0 | C36: 0 | D36: 0 | E36: 28372
A37: Total Liabilities | B37: =B30+SUM(B31:B36) | C37: =C30+SUM(C31:C36) | D37: =D30+SUM(D31:D36) | E37: =E30+SUM(E31:E36) | F37: =F30+SUM(F31:F36) | G37: =G30+SUM(G31:G36) | H37: =H30+SUM(H31:H36) | I37: =I30+SUM(I31:I36) | ... K37: =K30+SUM(K31:K36)
A38: Convertible Preferred Stock | B38: 824488 | C38: 824488 | D38: 824488 | E38: 1759975
A39: Common Stock | B39: 76 | C39: 77 | D39: 79 | E39: 101
A40: Treasury Stock | B40: 0 | C40: 0 | D40: 0 | E40: -48226
...

Sheet CASH FLOW
B1: FY2021 | C1: FY2022 | D1: FY2023 | E1: FY2024 | F1: FY2025 | G1: FY2026E | H1: FY2027E | I1: FY2028E | J1: FY2029E | K1: FY2030E | L1: FY2031E
A2: Net Income (Loss) | B2: 3937 | C2: -187282 | D2: 226801 | E2: 145074 | F2: 107999
A3: Depreciation & Amortization | B3: 1264 | C3: 1917 | D3: 3226 | E3: 7274 | F3: 29451
A4: Impairment of Intangibles | B4: 0 | C4: 2379 | D4: 0 | E4: 0 | F4: 0
A5: Allowance for Credit Losses | B5: 1494 | C5: 2352 | D5: 2128 | E5: 3294 | F5: 10600
A6: Amortization of Deferred Other Costs | B6: 0 | C6: 5885 | D6: 14124 | E6: 14124 | F6: 26326
A7: Inventory Write-Down | B7: 2355 | C7: 6131 | D7: 7312 | E7: 19086 | F7: 29190
A8: Gain (Loss) on Disposal of PP&E | B8: 0 | C8: 0 | D8: 198 | E8: 173 | F8: 0
A9: Stock-Based Compensation | B9: 36475 | C9: 20665 | D9: 21226 | E9: 19591 | F9: 28050
A10: (Benefit) Provision for Deferred Income Taxes | B10: -9201 | C10: 20244 | D10: -42055 | E10: -9730 | F10: -57336
A11: Foreign Currency Gain (Loss) | B11: 880 | C11: 483 | D11: 1246 | E11: 1734 | F11: 0
A12: Gain (Loss) on Lease Cancellations | B12: -28 | C12: 0 | D12: 0 | E12: 0 | F12: 0
A13: Change in Fair Value of Contingent Consideration | B13: 0 | C13: 0 | D13: 0 | E13: 0 | F13: 13800
... A28: Net Change in Other Working Capital | B28: 0 | C28: 0 | D28: 0 | E28: 0 | F28: 2481
A29: Cash Flow from Operations | B29: =SUM(B2:B28) | C29: =SUM(C2:C28) | D29: =SUM(D2:D28) | E29: =SUM(E2:E28) | F29: =SUM(F2:F28) | G29: =SUM(G2:G28) | H29: =SUM(H2:H28) | I29: =SUM(I2:I28) | ... L29: =SUM(L2:L28)
A30: Collections from Note Receivable | B30: 1886 | C30: 2592 | D30: 3233 | E30: 0 | F30: 0
A31: Purchase of PP&E | B31: -3150 | C31: -8264 | D31: -17433 | E31: -23390 | F31: -36067
A32: Purchase of Non-Marketable Equity Securities | B32: 0 | C32: 0 | D32: 0 | E32: -3000 | F32: -10000
A33: Acquisition of Big Beverages | B33: 0 | C33: 0 | D33: 0 | E33: -75336 | F33: 0
A34: Acquisitions, Net of Cash Acquired | B34: 0 | C34: 0 | D34: 0 | E34: 0 | F34: -1278769
A35: Working Capital Estimate from Pepsi (Rockstar) | B35: 0 | C35: 0 | D35: 0 | E35: 0 | F35: 29156
A36: Cash Flow from Investing | B36: =SUM(B30:B35) | C36: =SUM(C30:C35) | D36: =SUM(D30:D35) | E36: =SUM(E30:E35) | F36: =SUM(F30:F35) | G36: =SUM(G30:G35) | H36: =SUM(H30:H35) | I36: =SUM(I30:I35) | ... L36: =SUM(L30:L35)
A37: Finance Lease Payments | B37: -94 | C37: -63 | D37: -44 | E37: -61 | F37: 0
A38: Proceeds from Exercise of Stock Options | B38: 3720 | C38: 3683 | D38: 2285 | E38: 3856 | F38: 0
A39: Proceeds from Issuance of Common Stock | B39: 67769 | C39: 0 | D39: 0 | E39: 0 | F39: 0
A40: Proceeds from Issuance of Preferred Stock | B40: 0 | C40: 542018 | D40: 0 | E40: 0 | F40: 0
A41: Preferred Dividends | B41: 0 | C41: -11526 | D41: -27462 | E41: -27500 | F41: -37608
A42: Share Repurchases | B42: 0 | C42: 0 | D42: 0 | E42: -2261 | F42: -45504
A43: Proceeds from Issuance of Long-Term Debt | B43: 0 | C43: 0 | D43: 0 | E43: 0 | F43: 900000
A44: Repayments of Long-Term Debt | B44: 0 | C44: 0 | D44: 0 | E44: 0 | F44: -201750
A45: Debt Issuance Fees | B45: 0 | C45: 0 | D45: 0 | E45: 0 | F45: -32367
A46: Other Financing Activities | B46: 0 | C46: 0 | D46: 0 | E46: 0 | F46: -7
A47: Cash Flow from Financing | B47: =SUM(B37:B46) | C47: =SUM(C37:C46) | D47: =SUM(D37:D46) | E47: =SUM(E37:E46) | F47: =SUM(F37:F46) | G47: =SUM(G37:G46) | H47: =SUM(H37:H46) | I47: =SUM(I37:I46) | ... L47: =SUM(L37:L46)
A48: FX Effect on Cash | B48: -538 | C48: 50 | D48: 1257 | E48: -997 | F48: 3271
A49: Net Change in Cash | B49: =B29+B36+B47+B48 | C49: =C29+C36+C47+C48 | D49: =D29+D36+D47+D48 | E49: =E29+E36+E47+E48 | F49: =F29+F36+F47+F48 | G49: =G29+G36+G47+G48 | H49: =H29+H36+H47+H48 | I49: =I29+I36+I47+I48 | ... L49: =L29+L36+L47+L48

Sheet YTD P&L
B1: Q1 FY2022 | C1: Q2 FY2022 | D1: Q3 FY2022 | E1: Q1 FY2023 | F1: Q2 FY2023 | G1: Q3 FY2023 | H1: Q1 FY2024 | I1: Q2 FY2024 | J1: Q3 FY2024 | K1: Q1 FY2025 | L1: Q2 FY2025 | M1: Q3 FY2025
A2: Net Sales / Revenue | B2: 133388 | C2: 287408 | D2: 475640 | E2: 259939 | F2: 585822 | G2: 970579 | H2: 355708 | I2: 757685 | J2: 1023433 | K2: 329276 | L2: 1068535 | M2: 1793641
A3: COGS | B3: -79494 | C3: -174195 | D3: -283778 | E3: -146121 | F3: -313010 | G3: -503685 | H3: -173501 | I3: -366380 | J3: -509899 | K3: -156903 | L3: -515311 | M3: -868138
A4: Gross Profit (Loss) | B4: =B2+B3 | C4: =C2+C3 | D4: =D2+D3 | E4: =E2+E3 | F4: =F2+F3 | G4: =G2+G3 | H4: =H2+H3 | I4: =I2+I3 | ... M4: =M2+M3
A5: SG&A | B5: -43778 | C5: -90667 | D5: -316917 | E5: -68905 | F5: -163086 | G5: -259471 | H5: -99017 | I5: -213867 | J5: -339310 | K5: -120342 | L5: -358228 | M5: -563799
A6: Distributor Termination Fees | B6: 0 | C6: 0 | D6: 0 | E6: 0 | F6: 0 | G6: 0 | H6: 0 | I6: 0 | J6: 0 | K6: 0 | L6: 0 | M6: -246707
A7: Income (Loss) from Operations | B7: =B4+SUM(B5:B6) | C7: =C4+SUM(C5:C6) | D7: =D4+SUM(D5:D6) | E7: =E4+SUM(E5:E6) | F7: =F4+SUM(F5:F6) | G7: =G4+SUM(G5:G6) | H7: =H4+SUM(H5:H6) | I7: =I4+SUM(I5:I6) | ... M7: =M4+SUM(M5:M6)
A8: Interest Income (Expense) | B8: 76 | C8: 129 | D8: 1579 | E8: 4969 | F8: 10542 | G8: 17767 | H8: 9640 | I8: 20287 | J8: 31399 | K8: 7846 | L8: -6196 | M8: -19592
A9: Foreign Currency Gain (Loss) | B9: -162 | C9: -676 | D9: -930 | E9: -118 | F9: -1049 | G9: -1226 | H9: -369 | I9: -633 | J9: -356 | K9: 0 | L9: 0 | M9: 0
A10: Other Income (Expense) | B10: 0 | C10: 0 | D10: 0 | E10: 0 | F10: 0 | G10: 0 | H10: 0 | I10: 0 | J10: 0 | K10: 1116 | L10: 1658 | M10: 7022
A11: Pre-Tax Income (Loss) | B11: =B7+SUM(B8:B10) | C11: =C7+SUM(C8:C10) | D11: =D7+SUM(D8:D10) | E11: =E7+SUM(E8:E10) | F11: =F7+SUM(F8:F10) | G11: =G7+SUM(G8:G10) | H11: =H7+SUM(H8:H10) | I11: =I7+SUM(I8:I10) | ... M11: =M7+SUM(M8:M10)
A12: Income Tax (Expense) Benefit | B12: -3351 | C12: -6161 | D12: -41653 | E12: -8537 | F12: -26483 | G12: -47279 | H12: -14650 | I12: -39498 | J12: -41317 | K12: -16574 | L12: -46184 | M12: -19167
A13: Net Income (Loss) | B13: =B11+B12 | C13: =C11+C12 | D13: =D11+D12 | E13: =E11+E12 | F13: =F11+F12 | G13: =G11+G12 | H13: =H11+H12 | I13: =I11+I12 | ... M13: =M11+M12
A14: Preferred Dividends | B14: 0 | C14: 0 | D14: -4596 | E14: -6781 | F14: -13637 | G14: -20512 | H14: -6837 | I14: -13675 | J14: -20588 | K14: -6781 | L14: -13632 | M14: -23289
A15: Income Allocated to Participating Preferred | B15: 0 | C15: 0 | D15: 0 | E15: 0 | F15: -6727 | G15: -13263 | H15: -6128 | I15: -12417 | J15: -12357 | K15: -3219 | L15: -10703 | M15: -5272
A16: Net Income (Loss) Attributable to Common Shareholders | B16: =B13+B14+B15 | C16: =C13+C14+C15 | D16: =D13+D14+D15 | E16: =E13+E14+E15 | F16: =F13+F14+F15 | G16: =G13+G14+G15 | H16: =H13+H14+H15 | I16: =I13+I14+I15 | ... M16: =M13+M14+M15

Sheet YTD BS
B1: Q4 FY2022 | C1: Q1 FY2023 | D1: Q2 FY2023 | E1: Q3 FY2023 | F1: Q4 FY2023 | G1: Q1 FY2024 | H1: Q2 FY2024 | I1: Q3 FY2024 | J1: Q4 FY2024 | K1: Q1 FY2025 | L1: Q2 FY2025 | M1: Q3 FY2025
A2: Cash & Cash Equivalents | B2: 614159 | C2: 595476 | D2: 681054 | E2: 760022 | F2: 755981 | G2: 879498 | H2: 903210 | I2: 903748 | J2: 890190 | K2: 977285 | L2: 615233 | M2: 805955
A3: Restricted Cash | B3: 38768 | C3: 38105 | D3: 0 | E3: 0 | F3: 0 | G3: 0 | H3: 0 | I3: 0 | J3: 0 | K3: 0 | L3: 0 | M3: 126508
A4: Accounts Receivable | B4: 63311 | C4: 172032 | D4: 197811 | E4: 215243 | F4: 183703 | G4: 200117 | H4: 262920 | I4: 208774 | J4: 270342 | K4: 256424 | L4: 490389 | M4: 513682
A5: Note Receivable - Current | B5: 2979 | C5: 3587 | D5: 3323 | E5: 3309 | F5: 2318 | G5: 2259 | H5: 1166 | I5: 1025 | J5: 0 | K5: 0 | L5: 0 | M5: 0
A6: Inventories | B6: 173289 | C6: 154280 | D6: 152545 | E6: 198704 | F6: 229275 | G6: 197504 | H6: 180669 | I6: 197572 | J6: 131165 | K6: 141159 | L6: 230046 | M6: 282514
A7: Prepaid Expenses | B7: 11341 | C7: 15507 | D7: 23398 | E7: 23747 | F7: 19503 | G7: 21523 | H7: 22900 | I7: 38227 | J7: 18759 | K7: 22464 | L7: 41420 | M7: 163395
A8: Deferred Other Costs - Current | B8: 14124 | C8: 14124 | D8: 14124 | E8: 14124 | F8: 14124 | G8: 14124 | H8: 14124 | I8: 14124 | J8: 14124 | K8: 14124 | L8: 14124 | M8: 49520
A9: Total Current Assets | B9: =SUM(B2:B8) | C9: =SUM(C2:C8) | D9: =SUM(D2:D8) | E9: =SUM(E2:E8) | F9: =SUM(F2:F8) | G9: =SUM(G2:G8) | H9: =SUM(H2:H8) | I9: =SUM(I2:I8) | ... M9: =SUM(M2:M8)
A10: Note Receivable - Non-Current | B10: 3574 | C10: 0 | D10: 0 | E10: 0 | F10: 0 | G10: 0 | H10: 0 | I10: 0 | J10: 0 | K10: 0 | L10: 0 | M10: 0
A11: Net PP&E | B11: 10185 | C11: 12054 | D11: 15892 | E11: 21061 | F11: 24868 | G11: 28350 | H11: 36282 | I11: 38370 | J11: 55602 | K11: 58698 | L11: 72516 | M11: 80925
A12: ROU Assets - Operating - Non-Current | B12: 972 | C12: 931 | D12: 756 | E12: 1152 | F12: 1957 | G12: 1688 | H12: 1507 | I12: 5506 | J12: 21606 | K12: 20866 | L12: 0 | M12: 0
A13: Intangible Assets | B13: 12254 | C13: 12359 | D13: 12211 | E13: 11772 | F13: 12139 | G13: 11741 | H13: 11491 | I13: 11877 | J13: 12213 | K13: 12444 | L13: 1222115 | M13: 1397819
A14: Goodwill | B14: 13679 | C14: 13949 | D14: 13937 | E14: 13588 | F14: 14173 | G14: 13866 | H14: 13730 | I14: 14360 | J14: 71582 | K14: 72128 | L14: 802234 | M14: 914957
A15: Deferred Other Costs - Non-Current | B15: 262462 | C15: 258931 | D15: 255400 | E15: 251869 | F15: 248338 | G15: 244807 | H15: 241276 | I15: 237746 | J15: 234215 | K15: 230684 | L15: 227153 | M15: 784214
A16: Deferred Tax Assets | B16: 501 | C16: 482 | D16: 28373 | E16: 30614 | F16: 29518 | G16: 22437 | H16: 22727 | I16: 24186 | J16: 38699 | K16: 38525 | L16: 43158 | M16: 110410
A17: ROU Assets - Finance - Non-Current | B17: 208 | C17: 191 | D17: 171 | E17: 148 | F17: 208 | G17: 263 | H17: 233 | I17: 214 | J17: 0 | K17: 0 | L17: 0 | M17: 0
A18: Other Non-Current Assets | B18: 263 | C18: 263 | D18: 254 | E18: 265 | F18: 291 | G18: 7963 | H18: 6653 | I18: 8594 | J18: 8384 | K18: 14717 | L18: 36755 | M18: 35809
A19: Total Assets | B19: =B9+SUM(B10:B18) | C19: =C9+SUM(C10:C18) | D19: =D9+SUM(D10:D18) | E19: =E9+SUM(E10:E18) | F19: =F9+SUM(F10:F18) | G19: =G9+SUM(G10:G18) | H19: =H9+SUM(H10:H18) | I19: =I9+SUM(I10:I18) | ... M19: =M9+SUM(M10:M18)
A20: Accounts Payable | B20: 107340 | C20: 107112 | D20: 94313 | E20: 121088 | F20: 42840 | G20: 40196 | H20: 47423 | I20: 30938 | J20: 41287 | K20: 61052 | L20: 120962 | M20: 97794
A21: Accrued Expenses | B21: 0 | C21: 0 | D21: 0 | E21: 0 | F21: 62120 | G21: 63871 | H21: 79633 | I21: 73024 | J21: 148780 | K21: 152046 | L21: 225859 | M21: 311768
A22: Income Taxes Payable | B22: 0 | C22: 0 | D22: 58798 | E22: 58855 | F22: 50424 | G22: 58619 | H22: 5374 | I22: 739 | J22: 10834 | K22: 26206 | L22: 21765 | M22: 49590
A23: Accrued Distributor Termination Fees | B23: 3986 | C23: 1063 | D23: 0 | E23: 0 | F23: 0 | G23: 0 | H23: 0 | I23: 0 | J23: 0 | K23: 0 | L23: 0 | M23: 252953
A24: Accrued Promotional Allowance | B24: 35977 | C24: 68225 | D24: 98933 | E24: 136557 | F24: 99787 | G24: 129201 | H24: 156479 | I24: 158810 | J24: 135948 | K24: 151327 | L24: 200169 | M24: 234068
A25: Lease Liability - Operating - Current | B25: 661 | C25: 605 | D25: 505 | E25: 628 | F25: 980 | G25: 821 | H25: 729 | I25: 1358 | J25: 3265 | K25: 3550 | L25: 0 | M25: 0
A26: Lease Liability - Finance - Current | B26: 70 | C26: 69 | D26: 67 | E26: 63 | F26: 59 | G26: 61 | H26: 61 | I26: 99 | J26: 0 | K26: 0 | L26: 0 | M26: 0
A27: Contingent Consideration - Current | B27: 0 | C27: 0 | D27: 0 | E27: 0 | F27: 0 | G27: 0 | H27: 0 | I27: 0 | J27: 0 | K27: 0 | L27: 25000 | M27: 25000
A28: Deferred Revenue - Current | B28: 9675 | C28: 9563 | D28: 9500 | E28: 9500 | F28: 9513 | G28: 9513 | H28: 9513 | I28: 9513 | J28: 9513 | K28: 9513 | L28: 16071 | M28: 25557
A29: Other Current Liabilities | B29: 3586 | C29: 5094 | D29: 7109 | E29: 8826 | F29: 10890 | G29: 12987 | H29: 13772 | I29: 14979 | J29: 15908 | K29: 14160 | L29: 49949 | M29: 32258
A30: Total Current Liabilities | B30: =SUM(B20:B29) | C30: =SUM(C20:C29) | D30: =SUM(D20:D29) | E30: =SUM(E20:E29) | F30: =SUM(F20:F29) | G30: =SUM(G20:G29) | H30: =SUM(H20:H29) | I30: =SUM(I20:I29) | ... M30: =SUM(M20:M29)
A31: Lease Liability - Operating - Non-Current | B31: 326 | C31: 336 | D31: 249 | E31: 512 | F31: 955 | G31: 850 | H31: 762 | I31: 4193 | J31: 16674 | K31: 16152 | L31: 0 | M31: 0
A32: Lease Liability - Finance - Non-Current | B32: 162 | C32: 156 | D32: 147 | E32: 135 | F32: 193 | G32: 245 | H32: 228 | I32: 189 | J32: 0 | K32: 0 | L32: 0 | M32: 0
A33: Deferred Tax Liability | B33: 15919 | C33: 19250 | D33: 2333 | E33: 2249 | F33: 2880 | G33: 2248 | H33: 2201 | I33: 2275 | J33: 0 | K33: 0 | L33: 0 | M33: 0
A34: Long-Term Debt | B34: 0 | C34: 0 | D34: 0 | E34: 0 | F34: 0 | G34: 0 | H34: 0 | I34: 0 | J34: 0 | K34: 0 | L34: 862917 | M34: 861472
A35: Deferred Revenue - Non-Current | B35: 179788 | C35: 175275 | D35: 171745 | E35: 169370 | F35: 167227 | G35: 164849 | H35: 162471 | I35: 160092 | J35: 157714 | K35: 155336 | L35: 156135 | M35: 387432
A36: Other Non-Current Liabilities | B36: 0 | C36: 0 | D36: 0 | E36: 0 | F36: 0 | G36: 0 | H36: 0 | I36: 0 | J36: 2541 | K36: 2574 | L36: 25002 | M36: 24431
A37: Total Liabilities | B37: =B30+SUM(B31:B36) | C37: =C30+SUM(C31:C36) | D37: =D30+SUM(D31:D36) | E37: =E30+SUM(E31:E36) | F37: =F30+SUM(F31:F36) | G37: =G30+SUM(G31:G36) | H37: =H30+SUM(H31:H36) | I37: =I30+SUM(I31:I36) | ... M37: =M30+SUM(M31:M36)
A38: Convertible Preferred Stock | B38: 824488 | C38: 824488 | D38: 824488 | E38: 824488 | F38: 824488 | G38: 824488 | H38: 824488 | I38: 824488 | J38: 824488 | K38: 824488 | L38: 824488 | M38: 1760275
A39: Common Stock | B39: 76 | C39: 77 | D39: 77 | E39: 77 | F39: 77 | G39: 78 | H39: 78 | I39: 79 | J39: 79 | K39: 79 | L39: 101 | M39: 101
A40: Treasury Stock | B40: 0 | C40: 0 | D40: 0 | E40: 0 | F40: 0 | G40: 0 | H40: 0 | I40: 0 | J40: 0 | K40: 0 | L40: 0 | M40: 0
...

Sheet YTD CF
B1: Q1 FY2022 | C1: Q2 FY2022 | D1: Q3 FY2022 | E1: Q1 FY2023 | F1: Q2 FY2023 | G1: Q3 FY2023 | H1: Q1 FY2024 | I1: Q2 FY2024 | J1: Q3 FY2024 | K1: Q1 FY2025 | L1: Q2 FY2025 | M1: Q3 FY2025
A2: Net Income (Loss) | B2: 6679 | C2: 15838 | D2: -166059 | E2: 41227 | F2: 92736 | G2: 176685 | H2: 77811 | I2: 157594 | J2: 163950 | K2: 44419 | L2: 144274 | M2: 83260
A3: Depreciation | B3: 245 | C3: 556 | D3: 952 | E3: 404 | F3: 953 | G3: 1676 | H3: 0 | I3: 0 | J3: 0 | K3: 0 | L3: 0 | M3: 0
A4: Amortization | B4: 141 | C4: 275 | D4: 402 | E4: 145 | F4: 294 | G4: 445 | H4: 0 | I4: 0 | J4: 0 | K4: 0 | L4: 0 | M4: 0
A5: Impairment of Intangibles | B5: 0 | C5: 0 | D5: 2379 | E5: 0 | F5: 0 | G5: 0 | H5: 0 | I5: 0 | J5: 0 | K5: 0 | L5: 0 | M5: 0
A6: Depreciation & Amortization | B6: 0 | C6: 0 | D6: 0 | E6: 0 | F6: 0 | G6: 0 | H6: 1229 | I6: 2648 | J6: 4888 | K6: 2611 | L6: 11730 | M6: 20516
A7: Allowance for Credit Losses | B7: 455 | C7: 466 | D7: 705 | E7: 837 | F7: 1088 | G7: 1880 | H7: 2250 | I7: 4072 | J7: 4279 | K7: 2077 | L7: 5529 | M7: 3226
A8: Amortization of Deferred Other Costs | B8: 0 | C8: 0 | D8: 2354 | E8: 3531 | F8: 7062 | G8: 10593 | H8: 3531 | I8: 7062 | J8: 10593 | K8: 3531 | L8: 7062 | M8: 13391
A9: Inventory Write-Down | B9: 2596 | C9: 331 | D9: 1078 | E9: 1672 | F9: -3888 | G9: 2677 | H9: 2386 | I9: 11554 | J9: 17118 | K9: 5337 | L9: 15262 | M9: 22313
A10: Gain (Loss) on Disposal of PP&E | B10: 0 | C10: 0 | D10: 0 | E10: 0 | F10: 191 | G10: 195 | H10: -8 | I10: 31 | J10: 126 | K10: 0 | L10: 0 | M10: 0
A11: Stock-Based Compensation | B11: 4310 | C11: 8517 | D11: 14780 | E11: 5507 | F11: 11242 | G11: 16221 | H11: 3563 | I11: 8309 | J11: 13685 | K11: 5029 | L11: 11463 | M11: 18847
A12: (Benefit) Provision for Deferred Income Taxes | B12: 2561 | C12: 1072 | D12: 31329 | E12: 2873 | F12: -41044 | G12: -44303 | H12: 6450 | I12: 6112 | J12: 4727 | K12: 269 | L12: -4161 | M12: -71408
A13: Foreign Currency Gain (Loss) | B13: 85 | C13: 602 | D13: 1007 | E13: 69 | F13: 206 | G13: 258 | H13: 369 | I13: 633 | J13: 356 | K13: 0 | L13: 0 | M13: 0
... A31: Net Change in Other Working Capital | B31: 0 | C31: 488 | D31: 0 | E31: 0 | F31: 0 | G31: 0 | H31: 0 | I31: 0 | J31: 0 | K31: 148 | L31: -1210 | M31: -1786
A32: Cash Flow from Operations | B32: =SUM(B2:B31) | C32: =SUM(C2:C31) | D32: =SUM(D2:D31) | E32: =SUM(E2:E31) | F32: =SUM(F2:F31) | G32: =SUM(G2:G31) | H32: =SUM(H2:H31) | I32: =SUM(I2:I31) | ... M32: =SUM(M2:M31)
A33: Collections from Note Receivable | B33: 0 | C33: 2592 | D33: 2592 | E33: 3233 | F33: 3233 | G33: 3233 | H33: 0 | I33: 0 | J33: 0 | K33: 0 | L33: 0 | M33: 0
A34: Purchase of PP&E | B34: -742 | C34: -2456 | D34: -3477 | E34: -2253 | F34: -6810 | G34: -12687 | H34: -4525 | I34: -13739 | J34: -17983 | K34: -6944 | L34: -15194 | M34: -25539
A35: Purchase of Non-Marketable Equity Securities | B35: 0 | C35: 0 | D35: 0 | E35: 0 | F35: 0 | G35: 0 | H35: 0 | I35: 0 | J35: -3000 | K35: 0 | L35: -5000 | M35: -5000
A36: Acquisition of Big Beverages | B36: 0 | C36: 0 | D36: 0 | E36: 0 | F36: 0 | G36: 0 | H36: 0 | I36: 0 | J36: 0 | K36: 0 | L36: 0 | M36: 0
A37: Acquisitions, Net of Cash Acquired | B37: 0 | C37: 0 | D37: 0 | E37: 0 | F37: 0 | G37: 0 | H37: 0 | I37: 0 | J37: 0 | K37: 0 | L37: -1256351 | M37: -1278769
A38: Working Capital Estimate from Pepsi (Rockstar) | B38: 0 | C38: 0 | D38: 0 | E38: 0 | F38: 0 | G38: 0 | H38: 0 | I38: 0 | J38: 0 | K38: 0 | L38: 0 | M38: 30617
A39: Cash Flow from Investing | B39: =SUM(B33:B38) | C39: =SUM(C33:C38) | D39: =SUM(D33:D38) | E39: =SUM(E33:E38) | F39: =SUM(F33:F38) | G39: =SUM(G33:G38) | H39: =SUM(H33:H38) | I39: =SUM(I33:I38) | ... M39: =SUM(M33:M38)
A40: Finance Lease Payments | B40: -20 | C40: -37 | D40: -49 | E40: -11 | F40: -22 | G40: -33 | H40: -15 | I40: -30 | J40: -46 | K40: 0 | L40: 0 | M40: 0
A41: Proceeds from Exercise of Stock Options | B41: 810 | C41: 1260 | D41: 3104 | E41: 478 | F41: 707 | G41: 1603 | H41: 967 | I41: 1147 | J41: 3832 | K41: 0 | L41: 0 | M41: 0
A42: Proceeds from Issuance of Common Stock | B42: 0 | C42: 0 | D42: 0 | E42: 0 | F42: 0 | G42: 0 | H42: 0 | I42: 0 | J42: 0 | K42: 0 | L42: 0 | M42: 0
A43: Proceeds from Issuance of Preferred Stock | B43: 0 | C43: 0 | D43: 542018 | E43: 0 | F43: 0 | G43: 0 | H43: 0 | I43: 0 | J43: 0 | K43: 0 | L43: 0 | M43: 0
A44: Preferred Dividends | B44: 0 | C44: 0 | D44: -4596 | E44: -6781 | F44: -13637 | G44: -20512 | H44: -6837 | I44: -13675 | J44: -20588 | K44: -6781 | L44: -13632 | M44: -23301
A45: Share Repurchases | B45: 0 | C45: 0 | D45: 0 | E45: 0 | F45: 0 | G45: 0 | H45: 0 | I45: 0 | J45: -1658 | K45: -1932 | L45: -2811 | M45: -3259
A46: Proceeds from Issuance of Long-Term Debt | B46: 0 | C46: 0 | D46: 0 | E46: 0 | F46: 0 | G46: 0 | H46: 0 | I46: 0 | J46: 0 | K46: 0 | L46: 900000 | M46: 900000
A47: Repayments of Long-Term Debt | B47: 0 | C47: 0 | D47: 0 | E47: 0 | F47: 0 | G47: 0 | H47: 0 | I47: 0 | J47: 0 | K47: 0 | L47: 0 | M47: -2250
A48: Debt Issuance Fees | B48: 0 | C48: 0 | D48: 0 | E48: 0 | F48: 0 | G48: 0 | H48: 0 | I48: 0 | J48: 0 | K48: -2195 | L48: -31581 | M48: -31581
A49: Other Financing Activities | B49: 0 | C49: 0 | D49: 0 | E49: 0 | F49: 0 | G49: 0 | H49: 0 | I49: 0 | J49: 0 | K49: 321 | L49: 319 | M49: 301
A50: Cash Flow from Financing | B50: =SUM(B40:B49) | C50: =SUM(C40:C49) | D50: =SUM(D40:D49) | E50: =SUM(E40:E49) | F50: =SUM(F40:F49) | G50: =SUM(G40:G49) | H50: =SUM(H40:H49) | I50: =SUM(I40:I49) | ... M50: =SUM(M40:M49)
A51: FX Effect on Cash | B51: 104 | C51: 121 | D51: 158 | E51: -181 | F51: -555 | G51: -555 | H51: -722 | I51: -766 | J51: -16 | K51: 1259 | L51: 2214 | M51: 2174
A52: Net Change in Cash | B52: =B32+B39+B50+B51 | C52: =C32+C39+C50+C51 | D52: =D32+D39+D50+D51 | E52: =E32+E39+E50+E51 | F52: =F32+F39+F50+F51 | G52: =G32+G39+G50+G51 | H52: =H32+H39+H50+H51 | I52: =I32+I39+I50+I51 | ... M52: =M32+M39+M50+M51

Sheet QTR P&L
B1: Q1 FY2022 | C1: Q2 FY2022 | D1: Q3 FY2022 | E1: Q4 FY2022 | F1: Q1 FY2023 | G1: Q2 FY2023 | H1: Q3 FY2023 | I1: Q4 FY2023 | J1: Q1 FY2024 | K1: Q2 FY2024 | L1: Q3 FY2024 | M1: Q4 FY2024 | N1: Q1 FY2025 | O1: Q2 FY2025 | P1: Q3 FY2025 | Q1: Q4 FY2025
A2: Net Sales / Revenue | B2: ='YTD P&L'!B2 | C2: ='YTD P&L'!C2-'YTD P&L'!B2 | D2: ='YTD P&L'!D2-'YTD P&L'!C2 | E2: ='ANNL P&L'!C2-'YTD P&L'!D2 | F2: ='YTD P&L'!E2 | G2: ='YTD P&L'!F2-'YTD P&L'!E2 | H2: ='YTD P&L'!G2-'YTD P&L'!F2 | I2: ='ANNL P&L'!D2-'YTD P&L'!G2 | J2: ='YTD P&L'!H2 | K2: ='YTD P&L'!I2-'YTD P&L'!H2 | L2: ='YTD P&L'!J2-'YTD P&L'!I2 | M2: ='ANNL P&L'!E2-'YTD P&L'!J2 | N2: ='YTD P&L'!K2 | O2: ='YTD P&L'!L2-'YTD P&L'!K2 | P2: ='YTD P&L'!M2-'YTD P&L'!L2 | Q2: ='ANNL P&L'!F2-'YTD P&L'!M2
A3: COGS | B3: ='YTD P&L'!B3 | C3: ='YTD P&L'!C3-'YTD P&L'!B3 | D3: ='YTD P&L'!D3-'YTD P&L'!C3 | E3: ='ANNL P&L'!C3-'YTD P&L'!D3 | F3: ='YTD P&L'!E3 | G3: ='YTD P&L'!F3-'YTD P&L'!E3 | H3: ='YTD P&L'!G3-'YTD P&L'!F3 | I3: ='ANNL P&L'!D3-'YTD P&L'!G3 | J3: ='YTD P&L'!H3 | K3: ='YTD P&L'!I3-'YTD P&L'!H3 | L3: ='YTD P&L'!J3-'YTD P&L'!I3 | M3: ='ANNL P&L'!E3-'YTD P&L'!J3 | N3: ='YTD P&L'!K3 | O3: ='YTD P&L'!L3-'YTD P&L'!K3 | P3: ='YTD P&L'!M3-'YTD P&L'!L3 | Q3: ='ANNL P&L'!F3-'YTD P&L'!M3
A4: Gross Profit (Loss) | B4: ='YTD P&L'!B4 | C4: ='YTD P&L'!C4-'YTD P&L'!B4 | D4: ='YTD P&L'!D4-'YTD P&L'!C4 | E4: ='ANNL P&L'!C4-'YTD P&L'!D4 | F4: ='YTD P&L'!E4 | G4: ='YTD P&L'!F4-'YTD P&L'!E4 | H4: ='YTD P&L'!G4-'YTD P&L'!F4 | I4: ='ANNL P&L'!D4-'YTD P&L'!G4 | J4: ='YTD P&L'!H4 | K4: ='YTD P&L'!I4-'YTD P&L'!H4 | L4: ='YTD P&L'!J4-'YTD P&L'!I4 | M4: ='ANNL P&L'!E4-'YTD P&L'!J4 | N4: ='YTD P&L'!K4 | O4: ='YTD P&L'!L4-'YTD P&L'!K4 | P4: ='YTD P&L'!M4-'YTD P&L'!L4 | Q4: ='ANNL P&L'!F4-'YTD P&L'!M4
A5: SG&A | B5: ='YTD P&L'!B5 | C5: ='YTD P&L'!C5-'YTD P&L'!B5 | D5: ='YTD P&L'!D5-'YTD P&L'!C5 | E5: ='ANNL P&L'!C5-'YTD P&L'!D5 | F5: ='YTD P&L'!E5 | G5: ='YTD P&L'!F5-'YTD P&L'!E5 | H5: ='YTD P&L'!G5-'YTD P&L'!F5 | I5: ='ANNL P&L'!D5-'YTD P&L'!G5 | J5: ='YTD P&L'!H5 | K5: ='YTD P&L'!I5-'YTD P&L'!H5 | L5: ='YTD P&L'!J5-'YTD P&L'!I5 | M5: ='ANNL P&L'!E5-'YTD P&L'!J5 | N5: ='YTD P&L'!K5 | O5: ='YTD P&L'!L5-'YTD P&L'!K5 | P5: ='YTD P&L'!M5-'YTD P&L'!L5 | Q5: ='ANNL P&L'!F5-'YTD P&L'!M5
A6: Distributor Termination Fees | B6: ='YTD P&L'!B6 | C6: ='YTD P&L'!C6-'YTD P&L'!B6 | D6: ='YTD P&L'!D6-'YTD P&L'!C6 | E6: ='ANNL P&L'!C6-'YTD P&L'!D6 | F6: ='YTD P&L'!E6 | G6: ='YTD P&L'!F6-'YTD P&L'!E6 | H6: ='YTD P&L'!G6-'YTD P&L'!F6 | I6: ='ANNL P&L'!D6-'YTD P&L'!G6 | J6: ='YTD P&L'!H6 | K6: ='YTD P&L'!I6-'YTD P&L'!H6 | L6: ='YTD P&L'!J6-'YTD P&L'!I6 | M6: ='ANNL P&L'!E6-'YTD P&L'!J6 | N6: ='YTD P&L'!K6 | O6: ='YTD P&L'!L6-'YTD P&L'!K6 | P6: ='YTD P&L'!M6-'YTD P&L'!L6 | Q6: ='ANNL P&L'!F6-'YTD P&L'!M6
A7: Income (Loss) from Operations | B7: ='YTD P&L'!B7 | C7: ='YTD P&L'!C7-'YTD P&L'!B7 | D7: ='YTD P&L'!D7-'YTD P&L'!C7 | E7: ='ANNL P&L'!C7-'YTD P&L'!D7 | F7: ='YTD P&L'!E7 | G7: ='YTD P&L'!F7-'YTD P&L'!E7 | H7: ='YTD P&L'!G7-'YTD P&L'!F7 | I7: ='ANNL P&L'!D7-'YTD P&L'!G7 | J7: ='YTD P&L'!H7 | K7: ='YTD P&L'!I7-'YTD P&L'!H7 | L7: ='YTD P&L'!J7-'YTD P&L'!I7 | M7: ='ANNL P&L'!E7-'YTD P&L'!J7 | N7: ='YTD P&L'!K7 | O7: ='YTD P&L'!L7-'YTD P&L'!K7 | P7: ='YTD P&L'!M7-'YTD P&L'!L7 | Q7: ='ANNL P&L'!F7-'YTD P&L'!M7
A8: Interest Income (Expense) | B8: ='YTD P&L'!B8 | C8: ='YTD P&L'!C8-'YTD P&L'!B8 | D8: ='YTD P&L'!D8-'YTD P&L'!C8 | E8: ='ANNL P&L'!C8-'YTD P&L'!D8 | F8: ='YTD P&L'!E8 | G8: ='YTD P&L'!F8-'YTD P&L'!E8 | H8: ='YTD P&L'!G8-'YTD P&L'!F8 | I8: ='ANNL P&L'!D8-'YTD P&L'!G8 | J8: ='YTD P&L'!H8 | K8: ='YTD P&L'!I8-'YTD P&L'!H8 | L8: ='YTD P&L'!J8-'YTD P&L'!I8 | M8: ='ANNL P&L'!E8-'YTD P&L'!J8 | N8: ='YTD P&L'!K8 | O8: ='YTD P&L'!L8-'YTD P&L'!K8 | P8: ='YTD P&L'!M8-'YTD P&L'!L8 | Q8: ='ANNL P&L'!F8-'YTD P&L'!M8
A9: Foreign Currency Gain (Loss) | B9: ='YTD P&L'!B9 | C9: ='YTD P&L'!C9-'YTD P&L'!B9 | D9: ='YTD P&L'!D9-'YTD P&L'!C9 | E9: ='ANNL P&L'!C9-'YTD P&L'!D9 | F9: ='YTD P&L'!E9 | G9: ='YTD P&L'!F9-'YTD P&L'!E9 | H9: ='YTD P&L'!G9-'YTD P&L'!F9 | I9: ='ANNL P&L'!D9-'YTD P&L'!G9 | J9: ='YTD P&L'!H9 | K9: ='YTD P&L'!I9-'YTD P&L'!H9 | L9: ='YTD P&L'!J9-'YTD P&L'!I9 | M9: ='ANNL P&L'!E9-'YTD P&L'!J9 | N9: ='YTD P&L'!K9 | O9: ='YTD P&L'!L9-'YTD P&L'!K9 | P9: ='YTD P&L'!M9-'YTD P&L'!L9 | Q9: ='ANNL P&L'!F9-'YTD P&L'!M9
A10: Other Income (Expense) | B10: ='YTD P&L'!B10 | C10: ='YTD P&L'!C10-'YTD P&L'!B10 | D10: ='YTD P&L'!D10-'YTD P&L'!C10 | E10: ='ANNL P&L'!C10-'YTD P&L'!D10 | F10: ='YTD P&L'!E10 | G10: ='YTD P&L'!F10-'YTD P&L'!E10 | H10: ='YTD P&L'!G10-'YTD P&L'!F10 | I10: ='ANNL P&L'!D10-'YTD P&L'!G10 | J10: ='YTD P&L'!H10 | K10: ='YTD P&L'!I10-'YTD P&L'!H10 | L10: ='YTD P&L'!J10-'YTD P&L'!I10 | M10: ='ANNL P&L'!E10-'YTD P&L'!J10 | N10: ='YTD P&L'!K10 | O10: ='YTD P&L'!L10-'YTD P&L'!K10 | P10: ='YTD P&L'!M10-'YTD P&L'!L10 | Q10: ='ANNL P&L'!F10-'YTD P&L'!M10
A11: Pre-Tax Income (Loss) | B11: ='YTD P&L'!B11 | C11: ='YTD P&L'!C11-'YTD P&L'!B11 | D11: ='YTD P&L'!D11-'YTD P&L'!C11 | E11: ='ANNL P&L'!C11-'YTD P&L'!D11 | F11: ='YTD P&L'!E11 | G11: ='YTD P&L'!F11-'YTD P&L'!E11 | H11: ='YTD P&L'!G11-'YTD P&L'!F11 | I11: ='ANNL P&L'!D11-'YTD P&L'!G11 | J11: ='YTD P&L'!H11 | K11: ='YTD P&L'!I11-'YTD P&L'!H11 | L11: ='YTD P&L'!J11-'YTD P&L'!I11 | M11: ='ANNL P&L'!E11-'YTD P&L'!J11 | N11: ='YTD P&L'!K11 | O11: ='YTD P&L'!L11-'YTD P&L'!K11 | P11: ='YTD P&L'!M11-'YTD P&L'!L11 | Q11: ='ANNL P&L'!F11-'YTD P&L'!M11
A12: Income Tax (Expense) Benefit | B12: ='YTD P&L'!B12 | C12: ='YTD P&L'!C12-'YTD P&L'!B12 | D12: ='YTD P&L'!D12-'YTD P&L'!C12 | E12: ='ANNL P&L'!C12-'YTD P&L'!D12 | F12: ='YTD P&L'!E12 | G12: ='YTD P&L'!F12-'YTD P&L'!E12 | H12: ='YTD P&L'!G12-'YTD P&L'!F12 | I12: ='ANNL P&L'!D12-'YTD P&L'!G12 | J12: ='YTD P&L'!H12 | K12: ='YTD P&L'!I12-'YTD P&L'!H12 | L12: ='YTD P&L'!J12-'YTD P&L'!I12 | M12: ='ANNL P&L'!E12-'YTD P&L'!J12 | N12: ='YTD P&L'!K12 | O12: ='YTD P&L'!L12-'YTD P&L'!K12 | P12: ='YTD P&L'!M12-'YTD P&L'!L12 | Q12: ='ANNL P&L'!F12-'YTD P&L'!M12
A13: Net Income (Loss) | B13: ='YTD P&L'!B13 | C13: ='YTD P&L'!C13-'YTD P&L'!B13 | D13: ='YTD P&L'!D13-'YTD P&L'!C13 | E13: ='ANNL P&L'!C13-'YTD P&L'!D13 | F13: ='YTD P&L'!E13 | G13: ='YTD P&L'!F13-'YTD P&L'!E13 | H13: ='YTD P&L'!G13-'YTD P&L'!F13 | I13: ='ANNL P&L'!D13-'YTD P&L'!G13 | J13: ='YTD P&L'!H13 | K13: ='YTD P&L'!I13-'YTD P&L'!H13 | L13: ='YTD P&L'!J13-'YTD P&L'!I13 | M13: ='ANNL P&L'!E13-'YTD P&L'!J13 | N13: ='YTD P&L'!K13 | O13: ='YTD P&L'!L13-'YTD P&L'!K13 | P13: ='YTD P&L'!M13-'YTD P&L'!L13 | Q13: ='ANNL P&L'!F13-'YTD P&L'!M13
... A16: Net Income (Loss) Attributable to Common Shareholders | B16: ='YTD P&L'!B16 | C16: ='YTD P&L'!C16-'YTD P&L'!B16 | D16: ='YTD P&L'!D16-'YTD P&L'!C16 | E16: ='ANNL P&L'!C16-'YTD P&L'!D16 | F16: ='YTD P&L'!E16 | G16: ='YTD P&L'!F16-'YTD P&L'!E16 | H16: ='YTD P&L'!G16-'YTD P&L'!F16 | I16: ='ANNL P&L'!D16-'YTD P&L'!G16 | J16: ='YTD P&L'!H16 | K16: ='YTD P&L'!I16-'YTD P&L'!H16 | L16: ='YTD P&L'!J16-'YTD P&L'!I16 | M16: ='ANNL P&L'!E16-'YTD P&L'!J16 | N16: ='YTD P&L'!K16 | O16: ='YTD P&L'!L16-'YTD P&L'!K16 | P16: ='YTD P&L'!M16-'YTD P&L'!L16 | Q16: ='ANNL P&L'!F16-'YTD P&L'!M16

Sheet QTR BS
B1: Q4 FY2022 | C1: Q1 FY2023 | D1: Q2 FY2023 | E1: Q3 FY2023 | F1: Q4 FY2023 | G1: Q1 FY2024 | H1: Q2 FY2024 | I1: Q3 FY2024 | J1: Q4 FY2024 | K1: Q1 FY2025 | L1: Q2 FY2025 | M1: Q3 FY2025 | N1: Q4 FY2025
A2: Cash & Cash Equivalents | B2: ='BALANCE SHEET'!B2 | C2: ='YTD BS'!C2 | D2: ='YTD BS'!D2 | E2: ='YTD BS'!E2 | F2: ='BALANCE SHEET'!C2 | G2: ='YTD BS'!G2 | H2: ='YTD BS'!H2 | I2: ='YTD BS'!I2 | J2: ='BALANCE SHEET'!D2 | K2: ='YTD BS'!K2 | L2: ='YTD BS'!L2 | M2: ='YTD BS'!M2 | N2: ='BALANCE SHEET'!E2
A3: Restricted Cash | B3: ='BALANCE SHEET'!B3 | C3: ='YTD BS'!C3 | D3: ='YTD BS'!D3 | E3: ='YTD BS'!E3 | F3: ='BALANCE SHEET'!C3 | G3: ='YTD BS'!G3 | H3: ='YTD BS'!H3 | I3: ='YTD BS'!I3 | J3: ='BALANCE SHEET'!D3 | K3: ='YTD BS'!K3 | L3: ='YTD BS'!L3 | M3: ='YTD BS'!M3 | N3: ='BALANCE SHEET'!E3
A4: Accounts Receivable | B4: ='BALANCE SHEET'!B4 | C4: ='YTD BS'!C4 | D4: ='YTD BS'!D4 | E4: ='YTD BS'!E4 | F4: ='BALANCE SHEET'!C4 | G4: ='YTD BS'!G4 | H4: ='YTD BS'!H4 | I4: ='YTD BS'!I4 | J4: ='BALANCE SHEET'!D4 | K4: ='YTD BS'!K4 | L4: ='YTD BS'!L4 | M4: ='YTD BS'!M4 | N4: ='BALANCE SHEET'!E4
A5: Note Receivable - Current | B5: ='BALANCE SHEET'!B5 | C5: ='YTD BS'!C5 | D5: ='YTD BS'!D5 | E5: ='YTD BS'!E5 | F5: ='BALANCE SHEET'!C5 | G5: ='YTD BS'!G5 | H5: ='YTD BS'!H5 | I5: ='YTD BS'!I5 | J5: ='BALANCE SHEET'!D5 | K5: ='YTD BS'!K5 | L5: ='YTD BS'!L5 | M5: ='YTD BS'!M5 | N5: ='BALANCE SHEET'!E5
A6: Inventories | B6: ='BALANCE SHEET'!B6 | C6: ='YTD BS'!C6 | D6: ='YTD BS'!D6 | E6: ='YTD BS'!E6 | F6: ='BALANCE SHEET'!C6 | G6: ='YTD BS'!G6 | H6: ='YTD BS'!H6 | I6: ='YTD BS'!I6 | J6: ='BALANCE SHEET'!D6 | K6: ='YTD BS'!K6 | L6: ='YTD BS'!L6 | M6: ='YTD BS'!M6 | N6: ='BALANCE SHEET'!E6
A7: Prepaid Expenses | B7: ='BALANCE SHEET'!B7 | C7: ='YTD BS'!C7 | D7: ='YTD BS'!D7 | E7: ='YTD BS'!E7 | F7: ='BALANCE SHEET'!C7 | G7: ='YTD BS'!G7 | H7: ='YTD BS'!H7 | I7: ='YTD BS'!I7 | J7: ='BALANCE SHEET'!D7 | K7: ='YTD BS'!K7 | L7: ='YTD BS'!L7 | M7: ='YTD BS'!M7 | N7: ='BALANCE SHEET'!E7
A8: Deferred Other Costs - Current | B8: ='BALANCE SHEET'!B8 | C8: ='YTD BS'!C8 | D8: ='YTD BS'!D8 | E8: ='YTD BS'!E8 | F8: ='BALANCE SHEET'!C8 | G8: ='YTD BS'!G8 | H8: ='YTD BS'!H8 | I8: ='YTD BS'!I8 | J8: ='BALANCE SHEET'!D8 | K8: ='YTD BS'!K8 | L8: ='YTD BS'!L8 | M8: ='YTD BS'!M8 | N8: ='BALANCE SHEET'!E8
A9: Total Current Assets | B9: ='BALANCE SHEET'!B9 | C9: ='YTD BS'!C9 | D9: ='YTD BS'!D9 | E9: ='YTD BS'!E9 | F9: ='BALANCE SHEET'!C9 | G9: ='YTD BS'!G9 | H9: ='YTD BS'!H9 | I9: ='YTD BS'!I9 | J9: ='BALANCE SHEET'!D9 | K9: ='YTD BS'!K9 | L9: ='YTD BS'!L9 | M9: ='YTD BS'!M9 | N9: ='BALANCE SHEET'!E9
A10: Note Receivable - Non-Current | B10: ='BALANCE SHEET'!B10 | C10: ='YTD BS'!C10 | D10: ='YTD BS'!D10 | E10: ='YTD BS'!E10 | F10: ='BALANCE SHEET'!C10 | G10: ='YTD BS'!G10 | H10: ='YTD BS'!H10 | I10: ='YTD BS'!I10 | J10: ='BALANCE SHEET'!D10 | K10: ='YTD BS'!K10 | L10: ='YTD BS'!L10 | M10: ='YTD BS'!M10 | N10: ='BALANCE SHEET'!E10
A11: Net PP&E | B11: ='BALANCE SHEET'!B11 | C11: ='YTD BS'!C11 | D11: ='YTD BS'!D11 | E11: ='YTD BS'!E11 | F11: ='BALANCE SHEET'!C11 | G11: ='YTD BS'!G11 | H11: ='YTD BS'!H11 | I11: ='YTD BS'!I11 | J11: ='BALANCE SHEET'!D11 | K11: ='YTD BS'!K11 | L11: ='YTD BS'!L11 | M11: ='YTD BS'!M11 | N11: ='BALANCE SHEET'!E11
A12: ROU Assets - Operating - Non-Current | B12: ='BALANCE SHEET'!B12 | C12: ='YTD BS'!C12 | D12: ='YTD BS'!D12 | E12: ='YTD BS'!E12 | F12: ='BALANCE SHEET'!C12 | G12: ='YTD BS'!G12 | H12: ='YTD BS'!H12 | I12: ='YTD BS'!I12 | J12: ='BALANCE SHEET'!D12 | K12: ='YTD BS'!K12 | L12: ='YTD BS'!L12 | M12: ='YTD BS'!M12 | N12: ='BALANCE SHEET'!E12
A13: Intangible Assets | B13: ='BALANCE SHEET'!B14 | C13: ='YTD BS'!C13 | D13: ='YTD BS'!D13 | E13: ='YTD BS'!E13 | F13: ='BALANCE SHEET'!C14 | G13: ='YTD BS'!G13 | H13: ='YTD BS'!H13 | I13: ='YTD BS'!I13 | J13: ='BALANCE SHEET'!D14 | K13: ='YTD BS'!K13 | L13: ='YTD BS'!L13 | M13: ='YTD BS'!M13 | N13: ='BALANCE SHEET'!E14
A14: Goodwill | B14: ='BALANCE SHEET'!B15 | C14: ='YTD BS'!C14 | D14: ='YTD BS'!D14 | E14: ='YTD BS'!E14 | F14: ='BALANCE SHEET'!C15 | G14: ='YTD BS'!G14 | H14: ='YTD BS'!H14 | I14: ='YTD BS'!I14 | J14: ='BALANCE SHEET'!D15 | K14: ='YTD BS'!K14 | L14: ='YTD BS'!L14 | M14: ='YTD BS'!M14 | N14: ='BALANCE SHEET'!E15
A15: Deferred Other Costs - Non-Current | B15: ='BALANCE SHEET'!B16 | C15: ='YTD BS'!C15 | D15: ='YTD BS'!D15 | E15: ='YTD BS'!E15 | F15: ='BALANCE SHEET'!C16 | G15: ='YTD BS'!G15 | H15: ='YTD BS'!H15 | I15: ='YTD BS'!I15 | J15: ='BALANCE SHEET'!D16 | K15: ='YTD BS'!K15 | L15: ='YTD BS'!L15 | M15: ='YTD BS'!M15 | N15: ='BALANCE SHEET'!E16
A16: Deferred Tax Assets | B16: ='BALANCE SHEET'!B17 | C16: ='YTD BS'!C16 | D16: ='YTD BS'!D16 | E16: ='YTD BS'!E16 | F16: ='BALANCE SHEET'!C17 | G16: ='YTD BS'!G16 | H16: ='YTD BS'!H16 | I16: ='YTD BS'!I16 | J16: ='BALANCE SHEET'!D17 | K16: ='YTD BS'!K16 | L16: ='YTD BS'!L16 | M16: ='YTD BS'!M16 | N16: ='BALANCE SHEET'!E17
A17: ROU Assets - Finance - Non-Current | B17: ='BALANCE SHEET'!B13 | C17: ='YTD BS'!C17 | D17: ='YTD BS'!D17 | E17: ='YTD BS'!E17 | F17: ='BALANCE SHEET'!C13 | G17: ='YTD BS'!G17 | H17: ='YTD BS'!H17 | I17: ='YTD BS'!I17 | J17: ='BALANCE SHEET'!D13 | K17: ='YTD BS'!K17 | L17: ='YTD BS'!L17 | M17: ='YTD BS'!M17 | N17: ='BALANCE SHEET'!E13
A18: Other Non-Current Assets | B18: ='BALANCE SHEET'!B18 | C18: ='YTD BS'!C18 | D18: ='YTD BS'!D18 | E18: ='YTD BS'!E18 | F18: ='BALANCE SHEET'!C18 | G18: ='YTD BS'!G18 | H18: ='YTD BS'!H18 | I18: ='YTD BS'!I18 | J18: ='BALANCE SHEET'!D18 | K18: ='YTD BS'!K18 | L18: ='YTD BS'!L18 | M18: ='YTD BS'!M18 | N18: ='BALANCE SHEET'!E18
A19: Total Assets | B19: ='BALANCE SHEET'!B19 | C19: ='YTD BS'!C19 | D19: ='YTD BS'!D19 | E19: ='YTD BS'!E19 | F19: ='BALANCE SHEET'!C19 | G19: ='YTD BS'!G19 | H19: ='YTD BS'!H19 | I19: ='YTD BS'!I19 | J19: ='BALANCE SHEET'!D19 | K19: ='YTD BS'!K19 | L19: ='YTD BS'!L19 | M19: ='YTD BS'!M19 | N19: ='BALANCE SHEET'!E19
A20: Accounts Payable | B20: ='BALANCE SHEET'!B20 | C20: ='YTD BS'!C20 | D20: ='YTD BS'!D20 | E20: ='YTD BS'!E20 | F20: ='BALANCE SHEET'!C20 | G20: ='YTD BS'!G20 | H20: ='YTD BS'!H20 | I20: ='YTD BS'!I20 | J20: ='BALANCE SHEET'!D20 | K20: ='YTD BS'!K20 | L20: ='YTD BS'!L20 | M20: ='YTD BS'!M20 | N20: ='BALANCE SHEET'!E20
A21: Accrued Expenses | B21: ='BALANCE SHEET'!B21 | C21: ='YTD BS'!C21 | D21: ='YTD BS'!D21 | E21: ='YTD BS'!E21 | F21: ='BALANCE SHEET'!C21 | G21: ='YTD BS'!G21 | H21: ='YTD BS'!H21 | I21: ='YTD BS'!I21 | J21: ='BALANCE SHEET'!D21 | K21: ='YTD BS'!K21 | L21: ='YTD BS'!L21 | M21: ='YTD BS'!M21 | N21: ='BALANCE SHEET'!E21
A22: Income Taxes Payable | B22: ='BALANCE SHEET'!B22 | C22: ='YTD BS'!C22 | D22: ='YTD BS'!D22 | E22: ='YTD BS'!E22 | F22: ='BALANCE SHEET'!C22 | G22: ='YTD BS'!G22 | H22: ='YTD BS'!H22 | I22: ='YTD BS'!I22 | J22: ='BALANCE SHEET'!D22 | K22: ='YTD BS'!K22 | L22: ='YTD BS'!L22 | M22: ='YTD BS'!M22 | N22: ='BALANCE SHEET'!E22
A23: Accrued Distributor Termination Fees | B23: ='BALANCE SHEET'!B23 | C23: ='YTD BS'!C23 | D23: ='YTD BS'!D23 | E23: ='YTD BS'!E23 | F23: ='BALANCE SHEET'!C23 | G23: ='YTD BS'!G23 | H23: ='YTD BS'!H23 | I23: ='YTD BS'!I23 | J23: ='BALANCE SHEET'!D23 | K23: ='YTD BS'!K23 | L23: ='YTD BS'!L23 | M23: ='YTD BS'!M23 | N23: ='BALANCE SHEET'!E23
A24: Accrued Promotional Allowance | B24: ='BALANCE SHEET'!B24 | C24: ='YTD BS'!C24 | D24: ='YTD BS'!D24 | E24: ='YTD BS'!E24 | F24: ='BALANCE SHEET'!C24 | G24: ='YTD BS'!G24 | H24: ='YTD BS'!H24 | I24: ='YTD BS'!I24 | J24: ='BALANCE SHEET'!D24 | K24: ='YTD BS'!K24 | L24: ='YTD BS'!L24 | M24: ='YTD BS'!M24 | N24: ='BALANCE SHEET'!E24
A25: Lease Liability - Operating - Current | B25: ='BALANCE SHEET'!B25 | C25: ='YTD BS'!C25 | D25: ='YTD BS'!D25 | E25: ='YTD BS'!E25 | F25: ='BALANCE SHEET'!C25 | G25: ='YTD BS'!G25 | H25: ='YTD BS'!H25 | I25: ='YTD BS'!I25 | J25: ='BALANCE SHEET'!D25 | K25: ='YTD BS'!K25 | L25: ='YTD BS'!L25 | M25: ='YTD BS'!M25 | N25: ='BALANCE SHEET'!E25
A26: Lease Liability - Finance - Current | B26: ='BALANCE SHEET'!B26 | C26: ='YTD BS'!C26 | D26: ='YTD BS'!D26 | E26: ='YTD BS'!E26 | F26: ='BALANCE SHEET'!C26 | G26: ='YTD BS'!G26 | H26: ='YTD BS'!H26 | I26: ='YTD BS'!I26 | J26: ='BALANCE SHEET'!D26 | K26: ='YTD BS'!K26 | L26: ='YTD BS'!L26 | M26: ='YTD BS'!M26 | N26: ='BALANCE SHEET'!E26
A27: Contingent Consideration - Current | B27: ='BALANCE SHEET'!B27 | C27: ='YTD BS'!C27 | D27: ='YTD BS'!D27 | E27: ='YTD BS'!E27 | F27: ='BALANCE SHEET'!C27 | G27: ='YTD BS'!G27 | H27: ='YTD BS'!H27 | I27: ='YTD BS'!I27 | J27: ='BALANCE SHEET'!D27 | K27: ='YTD BS'!K27 | L27: ='YTD BS'!L27 | M27: ='YTD BS'!M27 | N27: ='BALANCE SHEET'!E27
A28: Deferred Revenue - Current | B28: ='BALANCE SHEET'!B28 | C28: ='YTD BS'!C28 | D28: ='YTD BS'!D28 | E28: ='YTD BS'!E28 | F28: ='BALANCE SHEET'!C28 | G28: ='YTD BS'!G28 | H28: ='YTD BS'!H28 | I28: ='YTD BS'!I28 | J28: ='BALANCE SHEET'!D28 | K28: ='YTD BS'!K28 | L28: ='YTD BS'!L28 | M28: ='YTD BS'!M28 | N28: ='BALANCE SHEET'!E28
A29: Other Current Liabilities | B29: ='BALANCE SHEET'!B29 | C29: ='YTD BS'!C29 | D29: ='YTD BS'!D29 | E29: ='YTD BS'!E29 | F29: ='BALANCE SHEET'!C29 | G29: ='YTD BS'!G29 | H29: ='YTD BS'!H29 | I29: ='YTD BS'!I29 | J29: ='BALANCE SHEET'!D29 | K29: ='YTD BS'!K29 | L29: ='YTD BS'!L29 | M29: ='YTD BS'!M29 | N29: ='BALANCE SHEET'!E29
... A45: Total Liabilities, Mezzanine & Stockholders' Equity | B45: ='BALANCE SHEET'!B45 | C45: ='YTD BS'!C45 | D45: ='YTD BS'!D45 | E45: ='YTD BS'!E45 | F45: ='BALANCE SHEET'!C45 | G45: ='YTD BS'!G45 | H45: ='YTD BS'!H45 | I45: ='YTD BS'!I45 | J45: ='BALANCE SHEET'!D45 | K45: ='YTD BS'!K45 | L45: ='YTD BS'!L45 | M45: ='YTD BS'!M45 | N45: ='BALANCE SHEET'!E45

Sheet QTR CF
B1: Q1 FY2022 | C1: Q2 FY2022 | D1: Q3 FY2022 | E1: Q4 FY2022 | F1: Q1 FY2023 | G1: Q2 FY2023 | H1: Q3 FY2023 | I1: Q4 FY2023 | J1: Q1 FY2024 | K1: Q2 FY2024 | L1: Q3 FY2024 | M1: Q4 FY2024 | N1: Q1 FY2025 | O1: Q2 FY2025 | P1: Q3 FY2025 | Q1: Q4 FY2025
A2: Net Income (Loss) | B2: ='YTD CF'!B2 | C2: ='YTD CF'!C2-'YTD CF'!B2 | D2: ='YTD CF'!D2-'YTD CF'!C2 | E2: ='CASH FLOW'!C2-'YTD CF'!D2 | F2: ='YTD CF'!E2 | G2: ='YTD CF'!F2-'YTD CF'!E2 | H2: ='YTD CF'!G2-'YTD CF'!F2 | I2: ='CASH FLOW'!D2-'YTD CF'!G2 | J2: ='YTD CF'!H2 | K2: ='YTD CF'!I2-'YTD CF'!H2 | L2: ='YTD CF'!J2-'YTD CF'!I2 | M2: ='CASH FLOW'!E2-'YTD CF'!J2 | N2: ='YTD CF'!K2 | O2: ='YTD CF'!L2-'YTD CF'!K2 | P2: ='YTD CF'!M2-'YTD CF'!L2 | Q2: ='CASH FLOW'!F2-'YTD CF'!M2
A3: Depreciation | B3: ='YTD CF'!B3 | C3: ='YTD CF'!C3-'YTD CF'!B3 | D3: ='YTD CF'!D3-'YTD CF'!C3 | F3: ='YTD CF'!E3 | G3: ='YTD CF'!F3-'YTD CF'!E3 | H3: ='YTD CF'!G3-'YTD CF'!F3 | J3: ='YTD CF'!H3 | K3: ='YTD CF'!I3-'YTD CF'!H3 | L3: ='YTD CF'!J3-'YTD CF'!I3 | N3: ='YTD CF'!K3 | O3: ='YTD CF'!L3-'YTD CF'!K3 | P3: ='YTD CF'!M3-'YTD CF'!L3
A4: Amortization | B4: ='YTD CF'!B4 | C4: ='YTD CF'!C4-'YTD CF'!B4 | D4: ='YTD CF'!D4-'YTD CF'!C4 | F4: ='YTD CF'!E4 | G4: ='YTD CF'!F4-'YTD CF'!E4 | H4: ='YTD CF'!G4-'YTD CF'!F4 | J4: ='YTD CF'!H4 | K4: ='YTD CF'!I4-'YTD CF'!H4 | L4: ='YTD CF'!J4-'YTD CF'!I4 | N4: ='YTD CF'!K4 | O4: ='YTD CF'!L4-'YTD CF'!K4 | P4: ='YTD CF'!M4-'YTD CF'!L4
A5: Impairment of Intangibles | B5: ='YTD CF'!B5 | C5: ='YTD CF'!C5-'YTD CF'!B5 | D5: ='YTD CF'!D5-'YTD CF'!C5 | E5: ='CASH FLOW'!C4-'YTD CF'!D5 | F5: ='YTD CF'!E5 | G5: ='YTD CF'!F5-'YTD CF'!E5 | H5: ='YTD CF'!G5-'YTD CF'!F5 | I5: ='CASH FLOW'!D4-'YTD CF'!G5 | J5: ='YTD CF'!H5 | K5: ='YTD CF'!I5-'YTD CF'!H5 | L5: ='YTD CF'!J5-'YTD CF'!I5 | M5: ='CASH FLOW'!E4-'YTD CF'!J5 | N5: ='YTD CF'!K5 | O5: ='YTD CF'!L5-'YTD CF'!K5 | P5: ='YTD CF'!M5-'YTD CF'!L5 | Q5: ='CASH FLOW'!F4-'YTD CF'!M5
A6: Depreciation & Amortization | B6: ='YTD CF'!B6 | C6: ='YTD CF'!C6-'YTD CF'!B6 | D6: ='YTD CF'!D6-'YTD CF'!C6 | E6: ='CASH FLOW'!C3-'YTD CF'!D6 | F6: ='YTD CF'!E6 | G6: ='YTD CF'!F6-'YTD CF'!E6 | H6: ='YTD CF'!G6-'YTD CF'!F6 | I6: ='CASH FLOW'!D3-'YTD CF'!G6 | J6: ='YTD CF'!H6 | K6: ='YTD CF'!I6-'YTD CF'!H6 | L6: ='YTD CF'!J6-'YTD CF'!I6 | M6: ='CASH FLOW'!E3-'YTD CF'!J6 | N6: ='YTD CF'!K6 | O6: ='YTD CF'!L6-'YTD CF'!K6 | P6: ='YTD CF'!M6-'YTD CF'!L6 | Q6: ='CASH FLOW'!F3-'YTD CF'!M6
A7: Allowance for Credit Losses | B7: ='YTD CF'!B7 | C7: ='YTD CF'!C7-'YTD CF'!B7 | D7: ='YTD CF'!D7-'YTD CF'!C7 | E7: ='CASH FLOW'!C5-'YTD CF'!D7 | F7: ='YTD CF'!E7 | G7: ='YTD CF'!F7-'YTD CF'!E7 | H7: ='YTD CF'!G7-'YTD CF'!F7 | I7: ='CASH FLOW'!D5-'YTD CF'!G7 | J7: ='YTD CF'!H7 | K7: ='YTD CF'!I7-'YTD CF'!H7 | L7: ='YTD CF'!J7-'YTD CF'!I7 | M7: ='CASH FLOW'!E5-'YTD CF'!J7 | N7: ='YTD CF'!K7 | O7: ='YTD CF'!L7-'YTD CF'!K7 | P7: ='YTD CF'!M7-'YTD CF'!L7 | Q7: ='CASH FLOW'!F5-'YTD CF'!M7
A8: Amortization of Deferred Other Costs | B8: ='YTD CF'!B8 | C8: ='YTD CF'!C8-'YTD CF'!B8 | D8: ='YTD CF'!D8-'YTD CF'!C8 | E8: ='CASH FLOW'!C6-'YTD CF'!D8 | F8: ='YTD CF'!E8 | G8: ='YTD CF'!F8-'YTD CF'!E8 | H8: ='YTD CF'!G8-'YTD CF'!F8 | I8: ='CASH FLOW'!D6-'YTD CF'!G8 | J8: ='YTD CF'!H8 | K8: ='YTD CF'!I8-'YTD CF'!H8 | L8: ='YTD CF'!J8-'YTD CF'!I8 | M8: ='CASH FLOW'!E6-'YTD CF'!J8 | N8: ='YTD CF'!K8 | O8: ='YTD CF'!L8-'YTD CF'!K8 | P8: ='YTD CF'!M8-'YTD CF'!L8 | Q8: ='CASH FLOW'!F6-'YTD CF'!M8
A9: Inventory Write-Down | B9: ='YTD CF'!B9 | C9: ='YTD CF'!C9-'YTD CF'!B9 | D9: ='YTD CF'!D9-'YTD CF'!C9 | E9: ='CASH FLOW'!C7-'YTD CF'!D9 | F9: ='YTD CF'!E9 | G9: ='YTD CF'!F9-'YTD CF'!E9 | H9: ='YTD CF'!G9-'YTD CF'!F9 | I9: ='CASH FLOW'!D7-'YTD CF'!G9 | J9: ='YTD CF'!H9 | K9: ='YTD CF'!I9-'YTD CF'!H9 | L9: ='YTD CF'!J9-'YTD CF'!I9 | M9: ='CASH FLOW'!E7-'YTD CF'!J9 | N9: ='YTD CF'!K9 | O9: ='YTD CF'!L9-'YTD CF'!K9 | P9: ='YTD CF'!M9-'YTD CF'!L9 | Q9: ='CASH FLOW'!F7-'YTD CF'!M9
A10: Gain (Loss) on Disposal of PP&E | B10: ='YTD CF'!B10 | C10: ='YTD CF'!C10-'YTD CF'!B10 | D10: ='YTD CF'!D10-'YTD CF'!C10 | E10: ='CASH FLOW'!C8-'YTD CF'!D10 | F10: ='YTD CF'!E10 | G10: ='YTD CF'!F10-'YTD CF'!E10 | H10: ='YTD CF'!G10-'YTD CF'!F10 | I10: ='CASH FLOW'!D8-'YTD CF'!G10 | J10: ='YTD CF'!H10 | K10: ='YTD CF'!I10-'YTD CF'!H10 | L10: ='YTD CF'!J10-'YTD CF'!I10 | M10: ='CASH FLOW'!E8-'YTD CF'!J10 | N10: ='YTD CF'!K10 | O10: ='YTD CF'!L10-'YTD CF'!K10 | P10: ='YTD CF'!M10-'YTD CF'!L10 | Q10: ='CASH FLOW'!F8-'YTD CF'!M10
A11: Stock-Based Compensation | B11: ='YTD CF'!B11 | C11: ='YTD CF'!C11-'YTD CF'!B11 | D11: ='YTD CF'!D11-'YTD CF'!C11 | E11: ='CASH FLOW'!C9-'YTD CF'!D11 | F11: ='YTD CF'!E11 | G11: ='YTD CF'!F11-'YTD CF'!E11 | H11: ='YTD CF'!G11-'YTD CF'!F11 | I11: ='CASH FLOW'!D9-'YTD CF'!G11 | J11: ='YTD CF'!H11 | K11: ='YTD CF'!I11-'YTD CF'!H11 | L11: ='YTD CF'!J11-'YTD CF'!I11 | M11: ='CASH FLOW'!E9-'YTD CF'!J11 | N11: ='YTD CF'!K11 | O11: ='YTD CF'!L11-'YTD CF'!K11 | P11: ='YTD CF'!M11-'YTD CF'!L11 | Q11: ='CASH FLOW'!F9-'YTD CF'!M11
A12: (Benefit) Provision for Deferred Income Taxes | B12: ='YTD CF'!B12 | C12: ='YTD CF'!C12-'YTD CF'!B12 | D12: ='YTD CF'!D12-'YTD CF'!C12 | E12: ='CASH FLOW'!C10-'YTD CF'!D12 | F12: ='YTD CF'!E12 | G12: ='YTD CF'!F12-'YTD CF'!E12 | H12: ='YTD CF'!G12-'YTD CF'!F12 | I12: ='CASH FLOW'!D10-'YTD CF'!G12 | J12: ='YTD CF'!H12 | K12: ='YTD CF'!I12-'YTD CF'!H12 | L12: ='YTD CF'!J12-'YTD CF'!I12 | M12: ='CASH FLOW'!E10-'YTD CF'!J12 | N12: ='YTD CF'!K12 | O12: ='YTD CF'!L12-'YTD CF'!K12 | P12: ='YTD CF'!M12-'YTD CF'!L12 | Q12: ='CASH FLOW'!F10-'YTD CF'!M12
A13: Foreign Currency Gain (Loss) | B13: ='YTD CF'!B13 | C13: ='YTD CF'!C13-'YTD CF'!B13 | D13: ='YTD CF'!D13-'YTD CF'!C13 | E13: ='CASH FLOW'!C11-'YTD CF'!D13 | F13: ='YTD CF'!E13 | G13: ='YTD CF'!F13-'YTD CF'!E13 | H13: ='YTD CF'!G13-'YTD CF'!F13 | I13: ='CASH FLOW'!D11-'YTD CF'!G13 | J13: ='YTD CF'!H13 | K13: ='YTD CF'!I13-'YTD CF'!H13 | L13: ='YTD CF'!J13-'YTD CF'!I13 | M13: ='CASH FLOW'!E11-'YTD CF'!J13 | N13: ='YTD CF'!K13 | O13: ='YTD CF'!L13-'YTD CF'!K13 | P13: ='YTD CF'!M13-'YTD CF'!L13 | Q13: ='CASH FLOW'!F11-'YTD CF'!M13
A14: Gain (Loss) on Lease Cancellations | B14: ='YTD CF'!B14 | C14: ='YTD CF'!C14-'YTD CF'!B14 | D14: ='YTD CF'!D14-'YTD CF'!C14 | E14: ='CASH FLOW'!C12-'YTD CF'!D14 | F14: ='YTD CF'!E14 | G14: ='YTD CF'!F14-'YTD CF'!E14 | H14: ='YTD CF'!G14-'YTD CF'!F14 | I14: ='CASH FLOW'!D12-'YTD CF'!G14 | J14: ='YTD CF'!H14 | K14: ='YTD CF'!I14-'YTD CF'!H14 | L14: ='YTD CF'!J14-'YTD CF'!I14 | M14: ='CASH FLOW'!E12-'YTD CF'!J14 | N14: ='YTD CF'!K14 | O14: ='YTD CF'!L14-'YTD CF'!K14 | P14: ='YTD CF'!M14-'YTD CF'!L14 | Q14: ='CASH FLOW'!F12-'YTD CF'!M14
A15: Change in Fair Value of Contingent Consideration | B15: ='YTD CF'!B15 | C15: ='YTD CF'!C15-'YTD CF'!B15 | D15: ='YTD CF'!D15-'YTD CF'!C15 | E15: ='CASH FLOW'!C13-'YTD CF'!D15 | F15: ='YTD CF'!E15 | G15: ='YTD CF'!F15-'YTD CF'!E15 | H15: ='YTD CF'!G15-'YTD CF'!F15 | I15: ='CASH FLOW'!D13-'YTD CF'!G15 | J15: ='YTD CF'!H15 | K15: ='YTD CF'!I15-'YTD CF'!H15 | L15: ='YTD CF'!J15-'YTD CF'!I15 | M15: ='CASH FLOW'!E13-'YTD CF'!J15 | N15: ='YTD CF'!K15 | O15: ='YTD CF'!L15-'YTD CF'!K15 | P15: ='YTD CF'!M15-'YTD CF'!L15 | Q15: ='CASH FLOW'!F13-'YTD CF'!M15
A16: Gain (Loss) on Extinguishment of Debt | B16: ='YTD CF'!B16 | C16: ='YTD CF'!C16-'YTD CF'!B16 | D16: ='YTD CF'!D16-'YTD CF'!C16 | E16: ='CASH FLOW'!C14-'YTD CF'!D16 | F16: ='YTD CF'!E16 | G16: ='YTD CF'!F16-'YTD CF'!E16 | H16: ='YTD CF'!G16-'YTD CF'!F16 | I16: ='CASH FLOW'!D14-'YTD CF'!G16 | J16: ='YTD CF'!H16 | K16: ='YTD CF'!I16-'YTD CF'!H16 | L16: ='YTD CF'!J16-'YTD CF'!I16 | M16: ='CASH FLOW'!E14-'YTD CF'!J16 | N16: ='YTD CF'!K16 | O16: ='YTD CF'!L16-'YTD CF'!K16 | P16: ='YTD CF'!M16-'YTD CF'!L16 | Q16: ='CASH FLOW'!F14-'YTD CF'!M16
A17: Other Operating Items | B17: ='YTD CF'!B17 | C17: ='YTD CF'!C17-'YTD CF'!B17 | D17: ='YTD CF'!D17-'YTD CF'!C17 | E17: ='CASH FLOW'!C15-'YTD CF'!D17 | F17: ='YTD CF'!E17 | G17: ='YTD CF'!F17-'YTD CF'!E17 | H17: ='YTD CF'!G17-'YTD CF'!F17 | I17: ='CASH FLOW'!D15-'YTD CF'!G17 | J17: ='YTD CF'!H17 | K17: ='YTD CF'!I17-'YTD CF'!H17 | L17: ='YTD CF'!J17-'YTD CF'!I17 | M17: ='CASH FLOW'!E15-'YTD CF'!J17 | N17: ='YTD CF'!K17 | O17: ='YTD CF'!L17-'YTD CF'!K17 | P17: ='YTD CF'!M17-'YTD CF'!L17 | Q17: ='CASH FLOW'!F15-'YTD CF'!M17
A18: Accounts Receivable | B18: ='YTD CF'!B18 | C18: ='YTD CF'!C18-'YTD CF'!B18 | D18: ='YTD CF'!D18-'YTD CF'!C18 | E18: ='CASH FLOW'!C16-'YTD CF'!D18 | F18: ='YTD CF'!E18 | G18: ='YTD CF'!F18-'YTD CF'!E18 | H18: ='YTD CF'!G18-'YTD CF'!F18 | I18: ='CASH FLOW'!D16-'YTD CF'!G18 | J18: ='YTD CF'!H18 | K18: ='YTD CF'!I18-'YTD CF'!H18 | L18: ='YTD CF'!J18-'YTD CF'!I18 | M18: ='CASH FLOW'!E16-'YTD CF'!J18 | N18: ='YTD CF'!K18 | O18: ='YTD CF'!L18-'YTD CF'!K18 | P18: ='YTD CF'!M18-'YTD CF'!L18 | Q18: ='CASH FLOW'!F16-'YTD CF'!M18
... A21: Prepaid Expenses | B21: ='YTD CF'!B21 | C21: ='YTD CF'!C21-'YTD CF'!B21 | D21: ='YTD CF'!D21-'YTD CF'!C21 | E21: ='CASH FLOW'!C19-'YTD CF'!D21 | F21: ='YTD CF'!E21 | G21: ='YTD CF'!F21-'YTD CF'!E21 | H21: ='YTD CF'!G21-'YTD CF'!F21 | I21: ='CASH FLOW'!D19-'YTD CF'!G21 | J21: ='YTD CF'!H21 | K21: ='YTD CF'!I21-'YTD CF'!H21 | L21: ='YTD CF'!J21-'YTD CF'!I21 | M21: ='CASH FLOW'!E19-'YTD CF'!J21 | N21: ='YTD CF'!K21 | O21: ='YTD CF'!L21-'YTD CF'!K21 | P21: ='YTD CF'!M21-'YTD CF'!L21 | Q21: ='CASH FLOW'!F19-'YTD CF'!M21
A22: Change in A/P and Accrued (legacy) | B22: ='YTD CF'!B22 | C22: ='YTD CF'!C22-'YTD CF'!B22 | D22: ='YTD CF'!D22-'YTD CF'!C22 | F22: ='YTD CF'!E22 | G22: ='YTD CF'!F22-'YTD CF'!E22 | H22: ='YTD CF'!G22-'YTD CF'!F22 | J22: ='YTD CF'!H22 | K22: ='YTD CF'!I22-'YTD CF'!H22 | L22: ='YTD CF'!J22-'YTD CF'!I22 | N22: ='YTD CF'!K22 | O22: ='YTD CF'!L22-'YTD CF'!K22 | P22: ='YTD CF'!M22-'YTD CF'!L22
A23: Other Non-Current Assets | B23: ='YTD CF'!B23 | C23: ='YTD CF'!C23-'YTD CF'!B23 | D23: ='YTD CF'!D23-'YTD CF'!C23 | E23: ='CASH FLOW'!C20-'YTD CF'!D23 | F23: ='YTD CF'!E23 | G23: ='YTD CF'!F23-'YTD CF'!E23 | H23: ='YTD CF'!G23-'YTD CF'!F23 | I23: ='CASH FLOW'!D20-'YTD CF'!G23 | J23: ='YTD CF'!H23 | K23: ='YTD CF'!I23-'YTD CF'!H23 | L23: ='YTD CF'!J23-'YTD CF'!I23 | M23: ='CASH FLOW'!E20-'YTD CF'!J23 | N23: ='YTD CF'!K23 | O23: ='YTD CF'!L23-'YTD CF'!K23 | P23: ='YTD CF'!M23-'YTD CF'!L23 | Q23: ='CASH FLOW'!F20-'YTD CF'!M23
A24: Accounts Payable | B24: ='YTD CF'!B24 | C24: ='YTD CF'!C24-'YTD CF'!B24 | D24: ='YTD CF'!D24-'YTD CF'!C24 | E24: ='CASH FLOW'!C21-'YTD CF'!D24 | F24: ='YTD CF'!E24 | G24: ='YTD CF'!F24-'YTD CF'!E24 | H24: ='YTD CF'!G24-'YTD CF'!F24 | I24: ='CASH FLOW'!D21-'YTD CF'!G24 | J24: ='YTD CF'!H24 | K24: ='YTD CF'!I24-'YTD CF'!H24 | L24: ='YTD CF'!J24-'YTD CF'!I24 | M24: ='CASH FLOW'!E21-'YTD CF'!J24 | N24: ='YTD CF'!K24 | O24: ='YTD CF'!L24-'YTD CF'!K24 | P24: ='YTD CF'!M24-'YTD CF'!L24 | Q24: ='CASH FLOW'!F21-'YTD CF'!M24
A25: Accrued Expenses | B25: ='YTD CF'!B25 | C25: ='YTD CF'!C25-'YTD CF'!B25 | D25: ='YTD CF'!D25-'YTD CF'!C25 | E25: ='CASH FLOW'!C22-'YTD CF'!D25 | F25: ='YTD CF'!E25 | G25: ='YTD CF'!F25-'YTD CF'!E25 | H25: ='YTD CF'!G25-'YTD CF'!F25 | I25: ='CASH FLOW'!D22-'YTD CF'!G25 | J25: ='YTD CF'!H25 | K25: ='YTD CF'!I25-'YTD CF'!H25 | L25: ='YTD CF'!J25-'YTD CF'!I25 | M25: ='CASH FLOW'!E22-'YTD CF'!J25 | N25: ='YTD CF'!K25 | O25: ='YTD CF'!L25-'YTD CF'!K25 | P25: ='YTD CF'!M25-'YTD CF'!L25 | Q25: ='CASH FLOW'!F22-'YTD CF'!M25
A26: Other Current Liabilities | B26: ='YTD CF'!B26 | C26: ='YTD CF'!C26-'YTD CF'!B26 | D26: ='YTD CF'!D26-'YTD CF'!C26 | E26: ='CASH FLOW'!C23-'YTD CF'!D26 | F26: ='YTD CF'!E26 | G26: ='YTD CF'!F26-'YTD CF'!E26 | H26: ='YTD CF'!G26-'YTD CF'!F26 | I26: ='CASH FLOW'!D23-'YTD CF'!G26 | J26: ='YTD CF'!H26 | K26: ='YTD CF'!I26-'YTD CF'!H26 | L26: ='YTD CF'!J26-'YTD CF'!I26 | M26: ='CASH FLOW'!E23-'YTD CF'!J26 | N26: ='YTD CF'!K26 | O26: ='YTD CF'!L26-'YTD CF'!K26 | P26: ='YTD CF'!M26-'YTD CF'!L26 | Q26: ='CASH FLOW'!F23-'YTD CF'!M26
A27: Accrued Promotional Allowance | B27: ='YTD CF'!B27 | C27: ='YTD CF'!C27-'YTD CF'!B27 | D27: ='YTD CF'!D27-'YTD CF'!C27 | E27: ='CASH FLOW'!C24-'YTD CF'!D27 | F27: ='YTD CF'!E27 | G27: ='YTD CF'!F27-'YTD CF'!E27 | H27: ='YTD CF'!G27-'YTD CF'!F27 | I27: ='CASH FLOW'!D24-'YTD CF'!G27 | J27: ='YTD CF'!H27 | K27: ='YTD CF'!I27-'YTD CF'!H27 | L27: ='YTD CF'!J27-'YTD CF'!I27 | M27: ='CASH FLOW'!E24-'YTD CF'!J27 | N27: ='YTD CF'!K27 | O27: ='YTD CF'!L27-'YTD CF'!K27 | P27: ='YTD CF'!M27-'YTD CF'!L27 | Q27: ='CASH FLOW'!F24-'YTD CF'!M27
A28: Accrued Distributor Termination | B28: ='YTD CF'!B28 | C28: ='YTD CF'!C28-'YTD CF'!B28 | D28: ='YTD CF'!D28-'YTD CF'!C28 | E28: ='CASH FLOW'!C25-'YTD CF'!D28 | F28: ='YTD CF'!E28 | G28: ='YTD CF'!F28-'YTD CF'!E28 | H28: ='YTD CF'!G28-'YTD CF'!F28 | I28: ='CASH FLOW'!D25-'YTD CF'!G28 | J28: ='YTD CF'!H28 | K28: ='YTD CF'!I28-'YTD CF'!H28 | L28: ='YTD CF'!J28-'YTD CF'!I28 | M28: ='CASH FLOW'!E25-'YTD CF'!J28 | N28: ='YTD CF'!K28 | O28: ='YTD CF'!L28-'YTD CF'!K28 | P28: ='YTD CF'!M28-'YTD CF'!L28 | Q28: ='CASH FLOW'!F25-'YTD CF'!M28
A29: ROU & Lease Liability, Net | B29: ='YTD CF'!B29 | C29: ='YTD CF'!C29-'YTD CF'!B29 | D29: ='YTD CF'!D29-'YTD CF'!C29 | E29: ='CASH FLOW'!C26-'YTD CF'!D29 | F29: ='YTD CF'!E29 | G29: ='YTD CF'!F29-'YTD CF'!E29 | H29: ='YTD CF'!G29-'YTD CF'!F29 | I29: ='CASH FLOW'!D26-'YTD CF'!G29 | J29: ='YTD CF'!H29 | K29: ='YTD CF'!I29-'YTD CF'!H29 | L29: ='YTD CF'!J29-'YTD CF'!I29 | M29: ='CASH FLOW'!E26-'YTD CF'!J29 | N29: ='YTD CF'!K29 | O29: ='YTD CF'!L29-'YTD CF'!K29 | P29: ='YTD CF'!M29-'YTD CF'!L29 | Q29: ='CASH FLOW'!F26-'YTD CF'!M29
A30: Deferred Revenue | B30: ='YTD CF'!B30 | C30: ='YTD CF'!C30-'YTD CF'!B30 | D30: ='YTD CF'!D30-'YTD CF'!C30 | E30: ='CASH FLOW'!C27-'YTD CF'!D30 | F30: ='YTD CF'!E30 | G30: ='YTD CF'!F30-'YTD CF'!E30 | H30: ='YTD CF'!G30-'YTD CF'!F30 | I30: ='CASH FLOW'!D27-'YTD CF'!G30 | J30: ='YTD CF'!H30 | K30: ='YTD CF'!I30-'YTD CF'!H30 | L30: ='YTD CF'!J30-'YTD CF'!I30 | M30: ='CASH FLOW'!E27-'YTD CF'!J30 | N30: ='YTD CF'!K30 | O30: ='YTD CF'!L30-'YTD CF'!K30 | P30: ='YTD CF'!M30-'YTD CF'!L30 | Q30: ='CASH FLOW'!F27-'YTD CF'!M30
A31: Net Change in Other Working Capital | B31: ='YTD CF'!B31 | C31: ='YTD CF'!C31-'YTD CF'!B31 | D31: ='YTD CF'!D31-'YTD CF'!C31 | E31: ='CASH FLOW'!C28-'YTD CF'!D31 | F31: ='YTD CF'!E31 | G31: ='YTD CF'!F31-'YTD CF'!E31 | H31: ='YTD CF'!G31-'YTD CF'!F31 | I31: ='CASH FLOW'!D28-'YTD CF'!G31 | J31: ='YTD CF'!H31 | K31: ='YTD CF'!I31-'YTD CF'!H31 | L31: ='YTD CF'!J31-'YTD CF'!I31 | M31: ='CASH FLOW'!E28-'YTD CF'!J31 | N31: ='YTD CF'!K31 | O31: ='YTD CF'!L31-'YTD CF'!K31 | P31: ='YTD CF'!M31-'YTD CF'!L31 | Q31: ='CASH FLOW'!F28-'YTD CF'!M31
A32: Cash Flow from Operations | B32: ='YTD CF'!B32 | C32: ='YTD CF'!C32-'YTD CF'!B32 | D32: ='YTD CF'!D32-'YTD CF'!C32 | E32: ='CASH FLOW'!C29-'YTD CF'!D32 | F32: ='YTD CF'!E32 | G32: ='YTD CF'!F32-'YTD CF'!E32 | H32: ='YTD CF'!G32-'YTD CF'!F32 | I32: ='CASH FLOW'!D29-'YTD CF'!G32 | J32: ='YTD CF'!H32 | K32: ='YTD CF'!I32-'YTD CF'!H32 | L32: ='YTD CF'!J32-'YTD CF'!I32 | M32: ='CASH FLOW'!E29-'YTD CF'!J32 | N32: ='YTD CF'!K32 | O32: ='YTD CF'!L32-'YTD CF'!K32 | P32: ='YTD CF'!M32-'YTD CF'!L32 | Q32: ='CASH FLOW'!F29-'YTD CF'!M32
A33: Collections from Note Receivable | B33: ='YTD CF'!B33 | C33: ='YTD CF'!C33-'YTD CF'!B33 | D33: ='YTD CF'!D33-'YTD CF'!C33 | E33: ='CASH FLOW'!C30-'YTD CF'!D33 | F33: ='YTD CF'!E33 | G33: ='YTD CF'!F33-'YTD CF'!E33 | H33: ='YTD CF'!G33-'YTD CF'!F33 | I33: ='CASH FLOW'!D30-'YTD CF'!G33 | J33: ='YTD CF'!H33 | K33: ='YTD CF'!I33-'YTD CF'!H33 | L33: ='YTD CF'!J33-'YTD CF'!I33 | M33: ='CASH FLOW'!E30-'YTD CF'!J33 | N33: ='YTD CF'!K33 | O33: ='YTD CF'!L33-'YTD CF'!K33 | P33: ='YTD CF'!M33-'YTD CF'!L33 | Q33: ='CASH FLOW'!F30-'YTD CF'!M33
A34: Purchase of PP&E | B34: ='YTD CF'!B34 | C34: ='YTD CF'!C34-'YTD CF'!B34 | D34: ='YTD CF'!D34-'YTD CF'!C34 | E34: ='CASH FLOW'!C31-'YTD CF'!D34 | F34: ='YTD CF'!E34 | G34: ='YTD CF'!F34-'YTD CF'!E34 | H34: ='YTD CF'!G34-'YTD CF'!F34 | I34: ='CASH FLOW'!D31-'YTD CF'!G34 | J34: ='YTD CF'!H34 | K34: ='YTD CF'!I34-'YTD CF'!H34 | L34: ='YTD CF'!J34-'YTD CF'!I34 | M34: ='CASH FLOW'!E31-'YTD CF'!J34 | N34: ='YTD CF'!K34 | O34: ='YTD CF'!L34-'YTD CF'!K34 | P34: ='YTD CF'!M34-'YTD CF'!L34 | Q34: ='CASH FLOW'!F31-'YTD CF'!M34
... A37: Acquisitions, Net of Cash Acquired | B37: ='YTD CF'!B37 | C37: ='YTD CF'!C37-'YTD CF'!B37 | D37: ='YTD CF'!D37-'YTD CF'!C37 | E37: ='CASH FLOW'!C34-'YTD CF'!D37 | F37: ='YTD CF'!E37 | G37: ='YTD CF'!F37-'YTD CF'!E37 | H37: ='YTD CF'!G37-'YTD CF'!F37 | I37: ='CASH FLOW'!D34-'YTD CF'!G37 | J37: ='YTD CF'!H37 | K37: ='YTD CF'!I37-'YTD CF'!H37 | L37: ='YTD CF'!J37-'YTD CF'!I37 | M37: ='CASH FLOW'!E34-'YTD CF'!J37 | N37: ='YTD CF'!K37 | O37: ='YTD CF'!L37-'YTD CF'!K37 | P37: ='YTD CF'!M37-'YTD CF'!L37 | Q37: ='CASH FLOW'!F34-'YTD CF'!M37
A38: Working Capital Estimate from Pepsi (Rockstar)
A39: Cash Flow from Investing | B39: ='YTD CF'!B39 | C39: ='YTD CF'!C39-'YTD CF'!B39 | D39: ='YTD CF'!D39-'YTD CF'!C39 | E39: ='CASH FLOW'!C36-'YTD CF'!D39 | F39: ='YTD CF'!E39 | G39: ='YTD CF'!F39-'YTD CF'!E39 | H39: ='YTD CF'!G39-'YTD CF'!F39 | I39: ='CASH FLOW'!D36-'YTD CF'!G39 | J39: ='YTD CF'!H39 | K39: ='YTD CF'!I39-'YTD CF'!H39 | L39: ='YTD CF'!J39-'YTD CF'!I39 | M39: ='CASH FLOW'!E36-'YTD CF'!J39 | N39: ='YTD CF'!K39 | O39: ='YTD CF'!L39-'YTD CF'!K39 | P39: ='YTD CF'!M39-'YTD CF'!L39 | Q39: ='CASH FLOW'!F36-'YTD CF'!M39
A40: Finance Lease Payments | B40: ='YTD CF'!B40 | C40: ='YTD CF'!C40-'YTD CF'!B40 | D40: ='YTD CF'!D40-'YTD CF'!C40 | E40: ='CASH FLOW'!C37-'YTD CF'!D40 | F40: ='YTD CF'!E40 | G40: ='YTD CF'!F40-'YTD CF'!E40 | H40: ='YTD CF'!G40-'YTD CF'!F40 | I40: ='CASH FLOW'!D37-'YTD CF'!G40 | J40: ='YTD CF'!H40 | K40: ='YTD CF'!I40-'YTD CF'!H40 | L40: ='YTD CF'!J40-'YTD CF'!I40 | M40: ='CASH FLOW'!E37-'YTD CF'!J40 | N40: ='YTD CF'!K40 | O40: ='YTD CF'!L40-'YTD CF'!K40 | P40: ='YTD CF'!M40-'YTD CF'!L40 | Q40: ='CASH FLOW'!F37-'YTD CF'!M40
