Workbook

Sheet ASSUMPTIONS
A1: Assumption | B1: Value | C1: Note
A2: Days in Quarter | B2: 91 | C2: Used by DSO/DIO/DPO ratios. Approximation; varies 89-92 by quarter.

Sheet ANNL P&L
B1: FY2021 | C1: FY2022 | D1: FY2023 | E1: FY2024 | F1: FY2025 | G1: FY2025E | H1: FY2026E | I1: FY2027E | J1: FY2028E | K1: FY2029E | L1: FY2030E
A2: Net Sales / Revenue | B2: 79474 | C2: 86392 | D2: 91471 | E2: 91854 | F2: 93925 | G2: ='QTR P&L'!N2+'QTR P&L'!O2+'QTR P&L'!P2+'QTR P&L'!Q2 | H2: ='QTR P&L'!R2+'QTR P&L'!S2+'QTR P&L'!T2+'QTR P&L'!U2 | I2: ='QTR P&L'!V2+'QTR P&L'!W2+'QTR P&L'!X2+'QTR P&L'!Y2 | J2: ='QTR P&L'!Z2+'QTR P&L'!AA2+'QTR P&L'!AB2+'QTR P&L'!AC2 | K2: ='QTR P&L'!AD2+'QTR P&L'!AE2+'QTR P&L'!AF2+'QTR P&L'!AG2 | L2: ='QTR P&L'!AH2+'QTR P&L'!AI2+'QTR P&L'!AJ2+'QTR P&L'!AK2
A3: COGS | B3: -37075 | C3: -40576 | D3: -41881 | E3: -41744 | F3: -43066 | G3: ='QTR P&L'!N3+'QTR P&L'!O3+'QTR P&L'!P3+'QTR P&L'!Q3 | H3: ='QTR P&L'!R3+'QTR P&L'!S3+'QTR P&L'!T3+'QTR P&L'!U3 | I3: ='QTR P&L'!V3+'QTR P&L'!W3+'QTR P&L'!X3+'QTR P&L'!Y3 | J3: ='QTR P&L'!Z3+'QTR P&L'!AA3+'QTR P&L'!AB3+'QTR P&L'!AC3 | K3: ='QTR P&L'!AD3+'QTR P&L'!AE3+'QTR P&L'!AF3+'QTR P&L'!AG3 | L3: ='QTR P&L'!AH3+'QTR P&L'!AI3+'QTR P&L'!AJ3+'QTR P&L'!AK3
A4: Gross Profit (Loss) | B4: =B2+B3 | C4: =C2+C3 | D4: =D2+D3 | E4: =E2+E3 | F4: =F2+F3 | G4: =G2+G3 | H4: =H2+H3 | I4: =I2+I3 | ... L4: =L2+L3
A5: SG&A | B5: -31237 | C5: -34459 | D5: -36677 | E5: -37190 | F5: -37368 | G5: ='QTR P&L'!N5+'QTR P&L'!O5+'QTR P&L'!P5+'QTR P&L'!Q5 | H5: ='QTR P&L'!R5+'QTR P&L'!S5+'QTR P&L'!T5+'QTR P&L'!U5 | I5: ='QTR P&L'!V5+'QTR P&L'!W5+'QTR P&L'!X5+'QTR P&L'!Y5 | J5: ='QTR P&L'!Z5+'QTR P&L'!AA5+'QTR P&L'!AB5+'QTR P&L'!AC5 | K5: ='QTR P&L'!AD5+'QTR P&L'!AE5+'QTR P&L'!AF5+'QTR P&L'!AG5 | L5: ='QTR P&L'!AH5+'QTR P&L'!AI5+'QTR P&L'!AJ5+'QTR P&L'!AK5
A6: Gain on Juice Transaction | B6: 0 | C6: -3321 | D6: 0 | E6: 0 | F6: 0 | G6: ='QTR P&L'!N6+'QTR P&L'!O6+'QTR P&L'!P6+'QTR P&L'!Q6 | H6: ='QTR P&L'!R6+'QTR P&L'!S6+'QTR P&L'!T6+'QTR P&L'!U6 | I6: ='QTR P&L'!V6+'QTR P&L'!W6+'QTR P&L'!X6+'QTR P&L'!Y6 | J6: ='QTR P&L'!Z6+'QTR P&L'!AA6+'QTR P&L'!AB6+'QTR P&L'!AC6 | K6: ='QTR P&L'!AD6+'QTR P&L'!AE6+'QTR P&L'!AF6+'QTR P&L'!AG6 | L6: ='QTR P&L'!AH6+'QTR P&L'!AI6+'QTR P&L'!AJ6+'QTR P&L'!AK6
A7: Impairment of Intangibles | B7: 0 | C7: -3166 | D7: -927 | E7: -33 | F7: -1993 | G7: ='QTR P&L'!N7+'QTR P&L'!O7+'QTR P&L'!P7+'QTR P&L'!Q7 | H7: ='QTR P&L'!R7+'QTR P&L'!S7+'QTR P&L'!T7+'QTR P&L'!U7 | I7: ='QTR P&L'!V7+'QTR P&L'!W7+'QTR P&L'!X7+'QTR P&L'!Y7 | J7: ='QTR P&L'!Z7+'QTR P&L'!AA7+'QTR P&L'!AB7+'QTR P&L'!AC7 | K7: ='QTR P&L'!AD7+'QTR P&L'!AE7+'QTR P&L'!AF7+'QTR P&L'!AG7 | L7: ='QTR P&L'!AH7+'QTR P&L'!AI7+'QTR P&L'!AJ7+'QTR P&L'!AK7
A8: Income (Loss) from Operations | B8: =B4+SUM(B5:B7) | C8: =C4+SUM(C5:C7) | D8: =D4+SUM(D5:D7) | E8: =E4+SUM(E5:E7) | F8: =F4+SUM(F5:F7) | G8: =G4+SUM(G5:G7) | H8: =H4+SUM(H5:H7) | I8: =I4+SUM(I5:I7) | ... L8: =L4+SUM(L5:L7)
A9: Other Pension and OPEB Benefits Income (Expense) | B9: 522 | C9: 132 | D9: 250 | E9: -22 | F9: -133 | G9: ='QTR P&L'!N9+'QTR P&L'!O9+'QTR P&L'!P9+'QTR P&L'!Q9 | H9: ='QTR P&L'!R9+'QTR P&L'!S9+'QTR P&L'!T9+'QTR P&L'!U9 | I9: ='QTR P&L'!V9+'QTR P&L'!W9+'QTR P&L'!X9+'QTR P&L'!Y9 | J9: ='QTR P&L'!Z9+'QTR P&L'!AA9+'QTR P&L'!AB9+'QTR P&L'!AC9 | K9: ='QTR P&L'!AD9+'QTR P&L'!AE9+'QTR P&L'!AF9+'QTR P&L'!AG9 | L9: ='QTR P&L'!AH9+'QTR P&L'!AI9+'QTR P&L'!AJ9+'QTR P&L'!AK9
A10: Interest Income (Expense) | B10: -1863 | C10: -939 | D10: -819 | E10: -919 | F10: -1121 | G10: ='QTR P&L'!N10+'QTR P&L'!O10+'QTR P&L'!P10+'QTR P&L'!Q10 | H10: ='QTR P&L'!R10+'QTR P&L'!S10+'QTR P&L'!T10+'QTR P&L'!U10 | I10: ='QTR P&L'!V10+'QTR P&L'!W10+'QTR P&L'!X10+'QTR P&L'!Y10 | J10: ='QTR P&L'!Z10+'QTR P&L'!AA10+'QTR P&L'!AB10+'QTR P&L'!AC10 | K10: ='QTR P&L'!AD10+'QTR P&L'!AE10+'QTR P&L'!AF10+'QTR P&L'!AG10 | L10: ='QTR P&L'!AH10+'QTR P&L'!AI10+'QTR P&L'!AJ10+'QTR P&L'!AK10
A11: Pre-Tax Income (Loss) | B11: =B8+SUM(B9:B10) | C11: =C8+SUM(C9:C10) | D11: =D8+SUM(D9:D10) | E11: =E8+SUM(E9:E10) | F11: =F8+SUM(F9:F10) | G11: =G8+SUM(G9:G10) | H11: =H8+SUM(H9:H10) | I11: =I8+SUM(I9:I10) | ... L11: =L8+SUM(L9:L10)
A12: Income Tax (Expense) Benefit | B12: -2142 | C12: -1727 | D12: -2262 | E12: -2320 | F12: -1949 | G12: ='QTR P&L'!N12+'QTR P&L'!O12+'QTR P&L'!P12+'QTR P&L'!Q12 | H12: ='QTR P&L'!R12+'QTR P&L'!S12+'QTR P&L'!T12+'QTR P&L'!U12 | I12: ='QTR P&L'!V12+'QTR P&L'!W12+'QTR P&L'!X12+'QTR P&L'!Y12 | J12: ='QTR P&L'!Z12+'QTR P&L'!AA12+'QTR P&L'!AB12+'QTR P&L'!AC12 | K12: ='QTR P&L'!AD12+'QTR P&L'!AE12+'QTR P&L'!AF12+'QTR P&L'!AG12 | L12: ='QTR P&L'!AH12+'QTR P&L'!AI12+'QTR P&L'!AJ12+'QTR P&L'!AK12
A13: Net Income (Loss) | B13: =B11+B12 | C13: =C11+C12 | D13: =D11+D12 | E13: =E11+E12 | F13: =F11+F12 | G13: =G11+G12 | H13: =H11+H12 | I13: =I11+I12 | ... L13: =L11+L12
A14: Net Income (Loss) Attributable to Noncontrolling Interest | B14: 61 | C14: 68 | D14: 81 | E14: 48 | F14: 55 | G14: ='QTR P&L'!N14+'QTR P&L'!O14+'QTR P&L'!P14+'QTR P&L'!Q14 | H14: ='QTR P&L'!R14+'QTR P&L'!S14+'QTR P&L'!T14+'QTR P&L'!U14 | I14: ='QTR P&L'!V14+'QTR P&L'!W14+'QTR P&L'!X14+'QTR P&L'!Y14 | J14: ='QTR P&L'!Z14+'QTR P&L'!AA14+'QTR P&L'!AB14+'QTR P&L'!AC14 | K14: ='QTR P&L'!AD14+'QTR P&L'!AE14+'QTR P&L'!AF14+'QTR P&L'!AG14 | L14: ='QTR P&L'!AH14+'QTR P&L'!AI14+'QTR P&L'!AJ14+'QTR P&L'!AK14
A15: Net Income (Loss) Less NCI | B15: =B13-B14 | C15: =C13-C14 | D15: =D13-D14 | E15: =E13-E14 | F15: =F13-F14 | G15: =G13-G14 | H15: =H13-H14 | I15: =I13-I14 | ... L15: =L13-L14
A16: Basic Earnings (Loss) per Share | B16: 5.51 | C16: 6.45 | D16: 6.59 | E16: 6.97 | F16: 6.02
A17: Diluted Earnings (Loss) per Share | B17: 5.49 | C17: 6.42 | D17: 6.56 | E17: 6.95 | F17: 6
A18: Weighted Average Shares Outstanding (Basic) | B18: 1382000000 | C18: 1380000000 | D18: 1376000000 | E18: 1373000000 | F18: 1369000000
A19: Weighted Average Shares Outstanding (Diluted) | B19: 1389000000 | C19: 1387000000 | D19: 1383000000 | E19: 1378000000 | F19: 1373000000

Sheet BALANCE SHEET
B1: FY2022 | C1: FY2023 | D1: FY2024 | E1: FY2025 | F1: FY2025E | G1: FY2026E | H1: FY2027E | I1: FY2028E | J1: FY2029E | K1: FY2030E
A2: Cash & Cash Equivalents | B2: 4954 | C2: 9711 | D2: 8505 | E2: 9159 | F2: ='QTR BS'!N2 | G2: ='QTR BS'!R2 | H2: ='QTR BS'!V2 | I2: ='QTR BS'!Z2 | J2: ='QTR BS'!AD2 | K2: ='QTR BS'!AH2
A3: Short-Term Investments | B3: 394 | C3: 292 | D3: 761 | E3: 371 | F3: ='QTR BS'!N3 | G3: ='QTR BS'!R3 | H3: ='QTR BS'!V3 | I3: ='QTR BS'!Z3 | J3: ='QTR BS'!AD3 | K3: ='QTR BS'!AH3
A4: Accounts Receivable | B4: 10163 | C4: 10815 | D4: 10333 | E4: 11506 | F4: ='QTR BS'!N4 | G4: ='QTR BS'!R4 | H4: ='QTR BS'!V4 | I4: ='QTR BS'!Z4 | J4: ='QTR BS'!AD4 | K4: ='QTR BS'!AH4
A5: Inventories | B5: 5222 | C5: 5334 | D5: 5306 | E5: 5845 | F5: ='QTR BS'!N5 | G5: ='QTR BS'!R5 | H5: ='QTR BS'!V5 | I5: ='QTR BS'!Z5 | J5: ='QTR BS'!AD5 | K5: ='QTR BS'!AH5
A6: Prepaid Expenses | B6: 806 | C6: 798 | D6: 921 | E6: 1068 | F6: ='QTR BS'!N6 | G6: ='QTR BS'!R6 | H6: ='QTR BS'!V6 | I6: ='QTR BS'!Z6 | J6: ='QTR BS'!AD6 | K6: ='QTR BS'!AH6
A7: Total Current Assets | B7: =SUM(B2:B6) | C7: =SUM(C2:C6) | D7: =SUM(D2:D6) | E7: =SUM(E2:E6) | F7: =SUM(F2:F6) | G7: =SUM(G2:G6) | H7: =SUM(H2:H6) | I7: =SUM(I2:I6) | ... K7: =SUM(K2:K6)
A8: Net PP&E | B8: 24291 | C8: 27039 | D8: 28008 | E8: 29905 | F8: ='QTR BS'!N8 | G8: ='QTR BS'!R8 | H8: ='QTR BS'!V8 | I8: ='QTR BS'!Z8 | J8: ='QTR BS'!AD8 | K8: ='QTR BS'!AH8
A9: Intangible Assets | B9: 15586 | C9: 14929 | D9: 14801 | E9: 15066 | F9: ='QTR BS'!N9 | G9: ='QTR BS'!R9 | H9: ='QTR BS'!V9 | I9: ='QTR BS'!Z9 | J9: ='QTR BS'!AD9 | K9: ='QTR BS'!AH9
A10: Goodwill | B10: 18202 | C10: 17728 | D10: 17534 | E10: 18916 | F10: ='QTR BS'!N10 | G10: ='QTR BS'!R10 | H10: ='QTR BS'!V10 | I10: ='QTR BS'!Z10 | J10: ='QTR BS'!AD10 | K10: ='QTR BS'!AH10
A11: Equity Method Investments | B11: 3073 | C11: 2714 | D11: 1985 | E11: 2038 | F11: ='QTR BS'!N11 | G11: ='QTR BS'!R11 | H11: ='QTR BS'!V11 | I11: ='QTR BS'!Z11 | J11: ='QTR BS'!AD11 | K11: ='QTR BS'!AH11
A12: Deferred Tax Assets | B12: 4204 | C12: 4474 | D12: 4362 | E12: 4541 | F12: ='QTR BS'!N12 | G12: ='QTR BS'!R12 | H12: ='QTR BS'!V12 | I12: ='QTR BS'!Z12 | J12: ='QTR BS'!AD12 | K12: ='QTR BS'!AH12
A13: Other Non-Current Assets | B13: 5292 | C13: 6661 | D13: 6951 | E13: 8984 | F13: ='QTR BS'!N13 | G13: ='QTR BS'!R13 | H13: ='QTR BS'!V13 | I13: ='QTR BS'!Z13 | J13: ='QTR BS'!AD13 | K13: ='QTR BS'!AH13
A14: Total Assets | B14: =B7+SUM(B8:B13) | C14: =C7+SUM(C8:C13) | D14: =D7+SUM(D8:D13) | E14: =E7+SUM(E8:E13) | F14: =F7+SUM(F8:F13) | G14: =G7+SUM(G8:G13) | H14: =H7+SUM(H8:H13) | I14: =I7+SUM(I8:I13) | ... K14: =K7+SUM(K8:K13)
A15: Short-Term Debt Obligations | B15: 3414 | C15: 6510 | D15: 7082 | E15: 6861 | F15: ='QTR BS'!N15 | G15: ='QTR BS'!R15 | H15: ='QTR BS'!V15 | I15: ='QTR BS'!Z15 | J15: ='QTR BS'!AD15 | K15: ='QTR BS'!AH15
A16: Accrued Expenses | B16: 23371 | C16: 25137 | D16: 24454 | E16: 25903 | F16: ='QTR BS'!N16 | G16: ='QTR BS'!R16 | H16: ='QTR BS'!V16 | I16: ='QTR BS'!Z16 | J16: ='QTR BS'!AD16 | K16: ='QTR BS'!AH16
A17: Total Current Liabilities | B17: =SUM(B15:B16) | C17: =SUM(C15:C16) | D17: =SUM(D15:D16) | E17: =SUM(E15:E16) | F17: =SUM(F15:F16) | G17: =SUM(G15:G16) | H17: =SUM(H15:H16) | I17: =SUM(I15:I16) | ... K17: =SUM(K15:K16)
A18: Long-Term Debt | B18: 35657 | C18: 37595 | D18: 37224 | E18: 42321 | F18: ='QTR BS'!N18 | G18: ='QTR BS'!R18 | H18: ='QTR BS'!V18 | I18: ='QTR BS'!Z18 | J18: ='QTR BS'!AD18 | K18: ='QTR BS'!AH18
A19: Deferred Tax Liability | B19: 4133 | C19: 3895 | D19: 3484 | E19: 3802 | F19: ='QTR BS'!N19 | G19: ='QTR BS'!R19 | H19: ='QTR BS'!V19 | I19: ='QTR BS'!Z19 | J19: ='QTR BS'!AD19 | K19: ='QTR BS'!AH19
A20: Other Non-Current Liabilities | B20: 8339 | C20: 8721 | D20: 9052 | E20: 7965 | F20: ='QTR BS'!N20 | G20: ='QTR BS'!R20 | H20: ='QTR BS'!V20 | I20: ='QTR BS'!Z20 | J20: ='QTR BS'!AD20 | K20: ='QTR BS'!AH20
A21: Total Liabilities | B21: =B17+SUM(B18:B20) | C21: =C17+SUM(C18:C20) | D21: =D17+SUM(D18:D20) | E21: =E17+SUM(E18:E20) | F21: =F17+SUM(F18:F20) | G21: =G17+SUM(G18:G20) | H21: =H17+SUM(H18:H20) | I21: =I17+SUM(I18:I20) | ... K21: =K17+SUM(K18:K20)
A22: Common Stock | B22: 23 | C22: 23 | D22: 23 | E22: 23 | F22: ='QTR BS'!N22 | G22: ='QTR BS'!R22 | H22: ='QTR BS'!V22 | I22: ='QTR BS'!Z22 | J22: ='QTR BS'!AD22 | K22: ='QTR BS'!AH22
A23: Additional Paid-in Capital | B23: 4134 | C23: 4261 | D23: 4385 | E23: 4451 | F23: ='QTR BS'!N23 | G23: ='QTR BS'!R23 | H23: ='QTR BS'!V23 | I23: ='QTR BS'!Z23 | J23: ='QTR BS'!AD23 | K23: ='QTR BS'!AH23
A24: Retained Earnings (Accumulated Deficit) | B24: 67800 | C24: 70035 | D24: 72266 | E24: 72788 | F24: ='QTR BS'!N24 | G24: ='QTR BS'!R24 | H24: ='QTR BS'!V24 | I24: ='QTR BS'!Z24 | J24: ='QTR BS'!AD24 | K24: ='QTR BS'!AH24
A25: Accumulated Other Comprehensive Income (Loss) | B25: -15302 | C25: -15534 | D25: -17612 | E25: -15024 | F25: ='QTR BS'!N25 | G25: ='QTR BS'!R25 | H25: ='QTR BS'!V25 | I25: ='QTR BS'!Z25 | J25: ='QTR BS'!AD25 | K25: ='QTR BS'!AH25
A26: Treasury Stock | B26: -39506 | C26: -40282 | D26: -41021 | E26: -41832 | F26: ='QTR BS'!N26 | G26: ='QTR BS'!R26 | H26: ='QTR BS'!V26 | I26: ='QTR BS'!Z26 | J26: ='QTR BS'!AD26 | K26: ='QTR BS'!AH26
A27: Noncontrolling Interest | B27: 124 | C27: 134 | D27: 130 | E27: 141 | F27: ='QTR BS'!N27 | G27: ='QTR BS'!R27 | H27: ='QTR BS'!V27 | I27: ='QTR BS'!Z27 | J27: ='QTR BS'!AD27 | K27: ='QTR BS'!AH27
A28: Total Stockholders' Equity | B28: =SUM(B22:B27) | C28: =SUM(C22:C27) | D28: =SUM(D22:D27) | E28: =SUM(E22:E27) | F28: =SUM(F22:F27) | G28: =SUM(G22:G27) | H28: =SUM(H22:H27) | I28: =SUM(I22:I27) | ... K28: =SUM(K22:K27)
A29: Total Liabilities, Mezzanine & Stockholders' Equity | B29: =B21+B28 | C29: =C21+C28 | D29: =D21+D28 | E29: =E21+E28 | F29: =F21+F28 | G29: =G21+G28 | H29: =H21+H28 | I29: =I21+I28 | ... K29: =K21+K28

Sheet CASH FLOW
B1: FY2021 | C1: FY2022 | D1: FY2023 | E1: FY2024 | F1: FY2025 | G1: FY2025E | H1: FY2026E | I1: FY2027E | J1: FY2028E | K1: FY2029E | L1: FY2030E
A2: Net Income (Loss) | B2: 7679 | C2: 8978 | D2: 9155 | E2: 9626 | F2: 8295 | G2: ='QTR CF'!N2+'QTR CF'!O2+'QTR CF'!P2+'QTR CF'!Q2 | H2: ='QTR CF'!R2+'QTR CF'!S2+'QTR CF'!T2+'QTR CF'!U2 | I2: ='QTR CF'!V2+'QTR CF'!W2+'QTR CF'!X2+'QTR CF'!Y2 | J2: ='QTR CF'!Z2+'QTR CF'!AA2+'QTR CF'!AB2+'QTR CF'!AC2 | K2: ='QTR CF'!AD2+'QTR CF'!AE2+'QTR CF'!AF2+'QTR CF'!AG2 | L2: ='QTR CF'!AH2+'QTR CF'!AI2+'QTR CF'!AJ2+'QTR CF'!AK2
A3: Depreciation & Amortization | B3: 2710 | C3: 2763 | D3: 2948 | E3: 3160 | F3: 3451 | G3: ='QTR CF'!N3+'QTR CF'!O3+'QTR CF'!P3+'QTR CF'!Q3 | H3: ='QTR CF'!R3+'QTR CF'!S3+'QTR CF'!T3+'QTR CF'!U3 | I3: ='QTR CF'!V3+'QTR CF'!W3+'QTR CF'!X3+'QTR CF'!Y3 | J3: ='QTR CF'!Z3+'QTR CF'!AA3+'QTR CF'!AB3+'QTR CF'!AC3 | K3: ='QTR CF'!AD3+'QTR CF'!AE3+'QTR CF'!AF3+'QTR CF'!AG3 | L3: ='QTR CF'!AH3+'QTR CF'!AI3+'QTR CF'!AJ3+'QTR CF'!AK3
A4: Gain on Juice Transaction | B4: 0 | C4: -3321 | D4: 0 | E4: 0 | F4: 0 | G4: ='QTR CF'!N4+'QTR CF'!O4+'QTR CF'!P4+'QTR CF'!Q4 | H4: ='QTR CF'!R4+'QTR CF'!S4+'QTR CF'!T4+'QTR CF'!U4 | I4: ='QTR CF'!V4+'QTR CF'!W4+'QTR CF'!X4+'QTR CF'!Y4 | J4: ='QTR CF'!Z4+'QTR CF'!AA4+'QTR CF'!AB4+'QTR CF'!AC4 | K4: ='QTR CF'!AD4+'QTR CF'!AE4+'QTR CF'!AF4+'QTR CF'!AG4 | L4: ='QTR CF'!AH4+'QTR CF'!AI4+'QTR CF'!AJ4+'QTR CF'!AK4
A5: Impairment and Other Charges | B5: 0 | C5: 3618 | D5: 1230 | E5: 714 | F5: 1946 | G5: ='QTR CF'!N5+'QTR CF'!O5+'QTR CF'!P5+'QTR CF'!Q5 | H5: ='QTR CF'!R5+'QTR CF'!S5+'QTR CF'!T5+'QTR CF'!U5 | I5: ='QTR CF'!V5+'QTR CF'!W5+'QTR CF'!X5+'QTR CF'!Y5 | J5: ='QTR CF'!Z5+'QTR CF'!AA5+'QTR CF'!AB5+'QTR CF'!AC5 | K5: ='QTR CF'!AD5+'QTR CF'!AE5+'QTR CF'!AF5+'QTR CF'!AG5 | L5: ='QTR CF'!AH5+'QTR CF'!AI5+'QTR CF'!AJ5+'QTR CF'!AK5
A6: Indirect Tax Impact | B6: 0 | C6: 0 | D6: 0 | E6: 218 | F6: 0
A7: Product Recall Impact | B7: 0 | C7: 0 | D7: 136 | E7: 187 | F7: 0 | G7: ='QTR CF'!N6+'QTR CF'!O6+'QTR CF'!P6+'QTR CF'!Q6 | H7: ='QTR CF'!R6+'QTR CF'!S6+'QTR CF'!T6+'QTR CF'!U6 | I7: ='QTR CF'!V6+'QTR CF'!W6+'QTR CF'!X6+'QTR CF'!Y6 | J7: ='QTR CF'!Z6+'QTR CF'!AA6+'QTR CF'!AB6+'QTR CF'!AC6 | K7: ='QTR CF'!AD6+'QTR CF'!AE6+'QTR CF'!AF6+'QTR CF'!AG6 | L7: ='QTR CF'!AH6+'QTR CF'!AI6+'QTR CF'!AJ6+'QTR CF'!AK6
A8: Cash Payments for Product Recall | B8: 0 | C8: 0 | D8: 0 | E8: -148 | F8: -6 | G8: ='QTR CF'!N7+'QTR CF'!O7+'QTR CF'!P7+'QTR CF'!Q7 | H8: ='QTR CF'!R7+'QTR CF'!S7+'QTR CF'!T7+'QTR CF'!U7 | I8: ='QTR CF'!V7+'QTR CF'!W7+'QTR CF'!X7+'QTR CF'!Y7 | J8: ='QTR CF'!Z7+'QTR CF'!AA7+'QTR CF'!AB7+'QTR CF'!AC7 | K8: ='QTR CF'!AD7+'QTR CF'!AE7+'QTR CF'!AF7+'QTR CF'!AG7 | L8: ='QTR CF'!AH7+'QTR CF'!AI7+'QTR CF'!AJ7+'QTR CF'!AK7
A9: Operating Lease ROU Asset Amortization | B9: 505 | C9: 517 | D9: 570 | E9: 655 | F9: 727 | G9: ='QTR CF'!N8+'QTR CF'!O8+'QTR CF'!P8+'QTR CF'!Q8 | H9: ='QTR CF'!R8+'QTR CF'!S8+'QTR CF'!T8+'QTR CF'!U8 | I9: ='QTR CF'!V8+'QTR CF'!W8+'QTR CF'!X8+'QTR CF'!Y8 | J9: ='QTR CF'!Z8+'QTR CF'!AA8+'QTR CF'!AB8+'QTR CF'!AC8 | K9: ='QTR CF'!AD8+'QTR CF'!AE8+'QTR CF'!AF8+'QTR CF'!AG8 | L9: ='QTR CF'!AH8+'QTR CF'!AI8+'QTR CF'!AJ8+'QTR CF'!AK8
A10: Stock-Based Compensation | B10: 301 | C10: 343 | D10: 380 | E10: 362 | F10: 288 | G10: ='QTR CF'!N9+'QTR CF'!O9+'QTR CF'!P9+'QTR CF'!Q9 | H10: ='QTR CF'!R9+'QTR CF'!S9+'QTR CF'!T9+'QTR CF'!U9 | I10: ='QTR CF'!V9+'QTR CF'!W9+'QTR CF'!X9+'QTR CF'!Y9 | J10: ='QTR CF'!Z9+'QTR CF'!AA9+'QTR CF'!AB9+'QTR CF'!AC9 | K10: ='QTR CF'!AD9+'QTR CF'!AE9+'QTR CF'!AF9+'QTR CF'!AG9 | L10: ='QTR CF'!AH9+'QTR CF'!AI9+'QTR CF'!AJ9+'QTR CF'!AK9
A11: Restructuring and Asset Impairment Charges | B11: 247 | C11: 411 | D11: 445 | E11: 727 | F11: 983 | G11: ='QTR CF'!N10+'QTR CF'!O10+'QTR CF'!P10+'QTR CF'!Q10 | H11: ='QTR CF'!R10+'QTR CF'!S10+'QTR CF'!T10+'QTR CF'!U10 | I11: ='QTR CF'!V10+'QTR CF'!W10+'QTR CF'!X10+'QTR CF'!Y10 | J11: ='QTR CF'!Z10+'QTR CF'!AA10+'QTR CF'!AB10+'QTR CF'!AC10 | K11: ='QTR CF'!AD10+'QTR CF'!AE10+'QTR CF'!AF10+'QTR CF'!AG10 | L11: ='QTR CF'!AH10+'QTR CF'!AI10+'QTR CF'!AJ10+'QTR CF'!AK10
A12: Cash Payments for Restructuring | B12: -256 | C12: -224 | D12: -434 | E12: -436 | F12: -796 | G12: ='QTR CF'!N11+'QTR CF'!O11+'QTR CF'!P11+'QTR CF'!Q11 | H12: ='QTR CF'!R11+'QTR CF'!S11+'QTR CF'!T11+'QTR CF'!U11 | I12: ='QTR CF'!V11+'QTR CF'!W11+'QTR CF'!X11+'QTR CF'!Y11 | J12: ='QTR CF'!Z11+'QTR CF'!AA11+'QTR CF'!AB11+'QTR CF'!AC11 | K12: ='QTR CF'!AD11+'QTR CF'!AE11+'QTR CF'!AF11+'QTR CF'!AG11 | L12: ='QTR CF'!AH11+'QTR CF'!AI11+'QTR CF'!AJ11+'QTR CF'!AK11
A13: Acquisition and Divestiture-Related Charges | B13: -4 | C13: 80 | D13: 41 | E13: 0 | F13: 453 | G13: ='QTR CF'!N12+'QTR CF'!O12+'QTR CF'!P12+'QTR CF'!Q12 | H13: ='QTR CF'!R12+'QTR CF'!S12+'QTR CF'!T12+'QTR CF'!U12 | I13: ='QTR CF'!V12+'QTR CF'!W12+'QTR CF'!X12+'QTR CF'!Y12 | J13: ='QTR CF'!Z12+'QTR CF'!AA12+'QTR CF'!AB12+'QTR CF'!AC12 | K13: ='QTR CF'!AD12+'QTR CF'!AE12+'QTR CF'!AF12+'QTR CF'!AG12 | L13: ='QTR CF'!AH12+'QTR CF'!AI12+'QTR CF'!AJ12+'QTR CF'!AK12
A14: Cash Payments for Acquisition and Divestiture Costs | B14: -176 | C14: -46 | D14: -41 | E14: 0 | F14: -228 | G14: ='QTR CF'!N13+'QTR CF'!O13+'QTR CF'!P13+'QTR CF'!Q13 | H14: ='QTR CF'!R13+'QTR CF'!S13+'QTR CF'!T13+'QTR CF'!U13 | I14: ='QTR CF'!V13+'QTR CF'!W13+'QTR CF'!X13+'QTR CF'!Y13 | J14: ='QTR CF'!Z13+'QTR CF'!AA13+'QTR CF'!AB13+'QTR CF'!AC13 | K14: ='QTR CF'!AD13+'QTR CF'!AE13+'QTR CF'!AF13+'QTR CF'!AG13 | L14: ='QTR CF'!AH13+'QTR CF'!AI13+'QTR CF'!AJ13+'QTR CF'!AK13
A15: Pension and Postretirement Benefits Expense | B15: 123 | C15: 419 | D15: 150 | E15: 414 | F15: 504 | G15: ='QTR CF'!N14+'QTR CF'!O14+'QTR CF'!P14+'QTR CF'!Q14 | H15: ='QTR CF'!R14+'QTR CF'!S14+'QTR CF'!T14+'QTR CF'!U14 | I15: ='QTR CF'!V14+'QTR CF'!W14+'QTR CF'!X14+'QTR CF'!Y14 | J15: ='QTR CF'!Z14+'QTR CF'!AA14+'QTR CF'!AB14+'QTR CF'!AC14 | K15: ='QTR CF'!AD14+'QTR CF'!AE14+'QTR CF'!AF14+'QTR CF'!AG14 | L15: ='QTR CF'!AH14+'QTR CF'!AI14+'QTR CF'!AJ14+'QTR CF'!AK14
A16: Pension and Postretirement Benefits Contributions | B16: -785 | C16: -384 | D16: -410 | E16: -348 | F16: -472 | G16: ='QTR CF'!N15+'QTR CF'!O15+'QTR CF'!P15+'QTR CF'!Q15 | H16: ='QTR CF'!R15+'QTR CF'!S15+'QTR CF'!T15+'QTR CF'!U15 | I16: ='QTR CF'!V15+'QTR CF'!W15+'QTR CF'!X15+'QTR CF'!Y15 | J16: ='QTR CF'!Z15+'QTR CF'!AA15+'QTR CF'!AB15+'QTR CF'!AC15 | K16: ='QTR CF'!AD15+'QTR CF'!AE15+'QTR CF'!AF15+'QTR CF'!AG15 | L16: ='QTR CF'!AH15+'QTR CF'!AI15+'QTR CF'!AJ15+'QTR CF'!AK15
A17: (Benefit) Provision for Deferred Income Taxes | B17: 298 | C17: -873 | D17: -271 | E17: -42 | F17: 71 | G17: ='QTR CF'!N16+'QTR CF'!O16+'QTR CF'!P16+'QTR CF'!Q16 | H17: ='QTR CF'!R16+'QTR CF'!S16+'QTR CF'!T16+'QTR CF'!U16 | I17: ='QTR CF'!V16+'QTR CF'!W16+'QTR CF'!X16+'QTR CF'!Y16 | J17: ='QTR CF'!Z16+'QTR CF'!AA16+'QTR CF'!AB16+'QTR CF'!AC16 | K17: ='QTR CF'!AD16+'QTR CF'!AE16+'QTR CF'!AF16+'QTR CF'!AG16 | L17: ='QTR CF'!AH16+'QTR CF'!AI16+'QTR CF'!AJ16+'QTR CF'!AK16
A18: Tax Expense Related to TCJ Act | B18: 190 | C18: 86 | D18: 0 | E18: 0 | F18: 0 | G18: ='QTR CF'!N17+'QTR CF'!O17+'QTR CF'!P17+'QTR CF'!Q17 | H18: ='QTR CF'!R17+'QTR CF'!S17+'QTR CF'!T17+'QTR CF'!U17 | I18: ='QTR CF'!V17+'QTR CF'!W17+'QTR CF'!X17+'QTR CF'!Y17 | J18: ='QTR CF'!Z17+'QTR CF'!AA17+'QTR CF'!AB17+'QTR CF'!AC17 | K18: ='QTR CF'!AD17+'QTR CF'!AE17+'QTR CF'!AF17+'QTR CF'!AG17 | L18: ='QTR CF'!AH17+'QTR CF'!AI17+'QTR CF'!AJ17+'QTR CF'!AK17
... A25: Other Operating Items | B25: 375 | C25: -359 | D25: 189 | E25: -307 | F25: -712 | G25: ='QTR CF'!N24+'QTR CF'!O24+'QTR CF'!P24+'QTR CF'!Q24 | H25: ='QTR CF'!R24+'QTR CF'!S24+'QTR CF'!T24+'QTR CF'!U24 | I25: ='QTR CF'!V24+'QTR CF'!W24+'QTR CF'!X24+'QTR CF'!Y24 | J25: ='QTR CF'!Z24+'QTR CF'!AA24+'QTR CF'!AB24+'QTR CF'!AC24 | K25: ='QTR CF'!AD24+'QTR CF'!AE24+'QTR CF'!AF24+'QTR CF'!AG24 | L25: ='QTR CF'!AH24+'QTR CF'!AI24+'QTR CF'!AJ24+'QTR CF'!AK24
A26: Cash Flow from Operations | B26: =SUM(B2:B25) | C26: =SUM(C2:C25) | D26: =SUM(D2:D25) | E26: =SUM(E2:E25) | F26: =SUM(F2:F25) | G26: =SUM(G2:G25) | H26: =SUM(H2:H25) | I26: =SUM(I2:I25) | ... L26: =SUM(L2:L25)
A27: Purchase of PP&E | B27: -4625 | C27: -5207 | D27: -5518 | E27: -5318 | F27: -4415 | G27: ='QTR CF'!N26+'QTR CF'!O26+'QTR CF'!P26+'QTR CF'!Q26 | H27: ='QTR CF'!R26+'QTR CF'!S26+'QTR CF'!T26+'QTR CF'!U26 | I27: ='QTR CF'!V26+'QTR CF'!W26+'QTR CF'!X26+'QTR CF'!Y26 | J27: ='QTR CF'!Z26+'QTR CF'!AA26+'QTR CF'!AB26+'QTR CF'!AC26 | K27: ='QTR CF'!AD26+'QTR CF'!AE26+'QTR CF'!AF26+'QTR CF'!AG26 | L27: ='QTR CF'!AH26+'QTR CF'!AI26+'QTR CF'!AJ26+'QTR CF'!AK26
A28: Proceeds from Sale of Assets | B28: 166 | C28: 251 | D28: 198 | E28: 342 | F28: 528 | G28: ='QTR CF'!N27+'QTR CF'!O27+'QTR CF'!P27+'QTR CF'!Q27 | H28: ='QTR CF'!R27+'QTR CF'!S27+'QTR CF'!T27+'QTR CF'!U27 | I28: ='QTR CF'!V27+'QTR CF'!W27+'QTR CF'!X27+'QTR CF'!Y27 | J28: ='QTR CF'!Z27+'QTR CF'!AA27+'QTR CF'!AB27+'QTR CF'!AC27 | K28: ='QTR CF'!AD27+'QTR CF'!AE27+'QTR CF'!AF27+'QTR CF'!AG27 | L28: ='QTR CF'!AH27+'QTR CF'!AI27+'QTR CF'!AJ27+'QTR CF'!AK27
A29: Acquisitions, Net of Cash Acquired | B29: -61 | C29: -873 | D29: -314 | E29: -256 | F29: -3391 | G29: ='QTR CF'!N28+'QTR CF'!O28+'QTR CF'!P28+'QTR CF'!Q28 | H29: ='QTR CF'!R28+'QTR CF'!S28+'QTR CF'!T28+'QTR CF'!U28 | I29: ='QTR CF'!V28+'QTR CF'!W28+'QTR CF'!X28+'QTR CF'!Y28 | J29: ='QTR CF'!Z28+'QTR CF'!AA28+'QTR CF'!AB28+'QTR CF'!AC28 | K29: ='QTR CF'!AD28+'QTR CF'!AE28+'QTR CF'!AF28+'QTR CF'!AG28 | L29: ='QTR CF'!AH28+'QTR CF'!AI28+'QTR CF'!AJ28+'QTR CF'!AK28
A30: Proceeds from Juice Transaction | B30: 0 | C30: 3456 | D30: 0 | E30: 0 | F30: 0 | G30: ='QTR CF'!N29+'QTR CF'!O29+'QTR CF'!P29+'QTR CF'!Q29 | H30: ='QTR CF'!R29+'QTR CF'!S29+'QTR CF'!T29+'QTR CF'!U29 | I30: ='QTR CF'!V29+'QTR CF'!W29+'QTR CF'!X29+'QTR CF'!Y29 | J30: ='QTR CF'!Z29+'QTR CF'!AA29+'QTR CF'!AB29+'QTR CF'!AC29 | K30: ='QTR CF'!AD29+'QTR CF'!AE29+'QTR CF'!AF29+'QTR CF'!AG29 | L30: ='QTR CF'!AH29+'QTR CF'!AI29+'QTR CF'!AJ29+'QTR CF'!AK29
A31: Proceeds from Divestitures of Businesses | B31: 169 | C31: 49 | D31: 75 | E31: 166 | F31: 39 | G31: ='QTR CF'!N30+'QTR CF'!O30+'QTR CF'!P30+'QTR CF'!Q30 | H31: ='QTR CF'!R30+'QTR CF'!S30+'QTR CF'!T30+'QTR CF'!U30 | I31: ='QTR CF'!V30+'QTR CF'!W30+'QTR CF'!X30+'QTR CF'!Y30 | J31: ='QTR CF'!Z30+'QTR CF'!AA30+'QTR CF'!AB30+'QTR CF'!AC30 | K31: ='QTR CF'!AD30+'QTR CF'!AE30+'QTR CF'!AF30+'QTR CF'!AG30 | L31: ='QTR CF'!AH30+'QTR CF'!AI30+'QTR CF'!AJ30+'QTR CF'!AK30
A32: Net Change in Short-Term Investments | B32: 1077 | C32: -117 | D32: 16 | E32: -420 | F32: 460 | G32: ='QTR CF'!N31+'QTR CF'!O31+'QTR CF'!P31+'QTR CF'!Q31 | H32: ='QTR CF'!R31+'QTR CF'!S31+'QTR CF'!T31+'QTR CF'!U31 | I32: ='QTR CF'!V31+'QTR CF'!W31+'QTR CF'!X31+'QTR CF'!Y31 | J32: ='QTR CF'!Z31+'QTR CF'!AA31+'QTR CF'!AB31+'QTR CF'!AC31 | K32: ='QTR CF'!AD31+'QTR CF'!AE31+'QTR CF'!AF31+'QTR CF'!AG31 | L32: ='QTR CF'!AH31+'QTR CF'!AI31+'QTR CF'!AJ31+'QTR CF'!AK31
A33: Other Investing Activities | B33: 5 | C33: 11 | D33: 48 | E33: 14 | F33: -100 | G33: ='QTR CF'!N32+'QTR CF'!O32+'QTR CF'!P32+'QTR CF'!Q32 | H33: ='QTR CF'!R32+'QTR CF'!S32+'QTR CF'!T32+'QTR CF'!U32 | I33: ='QTR CF'!V32+'QTR CF'!W32+'QTR CF'!X32+'QTR CF'!Y32 | J33: ='QTR CF'!Z32+'QTR CF'!AA32+'QTR CF'!AB32+'QTR CF'!AC32 | K33: ='QTR CF'!AD32+'QTR CF'!AE32+'QTR CF'!AF32+'QTR CF'!AG32 | L33: ='QTR CF'!AH32+'QTR CF'!AI32+'QTR CF'!AJ32+'QTR CF'!AK32
A34: Cash Flow from Investing | B34: =SUM(B27:B33) | C34: =SUM(C27:C33) | D34: =SUM(D27:D33) | E34: =SUM(E27:E33) | F34: =SUM(F27:F33) | G34: =SUM(G27:G33) | H34: =SUM(H27:H33) | I34: =SUM(I27:I33) | ... L34: =SUM(L27:L33)
A35: Proceeds from Issuance of Long-Term Debt | B35: 4122 | C35: 3377 | D35: 5482 | E35: 4042 | F35: 8189 | G35: ='QTR CF'!N34+'QTR CF'!O34+'QTR CF'!P34+'QTR CF'!Q34 | H35: ='QTR CF'!R34+'QTR CF'!S34+'QTR CF'!T34+'QTR CF'!U34 | I35: ='QTR CF'!V34+'QTR CF'!W34+'QTR CF'!X34+'QTR CF'!Y34 | J35: ='QTR CF'!Z34+'QTR CF'!AA34+'QTR CF'!AB34+'QTR CF'!AC34 | K35: ='QTR CF'!AD34+'QTR CF'!AE34+'QTR CF'!AF34+'QTR CF'!AG34 | L35: ='QTR CF'!AH34+'QTR CF'!AI34+'QTR CF'!AJ34+'QTR CF'!AK34
A36: Repayments of Long-Term Debt | B36: -8299 | C36: -4174 | D36: -3005 | E36: -3886 | F36: -4082 | G36: ='QTR CF'!N35+'QTR CF'!O35+'QTR CF'!P35+'QTR CF'!Q35 | H36: ='QTR CF'!R35+'QTR CF'!S35+'QTR CF'!T35+'QTR CF'!U35 | I36: ='QTR CF'!V35+'QTR CF'!W35+'QTR CF'!X35+'QTR CF'!Y35 | J36: ='QTR CF'!Z35+'QTR CF'!AA35+'QTR CF'!AB35+'QTR CF'!AC35 | K36: ='QTR CF'!AD35+'QTR CF'!AE35+'QTR CF'!AF35+'QTR CF'!AG35 | L36: ='QTR CF'!AH35+'QTR CF'!AI35+'QTR CF'!AJ35+'QTR CF'!AK35
A37: Proceeds from Short-Term Debt | B37: 8 | C37: 1969 | D37: 5428 | E37: 5786 | F37: 6391 | G37: ='QTR CF'!N36+'QTR CF'!O36+'QTR CF'!P36+'QTR CF'!Q36 | H37: ='QTR CF'!R36+'QTR CF'!S36+'QTR CF'!T36+'QTR CF'!U36 | I37: ='QTR CF'!V36+'QTR CF'!W36+'QTR CF'!X36+'QTR CF'!Y36 | J37: ='QTR CF'!Z36+'QTR CF'!AA36+'QTR CF'!AB36+'QTR CF'!AC36 | K37: ='QTR CF'!AD36+'QTR CF'!AE36+'QTR CF'!AF36+'QTR CF'!AG36 | L37: ='QTR CF'!AH36+'QTR CF'!AI36+'QTR CF'!AJ36+'QTR CF'!AK36
A38: Repayments of Short-Term Debt | B38: -397 | C38: -1951 | D38: -3106 | E38: -5639 | F38: -7920 | G38: ='QTR CF'!N37+'QTR CF'!O37+'QTR CF'!P37+'QTR CF'!Q37 | H38: ='QTR CF'!R37+'QTR CF'!S37+'QTR CF'!T37+'QTR CF'!U37 | I38: ='QTR CF'!V37+'QTR CF'!W37+'QTR CF'!X37+'QTR CF'!Y37 | J38: ='QTR CF'!Z37+'QTR CF'!AA37+'QTR CF'!AB37+'QTR CF'!AC37 | K38: ='QTR CF'!AD37+'QTR CF'!AE37+'QTR CF'!AF37+'QTR CF'!AG37 | L38: ='QTR CF'!AH37+'QTR CF'!AI37+'QTR CF'!AJ37+'QTR CF'!AK37
A39: Net Change in Other Short-Term Debt | B39: 434 | C39: -31 | D39: -29 | E39: 392 | F39: 1170 | G39: ='QTR CF'!N38+'QTR CF'!O38+'QTR CF'!P38+'QTR CF'!Q38 | H39: ='QTR CF'!R38+'QTR CF'!S38+'QTR CF'!T38+'QTR CF'!U38 | I39: ='QTR CF'!V38+'QTR CF'!W38+'QTR CF'!X38+'QTR CF'!Y38 | J39: ='QTR CF'!Z38+'QTR CF'!AA38+'QTR CF'!AB38+'QTR CF'!AC38 | K39: ='QTR CF'!AD38+'QTR CF'!AE38+'QTR CF'!AF38+'QTR CF'!AG38 | L39: ='QTR CF'!AH38+'QTR CF'!AI38+'QTR CF'!AJ38+'QTR CF'!AK38
A40: Payments of Contingent Consideration | B40: -773 | C40: 0 | D40: 0 | E40: 0 | F40: 0
A41: Common Dividends | B41: -5815 | C41: -6172 | D41: -6682 | E41: -7229 | F41: -7638 | G41: ='QTR CF'!N39+'QTR CF'!O39+'QTR CF'!P39+'QTR CF'!Q39 | H41: ='QTR CF'!R39+'QTR CF'!S39+'QTR CF'!T39+'QTR CF'!U39 | I41: ='QTR CF'!V39+'QTR CF'!W39+'QTR CF'!X39+'QTR CF'!Y39 | J41: ='QTR CF'!Z39+'QTR CF'!AA39+'QTR CF'!AB39+'QTR CF'!AC39 | K41: ='QTR CF'!AD39+'QTR CF'!AE39+'QTR CF'!AF39+'QTR CF'!AG39 | L41: ='QTR CF'!AH39+'QTR CF'!AI39+'QTR CF'!AJ39+'QTR CF'!AK39
A42: Share Repurchases | B42: -106 | C42: -1500 | D42: -1000 | E42: -1000 | F42: -1000 | G42: ='QTR CF'!N40+'QTR CF'!O40+'QTR CF'!P40+'QTR CF'!Q40 | H42: ='QTR CF'!R40+'QTR CF'!S40+'QTR CF'!T40+'QTR CF'!U40 | I42: ='QTR CF'!V40+'QTR CF'!W40+'QTR CF'!X40+'QTR CF'!Y40 | J42: ='QTR CF'!Z40+'QTR CF'!AA40+'QTR CF'!AB40+'QTR CF'!AC40 | K42: ='QTR CF'!AD40+'QTR CF'!AE40+'QTR CF'!AF40+'QTR CF'!AG40 | L42: ='QTR CF'!AH40+'QTR CF'!AI40+'QTR CF'!AJ40+'QTR CF'!AK40
A43: Proceeds from Exercise of Stock Options | B43: 185 | C43: 138 | D43: 116 | E43: 166 | F43: 97 | G43: ='QTR CF'!N41+'QTR CF'!O41+'QTR CF'!P41+'QTR CF'!Q41 | H43: ='QTR CF'!R41+'QTR CF'!S41+'QTR CF'!T41+'QTR CF'!U41 | I43: ='QTR CF'!V41+'QTR CF'!W41+'QTR CF'!X41+'QTR CF'!Y41 | J43: ='QTR CF'!Z41+'QTR CF'!AA41+'QTR CF'!AB41+'QTR CF'!AC41 | K43: ='QTR CF'!AD41+'QTR CF'!AE41+'QTR CF'!AF41+'QTR CF'!AG41 | L43: ='QTR CF'!AH41+'QTR CF'!AI41+'QTR CF'!AJ41+'QTR CF'!AK41
A44: Tax Withholdings on RSU/PSU Settlement | B44: -92 | C44: -107 | D44: -140 | E44: -135 | F44: -113 | G44: ='QTR CF'!N42+'QTR CF'!O42+'QTR CF'!P42+'QTR CF'!Q42 | H44: ='QTR CF'!R42+'QTR CF'!S42+'QTR CF'!T42+'QTR CF'!U42 | I44: ='QTR CF'!V42+'QTR CF'!W42+'QTR CF'!X42+'QTR CF'!Y42 | J44: ='QTR CF'!Z42+'QTR CF'!AA42+'QTR CF'!AB42+'QTR CF'!AC42 | K44: ='QTR CF'!AD42+'QTR CF'!AE42+'QTR CF'!AF42+'QTR CF'!AG42 | L44: ='QTR CF'!AH42+'QTR CF'!AI42+'QTR CF'!AJ42+'QTR CF'!AK42
A45: Other Financing Activities | B45: -47 | C45: -72 | D45: -73 | E45: -53 | F45: -73 | G45: ='QTR CF'!N43+'QTR CF'!O43+'QTR CF'!P43+'QTR CF'!Q43 | H45: ='QTR CF'!R43+'QTR CF'!S43+'QTR CF'!T43+'QTR CF'!U43 | I45: ='QTR CF'!V43+'QTR CF'!W43+'QTR CF'!X43+'QTR CF'!Y43 | J45: ='QTR CF'!Z43+'QTR CF'!AA43+'QTR CF'!AB43+'QTR CF'!AC43 | K45: ='QTR CF'!AD43+'QTR CF'!AE43+'QTR CF'!AF43+'QTR CF'!AG43 | L45: ='QTR CF'!AH43+'QTR CF'!AI43+'QTR CF'!AJ43+'QTR CF'!AK43
A46: Cash Flow from Financing | B46: =SUM(B35:B45) | C46: =SUM(C35:C45) | D46: =SUM(D35:D45) | E46: =SUM(E35:E45) | F46: =SUM(F35:F45) | G46: =SUM(G35:G45) | H46: =SUM(H35:H45) | I46: =SUM(I35:I45) | ... L46: =SUM(L35:L45)
...

Sheet YTD P&L
B1: Q1 FY2022 | C1: Q2 FY2022 | D1: Q3 FY2022 | E1: Q1 FY2023 | F1: Q2 FY2023 | G1: Q3 FY2023 | H1: Q1 FY2024 | I1: Q2 FY2024 | J1: Q3 FY2024 | K1: Q1 FY2025 | L1: Q2 FY2025 | M1: Q3 FY2025 | N1: Q1 FY2026
A2: Net Sales / Revenue | B2: 16200 | C2: 36425 | D2: 58396 | E2: 17846 | F2: 40168 | G2: 63621 | H2: 18250 | I2: 40751 | J2: 64070 | K2: 17919 | L2: 40645 | M2: 64582 | N2: 19443
A3: COGS | B3: -7433 | C3: -16848 | D3: -27156 | E3: -7988 | F3: -18109 | G3: -28784 | H3: -8248 | I3: -18167 | J3: -28563 | K3: -7926 | L3: -18230 | M3: -29343 | N3: -8712
A4: Gross Profit (Loss) | B4: =B2+B3 | C4: =C2+C3 | D4: =D2+D3 | E4: =E2+E3 | F4: =F2+F3 | G4: =G2+G3 | H4: =H2+H3 | I4: =I2+I3 | ... N4: =N2+N3
A5: SG&A | B5: -6580 | C5: -13967 | D5: -22262 | E5: -7229 | F5: -15771 | G5: -24528 | H5: -7285 | I5: -15819 | J5: -24870 | K5: -7410 | L5: -16183 | M5: -25305 | N5: -7518
A6: Gain on Juice Transaction | B6: -3322 | C6: -3335 | D6: -3321 | E6: 0 | F6: 0 | G6: 0 | H6: 0 | I6: 0 | J6: 0 | K6: 0 | L6: 0 | M6: 0 | N6: 0
A7: Impairment of Intangibles | B7: -242 | C7: -1601 | D7: -1602 | E7: 0 | F7: 0 | G7: -6 | H7: 0 | I7: 0 | J7: 0 | K7: 0 | L7: -1860 | M7: -1993 | N7: 0
A8: Income (Loss) from Operations | B8: =B4+SUM(B5:B7) | C8: =C4+SUM(C5:C7) | D8: =D4+SUM(D5:D7) | E8: =E4+SUM(E5:E7) | F8: =F4+SUM(F5:F7) | G8: =G4+SUM(G5:G7) | H8: =H4+SUM(H5:H7) | I8: =I4+SUM(I5:I7) | ... N8: =N4+SUM(N5:N7)
A9: Other Pension and OPEB Benefits Income (Expense) | B9: 134 | C9: 132 | D9: 168 | E9: 61 | F9: 121 | G9: 183 | H9: 58 | I9: 114 | J9: 155 | K9: 23 | L9: 65 | M9: 91 | N9: 58
A10: Interest Income (Expense) | B10: -240 | C10: -476 | D10: -666 | E10: -200 | F10: -401 | G10: -602 | H10: -202 | I10: -436 | J10: -655 | K10: -264 | L10: -524 | M10: -788 | N10: -301
A11: Pre-Tax Income (Loss) | B11: =B8+SUM(B9:B10) | C11: =C8+SUM(C9:C10) | D11: =D8+SUM(D9:D10) | E11: =E8+SUM(E9:E10) | F11: =F8+SUM(F9:F10) | G11: =G8+SUM(G9:G10) | H11: =H8+SUM(H9:H10) | I11: =I8+SUM(I9:I10) | ... N11: =N8+SUM(N9:N10)
A12: Income Tax (Expense) Benefit | B12: -888 | C12: -1281 | D12: -1756 | E12: -546 | F12: -1293 | G12: -2053 | H12: -520 | I12: -1296 | J12: -2045 | K12: -499 | L12: -791 | M12: -1504 | N12: -632
A13: Net Income (Loss) | B13: =B11+B12 | C13: =C11+C12 | D13: =D11+D12 | E13: =E11+E12 | F13: =F11+F12 | G13: =G11+G12 | H13: =H11+H12 | I13: =I11+I12 | ... N13: =N11+N12
A14: Net Income (Loss) Attributable to Noncontrolling Interest | B14: 12 | C14: 29 | D14: 51 | E14: 12 | F14: 35 | G14: 59 | H14: 11 | I14: 22 | J14: 37 | K14: 9 | L14: 25 | M14: 40 | N14: 11
A15: Net Income (Loss) Less NCI | B15: =B13-B14 | C15: =C13-C14 | D15: =D13-D14 | E15: =E13-E14 | F15: =F13-F14 | G15: =G13-G14 | H15: =H13-H14 | I15: =I13-I14 | ... N15: =N13-N14
A16: Basic Earnings (Loss) per Share | B16: 3.08 | C16: 4.11 | D16: 6.07 | E16: 1.4 | F16: 3.4 | G16: 5.64 | H16: 1.49 | I16: 3.73 | J16: 5.86 | K16: 1.34 | L16: 2.26 | M16: 4.16 | N16: 1.7
A17: Diluted Earnings (Loss) per Share | B17: 3.06 | C17: 4.09 | D17: 6.04 | E17: 1.4 | F17: 3.38 | G17: 5.62 | H17: 1.48 | I17: 3.71 | J17: 5.84 | K17: 1.33 | L17: 2.25 | M17: 4.15 | N17: 1.7
A18: Weighted Average Shares Outstanding (Basic) | B18: 1383000000 | C18: 1383000000 | D18: 1382000000 | E18: 1378000000 | F18: 1378000000 | G18: 1377000000 | H18: 1375000000 | I18: 1375000000 | J18: 1374000000 | K18: 1372000000 | L18: 1371000000 | M18: 1370000000 | N18: 1367000000
A19: Weighted Average Shares Outstanding (Diluted) | B19: 1391000000 | C19: 1390000000 | D19: 1389000000 | E19: 1384000000 | F19: 1384000000 | G19: 1384000000 | H19: 1380000000 | I19: 1380000000 | J19: 1379000000 | K19: 1376000000 | L19: 1374000000 | M19: 1373000000 | N19: 1371000000

Sheet YTD BS
B1: Q4 FY2022 | C1: Q1 FY2023 | D1: Q2 FY2023 | E1: Q3 FY2023 | F1: Q4 FY2023 | G1: Q1 FY2024 | H1: Q2 FY2024 | I1: Q3 FY2024 | J1: Q4 FY2024 | K1: Q1 FY2025 | L1: Q2 FY2025 | M1: Q3 FY2025 | N1: Q4 FY2025 | O1: Q1 FY2026
A2: Cash & Cash Equivalents | B2: 4954 | C2: 4770 | D2: 6116 | E2: 10017 | F2: 9711 | G2: 8047 | H2: 6353 | I2: 7308 | J2: 8505 | K2: 8268 | L2: 7631 | M2: 8126 | N2: 9159 | O2: 10475
A3: Short-Term Investments | B3: 394 | C3: 434 | D3: 338 | E3: 266 | F3: 292 | G3: 303 | H3: 315 | I3: 743 | J3: 761 | K3: 314 | L3: 342 | M3: 535 | N3: 371 | O3: 353
A4: Accounts Receivable | B4: 10163 | C4: 10469 | D4: 11456 | E4: 11782 | F4: 10815 | G4: 10938 | H4: 11942 | I4: 12088 | J4: 10333 | K4: 10800 | L4: 12390 | M4: 12634 | N4: 11506 | O4: 12171
A5: Inventories | B5: 5222 | C5: 5697 | D5: 5969 | E5: 5558 | F5: 5334 | G5: 5569 | H5: 5887 | I5: 5644 | J5: 5306 | K5: 5660 | L5: 6487 | M5: 6093 | N5: 5845 | O5: 6211
A6: Prepaid Expenses | B6: 806 | C6: 1057 | D6: 1075 | E6: 1026 | F6: 798 | G6: 1148 | H6: 1206 | I6: 1069 | J6: 921 | K6: 1246 | L6: 1360 | M6: 1334 | N6: 1068 | O6: 1706
A7: Total Current Assets | B7: =SUM(B2:B6) | C7: =SUM(C2:C6) | D7: =SUM(D2:D6) | E7: =SUM(E2:E6) | F7: =SUM(F2:F6) | G7: =SUM(G2:G6) | H7: =SUM(H2:H6) | I7: =SUM(I2:I6) | ... O7: =SUM(O2:O6)
A8: Net PP&E | B8: 24291 | C8: 24228 | D8: 24500 | E8: 24853 | F8: 27039 | G8: 26792 | H8: 27042 | I8: 27188 | J8: 28008 | K8: 28213 | L8: 28797 | M8: 29053 | N8: 29905 | O8: 29807
A9: Intangible Assets | B9: 15586 | C9: 15523 | D9: 15562 | E9: 15501 | F9: 14929 | G9: 14853 | H9: 14826 | I9: 14857 | J9: 14801 | K9: 15363 | L9: 15523 | M9: 14852 | N9: 15066 | O9: 15143
A10: Goodwill | B10: 18202 | C10: 18089 | D10: 17997 | E10: 17892 | F10: 17728 | G10: 17646 | H10: 17648 | I10: 17709 | J10: 17534 | K10: 18364 | L10: 18952 | M10: 18845 | N10: 18916 | O10: 19021
A11: Equity Method Investments | B11: 3073 | C11: 3123 | D11: 3038 | E11: 2955 | F11: 2714 | G11: 2734 | H11: 2674 | I11: 2645 | J11: 1985 | K11: 1996 | L11: 2061 | M11: 2084 | N11: 2038 | O11: 2135
A12: Deferred Tax Assets | B12: 4204 | C12: 4211 | D12: 4186 | E12: 4165 | F12: 4474 | G12: 4444 | H12: 4465 | I12: 4321 | J12: 4362 | K12: 4350 | L12: 4293 | M12: 4341 | N12: 4541 | O12: 4560
A13: Other Non-Current Assets | B13: 5292 | C13: 5441 | D13: 5669 | E13: 5938 | F13: 6661 | G13: 7566 | H13: 7175 | I13: 6941 | J13: 6951 | K13: 7163 | L13: 7509 | M13: 8661 | N13: 8984 | O13: 9064
A14: Total Assets | B14: =B7+SUM(B8:B13) | C14: =C7+SUM(C8:C13) | D14: =D7+SUM(D8:D13) | E14: =E7+SUM(E8:E13) | F14: =F7+SUM(F8:F13) | G14: =G7+SUM(G8:G13) | H14: =H7+SUM(H8:H13) | I14: =I7+SUM(I8:I13) | ... O14: =O7+SUM(O8:O13)
A15: Short-Term Debt Obligations | B15: 3414 | C15: 4281 | D15: 7613 | E15: 8937 | F15: 6510 | G15: 8161 | H15: 8289 | I15: 6524 | J15: 7082 | K15: 9099 | L15: 12056 | M15: 6736 | N15: 6861 | O15: 10151
A16: Accrued Expenses | B16: 23371 | C16: 21556 | D16: 22005 | E16: 23723 | F16: 25137 | G16: 22073 | H16: 22859 | I16: 23791 | J16: 24454 | K16: 22412 | L16: 24340 | M16: 24763 | N16: 25903 | O16: 24326
A17: Total Current Liabilities | B17: =SUM(B15:B16) | C17: =SUM(C15:C16) | D17: =SUM(D15:D16) | E17: =SUM(E15:E16) | F17: =SUM(F15:F16) | G17: =SUM(G15:G16) | H17: =SUM(H15:H16) | I17: =SUM(I15:I16) | ... O17: =SUM(O15:O16)
A18: Long-Term Debt | B18: 35657 | C18: 37486 | D18: 36008 | E18: 35837 | F18: 37595 | G18: 37707 | H18: 36638 | I18: 38490 | J18: 37224 | K18: 39419 | L18: 39328 | M18: 44113 | N18: 42321 | O18: 42577
A19: Deferred Tax Liability | B19: 4133 | C19: 4039 | D19: 4113 | E19: 4047 | F19: 3895 | G19: 4087 | H19: 3908 | I19: 3684 | J19: 3484 | K19: 3541 | L19: 3102 | M19: 3474 | N19: 3802 | O19: 4048
A20: Other Non-Current Liabilities | B20: 8339 | C20: 8505 | D20: 8342 | E20: 8439 | F20: 8721 | G20: 8822 | H20: 8259 | I20: 8419 | J20: 9052 | K20: 8737 | L20: 7960 | M20: 7929 | N20: 7965 | O20: 8008
A21: Total Liabilities | B21: =B17+SUM(B18:B20) | C21: =C17+SUM(C18:C20) | D21: =D17+SUM(D18:D20) | E21: =E17+SUM(E18:E20) | F21: =F17+SUM(F18:F20) | G21: =G17+SUM(G18:G20) | H21: =H17+SUM(H18:H20) | I21: =I17+SUM(I18:I20) | ... O21: =O17+SUM(O18:O20)
A22: Common Stock | B22: 23 | C22: 23 | D22: 23 | E22: 23 | F22: 23 | G22: 23 | H22: 23 | I22: 23 | J22: 23 | K22: 23 | L22: 23 | M22: 23 | N22: 23 | O22: 23
A23: Additional Paid-in Capital | B23: 4134 | C23: 3996 | D23: 4082 | E23: 4154 | F23: 4261 | G23: 4132 | H23: 4203 | I23: 4281 | J23: 4385 | K23: 4274 | L23: 4299 | M23: 4374 | N23: 4451 | O23: 4401
A24: Retained Earnings (Accumulated Deficit) | B24: 67800 | C24: 68142 | D24: 69135 | E24: 70479 | F24: 70035 | G24: 70331 | H24: 71545 | I24: 72607 | J24: 72266 | K24: 72238 | L24: 71547 | M24: 72197 | N24: 72788 | O24: 73165
A25: Accumulated Other Comprehensive Income (Loss) | B25: -15302 | C25: -15601 | D25: -15780 | E25: -15794 | F25: -15534 | G25: -15179 | H25: -15786 | I25: -16652 | J25: -17612 | K25: -17078 | L25: -16090 | M25: -15597 | N25: -15024 | O25: -14342
A26: Treasury Stock | B26: -39506 | C26: -39518 | D26: -39775 | E26: -40056 | F26: -40282 | G26: -40260 | H26: -40539 | I26: -40806 | J26: -41021 | K26: -41068 | L26: -41361 | M26: -41609 | N26: -41832 | O26: -41864
A27: Noncontrolling Interest | B27: 124 | C27: 133 | D27: 140 | E27: 164 | F27: 134 | G27: 143 | H27: 134 | I27: 152 | J27: 130 | K27: 140 | L27: 141 | M27: 155 | N27: 141 | O27: 153
A28: Total Stockholders' Equity | B28: =SUM(B22:B27) | C28: =SUM(C22:C27) | D28: =SUM(D22:D27) | E28: =SUM(E22:E27) | F28: =SUM(F22:F27) | G28: =SUM(G22:G27) | H28: =SUM(H22:H27) | I28: =SUM(I22:I27) | ... O28: =SUM(O22:O27)
A29: Total Liabilities, Mezzanine & Stockholders' Equity | B29: =B21+B28 | C29: =C21+C28 | D29: =D21+D28 | E29: =E21+E28 | F29: =F21+F28 | G29: =G21+G28 | H29: =H21+H28 | I29: =I21+I28 | ... O29: =O21+O28

Sheet YTD CF
B1: Q1 FY2022 | C1: Q2 FY2022 | D1: Q3 FY2022 | E1: Q1 FY2023 | F1: Q2 FY2023 | G1: Q3 FY2023 | H1: Q1 FY2024 | I1: Q2 FY2024 | J1: Q3 FY2024 | K1: Q1 FY2025 | L1: Q2 FY2025 | M1: Q3 FY2025 | N1: Q1 FY2026
A2: Net Income (Loss) | B2: 4273 | C2: 5719 | D2: 8443 | E2: 1944 | F2: 4715 | G2: 7831 | H2: 2053 | I2: 5147 | J2: 8092 | K2: 1843 | L2: 3122 | M2: 5740 | N2: 2338
A3: Depreciation & Amortization | B3: 555 | C3: 1195 | D3: 1854 | E3: 590 | F3: 1268 | G3: 1973 | H3: 641 | I3: 1379 | J3: 2118 | K3: 684 | L3: 1491 | M3: 2315 | N3: 742
A4: Gain on Juice Transaction | B4: -3322 | C4: -3335 | D4: -3321 | E4: 0 | F4: 0 | G4: 0 | H4: 0 | I4: 0 | J4: 0 | K4: 0 | L4: 0 | M4: 0 | N4: 0
A5: Impairment and Other Charges | B5: 482 | C5: 1871 | D5: 1877 | E5: -13 | F5: 97 | G5: 102 | H5: 0 | I5: 0 | J5: 10 | K5: 0 | L5: 1860 | M5: 1960 | N5: 0
A6: Product Recall Impact | B6: 0 | C6: 0 | D6: 0 | E6: 0 | F6: 0 | G6: 0 | H6: 167 | I6: 182 | J6: 184 | K6: 0 | L6: 0 | M6: 0 | N6: 0
A7: Cash Payments for Product Recall | B7: 0 | C7: 0 | D7: 0 | E7: 0 | F7: 0 | G7: 0 | H7: -108 | I7: -135 | J7: -138 | K7: -2 | L7: -2 | M7: -5 | N7: 0
A8: Operating Lease ROU Asset Amortization | B8: 103 | C8: 223 | D8: 346 | E8: 116 | F8: 248 | G8: 384 | H8: 127 | I8: 278 | J8: 438 | K8: 145 | L8: 315 | M8: 489 | N8: 162
A9: Stock-Based Compensation | B9: 81 | C9: 156 | D9: 233 | E9: 93 | F9: 179 | G9: 267 | H9: 97 | I9: 183 | J9: 260 | K9: 77 | L9: 131 | M9: 207 | N9: 93
A10: Restructuring and Asset Impairment Charges | B10: 27 | C10: 75 | D10: 126 | E10: 112 | F10: 204 | G10: 287 | H10: 96 | I10: 170 | J10: 415 | K10: 213 | L10: 426 | M10: 567 | N10: 133
A11: Cash Payments for Restructuring | B11: -32 | C11: -82 | D11: -134 | E11: -64 | F11: -187 | G11: -283 | H11: -60 | I11: -173 | J11: -284 | K11: -232 | L11: -387 | M11: -554 | N11: -145
A12: Acquisition and Divestiture-Related Charges | B12: 56 | C12: 64 | D12: 69 | E12: 2 | F12: 9 | G12: 20 | H12: 0 | I12: 0 | J12: 0 | K12: 0 | L12: 0 | M12: 308 | N12: -113
A13: Cash Payments for Acquisition and Divestiture Costs | B13: -17 | C13: -34 | D13: -41 | E13: -4 | F13: -10 | G13: -15 | H13: 0 | I13: 0 | J13: 0 | K13: 0 | L13: 0 | M13: -80 | N13: -14
... A24: Other Operating Items | B24: -133 | C24: -325 | D24: -426 | E24: 46 | F24: -6 | G24: 72 | H24: -68 | I24: -203 | J24: -135 | K24: -232 | L24: -269 | M24: -441 | N24: -157
A25: Cash Flow from Operations | B25: =SUM(B2:B24) | C25: =SUM(C2:C24) | D25: =SUM(D2:D24) | E25: =SUM(E2:E24) | F25: =SUM(F2:F24) | G25: =SUM(G2:G24) | H25: =SUM(H2:H24) | I25: =SUM(I2:I24) | ... N25: =SUM(N2:N24)
A26: Purchase of PP&E | B26: -522 | C26: -1499 | D26: -2556 | E26: -581 | F26: -1513 | G26: -2537 | H26: -614 | I26: -1701 | J26: -2850 | K26: -603 | L26: -1507 | M26: -2499 | N26: -447
A27: Proceeds from Sale of Assets | B27: 3 | C27: 222 | D27: 228 | E27: 19 | F27: 122 | G27: 131 | H27: 7 | I27: 127 | J27: 177 | K27: 132 | L27: 169 | M27: 272 | N27: 13
A28: Acquisitions, Net of Cash Acquired | B28: -13 | C28: -29 | D28: -804 | E28: -16 | F28: -83 | G28: -132 | H28: -6 | I28: -30 | J28: -31 | K28: -1200 | L28: -3130 | M28: -3176 | N28: -67
A29: Proceeds from Juice Transaction | B29: 3456 | C29: 3456 | D29: 3456 | E29: 0 | F29: 0 | G29: 0 | H29: 0 | I29: 0 | J29: 0 | K29: 0 | L29: 0 | M29: 0 | N29: 0
A30: Proceeds from Divestitures of Businesses | B30: 5 | C30: 15 | D30: 15 | E30: 85 | F30: 75 | G30: 75 | H30: 53 | I30: 135 | J30: 145 | K30: 2 | L30: 5 | M30: 5 | N30: 0
A31: Net Change in Short-Term Investments | B31: 22 | C31: 8 | D31: -37 | E31: -39 | F31: -56 | G31: 35 | H31: 8 | I31: 1 | J31: -421 | K31: 441 | L31: 447 | M31: 278 | N31: 5
A32: Other Investing Activities | B32: 4 | C32: -1 | D32: 7 | E32: 0 | F32: 32 | G32: 49 | H32: -10 | I32: 14 | J32: 15 | K32: -4 | L32: -111 | M32: -117 | N32: 19
A33: Cash Flow from Investing | B33: =SUM(B26:B32) | C33: =SUM(C26:C32) | D33: =SUM(D26:D32) | E33: =SUM(E26:E32) | F33: =SUM(F26:F32) | G33: =SUM(G26:G32) | H33: =SUM(H26:H32) | I33: =SUM(I26:I32) | ... N33: =SUM(N26:N32)
A34: Proceeds from Issuance of Long-Term Debt | B34: 0 | C34: 0 | D34: 3377 | E34: 2986 | F34: 2986 | G34: 2986 | H34: 1761 | I34: 1765 | J34: 4014 | K34: 3505 | L34: 3521 | M34: 8179 | N34: 2964
A35: Repayments of Long-Term Debt | B35: -1251 | C35: -3202 | D35: -3203 | E35: -1251 | F35: -2252 | G35: -2253 | H35: -1252 | I35: -2882 | J35: -2883 | K35: -1541 | L35: -2543 | M35: -3245 | N35: -1629
A36: Proceeds from Short-Term Debt | B36: 559 | C36: 1935 | D36: 1947 | E36: 393 | F36: 1660 | G36: 4688 | H36: 2313 | I36: 3080 | J36: 3808 | K36: 3656 | L36: 5251 | M36: 5528 | N36: 1937
A37: Repayments of Short-Term Debt | B37: 0 | C37: 0 | D37: -1932 | E37: -1 | F37: -26 | G37: -1037 | H37: -1631 | I37: -2138 | J37: -4177 | K37: -2119 | L37: -2492 | M37: -5417 | N37: -676
A38: Net Change in Other Short-Term Debt | B38: 647 | C38: 844 | D38: -45 | E38: 491 | F38: 2023 | G38: 1395 | H38: 774 | I38: 1286 | J38: 101 | K38: 373 | L38: 2438 | M38: 445 | N38: 1198
A39: Common Dividends | B39: -1505 | C39: -2997 | D39: -4586 | E39: -1608 | F39: -3199 | G39: -4941 | H39: -1767 | I39: -3506 | J39: -5369 | K39: -1882 | L39: -3743 | M39: -5692 | N39: -1966
A40: Share Repurchases | B40: -193 | C40: -699 | D40: -1156 | E40: -160 | F40: -453 | G40: -751 | H40: -146 | I40: -461 | J40: -760 | K40: -183 | L40: -494 | M40: -752 | N40: -182
A41: Proceeds from Exercise of Stock Options | B41: 49 | C41: 89 | D41: 113 | E41: 46 | F41: 86 | G41: 100 | H41: 66 | I41: 107 | J41: 138 | K41: 50 | L41: 58 | M41: 76 | N41: 93
A42: Tax Withholdings on RSU/PSU Settlement | B42: -85 | C42: -87 | D42: -97 | E42: -116 | F42: -119 | G42: -135 | H42: -108 | I42: -131 | J42: -132 | K42: -89 | L42: -111 | M42: -112 | N42: -76
A43: Other Financing Activities | B43: -1 | C43: -15 | D43: -25 | E43: -3 | F43: -16 | G43: -18 | H43: 0 | I43: -20 | J43: -22 | K43: -2 | L43: -17 | M43: -18 | N43: -1
A44: Cash Flow from Financing | B44: =SUM(B34:B43) | C44: =SUM(C34:C43) | D44: =SUM(D34:D43) | E44: =SUM(E34:E43) | F44: =SUM(F34:F43) | G44: =SUM(G34:G43) | H44: =SUM(H34:H43) | I44: =SUM(I34:I43) | ... N44: =SUM(N34:N43)
A45: FX Effect on Cash | B45: -17 | C45: -83 | D45: -197 | E45: -116 | F45: -144 | G45: -254 | H45: -38 | I45: -304 | J45: -391 | K45: 203 | L45: 422 | M45: 395 | N45: 121
A46: Net Change in Cash | B46: =B25+B33+B44+B45 | C46: =C25+C33+C44+C45 | D46: =D25+D33+D44+D45 | E46: =E25+E33+E44+E45 | F46: =F25+F33+F44+F45 | G46: =G25+G33+G44+G45 | H46: =H25+H33+H44+H45 | I46: =I25+I33+I44+I45 | ... N46: =N25+N33+N44+N45

Sheet QTR P&L
B1: Q1 FY2022 | C1: Q2 FY2022 | D1: Q3 FY2022 | E1: Q4 FY2022 | F1: Q1 FY2023 | G1: Q2 FY2023 | H1: Q3 FY2023 | I1: Q4 FY2023 | J1: Q1 FY2024 | K1: Q2 FY2024 | L1: Q3 FY2024 | M1: Q4 FY2024 | N1: Q1 FY2025 | O1: Q2 FY2025 | P1: Q3 FY2025 | Q1: Q4 FY2025 | R1: Q1 FY2026 | S1: Q2 FY2026E | T1: Q3 FY2026E | U1: Q4 FY2026E | V1: Q1 FY2027E | W1: Q2 FY2027E | X1: Q3 FY2027E | Y1: Q4 FY2027E | Z1: Q1 FY2028E | AA1: Q2 FY2028E | AB1: Q3 FY2028E | AC1: Q4 FY2028E | AD1: Q1 FY2029E | AE1: Q2 FY2029E | AF1: Q3 FY2029E | AG1: Q4 FY2029E | AH1: Q1 FY2030E | AI1: Q2 FY2030E | AJ1: Q3 FY2030E | AK1: Q4 FY2030E
A2: Net Sales / Revenue | B2: ='YTD P&L'!B2 | C2: ='YTD P&L'!C2-'YTD P&L'!B2 | D2: ='YTD P&L'!D2-'YTD P&L'!C2 | E2: ='ANNL P&L'!C2-'YTD P&L'!D2 | F2: ='YTD P&L'!E2 | G2: ='YTD P&L'!F2-'YTD P&L'!E2 | H2: ='YTD P&L'!G2-'YTD P&L'!F2 | I2: ='ANNL P&L'!D2-'YTD P&L'!G2 | J2: ='YTD P&L'!H2 | K2: ='YTD P&L'!I2-'YTD P&L'!H2 | L2: ='YTD P&L'!J2-'YTD P&L'!I2 | M2: ='ANNL P&L'!E2-'YTD P&L'!J2 | N2: ='YTD P&L'!K2 | O2: ='YTD P&L'!L2-'YTD P&L'!K2 | P2: ='YTD P&L'!M2-'YTD P&L'!L2 | Q2: ='ANNL P&L'!F2-'YTD P&L'!M2 | R2: ='YTD P&L'!N2 | S2: ='QTR P&L'!O2*(1+'IS DRIVERS'!S2) | T2: ='QTR P&L'!P2*(1+'IS DRIVERS'!T2) | U2: ='QTR P&L'!Q2*(1+'IS DRIVERS'!U2) | V2: ='QTR P&L'!R2*(1+'IS DRIVERS'!V2) | W2: ='QTR P&L'!S2*(1+'IS DRIVERS'!W2) | X2: ='QTR P&L'!T2*(1+'IS DRIVERS'!X2) | Y2: ='QTR P&L'!U2*(1+'IS DRIVERS'!Y2) | Z2: ='QTR P&L'!V2*(1+'IS DRIVERS'!Z2) | ... AK2: ='QTR P&L'!AG2*(1+'IS DRIVERS'!AK2)
A3: COGS | B3: ='YTD P&L'!B3 | C3: ='YTD P&L'!C3-'YTD P&L'!B3 | D3: ='YTD P&L'!D3-'YTD P&L'!C3 | E3: ='ANNL P&L'!C3-'YTD P&L'!D3 | F3: ='YTD P&L'!E3 | G3: ='YTD P&L'!F3-'YTD P&L'!E3 | H3: ='YTD P&L'!G3-'YTD P&L'!F3 | I3: ='ANNL P&L'!D3-'YTD P&L'!G3 | J3: ='YTD P&L'!H3 | K3: ='YTD P&L'!I3-'YTD P&L'!H3 | L3: ='YTD P&L'!J3-'YTD P&L'!I3 | M3: ='ANNL P&L'!E3-'YTD P&L'!J3 | N3: ='YTD P&L'!K3 | O3: ='YTD P&L'!L3-'YTD P&L'!K3 | P3: ='YTD P&L'!M3-'YTD P&L'!L3 | Q3: ='ANNL P&L'!F3-'YTD P&L'!M3 | R3: ='YTD P&L'!N3 | S3: ='QTR P&L'!S2*'IS DRIVERS'!S3 | T3: ='QTR P&L'!T2*'IS DRIVERS'!T3 | U3: ='QTR P&L'!U2*'IS DRIVERS'!U3 | V3: ='QTR P&L'!V2*'IS DRIVERS'!V3 | W3: ='QTR P&L'!W2*'IS DRIVERS'!W3 | X3: ='QTR P&L'!X2*'IS DRIVERS'!X3 | Y3: ='QTR P&L'!Y2*'IS DRIVERS'!Y3 | Z3: ='QTR P&L'!Z2*'IS DRIVERS'!Z3 | ... AK3: ='QTR P&L'!AK2*'IS DRIVERS'!AK3
A4: Gross Profit (Loss) | B4: ='YTD P&L'!B4 | C4: ='YTD P&L'!C4-'YTD P&L'!B4 | D4: ='YTD P&L'!D4-'YTD P&L'!C4 | E4: ='ANNL P&L'!C4-'YTD P&L'!D4 | F4: ='YTD P&L'!E4 | G4: ='YTD P&L'!F4-'YTD P&L'!E4 | H4: ='YTD P&L'!G4-'YTD P&L'!F4 | I4: ='ANNL P&L'!D4-'YTD P&L'!G4 | J4: ='YTD P&L'!H4 | K4: ='YTD P&L'!I4-'YTD P&L'!H4 | L4: ='YTD P&L'!J4-'YTD P&L'!I4 | M4: ='ANNL P&L'!E4-'YTD P&L'!J4 | N4: ='YTD P&L'!K4 | O4: ='YTD P&L'!L4-'YTD P&L'!K4 | P4: ='YTD P&L'!M4-'YTD P&L'!L4 | Q4: ='ANNL P&L'!F4-'YTD P&L'!M4 | R4: ='YTD P&L'!N4 | S4: =S2+S3 | T4: =T2+T3 | U4: =U2+U3 | V4: =V2+V3 | W4: =W2+W3 | X4: =X2+X3 | Y4: =Y2+Y3 | Z4: =Z2+Z3 | ... AK4: =AK2+AK3
A5: SG&A | B5: ='YTD P&L'!B5 | C5: ='YTD P&L'!C5-'YTD P&L'!B5 | D5: ='YTD P&L'!D5-'YTD P&L'!C5 | E5: ='ANNL P&L'!C5-'YTD P&L'!D5 | F5: ='YTD P&L'!E5 | G5: ='YTD P&L'!F5-'YTD P&L'!E5 | H5: ='YTD P&L'!G5-'YTD P&L'!F5 | I5: ='ANNL P&L'!D5-'YTD P&L'!G5 | J5: ='YTD P&L'!H5 | K5: ='YTD P&L'!I5-'YTD P&L'!H5 | L5: ='YTD P&L'!J5-'YTD P&L'!I5 | M5: ='ANNL P&L'!E5-'YTD P&L'!J5 | N5: ='YTD P&L'!K5 | O5: ='YTD P&L'!L5-'YTD P&L'!K5 | P5: ='YTD P&L'!M5-'YTD P&L'!L5 | Q5: ='ANNL P&L'!F5-'YTD P&L'!M5 | R5: ='YTD P&L'!N5 | S5: ='QTR P&L'!S2*'IS DRIVERS'!S4 | T5: ='QTR P&L'!T2*'IS DRIVERS'!T4 | U5: ='QTR P&L'!U2*'IS DRIVERS'!U4 | V5: ='QTR P&L'!V2*'IS DRIVERS'!V4 | W5: ='QTR P&L'!W2*'IS DRIVERS'!W4 | X5: ='QTR P&L'!X2*'IS DRIVERS'!X4 | Y5: ='QTR P&L'!Y2*'IS DRIVERS'!Y4 | Z5: ='QTR P&L'!Z2*'IS DRIVERS'!Z4 | ... AK5: ='QTR P&L'!AK2*'IS DRIVERS'!AK4
A6: Gain on Juice Transaction | B6: ='YTD P&L'!B6 | C6: ='YTD P&L'!C6-'YTD P&L'!B6 | D6: ='YTD P&L'!D6-'YTD P&L'!C6 | E6: ='ANNL P&L'!C6-'YTD P&L'!D6 | F6: ='YTD P&L'!E6 | G6: ='YTD P&L'!F6-'YTD P&L'!E6 | H6: ='YTD P&L'!G6-'YTD P&L'!F6 | I6: ='ANNL P&L'!D6-'YTD P&L'!G6 | J6: ='YTD P&L'!H6 | K6: ='YTD P&L'!I6-'YTD P&L'!H6 | L6: ='YTD P&L'!J6-'YTD P&L'!I6 | M6: ='ANNL P&L'!E6-'YTD P&L'!J6 | N6: ='YTD P&L'!K6 | O6: ='YTD P&L'!L6-'YTD P&L'!K6 | P6: ='YTD P&L'!M6-'YTD P&L'!L6 | Q6: ='ANNL P&L'!F6-'YTD P&L'!M6 | R6: ='YTD P&L'!N6 | S6: ='IS DRIVERS'!S5 | T6: ='IS DRIVERS'!T5 | U6: ='IS DRIVERS'!U5 | V6: ='IS DRIVERS'!V5 | W6: ='IS DRIVERS'!W5 | X6: ='IS DRIVERS'!X5 | Y6: ='IS DRIVERS'!Y5 | Z6: ='IS DRIVERS'!Z5 | ... AK6: ='IS DRIVERS'!AK5
A7: Impairment of Intangibles | B7: ='YTD P&L'!B7 | C7: ='YTD P&L'!C7-'YTD P&L'!B7 | D7: ='YTD P&L'!D7-'YTD P&L'!C7 | E7: ='ANNL P&L'!C7-'YTD P&L'!D7 | F7: ='YTD P&L'!E7 | G7: ='YTD P&L'!F7-'YTD P&L'!E7 | H7: ='YTD P&L'!G7-'YTD P&L'!F7 | I7: ='ANNL P&L'!D7-'YTD P&L'!G7 | J7: ='YTD P&L'!H7 | K7: ='YTD P&L'!I7-'YTD P&L'!H7 | L7: ='YTD P&L'!J7-'YTD P&L'!I7 | M7: ='ANNL P&L'!E7-'YTD P&L'!J7 | N7: ='YTD P&L'!K7 | O7: ='YTD P&L'!L7-'YTD P&L'!K7 | P7: ='YTD P&L'!M7-'YTD P&L'!L7 | Q7: ='ANNL P&L'!F7-'YTD P&L'!M7 | R7: ='YTD P&L'!N7 | S7: ='QTR P&L'!S2*'IS DRIVERS'!S6 | T7: ='QTR P&L'!T2*'IS DRIVERS'!T6 | U7: ='QTR P&L'!U2*'IS DRIVERS'!U6 | V7: ='QTR P&L'!V2*'IS DRIVERS'!V6 | W7: ='QTR P&L'!W2*'IS DRIVERS'!W6 | X7: ='QTR P&L'!X2*'IS DRIVERS'!X6 | Y7: ='QTR P&L'!Y2*'IS DRIVERS'!Y6 | Z7: ='QTR P&L'!Z2*'IS DRIVERS'!Z6 | ... AK7: ='QTR P&L'!AK2*'IS DRIVERS'!AK6
A8: Income (Loss) from Operations | B8: ='YTD P&L'!B8 | C8: ='YTD P&L'!C8-'YTD P&L'!B8 | D8: ='YTD P&L'!D8-'YTD P&L'!C8 | E8: ='ANNL P&L'!C8-'YTD P&L'!D8 | F8: ='YTD P&L'!E8 | G8: ='YTD P&L'!F8-'YTD P&L'!E8 | H8: ='YTD P&L'!G8-'YTD P&L'!F8 | I8: ='ANNL P&L'!D8-'YTD P&L'!G8 | J8: ='YTD P&L'!H8 | K8: ='YTD P&L'!I8-'YTD P&L'!H8 | L8: ='YTD P&L'!J8-'YTD P&L'!I8 | M8: ='ANNL P&L'!E8-'YTD P&L'!J8 | N8: ='YTD P&L'!K8 | O8: ='YTD P&L'!L8-'YTD P&L'!K8 | P8: ='YTD P&L'!M8-'YTD P&L'!L8 | Q8: ='ANNL P&L'!F8-'YTD P&L'!M8 | R8: ='YTD P&L'!N8 | S8: =S4+SUM(S5:S7) | T8: =T4+SUM(T5:T7) | U8: =U4+SUM(U5:U7) | V8: =V4+SUM(V5:V7) | W8: =W4+SUM(W5:W7) | X8: =X4+SUM(X5:X7) | Y8: =Y4+SUM(Y5:Y7) | Z8: =Z4+SUM(Z5:Z7) | ... AK8: =AK4+SUM(AK5:AK7)
A9: Other Pension and OPEB Benefits Income (Expense) | B9: ='YTD P&L'!B9 | C9: ='YTD P&L'!C9-'YTD P&L'!B9 | D9: ='YTD P&L'!D9-'YTD P&L'!C9 | E9: ='ANNL P&L'!C9-'YTD P&L'!D9 | F9: ='YTD P&L'!E9 | G9: ='YTD P&L'!F9-'YTD P&L'!E9 | H9: ='YTD P&L'!G9-'YTD P&L'!F9 | I9: ='ANNL P&L'!D9-'YTD P&L'!G9 | J9: ='YTD P&L'!H9 | K9: ='YTD P&L'!I9-'YTD P&L'!H9 | L9: ='YTD P&L'!J9-'YTD P&L'!I9 | M9: ='ANNL P&L'!E9-'YTD P&L'!J9 | N9: ='YTD P&L'!K9 | O9: ='YTD P&L'!L9-'YTD P&L'!K9 | P9: ='YTD P&L'!M9-'YTD P&L'!L9 | Q9: ='ANNL P&L'!F9-'YTD P&L'!M9 | R9: ='YTD P&L'!N9 | S9: ='IS DRIVERS'!S7 | T9: ='IS DRIVERS'!T7 | U9: ='IS DRIVERS'!U7 | V9: ='IS DRIVERS'!V7 | W9: ='IS DRIVERS'!W7 | X9: ='IS DRIVERS'!X7 | Y9: ='IS DRIVERS'!Y7 | Z9: ='IS DRIVERS'!Z7 | ... AK9: ='IS DRIVERS'!AK7
A10: Interest Income (Expense) | B10: ='YTD P&L'!B10 | C10: ='YTD P&L'!C10-'YTD P&L'!B10 | D10: ='YTD P&L'!D10-'YTD P&L'!C10 | E10: ='ANNL P&L'!C10-'YTD P&L'!D10 | F10: ='YTD P&L'!E10 | G10: ='YTD P&L'!F10-'YTD P&L'!E10 | H10: ='YTD P&L'!G10-'YTD P&L'!F10 | I10: ='ANNL P&L'!D10-'YTD P&L'!G10 | J10: ='YTD P&L'!H10 | K10: ='YTD P&L'!I10-'YTD P&L'!H10 | L10: ='YTD P&L'!J10-'YTD P&L'!I10 | M10: ='ANNL P&L'!E10-'YTD P&L'!J10 | N10: ='YTD P&L'!K10 | O10: ='YTD P&L'!L10-'YTD P&L'!K10 | P10: ='YTD P&L'!M10-'YTD P&L'!L10 | Q10: ='ANNL P&L'!F10-'YTD P&L'!M10 | R10: ='YTD P&L'!N10 | S10: ='IS DRIVERS'!S8 | T10: ='IS DRIVERS'!T8 | U10: ='IS DRIVERS'!U8 | V10: ='IS DRIVERS'!V8 | W10: ='IS DRIVERS'!W8 | X10: ='IS DRIVERS'!X8 | Y10: ='IS DRIVERS'!Y8 | Z10: ='IS DRIVERS'!Z8 | ... AK10: ='IS DRIVERS'!AK8
A11: Pre-Tax Income (Loss) | B11: ='YTD P&L'!B11 | C11: ='YTD P&L'!C11-'YTD P&L'!B11 | D11: ='YTD P&L'!D11-'YTD P&L'!C11 | E11: ='ANNL P&L'!C11-'YTD P&L'!D11 | F11: ='YTD P&L'!E11 | G11: ='YTD P&L'!F11-'YTD P&L'!E11 | H11: ='YTD P&L'!G11-'YTD P&L'!F11 | I11: ='ANNL P&L'!D11-'YTD P&L'!G11 | J11: ='YTD P&L'!H11 | K11: ='YTD P&L'!I11-'YTD P&L'!H11 | L11: ='YTD P&L'!J11-'YTD P&L'!I11 | M11: ='ANNL P&L'!E11-'YTD P&L'!J11 | N11: ='YTD P&L'!K11 | O11: ='YTD P&L'!L11-'YTD P&L'!K11 | P11: ='YTD P&L'!M11-'YTD P&L'!L11 | Q11: ='ANNL P&L'!F11-'YTD P&L'!M11 | R11: ='YTD P&L'!N11 | S11: =S8+SUM(S9:S10) | T11: =T8+SUM(T9:T10) | U11: =U8+SUM(U9:U10) | V11: =V8+SUM(V9:V10) | W11: =W8+SUM(W9:W10) | X11: =X8+SUM(X9:X10) | Y11: =Y8+SUM(Y9:Y10) | Z11: =Z8+SUM(Z9:Z10) | ... AK11: =AK8+SUM(AK9:AK10)
A12: Income Tax (Expense) Benefit | B12: ='YTD P&L'!B12 | C12: ='YTD P&L'!C12-'YTD P&L'!B12 | D12: ='YTD P&L'!D12-'YTD P&L'!C12 | E12: ='ANNL P&L'!C12-'YTD P&L'!D12 | F12: ='YTD P&L'!E12 | G12: ='YTD P&L'!F12-'YTD P&L'!E12 | H12: ='YTD P&L'!G12-'YTD P&L'!F12 | I12: ='ANNL P&L'!D12-'YTD P&L'!G12 | J12: ='YTD P&L'!H12 | K12: ='YTD P&L'!I12-'YTD P&L'!H12 | L12: ='YTD P&L'!J12-'YTD P&L'!I12 | M12: ='ANNL P&L'!E12-'YTD P&L'!J12 | N12: ='YTD P&L'!K12 | O12: ='YTD P&L'!L12-'YTD P&L'!K12 | P12: ='YTD P&L'!M12-'YTD P&L'!L12 | Q12: ='ANNL P&L'!F12-'YTD P&L'!M12 | R12: ='YTD P&L'!N12 | S12: ='QTR P&L'!S11*'IS DRIVERS'!S9 | T12: ='QTR P&L'!T11*'IS DRIVERS'!T9 | U12: ='QTR P&L'!U11*'IS DRIVERS'!U9 | V12: ='QTR P&L'!V11*'IS DRIVERS'!V9 | W12: ='QTR P&L'!W11*'IS DRIVERS'!W9 | X12: ='QTR P&L'!X11*'IS DRIVERS'!X9 | Y12: ='QTR P&L'!Y11*'IS DRIVERS'!Y9 | Z12: ='QTR P&L'!Z11*'IS DRIVERS'!Z9 | ... AK12: ='QTR P&L'!AK11*'IS DRIVERS'!AK9
A13: Net Income (Loss) | B13: ='YTD P&L'!B13 | C13: ='YTD P&L'!C13-'YTD P&L'!B13 | D13: ='YTD P&L'!D13-'YTD P&L'!C13 | E13: ='ANNL P&L'!C13-'YTD P&L'!D13 | F13: ='YTD P&L'!E13 | G13: ='YTD P&L'!F13-'YTD P&L'!E13 | H13: ='YTD P&L'!G13-'YTD P&L'!F13 | I13: ='ANNL P&L'!D13-'YTD P&L'!G13 | J13: ='YTD P&L'!H13 | K13: ='YTD P&L'!I13-'YTD P&L'!H13 | L13: ='YTD P&L'!J13-'YTD P&L'!I13 | M13: ='ANNL P&L'!E13-'YTD P&L'!J13 | N13: ='YTD P&L'!K13 | O13: ='YTD P&L'!L13-'YTD P&L'!K13 | P13: ='YTD P&L'!M13-'YTD P&L'!L13 | Q13: ='ANNL P&L'!F13-'YTD P&L'!M13 | R13: ='YTD P&L'!N13 | S13: =S11+S12 | T13: =T11+T12 | U13: =U11+U12 | V13: =V11+V12 | W13: =W11+W12 | X13: =X11+X12 | Y13: =Y11+Y12 | Z13: =Z11+Z12 | ... AK13: =AK11+AK12
A14: Net Income (Loss) Attributable to Noncontrolling Interest | B14: ='YTD P&L'!B14 | C14: ='YTD P&L'!C14-'YTD P&L'!B14 | D14: ='YTD P&L'!D14-'YTD P&L'!C14 | E14: ='ANNL P&L'!C14-'YTD P&L'!D14 | F14: ='YTD P&L'!E14 | G14: ='YTD P&L'!F14-'YTD P&L'!E14 | H14: ='YTD P&L'!G14-'YTD P&L'!F14 | I14: ='ANNL P&L'!D14-'YTD P&L'!G14 | J14: ='YTD P&L'!H14 | K14: ='YTD P&L'!I14-'YTD P&L'!H14 | L14: ='YTD P&L'!J14-'YTD P&L'!I14 | M14: ='ANNL P&L'!E14-'YTD P&L'!J14 | N14: ='YTD P&L'!K14 | O14: ='YTD P&L'!L14-'YTD P&L'!K14 | P14: ='YTD P&L'!M14-'YTD P&L'!L14 | Q14: ='ANNL P&L'!F14-'YTD P&L'!M14 | R14: ='YTD P&L'!N14 | S14: ='IS DRIVERS'!S10 | T14: ='IS DRIVERS'!T10 | U14: ='IS DRIVERS'!U10 | V14: ='IS DRIVERS'!V10 | W14: ='IS DRIVERS'!W10 | X14: ='IS DRIVERS'!X10 | Y14: ='IS DRIVERS'!Y10 | Z14: ='IS DRIVERS'!Z10 | ... AK14: ='IS DRIVERS'!AK10
A15: Net Income (Loss) Less NCI | B15: ='YTD P&L'!B15 | C15: ='YTD P&L'!C15-'YTD P&L'!B15 | D15: ='YTD P&L'!D15-'YTD P&L'!C15 | E15: ='ANNL P&L'!C15-'YTD P&L'!D15 | F15: ='YTD P&L'!E15 | G15: ='YTD P&L'!F15-'YTD P&L'!E15 | H15: ='YTD P&L'!G15-'YTD P&L'!F15 | I15: ='ANNL P&L'!D15-'YTD P&L'!G15 | J15: ='YTD P&L'!H15 | K15: ='YTD P&L'!I15-'YTD P&L'!H15 | L15: ='YTD P&L'!J15-'YTD P&L'!I15 | M15: ='ANNL P&L'!E15-'YTD P&L'!J15 | N15: ='YTD P&L'!K15 | O15: ='YTD P&L'!L15-'YTD P&L'!K15 | P15: ='YTD P&L'!M15-'YTD P&L'!L15 | Q15: ='ANNL P&L'!F15-'YTD P&L'!M15 | R15: ='YTD P&L'!N15
A16: Basic Earnings (Loss) per Share
A17: Diluted Earnings (Loss) per Share
A18: Weighted Average Shares Outstanding (Basic)
A19: Weighted Average Shares Outstanding (Diluted)

Sheet QTR BS
B1: Q4 FY2022 | C1: Q1 FY2023 | D1: Q2 FY2023 | E1: Q3 FY2023 | F1: Q4 FY2023 | G1: Q1 FY2024 | H1: Q2 FY2024 | I1: Q3 FY2024 | J1: Q4 FY2024 | K1: Q1 FY2025 | L1: Q2 FY2025 | M1: Q3 FY2025 | N1: Q4 FY2025 | O1: Q1 FY2026 | P1: Q2 FY2026E | Q1: Q3 FY2026E | R1: Q4 FY2026E | S1: Q1 FY2027E | T1: Q2 FY2027E | U1: Q3 FY2027E | V1: Q4 FY2027E | W1: Q1 FY2028E | X1: Q2 FY2028E | Y1: Q3 FY2028E | Z1: Q4 FY2028E | AA1: Q1 FY2029E | AB1: Q2 FY2029E | AC1: Q3 FY2029E | AD1: Q4 FY2029E | AE1: Q1 FY2030E | AF1: Q2 FY2030E | AG1: Q3 FY2030E | AH1: Q4 FY2030E
A2: Cash & Cash Equivalents | B2: ='BALANCE SHEET'!B2 | C2: ='YTD BS'!C2 | D2: ='YTD BS'!D2 | E2: ='YTD BS'!E2 | F2: ='BALANCE SHEET'!C2 | G2: ='YTD BS'!G2 | H2: ='YTD BS'!H2 | I2: ='YTD BS'!I2 | J2: ='BALANCE SHEET'!D2 | K2: ='YTD BS'!K2 | L2: ='YTD BS'!L2 | M2: ='YTD BS'!M2 | N2: ='BALANCE SHEET'!E2 | O2: ='YTD BS'!O2 | P2: ='BS DRIVERS'!P2 | Q2: ='BS DRIVERS'!Q2 | R2: ='BS DRIVERS'!R2 | S2: ='BS DRIVERS'!S2 | T2: ='BS DRIVERS'!T2 | U2: ='BS DRIVERS'!U2 | V2: ='BS DRIVERS'!V2 | W2: ='BS DRIVERS'!W2 | ... AH2: ='BS DRIVERS'!AH2
A3: Short-Term Investments | B3: ='BALANCE SHEET'!B3 | C3: ='YTD BS'!C3 | D3: ='YTD BS'!D3 | E3: ='YTD BS'!E3 | F3: ='BALANCE SHEET'!C3 | G3: ='YTD BS'!G3 | H3: ='YTD BS'!H3 | I3: ='YTD BS'!I3 | J3: ='BALANCE SHEET'!D3 | K3: ='YTD BS'!K3 | L3: ='YTD BS'!L3 | M3: ='YTD BS'!M3 | N3: ='BALANCE SHEET'!E3 | O3: ='YTD BS'!O3 | P3: ='BS DRIVERS'!P3 | Q3: ='BS DRIVERS'!Q3 | R3: ='BS DRIVERS'!R3 | S3: ='BS DRIVERS'!S3 | T3: ='BS DRIVERS'!T3 | U3: ='BS DRIVERS'!U3 | V3: ='BS DRIVERS'!V3 | W3: ='BS DRIVERS'!W3 | ... AH3: ='BS DRIVERS'!AH3
A4: Accounts Receivable | B4: ='BALANCE SHEET'!B4 | C4: ='YTD BS'!C4 | D4: ='YTD BS'!D4 | E4: ='YTD BS'!E4 | F4: ='BALANCE SHEET'!C4 | G4: ='YTD BS'!G4 | H4: ='YTD BS'!H4 | I4: ='YTD BS'!I4 | J4: ='BALANCE SHEET'!D4 | K4: ='YTD BS'!K4 | L4: ='YTD BS'!L4 | M4: ='YTD BS'!M4 | N4: ='BALANCE SHEET'!E4 | O4: ='YTD BS'!O4 | P4: ='QTR P&L'!S2*'BS DRIVERS'!P4/ASSUMPTIONS!$B$2 | Q4: ='QTR P&L'!T2*'BS DRIVERS'!Q4/ASSUMPTIONS!$B$2 | R4: ='QTR P&L'!U2*'BS DRIVERS'!R4/ASSUMPTIONS!$B$2 | S4: ='QTR P&L'!V2*'BS DRIVERS'!S4/ASSUMPTIONS!$B$2 | T4: ='QTR P&L'!W2*'BS DRIVERS'!T4/ASSUMPTIONS!$B$2 | U4: ='QTR P&L'!X2*'BS DRIVERS'!U4/ASSUMPTIONS!$B$2 | V4: ='QTR P&L'!Y2*'BS DRIVERS'!V4/ASSUMPTIONS!$B$2 | W4: ='QTR P&L'!Z2*'BS DRIVERS'!W4/ASSUMPTIONS!$B$2 | ... AH4: ='QTR P&L'!AK2*'BS DRIVERS'!AH4/ASSUMPTIONS!$B$2
A5: Inventories | B5: ='BALANCE SHEET'!B5 | C5: ='YTD BS'!C5 | D5: ='YTD BS'!D5 | E5: ='YTD BS'!E5 | F5: ='BALANCE SHEET'!C5 | G5: ='YTD BS'!G5 | H5: ='YTD BS'!H5 | I5: ='YTD BS'!I5 | J5: ='BALANCE SHEET'!D5 | K5: ='YTD BS'!K5 | L5: ='YTD BS'!L5 | M5: ='YTD BS'!M5 | N5: ='BALANCE SHEET'!E5 | O5: ='YTD BS'!O5 | P5: ='QTR P&L'!S3*'BS DRIVERS'!P5/ASSUMPTIONS!$B$2 | Q5: ='QTR P&L'!T3*'BS DRIVERS'!Q5/ASSUMPTIONS!$B$2 | R5: ='QTR P&L'!U3*'BS DRIVERS'!R5/ASSUMPTIONS!$B$2 | S5: ='QTR P&L'!V3*'BS DRIVERS'!S5/ASSUMPTIONS!$B$2 | T5: ='QTR P&L'!W3*'BS DRIVERS'!T5/ASSUMPTIONS!$B$2 | U5: ='QTR P&L'!X3*'BS DRIVERS'!U5/ASSUMPTIONS!$B$2 | V5: ='QTR P&L'!Y3*'BS DRIVERS'!V5/ASSUMPTIONS!$B$2 | W5: ='QTR P&L'!Z3*'BS DRIVERS'!W5/ASSUMPTIONS!$B$2 | ... AH5: ='QTR P&L'!AK3*'BS DRIVERS'!AH5/ASSUMPTIONS!$B$2
