Workbook

Sheet ASSUMPTIONS
A1: Assumption | B1: Value | C1: Note
A2: Days in Year | B2: 365 | C2: Used in DSO, DIO, DPO formulas
A3: Share Repurchases $ | B3: 0 | C3: Per-period repurchase assumption for projection

Sheet ANNL P&L
B1: FY2021 | C1: FY2022 | D1: FY2023 | E1: FY2024 | F1: FY2025 | G1: FY2025E | H1: FY2026E | I1: FY2027E | J1: FY2028E | K1: FY2029E | L1: FY2030E
A2: Net Sales / Revenue | B2: 79474 | C2: 86392 | D2: 91471 | E2: 91854 | F2: 93925 | G2: ='ANNL P&L'!F2*(1+'IS DRIVERS'!G2) | H2: ='ANNL P&L'!G2*(1+'IS DRIVERS'!H2) | I2: ='ANNL P&L'!H2*(1+'IS DRIVERS'!I2) | J2: ='ANNL P&L'!I2*(1+'IS DRIVERS'!J2) | K2: ='ANNL P&L'!J2*(1+'IS DRIVERS'!K2) | L2: ='ANNL P&L'!K2*(1+'IS DRIVERS'!L2)
A3: COGS | B3: -37075 | C3: -40576 | D3: -41881 | E3: -41744 | F3: -43066 | G3: ='IS DRIVERS'!G3*'ANNL P&L'!G2 | H3: ='IS DRIVERS'!H3*'ANNL P&L'!H2 | I3: ='IS DRIVERS'!I3*'ANNL P&L'!I2 | J3: ='IS DRIVERS'!J3*'ANNL P&L'!J2 | K3: ='IS DRIVERS'!K3*'ANNL P&L'!K2 | L3: ='IS DRIVERS'!L3*'ANNL P&L'!L2
A4: Gross Profit (Loss) | B4: =B2+B3 | C4: =C2+C3 | D4: =D2+D3 | E4: =E2+E3 | F4: =F2+F3 | G4: =G2+G3 | H4: =H2+H3 | I4: =I2+I3 | ... L4: =L2+L3
A5: SG&A | B5: -31237 | C5: -34459 | D5: -36677 | E5: -37190 | F5: -37368 | G5: ='IS DRIVERS'!G4*'ANNL P&L'!G2 | H5: ='IS DRIVERS'!H4*'ANNL P&L'!H2 | I5: ='IS DRIVERS'!I4*'ANNL P&L'!I2 | J5: ='IS DRIVERS'!J4*'ANNL P&L'!J2 | K5: ='IS DRIVERS'!K4*'ANNL P&L'!K2 | L5: ='IS DRIVERS'!L4*'ANNL P&L'!L2
A6: Gain on Juice Transaction | B6: 0 | C6: -3321 | D6: 0 | E6: 0 | F6: 0
A7: Impairment of Intangibles | B7: 0 | C7: -3166 | D7: -927 | E7: -33 | F7: -1993
A8: Income (Loss) from Operations | B8: =B4+SUM(B5:B7) | C8: =C4+SUM(C5:C7) | D8: =D4+SUM(D5:D7) | E8: =E4+SUM(E5:E7) | F8: =F4+SUM(F5:F7) | G8: =G4+SUM(G5:G7) | H8: =H4+SUM(H5:H7) | I8: =I4+SUM(I5:I7) | ... L8: =L4+SUM(L5:L7)
A9: Other Pension and OPEB Benefits Income (Expense) | B9: 522 | C9: 132 | D9: 250 | E9: -22 | F9: -133
A10: Interest Income (Expense) | B10: -1863 | C10: -939 | D10: -819 | E10: -919 | F10: -1121 | G10: ='IS DRIVERS'!G5 | H10: ='IS DRIVERS'!H5 | I10: ='IS DRIVERS'!I5 | J10: ='IS DRIVERS'!J5 | K10: ='IS DRIVERS'!K5 | L10: ='IS DRIVERS'!L5
A11: Pre-Tax Income (Loss) | B11: =B8+SUM(B9:B10) | C11: =C8+SUM(C9:C10) | D11: =D8+SUM(D9:D10) | E11: =E8+SUM(E9:E10) | F11: =F8+SUM(F9:F10) | G11: =G8+SUM(G9:G10) | H11: =H8+SUM(H9:H10) | I11: =I8+SUM(I9:I10) | ... L11: =L8+SUM(L9:L10)
A12: Income Tax (Expense) Benefit | B12: -2142 | C12: -1727 | D12: -2262 | E12: -2320 | F12: -1949
A13: Net Income (Loss) | B13: =B11+B12 | C13: =C11+C12 | D13: =D11+D12 | E13: =E11+E12 | F13: =F11+F12 | G13: =G11+G12 | H13: =H11+H12 | I13: =I11+I12 | ... L13: =L11+L12
A14: Net Income (Loss) Attributable to Noncontrolling Interest | B14: 61 | C14: 68 | D14: 81 | E14: 48 | F14: 55
A15: Net Income (Loss) Less NCI | B15: =B13-B14 | C15: =C13-C14 | D15: =D13-D14 | E15: =E13-E14 | F15: =F13-F14 | G15: =G13-G14 | H15: =H13-H14 | I15: =I13-I14 | ... L15: =L13-L14
A16: Basic Earnings (Loss) per Share | B16: 5.51 | C16: 6.45 | D16: 6.59 | E16: 6.97 | F16: 6.02
A17: Diluted Earnings (Loss) per Share | B17: 5.49 | C17: 6.42 | D17: 6.56 | E17: 6.95 | F17: 6
A18: Weighted Average Shares Outstanding (Basic) | B18: 1382000000 | C18: 1380000000 | D18: 1376000000 | E18: 1373000000 | F18: 1369000000 | G18: =F18 | H18: =G18 | I18: =H18 | J18: =I18 | K18: =J18 | L18: =K18
A19: Weighted Average Shares Outstanding (Diluted) | B19: 1389000000 | C19: 1387000000 | D19: 1383000000 | E19: 1378000000 | F19: 1373000000 | G19: =F19 | H19: =G19 | I19: =H19 | J19: =I19 | K19: =J19 | L19: =K19

Sheet BALANCE SHEET
B1: FY2022 | C1: FY2023 | D1: FY2024 | E1: FY2025 | F1: FY2025E | G1: FY2026E | H1: FY2027E | I1: FY2028E | J1: FY2029E | K1: FY2030E
A2: Cash & Cash Equivalents | B2: 4954 | C2: 9711 | D2: 8505 | E2: 9159 | F2: =E2+'CASH FLOW'!G48 | G2: =F2+'CASH FLOW'!H48 | H2: =G2+'CASH FLOW'!I48 | I2: =H2+'CASH FLOW'!J48 | J2: =I2+'CASH FLOW'!K48 | K2: =J2+'CASH FLOW'!L48
A3: Short-Term Investments | B3: 394 | C3: 292 | D3: 761 | E3: 371
A4: Accounts Receivable | B4: 10163 | C4: 10815 | D4: 10333 | E4: 11506 | F4: ='BS DRIVERS'!G3*'ANNL P&L'!G2/ASSUMPTIONS!$B$2 | G4: ='BS DRIVERS'!H3*'ANNL P&L'!H2/ASSUMPTIONS!$B$2 | H4: ='BS DRIVERS'!I3*'ANNL P&L'!I2/ASSUMPTIONS!$B$2 | I4: ='BS DRIVERS'!J3*'ANNL P&L'!J2/ASSUMPTIONS!$B$2 | J4: ='BS DRIVERS'!K3*'ANNL P&L'!K2/ASSUMPTIONS!$B$2 | K4: ='BS DRIVERS'!L3*'ANNL P&L'!L2/ASSUMPTIONS!$B$2
A5: Inventories | B5: 5222 | C5: 5334 | D5: 5306 | E5: 5845 | F5: ='BS DRIVERS'!G4*'ANNL P&L'!G3/ASSUMPTIONS!$B$2 | G5: ='BS DRIVERS'!H4*'ANNL P&L'!H3/ASSUMPTIONS!$B$2 | H5: ='BS DRIVERS'!I4*'ANNL P&L'!I3/ASSUMPTIONS!$B$2 | I5: ='BS DRIVERS'!J4*'ANNL P&L'!J3/ASSUMPTIONS!$B$2 | J5: ='BS DRIVERS'!K4*'ANNL P&L'!K3/ASSUMPTIONS!$B$2 | K5: ='BS DRIVERS'!L4*'ANNL P&L'!L3/ASSUMPTIONS!$B$2
A6: Prepaid Expenses | B6: 806 | C6: 798 | D6: 921 | E6: 1068 | F6: ='BS DRIVERS'!G7*'ANNL P&L'!G2 | G6: ='BS DRIVERS'!H7*'ANNL P&L'!H2 | H6: ='BS DRIVERS'!I7*'ANNL P&L'!I2 | I6: ='BS DRIVERS'!J7*'ANNL P&L'!J2 | J6: ='BS DRIVERS'!K7*'ANNL P&L'!K2 | K6: ='BS DRIVERS'!L7*'ANNL P&L'!L2
A7: Total Current Assets | B7: =SUM(B2:B6) | C7: =SUM(C2:C6) | D7: =SUM(D2:D6) | E7: =SUM(E2:E6) | F7: =SUM(F2:F6) | G7: =SUM(G2:G6) | H7: =SUM(H2:H6) | I7: =SUM(I2:I6) | ... K7: =SUM(K2:K6)
A8: Net PP&E | B8: 24291 | C8: 27039 | D8: 28008 | E8: 29905 | F8: =E8-'CASH FLOW'!G27-'CASH FLOW'!G3 | G8: =F8-'CASH FLOW'!H27-'CASH FLOW'!H3 | H8: =G8-'CASH FLOW'!I27-'CASH FLOW'!I3 | I8: =H8-'CASH FLOW'!J27-'CASH FLOW'!J3 | J8: =I8-'CASH FLOW'!K27-'CASH FLOW'!K3 | K8: =J8-'CASH FLOW'!L27-'CASH FLOW'!L3
A9: Intangible Assets | B9: 15586 | C9: 14929 | D9: 14801 | E9: 15066 | F9: =E9 | G9: =F9 | H9: =G9 | I9: =H9 | J9: =I9 | K9: =J9
A10: Goodwill | B10: 18202 | C10: 17728 | D10: 17534 | E10: 18916 | F10: =E10 | G10: =F10 | H10: =G10 | I10: =H10 | J10: =I10 | K10: =J10
A11: Equity Method Investments | B11: 3073 | C11: 2714 | D11: 1985 | E11: 2038
A12: Deferred Tax Assets | B12: 4204 | C12: 4474 | D12: 4362 | E12: 4541 | F12: =E12 | G12: =F12 | H12: =G12 | I12: =H12 | J12: =I12 | K12: =J12
A13: Other Non-Current Assets | B13: 5292 | C13: 6661 | D13: 6951 | E13: 8984 | F13: ='BS DRIVERS'!G9*'ANNL P&L'!G2 | G13: ='BS DRIVERS'!H9*'ANNL P&L'!H2 | H13: ='BS DRIVERS'!I9*'ANNL P&L'!I2 | I13: ='BS DRIVERS'!J9*'ANNL P&L'!J2 | J13: ='BS DRIVERS'!K9*'ANNL P&L'!K2 | K13: ='BS DRIVERS'!L9*'ANNL P&L'!L2
A14: Total Assets | B14: =B7+SUM(B8:B13) | C14: =C7+SUM(C8:C13) | D14: =D7+SUM(D8:D13) | E14: =E7+SUM(E8:E13) | F14: =F7+SUM(F8:F13) | G14: =G7+SUM(G8:G13) | H14: =H7+SUM(H8:H13) | I14: =I7+SUM(I8:I13) | ... K14: =K7+SUM(K8:K13)
A15: Short-Term Debt Obligations | B15: 3414 | C15: 6510 | D15: 7082 | E15: 6861
A16: Accrued Expenses | B16: 23371 | C16: 25137 | D16: 24454 | E16: 25903 | F16: ='BS DRIVERS'!G12*'ANNL P&L'!G2 | G16: ='BS DRIVERS'!H12*'ANNL P&L'!H2 | H16: ='BS DRIVERS'!I12*'ANNL P&L'!I2 | I16: ='BS DRIVERS'!J12*'ANNL P&L'!J2 | J16: ='BS DRIVERS'!K12*'ANNL P&L'!K2 | K16: ='BS DRIVERS'!L12*'ANNL P&L'!L2
A17: Total Current Liabilities | B17: =SUM(B15:B16) | C17: =SUM(C15:C16) | D17: =SUM(D15:D16) | E17: =SUM(E15:E16) | F17: =SUM(F15:F16) | G17: =SUM(G15:G16) | H17: =SUM(H15:H16) | I17: =SUM(I15:I16) | ... K17: =SUM(K15:K16)
A18: Long-Term Debt | B18: 35657 | C18: 37595 | D18: 37224 | E18: 42321
A19: Deferred Tax Liability | B19: 4133 | C19: 3895 | D19: 3484 | E19: 3802 | F19: =E19 | G19: =F19 | H19: =G19 | I19: =H19 | J19: =I19 | K19: =J19
A20: Other Non-Current Liabilities | B20: 8339 | C20: 8721 | D20: 9052 | E20: 7965
A21: Total Liabilities | B21: =B17+SUM(B18:B20) | C21: =C17+SUM(C18:C20) | D21: =D17+SUM(D18:D20) | E21: =E17+SUM(E18:E20) | F21: =F17+SUM(F18:F20) | G21: =G17+SUM(G18:G20) | H21: =H17+SUM(H18:H20) | I21: =I17+SUM(I18:I20) | ... K21: =K17+SUM(K18:K20)
A22: Common Stock | B22: 23 | C22: 23 | D22: 23 | E22: 23 | F22: =E22 | G22: =F22 | H22: =G22 | I22: =H22 | J22: =I22 | K22: =J22
A23: Additional Paid-in Capital | B23: 4134 | C23: 4261 | D23: 4385 | E23: 4451 | F23: =E23+'CASH FLOW'!G10+'CASH FLOW'!G43 | G23: =F23+'CASH FLOW'!H10+'CASH FLOW'!H43 | H23: =G23+'CASH FLOW'!I10+'CASH FLOW'!I43 | I23: =H23+'CASH FLOW'!J10+'CASH FLOW'!J43 | J23: =I23+'CASH FLOW'!K10+'CASH FLOW'!K43 | K23: =J23+'CASH FLOW'!L10+'CASH FLOW'!L43
A24: Retained Earnings (Accumulated Deficit) | B24: 67800 | C24: 70035 | D24: 72266 | E24: 72788 | F24: =E24+'ANNL P&L'!G13+'CASH FLOW'!G41 | G24: =F24+'ANNL P&L'!H13+'CASH FLOW'!H41 | H24: =G24+'ANNL P&L'!I13+'CASH FLOW'!I41 | I24: =H24+'ANNL P&L'!J13+'CASH FLOW'!J41 | J24: =I24+'ANNL P&L'!K13+'CASH FLOW'!K41 | K24: =J24+'ANNL P&L'!L13+'CASH FLOW'!L41
A25: Accumulated Other Comprehensive Income (Loss) | B25: -15302 | C25: -15534 | D25: -17612 | E25: -15024 | F25: =E25+'CASH FLOW'!G47 | G25: =F25+'CASH FLOW'!H47 | H25: =G25+'CASH FLOW'!I47 | I25: =H25+'CASH FLOW'!J47 | J25: =I25+'CASH FLOW'!K47 | K25: =J25+'CASH FLOW'!L47
A26: Treasury Stock | B26: -39506 | C26: -40282 | D26: -41021 | E26: -41832
A27: Noncontrolling Interest | B27: 124 | C27: 134 | D27: 130 | E27: 141
A28: Total Stockholders' Equity | B28: =SUM(B22:B27) | C28: =SUM(C22:C27) | D28: =SUM(D22:D27) | E28: =SUM(E22:E27) | F28: =SUM(F22:F27) | G28: =SUM(G22:G27) | H28: =SUM(H22:H27) | I28: =SUM(I22:I27) | ... K28: =SUM(K22:K27)
A29: Total Liabilities, Mezzanine & Stockholders' Equity | B29: =B21+B28 | C29: =C21+C28 | D29: =D21+D28 | E29: =E21+E28 | F29: =F21+F28 | G29: =G21+G28 | H29: =H21+H28 | I29: =I21+I28 | ... K29: =K21+K28

Sheet CASH FLOW
B1: FY2021 | C1: FY2022 | D1: FY2023 | E1: FY2024 | F1: FY2025 | G1: FY2025E | H1: FY2026E | I1: FY2027E | J1: FY2028E | K1: FY2029E | L1: FY2030E
A2: Net Income (Loss) | B2: 7679 | C2: 8978 | D2: 9155 | E2: 9626 | F2: 8295 | G2: ='ANNL P&L'!G13 | H2: ='ANNL P&L'!H13 | I2: ='ANNL P&L'!I13 | J2: ='ANNL P&L'!J13 | K2: ='ANNL P&L'!K13 | L2: ='ANNL P&L'!L13
A3: Depreciation & Amortization | B3: 2710 | C3: 2763 | D3: 2948 | E3: 3160 | F3: 3451 | G3: ='CF DRIVERS'!G3*'BALANCE SHEET'!E8 | H3: ='CF DRIVERS'!H3*'BALANCE SHEET'!F8 | I3: ='CF DRIVERS'!I3*'BALANCE SHEET'!G8 | J3: ='CF DRIVERS'!J3*'BALANCE SHEET'!H8 | K3: ='CF DRIVERS'!K3*'BALANCE SHEET'!I8 | L3: ='CF DRIVERS'!L3*'BALANCE SHEET'!J8
A4: Gain on Juice Transaction | B4: 0 | C4: -3321 | D4: 0 | E4: 0 | F4: 0
A5: Impairment and Other Charges | B5: 0 | C5: 3618 | D5: 1230 | E5: 714 | F5: 1946
A6: Indirect Tax Impact | B6: 0 | C6: 0 | D6: 0 | E6: 218 | F6: 0
A7: Product Recall Impact | B7: 0 | C7: 0 | D7: 136 | E7: 187 | F7: 0
A8: Cash Payments for Product Recall | B8: 0 | C8: 0 | D8: 0 | E8: -148 | F8: -6
A9: Operating Lease ROU Asset Amortization | B9: 505 | C9: 517 | D9: 570 | E9: 655 | F9: 727
A10: Stock-Based Compensation | B10: 301 | C10: 343 | D10: 380 | E10: 362 | F10: 288 | G10: ='CF DRIVERS'!G4 | H10: ='CF DRIVERS'!H4 | I10: ='CF DRIVERS'!I4 | J10: ='CF DRIVERS'!J4 | K10: ='CF DRIVERS'!K4 | L10: ='CF DRIVERS'!L4
A11: Restructuring and Asset Impairment Charges | B11: 247 | C11: 411 | D11: 445 | E11: 727 | F11: 983
A12: Cash Payments for Restructuring | B12: -256 | C12: -224 | D12: -434 | E12: -436 | F12: -796
A13: Acquisition and Divestiture-Related Charges | B13: -4 | C13: 80 | D13: 41 | E13: 0 | F13: 453
A14: Cash Payments for Acquisition and Divestiture Costs | B14: -176 | C14: -46 | D14: -41 | E14: 0 | F14: -228
A15: Pension and Postretirement Benefits Expense | B15: 123 | C15: 419 | D15: 150 | E15: 414 | F15: 504
A16: Pension and Postretirement Benefits Contributions | B16: -785 | C16: -384 | D16: -410 | E16: -348 | F16: -472
A17: (Benefit) Provision for Deferred Income Taxes | B17: 298 | C17: -873 | D17: -271 | E17: -42 | F17: 71 | G17: =0 | H17: =0 | I17: =0 | J17: =0 | K17: =0 | L17: =0
A18: Tax Expense Related to TCJ Act | B18: 190 | C18: 86 | D18: 0 | E18: 0 | F18: 0
A19: Tax Payments Related to TCJ Act | B19: -309 | C19: -309 | D19: -309 | E19: -579 | F19: -772
A20: Accounts Receivable | B20: -651 | C20: -1763 | D20: -793 | E20: -138 | F20: -580 | G20: =-('BALANCE SHEET'!F4-'BALANCE SHEET'!E4) | H20: =-('BALANCE SHEET'!G4-'BALANCE SHEET'!F4) | I20: =-('BALANCE SHEET'!H4-'BALANCE SHEET'!G4) | J20: =-('BALANCE SHEET'!I4-'BALANCE SHEET'!H4) | K20: =-('BALANCE SHEET'!J4-'BALANCE SHEET'!I4) | L20: =-('BALANCE SHEET'!K4-'BALANCE SHEET'!J4)
A21: Inventories | B21: -582 | C21: -1142 | D21: -261 | E21: -314 | F21: -150 | G21: =-('BALANCE SHEET'!F5-'BALANCE SHEET'!E5) | H21: =-('BALANCE SHEET'!G5-'BALANCE SHEET'!F5) | I21: =-('BALANCE SHEET'!H5-'BALANCE SHEET'!G5) | J21: =-('BALANCE SHEET'!I5-'BALANCE SHEET'!H5) | K21: =-('BALANCE SHEET'!J5-'BALANCE SHEET'!I5) | L21: =-('BALANCE SHEET'!K5-'BALANCE SHEET'!J5)
A22: Prepaid Expenses | B22: 159 | C22: 118 | D22: -13 | E22: 40 | F22: 195 | G22: =-('BALANCE SHEET'!F6-'BALANCE SHEET'!E6) | H22: =-('BALANCE SHEET'!G6-'BALANCE SHEET'!F6) | I22: =-('BALANCE SHEET'!H6-'BALANCE SHEET'!G6) | J22: =-('BALANCE SHEET'!I6-'BALANCE SHEET'!H6) | K22: =-('BALANCE SHEET'!J6-'BALANCE SHEET'!I6) | L22: =-('BALANCE SHEET'!K6-'BALANCE SHEET'!J6)
A23: Accounts Payable | B23: 1762 | C23: 1842 | D23: 420 | E23: -1161 | F23: -677
A24: Other Current Liabilities | B24: 30 | C24: 57 | D24: 310 | E24: -123 | F24: -433
A25: Other Operating Items | B25: 375 | C25: -359 | D25: 189 | E25: -307 | F25: -712 | G25: =0 | H25: =0 | I25: =0 | J25: =0 | K25: =0 | L25: =0
A26: Cash Flow from Operations | B26: =SUM(B2:B25) | C26: =SUM(C2:C25) | D26: =SUM(D2:D25) | E26: =SUM(E2:E25) | F26: =SUM(F2:F25) | G26: =SUM(G2:G25) | H26: =SUM(H2:H25) | I26: =SUM(I2:I25) | ... L26: =SUM(L2:L25)
A27: Purchase of PP&E | B27: -4625 | C27: -5207 | D27: -5518 | E27: -5318 | F27: -4415 | G27: ='CF DRIVERS'!G5*'BALANCE SHEET'!E8 | H27: ='CF DRIVERS'!H5*'BALANCE SHEET'!F8 | I27: ='CF DRIVERS'!I5*'BALANCE SHEET'!G8 | J27: ='CF DRIVERS'!J5*'BALANCE SHEET'!H8 | K27: ='CF DRIVERS'!K5*'BALANCE SHEET'!I8 | L27: ='CF DRIVERS'!L5*'BALANCE SHEET'!J8
A28: Proceeds from Sale of Assets | B28: 166 | C28: 251 | D28: 198 | E28: 342 | F28: 528
A29: Acquisitions, Net of Cash Acquired | B29: -61 | C29: -873 | D29: -314 | E29: -256 | F29: -3391
A30: Proceeds from Juice Transaction | B30: 0 | C30: 3456 | D30: 0 | E30: 0 | F30: 0
A31: Proceeds from Divestitures of Businesses | B31: 169 | C31: 49 | D31: 75 | E31: 166 | F31: 39
A32: Net Change in Short-Term Investments | B32: 1077 | C32: -117 | D32: 16 | E32: -420 | F32: 460
A33: Other Investing Activities | B33: 5 | C33: 11 | D33: 48 | E33: 14 | F33: -100
A34: Cash Flow from Investing | B34: =SUM(B27:B33) | C34: =SUM(C27:C33) | D34: =SUM(D27:D33) | E34: =SUM(E27:E33) | F34: =SUM(F27:F33) | G34: =SUM(G27:G33) | H34: =SUM(H27:H33) | I34: =SUM(I27:I33) | ... L34: =SUM(L27:L33)
A35: Proceeds from Issuance of Long-Term Debt | B35: 4122 | C35: 3377 | D35: 5482 | E35: 4042 | F35: 8189
A36: Repayments of Long-Term Debt | B36: -8299 | C36: -4174 | D36: -3005 | E36: -3886 | F36: -4082
A37: Proceeds from Short-Term Debt | B37: 8 | C37: 1969 | D37: 5428 | E37: 5786 | F37: 6391
A38: Repayments of Short-Term Debt | B38: -397 | C38: -1951 | D38: -3106 | E38: -5639 | F38: -7920
A39: Net Change in Other Short-Term Debt | B39: 434 | C39: -31 | D39: -29 | E39: 392 | F39: 1170
A40: Payments of Contingent Consideration | B40: -773 | C40: 0 | D40: 0 | E40: 0 | F40: 0
...

Sheet IS DRIVERS
B1: FY2021 | C1: FY2022 | D1: FY2023 | E1: FY2024 | F1: FY2025 | G1: FY2025E | H1: FY2026E | I1: FY2027E | J1: FY2028E | K1: FY2029E | L1: FY2030E
A2: Revenue Growth % | C2: =IFERROR(('ANNL P&L'!C2-'ANNL P&L'!B2)/'ANNL P&L'!B2,0) | D2: =IFERROR(('ANNL P&L'!D2-'ANNL P&L'!C2)/'ANNL P&L'!C2,0) | E2: =IFERROR(('ANNL P&L'!E2-'ANNL P&L'!D2)/'ANNL P&L'!D2,0) | F2: =IFERROR(('ANNL P&L'!F2-'ANNL P&L'!E2)/'ANNL P&L'!E2,0)
A3: COGS % of Revenue | B3: =IFERROR('ANNL P&L'!B3/'ANNL P&L'!B2,0) | C3: =IFERROR('ANNL P&L'!C3/'ANNL P&L'!C2,0) | D3: =IFERROR('ANNL P&L'!D3/'ANNL P&L'!D2,0) | E3: =IFERROR('ANNL P&L'!E3/'ANNL P&L'!E2,0) | F3: =IFERROR('ANNL P&L'!F3/'ANNL P&L'!F2,0) | G3: =F3 | H3: =G3 | I3: =H3 | J3: =I3 | K3: =J3 | L3: =K3
A4: SG&A % of Revenue | B4: =IFERROR('ANNL P&L'!B5/'ANNL P&L'!B2,0) | C4: =IFERROR('ANNL P&L'!C5/'ANNL P&L'!C2,0) | D4: =IFERROR('ANNL P&L'!D5/'ANNL P&L'!D2,0) | E4: =IFERROR('ANNL P&L'!E5/'ANNL P&L'!E2,0) | F4: =IFERROR('ANNL P&L'!F5/'ANNL P&L'!F2,0) | G4: =F4 | H4: =G4 | I4: =H4 | J4: =I4 | K4: =J4 | L4: =K4
A5: Interest Income (Expense) $ | B5: ='ANNL P&L'!B10 | C5: ='ANNL P&L'!C10 | D5: ='ANNL P&L'!D10 | E5: ='ANNL P&L'!E10 | F5: ='ANNL P&L'!F10 | G5: =F5 | H5: =G5 | I5: =H5 | J5: =I5 | K5: =J5 | L5: =K5
A6: Foreign Currency Gain (Loss) $ | G6: =F6 | H6: =G6 | I6: =H6 | J6: =I6 | K6: =J6 | L6: =K6
A7: Other Income (Expense) $ | G7: =F7 | H7: =G7 | I7: =H7 | J7: =I7 | K7: =J7 | L7: =K7
A8: Effective Tax Rate % | G8: =F8 | H8: =G8 | I8: =H8 | J8: =I8 | K8: =J8 | L8: =K8

Sheet BS DRIVERS
B1: FY2021 | C1: FY2022 | D1: FY2023 | E1: FY2024 | F1: FY2025 | G1: FY2025E | H1: FY2026E | I1: FY2027E | J1: FY2028E | K1: FY2029E | L1: FY2030E
A2: Current Assets
A3: DSO (days) | C3: =IFERROR('BALANCE SHEET'!B4/'ANNL P&L'!C2*ASSUMPTIONS!$B$2,0) | D3: =IFERROR('BALANCE SHEET'!C4/'ANNL P&L'!D2*ASSUMPTIONS!$B$2,0) | E3: =IFERROR('BALANCE SHEET'!D4/'ANNL P&L'!E2*ASSUMPTIONS!$B$2,0) | F3: =IFERROR('BALANCE SHEET'!E4/'ANNL P&L'!F2*ASSUMPTIONS!$B$2,0) | G3: =F3 | H3: =G3 | I3: =H3 | J3: =I3 | K3: =J3 | L3: =K3
A4: DIO (days) | C4: =IFERROR('BALANCE SHEET'!B5/'ANNL P&L'!C3*ASSUMPTIONS!$B$2,0) | D4: =IFERROR('BALANCE SHEET'!C5/'ANNL P&L'!D3*ASSUMPTIONS!$B$2,0) | E4: =IFERROR('BALANCE SHEET'!D5/'ANNL P&L'!E3*ASSUMPTIONS!$B$2,0) | F4: =IFERROR('BALANCE SHEET'!E5/'ANNL P&L'!F3*ASSUMPTIONS!$B$2,0) | G4: =F4 | H4: =G4 | I4: =H4 | J4: =I4 | K4: =J4 | L4: =K4
A5: Note Receivable - Current % of Rev | G5: =F5 | H5: =G5 | I5: =H5 | J5: =I5 | K5: =J5 | L5: =K5
A6: Deferred Other Costs - Current % of Rev | G6: =F6 | H6: =G6 | I6: =H6 | J6: =I6 | K6: =J6 | L6: =K6
A7: Prepaid Expenses % of Rev | C7: =IFERROR('BALANCE SHEET'!B6/'ANNL P&L'!C2,0) | D7: =IFERROR('BALANCE SHEET'!C6/'ANNL P&L'!D2,0) | E7: =IFERROR('BALANCE SHEET'!D6/'ANNL P&L'!E2,0) | F7: =IFERROR('BALANCE SHEET'!E6/'ANNL P&L'!F2,0) | G7: =F7 | H7: =G7 | I7: =H7 | J7: =I7 | K7: =J7 | L7: =K7
A8: Non-Current Assets
A9: Other Non-Current Assets % of Rev | C9: =IFERROR('BALANCE SHEET'!B13/'ANNL P&L'!C2,0) | D9: =IFERROR('BALANCE SHEET'!C13/'ANNL P&L'!D2,0) | E9: =IFERROR('BALANCE SHEET'!D13/'ANNL P&L'!E2,0) | F9: =IFERROR('BALANCE SHEET'!E13/'ANNL P&L'!F2,0) | G9: =F9 | H9: =G9 | I9: =H9 | J9: =I9 | K9: =J9 | L9: =K9
A10: Current Liabilities
A11: DPO (days) | G11: =F11 | H11: =G11 | I11: =H11 | J11: =I11 | K11: =J11 | L11: =K11
A12: Accrued Expenses % of Rev | C12: =IFERROR('BALANCE SHEET'!B16/'ANNL P&L'!C2,0) | D12: =IFERROR('BALANCE SHEET'!C16/'ANNL P&L'!D2,0) | E12: =IFERROR('BALANCE SHEET'!D16/'ANNL P&L'!E2,0) | F12: =IFERROR('BALANCE SHEET'!E16/'ANNL P&L'!F2,0) | G12: =F12 | H12: =G12 | I12: =H12 | J12: =I12 | K12: =J12 | L12: =K12
A13: Income Taxes Payable % of Rev | G13: =F13 | H13: =G13 | I13: =H13 | J13: =I13 | K13: =J13 | L13: =K13
A14: Accrued Distributor Termination Fees % of Rev | G14: =F14 | H14: =G14 | I14: =H14 | J14: =I14 | K14: =J14 | L14: =K14
A15: Accrued Promotional Allowance % of Rev | G15: =F15 | H15: =G15 | I15: =H15 | J15: =I15 | K15: =J15 | L15: =K15
A16: Lease Liability - Operating - Current % of Rev | G16: =F16 | H16: =G16 | I16: =H16 | J16: =I16 | K16: =J16 | L16: =K16
A17: Lease Liability - Finance - Current % of Rev | G17: =F17 | H17: =G17 | I17: =H17 | J17: =I17 | K17: =J17 | L17: =K17
A18: Deferred Revenue - Current % of Rev | G18: =F18 | H18: =G18 | I18: =H18 | J18: =I18 | K18: =J18 | L18: =K18
A19: Other Current Liabilities % of Rev | G19: =F19 | H19: =G19 | I19: =H19 | J19: =I19 | K19: =J19 | L19: =K19

Sheet CF DRIVERS
B1: FY2021 | C1: FY2022 | D1: FY2023 | E1: FY2024 | F1: FY2025 | G1: FY2025E | H1: FY2026E | I1: FY2027E | J1: FY2028E | K1: FY2029E | L1: FY2030E
A2: Allowance for Credit Losses % of Revenue | G2: =F2 | H2: =G2 | I2: =H2 | J2: =I2 | K2: =J2 | L2: =K2
A3: D&A % of PP&E | D3: =IFERROR('CASH FLOW'!D3/'BALANCE SHEET'!B8,0) | E3: =IFERROR('CASH FLOW'!E3/'BALANCE SHEET'!C8,0) | F3: =IFERROR('CASH FLOW'!F3/'BALANCE SHEET'!D8,0) | G3: =F3 | H3: =G3 | I3: =H3 | J3: =I3 | K3: =J3 | L3: =K3
A4: SBC $ | B4: ='CASH FLOW'!B10 | C4: ='CASH FLOW'!C10 | D4: ='CASH FLOW'!D10 | E4: ='CASH FLOW'!E10 | F4: ='CASH FLOW'!F10 | G4: =F4 | H4: =G4 | I4: =H4 | J4: =I4 | K4: =J4 | L4: =K4
A5: CapEx % of PP&E | D5: =IFERROR('CASH FLOW'!D27/'BALANCE SHEET'!B8,0) | E5: =IFERROR('CASH FLOW'!E27/'BALANCE SHEET'!C8,0) | F5: =IFERROR('CASH FLOW'!F27/'BALANCE SHEET'!D8,0) | G5: =F5 | H5: =G5 | I5: =H5 | J5: =I5 | K5: =J5 | L5: =K5
A6: Preferred Dividends % of Preferred Balance | G6: =F6 | H6: =G6 | I6: =H6 | J6: =I6 | K6: =J6 | L6: =K6
A7: Common Dividends % of Net Income | B7: =IFERROR('CASH FLOW'!B41/'CASH FLOW'!B2,0) | C7: =IFERROR('CASH FLOW'!C41/'CASH FLOW'!C2,0) | D7: =IFERROR('CASH FLOW'!D41/'CASH FLOW'!D2,0) | E7: =IFERROR('CASH FLOW'!E41/'CASH FLOW'!E2,0) | F7: =IFERROR('CASH FLOW'!F41/'CASH FLOW'!F2,0) | G7: =F7 | H7: =G7 | I7: =H7 | J7: =I7 | K7: =J7 | L7: =K7
A8: Share Repurchases $ | B8: ='CASH FLOW'!B42 | C8: ='CASH FLOW'!C42 | D8: ='CASH FLOW'!D42 | E8: ='CASH FLOW'!E42 | F8: ='CASH FLOW'!F42 | G8: =ASSUMPTIONS!$B$3 | H8: =ASSUMPTIONS!$B$3 | I8: =ASSUMPTIONS!$B$3 | J8: =ASSUMPTIONS!$B$3 | K8: =ASSUMPTIONS!$B$3 | L8: =ASSUMPTIONS!$B$3
A9: Net Debt $

Sheet QTR P&L
B1: Q1 FY2022 | C1: Q2 FY2022 | D1: Q3 FY2022 | E1: Q1 FY2023 | F1: Q2 FY2023 | G1: Q3 FY2023 | H1: Q1 FY2024 | I1: Q2 FY2024 | J1: Q3 FY2024 | K1: Q1 FY2025 | L1: Q2 FY2025 | M1: Q3 FY2025 | N1: Q1 FY2026
A2: Net Sales / Revenue | B2: 16200 | C2: 36425 | D2: 58396 | E2: 17846 | F2: 40168 | G2: 63621 | H2: 18250 | I2: 40751 | J2: 64070 | K2: 17919 | L2: 40645 | M2: 64582 | N2: 19443
A3: COGS | B3: -7433 | C3: -16848 | D3: -27156 | E3: -7988 | F3: -18109 | G3: -28784 | H3: -8248 | I3: -18167 | J3: -28563 | K3: -7926 | L3: -18230 | M3: -29343 | N3: -8712
A4: Gross Profit (Loss) | B4: =B2+B3 | C4: =C2+C3 | D4: =D2+D3 | E4: =E2+E3 | F4: =F2+F3 | G4: =G2+G3 | H4: =H2+H3 | I4: =I2+I3 | ... N4: =N2+N3
A5: SG&A | B5: -6580 | C5: -13967 | D5: -22262 | E5: -7229 | F5: -15771 | G5: -24528 | H5: -7285 | I5: -15819 | J5: -24870 | K5: -7410 | L5: -16183 | M5: -25305 | N5: -7518
A6: Gain on Juice Transaction | B6: -3322 | C6: -3335 | D6: -3321 | E6: 0 | F6: 0 | G6: 0 | H6: 0 | I6: 0 | J6: 0 | K6: 0 | L6: 0 | M6: 0 | N6: 0
A7: Impairment of Intangibles | B7: -242 | C7: -1601 | D7: -1602 | E7: 0 | F7: 0 | G7: -6 | H7: 0 | I7: 0 | J7: 0 | K7: 0 | L7: -1860 | M7: -1993 | N7: 0
A8: Income (Loss) from Operations | B8: =B4+SUM(B5:B7) | C8: =C4+SUM(C5:C7) | D8: =D4+SUM(D5:D7) | E8: =E4+SUM(E5:E7) | F8: =F4+SUM(F5:F7) | G8: =G4+SUM(G5:G7) | H8: =H4+SUM(H5:H7) | I8: =I4+SUM(I5:I7) | ... N8: =N4+SUM(N5:N7)
A9: Other Pension and OPEB Benefits Income (Expense) | B9: 134 | C9: 132 | D9: 168 | E9: 61 | F9: 121 | G9: 183 | H9: 58 | I9: 114 | J9: 155 | K9: 23 | L9: 65 | M9: 91 | N9: 58
A10: Interest Income (Expense) | B10: -240 | C10: -476 | D10: -666 | E10: -200 | F10: -401 | G10: -602 | H10: -202 | I10: -436 | J10: -655 | K10: -264 | L10: -524 | M10: -788 | N10: -301
A11: Pre-Tax Income (Loss) | B11: =B8+SUM(B9:B10) | C11: =C8+SUM(C9:C10) | D11: =D8+SUM(D9:D10) | E11: =E8+SUM(E9:E10) | F11: =F8+SUM(F9:F10) | G11: =G8+SUM(G9:G10) | H11: =H8+SUM(H9:H10) | I11: =I8+SUM(I9:I10) | ... N11: =N8+SUM(N9:N10)
A12: Income Tax (Expense) Benefit | B12: -888 | C12: -1281 | D12: -1756 | E12: -546 | F12: -1293 | G12: -2053 | H12: -520 | I12: -1296 | J12: -2045 | K12: -499 | L12: -791 | M12: -1504 | N12: -632
A13: Net Income (Loss) | B13: =B11+B12 | C13: =C11+C12 | D13: =D11+D12 | E13: =E11+E12 | F13: =F11+F12 | G13: =G11+G12 | H13: =H11+H12 | I13: =I11+I12 | ... N13: =N11+N12
A14: Net Income (Loss) Attributable to Noncontrolling Interest | B14: 12 | C14: 29 | D14: 51 | E14: 12 | F14: 35 | G14: 59 | H14: 11 | I14: 22 | J14: 37 | K14: 9 | L14: 25 | M14: 40 | N14: 11
A15: Net Income (Loss) Less NCI | B15: =B13-B14 | C15: =C13-C14 | D15: =D13-D14 | E15: =E13-E14 | F15: =F13-F14 | G15: =G13-G14 | H15: =H13-H14 | I15: =I13-I14 | ... N15: =N13-N14
A16: Basic Earnings (Loss) per Share | B16: 3.08 | C16: 4.11 | D16: 6.07 | E16: 1.4 | F16: 3.4 | G16: 5.64 | H16: 1.49 | I16: 3.73 | J16: 5.86 | K16: 1.34 | L16: 2.26 | M16: 4.16 | N16: 1.7
A17: Diluted Earnings (Loss) per Share | B17: 3.06 | C17: 4.09 | D17: 6.04 | E17: 1.4 | F17: 3.38 | G17: 5.62 | H17: 1.48 | I17: 3.71 | J17: 5.84 | K17: 1.33 | L17: 2.25 | M17: 4.15 | N17: 1.7
A18: Weighted Average Shares Outstanding (Basic) | B18: 1383000000 | C18: 1383000000 | D18: 1382000000 | E18: 1378000000 | F18: 1378000000 | G18: 1377000000 | H18: 1375000000 | I18: 1375000000 | J18: 1374000000 | K18: 1372000000 | L18: 1371000000 | M18: 1370000000 | N18: 1367000000
A19: Weighted Average Shares Outstanding (Diluted) | B19: 1391000000 | C19: 1390000000 | D19: 1389000000 | E19: 1384000000 | F19: 1384000000 | G19: 1384000000 | H19: 1380000000 | I19: 1380000000 | J19: 1379000000 | K19: 1376000000 | L19: 1374000000 | M19: 1373000000 | N19: 1371000000

Sheet QTR BS
B1: Q4 FY2022 | C1: Q1 FY2023 | D1: Q2 FY2023 | E1: Q3 FY2023 | F1: Q4 FY2023 | G1: Q1 FY2024 | H1: Q2 FY2024 | I1: Q3 FY2024 | J1: Q4 FY2024 | K1: Q1 FY2025 | L1: Q2 FY2025 | M1: Q3 FY2025 | N1: Q4 FY2025 | O1: Q1 FY2026
A2: Cash & Cash Equivalents | B2: 4954 | C2: 4770 | D2: 6116 | E2: 10017 | F2: 9711 | G2: 8047 | H2: 6353 | I2: 7308 | J2: 8505 | K2: 8268 | L2: 7631 | M2: 8126 | N2: 9159 | O2: 10475
A3: Short-Term Investments | B3: 394 | C3: 434 | D3: 338 | E3: 266 | F3: 292 | G3: 303 | H3: 315 | I3: 743 | J3: 761 | K3: 314 | L3: 342 | M3: 535 | N3: 371 | O3: 353
A4: Accounts Receivable | B4: 10163 | C4: 10469 | D4: 11456 | E4: 11782 | F4: 10815 | G4: 10938 | H4: 11942 | I4: 12088 | J4: 10333 | K4: 10800 | L4: 12390 | M4: 12634 | N4: 11506 | O4: 12171
A5: Inventories | B5: 5222 | C5: 5697 | D5: 5969 | E5: 5558 | F5: 5334 | G5: 5569 | H5: 5887 | I5: 5644 | J5: 5306 | K5: 5660 | L5: 6487 | M5: 6093 | N5: 5845 | O5: 6211
A6: Prepaid Expenses | B6: 806 | C6: 1057 | D6: 1075 | E6: 1026 | F6: 798 | G6: 1148 | H6: 1206 | I6: 1069 | J6: 921 | K6: 1246 | L6: 1360 | M6: 1334 | N6: 1068 | O6: 1706
A7: Total Current Assets | B7: =SUM(B2:B6) | C7: =SUM(C2:C6) | D7: =SUM(D2:D6) | E7: =SUM(E2:E6) | F7: =SUM(F2:F6) | G7: =SUM(G2:G6) | H7: =SUM(H2:H6) | I7: =SUM(I2:I6) | ... O7: =SUM(O2:O6)
A8: Net PP&E | B8: 24291 | C8: 24228 | D8: 24500 | E8: 24853 | F8: 27039 | G8: 26792 | H8: 27042 | I8: 27188 | J8: 28008 | K8: 28213 | L8: 28797 | M8: 29053 | N8: 29905 | O8: 29807
A9: Intangible Assets | B9: 15586 | C9: 15523 | D9: 15562 | E9: 15501 | F9: 14929 | G9: 14853 | H9: 14826 | I9: 14857 | J9: 14801 | K9: 15363 | L9: 15523 | M9: 14852 | N9: 15066 | O9: 15143
A10: Goodwill | B10: 18202 | C10: 18089 | D10: 17997 | E10: 17892 | F10: 17728 | G10: 17646 | H10: 17648 | I10: 17709 | J10: 17534 | K10: 18364 | L10: 18952 | M10: 18845 | N10: 18916 | O10: 19021
A11: Equity Method Investments | B11: 3073 | C11: 3123 | D11: 3038 | E11: 2955 | F11: 2714 | G11: 2734 | H11: 2674 | I11: 2645 | J11: 1985 | K11: 1996 | L11: 2061 | M11: 2084 | N11: 2038 | O11: 2135
A12: Deferred Tax Assets | B12: 4204 | C12: 4211 | D12: 4186 | E12: 4165 | F12: 4474 | G12: 4444 | H12: 4465 | I12: 4321 | J12: 4362 | K12: 4350 | L12: 4293 | M12: 4341 | N12: 4541 | O12: 4560
A13: Other Non-Current Assets | B13: 5292 | C13: 5441 | D13: 5669 | E13: 5938 | F13: 6661 | G13: 7566 | H13: 7175 | I13: 6941 | J13: 6951 | K13: 7163 | L13: 7509 | M13: 8661 | N13: 8984 | O13: 9064
A14: Total Assets | B14: =B7+SUM(B8:B13) | C14: =C7+SUM(C8:C13) | D14: =D7+SUM(D8:D13) | E14: =E7+SUM(E8:E13) | F14: =F7+SUM(F8:F13) | G14: =G7+SUM(G8:G13) | H14: =H7+SUM(H8:H13) | I14: =I7+SUM(I8:I13) | ... O14: =O7+SUM(O8:O13)
A15: Short-Term Debt Obligations | B15: 3414 | C15: 4281 | D15: 7613 | E15: 8937 | F15: 6510 | G15: 8161 | H15: 8289 | I15: 6524 | J15: 7082 | K15: 9099 | L15: 12056 | M15: 6736 | N15: 6861 | O15: 10151
A16: Accrued Expenses | B16: 23371 | C16: 21556 | D16: 22005 | E16: 23723 | F16: 25137 | G16: 22073 | H16: 22859 | I16: 23791 | J16: 24454 | K16: 22412 | L16: 24340 | M16: 24763 | N16: 25903 | O16: 24326
A17: Total Current Liabilities | B17: =SUM(B15:B16) | C17: =SUM(C15:C16) | D17: =SUM(D15:D16) | E17: =SUM(E15:E16) | F17: =SUM(F15:F16) | G17: =SUM(G15:G16) | H17: =SUM(H15:H16) | I17: =SUM(I15:I16) | ... O17: =SUM(O15:O16)
A18: Long-Term Debt | B18: 35657 | C18: 37486 | D18: 36008 | E18: 35837 | F18: 37595 | G18: 37707 | H18: 36638 | I18: 38490 | J18: 37224 | K18: 39419 | L18: 39328 | M18: 44113 | N18: 42321 | O18: 42577
A19: Deferred Tax Liability | B19: 4133 | C19: 4039 | D19: 4113 | E19: 4047 | F19: 3895 | G19: 4087 | H19: 3908 | I19: 3684 | J19: 3484 | K19: 3541 | L19: 3102 | M19: 3474 | N19: 3802 | O19: 4048
A20: Other Non-Current Liabilities | B20: 8339 | C20: 8505 | D20: 8342 | E20: 8439 | F20: 8721 | G20: 8822 | H20: 8259 | I20: 8419 | J20: 9052 | K20: 8737 | L20: 7960 | M20: 7929 | N20: 7965 | O20: 8008
A21: Total Liabilities | B21: =B17+SUM(B18:B20) | C21: =C17+SUM(C18:C20) | D21: =D17+SUM(D18:D20) | E21: =E17+SUM(E18:E20) | F21: =F17+SUM(F18:F20) | G21: =G17+SUM(G18:G20) | H21: =H17+SUM(H18:H20) | I21: =I17+SUM(I18:I20) | ... O21: =O17+SUM(O18:O20)
A22: Common Stock | B22: 23 | C22: 23 | D22: 23 | E22: 23 | F22: 23 | G22: 23 | H22: 23 | I22: 23 | J22: 23 | K22: 23 | L22: 23 | M22: 23 | N22: 23 | O22: 23
A23: Additional Paid-in Capital | B23: 4134 | C23: 3996 | D23: 4082 | E23: 4154 | F23: 4261 | G23: 4132 | H23: 4203 | I23: 4281 | J23: 4385 | K23: 4274 | L23: 4299 | M23: 4374 | N23: 4451 | O23: 4401
A24: Retained Earnings (Accumulated Deficit) | B24: 67800 | C24: 68142 | D24: 69135 | E24: 70479 | F24: 70035 | G24: 70331 | H24: 71545 | I24: 72607 | J24: 72266 | K24: 72238 | L24: 71547 | M24: 72197 | N24: 72788 | O24: 73165
A25: Accumulated Other Comprehensive Income (Loss) | B25: -15302 | C25: -15601 | D25: -15780 | E25: -15794 | F25: -15534 | G25: -15179 | H25: -15786 | I25: -16652 | J25: -17612 | K25: -17078 | L25: -16090 | M25: -15597 | N25: -15024 | O25: -14342
A26: Treasury Stock | B26: -39506 | C26: -39518 | D26: -39775 | E26: -40056 | F26: -40282 | G26: -40260 | H26: -40539 | I26: -40806 | J26: -41021 | K26: -41068 | L26: -41361 | M26: -41609 | N26: -41832 | O26: -41864
A27: Noncontrolling Interest | B27: 124 | C27: 133 | D27: 140 | E27: 164 | F27: 134 | G27: 143 | H27: 134 | I27: 152 | J27: 130 | K27: 140 | L27: 141 | M27: 155 | N27: 141 | O27: 153
A28: Total Stockholders' Equity | B28: =SUM(B22:B27) | C28: =SUM(C22:C27) | D28: =SUM(D22:D27) | E28: =SUM(E22:E27) | F28: =SUM(F22:F27) | G28: =SUM(G22:G27) | H28: =SUM(H22:H27) | I28: =SUM(I22:I27) | ... O28: =SUM(O22:O27)
A29: Total Liabilities, Mezzanine & Stockholders' Equity | B29: =B21+B28 | C29: =C21+C28 | D29: =D21+D28 | E29: =E21+E28 | F29: =F21+F28 | G29: =G21+G28 | H29: =H21+H28 | I29: =I21+I28 | ... O29: =O21+O28

Sheet QTR CF
B1: Q1 FY2022 | C1: Q2 FY2022 | D1: Q3 FY2022 | E1: Q1 FY2023 | F1: Q2 FY2023 | G1: Q3 FY2023 | H1: Q1 FY2024 | I1: Q2 FY2024 | J1: Q3 FY2024 | K1: Q1 FY2025 | L1: Q2 FY2025 | M1: Q3 FY2025 | N1: Q1 FY2026
A2: Net Income (Loss) | B2: 4273 | C2: 5719 | D2: 8443 | E2: 1944 | F2: 4715 | G2: 7831 | H2: 2053 | I2: 5147 | J2: 8092 | K2: 1843 | L2: 3122 | M2: 5740 | N2: 2338
A3: Depreciation & Amortization | B3: 555 | C3: 1195 | D3: 1854 | E3: 590 | F3: 1268 | G3: 1973 | H3: 641 | I3: 1379 | J3: 2118 | K3: 684 | L3: 1491 | M3: 2315 | N3: 742
A4: Gain on Juice Transaction | B4: -3322 | C4: -3335 | D4: -3321 | E4: 0 | F4: 0 | G4: 0 | H4: 0 | I4: 0 | J4: 0 | K4: 0 | L4: 0 | M4: 0 | N4: 0
A5: Impairment and Other Charges | B5: 482 | C5: 1871 | D5: 1877 | E5: -13 | F5: 97 | G5: 102 | H5: 0 | I5: 0 | J5: 10 | K5: 0 | L5: 1860 | M5: 1960 | N5: 0
A6: Product Recall Impact | B6: 0 | C6: 0 | D6: 0 | E6: 0 | F6: 0 | G6: 0 | H6: 167 | I6: 182 | J6: 184 | K6: 0 | L6: 0 | M6: 0 | N6: 0
A7: Cash Payments for Product Recall | B7: 0 | C7: 0 | D7: 0 | E7: 0 | F7: 0 | G7: 0 | H7: -108 | I7: -135 | J7: -138 | K7: -2 | L7: -2 | M7: -5 | N7: 0
A8: Operating Lease ROU Asset Amortization | B8: 103 | C8: 223 | D8: 346 | E8: 116 | F8: 248 | G8: 384 | H8: 127 | I8: 278 | J8: 438 | K8: 145 | L8: 315 | M8: 489 | N8: 162
A9: Stock-Based Compensation | B9: 81 | C9: 156 | D9: 233 | E9: 93 | F9: 179 | G9: 267 | H9: 97 | I9: 183 | J9: 260 | K9: 77 | L9: 131 | M9: 207 | N9: 93
A10: Restructuring and Asset Impairment Charges | B10: 27 | C10: 75 | D10: 126 | E10: 112 | F10: 204 | G10: 287 | H10: 96 | I10: 170 | J10: 415 | K10: 213 | L10: 426 | M10: 567 | N10: 133
A11: Cash Payments for Restructuring | B11: -32 | C11: -82 | D11: -134 | E11: -64 | F11: -187 | G11: -283 | H11: -60 | I11: -173 | J11: -284 | K11: -232 | L11: -387 | M11: -554 | N11: -145
A12: Acquisition and Divestiture-Related Charges | B12: 56 | C12: 64 | D12: 69 | E12: 2 | F12: 9 | G12: 20 | H12: 0 | I12: 0 | J12: 0 | K12: 0 | L12: 0 | M12: 308 | N12: -113
A13: Cash Payments for Acquisition and Divestiture Costs | B13: -17 | C13: -34 | D13: -41 | E13: -4 | F13: -10 | G13: -15 | H13: 0 | I13: 0 | J13: 0 | K13: 0 | L13: 0 | M13: -80 | N13: -14
... A24: Other Operating Items | B24: -133 | C24: -325 | D24: -426 | E24: 46 | F24: -6 | G24: 72 | H24: -68 | I24: -203 | J24: -135 | K24: -232 | L24: -269 | M24: -441 | N24: -157
A25: Cash Flow from Operations | B25: =SUM(B2:B24) | C25: =SUM(C2:C24) | D25: =SUM(D2:D24) | E25: =SUM(E2:E24) | F25: =SUM(F2:F24) | G25: =SUM(G2:G24) | H25: =SUM(H2:H24) | I25: =SUM(I2:I24) | ... N25: =SUM(N2:N24)
A26: Purchase of PP&E | B26: -522 | C26: -1499 | D26: -2556 | E26: -581 | F26: -1513 | G26: -2537 | H26: -614 | I26: -1701 | J26: -2850 | K26: -603 | L26: -1507 | M26: -2499 | N26: -447
A27: Proceeds from Sale of Assets | B27: 3 | C27: 222 | D27: 228 | E27: 19 | F27: 122 | G27: 131 | H27: 7 | I27: 127 | J27: 177 | K27: 132 | L27: 169 | M27: 272 | N27: 13
A28: Acquisitions, Net of Cash Acquired | B28: -13 | C28: -29 | D28: -804 | E28: -16 | F28: -83 | G28: -132 | H28: -6 | I28: -30 | J28: -31 | K28: -1200 | L28: -3130 | M28: -3176 | N28: -67
A29: Proceeds from Juice Transaction | B29: 3456 | C29: 3456 | D29: 3456 | E29: 0 | F29: 0 | G29: 0 | H29: 0 | I29: 0 | J29: 0 | K29: 0 | L29: 0 | M29: 0 | N29: 0
A30: Proceeds from Divestitures of Businesses | B30: 5 | C30: 15 | D30: 15 | E30: 85 | F30: 75 | G30: 75 | H30: 53 | I30: 135 | J30: 145 | K30: 2 | L30: 5 | M30: 5 | N30: 0
A31: Net Change in Short-Term Investments | B31: 22 | C31: 8 | D31: -37 | E31: -39 | F31: -56 | G31: 35 | H31: 8 | I31: 1 | J31: -421 | K31: 441 | L31: 447 | M31: 278 | N31: 5
A32: Other Investing Activities | B32: 4 | C32: -1 | D32: 7 | E32: 0 | F32: 32 | G32: 49 | H32: -10 | I32: 14 | J32: 15 | K32: -4 | L32: -111 | M32: -117 | N32: 19
A33: Cash Flow from Investing | B33: =SUM(B26:B32) | C33: =SUM(C26:C32) | D33: =SUM(D26:D32) | E33: =SUM(E26:E32) | F33: =SUM(F26:F32) | G33: =SUM(G26:G32) | H33: =SUM(H26:H32) | I33: =SUM(I26:I32) | ... N33: =SUM(N26:N32)
A34: Proceeds from Issuance of Long-Term Debt | B34: 0 | C34: 0 | D34: 3377 | E34: 2986 | F34: 2986 | G34: 2986 | H34: 1761 | I34: 1765 | J34: 4014 | K34: 3505 | L34: 3521 | M34: 8179 | N34: 2964
A35: Repayments of Long-Term Debt | B35: -1251 | C35: -3202 | D35: -3203 | E35: -1251 | F35: -2252 | G35: -2253 | H35: -1252 | I35: -2882 | J35: -2883 | K35: -1541 | L35: -2543 | M35: -3245 | N35: -1629
A36: Proceeds from Short-Term Debt | B36: 559 | C36: 1935 | D36: 1947 | E36: 393 | F36: 1660 | G36: 4688 | H36: 2313 | I36: 3080 | J36: 3808 | K36: 3656 | L36: 5251 | M36: 5528 | N36: 1937
A37: Repayments of Short-Term Debt | B37: 0 | C37: 0 | D37: -1932 | E37: -1 | F37: -26 | G37: -1037 | H37: -1631 | I37: -2138 | J37: -4177 | K37: -2119 | L37: -2492 | M37: -5417 | N37: -676
A38: Net Change in Other Short-Term Debt | B38: 647 | C38: 844 | D38: -45 | E38: 491 | F38: 2023 | G38: 1395 | H38: 774 | I38: 1286 | J38: 101 | K38: 373 | L38: 2438 | M38: 445 | N38: 1198
A39: Common Dividends | B39: -1505 | C39: -2997 | D39: -4586 | E39: -1608 | F39: -3199 | G39: -4941 | H39: -1767 | I39: -3506 | J39: -5369 | K39: -1882 | L39: -3743 | M39: -5692 | N39: -1966
A40: Share Repurchases | B40: -193 | C40: -699 | D40: -1156 | E40: -160 | F40: -453 | G40: -751 | H40: -146 | I40: -461 | J40: -760 | K40: -183 | L40: -494 | M40: -752 | N40: -182
A41: Proceeds from Exercise of Stock Options | B41: 49 | C41: 89 | D41: 113 | E41: 46 | F41: 86 | G41: 100 | H41: 66 | I41: 107 | J41: 138 | K41: 50 | L41: 58 | M41: 76 | N41: 93
A42: Tax Withholdings on RSU/PSU Settlement | B42: -85 | C42: -87 | D42: -97 | E42: -116 | F42: -119 | G42: -135 | H42: -108 | I42: -131 | J42: -132 | K42: -89 | L42: -111 | M42: -112 | N42: -76
A43: Other Financing Activities | B43: -1 | C43: -15 | D43: -25 | E43: -3 | F43: -16 | G43: -18 | H43: 0 | I43: -20 | J43: -22 | K43: -2 | L43: -17 | M43: -18 | N43: -1
A44: Cash Flow from Financing | B44: =SUM(B34:B43) | C44: =SUM(C34:C43) | D44: =SUM(D34:D43) | E44: =SUM(E34:E43) | F44: =SUM(F34:F43) | G44: =SUM(G34:G43) | H44: =SUM(H34:H43) | I44: =SUM(I34:I43) | ... N44: =SUM(N34:N43)
A45: FX Effect on Cash | B45: -17 | C45: -83 | D45: -197 | E45: -116 | F45: -144 | G45: -254 | H45: -38 | I45: -304 | J45: -391 | K45: 203 | L45: 422 | M45: 395 | N45: 121
A46: Net Change in Cash | B46: =B25+B33+B44+B45+B46 | C46: =C25+C33+C44+C45+C46 | D46: =D25+D33+D44+D45+D46 | E46: =E25+E33+E44+E45+E46 | F46: =F25+F33+F44+F45+F46 | G46: =G25+G33+G44+G45+G46 | H46: =H25+H33+H44+H45+H46 | I46: =I25+I33+I44+I45+I46 | ... N46: =N25+N33+N44+N45+N46
