Workbook

Sheet ASSUMPTIONS
A1: Assumption | B1: Value | C1: Note
A2: Days in Quarter | B2: 91 | C2: Used by DSO/DIO/DPO ratios. Approximation; varies 89-92 by quarter.

Sheet ANNL P&L
B1: FY2019 | C1: FY2020 | D1: FY2021 | E1: FY2022 | F1: FY2023 | G1: FY2024 | H1: FY2025 | I1: FY2026E | J1: FY2027E | K1: FY2028E | L1: FY2029E | M1: FY2030E | N1: FY2031E
A2: Net Sales / Revenue | B2: 75146.546 | C2: 130725.78 | D2: 314271.56 | E2: 653604 | F2: 1318014 | G2: 1355630 | H2: 2515269 | I2: ='QTR P&L'!AD2+'QTR P&L'!AE2+'QTR P&L'!AF2+'QTR P&L'!AG2 | J2: ='QTR P&L'!AH2+'QTR P&L'!AI2+'QTR P&L'!AJ2+'QTR P&L'!AK2 | K2: ='QTR P&L'!AL2+'QTR P&L'!AM2+'QTR P&L'!AN2+'QTR P&L'!AO2 | L2: ='QTR P&L'!AP2+'QTR P&L'!AQ2+'QTR P&L'!AR2+'QTR P&L'!AS2 | M2: ='QTR P&L'!AT2+'QTR P&L'!AU2+'QTR P&L'!AV2+'QTR P&L'!AW2
A3: COGS | B3: -43844.733 | C3: -69752.032 | D3: -186103.04 | E3: -382735 | F3: -684875 | G3: -675423 | H3: -1247936 | I3: ='QTR P&L'!AD3+'QTR P&L'!AE3+'QTR P&L'!AF3+'QTR P&L'!AG3 | J3: ='QTR P&L'!AH3+'QTR P&L'!AI3+'QTR P&L'!AJ3+'QTR P&L'!AK3 | K3: ='QTR P&L'!AL3+'QTR P&L'!AM3+'QTR P&L'!AN3+'QTR P&L'!AO3 | L3: ='QTR P&L'!AP3+'QTR P&L'!AQ3+'QTR P&L'!AR3+'QTR P&L'!AS3 | M3: ='QTR P&L'!AT3+'QTR P&L'!AU3+'QTR P&L'!AV3+'QTR P&L'!AW3
A4: Gross Profit (Loss) | B4: =B2+B3 | C4: =C2+C3 | D4: =D2+D3 | E4: =E2+E3 | F4: =F2+F3 | G4: =G2+G3 | H4: =H2+H3 | I4: =I2+I3 | ... N4: =N2+N3
A5: Sales and Marketing | B5: -21129.722 | C5: -34875.339 | D5: -74738.295 | E5: 0 | F5: 0 | G5: 0 | H5: 0 | I5: ='QTR P&L'!AD5+'QTR P&L'!AE5+'QTR P&L'!AF5+'QTR P&L'!AG5 | J5: ='QTR P&L'!AH5+'QTR P&L'!AI5+'QTR P&L'!AJ5+'QTR P&L'!AK5 | K5: ='QTR P&L'!AL5+'QTR P&L'!AM5+'QTR P&L'!AN5+'QTR P&L'!AO5 | L5: ='QTR P&L'!AP5+'QTR P&L'!AQ5+'QTR P&L'!AR5+'QTR P&L'!AS5 | M5: ='QTR P&L'!AT5+'QTR P&L'!AU5+'QTR P&L'!AV5+'QTR P&L'!AW5
A6: General and Administrative | B6: -11620.534 | C6: -18187.406 | D6: -57519.745 | E6: 0 | F6: 0 | G6: 0 | H6: 0 | I6: ='QTR P&L'!AD6+'QTR P&L'!AE6+'QTR P&L'!AF6+'QTR P&L'!AG6 | J6: ='QTR P&L'!AH6+'QTR P&L'!AI6+'QTR P&L'!AJ6+'QTR P&L'!AK6 | K6: ='QTR P&L'!AL6+'QTR P&L'!AM6+'QTR P&L'!AN6+'QTR P&L'!AO6 | L6: ='QTR P&L'!AP6+'QTR P&L'!AQ6+'QTR P&L'!AR6+'QTR P&L'!AS6 | M6: ='QTR P&L'!AT6+'QTR P&L'!AU6+'QTR P&L'!AV6+'QTR P&L'!AW6
A7: Operating Expenses | B7: -32750.256 | C7: -53062.745 | D7: -132258.04 | E7: 0 | F7: 0 | G7: 0 | H7: 0 | I7: ='QTR P&L'!AD7+'QTR P&L'!AE7+'QTR P&L'!AF7+'QTR P&L'!AG7 | J7: ='QTR P&L'!AH7+'QTR P&L'!AI7+'QTR P&L'!AJ7+'QTR P&L'!AK7 | K7: ='QTR P&L'!AL7+'QTR P&L'!AM7+'QTR P&L'!AN7+'QTR P&L'!AO7 | L7: ='QTR P&L'!AP7+'QTR P&L'!AQ7+'QTR P&L'!AR7+'QTR P&L'!AS7 | M7: ='QTR P&L'!AT7+'QTR P&L'!AU7+'QTR P&L'!AV7+'QTR P&L'!AW7
A8: SG&A | B8: 0 | C8: 0 | D8: 0 | E8: -428670 | F8: -366773 | G8: -524479 | H8: -798810 | I8: ='QTR P&L'!AD8+'QTR P&L'!AE8+'QTR P&L'!AF8+'QTR P&L'!AG8 | J8: ='QTR P&L'!AH8+'QTR P&L'!AI8+'QTR P&L'!AJ8+'QTR P&L'!AK8 | K8: ='QTR P&L'!AL8+'QTR P&L'!AM8+'QTR P&L'!AN8+'QTR P&L'!AO8 | L8: ='QTR P&L'!AP8+'QTR P&L'!AQ8+'QTR P&L'!AR8+'QTR P&L'!AS8 | M8: ='QTR P&L'!AT8+'QTR P&L'!AU8+'QTR P&L'!AV8+'QTR P&L'!AW8
A9: Distributor Termination Fees | B9: 0 | C9: 0 | D9: 0 | E9: 0 | F9: 0 | G9: 0 | H9: -327461 | I9: ='QTR P&L'!AD9+'QTR P&L'!AE9+'QTR P&L'!AF9+'QTR P&L'!AG9 | J9: ='QTR P&L'!AH9+'QTR P&L'!AI9+'QTR P&L'!AJ9+'QTR P&L'!AK9 | K9: ='QTR P&L'!AL9+'QTR P&L'!AM9+'QTR P&L'!AN9+'QTR P&L'!AO9 | L9: ='QTR P&L'!AP9+'QTR P&L'!AQ9+'QTR P&L'!AR9+'QTR P&L'!AS9 | M9: ='QTR P&L'!AT9+'QTR P&L'!AU9+'QTR P&L'!AV9+'QTR P&L'!AW9
A10: Income (Loss) from Operations | B10: =B4+SUM(B5:B9) | C10: =C4+SUM(C5:C9) | D10: =D4+SUM(D5:D9) | E10: =E4+SUM(E5:E9) | F10: =F4+SUM(F5:F9) | G10: =G4+SUM(G5:G9) | H10: =H4+SUM(H5:H9) | I10: =I4+SUM(I5:I9) | ... N10: =N4+SUM(N5:N9)
A11: Interest Income (Expense) | B11: -1011.755 | C11: -668.411 | D11: 307.328 | E11: 5529 | F11: 26629 | G11: 39263 | H11: -27892 | I11: ='QTR P&L'!AD11+'QTR P&L'!AE11+'QTR P&L'!AF11+'QTR P&L'!AG11 | J11: ='QTR P&L'!AH11+'QTR P&L'!AI11+'QTR P&L'!AJ11+'QTR P&L'!AK11 | K11: ='QTR P&L'!AL11+'QTR P&L'!AM11+'QTR P&L'!AN11+'QTR P&L'!AO11 | L11: ='QTR P&L'!AP11+'QTR P&L'!AQ11+'QTR P&L'!AR11+'QTR P&L'!AS11 | M11: ='QTR P&L'!AT11+'QTR P&L'!AU11+'QTR P&L'!AV11+'QTR P&L'!AW11
A12: Foreign Currency Gain (Loss) | B12: 0 | C12: 1375.925 | D12: -276.259 | E12: -392 | F12: -1246 | G12: -1734 | H12: 0 | I12: ='QTR P&L'!AD13+'QTR P&L'!AE13+'QTR P&L'!AF13+'QTR P&L'!AG13 | J12: ='QTR P&L'!AH13+'QTR P&L'!AI13+'QTR P&L'!AJ13+'QTR P&L'!AK13 | K12: ='QTR P&L'!AL13+'QTR P&L'!AM13+'QTR P&L'!AN13+'QTR P&L'!AO13 | L12: ='QTR P&L'!AP13+'QTR P&L'!AQ13+'QTR P&L'!AR13+'QTR P&L'!AS13 | M12: ='QTR P&L'!AT13+'QTR P&L'!AU13+'QTR P&L'!AV13+'QTR P&L'!AW13
A13: Other Income (Expense) | B13: 12431.458 | C13: -49.1 | D13: 0 | E13: 0 | F13: 0 | G13: 1793 | H13: 11863 | I13: ='QTR P&L'!AD12+'QTR P&L'!AE12+'QTR P&L'!AF12+'QTR P&L'!AG12 | J13: ='QTR P&L'!AH12+'QTR P&L'!AI12+'QTR P&L'!AJ12+'QTR P&L'!AK12 | K13: ='QTR P&L'!AL12+'QTR P&L'!AM12+'QTR P&L'!AN12+'QTR P&L'!AO12 | L13: ='QTR P&L'!AP12+'QTR P&L'!AQ12+'QTR P&L'!AR12+'QTR P&L'!AS12 | M13: ='QTR P&L'!AT12+'QTR P&L'!AU12+'QTR P&L'!AV12+'QTR P&L'!AW12
A14: Gain (Loss) on Lease Cancellations | B14: 0 | C14: 152.112 | D14: 0 | E14: 0 | F14: 0 | G14: 0 | H14: 0 | I14: ='QTR P&L'!AD14+'QTR P&L'!AE14+'QTR P&L'!AF14+'QTR P&L'!AG14 | J14: ='QTR P&L'!AH14+'QTR P&L'!AI14+'QTR P&L'!AJ14+'QTR P&L'!AK14 | K14: ='QTR P&L'!AL14+'QTR P&L'!AM14+'QTR P&L'!AN14+'QTR P&L'!AO14 | L14: ='QTR P&L'!AP14+'QTR P&L'!AQ14+'QTR P&L'!AR14+'QTR P&L'!AS14 | M14: ='QTR P&L'!AT14+'QTR P&L'!AU14+'QTR P&L'!AV14+'QTR P&L'!AW14
A15: Income Tax (Expense) Benefit | B15: 0 | C15: -197.677 | D15: 7995.72 | E15: -34618 | F15: -64948 | G15: -49976 | H15: -17034 | I15: ='QTR P&L'!AD15+'QTR P&L'!AE15+'QTR P&L'!AF15+'QTR P&L'!AG15 | J15: ='QTR P&L'!AH15+'QTR P&L'!AI15+'QTR P&L'!AJ15+'QTR P&L'!AK15 | K15: ='QTR P&L'!AL15+'QTR P&L'!AM15+'QTR P&L'!AN15+'QTR P&L'!AO15 | L15: ='QTR P&L'!AP15+'QTR P&L'!AQ15+'QTR P&L'!AR15+'QTR P&L'!AS15 | M15: ='QTR P&L'!AT15+'QTR P&L'!AU15+'QTR P&L'!AV15+'QTR P&L'!AW15
A16: Pre-Tax Income (Loss) | B16: =B10+SUM(B11:B15) | C16: =C10+SUM(C11:C15) | D16: =D10+SUM(D11:D15) | E16: =E10+SUM(E11:E15) | F16: =F10+SUM(F11:F15) | G16: =G10+SUM(G11:G15) | H16: =H10+SUM(H11:H15) | I16: =I10+SUM(I11:I15) | ... N16: =N10+SUM(N11:N15)
A17: Net Income (Loss) | B17: =B16 | C17: =C16 | D17: =D16 | E17: =E16 | F17: =F16 | G17: =G16 | H17: =H16 | I17: =I16 | ... N17: =N16
A18: Basic Earnings (Loss) per Share | B18: 0.16 | C18: 0.12 | D18: 0.05 | E18: 0 | F18: 0 | G18: 0 | H18: 0
A19: Diluted Earnings (Loss) per Share | B19: 0.16 | C19: 0.11 | D19: 0.05 | E19: 0 | F19: 0 | G19: 0 | H19: 0
A20: Weighted Average Shares Outstanding (Basic) | B20: 60761995 | C20: 70195085 | D20: 151469631 | E20: 0 | F20: 0 | G20: 0 | H20: 0
A21: Weighted Average Shares Outstanding (Diluted) | B21: 64183399 | C21: 74443601 | D21: 0 | E21: 0 | F21: 0 | G21: 0 | H21: 0
A22: Preferred Dividends | B22: 0 | C22: 0 | D22: 0 | E22: -11526 | F22: -27462 | G22: -27500 | H22: -37608 | I22: ='QTR P&L'!AD22+'QTR P&L'!AE22+'QTR P&L'!AF22+'QTR P&L'!AG22 | J22: ='QTR P&L'!AH22+'QTR P&L'!AI22+'QTR P&L'!AJ22+'QTR P&L'!AK22 | K22: ='QTR P&L'!AL22+'QTR P&L'!AM22+'QTR P&L'!AN22+'QTR P&L'!AO22 | L22: ='QTR P&L'!AP22+'QTR P&L'!AQ22+'QTR P&L'!AR22+'QTR P&L'!AS22 | M22: ='QTR P&L'!AT22+'QTR P&L'!AU22+'QTR P&L'!AV22+'QTR P&L'!AW22
A23: Income Allocated to Participating Preferred | B23: 0 | C23: 0 | D23: 0 | E23: 0 | F23: -17348 | G23: -10117 | H23: -6554 | I23: ='QTR P&L'!AD23+'QTR P&L'!AE23+'QTR P&L'!AF23+'QTR P&L'!AG23 | J23: ='QTR P&L'!AH23+'QTR P&L'!AI23+'QTR P&L'!AJ23+'QTR P&L'!AK23 | K23: ='QTR P&L'!AL23+'QTR P&L'!AM23+'QTR P&L'!AN23+'QTR P&L'!AO23 | L23: ='QTR P&L'!AP23+'QTR P&L'!AQ23+'QTR P&L'!AR23+'QTR P&L'!AS23 | M23: ='QTR P&L'!AT23+'QTR P&L'!AU23+'QTR P&L'!AV23+'QTR P&L'!AW23
A24: Net Income (Loss) Attributable to Common Shareholders | B24: =B17+B22+B23 | C24: =C17+C22+C23 | D24: =D17+D22+D23 | E24: =E17+E22+E23 | F24: =F17+F22+F23 | G24: =G17+G22+G23 | H24: =H17+H22+H23 | I24: =I17+I22+I23 | ... N24: =N17+N22+N23

Sheet BALANCE SHEET
B1: FY2019 | C1: FY2020 | D1: FY2021 | E1: FY2022 | F1: FY2023 | G1: FY2024 | H1: FY2025 | I1: FY2026E | J1: FY2027E | K1: FY2028E | L1: FY2029E | M1: FY2030E | N1: FY2031E
A2: Cash, Cash Equivalents & Restricted Cash | B2: 23090.682 | C2: 43248.021 | D2: 16254.708 | E2: 652927 | F2: 755981 | G2: 890190 | H2: 539987 | I2: ='QTR BS'!AD2 | J2: ='QTR BS'!AH2 | K2: ='QTR BS'!AL2 | L2: ='QTR BS'!AP2 | M2: ='QTR BS'!AT2
A3: Accounts Receivable | B3: 7774.618 | C3: 14986.213 | D3: 38741.049 | E3: 63311 | F3: 183703 | G3: 270342 | H3: 755499 | I3: ='QTR BS'!AD3 | J3: ='QTR BS'!AH3 | K3: ='QTR BS'!AL3 | L3: ='QTR BS'!AP3 | M3: ='QTR BS'!AT3
A4: Note Receivable - Current | B4: 1181.116 | C4: 1885.887 | D4: 2587.905 | E4: 2979 | F4: 2318 | G4: 0 | H4: 0 | I4: ='QTR BS'!AD4 | J4: ='QTR BS'!AH4 | K4: ='QTR BS'!AL4 | L4: ='QTR BS'!AP4 | M4: ='QTR BS'!AT4
A5: Inventories | B5: 15292.349 | C5: 18403.622 | D5: 191221.85 | E5: 173289 | F5: 229275 | G5: 131165 | H5: 337698 | I5: ='QTR BS'!AD5 | J5: ='QTR BS'!AH5 | K5: ='QTR BS'!AL5 | L5: ='QTR BS'!AP5 | M5: ='QTR BS'!AT5
A6: Prepaid Expenses | B6: 4170.136 | C6: 14626.922 | D6: 13555.037 | E6: 11341 | F6: 19503 | G6: 18759 | H6: 128806 | I6: ='QTR BS'!AD6 | J6: ='QTR BS'!AH6 | K6: ='QTR BS'!AL6 | L6: ='QTR BS'!AP6 | M6: ='QTR BS'!AT6
A7: Deferred Other Costs - Current | B7: 0 | C7: 0 | D7: 0 | E7: 14124 | F7: 14124 | G7: 14124 | H7: 49164 | I7: ='QTR BS'!AD7 | J7: ='QTR BS'!AH7 | K7: ='QTR BS'!AL7 | L7: ='QTR BS'!AP7 | M7: ='QTR BS'!AT7
A8: Total Current Assets | B8: =SUM(B2:B7) | C8: =SUM(C2:C7) | D8: =SUM(D2:D7) | E8: =SUM(E2:E7) | F8: =SUM(F2:F7) | G8: =SUM(G2:G7) | H8: =SUM(H2:H7) | I8: =SUM(I2:I7) | ... N8: =SUM(N2:N7)
A9: Note Receivable - Non-Current | B9: 10630.04 | C9: 9429.437 | D9: 7116.738 | E9: 3574 | F9: 0 | G9: 0 | H9: 0 | I9: ='QTR BS'!AD9 | J9: ='QTR BS'!AH9 | K9: ='QTR BS'!AL9 | L9: ='QTR BS'!AP9 | M9: ='QTR BS'!AT9
A10: Net PP&E | B10: 132.889 | C10: 579.377 | D10: 3180.058 | E10: 10185 | F10: 24868 | G10: 55602 | H10: 87910 | I10: ='QTR BS'!AD10 | J10: ='QTR BS'!AH10 | K10: ='QTR BS'!AL10 | L10: ='QTR BS'!AP10 | M10: ='QTR BS'!AT10
A11: ROU Assets - Operating - Non-Current | B11: 395.828 | C11: 836.038 | D11: 1128.151 | E11: 972 | F11: 1957 | G11: 21606 | H11: 0 | I11: ='QTR BS'!AD11 | J11: ='QTR BS'!AH11 | K11: ='QTR BS'!AL11 | L11: ='QTR BS'!AP11 | M11: ='QTR BS'!AT11
A12: ROU Assets - Finance - Non-Current | B12: 413.638 | C12: 162.119 | D12: 85.953 | E12: 208 | F12: 208 | G12: 230 | H12: 0 | I12: ='QTR BS'!AD16 | J12: ='QTR BS'!AH16 | K12: ='QTR BS'!AL16 | L12: ='QTR BS'!AP16 | M12: ='QTR BS'!AT16
A13: Intangible Assets | B13: 17173 | C13: 16590.083 | D13: 16301.326 | E13: 12254 | F13: 12139 | G13: 12213 | H13: 1391915 | I13: ='QTR BS'!AD12 | J13: ='QTR BS'!AH12 | K13: ='QTR BS'!AL12 | L13: ='QTR BS'!AP12 | M13: ='QTR BS'!AT12
A14: Goodwill | B14: 10023.806 | C14: 10419.321 | D14: 14526.583 | E14: 13679 | F14: 14173 | G14: 71582 | H14: 917560 | I14: ='QTR BS'!AD13 | J14: ='QTR BS'!AH13 | K14: ='QTR BS'!AL13 | L14: ='QTR BS'!AP13 | M14: ='QTR BS'!AT13
A15: Deferred Other Costs - Non-Current | B15: 0 | C15: 0 | D15: 0 | E15: 262462 | F15: 248338 | G15: 234215 | H15: 771635 | I15: ='QTR BS'!AD14 | J15: ='QTR BS'!AH14 | K15: ='QTR BS'!AL14 | L15: ='QTR BS'!AP14 | M15: ='QTR BS'!AT14
A16: Deferred Tax Assets | B16: 0 | C16: 0 | D16: 9019.241 | E16: 501 | F16: 29518 | G16: 38699 | H16: 96013 | I16: ='QTR BS'!AD15 | J16: ='QTR BS'!AH15 | K16: ='QTR BS'!AL15 | L16: ='QTR BS'!AP15 | M16: ='QTR BS'!AT15
A17: Other Non-Current Assets | B17: 104.134 | C17: 122.733 | D17: 299.828 | E17: 263 | F17: 291 | G17: 8154 | H17: 43434 | I17: ='QTR BS'!AD17 | J17: ='QTR BS'!AH17 | K17: ='QTR BS'!AL17 | L17: ='QTR BS'!AP17 | M17: ='QTR BS'!AT17
A18: Total Assets | B18: =B8+SUM(B9:B17) | C18: =C8+SUM(C9:C17) | D18: =D8+SUM(D9:D17) | E18: =E8+SUM(E9:E17) | F18: =F8+SUM(F9:F17) | G18: =G8+SUM(G9:G17) | H18: =H8+SUM(H9:H17) | I18: =I8+SUM(I9:I17) | ... N18: =N8+SUM(N9:N17)
A19: Accounts Payable | B19: 17292.647 | C19: 25412.753 | D19: 91478.612 | E19: 36248 | F19: 42840 | G19: 41287 | H19: 137930 | I19: ='QTR BS'!AD19 | J19: ='QTR BS'!AH19 | K19: ='QTR BS'!AL19 | L19: ='QTR BS'!AP19 | M19: ='QTR BS'!AT19
A20: Accrued Expenses | B20: 0 | C20: 0 | D20: 0 | E20: 69899 | F20: 62120 | G20: 148780 | H20: 230721 | I20: ='QTR BS'!AD20 | J20: ='QTR BS'!AH20 | K20: ='QTR BS'!AL20 | L20: ='QTR BS'!AP20 | M20: ='QTR BS'!AT20
A21: Income Taxes Payable | B21: 0 | C21: 0 | D21: 0 | E21: 1193 | F21: 50424 | G21: 10834 | H21: 49612 | I21: ='QTR BS'!AD21 | J21: ='QTR BS'!AH21 | K21: ='QTR BS'!AL21 | L21: ='QTR BS'!AP21 | M21: ='QTR BS'!AT21
A22: Accrued Distributor Termination Fees | B22: 0 | C22: 0 | D22: 0 | E22: 3986 | F22: 0 | G22: 0 | H22: 264088 | I22: ='QTR BS'!AD22 | J22: ='QTR BS'!AH22 | K22: ='QTR BS'!AL22 | L22: ='QTR BS'!AP22 | M22: ='QTR BS'!AT22
A23: Accrued Promotional Allowance | B23: 0 | C23: 0 | D23: 0 | E23: 35977 | F23: 99787 | G23: 135948 | H23: 307922 | I23: ='QTR BS'!AD23 | J23: ='QTR BS'!AH23 | K23: ='QTR BS'!AL23 | L23: ='QTR BS'!AP23 | M23: ='QTR BS'!AT23
A24: Lease Liability - Operating - Current | B24: 294.916 | C24: 321.283 | D24: 511.764 | E24: 661 | F24: 980 | G24: 3265 | H24: 0 | I24: ='QTR BS'!AD24 | J24: ='QTR BS'!AH24 | K24: ='QTR BS'!AL24 | L24: ='QTR BS'!AP24 | M24: ='QTR BS'!AT24
A25: Lease Liability - Finance - Current | B25: 354.158 | C25: 205.824 | D25: 157.046 | E25: 70 | F25: 59 | G25: 100 | H25: 0 | I25: ='QTR BS'!AD26 | J25: ='QTR BS'!AH26 | K25: ='QTR BS'!AL26 | L25: ='QTR BS'!AP26 | M25: ='QTR BS'!AT26
A26: Bonds Payable, Net | B26: 8634.279 | C26: 0 | D26: 0 | E26: 0 | F26: 0 | G26: 0 | H26: 0 | I26: ='QTR BS'!AD25 | J26: ='QTR BS'!AH25 | K26: ='QTR BS'!AL25 | L26: ='QTR BS'!AP25 | M26: ='QTR BS'!AT25
A27: Contingent Consideration - Current | B27: 0 | C27: 0 | D27: 0 | E27: 0 | F27: 0 | G27: 0 | H27: 25000 | I27: ='QTR BS'!AD27 | J27: ='QTR BS'!AH27 | K27: ='QTR BS'!AL27 | L27: ='QTR BS'!AP27 | M27: ='QTR BS'!AT27
A28: Deferred Revenue - Current | B28: 0 | C28: 0 | D28: 0 | E28: 9675 | F28: 9513 | G28: 9513 | H28: 26988 | I28: ='QTR BS'!AD28 | J28: ='QTR BS'!AH28 | K28: ='QTR BS'!AL28 | L28: ='QTR BS'!AP28 | M28: ='QTR BS'!AT28
A29: Other Current Liabilities | B29: 107.399 | C29: 425.232 | D29: 976.072 | E29: 3586 | F29: 10890 | G29: 15808 | H29: 36465 | I29: ='QTR BS'!AD29 | J29: ='QTR BS'!AH29 | K29: ='QTR BS'!AL29 | L29: ='QTR BS'!AP29 | M29: ='QTR BS'!AT29
A30: Total Current Liabilities | B30: =SUM(B19:B29) | C30: =SUM(C19:C29) | D30: =SUM(D19:D29) | E30: =SUM(E19:E29) | F30: =SUM(F19:F29) | G30: =SUM(G19:G29) | H30: =SUM(H19:H29) | I30: =SUM(I19:I29) | ... N30: =SUM(N19:N29)
A31: Lease Liability - Operating - Non-Current | B31: 107.311 | C31: 514.948 | D31: 657.935 | E31: 326 | F31: 955 | G31: 16674 | H31: 0 | I31: ='QTR BS'!AD31 | J31: ='QTR BS'!AH31 | K31: ='QTR BS'!AL31 | L31: ='QTR BS'!AP31 | M31: ='QTR BS'!AT31
A32: Lease Liability - Finance - Non-Current | B32: 132.537 | C32: 82.29 | D32: 45.408 | E32: 162 | F32: 193 | G32: 211 | H32: 0 | I32: ='QTR BS'!AD32 | J32: ='QTR BS'!AH32 | K32: ='QTR BS'!AL32 | L32: ='QTR BS'!AP32 | M32: ='QTR BS'!AT32
A33: Deferred Tax Liability | B33: 0 | C33: 0 | D33: 3146.394 | E33: 15919 | F33: 2880 | G33: 2330 | H33: 0 | I33: ='QTR BS'!AD33 | J33: ='QTR BS'!AH33 | K33: ='QTR BS'!AL33 | L33: ='QTR BS'!AP33 | M33: ='QTR BS'!AT33
A34: Long-Term Debt | B34: 0 | C34: 0 | D34: 0 | E34: 0 | F34: 0 | G34: 0 | H34: 669926 | I34: ='QTR BS'!AD34 | J34: ='QTR BS'!AH34 | K34: ='QTR BS'!AL34 | L34: ='QTR BS'!AP34 | M34: ='QTR BS'!AT34
A35: Deferred Revenue - Non-Current | B35: 0 | C35: 0 | D35: 0 | E35: 179788 | F35: 167227 | G35: 157714 | H35: 401155 | I35: ='QTR BS'!AD35 | J35: ='QTR BS'!AH35 | K35: ='QTR BS'!AL35 | L35: ='QTR BS'!AP35 | M35: ='QTR BS'!AT35
A36: Other Non-Current Liabilities | B36: 0 | C36: 0 | D36: 0 | E36: 0 | F36: 0 | G36: 0 | H36: 28372 | I36: ='QTR BS'!AD36 | J36: ='QTR BS'!AH36 | K36: ='QTR BS'!AL36 | L36: ='QTR BS'!AP36 | M36: ='QTR BS'!AT36
A37: Total Liabilities | B37: =B30+SUM(B31:B36) | C37: =C30+SUM(C31:C36) | D37: =D30+SUM(D31:D36) | E37: =E30+SUM(E31:E36) | F37: =F30+SUM(F31:F36) | G37: =G30+SUM(G31:G36) | H37: =H30+SUM(H31:H36) | I37: =I30+SUM(I31:I36) | ... N37: =N30+SUM(N31:N36)
A38: Convertible Preferred Stock | B38: 0 | C38: 0 | D38: 0 | E38: 824488 | F38: 824488 | G38: 824488 | H38: 1759975 | I38: ='QTR BS'!AD38 | J38: ='QTR BS'!AH38 | K38: ='QTR BS'!AL38 | L38: ='QTR BS'!AP38 | M38: ='QTR BS'!AT38
A39: Common Stock | B39: 68.942 | C39: 72.263 | D39: 74.909 | E39: 76 | F39: 77 | G39: 79 | H39: 101 | I39: ='QTR BS'!AD39 | J39: ='QTR BS'!AH39 | K39: ='QTR BS'!AL39 | L39: ='QTR BS'!AP39 | M39: ='QTR BS'!AT39
A40: Treasury Stock | B40: 0 | C40: 0 | D40: 0 | E40: 0 | F40: 0 | G40: 0 | H40: -48226 | I40: ='QTR BS'!AD40 | J40: ='QTR BS'!AH40 | K40: ='QTR BS'!AL40 | L40: ='QTR BS'!AP40 | M40: ='QTR BS'!AT40
...

Sheet CASH FLOW
B1: FY2019 | C1: FY2020 | D1: FY2021 | E1: FY2022 | F1: FY2023 | G1: FY2024 | H1: FY2025 | I1: FY2026E | J1: FY2027E | K1: FY2028E | L1: FY2029E | M1: FY2030E | N1: FY2031E
A2: Net Income (Loss) | B2: 9971.26 | C2: 8523.849 | D2: 3937 | E2: -187282 | F2: 226801 | G2: 145074 | H2: 107999 | I2: ='QTR CF'!Z2+'QTR CF'!AA2+'QTR CF'!AB2+'QTR CF'!AC2 | J2: ='QTR CF'!AD2+'QTR CF'!AE2+'QTR CF'!AF2+'QTR CF'!AG2 | K2: ='QTR CF'!AH2+'QTR CF'!AI2+'QTR CF'!AJ2+'QTR CF'!AK2 | L2: ='QTR CF'!AL2+'QTR CF'!AM2+'QTR CF'!AN2+'QTR CF'!AO2 | M2: ='QTR CF'!AP2+'QTR CF'!AQ2+'QTR CF'!AR2+'QTR CF'!AS2
A3: Depreciation | B3: 66.939 | C3: 127.263 | D3: 0 | E3: 0 | F3: 0 | G3: 0 | H3: 0 | I3: ='QTR CF'!Z3+'QTR CF'!AA3+'QTR CF'!AB3+'QTR CF'!AC3 | J3: ='QTR CF'!AD3+'QTR CF'!AE3+'QTR CF'!AF3+'QTR CF'!AG3 | K3: ='QTR CF'!AH3+'QTR CF'!AI3+'QTR CF'!AJ3+'QTR CF'!AK3 | L3: ='QTR CF'!AL3+'QTR CF'!AM3+'QTR CF'!AN3+'QTR CF'!AO3 | M3: ='QTR CF'!AP3+'QTR CF'!AQ3+'QTR CF'!AR3+'QTR CF'!AS3
A4: Amortization | B4: 826.474 | C4: 1484.303 | D4: 0 | E4: 0 | F4: 0 | G4: 0 | H4: 0 | I4: ='QTR CF'!Z4+'QTR CF'!AA4+'QTR CF'!AB4+'QTR CF'!AC4 | J4: ='QTR CF'!AD4+'QTR CF'!AE4+'QTR CF'!AF4+'QTR CF'!AG4 | K4: ='QTR CF'!AH4+'QTR CF'!AI4+'QTR CF'!AJ4+'QTR CF'!AK4 | L4: ='QTR CF'!AL4+'QTR CF'!AM4+'QTR CF'!AN4+'QTR CF'!AO4 | M4: ='QTR CF'!AP4+'QTR CF'!AQ4+'QTR CF'!AR4+'QTR CF'!AS4
A5: Depreciation & Amortization | B5: 0 | C5: 0 | D5: 1264 | E5: 1917 | F5: 3226 | G5: 7274 | H5: 29451 | I5: ='QTR CF'!Z6+'QTR CF'!AA6+'QTR CF'!AB6+'QTR CF'!AC6 | J5: ='QTR CF'!AD6+'QTR CF'!AE6+'QTR CF'!AF6+'QTR CF'!AG6 | K5: ='QTR CF'!AH6+'QTR CF'!AI6+'QTR CF'!AJ6+'QTR CF'!AK6 | L5: ='QTR CF'!AL6+'QTR CF'!AM6+'QTR CF'!AN6+'QTR CF'!AO6 | M5: ='QTR CF'!AP6+'QTR CF'!AQ6+'QTR CF'!AR6+'QTR CF'!AS6
A6: Impairment of Intangibles | B6: 0 | C6: 0 | D6: 0 | E6: 2379 | F6: 0 | G6: 0 | H6: 0 | I6: ='QTR CF'!Z5+'QTR CF'!AA5+'QTR CF'!AB5+'QTR CF'!AC5 | J6: ='QTR CF'!AD5+'QTR CF'!AE5+'QTR CF'!AF5+'QTR CF'!AG5 | K6: ='QTR CF'!AH5+'QTR CF'!AI5+'QTR CF'!AJ5+'QTR CF'!AK5 | L6: ='QTR CF'!AL5+'QTR CF'!AM5+'QTR CF'!AN5+'QTR CF'!AO5 | M6: ='QTR CF'!AP5+'QTR CF'!AQ5+'QTR CF'!AR5+'QTR CF'!AS5
A7: Allowance for Credit Losses | B7: 109.393 | C7: 257.177 | D7: 1494 | E7: 2352 | F7: 2128 | G7: 3294 | H7: 10600 | I7: ='QTR CF'!Z7+'QTR CF'!AA7+'QTR CF'!AB7+'QTR CF'!AC7 | J7: ='QTR CF'!AD7+'QTR CF'!AE7+'QTR CF'!AF7+'QTR CF'!AG7 | K7: ='QTR CF'!AH7+'QTR CF'!AI7+'QTR CF'!AJ7+'QTR CF'!AK7 | L7: ='QTR CF'!AL7+'QTR CF'!AM7+'QTR CF'!AN7+'QTR CF'!AO7 | M7: ='QTR CF'!AP7+'QTR CF'!AQ7+'QTR CF'!AR7+'QTR CF'!AS7
A8: Amortization of Deferred Other Costs | B8: 0 | C8: 0 | D8: 0 | E8: 5885 | F8: 14124 | G8: 14124 | H8: 26326 | I8: ='QTR CF'!Z8+'QTR CF'!AA8+'QTR CF'!AB8+'QTR CF'!AC8 | J8: ='QTR CF'!AD8+'QTR CF'!AE8+'QTR CF'!AF8+'QTR CF'!AG8 | K8: ='QTR CF'!AH8+'QTR CF'!AI8+'QTR CF'!AJ8+'QTR CF'!AK8 | L8: ='QTR CF'!AL8+'QTR CF'!AM8+'QTR CF'!AN8+'QTR CF'!AO8 | M8: ='QTR CF'!AP8+'QTR CF'!AQ8+'QTR CF'!AR8+'QTR CF'!AS8
A9: Inventory Write-Down | B9: 331.985 | C9: 747.507 | D9: 2355 | E9: 6131 | F9: 7312 | G9: 19086 | H9: 29190 | I9: ='QTR CF'!Z9+'QTR CF'!AA9+'QTR CF'!AB9+'QTR CF'!AC9 | J9: ='QTR CF'!AD9+'QTR CF'!AE9+'QTR CF'!AF9+'QTR CF'!AG9 | K9: ='QTR CF'!AH9+'QTR CF'!AI9+'QTR CF'!AJ9+'QTR CF'!AK9 | L9: ='QTR CF'!AL9+'QTR CF'!AM9+'QTR CF'!AN9+'QTR CF'!AO9 | M9: ='QTR CF'!AP9+'QTR CF'!AQ9+'QTR CF'!AR9+'QTR CF'!AS9
A10: Gain (Loss) on Disposal of PP&E | B10: 0 | C10: 0 | D10: 0 | E10: 0 | F10: 198 | G10: 173 | H10: 0 | I10: ='QTR CF'!Z10+'QTR CF'!AA10+'QTR CF'!AB10+'QTR CF'!AC10 | J10: ='QTR CF'!AD10+'QTR CF'!AE10+'QTR CF'!AF10+'QTR CF'!AG10 | K10: ='QTR CF'!AH10+'QTR CF'!AI10+'QTR CF'!AJ10+'QTR CF'!AK10 | L10: ='QTR CF'!AL10+'QTR CF'!AM10+'QTR CF'!AN10+'QTR CF'!AO10 | M10: ='QTR CF'!AP10+'QTR CF'!AQ10+'QTR CF'!AR10+'QTR CF'!AS10
A11: Stock-Based Compensation | B11: 4831.75 | C11: 6340 | D11: 36475 | E11: 20665 | F11: 21226 | G11: 19591 | H11: 28050 | I11: ='QTR CF'!Z11+'QTR CF'!AA11+'QTR CF'!AB11+'QTR CF'!AC11 | J11: ='QTR CF'!AD11+'QTR CF'!AE11+'QTR CF'!AF11+'QTR CF'!AG11 | K11: ='QTR CF'!AH11+'QTR CF'!AI11+'QTR CF'!AJ11+'QTR CF'!AK11 | L11: ='QTR CF'!AL11+'QTR CF'!AM11+'QTR CF'!AN11+'QTR CF'!AO11 | M11: ='QTR CF'!AP11+'QTR CF'!AQ11+'QTR CF'!AR11+'QTR CF'!AS11
A12: Gain on China Transaction | B12: -12461.037 | C12: -322.936 | D12: 0 | E12: 0 | F12: 0 | G12: 0 | H12: 0 | I12: ='QTR CF'!Z12+'QTR CF'!AA12+'QTR CF'!AB12+'QTR CF'!AC12 | J12: ='QTR CF'!AD12+'QTR CF'!AE12+'QTR CF'!AF12+'QTR CF'!AG12 | K12: ='QTR CF'!AH12+'QTR CF'!AI12+'QTR CF'!AJ12+'QTR CF'!AK12 | L12: ='QTR CF'!AL12+'QTR CF'!AM12+'QTR CF'!AN12+'QTR CF'!AO12 | M12: ='QTR CF'!AP12+'QTR CF'!AQ12+'QTR CF'!AR12+'QTR CF'!AS12
A13: (Benefit) Provision for Deferred Income Taxes | B13: 0 | C13: 0 | D13: -9201 | E13: 20244 | F13: -42055 | G13: -9730 | H13: -57336 | I13: ='QTR CF'!Z14+'QTR CF'!AA14+'QTR CF'!AB14+'QTR CF'!AC14 | J13: ='QTR CF'!AD14+'QTR CF'!AE14+'QTR CF'!AF14+'QTR CF'!AG14 | K13: ='QTR CF'!AH14+'QTR CF'!AI14+'QTR CF'!AJ14+'QTR CF'!AK14 | L13: ='QTR CF'!AL14+'QTR CF'!AM14+'QTR CF'!AN14+'QTR CF'!AO14 | M13: ='QTR CF'!AP14+'QTR CF'!AQ14+'QTR CF'!AR14+'QTR CF'!AS14
A14: Foreign Currency Gain (Loss) | B14: 0 | C14: 0 | D14: 880 | E14: 483 | F14: 1246 | G14: 1734 | H14: 0 | I14: ='QTR CF'!Z15+'QTR CF'!AA15+'QTR CF'!AB15+'QTR CF'!AC15 | J14: ='QTR CF'!AD15+'QTR CF'!AE15+'QTR CF'!AF15+'QTR CF'!AG15 | K14: ='QTR CF'!AH15+'QTR CF'!AI15+'QTR CF'!AJ15+'QTR CF'!AK15 | L14: ='QTR CF'!AL15+'QTR CF'!AM15+'QTR CF'!AN15+'QTR CF'!AO15 | M14: ='QTR CF'!AP15+'QTR CF'!AQ15+'QTR CF'!AR15+'QTR CF'!AS15
A15: Gain (Loss) on Lease Cancellations | B15: 0 | C15: -152.112 | D15: -28 | E15: 0 | F15: 0 | G15: 0 | H15: 0 | I15: ='QTR CF'!Z13+'QTR CF'!AA13+'QTR CF'!AB13+'QTR CF'!AC13 | J15: ='QTR CF'!AD13+'QTR CF'!AE13+'QTR CF'!AF13+'QTR CF'!AG13 | K15: ='QTR CF'!AH13+'QTR CF'!AI13+'QTR CF'!AJ13+'QTR CF'!AK13 | L15: ='QTR CF'!AL13+'QTR CF'!AM13+'QTR CF'!AN13+'QTR CF'!AO13 | M15: ='QTR CF'!AP13+'QTR CF'!AQ13+'QTR CF'!AR13+'QTR CF'!AS13
A16: Change in Fair Value of Contingent Consideration | B16: 0 | C16: 0 | D16: 0 | E16: 0 | F16: 0 | G16: 0 | H16: 13800 | I16: ='QTR CF'!Z16+'QTR CF'!AA16+'QTR CF'!AB16+'QTR CF'!AC16 | J16: ='QTR CF'!AD16+'QTR CF'!AE16+'QTR CF'!AF16+'QTR CF'!AG16 | K16: ='QTR CF'!AH16+'QTR CF'!AI16+'QTR CF'!AJ16+'QTR CF'!AK16 | L16: ='QTR CF'!AL16+'QTR CF'!AM16+'QTR CF'!AN16+'QTR CF'!AO16 | M16: ='QTR CF'!AP16+'QTR CF'!AQ16+'QTR CF'!AR16+'QTR CF'!AS16
A17: Gain (Loss) on Extinguishment of Debt | B17: 0 | C17: 0 | D17: 0 | E17: 0 | F17: 0 | G17: 0 | H17: 6003 | I17: ='QTR CF'!Z17+'QTR CF'!AA17+'QTR CF'!AB17+'QTR CF'!AC17 | J17: ='QTR CF'!AD17+'QTR CF'!AE17+'QTR CF'!AF17+'QTR CF'!AG17 | K17: ='QTR CF'!AH17+'QTR CF'!AI17+'QTR CF'!AJ17+'QTR CF'!AK17 | L17: ='QTR CF'!AL17+'QTR CF'!AM17+'QTR CF'!AN17+'QTR CF'!AO17 | M17: ='QTR CF'!AP17+'QTR CF'!AQ17+'QTR CF'!AR17+'QTR CF'!AS17
A18: Other Operating Items | B18: 0 | C18: 0 | D18: 0 | E18: 37 | F18: -28 | G18: -324 | H18: -1687 | I18: ='QTR CF'!Z18+'QTR CF'!AA18+'QTR CF'!AB18+'QTR CF'!AC18 | J18: ='QTR CF'!AD18+'QTR CF'!AE18+'QTR CF'!AF18+'QTR CF'!AG18 | K18: ='QTR CF'!AH18+'QTR CF'!AI18+'QTR CF'!AJ18+'QTR CF'!AK18 | L18: ='QTR CF'!AL18+'QTR CF'!AM18+'QTR CF'!AN18+'QTR CF'!AO18 | M18: ='QTR CF'!AP18+'QTR CF'!AQ18+'QTR CF'!AR18+'QTR CF'!AS18
A19: Accounts Receivable | B19: -1432.98 | C19: -7468.772 | D19: -25249 | E19: -26369 | F19: -121558 | G19: -89665 | H19: -412091 | I19: ='QTR CF'!Z19+'QTR CF'!AA19+'QTR CF'!AB19+'QTR CF'!AC19 | J19: ='QTR CF'!AD19+'QTR CF'!AE19+'QTR CF'!AF19+'QTR CF'!AG19 | K19: ='QTR CF'!AH19+'QTR CF'!AI19+'QTR CF'!AJ19+'QTR CF'!AK19 | L19: ='QTR CF'!AL19+'QTR CF'!AM19+'QTR CF'!AN19+'QTR CF'!AO19 | M19: ='QTR CF'!AP19+'QTR CF'!AQ19+'QTR CF'!AR19+'QTR CF'!AS19
A20: Note Receivable | B20: 0 | C20: 0 | D20: 0 | E20: 0 | F20: 0 | G20: 2318 | H20: 0 | I20: ='QTR CF'!Z20+'QTR CF'!AA20+'QTR CF'!AB20+'QTR CF'!AC20 | J20: ='QTR CF'!AD20+'QTR CF'!AE20+'QTR CF'!AF20+'QTR CF'!AG20 | K20: ='QTR CF'!AH20+'QTR CF'!AI20+'QTR CF'!AJ20+'QTR CF'!AK20 | L20: ='QTR CF'!AL20+'QTR CF'!AM20+'QTR CF'!AN20+'QTR CF'!AO20 | M20: ='QTR CF'!AP20+'QTR CF'!AQ20+'QTR CF'!AR20+'QTR CF'!AS20
A21: Inventories | B21: -2239.254 | C21: -3858.78 | D21: -175174 | E21: 11802 | F21: -63299 | G21: 77190 | H21: -129777 | I21: ='QTR CF'!Z21+'QTR CF'!AA21+'QTR CF'!AB21+'QTR CF'!AC21 | J21: ='QTR CF'!AD21+'QTR CF'!AE21+'QTR CF'!AF21+'QTR CF'!AG21 | K21: ='QTR CF'!AH21+'QTR CF'!AI21+'QTR CF'!AJ21+'QTR CF'!AK21 | L21: ='QTR CF'!AL21+'QTR CF'!AM21+'QTR CF'!AN21+'QTR CF'!AO21 | M21: ='QTR CF'!AP21+'QTR CF'!AQ21+'QTR CF'!AR21+'QTR CF'!AS21
A22: Prepaid Expenses | B22: -805.571 | C22: -10456.787 | D22: 1072 | E22: 2214 | F22: -7980 | G22: 1074 | H22: -108321 | I22: ='QTR CF'!Z22+'QTR CF'!AA22+'QTR CF'!AB22+'QTR CF'!AC22 | J22: ='QTR CF'!AD22+'QTR CF'!AE22+'QTR CF'!AF22+'QTR CF'!AG22 | K22: ='QTR CF'!AH22+'QTR CF'!AI22+'QTR CF'!AJ22+'QTR CF'!AK22 | L22: ='QTR CF'!AL22+'QTR CF'!AM22+'QTR CF'!AN22+'QTR CF'!AO22 | M22: ='QTR CF'!AP22+'QTR CF'!AQ22+'QTR CF'!AR22+'QTR CF'!AS22
A23: Change in A/P and Accrued (legacy) | B23: 2624.892 | C23: 8120.106 | D23: 0 | E23: 0 | F23: 0 | G23: 0 | H23: 0 | I23: ='QTR CF'!Z23+'QTR CF'!AA23+'QTR CF'!AB23+'QTR CF'!AC23 | J23: ='QTR CF'!AD23+'QTR CF'!AE23+'QTR CF'!AF23+'QTR CF'!AG23 | K23: ='QTR CF'!AH23+'QTR CF'!AI23+'QTR CF'!AJ23+'QTR CF'!AK23 | L23: ='QTR CF'!AL23+'QTR CF'!AM23+'QTR CF'!AN23+'QTR CF'!AO23 | M23: ='QTR CF'!AP23+'QTR CF'!AQ23+'QTR CF'!AR23+'QTR CF'!AS23
A24: Other Non-Current Assets | B24: 0 | C24: 0 | D24: 0 | E24: 0 | F24: 0 | G24: -4862 | H24: 2857 | I24: ='QTR CF'!Z24+'QTR CF'!AA24+'QTR CF'!AB24+'QTR CF'!AC24 | J24: ='QTR CF'!AD24+'QTR CF'!AE24+'QTR CF'!AF24+'QTR CF'!AG24 | K24: ='QTR CF'!AH24+'QTR CF'!AI24+'QTR CF'!AJ24+'QTR CF'!AK24 | L24: ='QTR CF'!AL24+'QTR CF'!AM24+'QTR CF'!AN24+'QTR CF'!AO24 | M24: ='QTR CF'!AP24+'QTR CF'!AQ24+'QTR CF'!AR24+'QTR CF'!AS24
A25: Accounts Payable | B25: 0 | C25: 0 | D25: 23966 | E25: 428 | F25: 5249 | G25: -1170 | H25: 51252 | I25: ='QTR CF'!Z25+'QTR CF'!AA25+'QTR CF'!AB25+'QTR CF'!AC25 | J25: ='QTR CF'!AD25+'QTR CF'!AE25+'QTR CF'!AF25+'QTR CF'!AG25 | K25: ='QTR CF'!AH25+'QTR CF'!AI25+'QTR CF'!AJ25+'QTR CF'!AK25 | L25: ='QTR CF'!AL25+'QTR CF'!AM25+'QTR CF'!AN25+'QTR CF'!AO25 | M25: ='QTR CF'!AP25+'QTR CF'!AQ25+'QTR CF'!AR25+'QTR CF'!AS25
A26: Accrued Expenses | B26: 0 | C26: 0 | D26: 26484 | E26: 34644 | F26: -8025 | G26: 85398 | H26: 45618 | I26: ='QTR CF'!Z26+'QTR CF'!AA26+'QTR CF'!AB26+'QTR CF'!AC26 | J26: ='QTR CF'!AD26+'QTR CF'!AE26+'QTR CF'!AF26+'QTR CF'!AG26 | K26: ='QTR CF'!AH26+'QTR CF'!AI26+'QTR CF'!AJ26+'QTR CF'!AK26 | L26: ='QTR CF'!AL26+'QTR CF'!AM26+'QTR CF'!AN26+'QTR CF'!AO26 | M26: ='QTR CF'!AP26+'QTR CF'!AQ26+'QTR CF'!AR26+'QTR CF'!AS26
A27: Change in Income Taxes | B27: 0 | C27: 0 | D27: 1357 | E27: -164 | F27: 48102 | G27: -39536 | H27: 38750 | I27: ='QTR CF'!Z27+'QTR CF'!AA27+'QTR CF'!AB27+'QTR CF'!AC27 | J27: ='QTR CF'!AD27+'QTR CF'!AE27+'QTR CF'!AF27+'QTR CF'!AG27 | K27: ='QTR CF'!AH27+'QTR CF'!AI27+'QTR CF'!AJ27+'QTR CF'!AK27 | L27: ='QTR CF'!AL27+'QTR CF'!AM27+'QTR CF'!AN27+'QTR CF'!AO27 | M27: ='QTR CF'!AP27+'QTR CF'!AQ27+'QTR CF'!AR27+'QTR CF'!AS27
... A33: Net Change in Other Working Capital | B33: 0 | C33: 0 | D33: 0 | E33: 0 | F33: 0 | G33: 0 | H33: 2481 | I33: ='QTR CF'!Z33+'QTR CF'!AA33+'QTR CF'!AB33+'QTR CF'!AC33 | J33: ='QTR CF'!AD33+'QTR CF'!AE33+'QTR CF'!AF33+'QTR CF'!AG33 | K33: ='QTR CF'!AH33+'QTR CF'!AI33+'QTR CF'!AJ33+'QTR CF'!AK33 | L33: ='QTR CF'!AL33+'QTR CF'!AM33+'QTR CF'!AN33+'QTR CF'!AO33 | M33: ='QTR CF'!AP33+'QTR CF'!AQ33+'QTR CF'!AR33+'QTR CF'!AS33
A34: Cash Flow from Operations | B34: =SUM(B2:B33) | C34: =SUM(C2:C33) | D34: =SUM(D2:D33) | E34: =SUM(E2:E33) | F34: =SUM(F2:F33) | G34: =SUM(G2:G33) | H34: =SUM(H2:H33) | I34: =SUM(I2:I33) | ... N34: =SUM(N2:N33)
A35: Collections from Note Receivable | B35: 0 | C35: 1331.011 | D35: 1886 | E35: 2592 | F35: 3233 | G35: 0 | H35: 0 | I35: ='QTR CF'!Z35+'QTR CF'!AA35+'QTR CF'!AB35+'QTR CF'!AC35 | J35: ='QTR CF'!AD35+'QTR CF'!AE35+'QTR CF'!AF35+'QTR CF'!AG35 | K35: ='QTR CF'!AH35+'QTR CF'!AI35+'QTR CF'!AJ35+'QTR CF'!AK35 | L35: ='QTR CF'!AL35+'QTR CF'!AM35+'QTR CF'!AN35+'QTR CF'!AO35 | M35: ='QTR CF'!AP35+'QTR CF'!AQ35+'QTR CF'!AR35+'QTR CF'!AS35
A36: Purchase of PP&E | B36: -77.974 | C36: -573.751 | D36: -3150 | E36: -8264 | F36: -17433 | G36: -23390 | H36: -36067 | I36: ='QTR CF'!Z36+'QTR CF'!AA36+'QTR CF'!AB36+'QTR CF'!AC36 | J36: ='QTR CF'!AD36+'QTR CF'!AE36+'QTR CF'!AF36+'QTR CF'!AG36 | K36: ='QTR CF'!AH36+'QTR CF'!AI36+'QTR CF'!AJ36+'QTR CF'!AK36 | L36: ='QTR CF'!AL36+'QTR CF'!AM36+'QTR CF'!AN36+'QTR CF'!AO36 | M36: ='QTR CF'!AP36+'QTR CF'!AQ36+'QTR CF'!AR36+'QTR CF'!AS36
A37: Purchase of Non-Marketable Equity Securities | B37: 0 | C37: 0 | D37: 0 | E37: 0 | F37: 0 | G37: -3000 | H37: -10000 | I37: ='QTR CF'!Z37+'QTR CF'!AA37+'QTR CF'!AB37+'QTR CF'!AC37 | J37: ='QTR CF'!AD37+'QTR CF'!AE37+'QTR CF'!AF37+'QTR CF'!AG37 | K37: ='QTR CF'!AH37+'QTR CF'!AI37+'QTR CF'!AJ37+'QTR CF'!AK37 | L37: ='QTR CF'!AL37+'QTR CF'!AM37+'QTR CF'!AN37+'QTR CF'!AO37 | M37: ='QTR CF'!AP37+'QTR CF'!AQ37+'QTR CF'!AR37+'QTR CF'!AS37
A38: Acquisition of Big Beverages | B38: 0 | C38: 0 | D38: 0 | E38: 0 | F38: 0 | G38: -75336 | H38: 0 | I38: ='QTR CF'!Z38+'QTR CF'!AA38+'QTR CF'!AB38+'QTR CF'!AC38 | J38: ='QTR CF'!AD38+'QTR CF'!AE38+'QTR CF'!AF38+'QTR CF'!AG38 | K38: ='QTR CF'!AH38+'QTR CF'!AI38+'QTR CF'!AJ38+'QTR CF'!AK38 | L38: ='QTR CF'!AL38+'QTR CF'!AM38+'QTR CF'!AN38+'QTR CF'!AO38 | M38: ='QTR CF'!AP38+'QTR CF'!AQ38+'QTR CF'!AR38+'QTR CF'!AS38
A39: Acquisitions, Net of Cash Acquired | B39: -14188.056 | C39: 0 | D39: 0 | E39: 0 | F39: 0 | G39: 0 | H39: -1278769 | I39: ='QTR CF'!Z39+'QTR CF'!AA39+'QTR CF'!AB39+'QTR CF'!AC39 | J39: ='QTR CF'!AD39+'QTR CF'!AE39+'QTR CF'!AF39+'QTR CF'!AG39 | K39: ='QTR CF'!AH39+'QTR CF'!AI39+'QTR CF'!AJ39+'QTR CF'!AK39 | L39: ='QTR CF'!AL39+'QTR CF'!AM39+'QTR CF'!AN39+'QTR CF'!AO39 | M39: ='QTR CF'!AP39+'QTR CF'!AQ39+'QTR CF'!AR39+'QTR CF'!AS39
A40: Working Capital Estimate from Pepsi (Rockstar) | B40: 0 | C40: 0 | D40: 0 | E40: 0 | F40: 0 | G40: 0 | H40: 29156 | I40: ='QTR CF'!Z40+'QTR CF'!AA40+'QTR CF'!AB40+'QTR CF'!AC40 | J40: ='QTR CF'!AD40+'QTR CF'!AE40+'QTR CF'!AF40+'QTR CF'!AG40 | K40: ='QTR CF'!AH40+'QTR CF'!AI40+'QTR CF'!AJ40+'QTR CF'!AK40 | L40: ='QTR CF'!AL40+'QTR CF'!AM40+'QTR CF'!AN40+'QTR CF'!AO40 | M40: ='QTR CF'!AP40+'QTR CF'!AQ40+'QTR CF'!AR40+'QTR CF'!AS40
A41: Cash Flow from Investing | B41: =SUM(B35:B40) | C41: =SUM(C35:C40) | D41: =SUM(D35:D40) | E41: =SUM(E35:E40) | F41: =SUM(F35:F40) | G41: =SUM(G35:G40) | H41: =SUM(H35:H40) | I41: =SUM(I35:I40) | ... N41: =SUM(N35:N40)
A42: Proceeds from Related-Party Notes | B42: 1500 | C42: 0 | D42: 0 | E42: 0 | F42: 0 | G42: 0 | H42: 0 | I42: ='QTR CF'!Z42+'QTR CF'!AA42+'QTR CF'!AB42+'QTR CF'!AC42 | J42: ='QTR CF'!AD42+'QTR CF'!AE42+'QTR CF'!AF42+'QTR CF'!AG42 | K42: ='QTR CF'!AH42+'QTR CF'!AI42+'QTR CF'!AJ42+'QTR CF'!AK42 | L42: ='QTR CF'!AL42+'QTR CF'!AM42+'QTR CF'!AN42+'QTR CF'!AO42 | M42: ='QTR CF'!AP42+'QTR CF'!AQ42+'QTR CF'!AR42+'QTR CF'!AS42
A43: Payments on Bonds Payable | B43: 0 | C43: -9601.531 | D43: 0 | E43: 0 | F43: 0 | G43: 0 | H43: 0 | I43: ='QTR CF'!Z43+'QTR CF'!AA43+'QTR CF'!AB43+'QTR CF'!AC43 | J43: ='QTR CF'!AD43+'QTR CF'!AE43+'QTR CF'!AF43+'QTR CF'!AG43 | K43: ='QTR CF'!AH43+'QTR CF'!AI43+'QTR CF'!AJ43+'QTR CF'!AK43 | L43: ='QTR CF'!AL43+'QTR CF'!AM43+'QTR CF'!AN43+'QTR CF'!AO43 | M43: ='QTR CF'!AP43+'QTR CF'!AQ43+'QTR CF'!AR43+'QTR CF'!AS43
A44: Finance Lease Payments | B44: -26.486 | C44: -280.208 | D44: -94 | E44: -63 | F44: -44 | G44: -61 | H44: 0 | I44: ='QTR CF'!Z44+'QTR CF'!AA44+'QTR CF'!AB44+'QTR CF'!AC44 | J44: ='QTR CF'!AD44+'QTR CF'!AE44+'QTR CF'!AF44+'QTR CF'!AG44 | K44: ='QTR CF'!AH44+'QTR CF'!AI44+'QTR CF'!AJ44+'QTR CF'!AK44 | L44: ='QTR CF'!AL44+'QTR CF'!AM44+'QTR CF'!AN44+'QTR CF'!AO44 | M44: ='QTR CF'!AP44+'QTR CF'!AQ44+'QTR CF'!AR44+'QTR CF'!AS44
A45: Proceeds from Exercise of Stock Options | B45: 224.083 | C45: 4126.791 | D45: 3720 | E45: 3683 | F45: 2285 | G45: 3856 | H45: 0 | I45: ='QTR CF'!Z46+'QTR CF'!AA46+'QTR CF'!AB46+'QTR CF'!AC46 | J45: ='QTR CF'!AD46+'QTR CF'!AE46+'QTR CF'!AF46+'QTR CF'!AG46 | K45: ='QTR CF'!AH46+'QTR CF'!AI46+'QTR CF'!AJ46+'QTR CF'!AK46 | L45: ='QTR CF'!AL46+'QTR CF'!AM46+'QTR CF'!AN46+'QTR CF'!AO46 | M45: ='QTR CF'!AP46+'QTR CF'!AQ46+'QTR CF'!AR46+'QTR CF'!AS46
...

Sheet YTD P&L
B1: Q1 FY2019 | C1: Q2 FY2019 | D1: Q3 FY2019 | E1: Q1 FY2020 | F1: Q2 FY2020 | G1: Q3 FY2020 | H1: Q1 FY2021 | I1: Q2 FY2021 | J1: Q3 FY2021 | K1: Q1 FY2022 | L1: Q2 FY2022 | M1: Q3 FY2022 | N1: Q1 FY2023 | O1: Q2 FY2023 | P1: Q3 FY2023 | Q1: Q1 FY2024 | R1: Q2 FY2024 | S1: Q3 FY2024 | T1: Q1 FY2025 | U1: Q2 FY2025 | V1: Q3 FY2025
A2: Net Sales / Revenue | B2: 14485.65 | C2: 30607.579 | D2: 51031.426 | E2: 28184.889 | F2: 58222.116 | G2: 95061.265 | H2: 50034.879 | I2: 115108.2 | J2: 210017.3 | K2: 133388 | L2: 287408 | M2: 475640 | N2: 259939 | O2: 585822 | P2: 970579 | Q2: 355708 | R2: 757685 | S2: 1023433 | T2: 329276 | U2: 1068535 | V2: 1793641
A3: COGS | B3: -8764.592 | C3: -18020.49 | D3: -29821.968 | E3: -15182.706 | F3: -32207.118 | G3: -51512.534 | H3: -29455.784 | I3: -66279.738 | J3: -123495.47 | K3: -79494 | L3: -174195 | M3: -283778 | N3: -146121 | O3: -313010 | P3: -503685 | Q3: -173501 | R3: -366380 | S3: -509899 | T3: -156903 | U3: -515311 | V3: -868138
A4: Gross Profit (Loss) | B4: =B2+B3 | C4: =C2+C3 | D4: =D2+D3 | E4: =E2+E3 | F4: =F2+F3 | G4: =G2+G3 | H4: =H2+H3 | I4: =I2+I3 | ... V4: =V2+V3
A5: Sales and Marketing | B5: -3601.003 | C5: -9162.942 | D5: -14086.91 | E5: -7506.047 | F5: -15372.918 | G5: -23640.914 | H5: -11959.053 | I5: -27490.041 | J5: -50111.103 | K5: -31597 | L5: -64072 | M5: -262782 | N5: 0 | O5: 0 | P5: 0 | Q5: 0 | R5: 0 | S5: 0 | T5: 0 | U5: 0 | V5: 0
A6: General and Administrative | B6: -2622.102 | C6: -5054.848 | D6: -7249.378 | E6: -4247.853 | F6: -7902.571 | G6: -12460.009 | H6: -7806.666 | I6: -16926.198 | J6: -28066.228 | K6: -12181 | L6: -26595 | M6: -54135 | N6: 0 | O6: 0 | P6: 0 | Q6: 0 | R6: 0 | S6: 0 | T6: 0 | U6: 0 | V6: 0
A7: Operating Expenses | B7: -6223.105 | C7: -14217.79 | D7: -21336.288 | E7: -11753.9 | F7: -23275.489 | G7: -36100.923 | H7: -19765.719 | I7: -44416.239 | J7: -78177.331 | K7: -43778 | L7: -90667 | M7: -316917 | N7: 0 | O7: 0 | P7: 0 | Q7: 0 | R7: 0 | S7: 0 | T7: 0 | U7: 0 | V7: 0
A8: SG&A | B8: 0 | C8: 0 | D8: 0 | E8: 0 | F8: 0 | G8: 0 | H8: 0 | I8: 0 | J8: 0 | K8: 0 | L8: 0 | M8: 0 | N8: -68905 | O8: -163086 | P8: -259471 | Q8: -99017 | R8: -213867 | S8: -339310 | T8: -120342 | U8: -358228 | V8: -563799
A9: Distributor Termination Fees | B9: 0 | C9: 0 | D9: 0 | E9: 0 | F9: 0 | G9: 0 | H9: 0 | I9: 0 | J9: 0 | K9: 0 | L9: 0 | M9: 0 | N9: 0 | O9: 0 | P9: 0 | Q9: 0 | R9: 0 | S9: 0 | T9: 0 | U9: 0 | V9: -246707
A10: Income (Loss) from Operations | B10: =B4+SUM(B5:B9) | C10: =C4+SUM(C5:C9) | D10: =D4+SUM(D5:D9) | E10: =E4+SUM(E5:E9) | F10: =F4+SUM(F5:F9) | G10: =G4+SUM(G5:G9) | H10: =H4+SUM(H5:H9) | I10: =I4+SUM(I5:I9) | ... V10: =V4+SUM(V5:V9)
A11: Interest Income (Expense) | B11: -114.572 | C11: -238.809 | D11: -779.749 | E11: -341.718 | F11: -394.85 | G11: -642.249 | H11: 84.925 | I11: 160.141 | J11: 232.09 | K11: 76 | L11: 129 | M11: 1579 | N11: 4969 | O11: 10542 | P11: 17767 | Q11: 9640 | R11: 20287 | S11: 31399 | T11: 7846 | U11: -6196 | V11: -19592
A12: Other Income (Expense) | B12: 12273.213 | C12: 12052.809 | D12: 12050.921 | E12: -282.591 | F12: -511.491 | G12: -361.705 | H12: -11.621 | I12: 97.038 | J12: 0 | K12: 0 | L12: 0 | M12: 0 | N12: 0 | O12: 0 | P12: 0 | Q12: 0 | R12: 0 | S12: 0 | T12: 1116 | U12: 1658 | V12: 7022
A13: Foreign Currency Gain (Loss) | B13: 260.665 | C13: 0 | D13: 0 | E13: -192.413 | F13: -119.105 | G13: 262.022 | H13: -301.256 | I13: -123.636 | J13: -451.217 | K13: -162 | L13: -676 | M13: -930 | N13: -118 | O13: -1049 | P13: -1226 | Q13: -369 | R13: -633 | S13: -356 | T13: 0 | U13: 0 | V13: 0
A14: Gain (Loss) on Lease Cancellations | B14: 0 | C14: 0 | D14: 0 | E14: 0 | F14: 152.112 | G14: 152.112 | H14: 0 | I14: 0 | J14: 0 | K14: 0 | L14: 0 | M14: 0 | N14: 0 | O14: 0 | P14: 0 | Q14: 0 | R14: 0 | S14: 0 | T14: 0 | U14: 0 | V14: 0
A15: Income Tax (Expense) Benefit | B15: 0 | C15: 0 | D15: 0 | E15: 0 | F15: 0 | G15: 0 | H15: 0 | I15: 0 | J15: -833.819 | K15: -3351 | L15: -6161 | M15: -41653 | N15: -8537 | O15: -26483 | P15: -47279 | Q15: -14650 | R15: -39498 | S15: -41317 | T15: -16574 | U15: -46184 | V15: -19167
A16: Pre-Tax Income (Loss) | B16: =B10+SUM(B11:B15) | C16: =C10+SUM(C11:C15) | D16: =D10+SUM(D11:D15) | E16: =E10+SUM(E11:E15) | F16: =F10+SUM(F11:F15) | G16: =G10+SUM(G11:G15) | H16: =H10+SUM(H11:H15) | I16: =I10+SUM(I11:I15) | ... V16: =V10+SUM(V11:V15)
A17: Net Income (Loss) | B17: =B16 | C17: =C16 | D17: =D16 | E17: =E16 | F17: =F16 | G17: =G16 | H17: =H16 | I17: =I16 | ... V17: =V16
A18: Basic Earnings (Loss) per Share | B18: 0.2 | C18: 0.18 | D18: 0.19 | E18: 0.01 | F18: 0.03 | G18: 0.1 | H18: 0.01 | I18: 0 | J18: 0 | K18: 0 | L18: 0 | M18: 0 | N18: 0 | O18: 0 | P18: 0 | Q18: 0 | R18: 0 | S18: 0 | T18: 0 | U18: 0 | V18: 0
A19: Diluted Earnings (Loss) per Share | B19: 0.19 | C19: 0.17 | D19: 0.2 | E19: 0.01 | F19: 0.03 | G19: 0.09 | H19: 0.01 | I19: 0 | J19: 0 | K19: 0 | L19: 0 | M19: 0 | N19: 0 | O19: 0 | P19: 0 | Q19: 0 | R19: 0 | S19: 0 | T19: 0 | U19: 0 | V19: 0
A20: Weighted Average Shares Outstanding (Basic) | B20: 57155445 | C20: 57267622 | D20: 58023685 | E20: 69284307 | F20: 69444655 | G20: 70184071 | H20: 72516396 | I20: 0 | J20: 0 | K20: 0 | L20: 0 | M20: 0 | N20: 0 | O20: 0 | P20: 0 | Q20: 0 | R20: 0 | S20: 0 | T20: 0 | U20: 0 | V20: 0
A21: Weighted Average Shares Outstanding (Diluted) | B21: 61687409 | C21: 61817621 | D21: 62050032 | E21: 70339416 | F21: 71073534 | G21: 73524209 | H21: 76925484 | I21: 0 | J21: 0 | K21: 0 | L21: 0 | M21: 0 | N21: 0 | O21: 0 | P21: 0 | Q21: 0 | R21: 0 | S21: 0 | T21: 0 | U21: 0 | V21: 0
A22: Preferred Dividends | B22: 0 | C22: 0 | D22: 0 | E22: 0 | F22: 0 | G22: 0 | H22: 0 | I22: 0 | J22: 0 | K22: 0 | L22: 0 | M22: -4596 | N22: -6781 | O22: -13637 | P22: -20512 | Q22: -6837 | R22: -13675 | S22: -20588 | T22: -6781 | U22: -13632 | V22: -23289
A23: Income Allocated to Participating Preferred | B23: 0 | C23: 0 | D23: 0 | E23: 0 | F23: 0 | G23: 0 | H23: 0 | I23: 0 | J23: 0 | K23: 0 | L23: 0 | M23: 0 | N23: 0 | O23: -6727 | P23: -13263 | Q23: -6128 | R23: -12417 | S23: -12357 | T23: -3219 | U23: -10703 | V23: -5272
A24: Net Income (Loss) Attributable to Common Shareholders | B24: =B17+B22+B23 | C24: =C17+C22+C23 | D24: =D17+D22+D23 | E24: =E17+E22+E23 | F24: =F17+F22+F23 | G24: =G17+G22+G23 | H24: =H17+H22+H23 | I24: =I17+I22+I23 | ... V24: =V17+V22+V23

Sheet YTD BS
B1: Q4 FY2019 | C1: Q1 FY2020 | D1: Q2 FY2020 | E1: Q3 FY2020 | F1: Q4 FY2020 | G1: Q1 FY2021 | H1: Q2 FY2021 | I1: Q3 FY2021 | J1: Q4 FY2021 | K1: Q1 FY2022 | L1: Q2 FY2022 | M1: Q3 FY2022 | N1: Q4 FY2022 | O1: Q1 FY2023 | P1: Q2 FY2023 | Q1: Q3 FY2023 | R1: Q4 FY2023 | S1: Q1 FY2024 | T1: Q2 FY2024 | U1: Q3 FY2024 | V1: Q4 FY2024 | W1: Q1 FY2025 | X1: Q2 FY2025 | Y1: Q3 FY2025
A2: Cash, Cash Equivalents & Restricted Cash | B2: 23090.682 | C2: 19094.101 | D2: 20110.815 | E2: 52158.098 | F2: 43248.021 | G2: 31634.675 | H2: 83789.981 | I2: 61377.202 | J2: 16255 | K2: 25532 | L2: 60031 | M2: 726972 | N2: 652927 | O2: 633581 | P2: 681054 | Q2: 760022 | R2: 755981 | S2: 879498 | T2: 903210 | U2: 903748 | V2: 890190 | W2: 977285 | X2: 615233 | Y2: 932463
A3: Accounts Receivable | B3: 7774.618 | C3: 10699.811 | D3: 12221.985 | E3: 16561.371 | F3: 14986.213 | G3: 23997.68 | H3: 32398.823 | I3: 43500.578 | J3: 38741 | K3: 72707 | L3: 66195 | M3: 117003 | N3: 63311 | O3: 172032 | P3: 197811 | Q3: 215243 | R3: 183703 | S3: 200117 | T3: 262920 | U3: 208774 | V3: 270342 | W3: 256424 | X3: 490389 | Y3: 513682
A4: Note Receivable - Current | B4: 1181.116 | C4: 1157.754 | D4: 1742.841 | E4: 1810.773 | F4: 1885.887 | G4: 2509.412 | H4: 2545.745 | I4: 2543.225 | J4: 2588 | K4: 5833 | L4: 3066 | M4: 2888 | N4: 2979 | O4: 3587 | P4: 3323 | Q4: 3309 | R4: 2318 | S4: 2259 | T4: 1166 | U4: 1025 | V4: 0 | W4: 0 | X4: 0 | Y4: 0
A5: Inventories | B5: 15292.349 | C5: 21038.367 | D5: 23512.418 | E5: 15679.192 | F5: 18403.622 | G5: 36891.859 | H5: 63826.596 | I5: 122311.45 | J5: 191222 | K5: 184094 | L5: 162138 | M5: 153933 | N5: 173289 | O5: 154280 | P5: 152545 | Q5: 198704 | R5: 229275 | S5: 197504 | T5: 180669 | U5: 197572 | V5: 131165 | W5: 141159 | X5: 230046 | Y5: 282514
A6: Prepaid Expenses | B6: 4170.136 | C6: 4671.721 | D6: 4312.554 | E6: 4731.887 | F6: 14626.922 | G6: 17183.929 | H6: 22744.642 | I6: 22829.51 | J6: 13555 | K6: 10042 | L6: 12298 | M6: 12096 | N6: 11341 | O6: 15507 | P6: 23398 | Q6: 23747 | R6: 19503 | S6: 21523 | T6: 22900 | U6: 38227 | V6: 18759 | W6: 22464 | X6: 41420 | Y6: 163395
A7: Deferred Other Costs - Current | B7: 0 | C7: 0 | D7: 0 | E7: 0 | F7: 0 | G7: 0 | H7: 0 | I7: 0 | J7: 0 | K7: 0 | L7: 0 | M7: 14124 | N7: 14124 | O7: 14124 | P7: 14124 | Q7: 14124 | R7: 14124 | S7: 14124 | T7: 14124 | U7: 14124 | V7: 14124 | W7: 14124 | X7: 14124 | Y7: 49520
A8: Total Current Assets | B8: =SUM(B2:B7) | C8: =SUM(C2:C7) | D8: =SUM(D2:D7) | E8: =SUM(E2:E7) | F8: =SUM(F2:F7) | G8: =SUM(G2:G7) | H8: =SUM(H2:H7) | I8: =SUM(I2:I7) | ... Y8: =SUM(Y2:Y7)
A9: Note Receivable - Non-Current | B9: 10630.041 | C9: 10416.12 | D9: 8714.205 | E9: 9053.866 | F9: 9429.437 | G9: 6900.882 | H9: 7000.8 | I9: 6993.869 | J9: 7117 | K9: 3888 | L9: 3679 | M9: 3465 | N9: 3574 | O9: 0 | P9: 0 | Q9: 0 | R9: 0 | S9: 0 | T9: 0 | U9: 0 | V9: 0 | W9: 0 | X9: 0 | Y9: 0
A10: Net PP&E | B10: 132.889 | C10: 115.324 | D10: 398.315 | E10: 467.38 | F10: 579.377 | G10: 1169.022 | H10: 1617.002 | I10: 2454.914 | J10: 3180 | K10: 3702 | L10: 5135 | M10: 5782 | N10: 10185 | O10: 12054 | P10: 15892 | Q10: 21061 | R10: 24868 | S10: 28350 | T10: 36282 | U10: 38370 | V10: 55602 | W10: 58698 | X10: 72516 | Y10: 80925
A11: ROU Assets - Operating - Non-Current | B11: 0 | C11: 0 | D11: 0 | E11: 0 | F11: 836.038 | G11: 791.969 | H11: 704.857 | I11: 888.911 | J11: 1128 | K11: 1141 | L11: 954 | M11: 1105 | N11: 972 | O11: 931 | P11: 756 | Q11: 1152 | R11: 1957 | S11: 1688 | T11: 1507 | U11: 5506 | V11: 21606 | W11: 20866 | X11: 0 | Y11: 0
A12: Intangible Assets | B12: 17173 | C12: 17029.472 | D12: 16888.97 | E12: 16740.838 | F12: 16590.083 | G12: 16439.197 | H12: 16287.537 | I12: 16811.762 | J12: 16301 | K12: 15838 | L12: 14689 | M12: 11322 | N12: 12254 | O12: 12359 | P12: 12211 | Q12: 11772 | R12: 12139 | S12: 11741 | T12: 11491 | U12: 11877 | V12: 12213 | W12: 12444 | X12: 1222115 | Y12: 1397819
A13: Goodwill | B13: 10023.806 | C13: 10023.806 | D13: 10419.321 | E13: 10419.321 | F13: 10419.321 | G13: 10419.321 | H13: 10419.321 | I13: 14851.635 | J13: 14527 | K13: 14238 | L13: 13323 | M13: 12502 | N13: 13679 | O13: 13949 | P13: 13937 | Q13: 13588 | R13: 14173 | S13: 13866 | T13: 13730 | U13: 14360 | V13: 71582 | W13: 72128 | X13: 802234 | Y13: 914957
A14: Deferred Other Costs - Non-Current | B14: 0 | C14: 0 | D14: 0 | E14: 0 | F14: 0 | G14: 0 | H14: 0 | I14: 0 | J14: 0 | K14: 0 | L14: 0 | M14: 265993 | N14: 262462 | O14: 258931 | P14: 255400 | Q14: 251869 | R14: 248338 | S14: 244807 | T14: 241276 | U14: 237746 | V14: 234215 | W14: 230684 | X14: 227153 | Y14: 784214
A15: Deferred Tax Assets | B15: 0 | C15: 0 | D15: 0 | E15: 0 | F15: 0 | G15: 0 | H15: 0 | I15: 0 | J15: 9019 | K15: 6396 | L15: 7686 | M15: 0 | N15: 501 | O15: 482 | P15: 28373 | Q15: 30614 | R15: 29518 | S15: 22437 | T15: 22727 | U15: 24186 | V15: 38699 | W15: 38525 | X15: 43158 | Y15: 110410
A16: ROU Assets - Finance - Non-Current | B16: 809.466 | C16: 626.12 | D16: 524.15 | E16: 415.595 | F16: 162.119 | G16: 129.625 | H16: 100.365 | I16: 106.675 | J16: 86 | K16: 220 | L16: 180 | M16: 222 | N16: 208 | O16: 191 | P16: 171 | Q16: 148 | R16: 208 | S16: 263 | T16: 233 | U16: 214 | V16: 0 | W16: 0 | X16: 0 | Y16: 0
A17: Other Non-Current Assets | B17: 104.134 | C17: 55.358 | D17: 53.523 | E17: 60.875 | F17: 122.733 | G17: 110.1 | H17: 112.456 | I17: 308.449 | J17: 300 | K17: 293 | L17: 264 | M17: 242 | N17: 263 | O17: 263 | P17: 254 | Q17: 265 | R17: 291 | S17: 7963 | T17: 6653 | U17: 8594 | V17: 8384 | W17: 14717 | X17: 36755 | Y17: 35809
A18: Total Assets | B18: =B8+SUM(B9:B17) | C18: =C8+SUM(C9:C17) | D18: =D8+SUM(D9:D17) | E18: =E8+SUM(E9:E17) | F18: =F8+SUM(F9:F17) | G18: =G8+SUM(G9:G17) | H18: =H8+SUM(H9:H17) | I18: =I8+SUM(I9:I17) | ... Y18: =Y8+SUM(Y9:Y17)
A19: Accounts Payable | B19: 17292.647 | C19: 19885.182 | D19: 20149.301 | E19: 18117.611 | F19: 25412.753 | G19: 37525.39 | H19: 52992.075 | I19: 91931.593 | J19: 91479 | K19: 109307 | L19: 102416 | M19: 143947 | N19: 107340 | O19: 107112 | P19: 94313 | Q19: 121088 | R19: 42840 | S19: 40196 | T19: 47423 | U19: 30938 | V19: 41287 | W19: 61052 | X19: 120962 | Y19: 97794
A20: Accrued Expenses | B20: 0 | C20: 0 | D20: 0 | E20: 0 | F20: 0 | G20: 0 | H20: 0 | I20: 0 | J20: 0 | K20: 0 | L20: 0 | M20: 0 | N20: 0 | O20: 0 | P20: 0 | Q20: 0 | R20: 62120 | S20: 63871 | T20: 79633 | U20: 73024 | V20: 148780 | W20: 152046 | X20: 225859 | Y20: 311768
A21: Income Taxes Payable | B21: 0 | C21: 0 | D21: 0 | E21: 0 | F21: 0 | G21: 0 | H21: 0 | I21: 0 | J21: 0 | K21: 0 | L21: 0 | M21: 0 | N21: 0 | O21: 0 | P21: 58798 | Q21: 58855 | R21: 50424 | S21: 58619 | T21: 5374 | U21: 739 | V21: 10834 | W21: 26206 | X21: 21765 | Y21: 49590
A22: Accrued Distributor Termination Fees | B22: 0 | C22: 0 | D22: 0 | E22: 0 | F22: 0 | G22: 0 | H22: 0 | I22: 0 | J22: 0 | K22: 0 | L22: 0 | M22: 115551 | N22: 3986 | O22: 1063 | P22: 0 | Q22: 0 | R22: 0 | S22: 0 | T22: 0 | U22: 0 | V22: 0 | W22: 0 | X22: 0 | Y22: 252953
A23: Accrued Promotional Allowance | B23: 0 | C23: 0 | D23: 0 | E23: 0 | F23: 0 | G23: 0 | H23: 0 | I23: 0 | J23: 0 | K23: 0 | L23: 0 | M23: 0 | N23: 35977 | O23: 68225 | P23: 98933 | Q23: 136557 | R23: 99787 | S23: 129201 | T23: 156479 | U23: 158810 | V23: 135948 | W23: 151327 | X23: 200169 | Y23: 234068
A24: Lease Liability - Operating - Current | B24: 649.074 | C24: 587.69 | D24: 411.946 | E24: 397.931 | F24: 321.283 | G24: 337.626 | H24: 318.142 | I24: 376.602 | J24: 512 | K24: 569 | L24: 556 | M24: 663 | N24: 661 | O24: 605 | P24: 505 | Q24: 628 | R24: 980 | S24: 821 | T24: 729 | U24: 1358 | V24: 3265 | W24: 3550 | X24: 0 | Y24: 0
A25: Bonds Payable, Net | B25: 8634.279 | C25: 8599.75 | D25: 8953.266 | E25: 9540.007 | F25: 0 | G25: 0 | H25: 0 | I25: 0 | J25: 0 | K25: 0 | L25: 0 | M25: 0 | N25: 0 | O25: 0 | P25: 0 | Q25: 0 | R25: 0 | S25: 0 | T25: 0 | U25: 0 | V25: 0 | W25: 0 | X25: 0 | Y25: 0
A26: Lease Liability - Finance - Current | B26: 0 | C26: 0 | D26: 0 | E26: 0 | F26: 205.824 | G26: 192.649 | H26: 191.753 | I26: 155.508 | J26: 157 | K26: 141 | L26: 101 | M26: 95 | N26: 70 | O26: 69 | P26: 67 | Q26: 63 | R26: 59 | S26: 61 | T26: 61 | U26: 99 | V26: 0 | W26: 0 | X26: 0 | Y26: 0
A27: Contingent Consideration - Current | B27: 0 | C27: 0 | D27: 0 | E27: 0 | F27: 0 | G27: 0 | H27: 0 | I27: 0 | J27: 0 | K27: 0 | L27: 0 | M27: 0 | N27: 0 | O27: 0 | P27: 0 | Q27: 0 | R27: 0 | S27: 0 | T27: 0 | U27: 0 | V27: 0 | W27: 0 | X27: 25000 | Y27: 25000
A28: Deferred Revenue - Current | B28: 0 | C28: 0 | D28: 0 | E28: 0 | F28: 0 | G28: 0 | H28: 0 | I28: 0 | J28: 0 | K28: 0 | L28: 0 | M28: 7770 | N28: 9675 | O28: 9563 | P28: 9500 | Q28: 9500 | R28: 9513 | S28: 9513 | T28: 9513 | U28: 9513 | V28: 9513 | W28: 9513 | X28: 16071 | Y28: 25557
A29: Other Current Liabilities | B29: 107.399 | C29: 160.646 | D29: 561.617 | E29: 716.678 | F29: 425.232 | G29: 586.954 | H29: 754.907 | I29: 957.627 | J29: 976 | K29: 1734 | L29: 2761 | M29: 3267 | N29: 3586 | O29: 5094 | P29: 7109 | Q29: 8826 | R29: 10890 | S29: 12987 | T29: 13772 | U29: 14979 | V29: 15908 | W29: 14160 | X29: 49949 | Y29: 32258
A30: Total Current Liabilities | B30: =SUM(B19:B29) | C30: =SUM(C19:C29) | D30: =SUM(D19:D29) | E30: =SUM(E19:E29) | F30: =SUM(F19:F29) | G30: =SUM(G19:G29) | H30: =SUM(H19:H29) | I30: =SUM(I19:I29) | ... Y30: =SUM(Y19:Y29)
A31: Lease Liability - Operating - Non-Current | B31: 239.848 | C31: 188.789 | D31: 203.101 | E31: 124.978 | F31: 514.948 | G31: 436.631 | H31: 391.157 | I31: 550.547 | J31: 658 | K31: 597 | L31: 420 | M31: 462 | N31: 326 | O31: 336 | P31: 249 | Q31: 512 | R31: 955 | S31: 850 | T31: 762 | U31: 4193 | V31: 16674 | W31: 16152 | X31: 0 | Y31: 0
A32: Lease Liability - Finance - Non-Current | B32: 0 | C32: 0 | D32: 0 | E32: 0 | F32: 82.29 | G32: 87.152 | H32: 60.731 | I32: 88.649 | J32: 45 | K32: 138 | L32: 138 | M32: 167 | N32: 162 | O32: 156 | P32: 147 | Q32: 135 | R32: 193 | S32: 245 | T32: 228 | U32: 189 | V32: 0 | W32: 0 | X32: 0 | Y32: 0
A33: Deferred Tax Liability | B33: 0 | C33: 0 | D33: 0 | E33: 0 | F33: 0 | G33: 0 | H33: 0 | I33: 3497.24 | J33: 3146 | K33: 3084 | L33: 2886 | M33: 25457 | N33: 15919 | O33: 19250 | P33: 2333 | Q33: 2249 | R33: 2880 | S33: 2248 | T33: 2201 | U33: 2275 | V33: 0 | W33: 0 | X33: 0 | Y33: 0
A34: Long-Term Debt | B34: 0 | C34: 0 | D34: 0 | E34: 0 | F34: 0 | G34: 0 | H34: 0 | I34: 0 | J34: 0 | K34: 0 | L34: 0 | M34: 0 | N34: 0 | O34: 0 | P34: 0 | Q34: 0 | R34: 0 | S34: 0 | T34: 0 | U34: 0 | V34: 0 | W34: 0 | X34: 862917 | Y34: 861472
A35: Deferred Revenue - Non-Current | B35: 0 | C35: 0 | D35: 0 | E35: 0 | F35: 0 | G35: 0 | H35: 0 | I35: 0 | J35: 0 | K35: 0 | L35: 0 | M35: 146333 | N35: 179788 | O35: 175275 | P35: 171745 | Q35: 169370 | R35: 167227 | S35: 164849 | T35: 162471 | U35: 160092 | V35: 157714 | W35: 155336 | X35: 156135 | Y35: 387432
A36: Other Non-Current Liabilities | B36: 0 | C36: 0 | D36: 0 | E36: 0 | F36: 0 | G36: 0 | H36: 0 | I36: 22.198 | J36: 0 | K36: 0 | L36: 487 | M36: 0 | N36: 0 | O36: 0 | P36: 0 | Q36: 0 | R36: 0 | S36: 0 | T36: 0 | U36: 0 | V36: 2541 | W36: 2574 | X36: 25002 | Y36: 24431
A37: Total Liabilities | B37: =B30+SUM(B31:B36) | C37: =C30+SUM(C31:C36) | D37: =D30+SUM(D31:D36) | E37: =E30+SUM(E31:E36) | F37: =F30+SUM(F31:F36) | G37: =G30+SUM(G31:G36) | H37: =H30+SUM(H31:H36) | I37: =I30+SUM(I31:I36) | ... Y37: =Y30+SUM(Y31:Y36)
A38: Convertible Preferred Stock | B38: 0 | C38: 0 | D38: 0 | E38: 0 | F38: 0 | G38: 0 | H38: 0 | I38: 0 | J38: 0 | K38: 0 | L38: 0 | M38: 824488 | N38: 824488 | O38: 824488 | P38: 824488 | Q38: 824488 | R38: 824488 | S38: 824488 | T38: 824488 | U38: 824488 | V38: 824488 | W38: 824488 | X38: 824488 | Y38: 1760275
A39: Common Stock | B39: 68.942 | C39: 69.28 | D39: 69.563 | E39: 71.652 | F39: 72.263 | G39: 72.586 | H39: 74.471 | I39: 74.746 | J39: 75 | K39: 75 | L39: 76 | M39: 76 | N39: 76 | O39: 77 | P39: 77 | Q39: 77 | R39: 77 | S39: 78 | T39: 78 | U39: 79 | V39: 79 | W39: 79 | X39: 101 | Y39: 101
A40: Treasury Stock | B40: 0 | C40: 0 | D40: 0 | E40: 0 | F40: 0 | G40: 0 | H40: 0 | I40: 0 | J40: 0 | K40: 0 | L40: 0 | M40: 0 | N40: 0 | O40: 0 | P40: 0 | Q40: 0 | R40: 0 | S40: 0 | T40: 0 | U40: 0 | V40: 0 | W40: 0 | X40: 0 | Y40: 0
...

Sheet YTD CF
B1: Q1 FY2020 | C1: Q2 FY2020 | D1: Q3 FY2020 | E1: Q1 FY2021 | F1: Q2 FY2021 | G1: Q3 FY2021 | H1: Q1 FY2022 | I1: Q2 FY2022 | J1: Q3 FY2022 | K1: Q1 FY2023 | L1: Q2 FY2023 | M1: Q3 FY2023 | N1: Q1 FY2024 | O1: Q2 FY2024 | P1: Q3 FY2024 | Q1: Q1 FY2025 | R1: Q2 FY2025 | S1: Q3 FY2025
A2: Net Income (Loss) | B2: 546.051 | C2: 2104.385 | D2: 6857.988 | E2: 585.424 | F2: 4545.768 | G2: 7291.559 | H2: 6679 | I2: 15838 | J2: -166059 | K2: 41227 | L2: 92736 | M2: 176685 | N2: 77811 | O2: 157594 | P2: 163950 | Q2: 44419 | R2: 144274 | S2: 83260
A3: Depreciation | B3: 124.939 | C3: 50.351 | D3: 82.18 | E3: 108.198 | F3: 178.425 | G3: 519.765 | H3: 245 | I3: 556 | J3: 952 | K3: 404 | L3: 953 | M3: 1676 | N3: 0 | O3: 0 | P3: 0 | Q3: 0 | R3: 0 | S3: 0
A4: Amortization | B4: 309.597 | C4: 851.045 | D4: 1224.684 | E4: 187.67 | F4: 375.141 | G4: 550.8 | H4: 141 | I4: 275 | J4: 402 | K4: 145 | L4: 294 | M4: 445 | N4: 0 | O4: 0 | P4: 0 | Q4: 0 | R4: 0 | S4: 0
A5: Impairment of Intangibles | B5: 0 | C5: 0 | D5: 0 | E5: 0 | F5: 0 | G5: 0 | H5: 0 | I5: 0 | J5: 2379 | K5: 0 | L5: 0 | M5: 0 | N5: 0 | O5: 0 | P5: 0 | Q5: 0 | R5: 0 | S5: 0
A6: Depreciation & Amortization | B6: 0 | C6: 0 | D6: 0 | E6: 0 | F6: 0 | G6: 0 | H6: 0 | I6: 0 | J6: 0 | K6: 0 | L6: 0 | M6: 0 | N6: 1229 | O6: 2648 | P6: 4888 | Q6: 2611 | R6: 11730 | S6: 20516
A7: Allowance for Credit Losses | B7: 221.222 | C7: 221.182 | D7: 244.685 | E7: 223.034 | F7: 854.606 | G7: -207.261 | H7: 455 | I7: 466 | J7: 705 | K7: 837 | L7: 1088 | M7: 1880 | N7: 2250 | O7: 4072 | P7: 4279 | Q7: 2077 | R7: 5529 | S7: 3226
A8: Amortization of Deferred Other Costs | B8: 0 | C8: 0 | D8: 0 | E8: 0 | F8: 0 | G8: 0 | H8: 0 | I8: 0 | J8: 2354 | K8: 3531 | L8: 7062 | M8: 10593 | N8: 3531 | O8: 7062 | P8: 10593 | Q8: 3531 | R8: 7062 | S8: 13391
A9: Inventory Write-Down | B9: -270.71 | C9: -137.37 | D9: 211.822 | E9: 753.935 | F9: 1260.076 | G9: 12.234 | H9: 2596 | I9: 331 | J9: 1078 | K9: 1672 | L9: -3888 | M9: 2677 | N9: 2386 | O9: 11554 | P9: 17118 | Q9: 5337 | R9: 15262 | S9: 22313
A10: Gain (Loss) on Disposal of PP&E | B10: 0 | C10: 0 | D10: 0 | E10: 0 | F10: 0 | G10: 0 | H10: 0 | I10: 0 | J10: 0 | K10: 0 | L10: 191 | M10: 195 | N10: -8 | O10: 31 | P10: 126 | Q10: 0 | R10: 0 | S10: 0
A11: Stock-Based Compensation | B11: 1400 | C11: 2574.999 | D11: 4718.699 | E11: 3575.001 | F11: 7597.26 | G11: 13400.581 | H11: 4310 | I11: 8517 | J11: 14780 | K11: 5507 | L11: 11242 | M11: 16221 | N11: 3563 | O11: 8309 | P11: 13685 | Q11: 5029 | R11: 11463 | S11: 18847
A12: Gain on China Transaction | B12: 144.403 | C12: 23.1 | D12: -384.493 | E12: 0 | F12: 0 | G12: 0 | H12: 0 | I12: 0 | J12: 0 | K12: 0 | L12: 0 | M12: 0 | N12: 0 | O12: 0 | P12: 0 | Q12: 0 | R12: 0 | S12: 0
A13: Gain (Loss) on Lease Cancellations | B13: 0 | C13: -152.112 | D13: -152.112 | E13: 0 | F13: 0 | G13: -14.669 | H13: 0 | I13: 0 | J13: 0 | K13: 0 | L13: 0 | M13: 0 | N13: 0 | O13: 0 | P13: 0 | Q13: 0 | R13: 0 | S13: 0
... A33: Net Change in Other Working Capital | B33: 0 | C33: 0 | D33: 0 | E33: 0 | F33: 0 | G33: 532.395 | H33: 0 | I33: 488 | J33: 0 | K33: 0 | L33: 0 | M33: 0 | N33: 0 | O33: 0 | P33: 0 | Q33: 148 | R33: -1210 | S33: -1786
A34: Cash Flow from Operations | B34: =SUM(B2:B33) | C34: =SUM(C2:C33) | D34: =SUM(D2:D33) | E34: =SUM(E2:E33) | F34: =SUM(F2:F33) | G34: =SUM(G2:G33) | H34: =SUM(H2:H33) | I34: =SUM(I2:I33) | ... S34: =SUM(S2:S33)
A35: Collections from Note Receivable | B35: 0 | C35: 1331.011 | D35: 1331.011 | E35: 1876.273 | F35: 1876.273 | G35: 1885.724 | H35: 0 | I35: 2592 | J35: 2592 | K35: 3233 | L35: 3233 | M35: 3233 | N35: 0 | O35: 0 | P35: 0 | Q35: 0 | R35: 0 | S35: 0
A36: Purchase of PP&E | B36: -107.372 | C36: -315.777 | D36: -416.671 | E36: -697.843 | F36: -1216.05 | G36: -2395.302 | H36: -742 | I36: -2456 | J36: -3477 | K36: -2253 | L36: -6810 | M36: -12687 | N36: -4525 | O36: -13739 | P36: -17983 | Q36: -6944 | R36: -15194 | S36: -25539
A37: Purchase of Non-Marketable Equity Securities | B37: 0 | C37: 0 | D37: 0 | E37: 0 | F37: 0 | G37: 0 | H37: 0 | I37: 0 | J37: 0 | K37: 0 | L37: 0 | M37: 0 | N37: 0 | O37: 0 | P37: -3000 | Q37: 0 | R37: -5000 | S37: -5000
A38: Acquisition of Big Beverages | B38: 0 | C38: 0 | D38: 0 | E38: 0 | F38: 0 | G38: 0 | H38: 0 | I38: 0 | J38: 0 | K38: 0 | L38: 0 | M38: 0 | N38: 0 | O38: 0 | P38: 0 | Q38: 0 | R38: 0 | S38: 0
A39: Acquisitions, Net of Cash Acquired | B39: 0 | C39: 0 | D39: 0 | E39: 0 | F39: 0 | G39: 0 | H39: 0 | I39: 0 | J39: 0 | K39: 0 | L39: 0 | M39: 0 | N39: 0 | O39: 0 | P39: 0 | Q39: 0 | R39: -1256351 | S39: -1278769
A40: Working Capital Estimate from Pepsi (Rockstar) | B40: 0 | C40: 0 | D40: 0 | E40: 0 | F40: 0 | G40: 0 | H40: 0 | I40: 0 | J40: 0 | K40: 0 | L40: 0 | M40: 0 | N40: 0 | O40: 0 | P40: 0 | Q40: 0 | R40: 0 | S40: 30617
A41: Cash Flow from Investing | B41: =SUM(B35:B40) | C41: =SUM(C35:C40) | D41: =SUM(D35:D40) | E41: =SUM(E35:E40) | F41: =SUM(F35:F40) | G41: =SUM(G35:G40) | H41: =SUM(H35:H40) | I41: =SUM(I35:I40) | ... S41: =SUM(S35:S40)
A42: Proceeds from Related-Party Notes | B42: 0 | C42: 0 | D42: 0 | E42: 0 | F42: 0 | G42: 0 | H42: 0 | I42: 0 | J42: 0 | K42: 0 | L42: 0 | M42: 0 | N42: 0 | O42: 0 | P42: 0 | Q42: 0 | R42: 0 | S42: 0
A43: Payments on Bonds Payable | B43: 0 | C43: 0 | D43: 0 | E43: 0 | F43: 0 | G43: 0 | H43: 0 | I43: 0 | J43: 0 | K43: 0 | L43: 0 | M43: 0 | N43: 0 | O43: 0 | P43: 0 | Q43: 0 | R43: 0 | S43: 0
A44: Finance Lease Payments | B44: -64.082 | C44: -222.052 | D44: -259.231 | E44: -25.149 | F44: -49.592 | G44: -72.386 | H44: -20 | I44: -37 | J44: -49 | K44: -11 | L44: -22 | M44: -33 | N44: -15 | O44: -30 | P44: -46 | Q44: 0 | R44: 0 | S44: 0
A45: Proceeds from Issuance of Common Stock | B45: 0 | C45: 0 | D45: 21983.116 | E45: 0 | F45: 67769.386 | G45: 67769.386 | H45: 0 | I45: 0 | J45: 0 | K45: 0 | L45: 0 | M45: 0 | N45: 0 | O45: 0 | P45: 0 | Q45: 0 | R45: 0 | S45: 0
A46: Proceeds from Exercise of Stock Options | B46: 215.347 | C46: 704.664 | D46: 2296.343 | E46: 715.91 | F46: 2515.017 | G46: 3242.073 | H46: 810 | I46: 1260 | J46: 3104 | K46: 478 | L46: 707 | M46: 1603 | N46: 967 | O46: 1147 | P46: 3832 | Q46: 0 | R46: 0 | S46: 0
A47: Cash Paid for RSU Tax Withholding | B47: 0 | C47: 0 | D47: 0 | E47: 0 | F47: 0 | G47: 0 | H47: 0 | I47: 0 | J47: 0 | K47: 0 | L47: 0 | M47: 0 | N47: 0 | O47: 0 | P47: 0 | Q47: 0 | R47: 0 | S47: 0
A48: Section 16(b) Short-Swing Profit Recovery | B48: 0 | C48: 0 | D48: 0 | E48: 0 | F48: 0 | G48: 0 | H48: 0 | I48: 0 | J48: 0 | K48: 0 | L48: 0 | M48: 0 | N48: 0 | O48: 0 | P48: 0 | Q48: 0 | R48: 0 | S48: 0
A49: Proceeds from Issuance of Preferred Stock | B49: 0 | C49: 0 | D49: 0 | E49: 0 | F49: 0 | G49: 0 | H49: 0 | I49: 0 | J49: 542018 | K49: 0 | L49: 0 | M49: 0 | N49: 0 | O49: 0 | P49: 0 | Q49: 0 | R49: 0 | S49: 0
A50: Preferred Dividends | B50: 0 | C50: 0 | D50: 0 | E50: 0 | F50: 0 | G50: 0 | H50: 0 | I50: 0 | J50: -4596 | K50: -6781 | L50: -13637 | M50: -20512 | N50: -6837 | O50: -13675 | P50: -20588 | Q50: -6781 | R50: -13632 | S50: -23301
A51: Share Repurchases | B51: 0 | C51: 0 | D51: 0 | E51: 0 | F51: 0 | G51: 0 | H51: 0 | I51: 0 | J51: 0 | K51: 0 | L51: 0 | M51: 0 | N51: 0 | O51: 0 | P51: -1658 | Q51: -1932 | R51: -2811 | S51: -3259
A52: Proceeds from Issuance of Long-Term Debt | B52: 0 | C52: 0 | D52: 0 | E52: 0 | F52: 0 | G52: 0 | H52: 0 | I52: 0 | J52: 0 | K52: 0 | L52: 0 | M52: 0 | N52: 0 | O52: 0 | P52: 0 | Q52: 0 | R52: 900000 | S52: 900000
A53: Repayments of Long-Term Debt | B53: 0 | C53: 0 | D53: 0 | E53: 0 | F53: 0 | G53: 0 | H53: 0 | I53: 0 | J53: 0 | K53: 0 | L53: 0 | M53: 0 | N53: 0 | O53: 0 | P53: 0 | Q53: 0 | R53: 0 | S53: -2250
... A55: Other Financing Activities | B55: 0 | C55: 0 | D55: 0 | E55: 0 | F55: 0 | G55: 0 | H55: 0 | I55: 0 | J55: 0 | K55: 0 | L55: 0 | M55: 0 | N55: 0 | O55: 0 | P55: 0 | Q55: 321 | R55: 319 | S55: 301
A56: Cash Flow from Financing | B56: =SUM(B42:B55) | C56: =SUM(C42:C55) | D56: =SUM(D42:D55) | E56: =SUM(E42:E55) | F56: =SUM(F42:F55) | G56: =SUM(G42:G55) | H56: =SUM(H42:H55) | I56: =SUM(I42:I55) | ... S56: =SUM(S42:S55)
