Workbook

Sheet ASSUMPTIONS
A1: Assumption | B1: Value | C1: Note
A2: Days in Quarter | B2: 91 | C2: Used by DSO/DIO/DPO ratios. Approximation; varies 89-92 by quarter.

Sheet ANNL P&L
B1: FY2021 | C1: FY2022 | D1: FY2023 | E1: FY2024 | F1: FY2025 | G1: FY2026E | H1: FY2027E | I1: FY2028E | J1: FY2029E | K1: FY2030E | L1: FY2031E
A2: Net Sales / Revenue | B2: 314272 | C2: 653604 | D2: 1318014 | E2: 1355630 | F2: 2515269 | G2: ='QTR P&L'!W2+'QTR P&L'!X2+'QTR P&L'!Y2+'QTR P&L'!Z2 -> 2852064.4 | H2: ='QTR P&L'!AA2+'QTR P&L'!AB2+'QTR P&L'!AC2+'QTR P&L'!AD2 -> 2797736.7 | I2: ='QTR P&L'!AE2+'QTR P&L'!AF2+'QTR P&L'!AG2+'QTR P&L'!AH2 -> 2744443.9 | J2: ='QTR P&L'!AI2+'QTR P&L'!AJ2+'QTR P&L'!AK2+'QTR P&L'!AL2 -> 2692166.2 | K2: ='QTR P&L'!AM2+'QTR P&L'!AN2+'QTR P&L'!AO2+'QTR P&L'!AP2 -> 2640884.3
A3: COGS | B3: -186103 | C3: -382735 | D3: -684875 | E3: -675423 | F3: -1247936 | G3: ='QTR P&L'!W3+'QTR P&L'!X3+'QTR P&L'!Y3+'QTR P&L'!Z3 -> -1501062 | H3: ='QTR P&L'!AA3+'QTR P&L'!AB3+'QTR P&L'!AC3+'QTR P&L'!AD3 -> -1472468.9 | I3: ='QTR P&L'!AE3+'QTR P&L'!AF3+'QTR P&L'!AG3+'QTR P&L'!AH3 -> -1444420.5 | J3: ='QTR P&L'!AI3+'QTR P&L'!AJ3+'QTR P&L'!AK3+'QTR P&L'!AL3 -> -1416906.4 | K3: ='QTR P&L'!AM3+'QTR P&L'!AN3+'QTR P&L'!AO3+'QTR P&L'!AP3 -> -1389916.4
A4: Gross Profit (Loss) | B4: =B2+B3 -> 128169 | C4: =C2+C3 -> 270869 | D4: =D2+D3 -> 633139 | E4: =E2+E3 -> 680207 | F4: =F2+F3 -> 1267333 | G4: =G2+G3 -> 1351002.4 | H4: =H2+H3 -> 1325267.8 | I4: =I2+I3 -> 1300023.3 | ... L4: =L2+L3 -> 0
A5: SG&A | B5: -132259 | C5: -428670 | D5: -366773 | E5: -524479 | F5: -798810 | G5: ='QTR P&L'!W8+'QTR P&L'!X8+'QTR P&L'!Y8+'QTR P&L'!Z8 -> -928825.54 | H5: ='QTR P&L'!AA8+'QTR P&L'!AB8+'QTR P&L'!AC8+'QTR P&L'!AD8 -> -911132.75 | I5: ='QTR P&L'!AE8+'QTR P&L'!AF8+'QTR P&L'!AG8+'QTR P&L'!AH8 -> -893776.99 | J5: ='QTR P&L'!AI8+'QTR P&L'!AJ8+'QTR P&L'!AK8+'QTR P&L'!AL8 -> -876751.82 | K5: ='QTR P&L'!AM8+'QTR P&L'!AN8+'QTR P&L'!AO8+'QTR P&L'!AP8 -> -860050.96
A6: Distributor Termination Fees | B6: 0 | C6: 0 | D6: 0 | E6: 0 | F6: -327461 | G6: ='QTR P&L'!W9+'QTR P&L'!X9+'QTR P&L'!Y9+'QTR P&L'!Z9 -> 0 | H6: ='QTR P&L'!AA9+'QTR P&L'!AB9+'QTR P&L'!AC9+'QTR P&L'!AD9 -> 0 | I6: ='QTR P&L'!AE9+'QTR P&L'!AF9+'QTR P&L'!AG9+'QTR P&L'!AH9 -> 0 | J6: ='QTR P&L'!AI9+'QTR P&L'!AJ9+'QTR P&L'!AK9+'QTR P&L'!AL9 -> 0 | K6: ='QTR P&L'!AM9+'QTR P&L'!AN9+'QTR P&L'!AO9+'QTR P&L'!AP9 -> 0
A7: Income (Loss) from Operations | B7: =B4+SUM(B5:B6) -> -4090 | C7: =C4+SUM(C5:C6) -> -157801 | D7: =D4+SUM(D5:D6) -> 266366 | E7: =E4+SUM(E5:E6) -> 155728 | F7: =F4+SUM(F5:F6) -> 141062 | G7: =G4+SUM(G5:G6) -> 422176.9 | H7: =H4+SUM(H5:H6) -> 414135.04 | I7: =I4+SUM(I5:I6) -> 406246.36 | ... L7: =L4+SUM(L5:L6) -> 0
A8: Interest Income (Expense) | B8: 307 | C8: 5529 | D8: 26629 | E8: 39263 | F8: -27892 | G8: ='QTR P&L'!W11+'QTR P&L'!X11+'QTR P&L'!Y11+'QTR P&L'!Z11 -> -33200 | H8: ='QTR P&L'!AA11+'QTR P&L'!AB11+'QTR P&L'!AC11+'QTR P&L'!AD11 -> -33200 | I8: ='QTR P&L'!AE11+'QTR P&L'!AF11+'QTR P&L'!AG11+'QTR P&L'!AH11 -> -33200 | J8: ='QTR P&L'!AI11+'QTR P&L'!AJ11+'QTR P&L'!AK11+'QTR P&L'!AL11 -> -33200 | K8: ='QTR P&L'!AM11+'QTR P&L'!AN11+'QTR P&L'!AO11+'QTR P&L'!AP11 -> -33200
A9: Foreign Currency Gain (Loss) | B9: -276 | C9: -392 | D9: -1246 | E9: -1734 | F9: 0 | G9: ='QTR P&L'!W12+'QTR P&L'!X12+'QTR P&L'!Y12+'QTR P&L'!Z12 -> 0 | H9: ='QTR P&L'!AA12+'QTR P&L'!AB12+'QTR P&L'!AC12+'QTR P&L'!AD12 -> 0 | I9: ='QTR P&L'!AE12+'QTR P&L'!AF12+'QTR P&L'!AG12+'QTR P&L'!AH12 -> 0 | J9: ='QTR P&L'!AI12+'QTR P&L'!AJ12+'QTR P&L'!AK12+'QTR P&L'!AL12 -> 0 | K9: ='QTR P&L'!AM12+'QTR P&L'!AN12+'QTR P&L'!AO12+'QTR P&L'!AP12 -> 0
A10: Other Income (Expense) | B10: 0 | C10: 0 | D10: 0 | E10: 1793 | F10: 11863 | G10: ='QTR P&L'!W13+'QTR P&L'!X13+'QTR P&L'!Y13+'QTR P&L'!Z13 -> 19364 | H10: ='QTR P&L'!AA13+'QTR P&L'!AB13+'QTR P&L'!AC13+'QTR P&L'!AD13 -> 19364 | I10: ='QTR P&L'!AE13+'QTR P&L'!AF13+'QTR P&L'!AG13+'QTR P&L'!AH13 -> 19364 | J10: ='QTR P&L'!AI13+'QTR P&L'!AJ13+'QTR P&L'!AK13+'QTR P&L'!AL13 -> 19364 | K10: ='QTR P&L'!AM13+'QTR P&L'!AN13+'QTR P&L'!AO13+'QTR P&L'!AP13 -> 19364
A11: Pre-Tax Income (Loss) | B11: =B7+SUM(B8:B10) -> -4059 | C11: =C7+SUM(C8:C10) -> -152664 | D11: =D7+SUM(D8:D10) -> 291749 | E11: =E7+SUM(E8:E10) -> 195050 | F11: =F7+SUM(F8:F10) -> 125033 | G11: =G7+SUM(G8:G10) -> 408340.9 | H11: =H7+SUM(H8:H10) -> 400299.04 | I11: =I7+SUM(I8:I10) -> 392410.36 | ... L11: =L7+SUM(L8:L10) -> 0
A12: Income Tax (Expense) Benefit | B12: 7996 | C12: -34618 | D12: -64948 | E12: -49976 | F12: -17034 | G12: ='QTR P&L'!W16+'QTR P&L'!X16+'QTR P&L'!Y16+'QTR P&L'!Z16 -> 38529.202 | H12: ='QTR P&L'!AA16+'QTR P&L'!AB16+'QTR P&L'!AC16+'QTR P&L'!AD16 -> 37770.408 | I12: ='QTR P&L'!AE16+'QTR P&L'!AF16+'QTR P&L'!AG16+'QTR P&L'!AH16 -> 37026.068 | J12: ='QTR P&L'!AI16+'QTR P&L'!AJ16+'QTR P&L'!AK16+'QTR P&L'!AL16 -> 36295.907 | K12: ='QTR P&L'!AM16+'QTR P&L'!AN16+'QTR P&L'!AO16+'QTR P&L'!AP16 -> 35579.654
A13: Net Income (Loss) | B13: =B11+B12 -> 3937 | C13: =C11+C12 -> -187282 | D13: =D11+D12 -> 226801 | E13: =E11+E12 -> 145074 | F13: =F11+F12 -> 107999 | G13: =G11+G12 -> 446870.1 | H13: =H11+H12 -> 438069.45 | I13: =I11+I12 -> 429436.43 | ... L13: =L11+L12 -> 0
A14: Preferred Dividends | B14: 0 | C14: -11526 | D14: -27462 | E14: -27500 | F14: -37608 | G14: ='QTR P&L'!W18+'QTR P&L'!X18+'QTR P&L'!Y18+'QTR P&L'!Z18 -> -57228 | H14: ='QTR P&L'!AA18+'QTR P&L'!AB18+'QTR P&L'!AC18+'QTR P&L'!AD18 -> -57228 | I14: ='QTR P&L'!AE18+'QTR P&L'!AF18+'QTR P&L'!AG18+'QTR P&L'!AH18 -> -57228 | J14: ='QTR P&L'!AI18+'QTR P&L'!AJ18+'QTR P&L'!AK18+'QTR P&L'!AL18 -> -57228 | K14: ='QTR P&L'!AM18+'QTR P&L'!AN18+'QTR P&L'!AO18+'QTR P&L'!AP18 -> -57228
A15: Income Allocated to Participating Preferred | B15: 0 | C15: 0 | D15: -17348 | E15: -10117 | F15: -6554 | G15: ='QTR P&L'!W19+'QTR P&L'!X19+'QTR P&L'!Y19+'QTR P&L'!Z19 -> -5128 | H15: ='QTR P&L'!AA19+'QTR P&L'!AB19+'QTR P&L'!AC19+'QTR P&L'!AD19 -> -5128 | I15: ='QTR P&L'!AE19+'QTR P&L'!AF19+'QTR P&L'!AG19+'QTR P&L'!AH19 -> -5128 | J15: ='QTR P&L'!AI19+'QTR P&L'!AJ19+'QTR P&L'!AK19+'QTR P&L'!AL19 -> -5128 | K15: ='QTR P&L'!AM19+'QTR P&L'!AN19+'QTR P&L'!AO19+'QTR P&L'!AP19 -> -5128
A16: Net Income (Loss) Attributable to Common Shareholders | B16: =B13+B14+B15 -> 3937 | C16: =C13+C14+C15 -> -198808 | D16: =D13+D14+D15 -> 181991 | E16: =E13+E14+E15 -> 107457 | F16: =F13+F14+F15 -> 63837 | G16: =G13+G14+G15 -> 384514.1 | H16: =H13+H14+H15 -> 375713.45 | I16: =I13+I14+I15 -> 367080.43 | ... L16: =L13+L14+L15 -> 0

Sheet BALANCE SHEET
B1: FY2022 | C1: FY2023 | D1: FY2024 | E1: FY2025 | F1: FY2026E | G1: FY2027E | H1: FY2028E | I1: FY2029E | J1: FY2030E | K1: FY2031E
A2: Cash, Cash Equivalents & Restricted Cash | B2: 652927 | C2: 755981 | D2: 890190 | E2: 539987 | F2: ='QTR BS'!W2 -> 539987 | G2: ='QTR BS'!AA2 -> 539987 | H2: ='QTR BS'!AE2 -> 539987 | I2: ='QTR BS'!AI2 -> 539987 | J2: ='QTR BS'!AM2 -> 539987
A3: Accounts Receivable | B3: 63311 | C3: 183703 | D3: 270342 | E3: 755499 | F3: ='QTR BS'!W3 -> 741107.83 | G3: ='QTR BS'!AA3 -> 726990.79 | H3: ='QTR BS'!AE3 -> 713142.67 | I3: ='QTR BS'!AI3 -> 699558.32 | J3: ='QTR BS'!AM3 -> 686232.75
A4: Note Receivable - Current | B4: 2979 | C4: 2318 | D4: 0 | E4: 0 | F4: ='QTR BS'!W4 -> 0 | G4: ='QTR BS'!AA4 -> 0 | H4: ='QTR BS'!AE4 -> 0 | I4: ='QTR BS'!AI4 -> 0 | J4: ='QTR BS'!AM4 -> 0
A5: Inventories | B5: 173289 | C5: 229275 | D5: 131165 | E5: 337698 | F5: ='QTR BS'!W5 -> 331265.34 | G5: ='QTR BS'!AA5 -> 324955.21 | H5: ='QTR BS'!AE5 -> 318765.28 | I5: ='QTR BS'!AI5 -> 312693.26 | J5: ='QTR BS'!AM5 -> 306736.91
A6: Prepaid Expenses | B6: 11341 | C6: 19503 | D6: 18759 | E6: 128806 | F6: ='QTR BS'!W6 -> 126352.43 | G6: ='QTR BS'!AA6 -> 123945.6 | H6: ='QTR BS'!AE6 -> 121584.61 | I6: ='QTR BS'!AI6 -> 119268.6 | J6: ='QTR BS'!AM6 -> 116996.71
A7: Deferred Other Costs - Current | B7: 14124 | C7: 14124 | D7: 14124 | E7: 49164 | F7: ='QTR BS'!W7 -> 48227.497 | G7: ='QTR BS'!AA7 -> 47308.832 | H7: ='QTR BS'!AE7 -> 46407.667 | I7: ='QTR BS'!AI7 -> 45523.668 | J7: ='QTR BS'!AM7 -> 44656.507
A8: Total Current Assets | B8: =SUM(B2:B7) -> 917971 | C8: =SUM(C2:C7) -> 1204904 | D8: =SUM(D2:D7) -> 1324580 | E8: =SUM(E2:E7) -> 1811154 | F8: =SUM(F2:F7) -> 1786940.1 | G8: =SUM(G2:G7) -> 1763187.4 | H8: =SUM(H2:H7) -> 1739887.2 | I8: =SUM(I2:I7) -> 1717030.9 | ... K8: =SUM(K2:K7) -> 0
A9: Note Receivable - Non-Current | B9: 3574 | C9: 0 | D9: 0 | E9: 0 | F9: ='QTR BS'!W9 -> 0 | G9: ='QTR BS'!AA9 -> 0 | H9: ='QTR BS'!AE9 -> 0 | I9: ='QTR BS'!AI9 -> 0 | J9: ='QTR BS'!AM9 -> 0
A10: Net PP&E | B10: 10185 | C10: 24868 | D10: 55602 | E10: 87910 | F10: ='QTR BS'!W10 -> 94205.957 | G10: ='QTR BS'!AA10 -> 100381.98 | H10: ='QTR BS'!AE10 -> 106440.37 | I10: ='QTR BS'!AI10 -> 112383.35 | J10: ='QTR BS'!AM10 -> 118213.12
A11: ROU Assets - Operating - Non-Current | B11: 972 | C11: 1957 | D11: 21606 | E11: 0 | F11: ='QTR BS'!W11 -> 0 | G11: ='QTR BS'!AA11 -> 0 | H11: ='QTR BS'!AE11 -> 0 | I11: ='QTR BS'!AI11 -> 0 | J11: ='QTR BS'!AM11 -> 0
A12: ROU Assets - Finance - Non-Current | B12: 208 | C12: 208 | D12: 230 | E12: 0 | F12: ='QTR BS'!W16 -> 0 | G12: ='QTR BS'!AA16 -> 0 | H12: ='QTR BS'!AE16 -> 0 | I12: ='QTR BS'!AI16 -> 0 | J12: ='QTR BS'!AM16 -> 0
A13: Intangible Assets | B13: 12254 | C13: 12139 | D13: 12213 | E13: 1391915 | F13: ='QTR BS'!W12 -> 1391915 | G13: ='QTR BS'!AA12 -> 1391915 | H13: ='QTR BS'!AE12 -> 1391915 | I13: ='QTR BS'!AI12 -> 1391915 | J13: ='QTR BS'!AM12 -> 1391915
A14: Goodwill | B14: 13679 | C14: 14173 | D14: 71582 | E14: 917560 | F14: ='QTR BS'!W13 -> 917560 | G14: ='QTR BS'!AA13 -> 917560 | H14: ='QTR BS'!AE13 -> 917560 | I14: ='QTR BS'!AI13 -> 917560 | J14: ='QTR BS'!AM13 -> 917560
A15: Deferred Other Costs - Non-Current | B15: 262462 | C15: 248338 | D15: 234215 | E15: 771635 | F15: ='QTR BS'!W14 -> 756936.46 | G15: ='QTR BS'!AA14 -> 742517.91 | H15: ='QTR BS'!AE14 -> 728374.02 | I15: ='QTR BS'!AI14 -> 714499.54 | J15: ='QTR BS'!AM14 -> 700889.35
A16: Deferred Tax Assets | B16: 501 | C16: 29518 | D16: 38699 | E16: 96013 | F16: ='QTR BS'!W15 -> 39725 | G16: ='QTR BS'!AA15 -> -16563 | H16: ='QTR BS'!AE15 -> -72851 | I16: ='QTR BS'!AI15 -> -129139 | J16: ='QTR BS'!AM15 -> -185427
A17: Other Non-Current Assets | B17: 263 | C17: 291 | D17: 8154 | E17: 43434 | F17: ='QTR BS'!W17 -> 42606.645 | G17: ='QTR BS'!AA17 -> 41795.05 | H17: ='QTR BS'!AE17 -> 40998.914 | I17: ='QTR BS'!AI17 -> 40217.944 | J17: ='QTR BS'!AM17 -> 39451.85
A18: Total Assets | B18: =B8+SUM(B9:B17) -> 1222069 | C18: =C8+SUM(C9:C17) -> 1536396 | D18: =D8+SUM(D9:D17) -> 1766881 | E18: =E8+SUM(E9:E17) -> 5119621 | F18: =F8+SUM(F9:F17) -> 5029889.2 | G18: =G8+SUM(G9:G17) -> 4940794.4 | H18: =H8+SUM(H9:H17) -> 4852324.5 | I18: =I8+SUM(I9:I17) -> 4764467.7 | ... K18: =K8+SUM(K9:K17) -> 0
A19: Accounts Payable | B19: 36248 | C19: 42840 | D19: 41287 | E19: 137930 | F19: ='QTR BS'!W19 -> 135302.63 | G19: ='QTR BS'!AA19 -> 132725.31 | H19: ='QTR BS'!AE19 -> 130197.09 | I19: ='QTR BS'!AI19 -> 127717.02 | J19: ='QTR BS'!AM19 -> 125284.19
A20: Accrued Expenses | B20: 69899 | C20: 62120 | D20: 148780 | E20: 230721 | F20: ='QTR BS'!W20 -> 226326.1 | G20: ='QTR BS'!AA20 -> 222014.91 | H20: ='QTR BS'!AE20 -> 217785.85 | I20: ='QTR BS'!AI20 -> 213637.34 | J20: ='QTR BS'!AM20 -> 209567.86
A21: Income Taxes Payable | B21: 1193 | C21: 50424 | D21: 10834 | E21: 49612 | F21: ='QTR BS'!W21 -> 48666.963 | G21: ='QTR BS'!AA21 -> 47739.927 | H21: ='QTR BS'!AE21 -> 46830.55 | I21: ='QTR BS'!AI21 -> 45938.496 | J21: ='QTR BS'!AM21 -> 45063.434
A22: Accrued Distributor Termination Fees | B22: 3986 | C22: 0 | D22: 0 | E22: 264088 | F22: ='QTR BS'!W22 -> 0 | G22: ='QTR BS'!AA22 -> 0 | H22: ='QTR BS'!AE22 -> 0 | I22: ='QTR BS'!AI22 -> 0 | J22: ='QTR BS'!AM22 -> 0
A23: Accrued Promotional Allowance | B23: 35977 | C23: 99787 | D23: 135948 | E23: 307922 | F23: ='QTR BS'!W23 -> 302056.53 | G23: ='QTR BS'!AA23 -> 296302.79 | H23: ='QTR BS'!AE23 -> 290658.65 | I23: ='QTR BS'!AI23 -> 285122.02 | J23: ='QTR BS'!AM23 -> 279690.85
A24: Lease Liability - Operating - Current | B24: 661 | C24: 980 | D24: 3265 | E24: 0 | F24: ='QTR BS'!W24 -> 0 | G24: ='QTR BS'!AA24 -> 0 | H24: ='QTR BS'!AE24 -> 0 | I24: ='QTR BS'!AI24 -> 0 | J24: ='QTR BS'!AM24 -> 0
A25: Lease Liability - Finance - Current | B25: 70 | C25: 59 | D25: 100 | E25: 0 | F25: ='QTR BS'!W25 -> 0 | G25: ='QTR BS'!AA25 -> 0 | H25: ='QTR BS'!AE25 -> 0 | I25: ='QTR BS'!AI25 -> 0 | J25: ='QTR BS'!AM25 -> 0
A26: Contingent Consideration - Current | B26: 0 | C26: 0 | D26: 0 | E26: 25000 | F26: ='QTR BS'!W26 -> 24523.786 | G26: ='QTR BS'!AA26 -> 24056.643 | H26: ='QTR BS'!AE26 -> 23598.399 | I26: ='QTR BS'!AI26 -> 23148.883 | J26: ='QTR BS'!AM26 -> 22707.93
A27: Deferred Revenue - Current | B27: 9675 | C27: 9513 | D27: 9513 | E27: 26988 | F27: ='QTR BS'!W27 -> 26473.917 | G27: ='QTR BS'!AA27 -> 25969.627 | H27: ='QTR BS'!AE27 -> 25474.943 | I27: ='QTR BS'!AI27 -> 24989.682 | J27: ='QTR BS'!AM27 -> 24513.665
A28: Other Current Liabilities | B28: 3586 | C28: 10890 | D28: 15808 | E28: 36465 | F28: ='QTR BS'!W28 -> 35770.394 | G28: ='QTR BS'!AA28 -> 35089.02 | H28: ='QTR BS'!AE28 -> 34420.624 | I28: ='QTR BS'!AI28 -> 33764.961 | J28: ='QTR BS'!AM28 -> 33121.787
A29: Total Current Liabilities | B29: =SUM(B19:B28) -> 161295 | C29: =SUM(C19:C28) -> 276613 | D29: =SUM(D19:D28) -> 365535 | E29: =SUM(E19:E28) -> 1078726 | F29: =SUM(F19:F28) -> 799120.32 | G29: =SUM(G19:G28) -> 783898.23 | H29: =SUM(H19:H28) -> 768966.09 | I29: =SUM(I19:I28) -> 754318.4 | ... K29: =SUM(K19:K28) -> 0
A30: Lease Liability - Operating - Non-Current | B30: 326 | C30: 955 | D30: 16674 | E30: 0 | F30: ='QTR BS'!W30 -> 0 | G30: ='QTR BS'!AA30 -> 0 | H30: ='QTR BS'!AE30 -> 0 | I30: ='QTR BS'!AI30 -> 0 | J30: ='QTR BS'!AM30 -> 0
A31: Lease Liability - Finance - Non-Current | B31: 162 | C31: 193 | D31: 211 | E31: 0 | F31: ='QTR BS'!W31 -> 0 | G31: ='QTR BS'!AA31 -> 0 | H31: ='QTR BS'!AE31 -> 0 | I31: ='QTR BS'!AI31 -> 0 | J31: ='QTR BS'!AM31 -> 0
A32: Deferred Tax Liability | B32: 15919 | C32: 2880 | D32: 2330 | E32: 0 | F32: ='QTR BS'!W32 -> 0 | G32: ='QTR BS'!AA32 -> 0 | H32: ='QTR BS'!AE32 -> 0 | I32: ='QTR BS'!AI32 -> 0 | J32: ='QTR BS'!AM32 -> 0
A33: Long-Term Debt | B33: 0 | C33: 0 | D33: 0 | E33: 669926 | F33: ='QTR BS'!W33 -> 669926 | G33: ='QTR BS'!AA33 -> 669926 | H33: ='QTR BS'!AE33 -> 669926 | I33: ='QTR BS'!AI33 -> 669926 | J33: ='QTR BS'!AM33 -> 669926
A34: Deferred Revenue - Non-Current | B34: 179788 | C34: 167227 | D34: 157714 | E34: 401155 | F34: ='QTR BS'!W34 -> 393513.57 | G34: ='QTR BS'!AA34 -> 386017.71 | H34: ='QTR BS'!AE34 -> 378664.63 | I34: ='QTR BS'!AI34 -> 371451.61 | J34: ='QTR BS'!AM34 -> 364375.99
A35: Other Non-Current Liabilities | B35: 0 | C35: 0 | D35: 0 | E35: 28372 | F35: ='QTR BS'!W35 -> 27831.554 | G35: ='QTR BS'!AA35 -> 27301.403 | H35: ='QTR BS'!AE35 -> 26781.351 | I35: ='QTR BS'!AI35 -> 26271.205 | J35: ='QTR BS'!AM35 -> 25770.776
A36: Total Liabilities | B36: =B29+SUM(B30:B35) -> 357490 | C36: =C29+SUM(C30:C35) -> 447868 | D36: =D29+SUM(D30:D35) -> 542464 | E36: =E29+SUM(E30:E35) -> 2178179 | F36: =F29+SUM(F30:F35) -> 1890391.4 | G36: =G29+SUM(G30:G35) -> 1867143.3 | H36: =H29+SUM(H30:H35) -> 1844338.1 | I36: =I29+SUM(I30:I35) -> 1821967.2 | ... K36: =K29+SUM(K30:K35) -> 0
A37: Convertible Preferred Stock | B37: 824488 | C37: 824488 | D37: 824488 | E37: 1759975 | F37: ='QTR BS'!W37 -> 1759975 | G37: ='QTR BS'!AA37 -> 1759975 | H37: ='QTR BS'!AE37 -> 1759975 | I37: ='QTR BS'!AI37 -> 1759975 | J37: ='QTR BS'!AM37 -> 1759975
A38: Common Stock | B38: 76 | C38: 77 | D38: 79 | E38: 101 | F38: ='QTR BS'!W38 -> 101 | G38: ='QTR BS'!AA38 -> 101 | H38: ='QTR BS'!AE38 -> 101 | I38: ='QTR BS'!AI38 -> 101 | J38: ='QTR BS'!AM38 -> 101
A39: Treasury Stock | B39: 0 | C39: 0 | D39: 0 | E39: -48226 | F39: ='QTR BS'!W39 -> -48226 | G39: ='QTR BS'!AA39 -> -48226 | H39: ='QTR BS'!AE39 -> -48226 | I39: ='QTR BS'!AI39 -> -48226 | J39: ='QTR BS'!AM39 -> -48226
A40: Additional Paid-in Capital | B40: 280668 | C40: 276717 | D40: 297579 | E40: 1050518 | F40: ='QTR BS'!W40 -> 1086890.7 | G40: ='QTR BS'!AA40 -> 1122570.5 | H40: ='QTR BS'!AE40 -> 1157570.7 | I40: ='QTR BS'!AI40 -> 1191904.2 | J40: ='QTR BS'!AM40 -> 1225583.7
...

Sheet CASH FLOW
B1: FY2021 | C1: FY2022 | D1: FY2023 | E1: FY2024 | F1: FY2025 | G1: FY2026E | H1: FY2027E | I1: FY2028E | J1: FY2029E | K1: FY2030E | L1: FY2031E
A2: Net Income (Loss) | B2: 3937 | C2: -187282 | D2: 226801 | E2: 145074 | F2: 107999 | G2: ='QTR CF'!W2+'QTR CF'!X2+'QTR CF'!Y2+'QTR CF'!Z2 -> 446870.1 | H2: ='QTR CF'!AA2+'QTR CF'!AB2+'QTR CF'!AC2+'QTR CF'!AD2 -> 438069.45 | I2: ='QTR CF'!AE2+'QTR CF'!AF2+'QTR CF'!AG2+'QTR CF'!AH2 -> 429436.43 | J2: ='QTR CF'!AI2+'QTR CF'!AJ2+'QTR CF'!AK2+'QTR CF'!AL2 -> 420967.86 | K2: ='QTR CF'!AM2+'QTR CF'!AN2+'QTR CF'!AO2+'QTR CF'!AP2 -> 412660.61
A3: Depreciation & Amortization | B3: 1264 | C3: 1917 | D3: 3226 | E3: 7274 | F3: 29451 | G3: ='QTR CF'!W6+'QTR CF'!X6+'QTR CF'!Y6+'QTR CF'!Z6 -> 35313.48 | H3: ='QTR CF'!AA6+'QTR CF'!AB6+'QTR CF'!AC6+'QTR CF'!AD6 -> 34640.809 | I3: ='QTR CF'!AE6+'QTR CF'!AF6+'QTR CF'!AG6+'QTR CF'!AH6 -> 33980.951 | J3: ='QTR CF'!AI6+'QTR CF'!AJ6+'QTR CF'!AK6+'QTR CF'!AL6 -> 33333.663 | K3: ='QTR CF'!AM6+'QTR CF'!AN6+'QTR CF'!AO6+'QTR CF'!AP6 -> 32698.705
A4: Impairment of Intangibles | B4: 0 | C4: 2379 | D4: 0 | E4: 0 | F4: 0 | G4: ='QTR CF'!W5+'QTR CF'!X5+'QTR CF'!Y5+'QTR CF'!Z5 -> 0 | H4: ='QTR CF'!AA5+'QTR CF'!AB5+'QTR CF'!AC5+'QTR CF'!AD5 -> 0 | I4: ='QTR CF'!AE5+'QTR CF'!AF5+'QTR CF'!AG5+'QTR CF'!AH5 -> 0 | J4: ='QTR CF'!AI5+'QTR CF'!AJ5+'QTR CF'!AK5+'QTR CF'!AL5 -> 0 | K4: ='QTR CF'!AM5+'QTR CF'!AN5+'QTR CF'!AO5+'QTR CF'!AP5 -> 0
A5: Allowance for Credit Losses | B5: 1494 | C5: 2352 | D5: 2128 | E5: 3294 | F5: 10600 | G5: ='QTR CF'!W7+'QTR CF'!X7+'QTR CF'!Y7+'QTR CF'!Z7 -> 0 | H5: ='QTR CF'!AA7+'QTR CF'!AB7+'QTR CF'!AC7+'QTR CF'!AD7 -> 0 | I5: ='QTR CF'!AE7+'QTR CF'!AF7+'QTR CF'!AG7+'QTR CF'!AH7 -> 0 | J5: ='QTR CF'!AI7+'QTR CF'!AJ7+'QTR CF'!AK7+'QTR CF'!AL7 -> 0 | K5: ='QTR CF'!AM7+'QTR CF'!AN7+'QTR CF'!AO7+'QTR CF'!AP7 -> 0
A6: Amortization of Deferred Other Costs | B6: 0 | C6: 5885 | D6: 14124 | E6: 14124 | F6: 26326 | G6: ='QTR CF'!W8+'QTR CF'!X8+'QTR CF'!Y8+'QTR CF'!Z8 -> 0 | H6: ='QTR CF'!AA8+'QTR CF'!AB8+'QTR CF'!AC8+'QTR CF'!AD8 -> 0 | I6: ='QTR CF'!AE8+'QTR CF'!AF8+'QTR CF'!AG8+'QTR CF'!AH8 -> 0 | J6: ='QTR CF'!AI8+'QTR CF'!AJ8+'QTR CF'!AK8+'QTR CF'!AL8 -> 0 | K6: ='QTR CF'!AM8+'QTR CF'!AN8+'QTR CF'!AO8+'QTR CF'!AP8 -> 0
A7: Inventory Write-Down | B7: 2355 | C7: 6131 | D7: 7312 | E7: 19086 | F7: 29190 | G7: ='QTR CF'!W9+'QTR CF'!X9+'QTR CF'!Y9+'QTR CF'!Z9 -> 0 | H7: ='QTR CF'!AA9+'QTR CF'!AB9+'QTR CF'!AC9+'QTR CF'!AD9 -> 0 | I7: ='QTR CF'!AE9+'QTR CF'!AF9+'QTR CF'!AG9+'QTR CF'!AH9 -> 0 | J7: ='QTR CF'!AI9+'QTR CF'!AJ9+'QTR CF'!AK9+'QTR CF'!AL9 -> 0 | K7: ='QTR CF'!AM9+'QTR CF'!AN9+'QTR CF'!AO9+'QTR CF'!AP9 -> 0
A8: Gain (Loss) on Disposal of PP&E | B8: 0 | C8: 0 | D8: 198 | E8: 173 | F8: 0 | G8: ='QTR CF'!W10+'QTR CF'!X10+'QTR CF'!Y10+'QTR CF'!Z10 -> 0 | H8: ='QTR CF'!AA10+'QTR CF'!AB10+'QTR CF'!AC10+'QTR CF'!AD10 -> 0 | I8: ='QTR CF'!AE10+'QTR CF'!AF10+'QTR CF'!AG10+'QTR CF'!AH10 -> 0 | J8: ='QTR CF'!AI10+'QTR CF'!AJ10+'QTR CF'!AK10+'QTR CF'!AL10 -> 0 | K8: ='QTR CF'!AM10+'QTR CF'!AN10+'QTR CF'!AO10+'QTR CF'!AP10 -> 0
A9: Stock-Based Compensation | B9: 36475 | C9: 20665 | D9: 21226 | E9: 19591 | F9: 28050 | G9: ='QTR CF'!W11+'QTR CF'!X11+'QTR CF'!Y11+'QTR CF'!Z11 -> 36372.687 | H9: ='QTR CF'!AA11+'QTR CF'!AB11+'QTR CF'!AC11+'QTR CF'!AD11 -> 35679.839 | I9: ='QTR CF'!AE11+'QTR CF'!AF11+'QTR CF'!AG11+'QTR CF'!AH11 -> 35000.19 | J9: ='QTR CF'!AI11+'QTR CF'!AJ11+'QTR CF'!AK11+'QTR CF'!AL11 -> 34333.487 | K9: ='QTR CF'!AM11+'QTR CF'!AN11+'QTR CF'!AO11+'QTR CF'!AP11 -> 33679.483
A10: (Benefit) Provision for Deferred Income Taxes | B10: -9201 | C10: 20244 | D10: -42055 | E10: -9730 | F10: -57336 | G10: ='QTR CF'!W14+'QTR CF'!X14+'QTR CF'!Y14+'QTR CF'!Z14 -> 56288 | H10: ='QTR CF'!AA14+'QTR CF'!AB14+'QTR CF'!AC14+'QTR CF'!AD14 -> 56288 | I10: ='QTR CF'!AE14+'QTR CF'!AF14+'QTR CF'!AG14+'QTR CF'!AH14 -> 56288 | J10: ='QTR CF'!AI14+'QTR CF'!AJ14+'QTR CF'!AK14+'QTR CF'!AL14 -> 56288 | K10: ='QTR CF'!AM14+'QTR CF'!AN14+'QTR CF'!AO14+'QTR CF'!AP14 -> 56288
A11: Foreign Currency Gain (Loss) | B11: 880 | C11: 483 | D11: 1246 | E11: 1734 | F11: 0 | G11: ='QTR CF'!W15+'QTR CF'!X15+'QTR CF'!Y15+'QTR CF'!Z15 -> 0 | H11: ='QTR CF'!AA15+'QTR CF'!AB15+'QTR CF'!AC15+'QTR CF'!AD15 -> 0 | I11: ='QTR CF'!AE15+'QTR CF'!AF15+'QTR CF'!AG15+'QTR CF'!AH15 -> 0 | J11: ='QTR CF'!AI15+'QTR CF'!AJ15+'QTR CF'!AK15+'QTR CF'!AL15 -> 0 | K11: ='QTR CF'!AM15+'QTR CF'!AN15+'QTR CF'!AO15+'QTR CF'!AP15 -> 0
A12: Gain (Loss) on Lease Cancellations | B12: -28 | C12: 0 | D12: 0 | E12: 0 | F12: 0 | G12: ='QTR CF'!W13+'QTR CF'!X13+'QTR CF'!Y13+'QTR CF'!Z13 -> 0 | H12: ='QTR CF'!AA13+'QTR CF'!AB13+'QTR CF'!AC13+'QTR CF'!AD13 -> 0 | I12: ='QTR CF'!AE13+'QTR CF'!AF13+'QTR CF'!AG13+'QTR CF'!AH13 -> 0 | J12: ='QTR CF'!AI13+'QTR CF'!AJ13+'QTR CF'!AK13+'QTR CF'!AL13 -> 0 | K12: ='QTR CF'!AM13+'QTR CF'!AN13+'QTR CF'!AO13+'QTR CF'!AP13 -> 0
A13: Change in Fair Value of Contingent Consideration | B13: 0 | C13: 0 | D13: 0 | E13: 0 | F13: 13800 | G13: ='QTR CF'!W16+'QTR CF'!X16+'QTR CF'!Y16+'QTR CF'!Z16 -> 0 | H13: ='QTR CF'!AA16+'QTR CF'!AB16+'QTR CF'!AC16+'QTR CF'!AD16 -> 0 | I13: ='QTR CF'!AE16+'QTR CF'!AF16+'QTR CF'!AG16+'QTR CF'!AH16 -> 0 | J13: ='QTR CF'!AI16+'QTR CF'!AJ16+'QTR CF'!AK16+'QTR CF'!AL16 -> 0 | K13: ='QTR CF'!AM16+'QTR CF'!AN16+'QTR CF'!AO16+'QTR CF'!AP16 -> 0
A14: Gain (Loss) on Extinguishment of Debt | B14: 0 | C14: 0 | D14: 0 | E14: 0 | F14: 6003 | G14: ='QTR CF'!W17+'QTR CF'!X17+'QTR CF'!Y17+'QTR CF'!Z17 -> 0 | H14: ='QTR CF'!AA17+'QTR CF'!AB17+'QTR CF'!AC17+'QTR CF'!AD17 -> 0 | I14: ='QTR CF'!AE17+'QTR CF'!AF17+'QTR CF'!AG17+'QTR CF'!AH17 -> 0 | J14: ='QTR CF'!AI17+'QTR CF'!AJ17+'QTR CF'!AK17+'QTR CF'!AL17 -> 0 | K14: ='QTR CF'!AM17+'QTR CF'!AN17+'QTR CF'!AO17+'QTR CF'!AP17 -> 0
A15: Other Operating Items | B15: 0 | C15: 37 | D15: -28 | E15: -324 | F15: -1687 | G15: ='QTR CF'!W18+'QTR CF'!X18+'QTR CF'!Y18+'QTR CF'!Z18 -> -257625.13 | H15: ='QTR CF'!AA18+'QTR CF'!AB18+'QTR CF'!AC18+'QTR CF'!AD18 -> 6339.7634 | I15: ='QTR CF'!AE18+'QTR CF'!AF18+'QTR CF'!AG18+'QTR CF'!AH18 -> 6219 | J15: ='QTR CF'!AI18+'QTR CF'!AJ18+'QTR CF'!AK18+'QTR CF'!AL18 -> 6100.537 | K15: ='QTR CF'!AM18+'QTR CF'!AN18+'QTR CF'!AO18+'QTR CF'!AP18 -> 5984.3306
A16: Accounts Receivable | B16: -25249 | C16: -26369 | D16: -121558 | E16: -89665 | F16: -412091 | G16: ='QTR CF'!W19+'QTR CF'!X19+'QTR CF'!Y19+'QTR CF'!Z19 -> 14391.168 | H16: ='QTR CF'!AA19+'QTR CF'!AB19+'QTR CF'!AC19+'QTR CF'!AD19 -> 14117.037 | I16: ='QTR CF'!AE19+'QTR CF'!AF19+'QTR CF'!AG19+'QTR CF'!AH19 -> 13848.128 | J16: ='QTR CF'!AI19+'QTR CF'!AJ19+'QTR CF'!AK19+'QTR CF'!AL19 -> 13584.341 | K16: ='QTR CF'!AM19+'QTR CF'!AN19+'QTR CF'!AO19+'QTR CF'!AP19 -> 13325.579
A17: Note Receivable | B17: 0 | C17: 0 | D17: 0 | E17: 2318 | F17: 0 | G17: ='QTR CF'!W20+'QTR CF'!X20+'QTR CF'!Y20+'QTR CF'!Z20 -> 0 | H17: ='QTR CF'!AA20+'QTR CF'!AB20+'QTR CF'!AC20+'QTR CF'!AD20 -> 0 | I17: ='QTR CF'!AE20+'QTR CF'!AF20+'QTR CF'!AG20+'QTR CF'!AH20 -> 0 | J17: ='QTR CF'!AI20+'QTR CF'!AJ20+'QTR CF'!AK20+'QTR CF'!AL20 -> 0 | K17: ='QTR CF'!AM20+'QTR CF'!AN20+'QTR CF'!AO20+'QTR CF'!AP20 -> 0
A18: Inventories | B18: -175174 | C18: 11802 | D18: -63299 | E18: 77190 | F18: -129777 | G18: ='QTR CF'!W21+'QTR CF'!X21+'QTR CF'!Y21+'QTR CF'!Z21 -> 6432.6608 | H18: ='QTR CF'!AA21+'QTR CF'!AB21+'QTR CF'!AC21+'QTR CF'!AD21 -> 6310.1278 | I18: ='QTR CF'!AE21+'QTR CF'!AF21+'QTR CF'!AG21+'QTR CF'!AH21 -> 6189.929 | J18: ='QTR CF'!AI21+'QTR CF'!AJ21+'QTR CF'!AK21+'QTR CF'!AL21 -> 6072.0198 | K18: ='QTR CF'!AM21+'QTR CF'!AN21+'QTR CF'!AO21+'QTR CF'!AP21 -> 5956.3565
A19: Prepaid Expenses | B19: 1072 | C19: 2214 | D19: -7980 | E19: 1074 | F19: -108321 | G19: ='QTR CF'!W22+'QTR CF'!X22+'QTR CF'!Y22+'QTR CF'!Z22 -> 2453.5689 | H19: ='QTR CF'!AA22+'QTR CF'!AB22+'QTR CF'!AC22+'QTR CF'!AD22 -> 2406.8319 | I19: ='QTR CF'!AE22+'QTR CF'!AF22+'QTR CF'!AG22+'QTR CF'!AH22 -> 2360.9852 | J19: ='QTR CF'!AI22+'QTR CF'!AJ22+'QTR CF'!AK22+'QTR CF'!AL22 -> 2316.0119 | K19: ='QTR CF'!AM22+'QTR CF'!AN22+'QTR CF'!AO22+'QTR CF'!AP22 -> 2271.8952
A20: Other Non-Current Assets | B20: 0 | C20: 0 | D20: 0 | E20: -4862 | F20: 2857 | G20: ='QTR CF'!W24+'QTR CF'!X24+'QTR CF'!Y24+'QTR CF'!Z24 -> 827.35518 | H20: ='QTR CF'!AA24+'QTR CF'!AB24+'QTR CF'!AC24+'QTR CF'!AD24 -> 811.59525 | I20: ='QTR CF'!AE24+'QTR CF'!AF24+'QTR CF'!AG24+'QTR CF'!AH24 -> 796.13553 | J20: ='QTR CF'!AI24+'QTR CF'!AJ24+'QTR CF'!AK24+'QTR CF'!AL24 -> 780.97029 | K20: ='QTR CF'!AM24+'QTR CF'!AN24+'QTR CF'!AO24+'QTR CF'!AP24 -> 766.09393
A21: Accounts Payable | B21: 23966 | C21: 428 | D21: 5249 | E21: -1170 | F21: 51252 | G21: ='QTR CF'!W25+'QTR CF'!X25+'QTR CF'!Y25+'QTR CF'!Z25 -> -2627.3679 | H21: ='QTR CF'!AA25+'QTR CF'!AB25+'QTR CF'!AC25+'QTR CF'!AD25 -> -2577.3204 | I21: ='QTR CF'!AE25+'QTR CF'!AF25+'QTR CF'!AG25+'QTR CF'!AH25 -> -2528.2261 | J21: ='QTR CF'!AI25+'QTR CF'!AJ25+'QTR CF'!AK25+'QTR CF'!AL25 -> -2480.0671 | K21: ='QTR CF'!AM25+'QTR CF'!AN25+'QTR CF'!AO25+'QTR CF'!AP25 -> -2432.8253
A22: Accrued Expenses | B22: 26484 | C22: 34644 | D22: -8025 | E22: 85398 | F22: 45618 | G22: ='QTR CF'!W26+'QTR CF'!X26+'QTR CF'!Y26+'QTR CF'!Z26 -> -4394.9029 | H22: ='QTR CF'!AA26+'QTR CF'!AB26+'QTR CF'!AC26+'QTR CF'!AD26 -> -4311.1863 | I22: ='QTR CF'!AE26+'QTR CF'!AF26+'QTR CF'!AG26+'QTR CF'!AH26 -> -4229.0645 | J22: ='QTR CF'!AI26+'QTR CF'!AJ26+'QTR CF'!AK26+'QTR CF'!AL26 -> -4148.5069 | K22: ='QTR CF'!AM26+'QTR CF'!AN26+'QTR CF'!AO26+'QTR CF'!AP26 -> -4069.4838
A23: Change in Income Taxes | B23: 1357 | C23: -164 | D23: 48102 | E23: -39536 | F23: 38750 | G23: ='QTR CF'!W27+'QTR CF'!X27+'QTR CF'!Y27+'QTR CF'!Z27 -> -945.03718 | H23: ='QTR CF'!AA27+'QTR CF'!AB27+'QTR CF'!AC27+'QTR CF'!AD27 -> -927.03558 | I23: ='QTR CF'!AE27+'QTR CF'!AF27+'QTR CF'!AG27+'QTR CF'!AH27 -> -909.37689 | J23: ='QTR CF'!AI27+'QTR CF'!AJ27+'QTR CF'!AK27+'QTR CF'!AL27 -> -892.05457 | K23: ='QTR CF'!AM27+'QTR CF'!AN27+'QTR CF'!AO27+'QTR CF'!AP27 -> -875.06221
A24: Accrued Promotional Allowance | B24: 13379 | C24: 16940 | D24: 63810 | E24: 36161 | F24: 153635 | G24: ='QTR CF'!W28+'QTR CF'!X28+'QTR CF'!Y28+'QTR CF'!Z28 -> -5865.4708 | H24: ='QTR CF'!AA28+'QTR CF'!AB28+'QTR CF'!AC28+'QTR CF'!AD28 -> -5753.7421 | I24: ='QTR CF'!AE28+'QTR CF'!AF28+'QTR CF'!AG28+'QTR CF'!AH28 -> -5644.1416 | J24: ='QTR CF'!AI28+'QTR CF'!AJ28+'QTR CF'!AK28+'QTR CF'!AL28 -> -5536.6288 | K24: ='QTR CF'!AM28+'QTR CF'!AN28+'QTR CF'!AO28+'QTR CF'!AP28 -> -5431.164
A25: Accrued Distributor Termination | B25: 0 | C25: 3986 | D25: -3739 | E25: -248 | F25: 257595 | G25: ='QTR CF'!W29+'QTR CF'!X29+'QTR CF'!Y29+'QTR CF'!Z29 -> 0 | H25: ='QTR CF'!AA29+'QTR CF'!AB29+'QTR CF'!AC29+'QTR CF'!AD29 -> 0 | I25: ='QTR CF'!AE29+'QTR CF'!AF29+'QTR CF'!AG29+'QTR CF'!AH29 -> 0 | J25: ='QTR CF'!AI29+'QTR CF'!AJ29+'QTR CF'!AK29+'QTR CF'!AL29 -> 0 | K25: ='QTR CF'!AM29+'QTR CF'!AN29+'QTR CF'!AO29+'QTR CF'!AP29 -> 0
A26: Other Current Liabilities | B26: 374 | C26: 2610 | D26: 7305 | E26: 4920 | F26: 9937 | G26: ='QTR CF'!W30+'QTR CF'!X30+'QTR CF'!Y30+'QTR CF'!Z30 -> -694.60576 | H26: ='QTR CF'!AA30+'QTR CF'!AB30+'QTR CF'!AC30+'QTR CF'!AD30 -> -681.37452 | I26: ='QTR CF'!AE30+'QTR CF'!AF30+'QTR CF'!AG30+'QTR CF'!AH30 -> -668.39531 | J26: ='QTR CF'!AI30+'QTR CF'!AJ30+'QTR CF'!AK30+'QTR CF'!AL30 -> -655.66335 | K26: ='QTR CF'!AM30+'QTR CF'!AN30+'QTR CF'!AO30+'QTR CF'!AP30 -> -643.1739
A27: ROU & Lease Liability, Net | B27: 29 | C27: -183 | D27: -102 | E27: 535 | F27: 0 | G27: ='QTR CF'!W31+'QTR CF'!X31+'QTR CF'!Y31+'QTR CF'!Z31 -> 0 | H27: ='QTR CF'!AA31+'QTR CF'!AB31+'QTR CF'!AC31+'QTR CF'!AD31 -> 0 | I27: ='QTR CF'!AE31+'QTR CF'!AF31+'QTR CF'!AG31+'QTR CF'!AH31 -> 0 | J27: ='QTR CF'!AI31+'QTR CF'!AJ31+'QTR CF'!AK31+'QTR CF'!AL31 -> 0 | K27: ='QTR CF'!AM31+'QTR CF'!AN31+'QTR CF'!AO31+'QTR CF'!AP31 -> 0
A28: Deferred Revenue | B28: 0 | C28: 189463 | D28: -12723 | E28: -9513 | F28: 255110 | G28: ='QTR CF'!W32+'QTR CF'!X32+'QTR CF'!Y32+'QTR CF'!Z32 -> 0 | H28: ='QTR CF'!AA32+'QTR CF'!AB32+'QTR CF'!AC32+'QTR CF'!AD32 -> 0 | I28: ='QTR CF'!AE32+'QTR CF'!AF32+'QTR CF'!AG32+'QTR CF'!AH32 -> 0 | J28: ='QTR CF'!AI32+'QTR CF'!AJ32+'QTR CF'!AK32+'QTR CF'!AL32 -> 0 | K28: ='QTR CF'!AM32+'QTR CF'!AN32+'QTR CF'!AO32+'QTR CF'!AP32 -> 0
A29: Net Change in Other Working Capital | B29: 0 | C29: 0 | D29: 0 | E29: 0 | F29: 2481 | G29: ='QTR CF'!W33+'QTR CF'!X33+'QTR CF'!Y33+'QTR CF'!Z33 -> 0 | H29: ='QTR CF'!AA33+'QTR CF'!AB33+'QTR CF'!AC33+'QTR CF'!AD33 -> 0 | I29: ='QTR CF'!AE33+'QTR CF'!AF33+'QTR CF'!AG33+'QTR CF'!AH33 -> 0 | J29: ='QTR CF'!AI33+'QTR CF'!AJ33+'QTR CF'!AK33+'QTR CF'!AL33 -> 0 | K29: ='QTR CF'!AM33+'QTR CF'!AN33+'QTR CF'!AO33+'QTR CF'!AP33 -> 0
A30: Cash Flow from Operations | B30: =SUM(B2:B29) -> -96586 | C30: =SUM(C2:C29) -> 108182 | D30: =SUM(D2:D29) -> 141218 | E30: =SUM(E2:E29) -> 262898 | F30: =SUM(F2:F29) -> 359442 | G30: =SUM(G2:G29) -> 326796.51 | H30: =SUM(H2:H29) -> 580412.79 | I30: =SUM(I2:I29) -> 570140.55 | ... L30: =SUM(L2:L29) -> 0
A31: Collections from Note Receivable | B31: 1886 | C31: 2592 | D31: 3233 | E31: 0 | F31: 0 | G31: ='QTR CF'!W35+'QTR CF'!X35+'QTR CF'!Y35+'QTR CF'!Z35 -> 0 | H31: ='QTR CF'!AA35+'QTR CF'!AB35+'QTR CF'!AC35+'QTR CF'!AD35 -> 0 | I31: ='QTR CF'!AE35+'QTR CF'!AF35+'QTR CF'!AG35+'QTR CF'!AH35 -> 0 | J31: ='QTR CF'!AI35+'QTR CF'!AJ35+'QTR CF'!AK35+'QTR CF'!AL35 -> 0 | K31: ='QTR CF'!AM35+'QTR CF'!AN35+'QTR CF'!AO35+'QTR CF'!AP35 -> 0
A32: Purchase of PP&E | B32: -3150 | C32: -8264 | D32: -17433 | E32: -23390 | F32: -36067 | G32: ='QTR CF'!W36+'QTR CF'!X36+'QTR CF'!Y36+'QTR CF'!Z36 -> -41609.437 | H32: ='QTR CF'!AA36+'QTR CF'!AB36+'QTR CF'!AC36+'QTR CF'!AD36 -> -40816.837 | I32: ='QTR CF'!AE36+'QTR CF'!AF36+'QTR CF'!AG36+'QTR CF'!AH36 -> -40039.335 | J32: ='QTR CF'!AI36+'QTR CF'!AJ36+'QTR CF'!AK36+'QTR CF'!AL36 -> -39276.643 | K32: ='QTR CF'!AM36+'QTR CF'!AN36+'QTR CF'!AO36+'QTR CF'!AP36 -> -38528.48
A33: Purchase of Non-Marketable Equity Securities | B33: 0 | C33: 0 | D33: 0 | E33: -3000 | F33: -10000 | G33: ='QTR CF'!W37+'QTR CF'!X37+'QTR CF'!Y37+'QTR CF'!Z37 -> 0 | H33: ='QTR CF'!AA37+'QTR CF'!AB37+'QTR CF'!AC37+'QTR CF'!AD37 -> 0 | I33: ='QTR CF'!AE37+'QTR CF'!AF37+'QTR CF'!AG37+'QTR CF'!AH37 -> 0 | J33: ='QTR CF'!AI37+'QTR CF'!AJ37+'QTR CF'!AK37+'QTR CF'!AL37 -> 0 | K33: ='QTR CF'!AM37+'QTR CF'!AN37+'QTR CF'!AO37+'QTR CF'!AP37 -> 0
A34: Acquisition of Big Beverages | B34: 0 | C34: 0 | D34: 0 | E34: -75336 | F34: 0 | G34: ='QTR CF'!W38+'QTR CF'!X38+'QTR CF'!Y38+'QTR CF'!Z38 -> 0 | H34: ='QTR CF'!AA38+'QTR CF'!AB38+'QTR CF'!AC38+'QTR CF'!AD38 -> 0 | I34: ='QTR CF'!AE38+'QTR CF'!AF38+'QTR CF'!AG38+'QTR CF'!AH38 -> 0 | J34: ='QTR CF'!AI38+'QTR CF'!AJ38+'QTR CF'!AK38+'QTR CF'!AL38 -> 0 | K34: ='QTR CF'!AM38+'QTR CF'!AN38+'QTR CF'!AO38+'QTR CF'!AP38 -> 0
A35: Acquisitions, Net of Cash Acquired | B35: 0 | C35: 0 | D35: 0 | E35: 0 | F35: -1278769 | G35: ='QTR CF'!W39+'QTR CF'!X39+'QTR CF'!Y39+'QTR CF'!Z39 -> 0 | H35: ='QTR CF'!AA39+'QTR CF'!AB39+'QTR CF'!AC39+'QTR CF'!AD39 -> 0 | I35: ='QTR CF'!AE39+'QTR CF'!AF39+'QTR CF'!AG39+'QTR CF'!AH39 -> 0 | J35: ='QTR CF'!AI39+'QTR CF'!AJ39+'QTR CF'!AK39+'QTR CF'!AL39 -> 0 | K35: ='QTR CF'!AM39+'QTR CF'!AN39+'QTR CF'!AO39+'QTR CF'!AP39 -> 0
A36: Working Capital Estimate from Pepsi (Rockstar) | B36: 0 | C36: 0 | D36: 0 | E36: 0 | F36: 29156 | G36: ='QTR CF'!W40+'QTR CF'!X40+'QTR CF'!Y40+'QTR CF'!Z40 -> 0 | H36: ='QTR CF'!AA40+'QTR CF'!AB40+'QTR CF'!AC40+'QTR CF'!AD40 -> 0 | I36: ='QTR CF'!AE40+'QTR CF'!AF40+'QTR CF'!AG40+'QTR CF'!AH40 -> 0 | J36: ='QTR CF'!AI40+'QTR CF'!AJ40+'QTR CF'!AK40+'QTR CF'!AL40 -> 0 | K36: ='QTR CF'!AM40+'QTR CF'!AN40+'QTR CF'!AO40+'QTR CF'!AP40 -> 0
A37: Cash Flow from Investing | B37: =SUM(B31:B36) -> -1264 | C37: =SUM(C31:C36) -> -5672 | D37: =SUM(D31:D36) -> -14200 | E37: =SUM(E31:E36) -> -101726 | F37: =SUM(F31:F36) -> -1295680 | G37: =SUM(G31:G36) -> -41609.437 | H37: =SUM(H31:H36) -> -40816.837 | I37: =SUM(I31:I36) -> -40039.335 | ... L37: =SUM(L31:L36) -> 0
A38: Finance Lease Payments | B38: -94 | C38: -63 | D38: -44 | E38: -61 | F38: 0 | G38: ='QTR CF'!W42+'QTR CF'!X42+'QTR CF'!Y42+'QTR CF'!Z42 -> 0 | H38: ='QTR CF'!AA42+'QTR CF'!AB42+'QTR CF'!AC42+'QTR CF'!AD42 -> 0 | I38: ='QTR CF'!AE42+'QTR CF'!AF42+'QTR CF'!AG42+'QTR CF'!AH42 -> 0 | J38: ='QTR CF'!AI42+'QTR CF'!AJ42+'QTR CF'!AK42+'QTR CF'!AL42 -> 0 | K38: ='QTR CF'!AM42+'QTR CF'!AN42+'QTR CF'!AO42+'QTR CF'!AP42 -> 0
A39: Proceeds from Exercise of Stock Options | B39: 3720 | C39: 3683 | D39: 2285 | E39: 3856 | F39: 0 | G39: ='QTR CF'!W44+'QTR CF'!X44+'QTR CF'!Y44+'QTR CF'!Z44 -> 0 | H39: ='QTR CF'!AA44+'QTR CF'!AB44+'QTR CF'!AC44+'QTR CF'!AD44 -> 0 | I39: ='QTR CF'!AE44+'QTR CF'!AF44+'QTR CF'!AG44+'QTR CF'!AH44 -> 0 | J39: ='QTR CF'!AI44+'QTR CF'!AJ44+'QTR CF'!AK44+'QTR CF'!AL44 -> 0 | K39: ='QTR CF'!AM44+'QTR CF'!AN44+'QTR CF'!AO44+'QTR CF'!AP44 -> 0
A40: Proceeds from Issuance of Common Stock | B40: 67769 | C40: 0 | D40: 0 | E40: 0 | F40: 0 | G40: ='QTR CF'!W43+'QTR CF'!X43+'QTR CF'!Y43+'QTR CF'!Z43 -> 0 | H40: ='QTR CF'!AA43+'QTR CF'!AB43+'QTR CF'!AC43+'QTR CF'!AD43 -> 0 | I40: ='QTR CF'!AE43+'QTR CF'!AF43+'QTR CF'!AG43+'QTR CF'!AH43 -> 0 | J40: ='QTR CF'!AI43+'QTR CF'!AJ43+'QTR CF'!AK43+'QTR CF'!AL43 -> 0 | K40: ='QTR CF'!AM43+'QTR CF'!AN43+'QTR CF'!AO43+'QTR CF'!AP43 -> 0
...

Sheet YTD P&L
B1: Q2 FY2020 | C1: Q3 FY2020 | D1: Q1 FY2021 | E1: Q2 FY2021 | F1: Q3 FY2021 | G1: Q1 FY2022 | H1: Q2 FY2022 | I1: Q3 FY2022 | J1: Q1 FY2023 | K1: Q2 FY2023 | L1: Q3 FY2023 | M1: Q1 FY2024 | N1: Q2 FY2024 | O1: Q3 FY2024 | P1: Q1 FY2025 | Q1: Q2 FY2025 | R1: Q3 FY2025
A2: Net Sales / Revenue | B2: 58222116 | C2: 95061265 | D2: 50035 | E2: 115108202 | F2: 210017302 | G2: 133388 | H2: 287408 | I2: 475640 | J2: 259939 | K2: 585822 | L2: 970579 | M2: 355708 | N2: 757685 | O2: 1023433 | P2: 329276 | Q2: 1068535 | R2: 1793641
A3: COGS | B3: -32207118 | C3: -51512534 | D3: -29456 | E3: -66279738 | F3: -123495466 | G3: -79494 | H3: -174195 | I3: -283778 | J3: -146121 | K3: -313010 | L3: -503685 | M3: -173501 | N3: -366380 | O3: -509899 | P3: -156903 | Q3: -515311 | R3: -868138
A4: Gross Profit (Loss) | B4: =B2+B3 -> 26014998 | C4: =C2+C3 -> 43548731 | D4: =D2+D3 -> 20579 | E4: =E2+E3 -> 48828464 | F4: =F2+F3 -> 86521836 | G4: =G2+G3 -> 53894 | H4: =H2+H3 -> 113213 | I4: =I2+I3 -> 191862 | ... R4: =R2+R3 -> 925503
A5: Sales and Marketing | B5: -15372918 | C5: -23640914 | D5: -11959 | E5: -27490041 | F5: -50111103 | G5: -31597 | H5: -64072 | I5: -262782 | J5: 0 | K5: 0 | L5: 0 | M5: 0 | N5: 0 | O5: 0 | P5: 0 | Q5: 0 | R5: 0
A6: General and Administrative | B6: -8426165 | C6: -13178593 | D6: -7807 | E6: -16926198 | F6: -28066228 | G6: -12181 | H6: -26595 | I6: -54135 | J6: 0 | K6: 0 | L6: 0 | M6: 0 | N6: 0 | O6: 0 | P6: 0 | Q6: 0 | R6: 0
A7: Operating Expenses | B7: -23799083 | C7: -36819507 | D7: -19766 | E7: -44416239 | F7: -78177331 | G7: -43778 | H7: -90667 | I7: -316917 | J7: 0 | K7: 0 | L7: 0 | M7: 0 | N7: 0 | O7: 0 | P7: 0 | Q7: 0 | R7: 0
A8: SG&A | B8: 0 | C8: 0 | D8: 0 | E8: 0 | F8: 0 | G8: 0 | H8: 0 | I8: 0 | J8: -68905 | K8: -163086 | L8: -259471 | M8: -99017 | N8: -213867 | O8: -339310 | P8: -120342 | Q8: -358228 | R8: -563799
A9: Distributor Termination Fees | B9: 0 | C9: 0 | D9: 0 | E9: 0 | F9: 0 | G9: 0 | H9: 0 | I9: 0 | J9: 0 | K9: 0 | L9: 0 | M9: 0 | N9: 0 | O9: 0 | P9: 0 | Q9: 0 | R9: -246707
A10: Income (Loss) from Operations | B10: =B4+SUM(B5:B9) -> -21583168 | C10: =C4+SUM(C5:C9) -> -30090283 | D10: =D4+SUM(D5:D9) -> -18953 | E10: =E4+SUM(E5:E9) -> -40004014 | F10: =F4+SUM(F5:F9) -> -69832826 | G10: =G4+SUM(G5:G9) -> -33662 | H10: =H4+SUM(H5:H9) -> -68121 | I10: =I4+SUM(I5:I9) -> -441972 | ... R10: =R4+SUM(R5:R9) -> 114997
A11: Interest Income (Expense) | B11: -394850 | C11: -642249 | D11: 85 | E11: 160141 | F11: 232090 | G11: 76 | H11: 129 | I11: 1579 | J11: 4969 | K11: 10542 | L11: 17767 | M11: 9640 | N11: 20287 | O11: 31399 | P11: 7846 | Q11: -6196 | R11: -19592
A12: Foreign Currency Gain (Loss) | B12: 96005 | C12: 646515 | D12: -301 | E12: -123636 | F12: -451217 | G12: -162 | H12: -676 | I12: -930 | J12: -118 | K12: -1049 | L12: -1226 | M12: -369 | N12: -633 | O12: -356 | P12: 0 | Q12: 0 | R12: 0
A13: Other Income (Expense) | B13: 35203 | C13: -27614 | D13: -12 | E13: 97038 | F13: 0 | G13: 0 | H13: 0 | I13: 0 | J13: 0 | K13: 0 | L13: 0 | M13: 0 | N13: 0 | O13: 0 | P13: 1116 | Q13: 1658 | R13: 7022
A14: Gain (Loss) on Lease Cancellations | B14: 152112 | C14: 152112 | D14: 0 | E14: 0 | F14: 0 | G14: 0 | H14: 0 | I14: 0 | J14: 0 | K14: 0 | L14: 0 | M14: 0 | N14: 0 | O14: 0 | P14: 0 | Q14: 0 | R14: 0
A15: Pre-Tax Income (Loss) | B15: =B10+SUM(B11:B14) -> -21694698 | C15: =C10+SUM(C11:C14) -> -29961519 | D15: =D10+SUM(D11:D14) -> -19181 | E15: =E10+SUM(E11:E14) -> -39870471 | F15: =F10+SUM(F11:F14) -> -70051953 | G15: =G10+SUM(G11:G14) -> -33748 | H15: =H10+SUM(H11:H14) -> -68668 | I15: =I10+SUM(I11:I14) -> -441323 | ... R15: =R10+SUM(R11:R14) -> 102427
A16: Income Tax (Expense) Benefit | B16: 0 | C16: 0 | D16: 0 | E16: 0 | F16: -833819 | G16: -3351 | H16: -6161 | I16: -41653 | J16: -8537 | K16: -26483 | L16: -47279 | M16: -14650 | N16: -39498 | O16: -41317 | P16: -16574 | Q16: -46184 | R16: -19167
A17: Net Income (Loss) | B17: =B15+B16 -> -21694698 | C17: =C15+C16 -> -29961519 | D17: =D15+D16 -> -19181 | E17: =E15+E16 -> -39870471 | F17: =F15+F16 -> -70885772 | G17: =G15+G16 -> -37099 | H17: =H15+H16 -> -74829 | I17: =I15+I16 -> -482976 | ... R17: =R15+R16 -> 83260
A18: Preferred Dividends | B18: 0 | C18: 0 | D18: 0 | E18: 0 | F18: 0 | G18: 0 | H18: 0 | I18: -4596 | J18: -6781 | K18: -13637 | L18: -20512 | M18: -6837 | N18: -13675 | O18: -20588 | P18: -6781 | Q18: -13632 | R18: -23289
A19: Income Allocated to Participating Preferred | B19: 0 | C19: 0 | D19: 0 | E19: 0 | F19: 0 | G19: 0 | H19: 0 | I19: 0 | J19: 0 | K19: -6727 | L19: -13263 | M19: -6128 | N19: -12417 | O19: -12357 | P19: -3219 | Q19: -10703 | R19: -5272
A20: Net Income (Loss) Attributable to Common Shareholders | B20: =B17+B18+B19 -> -21694698 | C20: =C17+C18+C19 -> -29961519 | D20: =D17+D18+D19 -> -19181 | E20: =E17+E18+E19 -> -39870471 | F20: =F17+F18+F19 -> -70885772 | G20: =G17+G18+G19 -> -37099 | H20: =H17+H18+H19 -> -74829 | I20: =I17+I18+I19 -> -487572 | ... R20: =R17+R18+R19 -> 54699

Sheet YTD BS
B1: Q4 FY2020 | C1: Q2 FY2021 | D1: Q3 FY2021 | E1: Q4 FY2021 | F1: Q1 FY2022 | G1: Q2 FY2022 | H1: Q3 FY2022 | I1: Q4 FY2022 | J1: Q1 FY2023 | K1: Q2 FY2023 | L1: Q3 FY2023 | M1: Q4 FY2023 | N1: Q1 FY2024 | O1: Q2 FY2024 | P1: Q3 FY2024 | Q1: Q4 FY2024 | R1: Q1 FY2025 | S1: Q2 FY2025 | T1: Q3 FY2025
A2: Cash, Cash Equivalents & Restricted Cash | B2: 43248021 | C2: 83789981 | D2: 61377202 | E2: 16255 | F2: 25532 | G2: 60031 | H2: 726972 | I2: 652927 | J2: 633581 | K2: 681054 | L2: 760022 | M2: 755981 | N2: 879498 | O2: 903210 | P2: 903748 | Q2: 890190 | R2: 977285 | S2: 615233 | T2: 932463
A3: Accounts Receivable | B3: 14986213 | C3: 32398823 | D3: 43500578 | E3: 38741 | F3: 72707 | G3: 66195 | H3: 117003 | I3: 63311 | J3: 172032 | K3: 197811 | L3: 215243 | M3: 183703 | N3: 200117 | O3: 262920 | P3: 208774 | Q3: 270342 | R3: 256424 | S3: 490389 | T3: 513682
A4: Note Receivable - Current | B4: 1885887 | C4: 2545745 | D4: 2543225 | E4: 2588 | F4: 5833 | G4: 3066 | H4: 2888 | I4: 2979 | J4: 3587 | K4: 3323 | L4: 3309 | M4: 2318 | N4: 2259 | O4: 1166 | P4: 1025 | Q4: 0 | R4: 0 | S4: 0 | T4: 0
A5: Inventories | B5: 18403622 | C5: 63826596 | D5: 122311445 | E5: 191222 | F5: 184094 | G5: 162138 | H5: 153933 | I5: 173289 | J5: 154280 | K5: 152545 | L5: 198704 | M5: 229275 | N5: 197504 | O5: 180669 | P5: 197572 | Q5: 131165 | R5: 141159 | S5: 230046 | T5: 282514
A6: Prepaid Expenses | B6: 14626922 | C6: 22744642 | D6: 22829510 | E6: 13555 | F6: 10042 | G6: 12298 | H6: 12096 | I6: 11341 | J6: 15507 | K6: 23398 | L6: 23747 | M6: 19503 | N6: 21523 | O6: 22900 | P6: 38227 | Q6: 18759 | R6: 22464 | S6: 41420 | T6: 163395
A7: Deferred Other Costs - Current | B7: 0 | C7: 0 | D7: 0 | E7: 0 | F7: 0 | G7: 0 | H7: 14124 | I7: 14124 | J7: 14124 | K7: 14124 | L7: 14124 | M7: 14124 | N7: 14124 | O7: 14124 | P7: 14124 | Q7: 14124 | R7: 14124 | S7: 14124 | T7: 49520
A8: Total Current Assets | B8: =SUM(B2:B7) -> 93150665 | C8: =SUM(C2:C7) -> 205305787 | D8: =SUM(D2:D7) -> 252561960 | E8: =SUM(E2:E7) -> 262361 | F8: =SUM(F2:F7) -> 298208 | G8: =SUM(G2:G7) -> 303728 | H8: =SUM(H2:H7) -> 1027016 | I8: =SUM(I2:I7) -> 917971 | ... T8: =SUM(T2:T7) -> 1941574
A9: Note Receivable - Non-Current | B9: 9429437 | C9: 7000800 | D9: 6993869 | E9: 7117 | F9: 3888 | G9: 3679 | H9: 3465 | I9: 3574 | J9: 0 | K9: 0 | L9: 0 | M9: 0 | N9: 0 | O9: 0 | P9: 0 | Q9: 0 | R9: 0 | S9: 0 | T9: 0
A10: Net PP&E | B10: 579377 | C10: 1617002 | D10: 2454914 | E10: 3180 | F10: 3702 | G10: 5135 | H10: 5782 | I10: 10185 | J10: 12054 | K10: 15892 | L10: 21061 | M10: 24868 | N10: 28350 | O10: 36282 | P10: 38370 | Q10: 55602 | R10: 58698 | S10: 72516 | T10: 80925
A11: ROU Assets - Operating - Non-Current | B11: 836038 | C11: 704857 | D11: 888911 | E11: 1128 | F11: 1141 | G11: 954 | H11: 1105 | I11: 972 | J11: 931 | K11: 756 | L11: 1152 | M11: 1957 | N11: 1688 | O11: 1507 | P11: 5506 | Q11: 21606 | R11: 20866 | S11: 0 | T11: 0
A12: Intangible Assets | B12: 16590083 | C12: 16287537 | D12: 16811762 | E12: 16301 | F12: 15838 | G12: 14689 | H12: 11322 | I12: 12254 | J12: 12359 | K12: 12211 | L12: 11772 | M12: 12139 | N12: 11741 | O12: 11491 | P12: 11877 | Q12: 12213 | R12: 12444 | S12: 1222115 | T12: 1397819
A13: Goodwill | B13: 10419321 | C13: 10419321 | D13: 14851635 | E13: 14527 | F13: 14238 | G13: 13323 | H13: 12502 | I13: 13679 | J13: 13949 | K13: 13937 | L13: 13588 | M13: 14173 | N13: 13866 | O13: 13730 | P13: 14360 | Q13: 71582 | R13: 72128 | S13: 802234 | T13: 914957
A14: Deferred Other Costs - Non-Current | B14: 0 | C14: 0 | D14: 0 | E14: 0 | F14: 0 | G14: 0 | H14: 265993 | I14: 262462 | J14: 258931 | K14: 255400 | L14: 251869 | M14: 248338 | N14: 244807 | O14: 241276 | P14: 237746 | Q14: 234215 | R14: 230684 | S14: 227153 | T14: 784214
A15: Deferred Tax Assets | B15: 0 | C15: 0 | D15: 0 | E15: 9019 | F15: 6396 | G15: 7686 | H15: 0 | I15: 501 | J15: 482 | K15: 28373 | L15: 30614 | M15: 29518 | N15: 22437 | O15: 22727 | P15: 24186 | Q15: 38699 | R15: 38525 | S15: 43158 | T15: 110410
A16: ROU Assets - Finance - Non-Current | B16: 162119 | C16: 100365 | D16: 106675 | E16: 86 | F16: 220 | G16: 180 | H16: 222 | I16: 208 | J16: 191 | K16: 171 | L16: 148 | M16: 208 | N16: 263 | O16: 233 | P16: 214 | Q16: 0 | R16: 0 | S16: 0 | T16: 0
A17: Other Non-Current Assets | B17: 122733 | C17: 112456 | D17: 308449 | E17: 300 | F17: 293 | G17: 264 | H17: 242 | I17: 263 | J17: 263 | K17: 254 | L17: 265 | M17: 291 | N17: 7963 | O17: 6653 | P17: 8594 | Q17: 8384 | R17: 14717 | S17: 36755 | T17: 35809
A18: Total Assets | B18: =B8+SUM(B9:B17) -> 131289773 | C18: =C8+SUM(C9:C17) -> 241548125 | D18: =D8+SUM(D9:D17) -> 294978175 | E18: =E8+SUM(E9:E17) -> 314019 | F18: =F8+SUM(F9:F17) -> 343924 | G18: =G8+SUM(G9:G17) -> 349638 | H18: =H8+SUM(H9:H17) -> 1327649 | I18: =I8+SUM(I9:I17) -> 1222069 | ... T18: =T8+SUM(T9:T17) -> 5265708
A19: Accounts Payable | B19: 25412753 | C19: 52992075 | D19: 91931593 | E19: 91479 | F19: 109307 | G19: 102416 | H19: 143947 | I19: 107340 | J19: 107112 | K19: 94313 | L19: 121088 | M19: 42840 | N19: 40196 | O19: 47423 | P19: 30938 | Q19: 41287 | R19: 61052 | S19: 120962 | T19: 97794
A20: Accrued Expenses | B20: 0 | C20: 0 | D20: 0 | E20: 0 | F20: 0 | G20: 0 | H20: 0 | I20: 0 | J20: 0 | K20: 0 | L20: 0 | M20: 62120 | N20: 63871 | O20: 79633 | P20: 73024 | Q20: 148780 | R20: 152046 | S20: 225859 | T20: 311768
A21: Income Taxes Payable | B21: 0 | C21: 0 | D21: 0 | E21: 0 | F21: 0 | G21: 0 | H21: 0 | I21: 0 | J21: 0 | K21: 58798 | L21: 58855 | M21: 50424 | N21: 58619 | O21: 5374 | P21: 739 | Q21: 10834 | R21: 26206 | S21: 21765 | T21: 49590
A22: Accrued Distributor Termination Fees | B22: 0 | C22: 0 | D22: 0 | E22: 0 | F22: 0 | G22: 0 | H22: 115551 | I22: 3986 | J22: 1063 | K22: 0 | L22: 0 | M22: 0 | N22: 0 | O22: 0 | P22: 0 | Q22: 0 | R22: 0 | S22: 0 | T22: 252953
A23: Accrued Promotional Allowance | B23: 0 | C23: 0 | D23: 0 | E23: 0 | F23: 0 | G23: 0 | H23: 0 | I23: 35977 | J23: 68225 | K23: 98933 | L23: 136557 | M23: 99787 | N23: 129201 | O23: 156479 | P23: 158810 | Q23: 135948 | R23: 151327 | S23: 200169 | T23: 234068
A24: Lease Liability - Operating - Current | B24: 321283 | C24: 318142 | D24: 376602 | E24: 512 | F24: 569 | G24: 556 | H24: 663 | I24: 661 | J24: 605 | K24: 505 | L24: 628 | M24: 980 | N24: 821 | O24: 729 | P24: 1358 | Q24: 3265 | R24: 3550 | S24: 0 | T24: 0
A25: Lease Liability - Finance - Current | B25: 205824 | C25: 191753 | D25: 155508 | E25: 157 | F25: 141 | G25: 101 | H25: 95 | I25: 70 | J25: 69 | K25: 67 | L25: 63 | M25: 59 | N25: 61 | O25: 61 | P25: 99 | Q25: 0 | R25: 0 | S25: 0 | T25: 0
A26: Contingent Consideration - Current | B26: 0 | C26: 0 | D26: 0 | E26: 0 | F26: 0 | G26: 0 | H26: 0 | I26: 0 | J26: 0 | K26: 0 | L26: 0 | M26: 0 | N26: 0 | O26: 0 | P26: 0 | Q26: 0 | R26: 0 | S26: 25000 | T26: 25000
A27: Deferred Revenue - Current | B27: 0 | C27: 0 | D27: 0 | E27: 0 | F27: 0 | G27: 0 | H27: 7770 | I27: 9675 | J27: 9563 | K27: 9500 | L27: 9500 | M27: 9513 | N27: 9513 | O27: 9513 | P27: 9513 | Q27: 9513 | R27: 9513 | S27: 16071 | T27: 25557
A28: Other Current Liabilities | B28: 425232 | C28: 754907 | D28: 957627 | E28: 976 | F28: 1734 | G28: 2761 | H28: 3267 | I28: 3586 | J28: 5094 | K28: 7109 | L28: 8826 | M28: 10890 | N28: 12987 | O28: 13772 | P28: 14979 | Q28: 15908 | R28: 14160 | S28: 49949 | T28: 32258
A29: Total Current Liabilities | B29: =SUM(B19:B28) -> 26365092 | C29: =SUM(C19:C28) -> 54256877 | D29: =SUM(D19:D28) -> 93421330 | E29: =SUM(E19:E28) -> 93124 | F29: =SUM(F19:F28) -> 111751 | G29: =SUM(G19:G28) -> 105834 | H29: =SUM(H19:H28) -> 271293 | I29: =SUM(I19:I28) -> 161295 | ... T29: =SUM(T19:T28) -> 1028988
A30: Lease Liability - Operating - Non-Current | B30: 514948 | C30: 391157 | D30: 550547 | E30: 658 | F30: 597 | G30: 420 | H30: 462 | I30: 326 | J30: 336 | K30: 249 | L30: 512 | M30: 955 | N30: 850 | O30: 762 | P30: 4193 | Q30: 16674 | R30: 16152 | S30: 0 | T30: 0
A31: Lease Liability - Finance - Non-Current | B31: 82290 | C31: 60731 | D31: 88649 | E31: 45 | F31: 138 | G31: 138 | H31: 167 | I31: 162 | J31: 156 | K31: 147 | L31: 135 | M31: 193 | N31: 245 | O31: 228 | P31: 189 | Q31: 0 | R31: 0 | S31: 0 | T31: 0
A32: Deferred Tax Liability | B32: 0 | C32: 0 | D32: 3497240 | E32: 3146 | F32: 3084 | G32: 2886 | H32: 25457 | I32: 15919 | J32: 19250 | K32: 2333 | L32: 2249 | M32: 2880 | N32: 2248 | O32: 2201 | P32: 2275 | Q32: 0 | R32: 0 | S32: 0 | T32: 0
A33: Long-Term Debt | B33: 0 | C33: 0 | D33: 0 | E33: 0 | F33: 0 | G33: 0 | H33: 0 | I33: 0 | J33: 0 | K33: 0 | L33: 0 | M33: 0 | N33: 0 | O33: 0 | P33: 0 | Q33: 0 | R33: 0 | S33: 862917 | T33: 861472
A34: Deferred Revenue - Non-Current | B34: 0 | C34: 0 | D34: 0 | E34: 0 | F34: 0 | G34: 0 | H34: 146333 | I34: 179788 | J34: 175275 | K34: 171745 | L34: 169370 | M34: 167227 | N34: 164849 | O34: 162471 | P34: 160092 | Q34: 157714 | R34: 155336 | S34: 156135 | T34: 387432
A35: Other Non-Current Liabilities | B35: 0 | C35: 0 | D35: 22198 | E35: 0 | F35: 0 | G35: 487 | H35: 0 | I35: 0 | J35: 0 | K35: 0 | L35: 0 | M35: 0 | N35: 0 | O35: 0 | P35: 0 | Q35: 2541 | R35: 2574 | S35: 25002 | T35: 24431
A36: Total Liabilities | B36: =B29+SUM(B30:B35) -> 26962330 | C36: =C29+SUM(C30:C35) -> 54708765 | D36: =D29+SUM(D30:D35) -> 97579964 | E36: =E29+SUM(E30:E35) -> 96973 | F36: =F29+SUM(F30:F35) -> 115570 | G36: =G29+SUM(G30:G35) -> 109765 | H36: =H29+SUM(H30:H35) -> 443712 | I36: =I29+SUM(I30:I35) -> 357490 | ... T36: =T29+SUM(T30:T35) -> 2302323
A37: Convertible Preferred Stock | B37: 0 | C37: 0 | D37: 0 | E37: 0 | F37: 0 | G37: 0 | H37: 824488 | I37: 824488 | J37: 824488 | K37: 824488 | L37: 824488 | M37: 824488 | N37: 824488 | O37: 824488 | P37: 824488 | Q37: 824488 | R37: 824488 | S37: 824488 | T37: 1760275
A38: Common Stock | B38: 72263 | C38: 74471 | D38: 74746 | E38: 75 | F38: 75 | G38: 76 | H38: 76 | I38: 76 | J38: 77 | K38: 77 | L38: 77 | M38: 77 | N38: 78 | O38: 78 | P38: 79 | Q38: 79 | R38: 79 | S38: 101 | T38: 101
A39: Treasury Stock | B39: 0 | C39: 0 | D39: 0 | E39: 0 | F39: 0 | G39: 0 | H39: 0 | I39: 0 | J39: 0 | K39: 0 | L39: 0 | M39: 0 | N39: 0 | O39: 0 | P39: 0 | Q39: 0 | R39: 0 | S39: 0 | T39: 0
A40: Additional Paid-in Capital | B40: 159884154 | C40: 237763609 | D40: 244293710 | E40: 267847 | F40: 272967 | G40: 277623 | H40: 281133 | I40: 280668 | J40: 279872 | K40: 278980 | L40: 277980 | M40: 276717 | N40: 281247 | O40: 286173 | P40: 292576 | Q40: 297579 | R40: 300877 | S40: 1028384 | T40: 1035021
...

Sheet YTD CF
B1: Q2 FY2020 | C1: Q3 FY2020 | D1: Q1 FY2021 | E1: Q2 FY2021 | F1: Q3 FY2021 | G1: Q1 FY2022 | H1: Q2 FY2022 | I1: Q3 FY2022 | J1: Q1 FY2023 | K1: Q2 FY2023 | L1: Q3 FY2023 | M1: Q1 FY2024 | N1: Q2 FY2024 | O1: Q3 FY2024 | P1: Q1 FY2025 | Q1: Q2 FY2025 | R1: Q3 FY2025
A2: Net Income (Loss) | B2: 2104385 | C2: 6857988 | D2: 585 | E2: 4545768 | F2: 7291559 | G2: 6679 | H2: 15838 | I2: -166059 | J2: 41227 | K2: 92736 | L2: 176685 | M2: 77811 | N2: 157594 | O2: 163950 | P2: 44419 | Q2: 144274 | R2: 83260
A3: Depreciation | B3: 50351 | C3: 82180 | D3: 108 | E3: 178425 | F3: 519765 | G3: 245 | H3: 556 | I3: 952 | J3: 404 | K3: 953 | L3: 1676 | M3: 0 | N3: 0 | O3: 0 | P3: 0 | Q3: 0 | R3: 0
A4: Amortization | B4: 851045 | C4: 1224684 | D4: 188 | E4: 375141 | F4: 550800 | G4: 141 | H4: 275 | I4: 402 | J4: 145 | K4: 294 | L4: 445 | M4: 0 | N4: 0 | O4: 0 | P4: 0 | Q4: 0 | R4: 0
A5: Impairment of Intangibles | B5: 0 | C5: 0 | D5: 0 | E5: 0 | F5: 0 | G5: 0 | H5: 0 | I5: 2379 | J5: 0 | K5: 0 | L5: 0 | M5: 0 | N5: 0 | O5: 0 | P5: 0 | Q5: 0 | R5: 0
A6: Depreciation & Amortization | B6: 0 | C6: 0 | D6: 0 | E6: 0 | F6: 0 | G6: 0 | H6: 0 | I6: 0 | J6: 0 | K6: 0 | L6: 0 | M6: 1229 | N6: 2648 | O6: 4888 | P6: 2611 | Q6: 11730 | R6: 20516
A7: Allowance for Credit Losses | B7: 221182 | C7: 244685 | D7: 223 | E7: 854606 | F7: -207261 | G7: 455 | H7: 466 | I7: 705 | J7: 837 | K7: 1088 | L7: 1880 | M7: 2250 | N7: 4072 | O7: 4279 | P7: 2077 | Q7: 5529 | R7: 3226
A8: Amortization of Deferred Other Costs | B8: 0 | C8: 0 | D8: 0 | E8: 0 | F8: 0 | G8: 0 | H8: 0 | I8: 2354 | J8: 3531 | K8: 7062 | L8: 10593 | M8: 3531 | N8: 7062 | O8: 10593 | P8: 3531 | Q8: 7062 | R8: 13391
A9: Inventory Write-Down | B9: -137370 | C9: 211822 | D9: 754 | E9: 1260076 | F9: 12234 | G9: 2596 | H9: 331 | I9: 1078 | J9: 1672 | K9: -3888 | L9: 2677 | M9: 2386 | N9: 11554 | O9: 17118 | P9: 5337 | Q9: 15262 | R9: 22313
A10: Gain (Loss) on Disposal of PP&E | B10: 0 | C10: 0 | D10: 0 | E10: 0 | F10: 0 | G10: 0 | H10: 0 | I10: 0 | J10: 0 | K10: 191 | L10: 195 | M10: -8 | N10: 31 | O10: 126 | P10: 0 | Q10: 0 | R10: 0
A11: Stock-Based Compensation | B11: 2574999 | C11: 4718699 | D11: 3575 | E11: 7597260 | F11: 13400581 | G11: 4310 | H11: 8517 | I11: 14780 | J11: 5507 | K11: 11242 | L11: 16221 | M11: 3563 | N11: 8309 | O11: 13685 | P11: 5029 | Q11: 11463 | R11: 18847
A12: Gain on China Transaction | B12: 23100 | C12: -384493 | D12: 0 | E12: 0 | F12: 0 | G12: 0 | H12: 0 | I12: 0 | J12: 0 | K12: 0 | L12: 0 | M12: 0 | N12: 0 | O12: 0 | P12: 0 | Q12: 0 | R12: 0
A13: Gain (Loss) on Lease Cancellations | B13: -152112 | C13: -152112 | D13: 0 | E13: 0 | F13: -14669 | G13: 0 | H13: 0 | I13: 0 | J13: 0 | K13: 0 | L13: 0 | M13: 0 | N13: 0 | O13: 0 | P13: 0 | Q13: 0 | R13: 0
... A33: Net Change in Other Working Capital | B33: 0 | C33: 213764 | D33: 0 | E33: 0 | F33: 532395 | G33: 0 | H33: 488 | I33: 0 | J33: 0 | K33: 0 | L33: 0 | M33: 0 | N33: 0 | O33: 0 | P33: 148 | Q33: -1210 | R33: -1786
A34: Cash Flow from Operations | B34: =SUM(B2:B33) -> -4246078 | C34: =SUM(C2:C33) -> 3843510 | D34: =SUM(D2:D33) -> -13318 | E34: =SUM(E2:E33) -> -30329464 | F34: =SUM(F2:F33) -> -52063949 | G34: =SUM(G2:G33) -> 9125 | H34: =SUM(H2:H33) -> 42296 | I34: =SUM(I2:I33) -> 170967 | ... R34: =SUM(R2:R33) -> 478880
A35: Collections from Note Receivable | B35: 1331011 | C35: 1331011 | D35: 1876 | E35: 1876273 | F35: 1885724 | G35: 0 | H35: 2592 | I35: 2592 | J35: 3233 | K35: 3233 | L35: 3233 | M35: 0 | N35: 0 | O35: 0 | P35: 0 | Q35: 0 | R35: 0
A36: Purchase of PP&E | B36: -315777 | C36: -416671 | D36: -698 | E36: -1216050 | F36: -2395302 | G36: -742 | H36: -2456 | I36: -3477 | J36: -2253 | K36: -6810 | L36: -12687 | M36: -4525 | N36: -13739 | O36: -17983 | P36: -6944 | Q36: -15194 | R36: -25539
A37: Purchase of Non-Marketable Equity Securities | B37: 0 | C37: 0 | D37: 0 | E37: 0 | F37: 0 | G37: 0 | H37: 0 | I37: 0 | J37: 0 | K37: 0 | L37: 0 | M37: 0 | N37: 0 | O37: -3000 | P37: 0 | Q37: -5000 | R37: -5000
A38: Acquisition of Big Beverages | B38: 0 | C38: 0 | D38: 0 | E38: 0 | F38: 0 | G38: 0 | H38: 0 | I38: 0 | J38: 0 | K38: 0 | L38: 0 | M38: 0 | N38: 0 | O38: 0 | P38: 0 | Q38: 0 | R38: 0
A39: Acquisitions, Net of Cash Acquired | B39: 0 | C39: 0 | D39: 0 | E39: 0 | F39: 0 | G39: 0 | H39: 0 | I39: 0 | J39: 0 | K39: 0 | L39: 0 | M39: 0 | N39: 0 | O39: 0 | P39: 0 | Q39: -1256351 | R39: -1278769
A40: Working Capital Estimate from Pepsi (Rockstar) | B40: 0 | C40: 0 | D40: 0 | E40: 0 | F40: 0 | G40: 0 | H40: 0 | I40: 0 | J40: 0 | K40: 0 | L40: 0 | M40: 0 | N40: 0 | O40: 0 | P40: 0 | Q40: 0 | R40: 30617
A41: Cash Flow from Investing | B41: =SUM(B35:B40) -> 1015234 | C41: =SUM(C35:C40) -> 914340 | D41: =SUM(D35:D40) -> 1178 | E41: =SUM(E35:E40) -> 660223 | F41: =SUM(F35:F40) -> -509578 | G41: =SUM(G35:G40) -> -742 | H41: =SUM(H35:H40) -> 136 | I41: =SUM(I35:I40) -> -885 | ... R41: =SUM(R35:R40) -> -1278691
A42: Finance Lease Payments | B42: -222052 | C42: -259231 | D42: -25 | E42: -49592 | F42: -72386 | G42: -20 | H42: -37 | I42: -49 | J42: -11 | K42: -22 | L42: -33 | M42: -15 | N42: -30 | O42: -46 | P42: 0 | Q42: 0 | R42: 0
A43: Proceeds from Issuance of Common Stock | B43: 0 | C43: 21983116 | D43: 0 | E43: 67769386 | F43: 67769386 | G43: 0 | H43: 0 | I43: 0 | J43: 0 | K43: 0 | L43: 0 | M43: 0 | N43: 0 | O43: 0 | P43: 0 | Q43: 0 | R43: 0
A44: Proceeds from Exercise of Stock Options | B44: 704664 | C44: 2296343 | D44: 716 | E44: 2515017 | F44: 3242073 | G44: 810 | H44: 1260 | I44: 3104 | J44: 478 | K44: 707 | L44: 1603 | M44: 967 | N44: 1147 | O44: 3832 | P44: 0 | Q44: 0 | R44: 0
A45: Proceeds from Issuance of Preferred Stock | B45: 0 | C45: 0 | D45: 0 | E45: 0 | F45: 0 | G45: 0 | H45: 0 | I45: 542018 | J45: 0 | K45: 0 | L45: 0 | M45: 0 | N45: 0 | O45: 0 | P45: 0 | Q45: 0 | R45: 0
A46: Preferred Dividends | B46: 0 | C46: 0 | D46: 0 | E46: 0 | F46: 0 | G46: 0 | H46: 0 | I46: -4596 | J46: -6781 | K46: -13637 | L46: -20512 | M46: -6837 | N46: -13675 | O46: -20588 | P46: -6781 | Q46: -13632 | R46: -23301
A47: Share Repurchases | B47: 0 | C47: 0 | D47: 0 | E47: 0 | F47: 0 | G47: 0 | H47: 0 | I47: 0 | J47: 0 | K47: 0 | L47: 0 | M47: 0 | N47: 0 | O47: -1658 | P47: -1932 | Q47: -2811 | R47: -3259
A48: Proceeds from Issuance of Long-Term Debt | B48: 0 | C48: 0 | D48: 0 | E48: 0 | F48: 0 | G48: 0 | H48: 0 | I48: 0 | J48: 0 | K48: 0 | L48: 0 | M48: 0 | N48: 0 | O48: 0 | P48: 0 | Q48: 900000 | R48: 900000
A49: Repayments of Long-Term Debt | B49: 0 | C49: 0 | D49: 0 | E49: 0 | F49: 0 | G49: 0 | H49: 0 | I49: 0 | J49: 0 | K49: 0 | L49: 0 | M49: 0 | N49: 0 | O49: 0 | P49: 0 | Q49: 0 | R49: -2250
A50: Debt Issuance Fees | B50: 0 | C50: 0 | D50: 0 | E50: 0 | F50: 0 | G50: 0 | H50: 0 | I50: 0 | J50: 0 | K50: 0 | L50: 0 | M50: 0 | N50: 0 | O50: 0 | P50: -2195 | Q50: -31581 | R50: -31581
A51: Other Financing Activities | B51: 0 | C51: 0 | D51: 0 | E51: 0 | F51: 0 | G51: 0 | H51: 0 | I51: 0 | J51: 0 | K51: 0 | L51: 0 | M51: 0 | N51: 0 | O51: 0 | P51: 321 | Q51: 319 | R51: 301
A52: Cash Flow from Financing | B52: =SUM(B42:B51) -> 482612 | C52: =SUM(C42:C51) -> 24020228 | D52: =SUM(D42:D51) -> 691 | E52: =SUM(E42:E51) -> 70234811 | F52: =SUM(F42:F51) -> 70939073 | G52: =SUM(G42:G51) -> 790 | H52: =SUM(H42:H51) -> 1223 | I52: =SUM(I42:I51) -> 540477 | ... R52: =SUM(R42:R51) -> 839910
A53: FX Effect on Cash | B53: -231635 | C53: 289338 | D53: -165 | E53: -23610 | F53: -236365 | G53: 104 | H53: 121 | I53: 158 | J53: -181 | K53: -555 | L53: -555 | M53: -722 | N53: -766 | O53: -16 | P53: 1259 | Q53: 2214 | R53: 2174
A54: Net Change in Cash | B54: =B34+B41+B52+B53 -> -2979867 | C54: =C34+C41+C52+C53 -> 29067416 | D54: =D34+D41+D52+D53 -> -11614 | E54: =E34+E41+E52+E53 -> 40541960 | F54: =F34+F41+F52+F53 -> 18129181 | G54: =G34+G41+G52+G53 -> 9277 | H54: =H34+H41+H52+H53 -> 43776 | I54: =I34+I41+I52+I53 -> 710717 | ... R54: =R34+R41+R52+R53 -> 42273

Sheet QTR P&L
B1: Q3 FY2020 | C1: Q1 FY2021 | D1: Q2 FY2021 | E1: Q3 FY2021 | F1: Q4 FY2021 | G1: Q1 FY2022 | H1: Q2 FY2022 | I1: Q3 FY2022 | J1: Q4 FY2022 | K1: Q1 FY2023 | L1: Q2 FY2023 | M1: Q3 FY2023 | N1: Q4 FY2023 | O1: Q1 FY2024 | P1: Q2 FY2024 | Q1: Q3 FY2024 | R1: Q4 FY2024 | S1: Q1 FY2025 | T1: Q2 FY2025 | U1: Q3 FY2025 | V1: Q4 FY2025 | W1: Q1 FY2026E | X1: Q2 FY2026E | Y1: Q3 FY2026E | Z1: Q4 FY2026E | AA1: Q1 FY2027E | AB1: Q2 FY2027E | AC1: Q3 FY2027E | AD1: Q4 FY2027E | AE1: Q1 FY2028E | AF1: Q2 FY2028E | AG1: Q3 FY2028E | AH1: Q4 FY2028E | AI1: Q1 FY2029E | AJ1: Q2 FY2029E | AK1: Q3 FY2029E | AL1: Q4 FY2029E | AM1: Q1 FY2030E | AN1: Q2 FY2030E | AO1: Q3 FY2030E | AP1: Q4 FY2030E
A2: Net Sales / Revenue | B2: ='YTD P&L'!C2-'YTD P&L'!B2 -> 36839149 | C2: ='YTD P&L'!D2 -> 50035 | D2: ='YTD P&L'!E2-'YTD P&L'!D2 -> 115058167 | E2: ='YTD P&L'!F2-'YTD P&L'!E2 -> 94909100 | F2: ='ANNL P&L'!B2-'YTD P&L'!F2 -> -209703030 | G2: ='YTD P&L'!G2 -> 133388 | H2: ='YTD P&L'!H2-'YTD P&L'!G2 -> 154020 | I2: ='YTD P&L'!I2-'YTD P&L'!H2 -> 188232 | J2: ='ANNL P&L'!C2-'YTD P&L'!I2 -> 177964 | K2: ='YTD P&L'!J2 -> 259939 | L2: ='YTD P&L'!K2-'YTD P&L'!J2 -> 325883 | M2: ='YTD P&L'!L2-'YTD P&L'!K2 -> 384757 | N2: ='ANNL P&L'!D2-'YTD P&L'!L2 -> 347435 | O2: ='YTD P&L'!M2 -> 355708 | P2: ='YTD P&L'!N2-'YTD P&L'!M2 -> 401977 | Q2: ='YTD P&L'!O2-'YTD P&L'!N2 -> 265748 | R2: ='ANNL P&L'!E2-'YTD P&L'!O2 -> 332197 | S2: ='YTD P&L'!P2 -> 329276 | T2: ='YTD P&L'!Q2-'YTD P&L'!P2 -> 739259 | U2: ='YTD P&L'!R2-'YTD P&L'!Q2 -> 725106 | V2: ='ANNL P&L'!F2-'YTD P&L'!R2 -> 721628 | W2: =IF('IS DRIVERS'!$B2="QoQ",'QTR P&L'!V2,'QTR P&L'!S2)*(1+'IS DRIVERS'!X2) -> 718166.68 | X2: =IF('IS DRIVERS'!$B2="QoQ",'QTR P&L'!W2,'QTR P&L'!T2)*(1+'IS DRIVERS'!Y2) -> 714721.97 | Y2: =IF('IS DRIVERS'!$B2="QoQ",'QTR P&L'!X2,'QTR P&L'!U2)*(1+'IS DRIVERS'!Z2) -> 711293.77 | Z2: =IF('IS DRIVERS'!$B2="QoQ",'QTR P&L'!Y2,'QTR P&L'!V2)*(1+'IS DRIVERS'!AA2) -> 707882.03 | AA2: =IF('IS DRIVERS'!$B2="QoQ",'QTR P&L'!Z2,'QTR P&L'!W2)*(1+'IS DRIVERS'!AB2) -> 704486.64 | AB2: =IF('IS DRIVERS'!$B2="QoQ",'QTR P&L'!AA2,'QTR P&L'!X2)*(1+'IS DRIVERS'!AC2) -> 701107.54 | AC2: =IF('IS DRIVERS'!$B2="QoQ",'QTR P&L'!AB2,'QTR P&L'!Y2)*(1+'IS DRIVERS'!AD2) -> 697744.65 | AD2: =IF('IS DRIVERS'!$B2="QoQ",'QTR P&L'!AC2,'QTR P&L'!Z2)*(1+'IS DRIVERS'!AE2) -> 694397.89 | ... AP2: =IF('IS DRIVERS'!$B2="QoQ",'QTR P&L'!AO2,'QTR P&L'!AL2)*(1+'IS DRIVERS'!AQ2) -> 655467.13
