Workbook

Sheet ASSUMPTIONS
A1: Assumption | B1: Value | C1: Note
A2: Days in Quarter | B2: 91 | C2: Used by DSO/DIO/DPO ratios. Approximation; varies 89-92 by quarter.

Sheet ANNL P&L
B1: FY2021 | C1: FY2022 | D1: FY2023 | E1: FY2024 | F1: FY2025 | G1: FY2026E | H1: FY2027E | I1: FY2028E | J1: FY2029E | K1: FY2030E | L1: FY2031E
A2: Net Sales / Revenue | B2: 314272 | C2: 653604 | D2: 1318014 | E2: 1355630 | F2: 2515269 | G2: ='QTR P&L'!R2+'QTR P&L'!S2+'QTR P&L'!T2+'QTR P&L'!U2 | H2: ='QTR P&L'!V2+'QTR P&L'!W2+'QTR P&L'!X2+'QTR P&L'!Y2 | I2: ='QTR P&L'!Z2+'QTR P&L'!AA2+'QTR P&L'!AB2+'QTR P&L'!AC2 | J2: ='QTR P&L'!AD2+'QTR P&L'!AE2+'QTR P&L'!AF2+'QTR P&L'!AG2
A3: COGS | B3: -186103 | C3: -382735 | D3: -684875 | E3: -675423 | F3: -1247936 | G3: ='QTR P&L'!R3+'QTR P&L'!S3+'QTR P&L'!T3+'QTR P&L'!U3 | H3: ='QTR P&L'!V3+'QTR P&L'!W3+'QTR P&L'!X3+'QTR P&L'!Y3 | I3: ='QTR P&L'!Z3+'QTR P&L'!AA3+'QTR P&L'!AB3+'QTR P&L'!AC3 | J3: ='QTR P&L'!AD3+'QTR P&L'!AE3+'QTR P&L'!AF3+'QTR P&L'!AG3
A4: Gross Profit (Loss) | B4: =B2+B3 | C4: =C2+C3 | D4: =D2+D3 | E4: =E2+E3 | F4: =F2+F3 | G4: =G2+G3 | H4: =H2+H3 | I4: =I2+I3 | ... L4: =L2+L3
A5: SG&A | B5: -132259 | C5: -428670 | D5: -366773 | E5: -524479 | F5: -798810 | G5: ='QTR P&L'!R5+'QTR P&L'!S5+'QTR P&L'!T5+'QTR P&L'!U5 | H5: ='QTR P&L'!V5+'QTR P&L'!W5+'QTR P&L'!X5+'QTR P&L'!Y5 | I5: ='QTR P&L'!Z5+'QTR P&L'!AA5+'QTR P&L'!AB5+'QTR P&L'!AC5 | J5: ='QTR P&L'!AD5+'QTR P&L'!AE5+'QTR P&L'!AF5+'QTR P&L'!AG5
A6: Distributor Termination Fees | B6: 0 | C6: 0 | D6: 0 | E6: 0 | F6: -327461 | G6: ='QTR P&L'!R6+'QTR P&L'!S6+'QTR P&L'!T6+'QTR P&L'!U6 | H6: ='QTR P&L'!V6+'QTR P&L'!W6+'QTR P&L'!X6+'QTR P&L'!Y6 | I6: ='QTR P&L'!Z6+'QTR P&L'!AA6+'QTR P&L'!AB6+'QTR P&L'!AC6 | J6: ='QTR P&L'!AD6+'QTR P&L'!AE6+'QTR P&L'!AF6+'QTR P&L'!AG6
A7: Income (Loss) from Operations | B7: =B4+SUM(B5:B6) | C7: =C4+SUM(C5:C6) | D7: =D4+SUM(D5:D6) | E7: =E4+SUM(E5:E6) | F7: =F4+SUM(F5:F6) | G7: =G4+SUM(G5:G6) | H7: =H4+SUM(H5:H6) | I7: =I4+SUM(I5:I6) | ... L7: =L4+SUM(L5:L6)
A8: Interest Income (Expense) | B8: 307 | C8: 5529 | D8: 26629 | E8: 39263 | F8: -27892 | G8: ='QTR P&L'!R8+'QTR P&L'!S8+'QTR P&L'!T8+'QTR P&L'!U8 | H8: ='QTR P&L'!V8+'QTR P&L'!W8+'QTR P&L'!X8+'QTR P&L'!Y8 | I8: ='QTR P&L'!Z8+'QTR P&L'!AA8+'QTR P&L'!AB8+'QTR P&L'!AC8 | J8: ='QTR P&L'!AD8+'QTR P&L'!AE8+'QTR P&L'!AF8+'QTR P&L'!AG8
A9: Foreign Currency Gain (Loss) | B9: -276 | C9: -392 | D9: -1246 | E9: -1734 | F9: 0 | G9: ='QTR P&L'!R9+'QTR P&L'!S9+'QTR P&L'!T9+'QTR P&L'!U9 | H9: ='QTR P&L'!V9+'QTR P&L'!W9+'QTR P&L'!X9+'QTR P&L'!Y9 | I9: ='QTR P&L'!Z9+'QTR P&L'!AA9+'QTR P&L'!AB9+'QTR P&L'!AC9 | J9: ='QTR P&L'!AD9+'QTR P&L'!AE9+'QTR P&L'!AF9+'QTR P&L'!AG9
A10: Other Income (Expense) | B10: 0 | C10: 0 | D10: 0 | E10: 1793 | F10: 11863 | G10: ='QTR P&L'!R10+'QTR P&L'!S10+'QTR P&L'!T10+'QTR P&L'!U10 | H10: ='QTR P&L'!V10+'QTR P&L'!W10+'QTR P&L'!X10+'QTR P&L'!Y10 | I10: ='QTR P&L'!Z10+'QTR P&L'!AA10+'QTR P&L'!AB10+'QTR P&L'!AC10 | J10: ='QTR P&L'!AD10+'QTR P&L'!AE10+'QTR P&L'!AF10+'QTR P&L'!AG10
A11: Pre-Tax Income (Loss) | B11: =B7+SUM(B8:B10) | C11: =C7+SUM(C8:C10) | D11: =D7+SUM(D8:D10) | E11: =E7+SUM(E8:E10) | F11: =F7+SUM(F8:F10) | G11: =G7+SUM(G8:G10) | H11: =H7+SUM(H8:H10) | I11: =I7+SUM(I8:I10) | ... L11: =L7+SUM(L8:L10)
A12: Income Tax (Expense) Benefit | B12: 7996 | C12: -34618 | D12: -64948 | E12: -49976 | F12: -17034 | G12: ='QTR P&L'!R12+'QTR P&L'!S12+'QTR P&L'!T12+'QTR P&L'!U12 | H12: ='QTR P&L'!V12+'QTR P&L'!W12+'QTR P&L'!X12+'QTR P&L'!Y12 | I12: ='QTR P&L'!Z12+'QTR P&L'!AA12+'QTR P&L'!AB12+'QTR P&L'!AC12 | J12: ='QTR P&L'!AD12+'QTR P&L'!AE12+'QTR P&L'!AF12+'QTR P&L'!AG12
A13: Net Income (Loss) | B13: =B11+B12 | C13: =C11+C12 | D13: =D11+D12 | E13: =E11+E12 | F13: =F11+F12 | G13: =G11+G12 | H13: =H11+H12 | I13: =I11+I12 | ... L13: =L11+L12
A14: Preferred Dividends | B14: 0 | C14: -11526 | D14: -27462 | E14: -27500 | F14: -37608 | G14: ='QTR P&L'!R14+'QTR P&L'!S14+'QTR P&L'!T14+'QTR P&L'!U14 | H14: ='QTR P&L'!V14+'QTR P&L'!W14+'QTR P&L'!X14+'QTR P&L'!Y14 | I14: ='QTR P&L'!Z14+'QTR P&L'!AA14+'QTR P&L'!AB14+'QTR P&L'!AC14 | J14: ='QTR P&L'!AD14+'QTR P&L'!AE14+'QTR P&L'!AF14+'QTR P&L'!AG14
A15: Income Allocated to Participating Preferred | B15: 0 | C15: 0 | D15: 17348 | E15: 10117 | F15: 6554 | G15: ='QTR P&L'!R15+'QTR P&L'!S15+'QTR P&L'!T15+'QTR P&L'!U15 | H15: ='QTR P&L'!V15+'QTR P&L'!W15+'QTR P&L'!X15+'QTR P&L'!Y15 | I15: ='QTR P&L'!Z15+'QTR P&L'!AA15+'QTR P&L'!AB15+'QTR P&L'!AC15 | J15: ='QTR P&L'!AD15+'QTR P&L'!AE15+'QTR P&L'!AF15+'QTR P&L'!AG15
A16: Net Income (Loss) Attributable to Common Shareholders | B16: 3937 | C16: -198808 | D16: 181991 | E16: 107457 | F16: 63837 | G16: ='QTR P&L'!R16+'QTR P&L'!S16+'QTR P&L'!T16+'QTR P&L'!U16 | H16: ='QTR P&L'!V16+'QTR P&L'!W16+'QTR P&L'!X16+'QTR P&L'!Y16 | I16: ='QTR P&L'!Z16+'QTR P&L'!AA16+'QTR P&L'!AB16+'QTR P&L'!AC16 | J16: ='QTR P&L'!AD16+'QTR P&L'!AE16+'QTR P&L'!AF16+'QTR P&L'!AG16

Sheet BALANCE SHEET
B1: FY2022 | C1: FY2023 | D1: FY2024 | E1: FY2025 | F1: FY2026E | G1: FY2027E | H1: FY2028E | I1: FY2029E | J1: FY2030E | K1: FY2031E
A2: Cash & Cash Equivalents | B2: 614159 | C2: 755981 | D2: 890190 | E2: 398866 | F2: ='QTR BS'!R2 | G2: ='QTR BS'!V2 | H2: ='QTR BS'!Z2 | I2: ='QTR BS'!AD2
A3: Restricted Cash | B3: 38768 | C3: 0 | D3: 0 | E3: 141121 | F3: ='QTR BS'!R3 | G3: ='QTR BS'!V3 | H3: ='QTR BS'!Z3 | I3: ='QTR BS'!AD3
A4: Accounts Receivable | B4: 63311 | C4: 183703 | D4: 270342 | E4: 755499 | F4: ='QTR BS'!R4 | G4: ='QTR BS'!V4 | H4: ='QTR BS'!Z4 | I4: ='QTR BS'!AD4
A5: Note Receivable - Current | B5: 2979 | C5: 2318 | D5: 0 | E5: 0 | F5: ='QTR BS'!R5 | G5: ='QTR BS'!V5 | H5: ='QTR BS'!Z5 | I5: ='QTR BS'!AD5
A6: Inventories | B6: 173289 | C6: 229275 | D6: 131165 | E6: 337698 | F6: ='QTR BS'!R6 | G6: ='QTR BS'!V6 | H6: ='QTR BS'!Z6 | I6: ='QTR BS'!AD6
A7: Prepaid Expenses | B7: 11341 | C7: 19503 | D7: 18759 | E7: 128806 | F7: ='QTR BS'!R7 | G7: ='QTR BS'!V7 | H7: ='QTR BS'!Z7 | I7: ='QTR BS'!AD7
A8: Deferred Other Costs - Current | B8: 14124 | C8: 14124 | D8: 14124 | E8: 49164 | F8: ='QTR BS'!R8 | G8: ='QTR BS'!V8 | H8: ='QTR BS'!Z8 | I8: ='QTR BS'!AD8
A9: Total Current Assets | B9: =SUM(B2:B8) | C9: =SUM(C2:C8) | D9: =SUM(D2:D8) | E9: =SUM(E2:E8) | F9: =SUM(F2:F8) | G9: =SUM(G2:G8) | H9: =SUM(H2:H8) | I9: =SUM(I2:I8) | ... K9: =SUM(K2:K8)
A10: Note Receivable - Non-Current | B10: 3574 | C10: 0 | D10: 0 | E10: 0 | F10: ='QTR BS'!R10 | G10: ='QTR BS'!V10 | H10: ='QTR BS'!Z10 | I10: ='QTR BS'!AD10
A11: Net PP&E | B11: 10185 | C11: 24868 | D11: 55602 | E11: 87910 | F11: ='QTR BS'!R11 | G11: ='QTR BS'!V11 | H11: ='QTR BS'!Z11 | I11: ='QTR BS'!AD11
A12: ROU Assets - Operating - Non-Current | B12: 972 | C12: 1957 | D12: 21606 | E12: 0 | F12: ='QTR BS'!R12 | G12: ='QTR BS'!V12 | H12: ='QTR BS'!Z12 | I12: ='QTR BS'!AD12
A13: ROU Assets - Finance - Non-Current | B13: 208 | C13: 208 | D13: 230 | E13: 0 | F13: ='QTR BS'!R17 | G13: ='QTR BS'!V17 | H13: ='QTR BS'!Z17 | I13: ='QTR BS'!AD17
A14: Intangible Assets | B14: 12254 | C14: 12139 | D14: 12213 | E14: 1391915 | F14: ='QTR BS'!R13 | G14: ='QTR BS'!V13 | H14: ='QTR BS'!Z13 | I14: ='QTR BS'!AD13
A15: Goodwill | B15: 13679 | C15: 14173 | D15: 71582 | E15: 917560 | F15: ='QTR BS'!R14 | G15: ='QTR BS'!V14 | H15: ='QTR BS'!Z14 | I15: ='QTR BS'!AD14
A16: Deferred Other Costs - Non-Current | B16: 262462 | C16: 248338 | D16: 234215 | E16: 771635 | F16: ='QTR BS'!R15 | G16: ='QTR BS'!V15 | H16: ='QTR BS'!Z15 | I16: ='QTR BS'!AD15
A17: Deferred Tax Assets | B17: 501 | C17: 29518 | D17: 38699 | E17: 96013 | F17: ='QTR BS'!R16 | G17: ='QTR BS'!V16 | H17: ='QTR BS'!Z16 | I17: ='QTR BS'!AD16
A18: Other Non-Current Assets | B18: 263 | C18: 291 | D18: 8154 | E18: 43434 | F18: ='QTR BS'!R18 | G18: ='QTR BS'!V18 | H18: ='QTR BS'!Z18 | I18: ='QTR BS'!AD18
A19: Total Assets | B19: =B9+SUM(B10:B18) | C19: =C9+SUM(C10:C18) | D19: =D9+SUM(D10:D18) | E19: =E9+SUM(E10:E18) | F19: =F9+SUM(F10:F18) | G19: =G9+SUM(G10:G18) | H19: =H9+SUM(H10:H18) | I19: =I9+SUM(I10:I18) | ... K19: =K9+SUM(K10:K18)
A20: Accounts Payable | B20: 36248 | C20: 42840 | D20: 41287 | E20: 137930 | F20: ='QTR BS'!R20 | G20: ='QTR BS'!V20 | H20: ='QTR BS'!Z20 | I20: ='QTR BS'!AD20
A21: Accrued Expenses | B21: 69899 | C21: 62120 | D21: 148780 | E21: 230721 | F21: ='QTR BS'!R21 | G21: ='QTR BS'!V21 | H21: ='QTR BS'!Z21 | I21: ='QTR BS'!AD21
A22: Income Taxes Payable | B22: 1193 | C22: 50424 | D22: 10834 | E22: 49612 | F22: ='QTR BS'!R22 | G22: ='QTR BS'!V22 | H22: ='QTR BS'!Z22 | I22: ='QTR BS'!AD22
A23: Accrued Distributor Termination Fees | B23: 3986 | C23: 0 | D23: 0 | E23: 264088 | F23: ='QTR BS'!R23 | G23: ='QTR BS'!V23 | H23: ='QTR BS'!Z23 | I23: ='QTR BS'!AD23
A24: Accrued Promotional Allowance | B24: 35977 | C24: 99787 | D24: 135948 | E24: 307922 | F24: ='QTR BS'!R24 | G24: ='QTR BS'!V24 | H24: ='QTR BS'!Z24 | I24: ='QTR BS'!AD24
A25: Lease Liability - Operating - Current | B25: 661 | C25: 980 | D25: 3265 | E25: 0 | F25: ='QTR BS'!R25 | G25: ='QTR BS'!V25 | H25: ='QTR BS'!Z25 | I25: ='QTR BS'!AD25
A26: Lease Liability - Finance - Current | B26: 70 | C26: 59 | D26: 100 | E26: 0 | F26: ='QTR BS'!R26 | G26: ='QTR BS'!V26 | H26: ='QTR BS'!Z26 | I26: ='QTR BS'!AD26
A27: Contingent Consideration - Current | B27: 0 | C27: 0 | D27: 0 | E27: 25000 | F27: ='QTR BS'!R27 | G27: ='QTR BS'!V27 | H27: ='QTR BS'!Z27 | I27: ='QTR BS'!AD27
A28: Deferred Revenue - Current | B28: 9675 | C28: 9513 | D28: 9513 | E28: 26988 | F28: ='QTR BS'!R28 | G28: ='QTR BS'!V28 | H28: ='QTR BS'!Z28 | I28: ='QTR BS'!AD28
A29: Other Current Liabilities | B29: 3586 | C29: 10890 | D29: 15808 | E29: 36465 | F29: ='QTR BS'!R29 | G29: ='QTR BS'!V29 | H29: ='QTR BS'!Z29 | I29: ='QTR BS'!AD29
A30: Total Current Liabilities | B30: =SUM(B20:B29) | C30: =SUM(C20:C29) | D30: =SUM(D20:D29) | E30: =SUM(E20:E29) | F30: =SUM(F20:F29) | G30: =SUM(G20:G29) | H30: =SUM(H20:H29) | I30: =SUM(I20:I29) | ... K30: =SUM(K20:K29)
A31: Lease Liability - Operating - Non-Current | B31: 326 | C31: 955 | D31: 16674 | E31: 0 | F31: ='QTR BS'!R31 | G31: ='QTR BS'!V31 | H31: ='QTR BS'!Z31 | I31: ='QTR BS'!AD31
A32: Lease Liability - Finance - Non-Current | B32: 162 | C32: 193 | D32: 211 | E32: 0 | F32: ='QTR BS'!R32 | G32: ='QTR BS'!V32 | H32: ='QTR BS'!Z32 | I32: ='QTR BS'!AD32
A33: Deferred Tax Liability | B33: 15919 | C33: 2880 | D33: 2330 | E33: 0 | F33: ='QTR BS'!R33 | G33: ='QTR BS'!V33 | H33: ='QTR BS'!Z33 | I33: ='QTR BS'!AD33
A34: Long-Term Debt | B34: 0 | C34: 0 | D34: 0 | E34: 669926 | F34: ='QTR BS'!R34 | G34: ='QTR BS'!V34 | H34: ='QTR BS'!Z34 | I34: ='QTR BS'!AD34
A35: Deferred Revenue - Non-Current | B35: 179788 | C35: 167227 | D35: 157714 | E35: 401155 | F35: ='QTR BS'!R35 | G35: ='QTR BS'!V35 | H35: ='QTR BS'!Z35 | I35: ='QTR BS'!AD35
A36: Other Non-Current Liabilities | B36: 0 | C36: 0 | D36: 0 | E36: 28372 | F36: ='QTR BS'!R36 | G36: ='QTR BS'!V36 | H36: ='QTR BS'!Z36 | I36: ='QTR BS'!AD36
A37: Total Liabilities | B37: =B30+SUM(B31:B36) | C37: =C30+SUM(C31:C36) | D37: =D30+SUM(D31:D36) | E37: =E30+SUM(E31:E36) | F37: =F30+SUM(F31:F36) | G37: =G30+SUM(G31:G36) | H37: =H30+SUM(H31:H36) | I37: =I30+SUM(I31:I36) | ... K37: =K30+SUM(K31:K36)
A38: Convertible Preferred Stock | B38: 824488 | C38: 824488 | D38: 824488 | E38: 1759975 | F38: ='QTR BS'!R38 | G38: ='QTR BS'!V38 | H38: ='QTR BS'!Z38 | I38: ='QTR BS'!AD38
A39: Common Stock | B39: 76 | C39: 77 | D39: 79 | E39: 101 | F39: ='QTR BS'!R39 | G39: ='QTR BS'!V39 | H39: ='QTR BS'!Z39 | I39: ='QTR BS'!AD39
A40: Treasury Stock | B40: 0 | C40: 0 | D40: 0 | E40: -48226 | F40: ='QTR BS'!R40 | G40: ='QTR BS'!V40 | H40: ='QTR BS'!Z40 | I40: ='QTR BS'!AD40
...

Sheet CASH FLOW
B1: FY2021 | C1: FY2022 | D1: FY2023 | E1: FY2024 | F1: FY2025 | G1: FY2026E | H1: FY2027E | I1: FY2028E | J1: FY2029E | K1: FY2030E | L1: FY2031E
A2: Net Income (Loss) | B2: 3937 | C2: -187282 | D2: 226801 | E2: 145074 | F2: 107999 | G2: ='QTR CF'!R2+'QTR CF'!S2+'QTR CF'!T2+'QTR CF'!U2 | H2: ='QTR CF'!V2+'QTR CF'!W2+'QTR CF'!X2+'QTR CF'!Y2 | I2: ='QTR CF'!Z2+'QTR CF'!AA2+'QTR CF'!AB2+'QTR CF'!AC2 | J2: ='QTR CF'!AD2+'QTR CF'!AE2+'QTR CF'!AF2+'QTR CF'!AG2
A3: Depreciation & Amortization | B3: 1264 | C3: 1917 | D3: 3226 | E3: 7274 | F3: 29451 | G3: ='QTR CF'!R6+'QTR CF'!S6+'QTR CF'!T6+'QTR CF'!U6 | H3: ='QTR CF'!V6+'QTR CF'!W6+'QTR CF'!X6+'QTR CF'!Y6 | I3: ='QTR CF'!Z6+'QTR CF'!AA6+'QTR CF'!AB6+'QTR CF'!AC6 | J3: ='QTR CF'!AD6+'QTR CF'!AE6+'QTR CF'!AF6+'QTR CF'!AG6
A4: Impairment of Intangibles | B4: 0 | C4: 2379 | D4: 0 | E4: 0 | F4: 0 | G4: ='QTR CF'!R5+'QTR CF'!S5+'QTR CF'!T5+'QTR CF'!U5 | H4: ='QTR CF'!V5+'QTR CF'!W5+'QTR CF'!X5+'QTR CF'!Y5 | I4: ='QTR CF'!Z5+'QTR CF'!AA5+'QTR CF'!AB5+'QTR CF'!AC5 | J4: ='QTR CF'!AD5+'QTR CF'!AE5+'QTR CF'!AF5+'QTR CF'!AG5
A5: Allowance for Credit Losses | B5: 1494 | C5: 2352 | D5: 2128 | E5: 3294 | F5: 10600 | G5: ='QTR CF'!R7+'QTR CF'!S7+'QTR CF'!T7+'QTR CF'!U7 | H5: ='QTR CF'!V7+'QTR CF'!W7+'QTR CF'!X7+'QTR CF'!Y7 | I5: ='QTR CF'!Z7+'QTR CF'!AA7+'QTR CF'!AB7+'QTR CF'!AC7 | J5: ='QTR CF'!AD7+'QTR CF'!AE7+'QTR CF'!AF7+'QTR CF'!AG7
A6: Amortization of Deferred Other Costs | B6: 0 | C6: 5885 | D6: 14124 | E6: 14124 | F6: 26326 | G6: ='QTR CF'!R8+'QTR CF'!S8+'QTR CF'!T8+'QTR CF'!U8 | H6: ='QTR CF'!V8+'QTR CF'!W8+'QTR CF'!X8+'QTR CF'!Y8 | I6: ='QTR CF'!Z8+'QTR CF'!AA8+'QTR CF'!AB8+'QTR CF'!AC8 | J6: ='QTR CF'!AD8+'QTR CF'!AE8+'QTR CF'!AF8+'QTR CF'!AG8
A7: Inventory Write-Down | B7: 2355 | C7: 6131 | D7: 7312 | E7: 19086 | F7: 29190 | G7: ='QTR CF'!R9+'QTR CF'!S9+'QTR CF'!T9+'QTR CF'!U9 | H7: ='QTR CF'!V9+'QTR CF'!W9+'QTR CF'!X9+'QTR CF'!Y9 | I7: ='QTR CF'!Z9+'QTR CF'!AA9+'QTR CF'!AB9+'QTR CF'!AC9 | J7: ='QTR CF'!AD9+'QTR CF'!AE9+'QTR CF'!AF9+'QTR CF'!AG9
A8: Gain (Loss) on Disposal of PP&E | B8: 0 | C8: 0 | D8: 198 | E8: 173 | F8: 0 | G8: ='QTR CF'!R10+'QTR CF'!S10+'QTR CF'!T10+'QTR CF'!U10 | H8: ='QTR CF'!V10+'QTR CF'!W10+'QTR CF'!X10+'QTR CF'!Y10 | I8: ='QTR CF'!Z10+'QTR CF'!AA10+'QTR CF'!AB10+'QTR CF'!AC10 | J8: ='QTR CF'!AD10+'QTR CF'!AE10+'QTR CF'!AF10+'QTR CF'!AG10
A9: Stock-Based Compensation | B9: 36475 | C9: 20665 | D9: 21226 | E9: 19591 | F9: 28050 | G9: ='QTR CF'!R11+'QTR CF'!S11+'QTR CF'!T11+'QTR CF'!U11 | H9: ='QTR CF'!V11+'QTR CF'!W11+'QTR CF'!X11+'QTR CF'!Y11 | I9: ='QTR CF'!Z11+'QTR CF'!AA11+'QTR CF'!AB11+'QTR CF'!AC11 | J9: ='QTR CF'!AD11+'QTR CF'!AE11+'QTR CF'!AF11+'QTR CF'!AG11
A10: (Benefit) Provision for Deferred Income Taxes | B10: -9201 | C10: 20244 | D10: -42055 | E10: -9730 | F10: -57336 | G10: ='QTR CF'!R12+'QTR CF'!S12+'QTR CF'!T12+'QTR CF'!U12 | H10: ='QTR CF'!V12+'QTR CF'!W12+'QTR CF'!X12+'QTR CF'!Y12 | I10: ='QTR CF'!Z12+'QTR CF'!AA12+'QTR CF'!AB12+'QTR CF'!AC12 | J10: ='QTR CF'!AD12+'QTR CF'!AE12+'QTR CF'!AF12+'QTR CF'!AG12
A11: Foreign Currency Gain (Loss) | B11: 880 | C11: 483 | D11: 1246 | E11: 1734 | F11: 0 | G11: ='QTR CF'!R13+'QTR CF'!S13+'QTR CF'!T13+'QTR CF'!U13 | H11: ='QTR CF'!V13+'QTR CF'!W13+'QTR CF'!X13+'QTR CF'!Y13 | I11: ='QTR CF'!Z13+'QTR CF'!AA13+'QTR CF'!AB13+'QTR CF'!AC13 | J11: ='QTR CF'!AD13+'QTR CF'!AE13+'QTR CF'!AF13+'QTR CF'!AG13
A12: Gain (Loss) on Lease Cancellations | B12: -28 | C12: 0 | D12: 0 | E12: 0 | F12: 0 | G12: ='QTR CF'!R14+'QTR CF'!S14+'QTR CF'!T14+'QTR CF'!U14 | H12: ='QTR CF'!V14+'QTR CF'!W14+'QTR CF'!X14+'QTR CF'!Y14 | I12: ='QTR CF'!Z14+'QTR CF'!AA14+'QTR CF'!AB14+'QTR CF'!AC14 | J12: ='QTR CF'!AD14+'QTR CF'!AE14+'QTR CF'!AF14+'QTR CF'!AG14
A13: Change in Fair Value of Contingent Consideration | B13: 0 | C13: 0 | D13: 0 | E13: 0 | F13: 13800 | G13: ='QTR CF'!R15+'QTR CF'!S15+'QTR CF'!T15+'QTR CF'!U15 | H13: ='QTR CF'!V15+'QTR CF'!W15+'QTR CF'!X15+'QTR CF'!Y15 | I13: ='QTR CF'!Z15+'QTR CF'!AA15+'QTR CF'!AB15+'QTR CF'!AC15 | J13: ='QTR CF'!AD15+'QTR CF'!AE15+'QTR CF'!AF15+'QTR CF'!AG15
A14: Gain (Loss) on Extinguishment of Debt | B14: 0 | C14: 0 | D14: 0 | E14: 0 | F14: 6003 | G14: ='QTR CF'!R16+'QTR CF'!S16+'QTR CF'!T16+'QTR CF'!U16 | H14: ='QTR CF'!V16+'QTR CF'!W16+'QTR CF'!X16+'QTR CF'!Y16 | I14: ='QTR CF'!Z16+'QTR CF'!AA16+'QTR CF'!AB16+'QTR CF'!AC16 | J14: ='QTR CF'!AD16+'QTR CF'!AE16+'QTR CF'!AF16+'QTR CF'!AG16
A15: Other Operating Items | B15: 0 | C15: 37 | D15: -28 | E15: -324 | F15: -1687 | G15: ='QTR CF'!R17+'QTR CF'!S17+'QTR CF'!T17+'QTR CF'!U17 | H15: ='QTR CF'!V17+'QTR CF'!W17+'QTR CF'!X17+'QTR CF'!Y17 | I15: ='QTR CF'!Z17+'QTR CF'!AA17+'QTR CF'!AB17+'QTR CF'!AC17 | J15: ='QTR CF'!AD17+'QTR CF'!AE17+'QTR CF'!AF17+'QTR CF'!AG17
A16: Accounts Receivable | B16: -25249 | C16: -26369 | D16: -121558 | E16: -89665 | F16: -412091 | G16: ='QTR CF'!R18+'QTR CF'!S18+'QTR CF'!T18+'QTR CF'!U18 | H16: ='QTR CF'!V18+'QTR CF'!W18+'QTR CF'!X18+'QTR CF'!Y18 | I16: ='QTR CF'!Z18+'QTR CF'!AA18+'QTR CF'!AB18+'QTR CF'!AC18 | J16: ='QTR CF'!AD18+'QTR CF'!AE18+'QTR CF'!AF18+'QTR CF'!AG18
... A19: Prepaid Expenses | B19: 1072 | C19: 2214 | D19: -7980 | E19: 1074 | F19: -108321 | G19: ='QTR CF'!R21+'QTR CF'!S21+'QTR CF'!T21+'QTR CF'!U21 | H19: ='QTR CF'!V21+'QTR CF'!W21+'QTR CF'!X21+'QTR CF'!Y21 | I19: ='QTR CF'!Z21+'QTR CF'!AA21+'QTR CF'!AB21+'QTR CF'!AC21 | J19: ='QTR CF'!AD21+'QTR CF'!AE21+'QTR CF'!AF21+'QTR CF'!AG21
A20: Other Non-Current Assets | B20: 0 | C20: 0 | D20: 0 | E20: -4862 | F20: 2857 | G20: ='QTR CF'!R23+'QTR CF'!S23+'QTR CF'!T23+'QTR CF'!U23 | H20: ='QTR CF'!V23+'QTR CF'!W23+'QTR CF'!X23+'QTR CF'!Y23 | I20: ='QTR CF'!Z23+'QTR CF'!AA23+'QTR CF'!AB23+'QTR CF'!AC23 | J20: ='QTR CF'!AD23+'QTR CF'!AE23+'QTR CF'!AF23+'QTR CF'!AG23
A21: Accounts Payable | B21: 23966 | C21: 428 | D21: 5249 | E21: -1170 | F21: 51252 | G21: ='QTR CF'!R24+'QTR CF'!S24+'QTR CF'!T24+'QTR CF'!U24 | H21: ='QTR CF'!V24+'QTR CF'!W24+'QTR CF'!X24+'QTR CF'!Y24 | I21: ='QTR CF'!Z24+'QTR CF'!AA24+'QTR CF'!AB24+'QTR CF'!AC24 | J21: ='QTR CF'!AD24+'QTR CF'!AE24+'QTR CF'!AF24+'QTR CF'!AG24
A22: Accrued Expenses | B22: 26484 | C22: 34644 | D22: -8025 | E22: 85398 | F22: 45618 | G22: ='QTR CF'!R25+'QTR CF'!S25+'QTR CF'!T25+'QTR CF'!U25 | H22: ='QTR CF'!V25+'QTR CF'!W25+'QTR CF'!X25+'QTR CF'!Y25 | I22: ='QTR CF'!Z25+'QTR CF'!AA25+'QTR CF'!AB25+'QTR CF'!AC25 | J22: ='QTR CF'!AD25+'QTR CF'!AE25+'QTR CF'!AF25+'QTR CF'!AG25
A23: Other Current Liabilities | B23: 1731 | C23: 2446 | D23: 55407 | E23: -34616 | F23: 48687 | G23: ='QTR CF'!R26+'QTR CF'!S26+'QTR CF'!T26+'QTR CF'!U26 | H23: ='QTR CF'!V26+'QTR CF'!W26+'QTR CF'!X26+'QTR CF'!Y26 | I23: ='QTR CF'!Z26+'QTR CF'!AA26+'QTR CF'!AB26+'QTR CF'!AC26 | J23: ='QTR CF'!AD26+'QTR CF'!AE26+'QTR CF'!AF26+'QTR CF'!AG26
A24: Accrued Promotional Allowance | B24: 13379 | C24: 16940 | D24: 63810 | E24: 36161 | F24: 153635 | G24: ='QTR CF'!R27+'QTR CF'!S27+'QTR CF'!T27+'QTR CF'!U27 | H24: ='QTR CF'!V27+'QTR CF'!W27+'QTR CF'!X27+'QTR CF'!Y27 | I24: ='QTR CF'!Z27+'QTR CF'!AA27+'QTR CF'!AB27+'QTR CF'!AC27 | J24: ='QTR CF'!AD27+'QTR CF'!AE27+'QTR CF'!AF27+'QTR CF'!AG27
A25: Accrued Distributor Termination | B25: 0 | C25: 3986 | D25: -3739 | E25: -248 | F25: 257595 | G25: ='QTR CF'!R28+'QTR CF'!S28+'QTR CF'!T28+'QTR CF'!U28 | H25: ='QTR CF'!V28+'QTR CF'!W28+'QTR CF'!X28+'QTR CF'!Y28 | I25: ='QTR CF'!Z28+'QTR CF'!AA28+'QTR CF'!AB28+'QTR CF'!AC28 | J25: ='QTR CF'!AD28+'QTR CF'!AE28+'QTR CF'!AF28+'QTR CF'!AG28
A26: ROU & Lease Liability, Net | B26: 29 | C26: -183 | D26: -102 | E26: 535 | F26: 0 | G26: ='QTR CF'!R29+'QTR CF'!S29+'QTR CF'!T29+'QTR CF'!U29 | H26: ='QTR CF'!V29+'QTR CF'!W29+'QTR CF'!X29+'QTR CF'!Y29 | I26: ='QTR CF'!Z29+'QTR CF'!AA29+'QTR CF'!AB29+'QTR CF'!AC29 | J26: ='QTR CF'!AD29+'QTR CF'!AE29+'QTR CF'!AF29+'QTR CF'!AG29
A27: Deferred Revenue | B27: 0 | C27: 189463 | D27: -12723 | E27: -9513 | F27: 255110 | G27: ='QTR CF'!R30+'QTR CF'!S30+'QTR CF'!T30+'QTR CF'!U30 | H27: ='QTR CF'!V30+'QTR CF'!W30+'QTR CF'!X30+'QTR CF'!Y30 | I27: ='QTR CF'!Z30+'QTR CF'!AA30+'QTR CF'!AB30+'QTR CF'!AC30 | J27: ='QTR CF'!AD30+'QTR CF'!AE30+'QTR CF'!AF30+'QTR CF'!AG30
A28: Net Change in Other Working Capital | B28: 0 | C28: 0 | D28: 0 | E28: 0 | F28: 2481 | G28: ='QTR CF'!R31+'QTR CF'!S31+'QTR CF'!T31+'QTR CF'!U31 | H28: ='QTR CF'!V31+'QTR CF'!W31+'QTR CF'!X31+'QTR CF'!Y31 | I28: ='QTR CF'!Z31+'QTR CF'!AA31+'QTR CF'!AB31+'QTR CF'!AC31 | J28: ='QTR CF'!AD31+'QTR CF'!AE31+'QTR CF'!AF31+'QTR CF'!AG31
A29: Cash Flow from Operations | B29: =SUM(B2:B28) | C29: =SUM(C2:C28) | D29: =SUM(D2:D28) | E29: =SUM(E2:E28) | F29: =SUM(F2:F28) | G29: =SUM(G2:G28) | H29: =SUM(H2:H28) | I29: =SUM(I2:I28) | ... L29: =SUM(L2:L28)
A30: Collections from Note Receivable | B30: 1886 | C30: 2592 | D30: 3233 | E30: 0 | F30: 0 | G30: ='QTR CF'!R33+'QTR CF'!S33+'QTR CF'!T33+'QTR CF'!U33 | H30: ='QTR CF'!V33+'QTR CF'!W33+'QTR CF'!X33+'QTR CF'!Y33 | I30: ='QTR CF'!Z33+'QTR CF'!AA33+'QTR CF'!AB33+'QTR CF'!AC33 | J30: ='QTR CF'!AD33+'QTR CF'!AE33+'QTR CF'!AF33+'QTR CF'!AG33
A31: Purchase of PP&E | B31: -3150 | C31: -8264 | D31: -17433 | E31: -23390 | F31: -36067 | G31: ='QTR CF'!R34+'QTR CF'!S34+'QTR CF'!T34+'QTR CF'!U34 | H31: ='QTR CF'!V34+'QTR CF'!W34+'QTR CF'!X34+'QTR CF'!Y34 | I31: ='QTR CF'!Z34+'QTR CF'!AA34+'QTR CF'!AB34+'QTR CF'!AC34 | J31: ='QTR CF'!AD34+'QTR CF'!AE34+'QTR CF'!AF34+'QTR CF'!AG34
A32: Purchase of Non-Marketable Equity Securities | B32: 0 | C32: 0 | D32: 0 | E32: -3000 | F32: -10000 | G32: ='QTR CF'!R35+'QTR CF'!S35+'QTR CF'!T35+'QTR CF'!U35 | H32: ='QTR CF'!V35+'QTR CF'!W35+'QTR CF'!X35+'QTR CF'!Y35 | I32: ='QTR CF'!Z35+'QTR CF'!AA35+'QTR CF'!AB35+'QTR CF'!AC35 | J32: ='QTR CF'!AD35+'QTR CF'!AE35+'QTR CF'!AF35+'QTR CF'!AG35
A33: Acquisition of Big Beverages | B33: 0 | C33: 0 | D33: 0 | E33: -75336 | F33: 0 | G33: ='QTR CF'!R36+'QTR CF'!S36+'QTR CF'!T36+'QTR CF'!U36 | H33: ='QTR CF'!V36+'QTR CF'!W36+'QTR CF'!X36+'QTR CF'!Y36 | I33: ='QTR CF'!Z36+'QTR CF'!AA36+'QTR CF'!AB36+'QTR CF'!AC36 | J33: ='QTR CF'!AD36+'QTR CF'!AE36+'QTR CF'!AF36+'QTR CF'!AG36
A34: Acquisitions, Net of Cash Acquired | B34: 0 | C34: 0 | D34: 0 | E34: 0 | F34: -1278769 | G34: ='QTR CF'!R37+'QTR CF'!S37+'QTR CF'!T37+'QTR CF'!U37 | H34: ='QTR CF'!V37+'QTR CF'!W37+'QTR CF'!X37+'QTR CF'!Y37 | I34: ='QTR CF'!Z37+'QTR CF'!AA37+'QTR CF'!AB37+'QTR CF'!AC37 | J34: ='QTR CF'!AD37+'QTR CF'!AE37+'QTR CF'!AF37+'QTR CF'!AG37
A35: Working Capital Estimate from Pepsi (Rockstar) | B35: 0 | C35: 0 | D35: 0 | E35: 0 | F35: 29156 | G35: ='QTR CF'!R38+'QTR CF'!S38+'QTR CF'!T38+'QTR CF'!U38 | H35: ='QTR CF'!V38+'QTR CF'!W38+'QTR CF'!X38+'QTR CF'!Y38 | I35: ='QTR CF'!Z38+'QTR CF'!AA38+'QTR CF'!AB38+'QTR CF'!AC38 | J35: ='QTR CF'!AD38+'QTR CF'!AE38+'QTR CF'!AF38+'QTR CF'!AG38
A36: Cash Flow from Investing | B36: =SUM(B30:B35) | C36: =SUM(C30:C35) | D36: =SUM(D30:D35) | E36: =SUM(E30:E35) | F36: =SUM(F30:F35) | G36: =SUM(G30:G35) | H36: =SUM(H30:H35) | I36: =SUM(I30:I35) | ... L36: =SUM(L30:L35)
A37: Finance Lease Payments | B37: -94 | C37: -63 | D37: -44 | E37: -61 | F37: 0 | G37: ='QTR CF'!R40+'QTR CF'!S40+'QTR CF'!T40+'QTR CF'!U40 | H37: ='QTR CF'!V40+'QTR CF'!W40+'QTR CF'!X40+'QTR CF'!Y40 | I37: ='QTR CF'!Z40+'QTR CF'!AA40+'QTR CF'!AB40+'QTR CF'!AC40 | J37: ='QTR CF'!AD40+'QTR CF'!AE40+'QTR CF'!AF40+'QTR CF'!AG40
A38: Proceeds from Exercise of Stock Options | B38: 3720 | C38: 3683 | D38: 2285 | E38: 3856 | F38: 0 | G38: ='QTR CF'!R41+'QTR CF'!S41+'QTR CF'!T41+'QTR CF'!U41 | H38: ='QTR CF'!V41+'QTR CF'!W41+'QTR CF'!X41+'QTR CF'!Y41 | I38: ='QTR CF'!Z41+'QTR CF'!AA41+'QTR CF'!AB41+'QTR CF'!AC41 | J38: ='QTR CF'!AD41+'QTR CF'!AE41+'QTR CF'!AF41+'QTR CF'!AG41
A39: Proceeds from Issuance of Common Stock | B39: 67769 | C39: 0 | D39: 0 | E39: 0 | F39: 0 | G39: ='QTR CF'!R42+'QTR CF'!S42+'QTR CF'!T42+'QTR CF'!U42 | H39: ='QTR CF'!V42+'QTR CF'!W42+'QTR CF'!X42+'QTR CF'!Y42 | I39: ='QTR CF'!Z42+'QTR CF'!AA42+'QTR CF'!AB42+'QTR CF'!AC42 | J39: ='QTR CF'!AD42+'QTR CF'!AE42+'QTR CF'!AF42+'QTR CF'!AG42
A40: Proceeds from Issuance of Preferred Stock | B40: 0 | C40: 542018 | D40: 0 | E40: 0 | F40: 0 | G40: ='QTR CF'!R43+'QTR CF'!S43+'QTR CF'!T43+'QTR CF'!U43 | H40: ='QTR CF'!V43+'QTR CF'!W43+'QTR CF'!X43+'QTR CF'!Y43 | I40: ='QTR CF'!Z43+'QTR CF'!AA43+'QTR CF'!AB43+'QTR CF'!AC43 | J40: ='QTR CF'!AD43+'QTR CF'!AE43+'QTR CF'!AF43+'QTR CF'!AG43
A41: Preferred Dividends | B41: 0 | C41: -11526 | D41: -27462 | E41: -27500 | F41: -37608 | G41: ='QTR CF'!R44+'QTR CF'!S44+'QTR CF'!T44+'QTR CF'!U44 | H41: ='QTR CF'!V44+'QTR CF'!W44+'QTR CF'!X44+'QTR CF'!Y44 | I41: ='QTR CF'!Z44+'QTR CF'!AA44+'QTR CF'!AB44+'QTR CF'!AC44 | J41: ='QTR CF'!AD44+'QTR CF'!AE44+'QTR CF'!AF44+'QTR CF'!AG44
A42: Share Repurchases | B42: 0 | C42: 0 | D42: 0 | E42: -2261 | F42: -45504 | G42: ='QTR CF'!R45+'QTR CF'!S45+'QTR CF'!T45+'QTR CF'!U45 | H42: ='QTR CF'!V45+'QTR CF'!W45+'QTR CF'!X45+'QTR CF'!Y45 | I42: ='QTR CF'!Z45+'QTR CF'!AA45+'QTR CF'!AB45+'QTR CF'!AC45 | J42: ='QTR CF'!AD45+'QTR CF'!AE45+'QTR CF'!AF45+'QTR CF'!AG45
...

Sheet YTD P&L
B1: Q1 FY2022 | C1: Q2 FY2022 | D1: Q3 FY2022 | E1: Q1 FY2023 | F1: Q2 FY2023 | G1: Q3 FY2023 | H1: Q1 FY2024 | I1: Q2 FY2024 | J1: Q3 FY2024 | K1: Q1 FY2025 | L1: Q2 FY2025 | M1: Q3 FY2025
A2: Net Sales / Revenue | B2: 133388 | C2: 287408 | D2: 475640 | E2: 259939 | F2: 585822 | G2: 970579 | H2: 355708 | I2: 757685 | J2: 1023433 | K2: 329276 | L2: 1068535 | M2: 1793641
A3: COGS | B3: -79494 | C3: -174195 | D3: -283778 | E3: -146121 | F3: -313010 | G3: -503685 | H3: -173501 | I3: -366380 | J3: -509899 | K3: -156903 | L3: -515311 | M3: -868138
A4: Gross Profit (Loss) | B4: =B2+B3 | C4: =C2+C3 | D4: =D2+D3 | E4: =E2+E3 | F4: =F2+F3 | G4: =G2+G3 | H4: =H2+H3 | I4: =I2+I3 | ... M4: =M2+M3
A5: SG&A | B5: -43778 | C5: -90667 | D5: -316917 | E5: -68905 | F5: -163086 | G5: -259471 | H5: -99017 | I5: -213867 | J5: -339310 | K5: -120342 | L5: -358228 | M5: -563799
A6: Distributor Termination Fees | B6: 0 | C6: 0 | D6: 0 | E6: 0 | F6: 0 | G6: 0 | H6: 0 | I6: 0 | J6: 0 | K6: 0 | L6: 0 | M6: -246707
A7: Income (Loss) from Operations | B7: =B4+SUM(B5:B6) | C7: =C4+SUM(C5:C6) | D7: =D4+SUM(D5:D6) | E7: =E4+SUM(E5:E6) | F7: =F4+SUM(F5:F6) | G7: =G4+SUM(G5:G6) | H7: =H4+SUM(H5:H6) | I7: =I4+SUM(I5:I6) | ... M7: =M4+SUM(M5:M6)
A8: Interest Income (Expense) | B8: 76 | C8: 129 | D8: 1579 | E8: 4969 | F8: 10542 | G8: 17767 | H8: 9640 | I8: 20287 | J8: 31399 | K8: 7846 | L8: -6196 | M8: -19592
A9: Foreign Currency Gain (Loss) | B9: -162 | C9: -676 | D9: -930 | E9: -118 | F9: -1049 | G9: -1226 | H9: -369 | I9: -633 | J9: -356 | K9: 0 | L9: 0 | M9: 0
A10: Other Income (Expense) | B10: 0 | C10: 0 | D10: 0 | E10: 0 | F10: 0 | G10: 0 | H10: 0 | I10: 0 | J10: 0 | K10: 1116 | L10: 1658 | M10: 7022
A11: Pre-Tax Income (Loss) | B11: =B7+SUM(B8:B10) | C11: =C7+SUM(C8:C10) | D11: =D7+SUM(D8:D10) | E11: =E7+SUM(E8:E10) | F11: =F7+SUM(F8:F10) | G11: =G7+SUM(G8:G10) | H11: =H7+SUM(H8:H10) | I11: =I7+SUM(I8:I10) | ... M11: =M7+SUM(M8:M10)
A12: Income Tax (Expense) Benefit | B12: -3351 | C12: -6161 | D12: -41653 | E12: -8537 | F12: -26483 | G12: -47279 | H12: -14650 | I12: -39498 | J12: -41317 | K12: -16574 | L12: -46184 | M12: -19167
A13: Net Income (Loss) | B13: =B11+B12 | C13: =C11+C12 | D13: =D11+D12 | E13: =E11+E12 | F13: =F11+F12 | G13: =G11+G12 | H13: =H11+H12 | I13: =I11+I12 | ... M13: =M11+M12
A14: Preferred Dividends | B14: 0 | C14: 0 | D14: -4596 | E14: -6781 | F14: -13637 | G14: -20512 | H14: -6837 | I14: -13675 | J14: -20588 | K14: -6781 | L14: -13632 | M14: -23289
A15: Income Allocated to Participating Preferred | B15: 0 | C15: 0 | D15: 0 | E15: 0 | F15: 6727 | G15: 13263 | H15: 6128 | I15: 12417 | J15: 12357 | K15: 3219 | L15: 10703 | M15: 5272
A16: Net Income (Loss) Attributable to Common Shareholders | B16: 6679 | C16: 15838 | D16: -170655 | E16: 34446 | F16: 72372 | G16: 142910 | H16: 64846 | I16: 131502 | J16: 131005 | K16: 34419 | L16: 119939 | M16: 54699

Sheet YTD BS
B1: Q4 FY2022 | C1: Q1 FY2023 | D1: Q2 FY2023 | E1: Q3 FY2023 | F1: Q4 FY2023 | G1: Q1 FY2024 | H1: Q2 FY2024 | I1: Q3 FY2024 | J1: Q4 FY2024 | K1: Q1 FY2025 | L1: Q2 FY2025 | M1: Q3 FY2025
A2: Cash & Cash Equivalents | B2: 614159 | C2: 595476 | D2: 681054 | E2: 760022 | F2: 755981 | G2: 879498 | H2: 903210 | I2: 903748 | J2: 890190 | K2: 977285 | L2: 615233 | M2: 805955
A3: Restricted Cash | B3: 38768 | C3: 38105 | D3: 0 | E3: 0 | F3: 0 | G3: 0 | H3: 0 | I3: 0 | J3: 0 | K3: 0 | L3: 0 | M3: 126508
A4: Accounts Receivable | B4: 63311 | C4: 172032 | D4: 197811 | E4: 215243 | F4: 183703 | G4: 200117 | H4: 262920 | I4: 208774 | J4: 270342 | K4: 256424 | L4: 490389 | M4: 513682
A5: Note Receivable - Current | B5: 2979 | C5: 3587 | D5: 3323 | E5: 3309 | F5: 2318 | G5: 2259 | H5: 1166 | I5: 1025 | J5: 0 | K5: 0 | L5: 0 | M5: 0
A6: Inventories | B6: 173289 | C6: 154280 | D6: 152545 | E6: 198704 | F6: 229275 | G6: 197504 | H6: 180669 | I6: 197572 | J6: 131165 | K6: 141159 | L6: 230046 | M6: 282514
A7: Prepaid Expenses | B7: 11341 | C7: 15507 | D7: 23398 | E7: 23747 | F7: 19503 | G7: 21523 | H7: 22900 | I7: 38227 | J7: 18759 | K7: 22464 | L7: 41420 | M7: 163395
A8: Deferred Other Costs - Current | B8: 14124 | C8: 14124 | D8: 14124 | E8: 14124 | F8: 14124 | G8: 14124 | H8: 14124 | I8: 14124 | J8: 14124 | K8: 14124 | L8: 14124 | M8: 49520
A9: Total Current Assets | B9: =SUM(B2:B8) | C9: =SUM(C2:C8) | D9: =SUM(D2:D8) | E9: =SUM(E2:E8) | F9: =SUM(F2:F8) | G9: =SUM(G2:G8) | H9: =SUM(H2:H8) | I9: =SUM(I2:I8) | ... M9: =SUM(M2:M8)
A10: Note Receivable - Non-Current | B10: 3574 | C10: 0 | D10: 0 | E10: 0 | F10: 0 | G10: 0 | H10: 0 | I10: 0 | J10: 0 | K10: 0 | L10: 0 | M10: 0
A11: Net PP&E | B11: 10185 | C11: 12054 | D11: 15892 | E11: 21061 | F11: 24868 | G11: 28350 | H11: 36282 | I11: 38370 | J11: 55602 | K11: 58698 | L11: 72516 | M11: 80925
A12: ROU Assets - Operating - Non-Current | B12: 972 | C12: 931 | D12: 756 | E12: 1152 | F12: 1957 | G12: 1688 | H12: 1507 | I12: 5506 | J12: 21606 | K12: 20866 | L12: 0 | M12: 0
A13: Intangible Assets | B13: 12254 | C13: 12359 | D13: 12211 | E13: 11772 | F13: 12139 | G13: 11741 | H13: 11491 | I13: 11877 | J13: 12213 | K13: 12444 | L13: 1222115 | M13: 1397819
A14: Goodwill | B14: 13679 | C14: 13949 | D14: 13937 | E14: 13588 | F14: 14173 | G14: 13866 | H14: 13730 | I14: 14360 | J14: 71582 | K14: 72128 | L14: 802234 | M14: 914957
A15: Deferred Other Costs - Non-Current | B15: 262462 | C15: 258931 | D15: 255400 | E15: 251869 | F15: 248338 | G15: 244807 | H15: 241276 | I15: 237746 | J15: 234215 | K15: 230684 | L15: 227153 | M15: 784214
A16: Deferred Tax Assets | B16: 501 | C16: 482 | D16: 28373 | E16: 30614 | F16: 29518 | G16: 22437 | H16: 22727 | I16: 24186 | J16: 38699 | K16: 38525 | L16: 43158 | M16: 110410
A17: ROU Assets - Finance - Non-Current | B17: 208 | C17: 191 | D17: 171 | E17: 148 | F17: 208 | G17: 263 | H17: 233 | I17: 214 | J17: 0 | K17: 0 | L17: 0 | M17: 0
A18: Other Non-Current Assets | B18: 263 | C18: 263 | D18: 254 | E18: 265 | F18: 291 | G18: 7963 | H18: 6653 | I18: 8594 | J18: 8384 | K18: 14717 | L18: 36755 | M18: 35809
A19: Total Assets | B19: =B9+SUM(B10:B18) | C19: =C9+SUM(C10:C18) | D19: =D9+SUM(D10:D18) | E19: =E9+SUM(E10:E18) | F19: =F9+SUM(F10:F18) | G19: =G9+SUM(G10:G18) | H19: =H9+SUM(H10:H18) | I19: =I9+SUM(I10:I18) | ... M19: =M9+SUM(M10:M18)
A20: Accounts Payable | B20: 107340 | C20: 107112 | D20: 94313 | E20: 121088 | F20: 42840 | G20: 40196 | H20: 47423 | I20: 30938 | J20: 41287 | K20: 61052 | L20: 120962 | M20: 97794
A21: Accrued Expenses | B21: 0 | C21: 0 | D21: 0 | E21: 0 | F21: 62120 | G21: 63871 | H21: 79633 | I21: 73024 | J21: 148780 | K21: 152046 | L21: 225859 | M21: 311768
A22: Income Taxes Payable | B22: 0 | C22: 0 | D22: 58798 | E22: 58855 | F22: 50424 | G22: 58619 | H22: 5374 | I22: 739 | J22: 10834 | K22: 26206 | L22: 21765 | M22: 49590
A23: Accrued Distributor Termination Fees | B23: 3986 | C23: 1063 | D23: 0 | E23: 0 | F23: 0 | G23: 0 | H23: 0 | I23: 0 | J23: 0 | K23: 0 | L23: 0 | M23: 252953
A24: Accrued Promotional Allowance | B24: 35977 | C24: 68225 | D24: 98933 | E24: 136557 | F24: 99787 | G24: 129201 | H24: 156479 | I24: 158810 | J24: 135948 | K24: 151327 | L24: 200169 | M24: 234068
A25: Lease Liability - Operating - Current | B25: 661 | C25: 605 | D25: 505 | E25: 628 | F25: 980 | G25: 821 | H25: 729 | I25: 1358 | J25: 3265 | K25: 3550 | L25: 0 | M25: 0
A26: Lease Liability - Finance - Current | B26: 70 | C26: 69 | D26: 67 | E26: 63 | F26: 59 | G26: 61 | H26: 61 | I26: 99 | J26: 0 | K26: 0 | L26: 0 | M26: 0
A27: Contingent Consideration - Current | B27: 0 | C27: 0 | D27: 0 | E27: 0 | F27: 0 | G27: 0 | H27: 0 | I27: 0 | J27: 0 | K27: 0 | L27: 25000 | M27: 25000
A28: Deferred Revenue - Current | B28: 9675 | C28: 9563 | D28: 9500 | E28: 9500 | F28: 9513 | G28: 9513 | H28: 9513 | I28: 9513 | J28: 9513 | K28: 9513 | L28: 16071 | M28: 25557
A29: Other Current Liabilities | B29: 3586 | C29: 5094 | D29: 7109 | E29: 8826 | F29: 10890 | G29: 12987 | H29: 13772 | I29: 14979 | J29: 15908 | K29: 14160 | L29: 49949 | M29: 32258
A30: Total Current Liabilities | B30: =SUM(B20:B29) | C30: =SUM(C20:C29) | D30: =SUM(D20:D29) | E30: =SUM(E20:E29) | F30: =SUM(F20:F29) | G30: =SUM(G20:G29) | H30: =SUM(H20:H29) | I30: =SUM(I20:I29) | ... M30: =SUM(M20:M29)
A31: Lease Liability - Operating - Non-Current | B31: 326 | C31: 336 | D31: 249 | E31: 512 | F31: 955 | G31: 850 | H31: 762 | I31: 4193 | J31: 16674 | K31: 16152 | L31: 0 | M31: 0
A32: Lease Liability - Finance - Non-Current | B32: 162 | C32: 156 | D32: 147 | E32: 135 | F32: 193 | G32: 245 | H32: 228 | I32: 189 | J32: 0 | K32: 0 | L32: 0 | M32: 0
A33: Deferred Tax Liability | B33: 15919 | C33: 19250 | D33: 2333 | E33: 2249 | F33: 2880 | G33: 2248 | H33: 2201 | I33: 2275 | J33: 0 | K33: 0 | L33: 0 | M33: 0
A34: Long-Term Debt | B34: 0 | C34: 0 | D34: 0 | E34: 0 | F34: 0 | G34: 0 | H34: 0 | I34: 0 | J34: 0 | K34: 0 | L34: 862917 | M34: 861472
A35: Deferred Revenue - Non-Current | B35: 179788 | C35: 175275 | D35: 171745 | E35: 169370 | F35: 167227 | G35: 164849 | H35: 162471 | I35: 160092 | J35: 157714 | K35: 155336 | L35: 156135 | M35: 387432
A36: Other Non-Current Liabilities | B36: 0 | C36: 0 | D36: 0 | E36: 0 | F36: 0 | G36: 0 | H36: 0 | I36: 0 | J36: 2541 | K36: 2574 | L36: 25002 | M36: 24431
A37: Total Liabilities | B37: =B30+SUM(B31:B36) | C37: =C30+SUM(C31:C36) | D37: =D30+SUM(D31:D36) | E37: =E30+SUM(E31:E36) | F37: =F30+SUM(F31:F36) | G37: =G30+SUM(G31:G36) | H37: =H30+SUM(H31:H36) | I37: =I30+SUM(I31:I36) | ... M37: =M30+SUM(M31:M36)
A38: Convertible Preferred Stock | B38: 824488 | C38: 824488 | D38: 824488 | E38: 824488 | F38: 824488 | G38: 824488 | H38: 824488 | I38: 824488 | J38: 824488 | K38: 824488 | L38: 824488 | M38: 1760275
A39: Common Stock | B39: 76 | C39: 77 | D39: 77 | E39: 77 | F39: 77 | G39: 78 | H39: 78 | I39: 79 | J39: 79 | K39: 79 | L39: 101 | M39: 101
A40: Treasury Stock | B40: 0 | C40: 0 | D40: 0 | E40: 0 | F40: 0 | G40: 0 | H40: 0 | I40: 0 | J40: 0 | K40: 0 | L40: 0 | M40: 0
...

Sheet YTD CF
B1: Q1 FY2022 | C1: Q2 FY2022 | D1: Q3 FY2022 | E1: Q1 FY2023 | F1: Q2 FY2023 | G1: Q3 FY2023 | H1: Q1 FY2024 | I1: Q2 FY2024 | J1: Q3 FY2024 | K1: Q1 FY2025 | L1: Q2 FY2025 | M1: Q3 FY2025
A2: Net Income (Loss) | B2: 6679 | C2: 15838 | D2: -166059 | E2: 41227 | F2: 92736 | G2: 176685 | H2: 77811 | I2: 157594 | J2: 163950 | K2: 44419 | L2: 144274 | M2: 83260
A3: Depreciation | B3: 245 | C3: 556 | D3: 952 | E3: 404 | F3: 953 | G3: 1676 | H3: 0 | I3: 0 | J3: 0 | K3: 0 | L3: 0 | M3: 0
A4: Amortization | B4: 141 | C4: 275 | D4: 402 | E4: 145 | F4: 294 | G4: 445 | H4: 0 | I4: 0 | J4: 0 | K4: 0 | L4: 0 | M4: 0
A5: Impairment of Intangibles | B5: 0 | C5: 0 | D5: 2379 | E5: 0 | F5: 0 | G5: 0 | H5: 0 | I5: 0 | J5: 0 | K5: 0 | L5: 0 | M5: 0
A6: Depreciation & Amortization | B6: 0 | C6: 0 | D6: 0 | E6: 0 | F6: 0 | G6: 0 | H6: 1229 | I6: 2648 | J6: 4888 | K6: 2611 | L6: 11730 | M6: 20516
A7: Allowance for Credit Losses | B7: 455 | C7: 466 | D7: 705 | E7: 837 | F7: 1088 | G7: 1880 | H7: 2250 | I7: 4072 | J7: 4279 | K7: 2077 | L7: 5529 | M7: 3226
A8: Amortization of Deferred Other Costs | B8: 0 | C8: 0 | D8: 2354 | E8: 3531 | F8: 7062 | G8: 10593 | H8: 3531 | I8: 7062 | J8: 10593 | K8: 3531 | L8: 7062 | M8: 13391
A9: Inventory Write-Down | B9: 2596 | C9: 331 | D9: 1078 | E9: 1672 | F9: -3888 | G9: 2677 | H9: 2386 | I9: 11554 | J9: 17118 | K9: 5337 | L9: 15262 | M9: 22313
A10: Gain (Loss) on Disposal of PP&E | B10: 0 | C10: 0 | D10: 0 | E10: 0 | F10: 191 | G10: 195 | H10: -8 | I10: 31 | J10: 126 | K10: 0 | L10: 0 | M10: 0
A11: Stock-Based Compensation | B11: 4310 | C11: 8517 | D11: 14780 | E11: 5507 | F11: 11242 | G11: 16221 | H11: 3563 | I11: 8309 | J11: 13685 | K11: 5029 | L11: 11463 | M11: 18847
A12: (Benefit) Provision for Deferred Income Taxes | B12: 2561 | C12: 1072 | D12: 31329 | E12: 2873 | F12: -41044 | G12: -44303 | H12: 6450 | I12: 6112 | J12: 4727 | K12: 269 | L12: -4161 | M12: -71408
A13: Foreign Currency Gain (Loss) | B13: 85 | C13: 602 | D13: 1007 | E13: 69 | F13: 206 | G13: 258 | H13: 369 | I13: 633 | J13: 356 | K13: 0 | L13: 0 | M13: 0
... A31: Net Change in Other Working Capital | B31: 0 | C31: 488 | D31: 0 | E31: 0 | F31: 0 | G31: 0 | H31: 0 | I31: 0 | J31: 0 | K31: 148 | L31: -1210 | M31: -1786
A32: Cash Flow from Operations | B32: =SUM(B2:B31) | C32: =SUM(C2:C31) | D32: =SUM(D2:D31) | E32: =SUM(E2:E31) | F32: =SUM(F2:F31) | G32: =SUM(G2:G31) | H32: =SUM(H2:H31) | I32: =SUM(I2:I31) | ... M32: =SUM(M2:M31)
A33: Collections from Note Receivable | B33: 0 | C33: 2592 | D33: 2592 | E33: 3233 | F33: 3233 | G33: 3233 | H33: 0 | I33: 0 | J33: 0 | K33: 0 | L33: 0 | M33: 0
A34: Purchase of PP&E | B34: -742 | C34: -2456 | D34: -3477 | E34: -2253 | F34: -6810 | G34: -12687 | H34: -4525 | I34: -13739 | J34: -17983 | K34: -6944 | L34: -15194 | M34: -25539
A35: Purchase of Non-Marketable Equity Securities | B35: 0 | C35: 0 | D35: 0 | E35: 0 | F35: 0 | G35: 0 | H35: 0 | I35: 0 | J35: -3000 | K35: 0 | L35: -5000 | M35: -5000
A36: Acquisition of Big Beverages | B36: 0 | C36: 0 | D36: 0 | E36: 0 | F36: 0 | G36: 0 | H36: 0 | I36: 0 | J36: 0 | K36: 0 | L36: 0 | M36: 0
A37: Acquisitions, Net of Cash Acquired | B37: 0 | C37: 0 | D37: 0 | E37: 0 | F37: 0 | G37: 0 | H37: 0 | I37: 0 | J37: 0 | K37: 0 | L37: -1256351 | M37: -1278769
A38: Working Capital Estimate from Pepsi (Rockstar) | B38: 0 | C38: 0 | D38: 0 | E38: 0 | F38: 0 | G38: 0 | H38: 0 | I38: 0 | J38: 0 | K38: 0 | L38: 0 | M38: 30617
A39: Cash Flow from Investing | B39: =SUM(B33:B38) | C39: =SUM(C33:C38) | D39: =SUM(D33:D38) | E39: =SUM(E33:E38) | F39: =SUM(F33:F38) | G39: =SUM(G33:G38) | H39: =SUM(H33:H38) | I39: =SUM(I33:I38) | ... M39: =SUM(M33:M38)
A40: Finance Lease Payments | B40: -20 | C40: -37 | D40: -49 | E40: -11 | F40: -22 | G40: -33 | H40: -15 | I40: -30 | J40: -46 | K40: 0 | L40: 0 | M40: 0
A41: Proceeds from Exercise of Stock Options | B41: 810 | C41: 1260 | D41: 3104 | E41: 478 | F41: 707 | G41: 1603 | H41: 967 | I41: 1147 | J41: 3832 | K41: 0 | L41: 0 | M41: 0
A42: Proceeds from Issuance of Common Stock | B42: 0 | C42: 0 | D42: 0 | E42: 0 | F42: 0 | G42: 0 | H42: 0 | I42: 0 | J42: 0 | K42: 0 | L42: 0 | M42: 0
A43: Proceeds from Issuance of Preferred Stock | B43: 0 | C43: 0 | D43: 542018 | E43: 0 | F43: 0 | G43: 0 | H43: 0 | I43: 0 | J43: 0 | K43: 0 | L43: 0 | M43: 0
A44: Preferred Dividends | B44: 0 | C44: 0 | D44: -4596 | E44: -6781 | F44: -13637 | G44: -20512 | H44: -6837 | I44: -13675 | J44: -20588 | K44: -6781 | L44: -13632 | M44: -23301
A45: Share Repurchases | B45: 0 | C45: 0 | D45: 0 | E45: 0 | F45: 0 | G45: 0 | H45: 0 | I45: 0 | J45: -1658 | K45: -1932 | L45: -2811 | M45: -3259
A46: Proceeds from Issuance of Long-Term Debt | B46: 0 | C46: 0 | D46: 0 | E46: 0 | F46: 0 | G46: 0 | H46: 0 | I46: 0 | J46: 0 | K46: 0 | L46: 900000 | M46: 900000
A47: Repayments of Long-Term Debt | B47: 0 | C47: 0 | D47: 0 | E47: 0 | F47: 0 | G47: 0 | H47: 0 | I47: 0 | J47: 0 | K47: 0 | L47: 0 | M47: -2250
A48: Debt Issuance Fees | B48: 0 | C48: 0 | D48: 0 | E48: 0 | F48: 0 | G48: 0 | H48: 0 | I48: 0 | J48: 0 | K48: -2195 | L48: -31581 | M48: -31581
A49: Other Financing Activities | B49: 0 | C49: 0 | D49: 0 | E49: 0 | F49: 0 | G49: 0 | H49: 0 | I49: 0 | J49: 0 | K49: 321 | L49: 319 | M49: 301
A50: Cash Flow from Financing | B50: =SUM(B40:B49) | C50: =SUM(C40:C49) | D50: =SUM(D40:D49) | E50: =SUM(E40:E49) | F50: =SUM(F40:F49) | G50: =SUM(G40:G49) | H50: =SUM(H40:H49) | I50: =SUM(I40:I49) | ... M50: =SUM(M40:M49)
A51: FX Effect on Cash | B51: 104 | C51: 121 | D51: 158 | E51: -181 | F51: -555 | G51: -555 | H51: -722 | I51: -766 | J51: -16 | K51: 1259 | L51: 2214 | M51: 2174
A52: Net Change in Cash | B52: =B32+B39+B50+B51 | C52: =C32+C39+C50+C51 | D52: =D32+D39+D50+D51 | E52: =E32+E39+E50+E51 | F52: =F32+F39+F50+F51 | G52: =G32+G39+G50+G51 | H52: =H32+H39+H50+H51 | I52: =I32+I39+I50+I51 | ... M52: =M32+M39+M50+M51

Sheet QTR P&L
B1: Q1 FY2022 | C1: Q2 FY2022 | D1: Q3 FY2022 | E1: Q4 FY2022 | F1: Q1 FY2023 | G1: Q2 FY2023 | H1: Q3 FY2023 | I1: Q4 FY2023 | J1: Q1 FY2024 | K1: Q2 FY2024 | L1: Q3 FY2024 | M1: Q4 FY2024 | N1: Q1 FY2025 | O1: Q2 FY2025 | P1: Q3 FY2025 | Q1: Q4 FY2025 | R1: Q1 FY2026E | S1: Q2 FY2026E | T1: Q3 FY2026E | U1: Q4 FY2026E | V1: Q1 FY2027E | W1: Q2 FY2027E | X1: Q3 FY2027E | Y1: Q4 FY2027E | Z1: Q1 FY2028E | AA1: Q2 FY2028E | AB1: Q3 FY2028E | AC1: Q4 FY2028E | AD1: Q1 FY2029E | AE1: Q2 FY2029E | AF1: Q3 FY2029E | AG1: Q4 FY2029E
A2: Net Sales / Revenue | B2: ='YTD P&L'!B2 | C2: ='YTD P&L'!C2-'YTD P&L'!B2 | D2: ='YTD P&L'!D2-'YTD P&L'!C2 | E2: ='ANNL P&L'!C2-'YTD P&L'!D2 | F2: ='YTD P&L'!E2 | G2: ='YTD P&L'!F2-'YTD P&L'!E2 | H2: ='YTD P&L'!G2-'YTD P&L'!F2 | I2: ='ANNL P&L'!D2-'YTD P&L'!G2 | J2: ='YTD P&L'!H2 | K2: ='YTD P&L'!I2-'YTD P&L'!H2 | L2: ='YTD P&L'!J2-'YTD P&L'!I2 | M2: ='ANNL P&L'!E2-'YTD P&L'!J2 | N2: ='YTD P&L'!K2 | O2: ='YTD P&L'!L2-'YTD P&L'!K2 | P2: ='YTD P&L'!M2-'YTD P&L'!L2 | Q2: ='ANNL P&L'!F2-'YTD P&L'!M2 | R2: ='QTR P&L'!N2*(1+'IS DRIVERS'!R2) | S2: ='QTR P&L'!O2*(1+'IS DRIVERS'!S2) | T2: ='QTR P&L'!P2*(1+'IS DRIVERS'!T2) | U2: ='QTR P&L'!Q2*(1+'IS DRIVERS'!U2) | V2: ='QTR P&L'!R2*(1+'IS DRIVERS'!V2) | W2: ='QTR P&L'!S2*(1+'IS DRIVERS'!W2) | X2: ='QTR P&L'!T2*(1+'IS DRIVERS'!X2) | Y2: ='QTR P&L'!U2*(1+'IS DRIVERS'!Y2) | ... AG2: ='QTR P&L'!AC2*(1+'IS DRIVERS'!AG2)
A3: COGS | B3: ='YTD P&L'!B3 | C3: ='YTD P&L'!C3-'YTD P&L'!B3 | D3: ='YTD P&L'!D3-'YTD P&L'!C3 | E3: ='ANNL P&L'!C3-'YTD P&L'!D3 | F3: ='YTD P&L'!E3 | G3: ='YTD P&L'!F3-'YTD P&L'!E3 | H3: ='YTD P&L'!G3-'YTD P&L'!F3 | I3: ='ANNL P&L'!D3-'YTD P&L'!G3 | J3: ='YTD P&L'!H3 | K3: ='YTD P&L'!I3-'YTD P&L'!H3 | L3: ='YTD P&L'!J3-'YTD P&L'!I3 | M3: ='ANNL P&L'!E3-'YTD P&L'!J3 | N3: ='YTD P&L'!K3 | O3: ='YTD P&L'!L3-'YTD P&L'!K3 | P3: ='YTD P&L'!M3-'YTD P&L'!L3 | Q3: ='ANNL P&L'!F3-'YTD P&L'!M3 | R3: ='QTR P&L'!R2*'IS DRIVERS'!R3 | S3: ='QTR P&L'!S2*'IS DRIVERS'!S3 | T3: ='QTR P&L'!T2*'IS DRIVERS'!T3 | U3: ='QTR P&L'!U2*'IS DRIVERS'!U3 | V3: ='QTR P&L'!V2*'IS DRIVERS'!V3 | W3: ='QTR P&L'!W2*'IS DRIVERS'!W3 | X3: ='QTR P&L'!X2*'IS DRIVERS'!X3 | Y3: ='QTR P&L'!Y2*'IS DRIVERS'!Y3 | ... AG3: ='QTR P&L'!AG2*'IS DRIVERS'!AG3
A4: Gross Profit (Loss) | B4: ='YTD P&L'!B4 | C4: ='YTD P&L'!C4-'YTD P&L'!B4 | D4: ='YTD P&L'!D4-'YTD P&L'!C4 | E4: ='ANNL P&L'!C4-'YTD P&L'!D4 | F4: ='YTD P&L'!E4 | G4: ='YTD P&L'!F4-'YTD P&L'!E4 | H4: ='YTD P&L'!G4-'YTD P&L'!F4 | I4: ='ANNL P&L'!D4-'YTD P&L'!G4 | J4: ='YTD P&L'!H4 | K4: ='YTD P&L'!I4-'YTD P&L'!H4 | L4: ='YTD P&L'!J4-'YTD P&L'!I4 | M4: ='ANNL P&L'!E4-'YTD P&L'!J4 | N4: ='YTD P&L'!K4 | O4: ='YTD P&L'!L4-'YTD P&L'!K4 | P4: ='YTD P&L'!M4-'YTD P&L'!L4 | Q4: ='ANNL P&L'!F4-'YTD P&L'!M4 | R4: =R2+R3 | S4: =S2+S3 | T4: =T2+T3 | U4: =U2+U3 | V4: =V2+V3 | W4: =W2+W3 | X4: =X2+X3 | Y4: =Y2+Y3 | ... AG4: =AG2+AG3
A5: SG&A | B5: ='YTD P&L'!B5 | C5: ='YTD P&L'!C5-'YTD P&L'!B5 | D5: ='YTD P&L'!D5-'YTD P&L'!C5 | E5: ='ANNL P&L'!C5-'YTD P&L'!D5 | F5: ='YTD P&L'!E5 | G5: ='YTD P&L'!F5-'YTD P&L'!E5 | H5: ='YTD P&L'!G5-'YTD P&L'!F5 | I5: ='ANNL P&L'!D5-'YTD P&L'!G5 | J5: ='YTD P&L'!H5 | K5: ='YTD P&L'!I5-'YTD P&L'!H5 | L5: ='YTD P&L'!J5-'YTD P&L'!I5 | M5: ='ANNL P&L'!E5-'YTD P&L'!J5 | N5: ='YTD P&L'!K5 | O5: ='YTD P&L'!L5-'YTD P&L'!K5 | P5: ='YTD P&L'!M5-'YTD P&L'!L5 | Q5: ='ANNL P&L'!F5-'YTD P&L'!M5 | R5: ='QTR P&L'!R2*'IS DRIVERS'!R4 | S5: ='QTR P&L'!S2*'IS DRIVERS'!S4 | T5: ='QTR P&L'!T2*'IS DRIVERS'!T4 | U5: ='QTR P&L'!U2*'IS DRIVERS'!U4 | V5: ='QTR P&L'!V2*'IS DRIVERS'!V4 | W5: ='QTR P&L'!W2*'IS DRIVERS'!W4 | X5: ='QTR P&L'!X2*'IS DRIVERS'!X4 | Y5: ='QTR P&L'!Y2*'IS DRIVERS'!Y4 | ... AG5: ='QTR P&L'!AG2*'IS DRIVERS'!AG4
A6: Distributor Termination Fees | B6: ='YTD P&L'!B6 | C6: ='YTD P&L'!C6-'YTD P&L'!B6 | D6: ='YTD P&L'!D6-'YTD P&L'!C6 | E6: ='ANNL P&L'!C6-'YTD P&L'!D6 | F6: ='YTD P&L'!E6 | G6: ='YTD P&L'!F6-'YTD P&L'!E6 | H6: ='YTD P&L'!G6-'YTD P&L'!F6 | I6: ='ANNL P&L'!D6-'YTD P&L'!G6 | J6: ='YTD P&L'!H6 | K6: ='YTD P&L'!I6-'YTD P&L'!H6 | L6: ='YTD P&L'!J6-'YTD P&L'!I6 | M6: ='ANNL P&L'!E6-'YTD P&L'!J6 | N6: ='YTD P&L'!K6 | O6: ='YTD P&L'!L6-'YTD P&L'!K6 | P6: ='YTD P&L'!M6-'YTD P&L'!L6 | Q6: ='ANNL P&L'!F6-'YTD P&L'!M6 | R6: ='IS DRIVERS'!R5 | S6: ='IS DRIVERS'!S5 | T6: ='IS DRIVERS'!T5 | U6: ='IS DRIVERS'!U5 | V6: ='IS DRIVERS'!V5 | W6: ='IS DRIVERS'!W5 | X6: ='IS DRIVERS'!X5 | Y6: ='IS DRIVERS'!Y5 | ... AG6: ='IS DRIVERS'!AG5
A7: Income (Loss) from Operations | B7: ='YTD P&L'!B7 | C7: ='YTD P&L'!C7-'YTD P&L'!B7 | D7: ='YTD P&L'!D7-'YTD P&L'!C7 | E7: ='ANNL P&L'!C7-'YTD P&L'!D7 | F7: ='YTD P&L'!E7 | G7: ='YTD P&L'!F7-'YTD P&L'!E7 | H7: ='YTD P&L'!G7-'YTD P&L'!F7 | I7: ='ANNL P&L'!D7-'YTD P&L'!G7 | J7: ='YTD P&L'!H7 | K7: ='YTD P&L'!I7-'YTD P&L'!H7 | L7: ='YTD P&L'!J7-'YTD P&L'!I7 | M7: ='ANNL P&L'!E7-'YTD P&L'!J7 | N7: ='YTD P&L'!K7 | O7: ='YTD P&L'!L7-'YTD P&L'!K7 | P7: ='YTD P&L'!M7-'YTD P&L'!L7 | Q7: ='ANNL P&L'!F7-'YTD P&L'!M7 | R7: =R4+SUM(R5:R6) | S7: =S4+SUM(S5:S6) | T7: =T4+SUM(T5:T6) | U7: =U4+SUM(U5:U6) | V7: =V4+SUM(V5:V6) | W7: =W4+SUM(W5:W6) | X7: =X4+SUM(X5:X6) | Y7: =Y4+SUM(Y5:Y6) | ... AG7: =AG4+SUM(AG5:AG6)
A8: Interest Income (Expense) | B8: ='YTD P&L'!B8 | C8: ='YTD P&L'!C8-'YTD P&L'!B8 | D8: ='YTD P&L'!D8-'YTD P&L'!C8 | E8: ='ANNL P&L'!C8-'YTD P&L'!D8 | F8: ='YTD P&L'!E8 | G8: ='YTD P&L'!F8-'YTD P&L'!E8 | H8: ='YTD P&L'!G8-'YTD P&L'!F8 | I8: ='ANNL P&L'!D8-'YTD P&L'!G8 | J8: ='YTD P&L'!H8 | K8: ='YTD P&L'!I8-'YTD P&L'!H8 | L8: ='YTD P&L'!J8-'YTD P&L'!I8 | M8: ='ANNL P&L'!E8-'YTD P&L'!J8 | N8: ='YTD P&L'!K8 | O8: ='YTD P&L'!L8-'YTD P&L'!K8 | P8: ='YTD P&L'!M8-'YTD P&L'!L8 | Q8: ='ANNL P&L'!F8-'YTD P&L'!M8 | R8: ='IS DRIVERS'!R6 | S8: ='IS DRIVERS'!S6 | T8: ='IS DRIVERS'!T6 | U8: ='IS DRIVERS'!U6 | V8: ='IS DRIVERS'!V6 | W8: ='IS DRIVERS'!W6 | X8: ='IS DRIVERS'!X6 | Y8: ='IS DRIVERS'!Y6 | ... AG8: ='IS DRIVERS'!AG6
A9: Foreign Currency Gain (Loss) | B9: ='YTD P&L'!B9 | C9: ='YTD P&L'!C9-'YTD P&L'!B9 | D9: ='YTD P&L'!D9-'YTD P&L'!C9 | E9: ='ANNL P&L'!C9-'YTD P&L'!D9 | F9: ='YTD P&L'!E9 | G9: ='YTD P&L'!F9-'YTD P&L'!E9 | H9: ='YTD P&L'!G9-'YTD P&L'!F9 | I9: ='ANNL P&L'!D9-'YTD P&L'!G9 | J9: ='YTD P&L'!H9 | K9: ='YTD P&L'!I9-'YTD P&L'!H9 | L9: ='YTD P&L'!J9-'YTD P&L'!I9 | M9: ='ANNL P&L'!E9-'YTD P&L'!J9 | N9: ='YTD P&L'!K9 | O9: ='YTD P&L'!L9-'YTD P&L'!K9 | P9: ='YTD P&L'!M9-'YTD P&L'!L9 | Q9: ='ANNL P&L'!F9-'YTD P&L'!M9 | R9: ='IS DRIVERS'!R7 | S9: ='IS DRIVERS'!S7 | T9: ='IS DRIVERS'!T7 | U9: ='IS DRIVERS'!U7 | V9: ='IS DRIVERS'!V7 | W9: ='IS DRIVERS'!W7 | X9: ='IS DRIVERS'!X7 | Y9: ='IS DRIVERS'!Y7 | ... AG9: ='IS DRIVERS'!AG7
A10: Other Income (Expense) | B10: ='YTD P&L'!B10 | C10: ='YTD P&L'!C10-'YTD P&L'!B10 | D10: ='YTD P&L'!D10-'YTD P&L'!C10 | E10: ='ANNL P&L'!C10-'YTD P&L'!D10 | F10: ='YTD P&L'!E10 | G10: ='YTD P&L'!F10-'YTD P&L'!E10 | H10: ='YTD P&L'!G10-'YTD P&L'!F10 | I10: ='ANNL P&L'!D10-'YTD P&L'!G10 | J10: ='YTD P&L'!H10 | K10: ='YTD P&L'!I10-'YTD P&L'!H10 | L10: ='YTD P&L'!J10-'YTD P&L'!I10 | M10: ='ANNL P&L'!E10-'YTD P&L'!J10 | N10: ='YTD P&L'!K10 | O10: ='YTD P&L'!L10-'YTD P&L'!K10 | P10: ='YTD P&L'!M10-'YTD P&L'!L10 | Q10: ='ANNL P&L'!F10-'YTD P&L'!M10 | R10: ='IS DRIVERS'!R8 | S10: ='IS DRIVERS'!S8 | T10: ='IS DRIVERS'!T8 | U10: ='IS DRIVERS'!U8 | V10: ='IS DRIVERS'!V8 | W10: ='IS DRIVERS'!W8 | X10: ='IS DRIVERS'!X8 | Y10: ='IS DRIVERS'!Y8 | ... AG10: ='IS DRIVERS'!AG8
A11: Pre-Tax Income (Loss) | B11: ='YTD P&L'!B11 | C11: ='YTD P&L'!C11-'YTD P&L'!B11 | D11: ='YTD P&L'!D11-'YTD P&L'!C11 | E11: ='ANNL P&L'!C11-'YTD P&L'!D11 | F11: ='YTD P&L'!E11 | G11: ='YTD P&L'!F11-'YTD P&L'!E11 | H11: ='YTD P&L'!G11-'YTD P&L'!F11 | I11: ='ANNL P&L'!D11-'YTD P&L'!G11 | J11: ='YTD P&L'!H11 | K11: ='YTD P&L'!I11-'YTD P&L'!H11 | L11: ='YTD P&L'!J11-'YTD P&L'!I11 | M11: ='ANNL P&L'!E11-'YTD P&L'!J11 | N11: ='YTD P&L'!K11 | O11: ='YTD P&L'!L11-'YTD P&L'!K11 | P11: ='YTD P&L'!M11-'YTD P&L'!L11 | Q11: ='ANNL P&L'!F11-'YTD P&L'!M11 | R11: =R7+SUM(R8:R10) | S11: =S7+SUM(S8:S10) | T11: =T7+SUM(T8:T10) | U11: =U7+SUM(U8:U10) | V11: =V7+SUM(V8:V10) | W11: =W7+SUM(W8:W10) | X11: =X7+SUM(X8:X10) | Y11: =Y7+SUM(Y8:Y10) | ... AG11: =AG7+SUM(AG8:AG10)
A12: Income Tax (Expense) Benefit | B12: ='YTD P&L'!B12 | C12: ='YTD P&L'!C12-'YTD P&L'!B12 | D12: ='YTD P&L'!D12-'YTD P&L'!C12 | E12: ='ANNL P&L'!C12-'YTD P&L'!D12 | F12: ='YTD P&L'!E12 | G12: ='YTD P&L'!F12-'YTD P&L'!E12 | H12: ='YTD P&L'!G12-'YTD P&L'!F12 | I12: ='ANNL P&L'!D12-'YTD P&L'!G12 | J12: ='YTD P&L'!H12 | K12: ='YTD P&L'!I12-'YTD P&L'!H12 | L12: ='YTD P&L'!J12-'YTD P&L'!I12 | M12: ='ANNL P&L'!E12-'YTD P&L'!J12 | N12: ='YTD P&L'!K12 | O12: ='YTD P&L'!L12-'YTD P&L'!K12 | P12: ='YTD P&L'!M12-'YTD P&L'!L12 | Q12: ='ANNL P&L'!F12-'YTD P&L'!M12 | R12: ='QTR P&L'!R11*'IS DRIVERS'!R9 | S12: ='QTR P&L'!S11*'IS DRIVERS'!S9 | T12: ='QTR P&L'!T11*'IS DRIVERS'!T9 | U12: ='QTR P&L'!U11*'IS DRIVERS'!U9 | V12: ='QTR P&L'!V11*'IS DRIVERS'!V9 | W12: ='QTR P&L'!W11*'IS DRIVERS'!W9 | X12: ='QTR P&L'!X11*'IS DRIVERS'!X9 | Y12: ='QTR P&L'!Y11*'IS DRIVERS'!Y9 | ... AG12: ='QTR P&L'!AG11*'IS DRIVERS'!AG9
A13: Net Income (Loss) | B13: ='YTD P&L'!B13 | C13: ='YTD P&L'!C13-'YTD P&L'!B13 | D13: ='YTD P&L'!D13-'YTD P&L'!C13 | E13: ='ANNL P&L'!C13-'YTD P&L'!D13 | F13: ='YTD P&L'!E13 | G13: ='YTD P&L'!F13-'YTD P&L'!E13 | H13: ='YTD P&L'!G13-'YTD P&L'!F13 | I13: ='ANNL P&L'!D13-'YTD P&L'!G13 | J13: ='YTD P&L'!H13 | K13: ='YTD P&L'!I13-'YTD P&L'!H13 | L13: ='YTD P&L'!J13-'YTD P&L'!I13 | M13: ='ANNL P&L'!E13-'YTD P&L'!J13 | N13: ='YTD P&L'!K13 | O13: ='YTD P&L'!L13-'YTD P&L'!K13 | P13: ='YTD P&L'!M13-'YTD P&L'!L13 | Q13: ='ANNL P&L'!F13-'YTD P&L'!M13 | R13: =R11+R12 | S13: =S11+S12 | T13: =T11+T12 | U13: =U11+U12 | V13: =V11+V12 | W13: =W11+W12 | X13: =X11+X12 | Y13: =Y11+Y12 | ... AG13: =AG11+AG12
A14: Preferred Dividends | B14: ='YTD P&L'!B14 | C14: ='YTD P&L'!C14-'YTD P&L'!B14 | D14: ='YTD P&L'!D14-'YTD P&L'!C14 | E14: ='ANNL P&L'!C14-'YTD P&L'!D14 | F14: ='YTD P&L'!E14 | G14: ='YTD P&L'!F14-'YTD P&L'!E14 | H14: ='YTD P&L'!G14-'YTD P&L'!F14 | I14: ='ANNL P&L'!D14-'YTD P&L'!G14 | J14: ='YTD P&L'!H14 | K14: ='YTD P&L'!I14-'YTD P&L'!H14 | L14: ='YTD P&L'!J14-'YTD P&L'!I14 | M14: ='ANNL P&L'!E14-'YTD P&L'!J14 | N14: ='YTD P&L'!K14 | O14: ='YTD P&L'!L14-'YTD P&L'!K14 | P14: ='YTD P&L'!M14-'YTD P&L'!L14 | Q14: ='ANNL P&L'!F14-'YTD P&L'!M14
A15: Income Allocated to Participating Preferred | B15: ='YTD P&L'!B15 | C15: ='YTD P&L'!C15-'YTD P&L'!B15 | D15: ='YTD P&L'!D15-'YTD P&L'!C15 | E15: ='ANNL P&L'!C15-'YTD P&L'!D15 | F15: ='YTD P&L'!E15 | G15: ='YTD P&L'!F15-'YTD P&L'!E15 | H15: ='YTD P&L'!G15-'YTD P&L'!F15 | I15: ='ANNL P&L'!D15-'YTD P&L'!G15 | J15: ='YTD P&L'!H15 | K15: ='YTD P&L'!I15-'YTD P&L'!H15 | L15: ='YTD P&L'!J15-'YTD P&L'!I15 | M15: ='ANNL P&L'!E15-'YTD P&L'!J15 | N15: ='YTD P&L'!K15 | O15: ='YTD P&L'!L15-'YTD P&L'!K15 | P15: ='YTD P&L'!M15-'YTD P&L'!L15 | Q15: ='ANNL P&L'!F15-'YTD P&L'!M15
A16: Net Income (Loss) Attributable to Common Shareholders | B16: ='YTD P&L'!B16 | C16: ='YTD P&L'!C16-'YTD P&L'!B16 | D16: ='YTD P&L'!D16-'YTD P&L'!C16 | E16: ='ANNL P&L'!C16-'YTD P&L'!D16 | F16: ='YTD P&L'!E16 | G16: ='YTD P&L'!F16-'YTD P&L'!E16 | H16: ='YTD P&L'!G16-'YTD P&L'!F16 | I16: ='ANNL P&L'!D16-'YTD P&L'!G16 | J16: ='YTD P&L'!H16 | K16: ='YTD P&L'!I16-'YTD P&L'!H16 | L16: ='YTD P&L'!J16-'YTD P&L'!I16 | M16: ='ANNL P&L'!E16-'YTD P&L'!J16 | N16: ='YTD P&L'!K16 | O16: ='YTD P&L'!L16-'YTD P&L'!K16 | P16: ='YTD P&L'!M16-'YTD P&L'!L16 | Q16: ='ANNL P&L'!F16-'YTD P&L'!M16 | R16: ='QTR P&L'!R2*'IS DRIVERS'!R10 | S16: ='QTR P&L'!S2*'IS DRIVERS'!S10 | T16: ='QTR P&L'!T2*'IS DRIVERS'!T10 | U16: ='QTR P&L'!U2*'IS DRIVERS'!U10 | V16: ='QTR P&L'!V2*'IS DRIVERS'!V10 | W16: ='QTR P&L'!W2*'IS DRIVERS'!W10 | X16: ='QTR P&L'!X2*'IS DRIVERS'!X10 | Y16: ='QTR P&L'!Y2*'IS DRIVERS'!Y10 | ... AG16: ='QTR P&L'!AG2*'IS DRIVERS'!AG10

Sheet QTR BS
B1: Q4 FY2022 | C1: Q1 FY2023 | D1: Q2 FY2023 | E1: Q3 FY2023 | F1: Q4 FY2023 | G1: Q1 FY2024 | H1: Q2 FY2024 | I1: Q3 FY2024 | J1: Q4 FY2024 | K1: Q1 FY2025 | L1: Q2 FY2025 | M1: Q3 FY2025 | N1: Q4 FY2025 | O1: Q1 FY2026E | P1: Q2 FY2026E | Q1: Q3 FY2026E | R1: Q4 FY2026E | S1: Q1 FY2027E | T1: Q2 FY2027E | U1: Q3 FY2027E | V1: Q4 FY2027E | W1: Q1 FY2028E | X1: Q2 FY2028E | Y1: Q3 FY2028E | Z1: Q4 FY2028E | AA1: Q1 FY2029E | AB1: Q2 FY2029E | AC1: Q3 FY2029E | AD1: Q4 FY2029E
A2: Cash & Cash Equivalents | B2: ='BALANCE SHEET'!B2 | C2: ='YTD BS'!C2 | D2: ='YTD BS'!D2 | E2: ='YTD BS'!E2 | F2: ='BALANCE SHEET'!C2 | G2: ='YTD BS'!G2 | H2: ='YTD BS'!H2 | I2: ='YTD BS'!I2 | J2: ='BALANCE SHEET'!D2 | K2: ='YTD BS'!K2 | L2: ='YTD BS'!L2 | M2: ='YTD BS'!M2 | N2: ='BALANCE SHEET'!E2 | O2: ='BS DRIVERS'!O2 | P2: ='BS DRIVERS'!P2 | Q2: ='BS DRIVERS'!Q2 | R2: ='BS DRIVERS'!R2 | S2: ='BS DRIVERS'!S2 | T2: ='BS DRIVERS'!T2 | U2: ='BS DRIVERS'!U2 | V2: ='BS DRIVERS'!V2 | ... AD2: ='BS DRIVERS'!AD2
A3: Restricted Cash | B3: ='BALANCE SHEET'!B3 | C3: ='YTD BS'!C3 | D3: ='YTD BS'!D3 | E3: ='YTD BS'!E3 | F3: ='BALANCE SHEET'!C3 | G3: ='YTD BS'!G3 | H3: ='YTD BS'!H3 | I3: ='YTD BS'!I3 | J3: ='BALANCE SHEET'!D3 | K3: ='YTD BS'!K3 | L3: ='YTD BS'!L3 | M3: ='YTD BS'!M3 | N3: ='BALANCE SHEET'!E3 | O3: ='BS DRIVERS'!O3 | P3: ='BS DRIVERS'!P3 | Q3: ='BS DRIVERS'!Q3 | R3: ='BS DRIVERS'!R3 | S3: ='BS DRIVERS'!S3 | T3: ='BS DRIVERS'!T3 | U3: ='BS DRIVERS'!U3 | V3: ='BS DRIVERS'!V3 | ... AD3: ='BS DRIVERS'!AD3
A4: Accounts Receivable | B4: ='BALANCE SHEET'!B4 | C4: ='YTD BS'!C4 | D4: ='YTD BS'!D4 | E4: ='YTD BS'!E4 | F4: ='BALANCE SHEET'!C4 | G4: ='YTD BS'!G4 | H4: ='YTD BS'!H4 | I4: ='YTD BS'!I4 | J4: ='BALANCE SHEET'!D4 | K4: ='YTD BS'!K4 | L4: ='YTD BS'!L4 | M4: ='YTD BS'!M4 | N4: ='BALANCE SHEET'!E4 | O4: ='QTR P&L'!R2*'BS DRIVERS'!O4/ASSUMPTIONS!$B$2 | P4: ='QTR P&L'!S2*'BS DRIVERS'!P4/ASSUMPTIONS!$B$2 | Q4: ='QTR P&L'!T2*'BS DRIVERS'!Q4/ASSUMPTIONS!$B$2 | R4: ='QTR P&L'!U2*'BS DRIVERS'!R4/ASSUMPTIONS!$B$2 | S4: ='QTR P&L'!V2*'BS DRIVERS'!S4/ASSUMPTIONS!$B$2 | T4: ='QTR P&L'!W2*'BS DRIVERS'!T4/ASSUMPTIONS!$B$2 | U4: ='QTR P&L'!X2*'BS DRIVERS'!U4/ASSUMPTIONS!$B$2 | V4: ='QTR P&L'!Y2*'BS DRIVERS'!V4/ASSUMPTIONS!$B$2 | ... AD4: ='QTR P&L'!AG2*'BS DRIVERS'!AD4/ASSUMPTIONS!$B$2
A5: Note Receivable - Current | B5: ='BALANCE SHEET'!B5 | C5: ='YTD BS'!C5 | D5: ='YTD BS'!D5 | E5: ='YTD BS'!E5 | F5: ='BALANCE SHEET'!C5 | G5: ='YTD BS'!G5 | H5: ='YTD BS'!H5 | I5: ='YTD BS'!I5 | J5: ='BALANCE SHEET'!D5 | K5: ='YTD BS'!K5 | L5: ='YTD BS'!L5 | M5: ='YTD BS'!M5 | N5: ='BALANCE SHEET'!E5 | O5: ='QTR P&L'!R2*'BS DRIVERS'!O5/ASSUMPTIONS!$B$2 | P5: ='QTR P&L'!S2*'BS DRIVERS'!P5/ASSUMPTIONS!$B$2 | Q5: ='QTR P&L'!T2*'BS DRIVERS'!Q5/ASSUMPTIONS!$B$2 | R5: ='QTR P&L'!U2*'BS DRIVERS'!R5/ASSUMPTIONS!$B$2 | S5: ='QTR P&L'!V2*'BS DRIVERS'!S5/ASSUMPTIONS!$B$2 | T5: ='QTR P&L'!W2*'BS DRIVERS'!T5/ASSUMPTIONS!$B$2 | U5: ='QTR P&L'!X2*'BS DRIVERS'!U5/ASSUMPTIONS!$B$2 | V5: ='QTR P&L'!Y2*'BS DRIVERS'!V5/ASSUMPTIONS!$B$2 | ... AD5: ='QTR P&L'!AG2*'BS DRIVERS'!AD5/ASSUMPTIONS!$B$2
A6: Inventories | B6: ='BALANCE SHEET'!B6 | C6: ='YTD BS'!C6 | D6: ='YTD BS'!D6 | E6: ='YTD BS'!E6 | F6: ='BALANCE SHEET'!C6 | G6: ='YTD BS'!G6 | H6: ='YTD BS'!H6 | I6: ='YTD BS'!I6 | J6: ='BALANCE SHEET'!D6 | K6: ='YTD BS'!K6 | L6: ='YTD BS'!L6 | M6: ='YTD BS'!M6 | N6: ='BALANCE SHEET'!E6 | O6: ='QTR P&L'!R3*'BS DRIVERS'!O6/ASSUMPTIONS!$B$2 | P6: ='QTR P&L'!S3*'BS DRIVERS'!P6/ASSUMPTIONS!$B$2 | Q6: ='QTR P&L'!T3*'BS DRIVERS'!Q6/ASSUMPTIONS!$B$2 | R6: ='QTR P&L'!U3*'BS DRIVERS'!R6/ASSUMPTIONS!$B$2 | S6: ='QTR P&L'!V3*'BS DRIVERS'!S6/ASSUMPTIONS!$B$2 | T6: ='QTR P&L'!W3*'BS DRIVERS'!T6/ASSUMPTIONS!$B$2 | U6: ='QTR P&L'!X3*'BS DRIVERS'!U6/ASSUMPTIONS!$B$2 | V6: ='QTR P&L'!Y3*'BS DRIVERS'!V6/ASSUMPTIONS!$B$2 | ... AD6: ='QTR P&L'!AG3*'BS DRIVERS'!AD6/ASSUMPTIONS!$B$2
A7: Prepaid Expenses | B7: ='BALANCE SHEET'!B7 | C7: ='YTD BS'!C7 | D7: ='YTD BS'!D7 | E7: ='YTD BS'!E7 | F7: ='BALANCE SHEET'!C7 | G7: ='YTD BS'!G7 | H7: ='YTD BS'!H7 | I7: ='YTD BS'!I7 | J7: ='BALANCE SHEET'!D7 | K7: ='YTD BS'!K7 | L7: ='YTD BS'!L7 | M7: ='YTD BS'!M7 | N7: ='BALANCE SHEET'!E7 | O7: ='QTR P&L'!R2*'BS DRIVERS'!O7 | P7: ='QTR P&L'!S2*'BS DRIVERS'!P7 | Q7: ='QTR P&L'!T2*'BS DRIVERS'!Q7 | R7: ='QTR P&L'!U2*'BS DRIVERS'!R7 | S7: ='QTR P&L'!V2*'BS DRIVERS'!S7 | T7: ='QTR P&L'!W2*'BS DRIVERS'!T7 | U7: ='QTR P&L'!X2*'BS DRIVERS'!U7 | V7: ='QTR P&L'!Y2*'BS DRIVERS'!V7 | ... AD7: ='QTR P&L'!AG2*'BS DRIVERS'!AD7
A8: Deferred Other Costs - Current | B8: ='BALANCE SHEET'!B8 | C8: ='YTD BS'!C8 | D8: ='YTD BS'!D8 | E8: ='YTD BS'!E8 | F8: ='BALANCE SHEET'!C8 | G8: ='YTD BS'!G8 | H8: ='YTD BS'!H8 | I8: ='YTD BS'!I8 | J8: ='BALANCE SHEET'!D8 | K8: ='YTD BS'!K8 | L8: ='YTD BS'!L8 | M8: ='YTD BS'!M8 | N8: ='BALANCE SHEET'!E8 | O8: ='QTR P&L'!R2*'BS DRIVERS'!O8 | P8: ='QTR P&L'!S2*'BS DRIVERS'!P8 | Q8: ='QTR P&L'!T2*'BS DRIVERS'!Q8 | R8: ='QTR P&L'!U2*'BS DRIVERS'!R8 | S8: ='QTR P&L'!V2*'BS DRIVERS'!S8 | T8: ='QTR P&L'!W2*'BS DRIVERS'!T8 | U8: ='QTR P&L'!X2*'BS DRIVERS'!U8 | V8: ='QTR P&L'!Y2*'BS DRIVERS'!V8 | ... AD8: ='QTR P&L'!AG2*'BS DRIVERS'!AD8
A9: Total Current Assets | B9: ='BALANCE SHEET'!B9 | C9: ='YTD BS'!C9 | D9: ='YTD BS'!D9 | E9: ='YTD BS'!E9 | F9: ='BALANCE SHEET'!C9 | G9: ='YTD BS'!G9 | H9: ='YTD BS'!H9 | I9: ='YTD BS'!I9 | J9: ='BALANCE SHEET'!D9 | K9: ='YTD BS'!K9 | L9: ='YTD BS'!L9 | M9: ='YTD BS'!M9 | N9: ='BALANCE SHEET'!E9 | O9: =SUM(O2:O8) | P9: =SUM(P2:P8) | Q9: =SUM(Q2:Q8) | R9: =SUM(R2:R8) | S9: =SUM(S2:S8) | T9: =SUM(T2:T8) | U9: =SUM(U2:U8) | V9: =SUM(V2:V8) | ... AD9: =SUM(AD2:AD8)
A10: Note Receivable - Non-Current | B10: ='BALANCE SHEET'!B10 | C10: ='YTD BS'!C10 | D10: ='YTD BS'!D10 | E10: ='YTD BS'!E10 | F10: ='BALANCE SHEET'!C10 | G10: ='YTD BS'!G10 | H10: ='YTD BS'!H10 | I10: ='YTD BS'!I10 | J10: ='BALANCE SHEET'!D10 | K10: ='YTD BS'!K10 | L10: ='YTD BS'!L10 | M10: ='YTD BS'!M10 | N10: ='BALANCE SHEET'!E10 | O10: ='QTR P&L'!R2*'BS DRIVERS'!O9 | P10: ='QTR P&L'!S2*'BS DRIVERS'!P9 | Q10: ='QTR P&L'!T2*'BS DRIVERS'!Q9 | R10: ='QTR P&L'!U2*'BS DRIVERS'!R9 | S10: ='QTR P&L'!V2*'BS DRIVERS'!S9 | T10: ='QTR P&L'!W2*'BS DRIVERS'!T9 | U10: ='QTR P&L'!X2*'BS DRIVERS'!U9 | V10: ='QTR P&L'!Y2*'BS DRIVERS'!V9 | ... AD10: ='QTR P&L'!AG2*'BS DRIVERS'!AD9
A11: Net PP&E | B11: ='BALANCE SHEET'!B11 | C11: ='YTD BS'!C11 | D11: ='YTD BS'!D11 | E11: ='YTD BS'!E11 | F11: ='BALANCE SHEET'!C11 | G11: ='YTD BS'!G11 | H11: ='YTD BS'!H11 | I11: ='YTD BS'!I11 | J11: ='BALANCE SHEET'!D11 | K11: ='YTD BS'!K11 | L11: ='YTD BS'!L11 | M11: ='YTD BS'!M11 | N11: ='BALANCE SHEET'!E11 | O11: ='BS DRIVERS'!O10 | P11: ='BS DRIVERS'!P10 | Q11: ='BS DRIVERS'!Q10 | R11: ='BS DRIVERS'!R10 | S11: ='BS DRIVERS'!S10 | T11: ='BS DRIVERS'!T10 | U11: ='BS DRIVERS'!U10 | V11: ='BS DRIVERS'!V10 | ... AD11: ='BS DRIVERS'!AD10
A12: ROU Assets - Operating - Non-Current | B12: ='BALANCE SHEET'!B12 | C12: ='YTD BS'!C12 | D12: ='YTD BS'!D12 | E12: ='YTD BS'!E12 | F12: ='BALANCE SHEET'!C12 | G12: ='YTD BS'!G12 | H12: ='YTD BS'!H12 | I12: ='YTD BS'!I12 | J12: ='BALANCE SHEET'!D12 | K12: ='YTD BS'!K12 | L12: ='YTD BS'!L12 | M12: ='YTD BS'!M12 | N12: ='BALANCE SHEET'!E12 | O12: ='QTR P&L'!R2*'BS DRIVERS'!O11 | P12: ='QTR P&L'!S2*'BS DRIVERS'!P11 | Q12: ='QTR P&L'!T2*'BS DRIVERS'!Q11 | R12: ='QTR P&L'!U2*'BS DRIVERS'!R11 | S12: ='QTR P&L'!V2*'BS DRIVERS'!S11 | T12: ='QTR P&L'!W2*'BS DRIVERS'!T11 | U12: ='QTR P&L'!X2*'BS DRIVERS'!U11 | V12: ='QTR P&L'!Y2*'BS DRIVERS'!V11 | ... AD12: ='QTR P&L'!AG2*'BS DRIVERS'!AD11
